File: Data/Raman/processed/albite_150 (500nm)_633nm_edge_100%_x50_vis_lwd_h30um_30sx2_01.txt
#Acq. time (s)=	30
#Accumulations=	2
#Range (cm-¹)=	100...4000
#Windows=	1
#Auto scanning=	Off
#Autofocus=	Off
#Macrospot=	Off
#AutoExposure=	Off
#Spike filter=	Multiple accum.
#Delay time (s)=	2
#Binning=	1
#Readout mode=	Signal
#DeNoise=	Standard
#ICS correction=	On
#Dark correction=	Off
#Inst. Process=	Off
#Detector Gain=	Best Dynamic
#Detector ADC=	50 kHz HS
#Detector temperature (°C)=	-60.09
#Instrument=	LabRAM HR Evol
#Detector=	SIN-EM FIVIS
#Objective=	x50_VIS_LWD
#Grating=	150 (500nm)
#ND Filter=	100%
#Laser=	633nm_Edge
#Hole=	30.0125
#Temperature=	0
#Range=	Visible
#StageXY=	75x50mm Scan+
#StageZ=	Z motor
#X (µm)=	0
#Y (µm)=	0
#Z (µm)=	59.3
#Full time(mm:ss)=	1:04
#Project=	20_10_27
#Sample=	BU24
#Site=
#Title=	BU24-Turm1-host_150 (500nm)_633nm_Edge_100%_x50_VIS_LWD_H30um_30sX2
#Remark=
#Date=	27.10.2020 18:26
#Acquired=	27.10.2020 18:26:54
#Data Range:Extract=	01.07.2021 19:23:37
#Base:Fit=	01.07.2021 19:24:15
#Base:Fit=	01.07.2021 19:24:39
#Base:Fit=	01.07.2021 19:24:47
#Base:Sub=	01.07.2021 19:24:50
100.764	9.63501
107.281	52.0633
113.791	449.659
120.297	149.834
126.797	50.998
133.291	23.408
139.78	43.0416
146.264	154.58
152.741	458.271
159.214	297.151
165.682	408.379
172.144	258.763
178.601	110.203
185.053	178.624
191.499	178.048
197.939	136.18
204.374	133.538
210.805	188.082
217.23	97.8754
223.648	46.4702
230.063	31.1688
236.472	40.3917
242.874	69.9393
249.273	183.191
255.667	255.66
262.053	125.787
268.436	309.961
274.813	270.236
281.185	194.473
287.552	464.023
293.913	711.463
300.27	209.338
306.62	122.239
312.965	91.1527
319.306	69.1922
325.64	60.6061
331.971	53.4592
338.295	41.6832
344.614	30.6719
350.93	21.4114
357.238	13.1744
363.542	6.03979
369.842	0.569092
376.135	-1.77893
382.423	2.48724
388.706	15.1197
394.984	39.1647
401.258	75.9227
407.526	142.888
413.789	211.439
420.046	173.532
426.299	44.9072
432.546	19.6658
438.788	15.9787
445.025	19.6591
451.257	29.8141
457.484	46.574
463.706	76.3401
469.923	147.727
476.135	640.743
482.342	1117.59
488.544	330.005
494.741	204.282
500.933	397.149
507.12	1719.89
513.3	998.171
519.477	253.65
525.649	133.104
531.815	75.765
537.976	43.7625
544.133	25.7975
550.285	17.1205
556.43	13.3989
562.572	10.6501
568.709	8.00635
574.84	5.3114
580.967	1.89026
587.09	-1.41614
593.205	-3.40283
599.318	-1.79626
605.424	3.65845
611.527	11.5194
617.623	19.5961
623.716	25.1462
629.802	27.0063
635.884	22.7039
641.962	14.9215
648.034	7.43994
654.101	3.41956
660.165	2.58875
666.222	6.03748
672.274	12.4803
678.324	19.3638
684.366	23.5619
690.404	23.4159
696.438	20.1294
702.466	15.3895
708.491	10.1715
714.51	4.93872
720.523	0.973999
726.533	-2.06091
732.537	-2.54395
738.537	0.150635
744.531	11.6635
750.521	12.9296
756.507	59.4841
762.487	197.126
768.463	159.747
774.434	87.1113
780.4	44.8153
786.362	28.6594
792.319	18.9624
798.269	16.7224
804.217	19.7522
810.159	23.8342
816.097	23.8982
822.03	21.5515
827.958	18.7517
833.881	16.8914
839.801	16.7117
845.714	17.8176
851.624	19.5564
857.529	21.0879
863.428	21.0347
869.324	18.0918
875.215	12.8699
881.1	7.14722
886.982	2.82056
892.858	0.334717
898.73	-0.624512
904.597	-0.727051
910.459	-0.65918
916.318	-0.501465
922.171	1.42725
928.02	5.83594
933.864	4.37744
939.703	3.76025
945.539	8.98877
951.368	23.0278
957.194	45.1797
963.014	59.3086
968.832	68.3606
974.643	70.905
980.45	65.25
986.253	50.6658
992.051	32.47
997.844	18.7368
1003.63	8.66699
1009.42	9.03101
1015.2	15.7847
1020.97	24.1145
1026.74	33.3125
1032.51	42.8018
1038.27	49.7632
1044.03	51.7134
1049.78	47.1306
1055.53	34.4502
1061.27	18.5901
1067.01	11.3726
1072.75	-0.800049
1078.48	9.51147
1084.2	34.2197
1089.92	68.7107
1095.64	101.995
1101.35	124.84
1107.06	130.565
1112.77	118.625
1118.46	93.2427
1124.16	70.3218
1129.85	49.332
1135.53	33.7554
1141.22	25.4727
1146.89	22.5015
1152.56	20.3848
1158.23	15.2241
1163.9	9.64746
1169.56	5.89551
1175.21	2.97852
1180.86	-7.12354
1186.51	-5.68652
1192.15	6.38428
1197.78	26.8506
1203.42	47.709
1209.04	65.9766
1214.67	88.0859
1220.29	97.3521
1225.9	93.3125
1231.51	80.6436
1237.12	67.8364
1242.72	56.0684
1248.32	44.166
1253.92	26.5703
1259.5	8.38965
1265.09	0.849121
1270.67	3.89355
1276.25	10.6553
1281.82	19.4429
1287.39	33.5757
1292.95	46.46
1298.51	51.647
1304.06	52.2046
1309.61	48.3511
1315.16	41.061
1320.7	34.4111
1326.24	31.3472
1331.77	29.3765
1337.3	29.0898
1342.83	35.5728
1348.35	29.6099
1353.86	23.4595
1359.37	20.479
1364.88	23.0571
1370.39	21.5391
1375.89	23.646
1381.38	27.9033
1386.87	24.3784
1392.36	23.9907
1397.84	27.5562
1403.32	38.4077
1408.79	67.7964
1414.26	87.8037
1419.73	98.5737
1425.19	98.7793
1430.65	88.4946
1436.1	73.3633
1441.55	55.4189
1447	32.853
1452.44	10.1587
1457.87	-1.19922
1463.31	2.3418
1468.73	11.6953
1474.16	20.4229
1479.58	29.9282
1484.99	40.0547
1490.41	49.8403
1495.81	60.688
1501.22	73.2427
1506.62	85.7739
1512.01	96.627
1517.4	103.533
1522.79	105.546
1528.17	110.25
1533.55	120.835
1538.93	126.877
1544.3	118.847
1549.67	105.835
1555.03	94.646
1560.39	83.8657
1565.74	79.916
1571.09	84.6865
1576.44	94.1157
1581.78	110.401
1587.12	126.843
1592.45	136.856
1597.78	144.17
1603.11	148.297
1608.43	162.056
1613.75	174.649
1619.07	187.413
1624.38	199.759
1629.68	210.156
1634.98	217.073
1640.28	219.766
1645.58	219.868
1650.87	216.992
1656.15	212.666
1661.44	207.643
1666.71	201.533
1671.99	194.925
1677.26	188.153
1682.53	180.289
1687.79	175.551
1693.05	185.23
1698.3	197.707
1703.55	207.568
1708.8	215.79
1714.04	217.558
1719.28	223.876
1724.51	236.039
1729.75	246.216
1734.97	252.077
1740.2	255.098
1745.42	252.817
1750.63	245.005
1755.84	226.365
1761.05	203.516
1766.25	185.244
1771.45	170.286
1776.65	157.831
1781.84	153.302
1787.03	164.637
1792.21	192.341
1797.39	223.417
1802.57	248.295
1807.74	264.045
1812.91	271.531
1818.08	268.414
1823.24	257.054
1828.39	244.647
1833.55	227.643
1838.7	212.483
1843.84	206.68
1848.99	204.301
1854.12	203.39
1859.26	208.288
1864.39	218.584
1869.52	229.197
1874.64	238.586
1879.76	244.604
1884.87	251.971
1889.98	258.523
1895.09	261.075
1900.2	256.978
1905.3	248.084
1910.39	246.347
1915.49	248.158
1920.57	250.727
1925.66	253.78
1930.74	257.541
1935.82	261.654
1940.89	265.815
1945.96	264.116
1951.03	259.247
1956.09	248.886
1961.15	227.349
1966.21	200.039
1971.26	182.737
1976.31	174.236
1981.35	175.442
1986.39	187.681
1991.43	207.575
1996.46	226.785
2001.49	225.45
2006.52	237.437
2011.54	252.603
2016.56	268.312
2021.57	275.808
2026.58	277.166
2031.59	271.181
2036.59	265.216
2041.59	262.249
2046.59	261.511
2051.58	263.642
2056.57	268.486
2061.55	277.058
2066.54	273.295
2071.51	267.448
2076.49	260.058
2081.46	241.969
2086.43	222.421
2091.39	211.279
2096.35	210.229
2101.3	214.292
2106.26	217.646
2111.21	218
2116.15	215.308
2121.09	213.985
2126.03	210.709
2130.97	203.334
2135.9	187.725
2140.83	172.349
2145.75	161.573
2150.67	153.854
2155.59	149.295
2160.5	146.712
2165.41	146.636
2170.31	146.165
2175.22	143.464
2180.12	142.242
2185.01	144.318
2189.9	150.271
2194.79	160.051
2199.68	170.146
2204.56	183.065
2209.43	194.347
2214.31	198.969
2219.18	198.01
2224.05	192.347
2228.91	184.822
2233.77	178.247
2238.63	173.702
2243.48	168.675
2248.33	162.874
2253.17	153.39
2258.02	141.568
2262.86	125.756
2267.69	110.155
2272.52	100.301
2277.35	94.6914
2282.18	93.0566
2287	95.6016
2291.82	102.441
2296.63	110.526
2301.44	112.688
2306.25	125.69
2311.05	135.418
2315.86	145.236
2320.65	153.791
2325.45	148.563
2330.24	154.85
2335.03	161.778
2339.81	168.7
2344.59	178.679
2349.37	185.185
2354.14	178.201
2358.91	164.857
2363.67	154.435
2368.44	141.589
2373.2	127.494
2377.95	112.258
2382.71	96.1738
2387.46	80.1709
2392.2	66.7197
2396.95	34.9395
2401.68	39.5635
2406.42	52.9131
2411.15	62.9443
2415.88	75.1543
2420.61	90.7061
2425.33	106.915
2430.05	123.336
2434.77	141.742
2439.48	161.464
2444.19	168.355
2448.89	159.352
2453.6	151.755
2458.29	140.272
2462.99	124.264
2467.68	110.052
2472.37	104.97
2477.06	108.748
2481.74	118.664
2486.42	128.557
2491.1	133.634
2495.77	139.823
2500.44	142.422
2505.1	135.508
2509.76	121.702
2514.42	117.862
2519.08	111.881
2523.73	101.593
2528.38	90.3828
2533.03	81.0703
2537.67	72.457
2542.31	66.7158
2546.95	64.3203
2551.58	68.874
2556.21	82.9463
2560.84	100.612
2565.46	112.552
2570.08	111.248
2574.7	98.2402
2579.31	73.4629
2583.92	43.4492
2588.53	22.585
2593.13	5.73828
2597.73	-0.588867
2602.33	-2.68164
2606.92	-1.15039
2611.51	3.77539
2616.1	12.3252
2620.68	22.2158
2625.26	19.8066
2629.84	66.2939
2634.42	114.616
2638.99	100.757
2643.56	61.3291
2648.12	27.4385
2652.68	40.8569
2657.24	43.8672
2661.8	39.332
2666.35	43.5815
2670.9	49.5781
2675.45	54.4844
2679.99	57.3931
2684.53	55.3564
2689.06	45.6938
2693.6	31.2324
2698.13	16.064
2702.66	7.92285
2707.18	7.94727
2711.7	15.2881
2716.22	25.5547
2720.73	39.4077
2725.24	53.334
2729.75	54.6455
2734.26	47.5381
2738.76	33.4902
2743.25	20.6255
2747.75	14.2456
2752.24	15.0532
2756.73	23.8804
2761.22	36.521
2765.7	48.3047
2770.18	59.6167
2774.66	68.9341
2779.13	76.3315
2783.6	80.8369
2788.07	81.6484
2792.53	79.9746
2797	75.8081
2801.45	68.3613
2805.91	57.8887
2810.36	44.4341
2814.81	32.8901
2819.26	33.3164
2823.7	35.6895
2828.14	38.771
2832.57	45.9019
2837.01	55.5581
2841.44	61.3101
2845.87	60.9458
2850.29	56.8203
2854.71	46.2856
2859.13	39.6841
2863.55	42.6221
2867.96	51.269
2872.37	66.4556
2876.77	84.9487
2881.18	102.272
2885.58	98.98
2889.97	83.6572
2894.37	61.3179
2898.76	36.4995
2903.15	27.1733
2907.53	26.4238
2911.91	29.8169
2916.29	34.6553
2920.67	40.832
2925.04	50.7656
2929.41	66.3848
2933.78	84.5488
2938.14	100.787
2942.5	114.971
2946.86	121.554
2951.22	116.74
2955.57	110.294
2959.92	101.759
2964.26	96.3042
2968.61	96.7793
2972.95	99.5762
2977.28	102.635
2981.62	103.19
2985.95	104.637
2990.28	103.134
2994.6	106.873
2998.93	115.845
3003.25	120.866
3007.56	120.48
3011.88	114.51
3016.19	106.365
3020.49	95.8267
3024.8	85.2271
3029.1	77.1079
3033.4	73.1313
3037.7	74.9336
3041.99	80.1362
3046.28	83.7017
3050.57	84.4912
3054.85	93.5684
3059.13	143.007
3063.41	118.883
3067.69	94.9189
3071.96	80.2896
3076.23	78.707
3080.5	89.9541
3084.76	108.456
3089.02	119.118
3093.28	130.402
3097.53	142.684
3101.79	154.581
3106.04	163.556
3110.28	158.486
3114.53	148.179
3118.77	135.431
3123.01	124.885
3127.24	118.782
3131.47	117.198
3135.7	119.001
3139.93	123.942
3144.15	130.842
3148.38	141.412
3152.59	146.655
3156.81	140.172
3161.02	130.944
3165.23	119.925
3169.44	108.422
3173.64	95.48
3177.84	83.0166
3182.04	76.4565
3186.24	80.9175
3190.43	82.7593
3194.62	87.6099
3198.81	90.7427
3202.99	88.3442
3207.17	84.3208
3211.35	83.542
3215.53	84.8877
3219.7	89.2632
3223.87	95.4731
3228.04	101.116
3232.2	105.251
3236.36	108.627
3240.52	112.016
3244.68	115.995
3248.83	117.471
3252.98	108.957
3257.13	97.084
3261.28	89.7231
3265.42	86.1489
3269.56	78.9453
3273.7	75.6736
3277.83	82.7251
3281.96	86.6006
3286.09	84.9338
3290.22	77.8047
3294.34	65.6851
3298.46	50.9954
3302.58	39.8955
3306.69	29.5146
3310.8	12.3801
3314.91	5.10889
3319.02	-0.0456543
3323.12	0.72168
3327.23	12.9148
3331.32	33.2813
3335.42	41.7319
3339.51	37.7771
3343.6	29.8269
3347.69	24.5747
3351.78	22.907
3355.86	25.3948
3359.94	30.6626
3364.02	38.0303
3368.09	51.8982
3372.16	64.7134
3376.23	69.3765
3380.29	67.7034
3384.36	60.749
3388.42	52.1086
3392.48	45.6113
3396.53	39.8621
3400.58	35.3772
3404.63	33.1912
3408.68	34.9961
3412.73	41.231
3416.77	55.9219
3420.81	66.5803
3424.84	73.6404
3428.88	77.7397
3432.91	78.1787
3436.94	75.9231
3440.96	69.5935
3444.99	61.6169
3449.01	54.301
3453.03	49.7375
3457.04	47.6323
3461.05	48.9971
3465.06	52.9419
3469.07	59.2183
3473.08	69.0562
3477.08	83.7793
3481.08	93.0237
3485.07	90.9878
3489.07	82.0823
3493.06	66.9421
3497.05	52.1125
3501.04	40.926
3505.02	35.2
3509	35.5261
3512.98	38.8977
3516.96	42.2903
3520.93	44.8994
3524.9	47.2063
3528.87	51.7256
3532.83	58.957
3536.8	66.5642
3540.76	73.6284
3544.71	78.0295
3548.67	78.3
3552.62	59.3667
3556.57	36.2102
3560.52	25.2505
3564.47	12.5493
3568.41	1.32373
3572.35	-2.46533
3576.29	2.33325
3580.22	15.365
3584.15	30.3804
3588.08	38.1367
3592.01	33.6394
3595.93	36.0723
3599.85	38.3936
3603.77	39.8308
3607.69	41.74
3611.61	44.1948
3615.52	46.7842
3619.43	50.0605
3623.33	52.7029
3627.24	53.3169
3631.14	50.9724
3635.04	50.5627
3638.93	52.3745
3642.83	52.6033
3646.72	50.8882
3650.61	45.9539
3654.49	40.3787
3658.38	34.6941
3662.26	30.4951
3666.14	29.5686
3670.01	32.397
3673.89	39.8562
3677.76	47.8481
3681.63	54.3865
3685.5	54.6721
3689.36	55.5479
3693.22	58.873
3697.08	62.3608
3700.94	64.7793
3704.79	65.6567
3708.64	65.3817
3712.49	63.0006
3716.34	59.7195
3720.18	56.6089
3724.02	54.1021
3727.86	55.0092
3731.7	57.2937
3735.53	58.7871
3739.36	59.0031
3743.19	59.5383
3747.02	62.5287
3750.84	69.3821
3754.66	79.5205
3758.48	91.2175
3762.3	102.978
3766.12	108.442
3769.93	103.021
3773.74	93.6787
3777.54	87.1228
3781.35	83.4729
3785.15	78.2518
3788.95	73.5155
3792.75	78.9603
3796.54	86.5156
3800.34	91.23
3804.13	93.7461
3807.91	94.6344
3811.7	95.7417
3815.48	103.257
3819.26	107.255
3823.04	106.731
3826.82	105.49
3830.59	105.762
3834.36	109.671
3838.13	108.966
3841.89	106.107
3845.66	107.916
3849.42	114.766
3853.18	121.053
3856.93	122.154
3860.69	121.737
3864.44	118.321
3868.19	113.137
3871.93	107.426
3875.68	102.369
3879.42	100.708
3883.16	106.761
3886.9	109.579
3890.63	109.16
3894.37	110.752
3898.1	102.025
3901.82	91.5524
3905.55	85.2324
3909.27	85.0861
3912.99	91.8052
3916.71	97.9307
3920.43	100.741
3924.14	98.9824
3927.85	94.7418
3931.56	85.4912
3935.27	76.0834
3938.97	70.5952
3942.67	70.1184
3946.37	69.9121
3950.07	62.7235
3953.77	49.307
3957.46	38.1478
3961.15	35.5438
3964.84	30.3549
3968.52	24.3875
3972.2	17.845
3975.89	11.3448
3979.56	5.54272
3983.24	1.40393
3986.92	-0.594604
3990.59	-0.5802
3994.26	3.68726
3997.92	2.37085
3999.76	-5.93616