File: Data/Raman/processed/apatite-F_150 (500nm)_633nm_Edge_50%_x50_VIS_LWD_H100um_15sX2.txt
#Acq. time (s)=	15
#Accumulations=	2
#Range (cm-¹)=	100...4000
#Windows=	1
#Auto scanning=	Off
#Autofocus=	Off
#Macrospot=	Off
#AutoExposure=	Off
#Spike filter=	Multiple accum.
#Delay time (s)=	0
#Binning=	1
#Readout mode=	Signal
#DeNoise=	Standard
#ICS correction=	On
#Dark correction=	Off
#Inst. Process=	On
#Detector Gain=	Best Dynamic
#Detector ADC=	50 kHz HS
#Detector temperature (°C)=	-60.09
#Instrument=	LabRAM HR Evol
#Detector=	SIN-EM FIVIS
#Objective=	x50_VIS_LWD
#Grating=	150 (500nm)
#ND Filter=	50%
#Laser=	633nm_Edge
#Hole=	100.021
#Temperature=	0
#Range=	Visible
#StageXY=	75x50mm Scan+
#StageZ=	Z motor
#X (µm)=	0
#Y (µm)=	0
#Z (µm)=	83.3
#Project=	20_05_11
#Sample=	BU20b
#Site=
#Title=	BU20b-area1-apatite_clear-top_150 (500nm)_633nm_Edge_50%_x50_VIS_LWD_H100um_15sX2
#Remark=
#Date=	11.05.2020 18:09
#Acquired=	11.05.2020 18:09:27
#Data Range:Extract=	01.07.2021 19:23:37
#Base:Fit=	01.07.2021 19:24:15
#Base:Fit=	01.07.2021 19:24:39
#Base:Fit=	01.07.2021 19:24:47
#Base:Sub=	01.07.2021 19:24:50
100.862	0.160767
107.378	28.6071
113.889	28.9949
120.394	26.1281
126.894	39.3044
133.388	55.2703
139.878	62.0348
146.361	60.264
152.84	57.7917
159.313	67.3784
165.78	78.2291
172.242	87.4952
178.699	103.917
185.149	100.25
191.596	95.6853
198.037	90.2583
204.472	186.22
210.903	303.363
217.326	305.734
223.746	247.271
230.16	207.575
236.568	167.315
242.972	127.966
249.371	85.0676
255.762	62.7261
262.151	51.8229
268.533	50.4094
274.91	72.5316
281.282	103.441
287.648	131.827
294.01	155.004
300.365	178.208
306.716	172.144
313.061	148.664
319.401	112.561
325.737	73.14
332.066	40.2476
338.392	22.1185
344.711	12.5363
351.024	3.88489
357.335	-0.621277
363.638	-1.54224
369.936	-0.290649
376.23	2.0965
382.519	5.24768
388.802	7.76068
395.08	24.323
401.353	25.6442
407.62	43.9401
413.884	62.4523
420.141	158.815
426.394	484.93
432.641	1030.29
438.883	797.634
445.12	477.829
451.352	404.886
457.579	338.08
463.801	255.712
470.018	177.338
476.23	119.308
482.437	77.9061
488.638	51.6431
494.834	39.7589
501.026	31.0273
507.212	27.2345
513.394	27.4468
519.571	27.4664
525.743	25.012
531.908	25.5494
538.07	26.0043
544.227	26.8817
550.377	28.8486
556.524	39.2428
562.666	39.696
568.801	60.6753
574.933	78.7319
581.061	207.453
587.181	535.373
593.299	1486.74
599.41	757.728
605.517	314.73
611.618	522.744
617.716	206.797
623.807	101.119
629.895	58.3286
635.977	35.2469
642.053	18.4445
648.127	9.91888
654.193	6.33893
660.256	5.66418
666.314	7.12994
672.367	9.84558
678.414	13.5669
684.457	17.5053
690.496	21.1412
696.529	23.4416
702.558	23.4192
708.581	20.6164
714.6	15.8425
720.614	9.97522
726.624	4.18298
732.628	-0.117737
738.628	-1.81622
744.623	-0.737549
750.613	1.55786
756.598	4.79596
762.578	8.57544
768.554	11.8732
774.525	13.55
780.49	12.9008
786.451	10.496
792.408	7.40552
798.36	4.13977
804.307	1.42365
810.25	0.0346069
816.186	0.586975
822.119	3.54504
828.048	8.77722
833.972	13.9608
839.889	17.0453
845.804	19.5178
851.714	21.7369
857.617	24.0695
863.518	26.3145
869.413	27.2232
875.303	23.5869
881.19	21.0394
887.07	20.134
892.947	18.4838
898.818	19.2572
904.686	25.4031
910.548	28.5353
916.406	39.3549
922.26	50.9417
928.108	66.0219
933.953	82.2728
939.792	106.157
945.626	209.006
951.457	558.391
957.282	1858.09
963.103	5573.05
968.919	8363.86
974.731	3029.07
980.539	702.251
986.341	180.303
992.139	98.6508
997.932	66.53
1003.72	66.1848
1009.51	77.6636
1015.29	105.344
1021.06	148.997
1026.83	196.282
1032.6	253.732
1038.36	368.006
1044.12	737.639
1049.87	1373.35
1055.62	1607.15
1061.36	607.799
1067.1	244.556
1072.84	226.079
1078.56	415.749
1084.29	673.54
1090.01	435.991
1095.73	200.334
1101.44	115.831
1107.15	86.0989
1112.85	74.1117
1118.55	64.2847
1124.24	59.2531
1129.94	55.5818
1135.62	51.3134
1141.3	47.6724
1146.98	44.8209
1152.65	43.4152
1158.32	43.9222
1163.98	45.5148
1169.64	47.2691
1175.3	47.8502
1180.95	47.7322
1186.59	46.8956
1192.23	45.3468
1197.87	44.0472
1203.5	45.5223
1209.13	48.5808
1214.75	51.9122
1220.37	53.6031
1225.99	53.3906
1231.6	51.6599
1237.21	49.5031
1242.81	47.1837
1248.41	43.8182
1254	39.808
1259.59	35.9198
1265.17	32.9266
1270.75	30.562
1276.33	28.356
1281.9	23.8019
1287.47	19.5148
1293.03	18.4171
1298.59	19.6569
1304.15	23.9032
1309.7	28.3425
1315.24	29.4769
1320.78	29.282
1326.32	27.0174
1331.85	23.5816
1337.38	19.9031
1342.91	17.0583
1348.43	15.4371
1353.95	16.3979
1359.46	18.5941
1364.97	20.3204
1370.47	21.3027
1375.97	22.1347
1381.46	21.965
1386.96	21.2962
1392.44	20.4278
1397.92	19.6077
1403.4	18.7108
1408.88	17.9021
1414.35	16.6589
1419.81	11.4188
1425.27	10.6245
1430.73	11.033
1436.18	11.0083
1441.63	11.2544
1447.08	11.305
1452.52	10.1311
1457.96	6.27747
1463.39	2.27051
1468.82	0.138794
1474.24	-0.334656
1479.66	0.3172
1485.08	1.43939
1490.49	4.16797
1495.9	8.09637
1501.3	11.5027
1506.7	13.1342
1512.09	14.2677
1517.49	15.3543
1522.87	16.1628
1528.26	15.9119
1533.63	14.6567
1539.01	13.0591
1544.38	10.5447
1549.75	6.36542
1555.11	-0.754395
1560.47	-3.59802
1565.82	-3.33502
1571.17	-0.310791
1576.52	4.20569
1581.86	8.97974
1587.2	15.1417
1592.54	19.9131
1597.86	19.2399
1603.19	16.7306
1608.51	14.6725
1613.83	13.7138
1619.15	12.8349
1624.46	11.1619
1629.76	9.38141
1635.06	10.0524
1640.36	12.9254
1645.66	13.6182
1650.95	12.6675
1656.23	10.957
1661.52	8.66058
1666.79	5.92664
1672.07	3.13928
1677.34	2.15576
1682.6	5.4812
1687.87	9.91791
1693.13	13.6253
1698.38	15.804
1703.63	15.9452
1708.88	14.0294
1714.12	10.8641
1719.36	7.15649
1724.59	4.25159
1729.82	2.836
1735.05	2.39526
1740.27	1.8479
1745.49	2.46661
1750.71	4.65265
1755.92	7.95422
1761.13	10.6458
1766.33	10.9973
1771.53	9.64557
1776.73	7.1319
1781.92	4.42053
1787.11	2.70819
1792.29	2.33496
1797.47	2.38934
1802.65	2.00226
1807.82	1.20062
1812.99	1.36078
1818.15	3.18896
1823.32	5.36102
1828.47	7.60187
1833.63	7.59216
1838.78	2.28943
1843.92	2.22351
1849.06	1.85095
1854.2	1.54364
1859.34	1.67566
1864.47	1.59631
1869.59	1.34656
1874.72	0.902283
1879.84	-1.58466
1884.95	-5.2782
1890.06	-7.3374
1895.17	-6.51843
1900.27	-3.44482
1905.37	-1.93652
1910.47	0.0150146
1915.56	2.56458
1920.65	5.25409
1925.74	7.30902
1930.82	8.46191
1935.9	8.69305
1940.97	7.30664
1946.04	4.96454
1951.11	2.35107
1956.17	1.86896
1961.23	2.12549
1966.28	2.65277
1971.33	3.1908
1976.38	3.43018
1981.43	3.50085
1986.47	3.41034
1991.5	2.91724
1996.54	1.5152
2001.57	-1.24884
2006.59	-1.9906
2011.61	0.474792
2016.63	3.75696
2021.65	6.97235
2026.66	9.51843
2031.66	12.093
2036.67	17.1426
2041.67	20.6912
2046.66	20.9951
2051.66	20.2171
2056.65	18.7712
2061.63	17.045
2066.61	15.2084
2071.59	13.7804
2076.56	13.1963
2081.53	12.7061
2086.5	12.2296
2091.46	12.4434
2096.42	13.9208
2101.38	15.1198
2106.33	14.7927
2111.28	13.6317
2116.23	12.061
2121.17	9.97681
2126.11	8.43768
2131.04	8.53925
2135.97	10.6999
2140.9	13.6789
2145.82	17.8841
2150.74	21.8771
2155.66	24.72
2160.57	24.8217
2165.48	22.3123
2170.39	18.5397
2175.29	15.5735
2180.19	14.2598
2185.09	14.3702
2189.98	15.8951
2194.86	19.1504
2199.75	22.269
2204.63	20.4434
2209.51	18.4681
2214.38	17.3068
2219.25	16.7391
2224.12	17.1046
2228.98	18.405
2233.84	20.7952
2238.7	23.9395
2243.55	25.8702
2248.4	25.199
2253.25	20.8361
2258.09	16.0359
2262.93	13.5448
2267.76	13.7685
2272.6	16.3738
2277.43	19.8533
2282.25	21.3709
2287.07	20.0645
2291.89	17.6299
2296.7	13.2487
2301.52	7.50696
2306.32	6.00543
2311.13	7.7146
2315.93	12.7414
2320.73	18.072
2325.52	22.4435
2330.31	25.2206
2335.1	26.831
2339.88	27.4213
2344.66	26.7117
2349.44	24.0486
2354.21	20.6335
2358.98	18.511
2363.75	18.9852
2368.51	19.8557
2373.27	19.9577
2378.03	18.8393
2382.78	17.7227
2387.53	18.0682
2392.28	19.777
2397.02	21.5533
2401.76	23.2687
2406.49	24.6735
2411.23	25.242
2415.95	24.3679
2420.68	22.7303
2425.4	20.7514
2430.12	19.1345
2434.84	18.7176
2439.55	18.8948
2444.26	19.6569
2448.96	19.8124
2453.67	19.1458
2458.37	20.8311
2463.06	23.2515
2467.75	25.0295
2472.44	25.8986
2477.13	25.9617
2481.81	25.5234
2486.49	25.084
2491.17	24.1588
2495.84	20.6005
2500.51	17.5681
2505.17	18.0158
2509.84	18.6129
2514.5	19.3557
2519.15	20.6072
2523.8	22.0932
2528.45	24.4623
2533.1	27.252
2537.74	29.1732
2542.38	29.8086
2547.02	28.7595
2551.65	26.9949
2556.28	25.8147
2560.91	25.3124
2565.53	24.4816
2570.15	22.6912
2574.77	20.5358
2579.38	18.5689
2583.99	18.6195
2588.6	20.1161
2593.2	21.5665
2597.8	22.4362
2602.4	24.0265
2606.99	26.2253
2611.58	28.3898
2616.17	29.6866
2620.75	29.8275
2625.33	29.1324
2629.91	28.2312
2634.49	27.6855
2639.06	27.9434
2643.63	28.7195
2648.19	29.1035
2652.75	28.6301
2657.31	27.2581
2661.87	25.3546
2666.42	22.9654
2670.97	20.8571
2675.51	20.0354
2680.06	22.7402
2684.6	23.6277
2689.13	22.2718
2693.67	20.3197
2698.2	18.3179
2702.72	17.0765
2707.25	16.0865
2711.77	16.4084
2716.28	23.5696
2720.8	19.3887
2725.31	14.8672
2729.82	10.3922
2734.32	6.77356
2738.83	7.19397
2743.32	11.6519
2747.82	14.8243
2752.31	18.695
2756.8	20.6354
2761.29	20.5281
2765.77	19.4468
2770.25	17.2023
2774.73	14.3181
2779.2	11.3438
2783.67	9.23541
2788.14	9.47656
2792.6	10.2731
2797.06	12.4373
2801.52	12.9665
2805.98	13.8793
2810.43	14.3393
2814.88	13.5417
2819.32	9.41278
2823.77	3.38611
2828.2	-0.89563
2832.64	-2.54358
2837.08	-0.782166
2841.51	3.66016
2845.93	11.0228
2850.36	17.9904
2854.78	21.2521
2859.2	20.147
2863.61	15.647
2868.02	9.83752
2872.43	7.46069
2876.84	7.39728
2881.24	9.22888
2885.64	12.5511
2890.04	15.6554
2894.43	17.7607
2898.82	16.768
2903.21	14.8167
2907.6	13.1407
2911.98	13.4953
2916.36	13.0634
2920.74	12.569
2925.11	13.7852
2929.48	17.6611
2933.84	22.4658
2938.21	23.9462
2942.57	20.6974
2946.93	14.5357
2951.28	8.45386
2955.64	4.85394
2959.98	4.17889
2964.33	6.34216
2968.67	10.7856
2973.01	18.0394
2977.35	24.4851
2981.68	26.1452
2986.02	24.3174
2990.34	20.4922
2994.67	16.8704
2998.99	15.3448
3003.31	15.8629
3007.63	17.0696
3011.94	15.4343
3016.25	11.7752
3020.56	16.4069
3024.86	11.5882
3029.17	10.0729
3033.47	9.22272
3037.76	7.60486
3042.05	7.92365
3046.34	8.71698
3050.63	8.4151
3054.92	6.46442
3059.2	3.74731
3063.48	1.30975
3067.75	0.803528
3072.02	3.10339
3076.29	5.74329
3080.56	7.90405
3084.82	10.7789
3089.09	13.6148
3093.34	15.0947
3097.6	16.8878
3101.85	19.9412
3106.1	17.6779
3110.35	15.5699
3114.59	17.8379
3118.83	22.4763
3123.07	24.2565
3127.31	19.9993
3131.54	15.0257
3135.77	10.6794
3140	7.7381
3144.22	4.65137
3148.44	0.510071
3152.66	-0.217041
3156.87	-0.264099
3161.09	-0.154846
3165.29	1.78967
3169.5	4.76166
3173.71	7.78839
3177.91	10.0564
3182.11	11.3824
3186.3	11.9109
3190.49	12.1741
3194.68	12.6095
3198.87	14.0626
3203.05	15.2876
3207.24	16.6179
3211.41	18.5077
3215.59	19.6431
3219.76	17.6848
3223.93	18.0269
3228.1	16.686
3232.27	10.8759
3236.43	7.185
3240.59	4.52606
3244.74	4.13879
3248.9	7.01678
3253.05	12.054
3257.2	17.5976
3261.34	18.2437
3265.48	16.3657
3269.62	14.2511
3273.76	13.0403
3277.89	11.619
3282.02	10.5925
3286.15	10.6033
3290.28	6.01227
3294.4	4.11725
3298.52	3.73108
3302.64	4.25323
3306.75	6.82928
3310.87	9.32953
3314.98	10.7032
3319.08	9.62976
3323.19	7.01373
3327.29	4.87726
3331.39	5.41797
3335.48	5.97266
3339.58	6.61761
3343.67	7.19537
3347.75	7.87231
3351.84	8.2229
3355.92	8.37256
3360	8.64508
3364.08	9.23413
3368.15	10.4168
3372.22	3.87592
3376.29	0.5802
3380.36	1.92975
3384.42	8.64551
3388.48	7.0047
3392.54	4.19482
3396.59	2.6618
3400.65	2.4389
3404.7	5.71967
3408.74	8.44281
3412.79	9.34344
3416.83	9.75342
3420.87	10.0153
3424.91	9.86365
3428.94	9.98291
3432.97	5.63745
3437	0.96991
3441.02	-2.41351
3445.05	-1.75922
3449.07	0.0810547
3453.09	3.10864
3457.1	7.73956
3461.11	12.0466
3465.13	15.593
3469.13	17.9813
3473.14	8.40466
3477.14	9.88208
3481.14	19.4583
3485.14	17.3528
3489.13	16.6134
3493.12	17.8277
3497.11	18.3052
3501.1	19.4575
3505.08	21.3071
3509.06	24.2115
3513.04	28.6259
3517.02	34.2441
3520.99	37.7623
3524.96	43.3705
3528.93	52.316
3532.89	60.6362
3536.86	67.3477
3540.82	63.3443
3544.78	54.8063
3548.73	45.2954
3552.68	37.6603
3556.63	32.4751
3560.58	29.9271
3564.53	28.3589
3568.47	26.0508
3572.41	23.5892
3576.34	21.2722
3580.28	19.3514
3584.21	17.6343
3588.14	14.091
3592.07	10.0604
3595.99	8.13019
3599.91	7.50647
3603.83	7.0379
3607.75	6.77985
3611.66	6.88403
3615.58	4.92108
3619.49	2.35016
3623.39	0.495667
3627.3	-0.00524902
3631.2	1.42035
3635.1	2.93634
3638.99	3.65637
3642.89	4.16901
3646.78	1.49292
3650.67	-0.56311
3654.55	0.201355
3658.44	2.93274
3662.32	5.88898
3666.2	4.43726
3670.07	2.56018
3673.95	0.575745
3677.82	-1.68671
3681.69	-3.7428
3685.55	-5.12042
3689.42	-4.73505
3693.28	-3.21173
3697.14	-1.02087
3700.99	1.84558
3704.85	4.62842
3708.7	7.17218
3712.55	9.03986
3716.39	10.1956
3720.24	10.8876
3724.08	10.1514
3727.92	9.16479
3731.76	8.02631
3735.59	5.9787
3739.42	9.12952
3743.25	12.2206
3747.08	11.8528
3750.9	10.6106
3754.72	8.59601
3758.54	5.73999
3762.36	1.74463
3766.17	-1.16791
3769.99	0.323792
3773.79	2.99896
3777.6	4.51111
3781.41	5.22449
3785.21	6.57153
3789.01	8.01727
3792.81	8.80951
3796.6	8.52997
3800.39	6.31451
3804.18	3.45459
3807.97	0.885803
3811.76	1.17645
3815.54	1.85632
3819.32	2.18475
3823.1	2.72827
3826.87	4.6944
3830.65	7.27063
3834.42	7.15613
3838.18	6.57898
3841.95	4.07178
3845.71	2.66681
3849.48	2.41559
3853.23	2.73871
3856.99	3.39948
3860.74	3.68707
3864.5	3.37921
3868.24	1.8335
3871.99	0.744995
3875.74	1.29932
3879.48	5.46631
3883.22	1.95013
3886.95	2.52209
3890.69	3.07306
3894.42	5.75238
3898.15	-17.7154
3901.88	12.7292
3905.61	14.4686
3909.33	12.6678
3913.05	10.9412
3916.77	10.4078
3920.48	12.3888
3924.2	6.63254
3927.91	2.75769
3931.62	3.82034
3935.32	4.707
3939.03	8.14395
3942.73	9.85583
3946.43	9.29755
3950.13	6.97668
3953.82	8.71024
3957.51	16.3614
3961.2	14.0291
3964.89	6.87079
3968.58	1.31784
3972.26	-0.908447
3975.94	0.252808
3979.62	-0.609406
3983.3	2.16205
3986.97	6.54764
3990.64	9.85773
3994.31	9.01761
3997.98	5.4903
3999.81	6.78711