File: Data/Raman/processed/apatite-OH_150 (500nm)_633nm_edge_100%_x50_vis_lwd_h30um_30sx2_01.txt
#Acq. time (s)=	30
#Accumulations=	2
#Range (cm-¹)=	100...4000
#Windows=	1
#Auto scanning=	Off
#Autofocus=	Off
#Macrospot=	Off
#AutoExposure=	Off
#Spike filter=	Multiple accum.
#Delay time (s)=	2
#Binning=	1
#Readout mode=	Signal
#DeNoise=	Standard
#ICS correction=	On
#Dark correction=	Off
#Inst. Process=	Off
#Detector Gain=	Best Dynamic
#Detector ADC=	50 kHz HS
#Detector temperature (°C)=	-60.09
#Instrument=	LabRAM HR Evol
#Detector=	SIN-EM FIVIS
#Objective=	x50_VIS_LWD
#Grating=	150 (500nm)
#ND Filter=	100%
#Laser=	633nm_Edge
#Hole=	30.0125
#Temperature=	0
#Range=	Visible
#StageXY=	75x50mm Scan+
#StageZ=	Z motor
#X (µm)=	0
#Y (µm)=	0
#Z (µm)=	-46.1
#Full time(mm:ss)=	1:04
#Project=	21_02_17
#Sample=	BU19_TS(1)
#Site=
#Title=	BU19TS(1)-Area1_fibrousINclorful_150 (500nm)_633nm_Edge_100%_x50_VIS_LWD_H30um_30sX2
#Remark=
#Date=	17.02.2021 19:27
#Acquired=	17.02.2021 19:27:21
#Data Range:Extract=	01.07.2021 19:23:36
#Base:Fit=	01.07.2021 19:24:15
#Base:Fit=	01.07.2021 19:24:39
#Base:Fit=	01.07.2021 19:24:47
#Base:Sub=	01.07.2021 19:24:50
100.892	264.981
107.408	249.188
113.919	224.67
120.424	210.658
126.924	214.292
133.418	255.631
139.907	300.863
146.391	263.041
152.868	225.233
159.341	200.977
165.808	173.059
172.271	171.601
178.728	192.757
185.179	207.242
191.625	192.704
198.065	193.479
204.501	221.653
210.931	225.471
217.356	175.182
223.774	165.162
230.188	157.857
236.598	144.018
243	117.402
249.399	88.0968
255.792	67.6615
262.179	58.2882
268.561	66.2626
274.938	78.8583
281.31	97.4275
287.677	110.362
294.038	113.786
300.394	98.4018
306.744	82.7107
313.089	64.2061
319.43	47.796
325.765	34.0132
332.095	29.5031
338.419	21.4979
344.738	13.3287
351.054	5.47784
357.362	1.37958
363.666	-0.260193
369.965	0.231384
376.259	3.46802
382.547	11.6441
388.83	12.9673
395.107	29.1335
401.381	30.7504
407.649	22.1785
413.911	41.9835
420.169	123.223
426.421	375.204
432.668	662.46
438.911	382.651
445.148	294.897
451.38	263.174
457.607	151.577
463.828	87.3229
470.045	48.1107
476.257	33.863
482.464	18.9723
488.666	7.19824
494.862	2.13354
501.054	1.19055
507.241	2.18604
513.421	4.2981
519.598	7.00903
525.77	9.9093
531.936	12.774
538.097	13.1212
544.253	15.9098
550.405	12.8198
556.551	4.4281
562.693	6.25598
568.83	10.0286
574.96	78.27
581.087	199.459
587.21	365.52
593.325	610.074
599.438	175.31
605.544	141.29
611.646	174.615
617.743	74.3345
623.835	33.655
629.922	17.4984
636.003	11.4303
642.081	11.5076
648.153	11.8347
654.22	9.67932
660.284	8.48108
666.341	7.73584
672.393	7.45935
678.442	7.59485
684.485	7.96533
690.523	8.62097
696.556	9.34363
702.584	11.0045
708.609	12.4744
714.628	12.0911
720.641	9.36951
726.651	6.10974
732.655	2.83899
738.654	0.661987
744.649	0.228516
750.639	2.25781
756.624	5.37988
762.604	8.66199
768.58	11.1637
774.551	15.1472
780.517	18.5371
786.479	19.0768
792.435	18.5071
798.386	17.601
804.333	17.0865
810.276	16.1355
816.214	14.9335
822.147	14.7147
828.074	16.6442
833.998	20.0408
839.917	23.3385
845.83	25.5612
851.74	25.4709
857.645	24.4071
863.544	23.4205
869.439	23.1993
875.329	22.9299
881.215	22.2837
887.097	21.5768
892.973	21.1898
898.846	21.6334
904.712	23.9788
910.574	28.0536
916.433	33.9613
922.285	44.2437
928.135	59.8243
933.978	61.006
939.817	88.8691
945.653	163.623
951.483	379.518
957.308	1017.42
963.129	5879.02
968.946	1962.52
974.757	253.187
980.564	113.076
986.367	56.0123
992.165	18.8033
997.958	-0.0966797
1003.75	-0.365601
1009.53	12.4932
1015.31	30.7173
1021.09	57.207
1026.86	102.233
1032.62	139.221
1038.39	230.342
1044.14	462.226
1049.89	691.969
1055.64	281.293
1061.39	109.838
1067.13	54.3937
1072.86	129.938
1078.59	375.988
1084.32	111.635
1090.04	51.8042
1095.75	22.1984
1101.47	3.08472
1107.17	1.06775
1112.88	7.04834
1118.58	13.0468
1124.27	17.115
1129.96	19.2516
1135.65	20.2798
1141.33	20.4961
1147	20.8936
1152.68	20.8929
1158.34	20.4802
1164.01	19.2944
1169.67	16.5131
1175.32	8.98267
1180.97	9.25269
1186.62	8.42444
1192.26	7.03259
1197.89	6.12512
1203.53	5.3772
1209.16	7.42505
1214.78	16.8309
1220.4	18.7026
1226.01	17.3969
1231.62	15.8326
1237.23	14.7094
1242.83	12.8173
1248.43	9.54089
1254.02	4.53357
1259.61	0.762207
1265.2	2.37805
1270.78	5.56152
1276.35	8.50256
1281.93	10.548
1287.49	12.2339
1293.06	13.6753
1298.62	14.6254
1304.17	13.0918
1309.72	9.89929
1315.27	7.0791
1320.81	4.90271
1326.35	3.41284
1331.88	2.47717
1337.41	2.29578
1342.93	2.86377
1348.45	4.26758
1353.97	6.48486
1359.48	9.72253
1364.99	13.6536
1370.49	18.5247
1375.99	21.6359
1381.49	22.5406
1386.98	20.2875
1392.47	17.1553
1397.95	14.2012
1403.43	12.0361
1408.9	11.1188
1414.37	11.1262
1419.84	12.6204
1425.3	15.5496
1430.76	19.4406
1436.21	22.1204
1441.66	22.308
1447.1	21.5267
1452.54	20.375
1457.98	18.5947
1463.41	16.4515
1468.84	11.9315
1474.27	10.6027
1479.69	11.2439
1485.1	12.9675
1490.51	15.6384
1495.92	18.9708
1501.32	24.3303
1506.72	30.8082
1512.12	33.7845
1517.51	34.7456
1522.9	34.1681
1528.28	37.7977
1533.66	39.3429
1539.03	38.8635
1544.4	37.2395
1549.77	34.806
1555.13	31.5557
1560.49	29.2074
1565.85	25.7661
1571.2	22.0878
1576.54	26.3311
1581.89	31.009
1587.22	34.1487
1592.56	37.5697
1597.89	43.2961
1603.21	45.7905
1608.54	44.0581
1613.86	39.6088
1619.17	35.4534
1624.48	32.1361
1629.79	29.6135
1635.09	28.7919
1640.39	28.563
1645.68	27.8672
1650.97	26.8103
1656.26	25.4711
1661.54	23.4988
1666.82	22.6987
1672.09	22.6593
1677.36	22.8169
1682.63	23.1431
1687.89	23.5519
1693.15	23.5797
1698.4	22.8046
1703.65	20.9752
1708.9	18.8745
1714.14	21.4779
1719.38	22.3602
1724.62	23.515
1729.85	24.5476
1735.08	25.6763
1740.3	31.5037
1745.52	32.9923
1750.73	26.4181
1755.94	18.0334
1761.15	7.34644
1766.35	0.427368
1771.55	-0.944336
1776.75	2.83899
1781.94	10.7297
1787.13	18.6147
1792.31	26.5221
1797.5	34.387
1802.67	37.146
1807.84	37.172
1813.01	36.881
1818.18	36.1726
1823.34	32.368
1828.5	28.5419
1833.65	26.1384
1838.8	25.2195
1843.94	25.5474
1849.09	26.5527
1854.23	28.5444
1859.36	31.3917
1864.49	32.6896
1869.62	30.1204
1874.74	26.0642
1879.86	22.3569
1884.97	18.8943
1890.09	17.8617
1895.19	19.9589
1900.3	22.3143
1905.4	25.4447
1910.49	28.459
1915.59	30.3979
1920.67	30.4567
1925.76	29.3551
1930.84	25.1307
1935.92	20.4475
1940.99	17.6134
1946.06	16.4926
1951.13	16.8336
1956.19	18.317
1961.25	19.951
1966.31	20.9974
1971.36	22.1563
1976.4	24.9705
1981.45	27.1166
1986.49	22.9414
1991.53	21.2205
1996.56	20.1704
2001.59	19.8927
2006.61	20.5573
2011.64	19.8256
2016.65	18.2405
2021.67	16.6357
2026.68	15.6063
2031.69	15.0879
2036.69	15.3783
2041.69	16.4763
2046.69	18.5751
2051.68	21.556
2056.67	25.9861
2061.65	28.8669
2066.63	30.3767
2071.61	31.8782
2076.59	30.5831
2081.56	28.4026
2086.52	25.7434
2091.49	21.8557
2096.45	17.4525
2101.4	16.6035
2106.36	15.5899
2111.3	15.8489
2116.25	19.9922
2121.19	24.7292
2126.13	27.248
2131.06	28.0813
2135.99	24.5464
2140.92	20.0883
2145.85	17.3195
2150.77	16.2043
2155.68	16.587
2160.59	18.2484
2165.5	20.902
2170.41	19.3842
2175.31	20.0109
2180.21	26.3484
2185.11	33.8716
2190	38.2665
2194.89	40.3132
2199.77	38.8817
2204.65	35.4531
2209.53	31.7733
2214.4	29.2593
2219.28	30.0462
2224.14	30.6832
2229.01	30.5297
2233.86	30.1077
2238.72	29.6392
2243.57	28.3412
2248.42	24.8339
2253.27	20.3354
2258.11	19.0955
2262.95	19.073
2267.79	19.8304
2272.62	22.3965
2277.45	24.3276
2282.27	25.084
2287.09	24.9888
2291.91	24.1772
2296.73	22.3478
2301.54	19.5104
2306.35	16.1115
2311.15	14.0114
2315.95	14.1718
2320.75	15.5943
2325.54	18.1101
2330.33	21.2903
2335.12	23.8991
2339.9	24.1998
2344.68	22.0128
2349.46	17.7572
2354.23	12.868
2359	10.9728
2363.77	7.93127
2368.53	4.51843
2373.29	3.94141
2378.05	3.42664
2382.8	2.63904
2387.55	3.40942
2392.3	6.62579
2397.04	10.0721
2401.78	12.59
2406.51	14.5065
2411.25	13.9113
2415.98	12.8671
2420.7	14.0307
2425.42	15.347
2430.14	18.0414
2434.86	23.037
2439.57	26.5997
2444.28	25.4095
2448.99	24.4901
2453.69	20.923
2458.39	18.7717
2463.08	17.6942
2467.77	16.9325
2472.46	16.0176
2477.15	14.9714
2481.83	12.0253
2486.51	9.91785
2491.19	8.94543
2495.86	8.94305
2500.53	9.73718
2505.19	11.2515
2509.86	13.9965
2514.52	16.9703
2519.17	18.1688
2523.82	18.6667
2528.47	19.4525
2533.12	19.9697
2537.76	18.3046
2542.4	16.0425
2547.04	14.2668
2551.67	12.0687
2556.3	8.66919
2560.93	4.18463
2565.55	0.91925
2570.17	-0.435913
2574.79	0.21051
2579.4	2.91833
2584.01	8.19836
2588.62	13.7625
2593.22	17.8382
2597.82	20.9166
2602.42	22.3206
2607.01	23.5767
2611.6	21.7626
2616.19	17.5372
2620.77	12.6028
2625.35	9.40784
2629.93	8.55524
2634.51	10.4245
2639.08	13.177
2643.65	14.843
2648.21	16.5918
2652.77	17.287
2657.33	14.6915
2661.89	13.7022
2666.44	14.7045
2670.99	17.3445
2675.53	19.3035
2680.08	20.3871
2684.62	20.5693
2689.15	20.1169
2693.69	19.1014
2698.22	17.6735
2702.74	15.8921
2707.27	13.9838
2711.79	11.9201
2716.3	9.54321
2720.82	6.64569
2725.33	6.50861
2729.84	9.86658
2734.34	12.5815
2738.84	13.6266
2743.34	13.4124
2747.84	12.7006
2752.33	12.492
2756.82	11.719
2761.31	12.065
2765.79	13.2326
2770.27	14.8884
2774.75	14.2623
2779.22	12.4553
2783.69	10.737
2788.16	9.20319
2792.62	7.54144
2797.08	5.41656
2801.54	5.00665
2806	8.48254
2810.45	9.83636
2814.9	11.8569
2819.34	12.2312
2823.79	11.4672
2828.23	10.441
2832.66	8.36871
2837.09	5.62164
2841.53	3.61188
2845.95	4.48181
2850.38	5.36255
2854.8	7.06549
2859.22	9.07605
2863.63	10.8391
2868.04	15.2326
2872.45	15.6512
2876.86	13.8589
2881.26	12.4509
2885.66	12.0084
2890.06	11.2195
2894.45	12.6889
2898.85	13.062
2903.23	12.2885
2907.62	11.5484
2912	10.9486
2916.38	10.5178
2920.75	10.4265
2925.13	10.8618
2929.5	11.5535
2933.86	12.4629
2938.23	13.4896
2942.59	14.3744
2946.95	13.5354
2951.3	12.0677
2955.65	10.6219
2960	8.32172
2964.35	7.94794
2968.69	11.048
2973.03	13.2411
2977.37	13.7269
2981.7	12.3772
2986.03	9.29984
2990.36	3.86249
2994.69	0.329742
2999.01	-0.141937
3003.33	2.289
3007.65	7.28992
3011.96	14.5022
3016.27	21.0179
3020.58	24.3063
3024.88	24.4899
3029.19	22.1881
3033.48	18.1301
3037.78	14.1807
3042.07	11.1882
3046.36	10.1705
3050.65	9.74542
3054.93	11.2391
3059.22	11.1479
3063.49	9.00327
3067.77	7.08636
3072.04	7.4404
3076.31	8.32101
3080.58	8.29337
3084.84	6.82529
3089.1	7.11877
3093.36	9.23624
3097.62	12.8254
3101.87	15.3333
3106.12	17.7239
3110.37	25.1884
3114.61	22.6249
3118.85	18.2017
3123.09	12.4373
3127.33	8.20297
3131.56	9.81845
3135.79	16.5031
3140.01	18.93
3144.24	18.7885
3148.46	17.3989
3152.68	13.7993
3156.89	12.502
3161.1	11.8314
3165.31	12.2966
3169.52	14.3281
3173.72	17.7027
3177.93	20.1115
3182.12	18.6459
3186.32	16.3009
3190.51	14.9028
3194.7	14.1083
3198.89	13.2783
3203.07	12.8189
3207.25	12.6665
3211.43	12.7815
3215.61	13.1143
3219.78	13.4715
3223.95	12.9652
3228.12	11.3171
3232.28	10.5402
3236.45	10.7136
3240.6	11.255
3244.76	9.72388
3248.91	7.06012
3253.07	6.06436
3257.21	7.48541
3261.36	7.55508
3265.5	6.37338
3269.64	5.82068
3273.78	7.04074
3277.91	8.35327
3282.04	7.73578
3286.17	7.87238
3290.3	8.89908
3294.42	11.1301
3298.54	13.1254
3302.66	13.1283
3306.77	13.0471
3310.89	13.8062
3314.99	15.1987
3319.1	16.4749
3323.21	18.15
3327.31	20.0461
3331.4	19.5734
3335.5	17.2568
3339.59	12.8243
3343.68	7.94614
3347.77	4.55746
3351.86	3.75705
3355.94	4.2381
3360.02	5.50403
3364.09	7.60593
3368.17	9.61612
3372.24	10.1928
3376.31	8.94833
3380.37	5.66751
3384.44	0.555298
3388.5	-1.09531
3392.56	-0.189606
3396.61	2.87604
3400.66	6.31339
3404.71	7.85236
3408.76	7.56485
3412.81	6.71643
3416.85	6.89502
3420.89	11.9894
3424.92	14.6332
3428.96	14.5577
3432.99	11.8675
3437.02	6.99042
3441.04	0.571686
3445.07	-1.06332
3449.09	1.797
3453.1	2.78543
3457.12	4.18353
3461.13	6.45865
3465.14	8.89352
3469.15	9.33792
3473.15	6.55383
3477.16	6.37241
3481.16	5.80914
3485.15	4.81314
3489.15	4.98157
3493.14	8.80505
3497.13	13.7732
3501.11	17.2241
3505.1	18.9915
3509.08	18.8437
3513.06	16.6353
3517.03	12.3262
3521.01	7.21356
3524.98	3.81561
3528.95	4.57718
3532.91	7.68692
3536.87	11.6971
3540.84	15.953
3544.79	20.317
3548.75	21.0897
3552.7	16.8116
3556.65	20.9297
3560.6	25.6083
3564.54	48.349
3568.49	102.674
3572.43	170.992
3576.36	83.8801
3580.3	52.8671
3584.23	39.0032
3588.16	22.045
3592.09	12.7527
3596.01	6.36554
3599.93	4.2919
3603.85	4.70612
3607.77	6.27844
3611.68	8.25717
3615.59	8.58395
3619.5	2.85272
3623.41	3.18362
3627.31	5.0018
3631.21	7.57037
3635.11	10.5653
3639.01	12.6267
3642.9	13.0228
3646.8	12.023
3650.68	9.40131
3654.57	6.03995
3658.45	3.78845
3662.34	2.90506
3666.22	3.1424
3670.09	4.00626
3673.97	4.26419
3677.84	3.03488
3681.7	1.46466
3685.57	0.887466
3689.44	2.12718
3693.3	2.49228
3697.16	1.72835
3701.01	1.31607
3704.87	0.726196
3708.72	-0.355026
3712.57	4.30035
3716.41	5.57347
3720.26	6.48953
3724.1	6.90105
3727.94	6.95461
3731.77	6.90665
3735.61	9.526
3739.44	7.53108
3743.27	5.83809
3747.09	5.13684
3750.92	5.13588
3754.74	6.0938
3758.56	6.06741
3762.38	5.39934
3766.19	4.77022
3770	5.81999
3773.81	6.05589
3777.62	6.14423
3781.42	7.28932
3785.23	7.94537
3789.03	7.79814
3792.82	5.58733
3796.62	2.82614
3800.41	1.59653
3804.2	2.51643
3807.99	4.69725
3811.77	5.92735
3815.56	6.56409
3819.34	6.27522
3823.11	5.01282
3826.89	2.71613
3830.66	0.109161
3834.43	0.0130768
3838.2	2.34247
3841.97	3.46548
3845.73	4.24504
3849.49	4.1226
3853.25	4.96591
3857.01	2.75592
3860.76	-0.164139
3864.51	-0.573059
3868.26	-0.674301
3872.01	-0.882767
3875.75	-1.3149
3879.49	-1.15024
3883.23	1.32135
3886.97	0.921494
3890.71	0.444443
3894.44	0.646484
3898.17	1.69498
3901.9	0.890594
3905.62	0.0863037
3909.35	-0.355591
3913.07	-0.0579529
3916.78	0.694168
3920.5	1.81569
3924.21	3.13351
3927.93	4.52574
3931.63	5.54739
3935.34	4.47739
3939.04	2.36049
3942.75	1.40387
3946.45	1.89041
3950.14	2.29756
3953.84	1.98737
3957.53	2.86363
3961.22	3.82948
3964.91	3.50093
3968.59	2.00128
3972.28	0.345886
3975.96	-0.643402
3979.64	-0.250656
3983.31	0.43692
3986.99	0.566711
3990.66	-0.00694275
3994.33	0.458176
3997.99	3.05466
3999.83	7.94193