File: Data/Raman/processed/augelite_150 (500nm)_633nm_edge_100%_x50_vis_lwd_h30um_30sx2_01.txt
#Acq. time (s)=	30
#Accumulations=	2
#Range (cm-¹)=	100...4000
#Windows=	1
#Auto scanning=	Off
#Autofocus=	Off
#Macrospot=	Off
#AutoExposure=	Off
#Spike filter=	Multiple accum.
#Delay time (s)=	2
#Binning=	1
#Readout mode=	Signal
#DeNoise=	Standard
#ICS correction=	On
#Dark correction=	Off
#Inst. Process=	Off
#Detector Gain=	Best Dynamic
#Detector ADC=	50 kHz HS
#Detector temperature (°C)=	-60.09
#Instrument=	LabRAM HR Evol
#Detector=	SIN-EM FIVIS
#Objective=	x50_VIS_LWD
#Grating=	150 (500nm)
#ND Filter=	100%
#Laser=	633nm_Edge
#Hole=	30.0125
#Temperature=	0
#Range=	Visible
#StageXY=	75x50mm Scan+
#StageZ=	Z motor
#X (µm)=	0
#Y (µm)=	0
#Z (µm)=	58.4
#Full time(mm:ss)=	1:04
#Project=	21_02_17
#Sample=	BU19w
#Site=
#Title=	BU19w-Area11-augelite_overBrt_150 (500nm)_633nm_Edge_100%_x50_VIS_LWD_H30um_30sX2
#Remark=
#Date=	17.02.2021 10:31
#Acquired=	17.02.2021 10:31:38
#Data Range:Extract=	01.07.2021 19:23:36
#Base:Fit=	01.07.2021 19:24:15
#Base:Fit=	01.07.2021 19:24:39
#Base:Fit=	01.07.2021 19:24:47
#Base:Sub=	01.07.2021 19:24:50
100.724	-0.858856
107.24	4.54958
113.751	0.741791
120.256	20.0056
126.756	122.728
133.251	171.29
139.74	79.9872
146.224	72.3848
152.702	136.304
159.175	358.97
165.643	737.469
172.105	644.566
178.561	276.286
185.013	134.761
191.459	77.7668
197.9	47.051
204.336	34.7886
210.765	32.9573
217.19	56.6592
223.61	124.68
230.024	317.634
236.432	93.0673
242.836	51.9974
249.233	139.445
255.627	422.137
262.015	126.495
268.397	25.3008
274.774	4.52057
281.145	-0.0660553
287.513	2.68375
293.873	7.05991
300.23	7.50793
306.58	6.03618
312.927	3.67804
319.266	2.30037
325.602	3.13531
331.932	11.6046
338.256	21.1185
344.577	36.3477
350.89	71.4904
357.199	89.883
363.504	94.8417
369.803	208.259
376.096	189.229
382.384	77.6627
388.669	34.7599
394.947	26.0457
401.219	38.6889
407.487	81.3061
413.75	127.407
420.007	152.695
426.261	128.348
432.508	97.7013
438.751	95.0398
444.988	115.331
451.22	139.752
457.447	157.902
463.669	158.219
469.886	184.107
476.098	126.974
482.303	75.7937
488.505	50.5485
494.702	39.7775
500.894	42.4148
507.081	62.4288
513.263	99.9033
519.44	164.864
525.61	234.034
531.777	279.943
537.939	249.397
544.096	217.3
550.246	212.422
556.393	238.079
562.535	265.446
568.671	278.316
574.803	245.09
580.929	199.978
587.051	143.354
593.167	90.2664
599.28	63.8355
605.387	71.0767
611.489	99.4674
617.585	142.734
623.678	186.595
629.764	326.452
635.847	710.41
641.924	837.944
647.998	363.434
654.065	148.088
660.127	91.4926
666.184	61.6642
672.238	40.2323
678.286	23.5558
684.329	11.1931
690.367	5.27228
696.401	3.79251
702.43	5.3622
708.453	8.0002
714.472	11.6215
720.486	14.9311
726.495	16.8401
732.5	16.8985
738.501	15.6767
744.495	14.5246
750.485	10.7385
756.471	6.79286
762.451	2.09299
768.426	-1.063
774.397	0.352066
780.363	3.3421
786.325	5.33536
792.281	9.18709
798.234	10.1981
804.181	9.03084
810.124	6.64046
816.06	4.77306
821.993	4.14412
827.922	6.44063
833.846	12.8884
839.764	22.4068
845.678	38.9477
851.588	58.9023
857.492	78.3564
863.392	87.0928
869.287	74.3392
875.178	51.9901
881.063	45.5425
886.945	42.5352
892.822	45.9361
898.694	51.6113
904.56	48.0647
910.424	34.393
916.281	18.0306
922.135	6.67203
927.984	8.07506
933.827	10.7707
939.668	12.1218
945.502	10.5558
951.332	10.9025
957.159	8.78024
962.979	9.40573
968.796	9.62422
974.607	10.5516
980.414	12.7071
986.218	15.2282
992.016	13.6018
997.809	19.4043
1003.6	30.1325
1009.38	49.2103
1015.16	60.5624
1020.94	66.2586
1026.71	54.6101
1032.48	45.9939
1038.24	40.0912
1043.99	35.8989
1049.75	48.0224
1055.5	54.4823
1061.24	70.3928
1066.98	85.541
1072.71	78.1296
1078.44	68.1336
1084.17	73.3317
1089.89	92.1868
1095.61	128.332
1101.32	201.991
1107.03	344.211
1112.73	505.981
1118.43	401.574
1124.12	208.941
1129.81	127.329
1135.5	90.2449
1141.18	77.471
1146.86	77.3736
1152.53	93.7766
1158.2	118.145
1163.86	132.37
1169.52	116.221
1175.17	86.1422
1180.83	54.9568
1186.47	35.4034
1192.11	28.1373
1197.75	23.988
1203.38	18.3517
1209.01	15.2406
1214.63	15.1264
1220.25	14.3893
1225.87	12.515
1231.48	11.3634
1237.09	10.7649
1242.69	9.70154
1248.29	8.6003
1253.88	8.41125
1259.47	7.56946
1265.05	6.26273
1270.63	4.19765
1276.21	2.62128
1281.78	3.27739
1287.35	5.42648
1292.91	7.0629
1298.47	7.58691
1304.03	7.4108
1309.58	6.52594
1315.13	5.03134
1320.67	2.95508
1326.2	0.366791
1331.74	0.450211
1337.27	0.966675
1342.79	1.45772
1348.31	1.76248
1353.83	1.91487
1359.34	2.00536
1364.85	1.92239
1370.35	1.6144
1375.85	1.12933
1381.35	0.569122
1386.84	0.264694
1392.32	0.510986
1397.81	-0.536484
1403.29	-0.240646
1408.76	0.551758
1414.23	1.8698
1419.7	0.785904
1425.16	1.08263
1430.61	1.34644
1436.07	0.927139
1441.52	-0.385345
1446.96	-2.02831
1452.4	-1.48448
1457.84	0.526184
1463.27	1.14314
1468.7	0.98468
1474.12	1.84543
1479.55	3.3304
1484.96	4.76326
1490.37	6.11775
1495.78	6.45654
1501.18	6.36081
1506.58	5.28351
1511.98	3.80128
1517.37	2.74802
1522.76	2.35989
1528.14	2.27927
1533.52	2.117
1538.9	1.87263
1544.27	1.29219
1549.63	0.373169
1555	-0.0661163
1560.35	-0.157883
1565.71	0.78949
1571.06	1.9335
1576.41	2.99759
1581.75	4.00673
1587.09	4.70424
1592.42	5.28429
1597.75	5.82655
1603.08	6.27357
1608.4	6.63084
1613.72	6.91512
1619.03	7.15118
1624.34	7.44252
1629.65	7.48108
1634.95	7.407
1640.25	7.24547
1645.54	6.99843
1650.83	6.68391
1656.12	6.32867
1661.4	5.93883
1666.68	5.5865
1671.96	5.2019
1677.23	4.82655
1682.49	4.48352
1687.75	4.22885
1693.01	3.95557
1698.27	3.6705
1703.52	3.36366
1708.77	3.10541
1714.01	2.95811
1719.25	2.57697
1724.48	3.26135
1729.71	4.69662
1734.94	6.10954
1740.16	6.78954
1745.38	7.1181
1750.6	7.23407
1755.81	7.12099
1761.02	6.91147
1766.22	6.77107
1771.42	6.59695
1776.62	6.65044
1781.81	6.53268
1787	6.25902
1792.18	5.63293
1797.36	4.92012
1802.54	4.12535
1807.71	3.29878
1812.88	2.57617
1818.05	2.22144
1823.21	3.30231
1828.36	5.15663
1833.52	6.02591
1838.67	6.36658
1843.81	6.53894
1848.95	6.29738
1854.09	5.213
1859.23	4.68355
1864.36	4.66147
1869.48	5.51343
1874.61	7.18512
1879.73	7.10336
1884.84	6.37553
1889.95	5.61353
1895.06	5.22128
1900.17	5.07404
1905.27	5.28906
1910.36	6.04019
1915.45	7.70386
1920.54	8.78487
1925.63	8.32884
1930.71	6.79057
1935.79	5.20934
1940.86	3.90591
1945.93	2.80594
1951	3.83203
1956.06	-1.70871
1961.12	8.18671
1966.18	9.28903
1971.23	9.25014
1976.28	9.07677
1981.32	8.89813
1986.36	8.72685
1991.4	8.80234
1996.43	9.12621
2001.46	9.52496
2006.48	9.97244
2011.51	10.4099
2016.52	10.8026
2021.54	11.1163
2026.55	11.3358
2031.56	11.1994
2036.56	10.9193
2041.56	10.4049
2046.56	10.6706
2051.55	9.91478
2056.54	7.98466
2061.52	4.60155
2066.51	3.05074
2071.48	2.16376
2076.46	1.81483
2081.43	2.66508
2086.4	5.26421
2091.36	7.50932
2096.32	7.79135
2101.28	6.03339
2106.23	4.92163
2111.18	3.65723
2116.12	2.26674
2121.06	0.396423
2126	-0.033371
2130.94	1.67316
2135.87	2.8569
2140.79	3.74178
2145.72	4.27821
2150.64	4.61211
2155.56	4.70291
2160.47	4.68292
2165.38	4.49066
2170.28	4.27234
2175.19	4.07567
2180.09	3.98804
2184.98	3.83563
2189.87	4.16162
2194.76	4.86555
2199.65	5.73262
2204.53	6.44278
2209.4	7.09296
2214.28	6.56047
2219.15	5.67236
2224.02	4.62479
2228.88	4.53979
2233.74	4.69025
2238.6	4.89543
2243.45	4.9969
2248.3	4.76614
2253.14	4.40778
2257.99	4.15697
2262.83	3.19795
2267.66	2.13127
2272.49	1.10594
2277.32	0.651428
2282.15	0.811844
2286.97	1.35072
2291.79	2.14337
2296.6	3.37381
2301.41	4.91881
2306.22	6.51456
2311.02	7.8517
2315.83	8.79138
2320.62	9.24919
2325.42	9.32786
2330.21	9.01772
2335	8.39407
2339.78	7.59669
2344.56	6.68217
2349.34	5.81485
2354.11	4.76618
2358.88	3.56802
2363.65	2.38629
2368.41	1.3503
2373.17	0.553001
2377.93	0.346771
2382.68	0.783684
2387.43	2.51925
2392.17	4.76817
2396.92	5.47189
2401.66	4.65478
2406.39	3.76733
2411.13	3.39326
2415.85	3.43224
2420.58	3.85521
2425.3	4.57677
2430.02	5.86388
2434.74	7.31876
2439.45	8.78582
2444.16	9.18503
2448.86	8.90472
2453.57	8.67805
2458.27	8.61267
2462.96	7.82668
2467.65	6.28787
2472.34	4.91037
2477.03	4.04586
2481.71	3.70396
2486.39	4.37733
2491.07	5.17986
2495.74	5.95361
2500.41	6.54616
2505.07	6.25006
2509.74	5.41588
2514.4	3.82587
2519.05	2.16741
2523.7	0.739128
2528.35	0.49173
2533	0.718742
2537.64	1.35564
2542.28	2.67152
2546.92	4.46318
2551.55	6.30454
2556.18	7.91384
2560.81	8.96497
2565.43	9.18286
2570.05	8.64294
2574.67	7.27119
2579.28	5.82001
2583.89	4.38212
2588.5	3.48397
2593.1	2.73861
2597.7	2.24713
2602.3	2.08588
2606.89	2.26752
2611.48	2.66338
2616.07	3.33941
2620.66	4.24546
2625.24	5.52823
2629.82	6.86035
2634.39	8.13839
2638.96	8.87024
2643.53	8.72569
2648.09	7.75922
2652.66	6.07688
2657.21	4.29806
2661.77	3.66123
2666.32	4.36465
2670.87	4.5837
2675.42	4.31306
2679.96	4.34199
2684.5	4.61156
2689.04	4.92037
2693.57	5.15636
2698.1	5.34747
2702.63	5.55087
2707.15	6.07594
2711.67	6.33706
2716.19	4.91711
2720.7	6.12333
2725.21	8.66925
2729.72	11.2094
2734.23	9.54131
2738.73	2.49348
2743.23	0.602524
2747.72	5.23702
2752.22	6.7589
2756.7	6.60387
2761.19	4.88212
2765.67	4.80325
2770.15	4.86311
2774.63	5.03961
2779.1	5.2611
2783.57	5.56998
2788.04	5.88203
2792.51	6.15559
2796.97	6.39202
2801.43	6.48988
2805.88	6.36031
2810.33	5.885
2814.78	4.84377
2819.23	3.45631
2823.67	0.760139
2828.11	-1.00711
2832.55	-2.66225
2836.98	-1.73878
2841.41	0.100273
2845.84	2.23508
2850.26	5.9275
2854.69	6.03407
2859.1	3.63186
2863.52	3.74715
2867.93	3.21058
2872.34	2.64296
2876.75	2.32758
2881.15	2.52726
2885.55	2.827
2889.95	3.22421
2894.34	3.88979
2898.73	4.63448
2903.12	5.46155
2907.5	5.83578
2911.89	5.44127
2916.27	4.70676
2920.64	4.05515
2925.01	3.69994
2929.38	3.26508
2933.75	2.92612
2938.12	2.74129
2942.48	2.69637
2946.84	2.82262
2951.19	3.13206
2955.54	3.60434
2959.89	4.32164
2964.24	5.17915
2968.58	5.86525
2972.92	5.43642
2977.26	4.66753
2981.59	3.47161
2985.92	2.16382
2990.25	1.42538
2994.58	0.734505
2998.9	-0.0646057
3003.22	1.59958
3007.54	2.40907
3011.85	1.56607
3016.16	-0.184875
3020.47	-0.194977
3024.77	0.12941
3029.07	0.515961
3033.37	0.778122
3037.67	0.860977
3041.96	0.784088
3046.25	0.568031
3050.54	0.295677
3054.82	-0.00188446
3059.11	-0.18763
3063.38	-0.190193
3067.66	0.170578
3071.93	1.10121
3076.2	4.20796
3080.47	7.01864
3084.73	7.77763
3088.99	6.38473
3093.25	4.57404
3097.51	3.575
3101.76	3.4684
3106.01	3.47254
3110.26	3.53375
3114.5	3.68605
3118.74	3.60943
3122.98	3.29771
3127.22	2.77402
3131.45	2.13528
3135.68	1.56033
3139.91	1.53532
3144.13	2.11948
3148.35	2.79327
3152.57	3.36144
3156.78	3.4803
3161	3.4509
3165.21	3.45571
3169.41	3.54102
3173.62	3.7817
3177.82	4.06856
3182.02	5.24237
3186.21	6.5564
3190.4	7.17139
3194.59	6.5572
3198.78	6.5883
3202.96	5.34074
3207.15	3.68048
3211.33	1.94352
3215.5	0.599892
3219.67	-1.26763
3223.84	0.92366
3228.01	4.0135
3232.18	6.88987
3236.34	8.65986
3240.5	8.69707
3244.65	5.92935
3248.81	3.86005
3252.96	2.76004
3257.11	2.59842
3261.25	2.87313
3265.39	3.12544
3269.53	3.45134
3273.67	3.88327
3277.8	4.33625
3281.94	4.72913
3286.06	4.96986
3290.19	5.76707
3294.31	7.02051
3298.43	8.70586
3302.55	10.2402
3306.67	11.8377
3310.78	13.1321
3314.89	14.2427
3319	15.2211
3323.1	16.03
3327.2	16.7019
3331.3	17.3254
3335.39	17.7948
3339.49	18.1743
3343.58	18.5236
3347.67	18.9567
3351.75	19.3275
3355.83	19.756
3359.91	20.2597
3363.99	21.8568
3368.06	26.4601
3372.14	29.5511
3376.2	32.2855
3380.27	35.0464
3384.33	38.0364
3388.39	41.4576
3392.45	44.9054
3396.51	45.4743
3400.56	50.3165
3404.61	57.9689
3408.66	60.4084
3412.7	63.1323
3416.74	67.1565
3420.78	72.8365
3424.82	80.3171
3428.85	89.3599
3432.88	100.043
3436.91	112.247
3440.94	127.318
3444.96	144.352
3448.98	157.927
3453	173.021
3457.02	192.33
3461.03	222.075
3465.04	297.71
3469.05	417.534
3473.05	423.385
3477.05	354.179
3481.05	277.628
3485.05	229.067
3489.04	202.557
3493.04	188.176
3497.03	181.362
3501.01	174.911
3505	172.559
3508.98	172.091
3512.96	174.305
3516.93	178.62
3520.9	184.593
3524.88	189.784
3528.84	202.193
3532.81	226.096
3536.77	250.93
3540.73	271.773
3544.69	282.906
3548.65	291.044
3552.6	277.162
3556.55	252.447
3560.5	219.962
3564.44	183.126
3568.38	145.953
3572.32	113.894
3576.26	88.7197
3580.2	73.7625
3584.13	62.9105
3588.06	54.2144
3591.98	47.7528
3595.91	43.1988
3599.83	39.482
3603.75	35.5733
3607.67	31.6392
3611.58	27.4217
3615.49	25.2891
3619.4	24.6988
3623.31	25.4818
3627.21	26.2347
3631.11	23.5591
3635.01	21.3718
3638.91	20.0469
3642.8	18.4958
3646.69	17.5873
3650.58	16.8028
3654.47	16.01
3658.35	15.2507
3662.24	14.221
3666.11	12.3045
3669.99	10.1284
3673.86	8.01691
3677.74	6.12604
3681.6	5.25873
3685.47	5.22575
3689.34	5.86721
3693.2	7.36357
3697.06	9.44598
3700.91	9.01188
3704.77	9.46526
3708.62	8.8613
3712.47	6.16219
3716.31	3.33262
3720.16	2.02171
3724	1.53453
3727.84	1.88921
3731.67	3.9371
3735.51	6.07443
3739.34	6.28889
3743.17	5.23499
3747	5.89477
3750.82	6.88024
3754.64	6.97944
3758.46	6.10049
3762.28	5.3178
3766.09	4.75783
3769.9	4.50677
3773.71	4.50771
3777.52	4.84933
3781.33	5.27644
3785.13	5.78605
3788.93	6.41586
3792.72	7.19081
3796.52	7.78651
3800.31	7.62848
3804.1	5.92741
3807.89	4.04084
3811.68	1.95895
3815.46	0.501846
3819.24	-0.452698
3823.02	-0.481506
3826.79	0.810898
3830.56	2.36668
3834.34	3.93577
3838.1	4.86131
3841.87	5.56389
3845.63	6.59492
3849.39	7.50365
3853.15	8.0638
3856.91	8.22665
3860.66	7.5789
3864.42	6.29297
3868.16	4.32693
3871.91	2.51777
3875.66	2.23946
3879.4	3.15895
3883.14	4.99512
3886.88	6.40805
3890.61	5.10059
3894.34	4.56026
3898.07	4.41963
3901.8	4.93517
3905.53	6.36468
3909.25	5.0172
3912.97	4.24332
3916.69	3.56536
3920.4	3.39269
3924.12	5.102
3927.83	4.30868
3931.54	2.79185
3935.24	1.85454
3938.95	1.55772
3942.65	1.93979
3946.35	2.86964
3950.05	4.50098
3953.74	6.39758
3957.44	8.02567
3961.13	7.64362
3964.81	6.83192
3968.5	6.02223
3972.18	5.22264
3975.86	4.43376
3979.54	3.70441
3983.22	3.05645
3986.89	2.44269
3990.56	1.80698
3994.23	1.08544
3997.9	0.0093689
3999.73	-0.492111