File: Data/Raman/processed/bertossaite_150 (500nm)_633nm_edge_100%_x50_vis_lwd_h30um_30sx2_01.txt
#Acq. time (s)=	30
#Accumulations=	2
#Range (cm-¹)=	100...4000
#Windows=	1
#Auto scanning=	Off
#Autofocus=	Off
#Macrospot=	Off
#AutoExposure=	Off
#Spike filter=	Multiple accum.
#Delay time (s)=	2
#Binning=	1
#Readout mode=	Signal
#DeNoise=	Standard
#ICS correction=	On
#Dark correction=	Off
#Inst. Process=	Off
#Detector Gain=	Best Dynamic
#Detector ADC=	50 kHz HS
#Detector temperature (°C)=	-60.09
#Instrument=	LabRAM HR Evol
#Detector=	SIN-EM FIVIS
#Objective=	x50_VIS_LWD
#Grating=	150 (500nm)
#ND Filter=	100%
#Laser=	633nm_Edge
#Hole=	30.0125
#Temperature=	0
#Range=	Visible
#StageXY=	75x50mm Scan+
#StageZ=	Z motor
#X (µm)=	0
#Y (µm)=	0
#Z (µm)=	58.5
#Full time(mm:ss)=	1:04
#Project=	21_02_17
#Sample=	BU19w
#Site=
#Title=	BU19w-Area11-bertossaite-bottom_150 (500nm)_633nm_Edge_100%_x50_VIS_LWD_H30um_30sX2
#Remark=
#Date=	17.02.2021 10:27
#Acquired=	17.02.2021 10:27:54
#Data Range:Extract=	01.07.2021 19:23:37
#Base:Fit=	01.07.2021 19:24:15
#Base:Fit=	01.07.2021 19:24:39
#Base:Fit=	01.07.2021 19:24:47
#Base:Sub=	01.07.2021 19:24:50
100.724	131.777
107.24	75.0438
113.751	52.4883
120.256	48.3666
126.756	53.1302
133.251	55.5845
139.74	67.3765
146.224	92.2446
152.702	101.834
159.175	85.6809
165.643	110.443
172.105	254.22
178.561	172.31
185.013	41.5443
191.459	11.2148
197.9	6.70334
204.336	8.77451
210.765	5.88278
217.19	1.54523
223.61	4.54385
230.024	25.205
236.432	98.6385
242.836	268.781
249.233	289.601
255.627	142.205
262.015	118.71
268.397	127.006
274.774	124.707
281.145	100.264
287.513	113.622
293.873	156.521
300.23	118.006
306.58	71.7758
312.927	67.6702
319.266	98.1691
325.602	209.411
331.932	495.91
338.256	698.524
344.577	363.253
350.89	163.859
357.199	103.666
363.504	112.216
369.803	142.573
376.096	148.66
382.384	112.539
388.669	55.7149
394.947	45.7112
401.219	47.9971
407.487	51.2433
413.75	57.7505
420.007	69.1905
426.261	99.077
432.508	147.524
438.751	209.976
444.988	263.646
451.22	211.233
457.447	191.923
463.669	235.075
469.886	186.825
476.098	131.753
482.303	92.9931
488.505	81.6292
494.702	76.0288
500.894	78.4141
507.081	95.3148
513.263	126.778
519.44	160.254
525.61	179.884
531.777	170.843
537.939	153.901
544.096	139.571
550.246	126.3
556.393	111.21
562.535	97.6
568.671	82.8374
574.803	67.7763
580.929	55.9488
587.051	51.9774
593.167	54.0009
599.28	64.4319
605.387	78.6027
611.489	95.2101
617.585	116.148
623.678	134.213
629.764	143.362
635.847	135.148
641.924	110.857
647.998	71.1793
654.065	70.2179
660.127	76.8294
666.184	77.5408
672.238	70.0574
678.286	56.9568
684.329	41.5435
690.367	27.0872
696.401	16.2536
702.43	8.70566
708.453	7.95462
714.472	7.3299
720.486	6.91672
726.495	8.01392
732.5	5.25974
738.501	3.16138
744.495	0.0969849
750.485	0.104004
756.471	2.12595
762.451	3.1257
768.426	4.72614
774.397	5.935
780.363	5.36703
786.325	4.07983
792.281	3.41931
798.234	4.1532
804.181	3.81726
810.124	3.57373
816.06	4.02921
821.993	4.86737
827.922	6.07898
833.846	7.70026
839.764	9.44791
845.678	11.8885
851.588	16.0209
857.492	21.619
863.392	28.9176
869.287	37.6977
875.178	45.8141
881.063	52.7479
886.945	54.5753
892.822	52.4457
898.694	50.4911
904.56	45.9089
910.424	42.8848
916.281	41.2327
922.135	44.2193
927.984	52.9321
933.827	69.7544
939.668	90.8345
945.502	127.775
951.332	183.92
957.159	250.642
962.979	299.223
968.796	279.02
974.607	256.017
980.414	267.971
986.218	332.534
992.016	433.419
997.809	581.009
1003.6	463.64
1009.38	366.573
1015.16	337.325
1020.94	357.233
1026.71	424.033
1032.48	527.442
1038.24	420.363
1043.99	285.846
1049.75	202.026
1055.5	161.258
1061.24	138.534
1066.98	124.287
1072.71	102.987
1078.44	95.5309
1084.17	105.044
1089.89	139.577
1095.61	191.049
1101.32	266.426
1107.03	390.562
1112.73	340.055
1118.43	195.813
1124.12	135.431
1129.81	112.446
1135.5	117.023
1141.18	149.526
1146.86	208.079
1152.53	273.65
1158.2	373.98
1163.86	488.305
1169.52	242.303
1175.17	135.105
1180.83	99.1086
1186.47	82.1183
1192.11	62.9899
1197.75	48.59
1203.38	36.0072
1209.01	29.5986
1214.63	25.0439
1220.25	21.4925
1225.87	19.5867
1231.48	16.3241
1237.09	12.9771
1242.69	10.9305
1248.29	9.41492
1253.88	8.71014
1259.47	8.4798
1265.05	8.51987
1270.63	8.60672
1276.21	8.91309
1281.78	9.28439
1287.35	9.6012
1292.91	10.276
1298.47	10.909
1304.03	10.6368
1309.58	10.4427
1315.13	10.4568
1320.67	10.9171
1326.2	11.848
1331.74	10.8306
1337.27	8.1879
1342.79	5.63992
1348.31	3.5159
1353.83	1.67963
1359.34	0.378448
1364.85	1.29004
1370.35	8.90366
1375.85	11.2144
1381.35	9.70703
1386.84	5.53723
1392.32	-0.130402
1397.81	1.87817
1403.29	5.78458
1408.76	9.85693
1414.23	12.675
1419.7	14.3931
1425.16	14.7418
1430.61	14.1665
1436.07	10.9202
1441.52	7.43765
1446.96	4.51483
1452.4	2.20316
1457.84	0.595184
1463.27	-0.127228
1468.7	0.0745239
1474.12	1.71994
1479.55	5.12497
1484.96	7.52423
1490.37	8.54169
1495.78	8.51752
1501.18	7.56079
1506.58	5.71469
1511.98	3.37451
1517.37	2.01056
1522.76	1.93353
1528.14	4.25629
1533.52	7.07913
1538.9	9.07352
1544.27	10.3998
1549.63	10.679
1555	10.3202
1560.35	9.67175
1565.71	8.76584
1571.06	7.96335
1576.41	7.03363
1581.75	8.15518
1587.09	9.39261
1592.42	9.97827
1597.75	9.76544
1603.08	9.371
1608.4	8.99371
1613.72	8.74182
1619.03	8.80261
1624.34	8.98087
1629.65	9.20279
1634.95	9.61636
1640.25	9.79254
1645.54	8.96667
1650.83	7.64755
1656.12	6.22125
1661.4	5.81784
1666.68	6.3887
1671.96	7.53503
1677.23	9.03812
1682.49	9.47485
1687.75	9.36871
1693.01	8.69843
1698.27	7.64114
1703.52	7.12814
1708.77	7.92413
1714.01	8.80435
1719.25	9.77988
1724.48	10.791
1729.71	12.4603
1734.94	14.1837
1740.16	12.8567
1745.38	10.5889
1750.6	7.92975
1755.81	5.47519
1761.02	3.62485
1766.22	3.18271
1771.42	4.46436
1776.62	5.32782
1781.81	8.54016
1787	11.6894
1792.18	14.087
1797.36	14.6029
1802.54	14.1227
1807.71	13.1514
1812.88	9.21347
1818.05	8.53928
1823.21	7.61401
1828.36	8.47772
1833.52	10.9706
1838.67	11.8543
1843.81	11.6075
1848.95	12.2909
1854.09	12.5656
1859.23	12.6075
1864.36	12.4482
1869.48	11.7407
1874.61	11.362
1879.73	13.1664
1884.84	15.4144
1889.95	15.0428
1895.06	13.874
1900.17	12.3599
1905.27	10.7755
1910.36	9.11176
1915.45	7.42438
1920.54	5.88733
1925.63	4.72623
1930.71	4.80951
1935.79	5.24301
1940.86	7.0564
1945.93	9.78922
1951	12.0471
1956.06	13.3253
1961.12	13.9384
1966.18	13.5459
1971.23	12.6679
1976.28	11.4125
1981.32	9.90714
1986.36	8.49417
1991.4	7.01169
1996.43	5.06351
2001.46	3.02173
2006.48	1.0307
2011.51	-0.229065
2016.52	-0.562988
2021.54	1.28088
2026.55	3.33746
2031.56	5.2381
2036.56	6.90817
2041.56	8.19318
2046.56	8.95801
2051.55	9.39365
2056.54	10.2595
2061.52	11.8563
2066.51	12.6486
2071.48	12.7372
2076.46	13.0113
2081.43	12.4481
2086.4	11.5614
2091.36	10.9332
2096.32	10.6057
2101.28	10.4221
2106.23	10.3837
2111.18	10.3427
2116.12	10.4322
2121.06	10.9111
2126	12.3741
2130.94	12.9556
2135.87	11.8787
2140.79	11.6568
2145.72	11.5586
2150.64	11.5578
2155.56	10.9471
2160.47	10.0724
2165.38	9.46185
2170.28	9.17262
2175.19	8.43852
2180.09	7.02542
2184.98	6.24632
2189.87	7.16591
2194.76	8.97171
2199.65	10.6899
2204.53	12.1632
2209.4	13.3037
2214.28	14.0583
2219.15	14.261
2224.02	13.8965
2228.88	13.0802
2233.74	11.8978
2238.6	10.2225
2243.45	8.44006
2248.3	6.63889
2253.14	5.52287
2257.99	4.70459
2262.83	4.27916
2267.66	3.79427
2272.49	3.36673
2277.32	2.86418
2282.15	2.15248
2286.97	1.73512
2291.79	1.73224
2296.6	2.15945
2301.41	3.19464
2306.22	5.09657
2311.02	6.58835
2315.83	6.56947
2320.62	5.46823
2325.42	3.55388
2330.21	3.10843
2335	4.05313
2339.78	5.45201
2344.56	8.08495
2349.34	9.67673
2354.11	9.71255
2358.88	8.1266
2363.65	5.23853
2368.41	1.8212
2373.17	0.124756
2377.93	-0.124298
2382.68	1.26471
2387.43	6.23508
2392.17	10.0776
2396.92	11.5993
2401.66	11.1269
2406.39	8.57071
2411.13	5.78752
2415.85	4.60814
2420.58	4.06116
2425.3	3.89314
2430.02	4.72513
2434.74	6.10777
2439.45	7.22083
2444.16	7.66879
2448.86	6.91907
2453.57	6.29739
2458.27	6.18219
2462.96	5.27159
2467.65	3.57063
2472.34	2.05835
2477.03	1.79713
2481.71	2.47157
2486.39	3.92516
2491.07	5.71153
2495.74	7.08493
2500.41	7.04214
2505.07	10.238
2509.74	11.6483
2514.4	12.3961
2519.05	10.5909
2523.7	9.16176
2528.35	9.1217
2533	8.4438
2537.64	8.32397
2542.28	8.44545
2546.92	7.75845
2551.55	6.81548
2556.18	3.9848
2560.81	2.32277
2565.43	1.26149
2570.05	0.816391
2574.67	0.889603
2579.28	1.23492
2583.89	2.07475
2588.5	3.07176
2593.1	4.13797
2597.7	5.12508
2602.3	5.65646
2606.89	5.58194
2611.48	5.28444
2616.07	4.4977
2620.66	3.34415
2625.24	2.05223
2629.82	1.67078
2634.39	2.3181
2638.96	1.20901
2643.53	0.490677
2648.09	0.666702
2652.66	1.50629
2657.21	2.73041
2661.77	3.57675
2666.32	3.78249
2670.87	2.48528
2675.42	1.27708
2679.96	0.939316
2684.5	0.733673
2689.04	0.549164
2693.57	0.615799
2698.1	1.99356
2702.63	3.04962
2707.15	2.73787
2711.67	0.038681
2716.19	-2.12521
2720.7	-2.64569
2725.21	-1.63213
2729.72	0.320587
2734.23	2.26161
2738.73	4.11469
2743.23	5.14063
2747.72	4.67159
2752.22	3.92656
2756.7	2.92676
2761.19	2.36351
2765.67	2.35422
2770.15	2.6656
2774.63	3.18802
2779.1	3.38335
2783.57	3.38104
2788.04	4.03265
2792.51	5.68877
2796.97	7.19449
2801.43	7.23593
2805.88	8.13358
2810.33	8.76266
2814.78	8.29221
2819.23	6.65022
2823.67	5.03024
2828.11	4.58365
2832.55	4.50212
2836.98	4.62915
2841.41	4.86694
2845.84	5.17485
2850.26	5.37511
2854.69	5.31335
2859.1	5.3391
2863.52	5.12514
2867.93	5.1241
2872.34	3.76279
2876.75	3.37747
2881.15	4.22673
2885.55	5.42531
2889.95	5.25525
2894.34	4.51405
2898.73	4.05562
2903.12	3.67657
2907.5	2.43283
2911.89	2.40775
2916.27	3.50905
2920.64	5.42839
2925.01	6.97684
2929.38	6.70891
2933.75	6.59956
2938.12	6.36765
2942.48	5.92929
2946.84	5.3959
2951.19	4.79912
2955.54	4.06413
2959.89	2.90372
2964.24	1.6609
2968.58	1.10147
2972.92	1.52892
2977.26	2.83038
2981.59	3.45532
2985.92	4.27243
2990.25	6.74698
2994.58	9.12079
2998.9	10.6297
3003.22	10.9258
3007.54	10.5762
3011.85	9.92189
3016.16	9.86369
3020.47	9.89182
3024.77	9.9249
3029.07	10.0827
3033.37	11.7846
3037.67	13.6031
3041.96	14.7534
3046.25	15.3389
3050.54	15.9218
3054.82	17.4197
3059.11	18.1432
3063.38	19.4084
3067.66	21.9406
3071.93	25.4754
3076.2	29.2957
3080.47	32.5344
3084.73	33.7592
3088.99	34.4292
3093.25	35.2389
3097.51	36.2955
3101.76	37.6611
3106.01	39.4324
3110.26	41.7588
3114.5	44.6354
3118.74	48.2279
3122.98	50.0634
3127.22	49.8606
3131.45	50.6012
3135.68	53.0644
3139.91	56.2904
3144.13	59.5845
3148.35	63.0306
3152.57	66.6391
3156.78	70.5921
3161	74.8416
3165.21	79.8884
3169.41	85.1734
3173.62	90.5761
3177.82	94.9837
3182.02	98.8324
3186.21	102.011
3190.4	104.273
3194.59	104.576
3198.78	104.862
3202.96	106.812
3207.15	109.286
3211.33	109.604
3215.5	107.319
3219.67	104.357
3223.84	100.508
3228.01	96.0431
3232.18	91.0147
3236.34	88.089
3240.5	82.8041
3244.65	75.8957
3248.81	68.6795
3252.96	61.5848
3257.11	56.7535
3261.25	53.9914
3265.39	53.1192
3269.53	53.086
3273.67	52.2473
3277.8	50.0814
3281.94	46.8852
3286.06	42.7002
3290.19	37.649
3294.31	32.9557
3298.43	30.8208
3302.55	30.3815
3306.67	31.2075
3310.78	32.3687
3314.89	33.5229
3319	34.9731
3323.1	37.1403
3327.2	37.372
3331.3	35.1016
3335.39	31.861
3339.49	28.6251
3343.58	25.7227
3347.67	23.692
3351.75	23.2418
3355.83	22.7327
3359.91	22.3885
3363.99	22.226
3368.06	20.9883
3372.14	20.1373
3376.2	20.1654
3380.27	20.6729
3384.33	22.0783
3388.39	23.6037
3392.45	22.3704
3396.51	20.4534
3400.56	18.5118
3404.61	16.6315
3408.66	15.7682
3412.7	16.5034
3416.74	17.1469
3420.78	17.2518
3424.82	16.9699
3428.85	16.0797
3432.88	14.8807
3436.91	13.6399
3440.94	11.9802
3444.96	9.71499
3448.98	7.37112
3453	7.50389
3457.02	7.64822
3461.03	8.35629
3465.04	9.1943
3469.05	9.03175
3473.05	10.4725
3477.05	11.4234
3481.05	11.9951
3485.05	12.5061
3489.04	11.1013
3493.04	7.20518
3497.03	5.9247
3501.01	5.55276
3505	7.09965
3508.98	9.14896
3512.96	11.0125
3516.93	12.9277
3520.9	14.1183
3524.88	13.3401
3528.84	11.1255
3532.81	8.87772
3536.77	6.71352
3540.73	5.63252
3544.69	6.23173
3548.65	8.23094
3552.6	10.6666
3556.55	12.8437
3560.5	14.4765
3564.44	15.1509
3568.38	15.5455
3572.32	16.3496
3576.26	17.6687
3580.2	19.355
3584.13	22.0382
3588.06	23.7761
3591.98	23.824
3595.91	22.8706
3599.83	20.0265
3603.75	16.3099
3607.67	13.9763
3611.58	12.9073
3615.49	12.7194
3619.4	12.9522
3623.31	12.4422
3627.21	10.1599
3631.11	7.54204
3635.01	4.43628
3638.91	1.17206
3642.8	-0.334694
3646.69	-0.247742
3650.58	1.47409
3654.47	4.0218
3658.35	5.93023
3662.24	6.61717
3666.11	5.98993
3669.99	4.11939
3673.86	2.96394
3677.74	3.11633
3681.6	3.50987
3685.47	2.77055
3689.34	1.97929
3693.2	1.62968
3697.06	1.66486
3700.91	1.92818
3704.77	2.45265
3708.62	3.18516
3712.47	4.40466
3716.31	5.01162
3720.16	4.70183
3724	3.85065
3727.84	3.32541
3731.67	4.1792
3735.51	5.4022
3739.34	5.43819
3743.17	6.51116
3747	7.91631
3750.82	8.91438
3754.64	9.06807
3758.46	8.83868
3762.28	8.34658
3766.09	7.66497
3769.9	6.91787
3773.71	6.36764
3777.52	5.97728
3781.33	6.48568
3785.13	6.91143
3788.93	6.66247
3792.72	4.81755
3796.52	3.07923
3800.31	1.58775
3804.1	-0.190872
3807.89	-0.642502
3811.68	0.212753
3815.46	2.17271
3819.24	4.21988
3823.02	5.9868
3826.79	7.12769
3830.56	7.43677
3834.34	7.42197
3838.1	7.06987
3841.87	6.9938
3845.63	7.52622
3849.39	7.89581
3853.15	8.00318
3856.91	7.80952
3860.66	7.25683
3864.42	6.59707
3868.16	6.52163
3871.91	6.94563
3875.66	7.29115
3879.4	7.52179
3883.14	7.31375
3886.88	6.16281
3890.61	4.73309
3894.34	3.20875
3898.07	1.89203
3901.8	0.907219
3905.53	0.217827
3909.25	-0.132324
3912.97	-0.26886
3916.69	0.000686646
3920.4	0.606873
3924.12	1.34785
3927.83	2.3284
3931.54	2.31039
3935.24	1.77785
3938.95	1.24184
3942.65	0.680588
3946.35	0.230171
3950.05	0.0425186
3953.74	0.0195084
3957.44	-0.106224
3961.13	0.086792
3964.81	0.388374
3968.5	0.725235
3972.18	1.0761
3975.86	0.225243
3979.54	-0.449249
3983.22	-0.766754
3986.89	-0.44751
3990.56	0.115639
3994.23	-0.218018
3997.9	1.68169
3999.73	4.02229