File: Data/Raman/processed/beryl_150 (500nm)_633nm_Edge_100%_x50_VIS_LWD_H100um_15sx2.txt
#Acq. time (s)=	15
#Accumulations=	2
#Range (cm-¹)=	100...4000
#Windows=	1
#Auto scanning=	Off
#Autofocus=	Off
#Macrospot=	Off
#AutoExposure=	Off
#Spike filter=	Multiple accum.
#Delay time (s)=	0
#Binning=	1
#Readout mode=	Signal
#DeNoise=	Standard
#ICS correction=	On
#Dark correction=	Off
#Inst. Process=	On
#Detector Gain=	Best Dynamic
#Detector ADC=	50 kHz HS
#Detector temperature (°C)=	-60.09
#Instrument=	LabRAM HR Evol
#Detector=	SIN-EM FIVIS
#Objective=	x50_VIS_LWD
#Grating=	150 (500nm)
#ND Filter=	100%
#Laser=	633nm_Edge
#Hole=	100.021
#Temperature=	0
#Range=	Visible
#StageXY=	75x50mm Scan+
#StageZ=	Z motor
#X (µm)=	0
#Y (µm)=	0
#Z (µm)=	875.9
#Project=	20_09_03
#Sample=	BU18FA12
#Site=
#Title=	BU12-mineralA-3_150 (500nm)_633nm_Edge_100%_x50_VIS_LWD_H100um_15sx2
#Remark=
#Date=	03.09.2020 11:22
#Acquired=	03.09.2020 11:22:12
#Data Range:Extract=	01.07.2021 19:23:37
#Base:Fit=	01.07.2021 19:24:15
#Base:Fit=	01.07.2021 19:24:39
#Base:Fit=	01.07.2021 19:24:47
#Base:Sub=	01.07.2021 19:24:50
100.474	14.7701
106.99	13.146
113.501	28.0399
120.007	42.1976
126.507	55.5931
133.002	68.7262
139.491	75.4908
145.975	68.9443
152.454	51.9841
158.927	16.0663
165.395	1.396
171.858	-2.77588
178.315	1.62878
184.765	7.73438
191.212	12.0952
197.653	21.3085
204.089	22.3901
210.52	20.0964
216.944	13.3525
223.364	8.53748
229.779	6.64783
236.187	9.36841
242.591	16.3364
248.99	13.8464
255.382	10.3215
261.77	5.82471
268.152	1.97058
274.53	0.0755615
280.903	-2.17371
287.269	11.2002
293.631	33.6147
299.987	33.9585
306.338	36.2236
312.684	49.3053
319.024	98.744
325.36	239.905
331.689	102.678
338.015	31.5865
344.335	12.17
350.649	8.90894
356.959	10.5743
363.263	7.04553
369.561	9.25952
375.855	16.7935
382.145	32.7097
388.428	82.7167
394.706	259.21
400.979	533.558
407.247	282.592
413.511	131.522
419.769	136.901
426.022	159.539
432.269	114.869
438.512	111.765
444.749	124.839
450.981	128.386
457.209	109.005
463.431	77.4965
469.648	62.4628
475.86	54.443
482.067	50.5376
488.269	58.5153
494.465	64.4523
500.657	66.52
506.844	68.2311
513.026	74.1295
519.203	95.1371
525.375	138.264
531.541	148.747
537.703	148.16
543.86	112.514
550.011	89.9143
556.158	79.7151
562.3	81.7485
568.436	86.4147
574.568	93.3474
580.696	104.978
586.817	114.255
592.934	117.29
599.046	113.571
605.153	104.824
611.255	94.3842
617.353	82.3033
623.444	71.6349
629.533	63.8899
635.614	58.2443
641.691	54.6049
647.765	55.561
653.832	61.6436
659.895	70.9056
665.954	89.3866
672.006	100.011
678.054	189.414
684.097	692.936
690.137	1123.49
696.17	494.343
702.199	217.076
708.222	140.498
714.241	97.3677
720.256	72.4972
726.266	50.7137
732.271	45.49
738.271	41.8138
744.266	44.4453
750.256	44.6942
756.241	45.27
762.222	47.2589
768.198	76.4727
774.169	98.4601
780.136	82.5839
786.096	70.5704
792.053	56.5966
798.005	43.7964
803.953	31.7705
809.896	19.892
815.834	13.3522
821.766	9.70825
827.695	13.5441
833.619	21.1848
839.537	30.1096
845.452	37.2007
851.362	38.9568
857.266	35.4764
863.166	26.8525
869.062	18.2417
874.952	13.9747
880.839	11.0043
886.72	10.1969
892.597	11.9893
898.469	16.834
904.337	24.5585
910.199	27.5266
916.058	28.0565
921.911	28.3701
927.76	27.533
933.605	16.714
939.444	13.2179
945.279	11.8992
951.11	12.5323
956.935	12.8219
962.756	3.92834
968.573	-0.829468
974.386	-1.04822
980.193	3.16418
985.996	11.8025
991.794	29.3848
997.587	44.5254
1003.38	86.2921
1009.16	133.534
1014.94	170.053
1020.72	139.705
1026.49	83.5973
1032.25	51.2615
1038.02	32.0204
1043.77	26.6785
1049.53	30.15
1055.28	52.929
1061.02	87.749
1066.76	112.948
1072.49	126.854
1078.22	105.133
1083.95	81.6959
1089.67	55.1626
1095.39	31.0221
1101.1	9.92139
1106.81	5.77771
1112.51	3.98157
1118.21	7.36023
1123.91	15.6007
1129.6	25.1804
1135.28	32.981
1140.96	37.4419
1146.64	35.1852
1152.31	30.2866
1157.98	12.9948
1163.64	6.01575
1169.3	5.89197
1174.96	11.5248
1180.61	14.5115
1186.25	16.0442
1191.9	23.702
1197.53	29.1375
1203.17	34.1954
1208.8	40.2955
1214.42	47.9175
1220.04	56.7288
1225.65	66.4789
1231.27	76.8097
1236.87	86.774
1242.47	95.0627
1248.07	93.7988
1253.67	80.3811
1259.26	62.1934
1264.84	41.6892
1270.42	25.235
1276	13.9849
1281.57	8.33313
1287.14	9.50977
1292.7	18.1068
1298.26	26.355
1303.81	33.3759
1309.37	37.3251
1314.91	35.6401
1320.45	31.4778
1325.99	26.4104
1331.53	22.4969
1337.05	20.6699
1342.58	21.2198
1348.1	24.0948
1353.62	28.843
1359.13	29.0676
1364.64	28.4722
1370.14	27.3148
1375.64	24.9958
1381.14	20.9982
1386.63	15.3716
1392.12	10.2949
1397.6	8.31482
1403.08	8.68018
1408.55	9.4375
1414.02	9.94995
1419.49	10.1207
1424.95	9.70447
1430.41	8.54309
1435.86	6.36963
1441.31	2.96863
1446.75	0.816772
1452.2	0.0704346
1457.63	0.0841064
1463.06	0.475464
1468.49	1.2583
1473.92	2.83569
1479.34	5.47961
1484.75	8.8031
1490.17	12.1923
1495.57	14.6208
1500.98	18.3533
1506.38	27.3662
1511.77	27.2773
1517.16	24.6364
1522.55	22.8872
1527.94	21.4303
1533.31	19.5183
1538.69	16.989
1544.06	17.6101
1549.43	18.9777
1554.79	18.8341
1560.15	17.3444
1565.5	15.9883
1570.85	15.1647
1576.2	15.4713
1581.54	16.3306
1586.88	17.356
1592.22	18.4233
1597.55	19.4216
1602.87	20.0337
1608.2	20.4369
1613.51	20.5785
1618.83	20.594
1624.14	20.522
1629.45	20.462
1634.75	20.4949
1640.05	21.0792
1645.34	21.7062
1650.63	22.7603
1655.92	24.3271
1661.2	25.7402
1666.48	25.6416
1671.75	21.0466
1677.02	14.6594
1682.29	8.31042
1687.55	-0.0544434
1692.81	-2.76123
1698.07	3.06189
1703.32	12.7317
1708.56	18.6018
1713.81	19.9218
1719.05	16.3665
1724.28	16.3977
1729.51	24.4298
1734.74	25.871
1739.96	25.6499
1745.18	23.0624
1750.4	20.0712
1755.61	18.106
1760.82	16.9015
1766.02	16.2269
1771.22	15.9354
1776.42	15.9323
1781.61	16.1512
1786.8	16.9391
1791.98	17.9656
1797.16	19.101
1802.34	19.553
1807.51	19.8235
1812.68	19.765
1817.85	19.3966
1823.01	18.8436
1828.17	18.246
1833.32	23.2114
1838.47	23.6033
1843.62	23.517
1848.76	14.6639
1853.9	-1.06226
1859.03	-7.20752
1864.16	1.50049
1869.29	12.0859
1874.41	18.1835
1879.53	14.0789
1884.65	9.16199
1889.76	6.36108
1894.87	7.14453
1899.97	8.87109
1905.07	11.3622
1910.17	14.9135
1915.26	17.1512
1920.35	14.4963
1925.43	13.5958
1930.52	14.1376
1935.59	15.884
1940.67	20.3779
1945.74	23.9501
1950.8	25.4286
1955.87	24.6326
1960.93	21.7357
1965.98	16.5112
1971.03	10.1284
1976.08	5.62195
1981.13	3.38062
1986.17	2.62085
1991.2	2.72083
1996.24	1.35413
2001.27	4.61487
2006.29	14.6582
2011.31	27.6105
2016.33	35.8147
2021.35	25.5638
2026.36	15.6581
2031.36	7.0708
2036.37	2.17822
2041.37	1.29443
2046.37	3.88586
2051.36	9.66821
2056.35	17.4703
2061.33	24.9479
2066.31	31.0555
2071.29	36.4635
2076.27	38.8776
2081.24	38.0258
2086.21	36.4967
2091.17	33.9948
2096.13	30.6964
2101.08	26.8175
2106.04	23.4312
2110.99	21.619
2115.93	20.313
2120.88	19.0724
2125.81	18.1333
2130.75	18.5992
2135.68	21.8475
2140.61	21.8723
2145.53	20.5084
2150.45	20.9583
2155.37	22.0554
2160.28	22.1317
2165.19	21.351
2170.1	22.7343
2175	25.2756
2179.9	27.673
2184.79	28.7141
2189.69	26.9597
2194.57	27.7549
2199.46	31.6575
2204.34	34.9286
2209.22	37.5383
2214.09	40.3173
2218.96	44.7103
2223.83	48.7693
2228.69	51.1025
2233.55	51.3632
2238.41	48.6129
2243.26	45.3956
2248.11	43.1077
2252.96	41.9762
2257.8	41.2941
2262.64	40.9105
2267.48	40.7152
2272.31	40.3846
2277.14	40.2344
2281.96	40.3058
2286.78	41.167
2291.6	42.1012
2296.42	43.0759
2301.23	43.3647
2306.04	43.6079
2310.84	43.6309
2315.64	43.4225
2320.44	43.0056
2325.23	42.4015
2330.02	41.5999
2334.81	40.5608
2339.6	39.2555
2344.38	37.6801
2349.15	35.8202
2353.93	33.6383
2358.7	32.3741
2363.46	33.3591
2368.23	35.9142
2372.99	38.2303
2377.74	38.446
2382.5	37.8557
2387.25	38.1183
2391.99	37.9001
2396.73	36.0194
2401.47	33.4861
2406.21	33.999
2410.94	37.0045
2415.67	42.3115
2420.4	47.8917
2425.12	54.7343
2429.84	61.6918
2434.56	66.2548
2439.27	66.3883
2443.98	60.5222
2448.68	56.3625
2453.39	55.2506
2458.09	54.4271
2462.78	53.6262
2467.47	52.6915
2472.16	51.519
2476.85	50.0195
2481.53	48.1522
2486.21	45.9354
2490.89	46.2955
2495.56	50.0349
2500.23	53.6666
2504.89	56.6475
2509.56	57.369
2514.22	55.3286
2518.87	52.4766
2523.53	49.681
2528.18	47.9116
2532.82	46.6443
2537.46	45.6964
2542.1	44.2426
2546.74	42.5858
2551.37	40.9369
2556	39.4423
2560.63	38.1926
2565.25	37.2825
2569.87	36.9446
2574.49	37.3925
2579.1	41.4003
2583.71	44.5308
2588.32	45.5995
2592.93	46.0402
2597.53	45.9727
2602.12	45.6893
2606.72	45.4362
2611.31	45.421
2615.9	45.0067
2620.48	44.4052
2625.06	43.6152
2629.64	42.6254
2634.21	43.1466
2638.79	44.0116
2643.35	44.9248
2647.92	45.7544
2652.48	45.7432
2657.04	43.6667
2661.6	40.4998
2666.15	36.8282
2670.7	33.8132
2675.24	32.1149
2679.79	31.6154
2684.33	29.8665
2688.86	28.9364
2693.4	30.2549
2697.93	25.486
2702.45	20.2297
2706.98	20.0917
2711.5	23.0598
2716.02	27.337
2720.53	33.6093
2725.04	32.9891
2729.55	28.5759
2734.05	16.147
2738.56	5.74084
2743.05	-1.20605
2747.55	7.38953
2752.04	13.2657
2756.53	14.475
2761.02	16.6121
2765.5	19.5389
2769.98	20.7043
2774.46	26.6683
2778.93	32.6193
2783.4	39.272
2787.87	54.0542
2792.34	62.1656
2796.8	60.0586
2801.26	48.6254
2805.71	28.4437
2810.16	15.3201
2814.61	21.1295
2819.06	28.0884
2823.5	33.7915
2827.94	23.2156
2832.38	14.6758
2836.81	16.3777
2841.24	22.451
2845.67	26.9038
2850.09	29.7749
2854.52	31.0905
2858.93	26.203
2863.35	20.3776
2867.76	17.5142
2872.17	17.0017
2876.58	17.9092
2880.98	19.6852
2885.38	21.9763
2889.78	25.1288
2894.17	28.1177
2898.56	27.5892
2902.95	24.2864
2907.34	23.6172
2911.72	24.3569
2916.1	24.5873
2920.47	24.428
2924.85	24.0488
2929.22	23.45
2933.58	22.6074
2937.95	21.5028
2942.31	20.1421
2946.67	17.8694
2951.02	17.8684
2955.38	21.212
2959.72	22.7386
2964.07	23.8297
2968.41	37.8893
2972.75	28.4391
2977.09	15.5548
2981.43	15.129
2985.76	11.2761
2990.09	13.1287
2994.41	10.2935
2998.73	20.4899
3003.05	34.4659
3007.37	34.1846
3011.68	27.5977
3015.99	19.3751
3020.3	15.2558
3024.61	13.6753
3028.91	14.0604
3033.21	14.7851
3037.51	14.1706
3041.8	11.5673
3046.09	8.35529
3050.38	6.92682
3054.66	7.98785
3058.94	11.1127
3063.22	15.2256
3067.5	18.3594
3071.77	19.7337
3076.04	17.8976
3080.31	15.4794
3084.57	15.2732
3088.83	16.6483
3093.09	18.911
3097.35	21.3021
3101.6	22.904
3105.85	23.2513
3110.09	22.1572
3114.34	20.0173
3118.58	17.2446
3122.82	14.1137
3127.05	11.3598
3131.29	8.78851
3135.52	6.89172
3139.74	7.62256
3143.97	11.9391
3148.19	18.57
3152.41	22.9901
3156.62	23.368
3160.83	21.0281
3165.04	17.3696
3169.25	13.8285
3173.45	11.4175
3177.66	10.4108
3181.85	11.0087
3186.05	12.9709
3190.24	15.8919
3194.43	18.0064
3198.62	18.5638
3202.81	17.4893
3206.99	15.1661
3211.17	12.43
3215.34	10.6569
3219.51	9.92804
3223.69	10.0419
3227.85	11.1904
3232.02	12.3759
3236.18	11.7065
3240.34	11.9275
3244.49	12.2383
3248.65	12.4466
3252.8	13.8693
3256.95	18.1649
3261.09	21.4662
3265.24	20.863
3269.38	16.2634
3273.51	7.06665
3277.65	-0.339294
3281.78	-2.18463
3285.91	1.6897
3290.03	9.15155
3294.16	18.7008
3298.28	24.0609
3302.39	24.2109
3306.51	17.9166
3310.62	7.7608
3314.73	1.51837
3318.84	-1.86438
3322.94	-2.19141
3327.04	0.445251
3331.14	5.28577
3335.24	10.0081
3339.33	11.8932
3343.42	11.7264
3347.51	12.0983
3351.59	12.874
3355.68	18.215
3359.76	18.1
3363.83	11.2911
3367.91	6.15845
3371.98	3.21796
3376.05	2.8924
3380.11	5.52789
3384.18	11.0178
3388.24	13.9516
3392.3	13.9085
3396.35	10.5736
3400.4	4.94775
3404.45	1.45416
3408.5	0.200562
3412.55	1.25592
3416.59	4.95245
3420.63	12.9265
3424.66	18.4828
3428.7	20.4558
3432.73	19.0469
3436.76	13.1356
3440.79	8.92706
3444.81	7.90607
3448.83	8.87628
3452.85	11.9266
3456.86	16.6971
3460.88	19.0328
3464.89	19.2027
3468.89	17.8453
3472.9	24.6874
3476.9	27.5891
3480.9	30.516
3484.9	30.6754
3488.89	18.7996
3492.88	11.141
3496.87	9.12085
3500.86	9.49536
3504.84	10.8577
3508.82	12.6774
3512.8	14.1866
3516.78	15.1918
3520.75	15.5714
3524.72	15.334
3528.69	14.4744
3532.66	13.0031
3536.62	10.9018
3540.58	8.10156
3544.54	4.49103
3548.49	2.25214
3552.45	3.90588
3556.4	7.04242
3560.34	10.9124
3564.29	15.04
3568.23	16.8769
3572.17	16.0731
3576.11	15.477
3580.04	15.139
3583.98	18.8596
3587.91	28.0255
3591.83	42.2202
3595.76	67.0266
3599.68	124.046
3603.6	184.954
3607.52	426.918
3611.43	634.895
3615.34	195.895
3619.25	65.0629
3623.16	32.6305
3627.06	25.4714
3630.96	20.0108
3634.86	19.0644
3638.76	16.8072
3642.65	18.3018
3646.55	16.3337
3650.44	14.562
3654.32	13.6639
3658.21	13.101
3662.09	11.655
3665.97	12.0805
3669.84	15.5413
3673.72	19.2401
3677.59	22.0598
3681.46	24.0305
3685.32	19.588
3689.19	24.0955
3693.05	25.8496
3696.91	24.2022
3700.76	19.7379
3704.62	14.517
3708.47	9.96716
3712.32	7.89886
3716.16	5.03546
3720.01	0.464783
3723.85	-1.46515
3727.69	1.72937
3731.53	7.07245
3735.36	13.4326
3739.19	17.1743
3743.02	17.2221
3746.85	16.1293
3750.67	15.4797
3754.49	12.9056
3758.31	11.6769
3762.13	9.8089
3765.95	12.6602
3769.76	11.439
3773.57	8.35175
3777.37	7.54803
3781.18	9.47064
3784.98	12.0167
3788.78	14.1301
3792.58	15.8912
3796.37	17.1456
3800.17	17.6179
3803.96	17.0331
3807.74	16.0955
3811.53	16.4338
3815.31	15.7603
3819.09	10.4698
3822.87	3.64117
3826.65	-0.0524292
3830.42	-0.940979
3834.19	-0.714417
3837.96	0.667297
3841.73	4.66431
3845.49	8.53754
3849.25	10.6028
3853.01	11.2072
3856.77	9.77618
3860.52	8.03937
3864.27	9.95111
3868.02	11.8207
3871.77	6.79193
3875.51	5.01892
3879.25	9.38904
3882.99	16.9263
3886.73	17.2478
3890.47	14.1907
3894.2	11.7803
3897.93	9.789
3901.66	8.24292
3905.38	7.19006
3909.11	6.75781
3912.83	7.04626
3916.55	5.37042
3920.26	1.60315
3923.98	-0.616272
3927.69	-0.303101
3931.4	3.61377
3935.1	11.0565
3938.81	17.5383
3942.51	22.3366
3946.21	25.562
3949.91	26.7145
3953.6	26.3826
3957.29	25.744
3960.98	25.6873
3964.67	25.7986
3968.36	26.2
3972.04	26.9505
3975.72	28.0801
3979.4	29.5919
3983.08	31.5828
3986.75	33.7512
3990.42	30.5087
3994.09	28.7672
3997.76	27.9427
3999.59	28.011