File: Data/Raman/processed/brazilianite_150 (500nm)_633nm_Edge_100%_x50_VIS_LWD_H100um_15sX2.txt
#Acq. time (s)=	15
#Accumulations=	2
#Range (cm-¹)=	100...4000
#Windows=	1
#Auto scanning=	Off
#Autofocus=	Off
#Macrospot=	Off
#AutoExposure=	Off
#Spike filter=	Single accum. (Size=4)
#Delay time (s)=	0
#Binning=	1
#Readout mode=	Signal
#DeNoise=	Standard
#ICS correction=	On
#Dark correction=	Off
#Inst. Process=	On
#Detector Gain=	Best Dynamic
#Detector ADC=	50 kHz HS
#Detector temperature (°C)=	-60.09
#Instrument=	LabRAM HR Evol
#Detector=	SIN-EM FIVIS
#Objective=	x50_VIS_LWD
#Grating=	150 (500nm)
#ND Filter=	100%
#Laser=	633nm_Edge
#Hole=	100.021
#Temperature=	0
#Range=	Visible
#StageXY=	75x50mm Scan+
#StageZ=	Z motor
#X (µm)=	0
#Y (µm)=	0
#Z (µm)=	76.8
#Project=	20_05_11
#Sample=	BU20b
#Site=
#Title=	BU20b-area3-blue-rim-on-Scz_bottom_150 (500nm)_633nm_Edge_100%_x50_VIS_LWD_H100um_15sX2
#Remark=
#Date=	11.05.2020 19:20
#Acquired=	11.05.2020 19:20:54
#Data Range:Extract=	01.07.2021 19:23:37
#Base:Fit=	01.07.2021 19:24:15
#Base:Fit=	01.07.2021 19:24:39
#Base:Fit=	01.07.2021 19:24:47
#Base:Sub=	01.07.2021 19:24:50
100.862	296.326
107.378	473.724
113.889	344.387
120.394	176.349
126.894	56.8746
133.388	1.0321
139.878	26.5129
146.361	63.9766
152.84	137.881
159.313	88.2463
165.78	100.99
172.242	221.582
178.699	422.893
185.149	154.134
191.596	59.5918
198.037	63.9052
204.472	92.8754
210.903	125.956
217.326	161.623
223.746	191.71
230.16	169.543
236.568	155.684
242.972	135.369
249.371	142.75
255.762	192.827
262.151	141.481
268.533	74.576
274.91	146.781
281.282	270.946
287.648	258.55
294.01	135.562
300.365	141.875
306.716	83.4856
313.061	120.733
319.401	290.895
325.737	199.228
332.066	106.135
338.392	79.1969
344.711	70.0211
351.024	87.1945
357.335	151.414
363.638	296.896
369.936	202.781
376.23	89.6671
382.519	53.431
388.802	19.1503
395.08	13.3665
401.353	46.855
407.62	117.124
413.884	243.925
420.141	251.511
426.394	194.271
432.641	152.594
438.883	240.184
445.12	381.71
451.352	250.458
457.579	210.873
463.801	282.51
470.018	371.568
476.23	309.712
482.437	272.413
488.638	329.882
494.834	415.391
501.026	516.066
507.212	626.584
513.394	707.862
519.571	733.329
525.743	735.151
531.908	837.325
538.07	946.209
544.227	883.971
550.377	745.632
556.524	778.421
562.666	1073.2
568.801	1192.15
574.933	986.52
581.061	650.871
587.181	523.279
593.299	592.057
599.41	885.978
605.517	1185.34
611.618	864.069
617.716	460.519
623.807	334.007
629.895	286.859
635.977	286.845
642.053	276.493
648.127	222.346
654.193	201.995
660.256	214.815
666.314	203.632
672.367	155.125
678.414	101.11
684.457	57.0739
690.496	29.6788
696.529	12.6852
702.558	3.24841
708.581	0.0424194
714.6	-0.369629
720.614	0.674622
726.624	2.80566
732.628	0.497131
738.628	2.40649
744.623	6.85992
750.613	12.9236
756.598	20.6208
762.578	30.0106
768.554	39.4299
774.525	46.569
780.49	52.1956
786.451	58.2882
792.408	66.4005
798.36	78.3996
804.307	81.2634
810.25	76.7365
816.186	60.5229
822.119	43.6771
828.048	28.6531
833.972	17.7581
839.889	9.33044
845.804	4.10406
851.714	2.16211
857.617	1.7757
863.518	1.00555
869.413	0.460632
875.303	0.676208
881.19	1.09204
887.07	0.812073
892.947	-0.183044
898.818	-0.934692
904.686	-0.165588
910.548	2.26611
916.406	6.58875
922.26	15.2883
928.108	30.545
933.953	52.8465
939.792	85.3397
945.626	121.98
951.457	175.055
957.282	236.487
963.103	307.266
968.919	423.34
974.731	675.385
980.539	843.568
986.341	1022.35
992.139	1273.83
997.932	1186.11
1003.72	843.931
1009.51	783.584
1015.29	1008.98
1021.06	1556.08
1026.83	1624.68
1032.6	1289.53
1038.36	1018.36
1044.12	894.838
1049.87	779.757
1055.62	635.605
1061.36	599.305
1067.1	585.637
1072.84	571.842
1078.56	536.817
1084.29	490.344
1090.01	426.371
1095.73	347.342
1101.44	278.153
1107.15	268.208
1112.85	334.315
1118.55	493.378
1124.24	549.464
1129.94	399.078
1135.62	285.138
1141.3	247.152
1146.98	285.363
1152.65	303.015
1158.32	225.983
1163.98	155.688
1169.64	120.539
1175.3	96.2012
1180.95	76.6601
1186.59	62.569
1192.23	52.5793
1197.87	45.0764
1203.5	40.0829
1209.13	36.2188
1214.75	32.4315
1220.37	29.2704
1225.99	26.7983
1231.6	25.0561
1237.21	23.6563
1242.81	21.7933
1248.41	19.9261
1254	17.4929
1259.59	15.4584
1265.17	14.2885
1270.75	14.1041
1276.33	14.7221
1281.9	15.256
1287.47	15.6826
1293.03	16.0093
1298.59	16.8234
1304.15	17.6643
1309.7	18.0285
1315.24	17.9863
1320.78	17.7227
1326.32	17.8312
1331.85	18.5167
1337.38	19.0836
1342.91	18.1766
1348.43	19.1753
1353.95	20.0726
1359.46	20.0399
1364.97	20.2455
1370.47	19.2227
1375.97	17.5958
1381.46	15.3417
1386.96	13.2299
1392.44	12.6981
1397.92	13.4486
1403.4	14.2769
1408.88	14.731
1414.35	14.6322
1419.81	14.0546
1425.27	12.9158
1430.73	11.0818
1436.18	9.54959
1441.63	9.21469
1447.08	9.52185
1452.52	9.61005
1457.96	9.82629
1463.39	10.3057
1468.82	10.7907
1474.24	10.7682
1479.66	10.1356
1485.08	9.99756
1490.49	10.4576
1495.9	12.1162
1501.3	12.6171
1506.7	13.2122
1512.09	12.967
1517.49	11.5282
1522.87	9.71143
1528.26	8.37021
1533.63	7.96143
1539.01	8.25888
1544.38	9.21243
1549.75	9.33963
1555.11	14.2439
1560.47	15.5293
1565.82	12.8718
1571.17	8.35138
1576.52	5.87476
1581.86	6.19778
1587.2	7.08456
1592.54	8.29541
1597.86	10.1173
1603.19	11.5116
1608.51	12.3004
1613.83	12.3581
1619.15	12.0271
1624.46	11.824
1629.76	12.4739
1635.06	13.7686
1640.36	12.9587
1645.66	10.5249
1650.95	9.51044
1656.23	9.03714
1661.52	9.1745
1666.79	9.39496
1672.07	9.69797
1677.34	10.1877
1682.6	10.5247
1687.87	10.5798
1693.13	10.0039
1698.38	9.13181
1703.63	8.13733
1708.88	7.5625
1714.12	6.60938
1719.36	4.64035
1724.59	3.65594
1729.82	4.6185
1735.05	6.22021
1740.27	7.59683
1745.49	8.3331
1750.71	6.8399
1755.92	4.41727
1761.13	2.03564
1766.33	0.432861
1771.53	-0.111481
1776.73	-0.376038
1781.92	0.937164
1787.11	2.76877
1792.29	4.50116
1797.47	6.04535
1802.65	6.08777
1807.82	5.50613
1812.99	5.63647
1818.15	6.27356
1823.32	6.59683
1828.47	5.9584
1833.63	3.716
1838.78	2.22137
1843.92	1.36383
1849.06	0.822937
1854.2	0.489227
1859.34	0.276398
1864.47	0.170349
1869.59	0.460419
1874.72	0.0768738
1879.84	-0.36676
1884.95	-0.456848
1890.06	0.147217
1895.17	1.07648
1900.27	2.29581
1905.37	3.40152
1910.47	4.2944
1915.56	5.46362
1920.65	5.73605
1925.74	4.89209
1930.82	3.68564
1935.9	2.62408
1940.97	2.29068
1946.04	3.01215
1951.11	4.36301
1956.17	5.65213
1961.23	6.41937
1966.28	6.5899
1971.33	4.39185
1976.38	1.94952
1981.43	0.434845
1986.47	-0.309906
1991.5	-0.162384
1996.54	0.947083
2001.57	2.16217
2006.59	1.68198
2011.61	1.03867
2016.63	1.59702
2021.65	3.42984
2026.66	4.46902
2031.66	4.90179
2036.67	4.05682
2041.67	2.88397
2046.66	1.85214
2051.66	1.21167
2056.65	2.30701
2061.63	3.84198
2066.61	5.46066
2071.59	7.0748
2076.56	8.22955
2081.53	8.28592
2086.5	7.51669
2091.46	7.20859
2096.42	7.21722
2101.38	7.50168
2106.33	8.26035
2111.28	9.64667
2116.23	11.0273
2121.17	12.1021
2126.11	12.7241
2131.04	12.4134
2135.97	11.0446
2140.9	9.79428
2145.82	9.7056
2150.74	9.97781
2155.66	10.2217
2160.57	10.4137
2165.48	10.2574
2170.39	8.92551
2175.29	5.01434
2180.19	1.78677
2185.09	-1.22964
2189.98	-0.262726
2194.86	3.26883
2199.75	8.55032
2204.63	11.4485
2209.51	11.7537
2214.38	11.5159
2219.25	11.4538
2224.12	10.1638
2228.98	9.00119
2233.84	8.23679
2238.7	8.0162
2243.55	8.35553
2248.4	9.4848
2253.25	11.6118
2258.09	13.174
2262.93	13.6533
2267.76	13.5534
2272.6	12.4286
2277.43	11.128
2282.25	9.27011
2287.07	7.70129
2291.89	6.88904
2296.7	6.63538
2301.52	7.07849
2306.32	7.97034
2311.13	8.68256
2315.93	12.1698
2320.73	13.4671
2325.52	13.014
2330.31	11.1372
2335.1	9.07736
2339.88	8.58685
2344.66	8.49866
2349.44	8.13745
2354.21	8.54391
2358.98	9.20575
2363.75	9.89209
2368.51	10.3904
2373.27	10.7081
2378.03	10.5528
2382.78	10.3151
2387.53	11.0796
2392.28	10.0331
2397.02	7.4642
2401.76	5.15891
2406.49	3.97525
2411.23	4.02063
2415.95	4.76819
2420.68	5.95386
2425.4	7.61935
2430.12	8.73517
2434.84	9.07703
2439.55	8.99756
2444.26	9.05188
2448.96	9.56473
2453.67	10.5846
2458.37	9.9494
2463.06	8.51392
2467.75	6.96457
2472.44	6.34406
2477.13	7.71283
2481.81	9.74619
2486.49	13.0111
2491.17	16.8668
2495.84	17.1084
2500.51	15.3159
2505.17	11.7922
2509.84	8.02878
2514.5	7.52234
2519.15	7.37347
2523.8	7.36301
2528.45	7.63776
2533.1	8.21228
2537.74	8.80951
2542.38	9.17719
2547.02	8.90836
2551.65	8.74155
2556.28	8.7619
2560.91	9.03839
2565.53	9.48196
2570.15	10.3189
2574.77	11.775
2579.38	13.2206
2583.99	13.5842
2588.6	12.8692
2593.2	11.8058
2597.8	10.7151
2602.4	9.92233
2606.99	9.15411
2611.58	8.24597
2616.17	7.54562
2620.75	6.89063
2625.33	6.8063
2629.91	6.4942
2634.49	5.85995
2639.06	5.26563
2643.63	4.72754
2648.19	4.28513
2652.75	4.22238
2657.31	5.44992
2661.87	5.89383
2666.42	6.49316
2670.97	7.31555
2675.51	7.47321
2680.06	7.00247
2684.6	6.77335
2689.13	6.13443
2693.67	5.4339
2698.2	4.14886
2702.72	2.92114
2707.25	1.70203
2711.77	0.630096
2716.28	-0.0819092
2720.8	-0.243774
2725.31	0.624115
2729.82	2.39758
2734.32	4.08679
2738.83	5.51825
2743.32	5.95279
2747.82	5.92844
2752.31	5.25558
2756.8	4.70682
2761.29	4.21219
2765.77	3.3364
2770.25	2.54276
2774.73	1.55084
2779.2	0.592712
2783.67	-0.0906067
2788.14	-0.0263977
2792.6	0.683624
2797.06	2.14929
2801.52	3.69672
2805.98	3.8764
2810.43	3.65015
2814.88	2.77267
2819.32	1.59756
2823.77	0.972382
2828.2	0.871796
2832.64	1.17422
2837.08	2.02176
2841.51	2.98376
2845.93	3.81973
2850.36	3.97122
2854.78	3.76898
2859.2	3.01633
2863.61	2.33682
2868.02	2.51926
2872.43	3.2168
2876.84	4.42725
2881.24	5.25043
2885.64	5.16229
2890.04	4.46609
2894.43	3.38467
2898.82	2.26666
2903.21	2.5166
2907.6	3.57263
2911.98	4.20453
2916.36	4.61789
2920.74	4.5484
2925.11	4.3884
2929.48	4.26663
2933.84	3.89319
2938.21	3.20795
2942.57	3.21683
2946.93	2.2402
2951.28	0.747253
2955.64	-0.368042
2959.98	-0.485016
2964.33	0.00152588
2968.67	0.306702
2973.01	1.20206
2977.35	3.09418
2981.68	4.38892
2986.02	4.17828
2990.34	4.37823
2994.67	4.97723
2998.99	5.35181
3003.31	4.75818
3007.63	4.23743
3011.94	3.97186
3016.25	2.3692
3020.56	0.424194
3024.86	-0.685486
3029.17	-0.731537
3033.47	0.125549
3037.76	1.71271
3042.05	3.47269
3046.34	4.43726
3050.63	4.86597
3054.92	4.40619
3059.2	2.84457
3063.48	1.31186
3067.75	0.201355
3072.02	0.156158
3076.29	1.01154
3080.56	3.43903
3084.82	6.23111
3089.09	8.52826
3093.34	10.7758
3097.6	12.4907
3101.85	14.1046
3106.1	18.0106
3110.35	19.2556
3114.59	19.2719
3118.83	19.1629
3123.07	19.9896
3127.31	22.3868
3131.54	25.7168
3135.77	29.4834
3140	33.6244
3144.22	38.0187
3148.44	41.976
3152.66	44.8854
3156.87	46.3333
3161.09	47.89
3165.29	48.7761
3169.5	49.3068
3173.71	50.2517
3177.91	51.7964
3182.11	54.3449
3186.3	58.9796
3190.49	65.5009
3194.68	74.0522
3198.87	84.98
3203.05	97.8709
3207.24	112.566
3211.41	128.702
3215.59	147.69
3219.76	168.065
3223.93	189.814
3228.1	213.411
3232.27	237.24
3236.43	257.206
3240.59	275.562
3244.74	289.87
3248.9	299.453
3253.05	300.829
3257.2	296.671
3261.34	289.033
3265.48	279.09
3269.62	269.14
3273.76	256.481
3277.89	242.372
3282.02	227.109
3286.15	211.819
3290.28	197.001
3294.4	183.095
3298.52	170.181
3302.64	158.86
3306.75	149.813
3310.87	142.516
3314.98	136.767
3319.08	132.804
3323.19	130.7
3327.29	129.535
3331.39	128.999
3335.48	128.776
3339.58	128.55
3343.67	128.444
3347.75	128.646
3351.84	130.209
3355.92	133.467
3360	139.111
3364.08	145.964
3368.15	153.905
3372.22	162.567
3376.29	165.993
3380.36	169.686
3384.42	176.128
3388.48	188.042
3392.54	212.905
3396.59	243.312
3400.65	300.488
3404.7	372.998
3408.74	460.06
3412.79	559.576
3416.83	632.643
3420.87	700.592
3424.91	666.87
3428.94	627.628
3432.97	569.052
3437	505.008
3441.02	485.016
3445.05	517.148
3449.07	566.341
3453.09	632.724
3457.1	773.738
3461.11	966.807
3465.13	1102.16
3469.13	1140.63
3473.14	1072.73
3477.14	961.567
3481.14	835.521
3485.14	713.422
3489.13	599.782
3493.12	499.283
3497.11	410.01
3501.1	344.829
3505.08	296.178
3509.06	265.845
3513.04	244.309
3517.02	225.952
3520.99	209.34
3524.96	193.809
3528.93	177.608
3532.89	161.44
3536.86	144.292
3540.82	132.541
3544.78	122.588
3548.73	113.12
3552.68	104.185
3556.63	96.6556
3560.58	90.2382
3564.53	84.0134
3568.47	78.2847
3572.41	72.5491
3576.34	68.2591
3580.28	66.0996
3584.21	64.9671
3588.14	62.9933
3592.07	59.6144
3595.99	53.3685
3599.91	50.1114
3603.83	48.0184
3607.75	46.9957
3611.66	46.329
3615.58	43.3436
3619.49	39.5216
3623.39	35.0181
3627.3	30.2589
3631.2	25.8192
3635.1	22.0287
3638.99	18.6377
3642.89	17.6002
3646.78	17.267
3650.67	16.0408
3654.55	14.9512
3658.44	14.1713
3662.32	13.45
3666.2	11.251
3670.07	9.89871
3673.95	9.08359
3677.82	7.29501
3681.69	4.16473
3685.55	1.65593
3689.42	0.552872
3693.28	0.437164
3697.14	1.76283
3700.99	4.77225
3704.85	7.29486
3708.7	9.36519
3712.55	10.7704
3716.39	10.5103
3720.24	8.98204
3724.08	7.22546
3727.92	4.95146
3731.76	2.97845
3735.59	1.24887
3739.42	0.284714
3743.25	-0.0842133
3747.08	0.492844
3750.9	0.582382
3754.72	0.441254
3758.54	0.194672
3762.36	1.40976
3766.17	3.04353
3769.99	5.26816
3773.79	7.43912
3777.6	8.25723
3781.41	7.5636
3785.21	5.39264
3789.01	3.35828
3792.81	2.24059
3796.6	1.89677
3800.39	2.75816
3804.18	4.40263
3807.97	6.19168
3811.76	7.10225
3815.54	6.06747
3819.32	4.32536
3823.1	3.28995
3826.87	5.70209
3830.65	5.85365
3834.42	3.41734
3838.18	0.207657
3841.95	-1.04604
3845.71	-0.855942
3849.48	0.145874
3853.23	1.49158
3856.99	2.77245
3860.74	3.85123
3864.5	4.80301
3868.24	8.23518
3871.99	4.30421
3875.74	2.89056
3879.48	6.31506
3883.22	7.18004
3886.95	6.22527
3890.69	5.12846
3894.42	7.33182
3898.15	8.84457
3901.88	5.84782
3905.61	5.99139
3909.33	6.3524
3913.05	6.05553
3916.77	6.35239
3920.48	6.59532
3924.2	7.26195
3927.91	7.83926
3931.62	7.79005
3935.32	7.06075
3939.03	5.53589
3942.73	3.0426
3946.43	0.946854
3950.13	0.162354
3953.82	0.439377
3957.51	1.63202
3961.2	3.41092
3964.89	5.27423
3968.58	6.43793
3972.26	6.38434
3975.94	5.22586
3979.62	4.25987
3983.3	3.74257
3986.97	3.65913
3990.64	3.57504
3994.31	3.44022
3997.98	1.56612
3999.81	0.487946