File: Data/Raman/processed/montebrasite-OH_150 (500nm)_633nm_Edge_50%_x50_VIS_LWD_H100um_15sX2.txt
#Acq. time (s)=	15
#Accumulations=	2
#Range (cm-¹)=	100...4000
#Windows=	1
#Auto scanning=	Off
#Autofocus=	Off
#Macrospot=	Off
#AutoExposure=	Off
#Spike filter=	Multiple accum.
#Delay time (s)=	0
#Binning=	1
#Readout mode=	Signal
#DeNoise=	Standard
#ICS correction=	On
#Dark correction=	Off
#Inst. Process=	On
#Detector Gain=	Best Dynamic
#Detector ADC=	50 kHz HS
#Detector temperature (°C)=	-60.09
#Instrument=	LabRAM HR Evol
#Detector=	SIN-EM FIVIS
#Objective=	x50_VIS_LWD
#Grating=	150 (500nm)
#ND Filter=	50%
#Laser=	633nm_Edge
#Hole=	100.021
#Temperature=	0
#Range=	Visible
#StageXY=	75x50mm Scan+
#StageZ=	Z motor
#X (µm)=	0
#Y (µm)=	0
#Z (µm)=	82.3
#Project=	20_05_11
#Sample=	BU20b
#Site=
#Title=	BU20b-area1-cleavaged-clear-rim_150 (500nm)_633nm_Edge_50%_x50_VIS_LWD_H100um_15sX2
#Remark=
#Date=	11.05.2020 17:45
#Acquired=	11.05.2020 17:45:00
#Data Range:Extract=	01.07.2021 19:23:37
#Base:Fit=	01.07.2021 19:24:15
#Base:Fit=	01.07.2021 19:24:39
#Base:Fit=	01.07.2021 19:24:47
#Base:Sub=	01.07.2021 19:24:50
100.862	9.12927
107.378	5.99829
113.889	3.17249
120.394	-0.108643
126.894	1.58496
133.388	19.194
139.878	75.714
146.361	50.4235
152.84	11.1523
159.313	15.9758
165.78	81.5143
172.242	222.367
178.699	255.965
185.149	152.447
191.596	110.509
198.037	63.3412
204.472	30.3827
210.903	25.1653
217.326	57.0542
223.746	126.596
230.16	167.959
236.568	132.483
242.972	91.3154
249.371	36.0752
255.762	4.96692
262.151	31.1946
268.533	110.44
274.91	451.206
281.282	1012.24
287.648	472.295
294.01	485.001
300.365	1339.6
306.716	877.758
313.061	397.412
319.401	203.341
325.737	102.491
332.066	50.0833
338.392	22.9641
344.711	4.47583
351.024	-0.294434
357.335	2.59631
363.638	9.60498
369.936	21.7408
376.23	34.702
382.519	51.3553
388.802	71.5166
395.08	92.4261
401.353	109.984
407.62	122.94
413.884	131.471
420.141	151.828
426.394	253.389
432.641	385.346
438.883	150.702
445.12	77.0226
451.352	64.2694
457.579	53.3933
463.801	77.472
470.018	142.169
476.23	271.197
482.437	523.614
488.638	669.119
494.834	567.467
501.026	390.153
507.212	221.95
513.394	97.5048
519.571	51.861
525.743	40.1453
531.908	42.0281
538.07	38.269
544.227	35.7615
550.377	34.6429
556.524	33.0659
562.666	26.8255
568.801	25.6815
574.933	9.29218
581.061	30.2129
587.181	30.2831
593.299	83.1039
599.41	185.721
605.517	297.074
611.618	149.108
617.716	128.021
623.807	292.39
629.895	641.084
635.977	520.588
642.053	385.669
648.127	699.533
654.193	444.484
660.256	165.114
666.314	65.2133
672.367	21.6714
678.414	10.2894
684.457	7.54492
690.496	15.7617
696.529	21.3234
702.558	7.30725
708.581	1.0451
714.6	-1.15277
720.614	1.83734
726.624	1.49323
732.628	-1.12366
738.628	-0.0739746
744.623	2.4635
750.613	6.15326
756.598	12.8873
762.578	22.4724
768.554	37.34
774.525	48.9626
780.49	67.0648
786.451	106.258
792.408	187.418
798.36	375.342
804.307	506.379
810.25	347.482
816.186	204.356
822.119	107.653
828.048	54.9453
833.972	40.1634
839.889	40.3756
845.804	38.7564
851.714	35.5271
857.617	33.9232
863.518	35.9487
869.413	36.8982
875.303	37.875
881.19	37.2939
887.07	34.3919
892.947	29.576
898.818	26.9601
904.686	25.4291
910.548	23.1921
916.406	24.4661
922.26	25.6149
928.108	30.0449
933.953	35.7933
939.792	42.81
945.626	49.5203
951.457	55.5981
957.282	58.947
963.103	61.6644
968.919	56.4852
974.731	69.4699
980.539	71.1327
986.341	86.477
992.139	142.65
997.932	249.559
1003.72	450.284
1009.51	902.474
1015.29	1280.2
1021.06	866.469
1026.83	474.794
1032.6	358.226
1038.36	480.085
1044.12	828.052
1049.87	1125.21
1055.62	804.897
1061.36	671.981
1067.1	427.833
1072.84	251.557
1078.56	159.059
1084.29	127.606
1090.01	132.198
1095.73	151.879
1101.44	209.58
1107.15	505.793
1112.85	762.792
1118.55	499.908
1124.24	293.236
1129.94	174.386
1135.62	117.997
1141.3	88.6255
1146.98	72.7317
1152.65	66.4335
1158.32	64.1876
1163.98	67.0175
1169.64	77.9002
1175.3	97.3014
1180.95	131.324
1186.59	189.354
1192.23	261.191
1197.87	225.865
1203.5	165.698
1209.13	121.644
1214.75	97.2633
1220.37	79.1697
1225.99	65.5878
1231.6	56.4047
1237.21	47.4229
1242.81	42.8179
1248.41	40.7466
1254	39.0225
1259.59	38.8337
1265.17	37.401
1270.75	34.2121
1276.33	31.8679
1281.9	29.6019
1287.47	26.9258
1293.03	26.4094
1298.59	29.1716
1304.15	33.1147
1309.7	36.5911
1315.24	38.2127
1320.78	38.8468
1326.32	37.9579
1331.85	32.5628
1337.38	30.7134
1342.91	35.1389
1348.43	38.6943
1353.95	40.2271
1359.46	33.0817
1364.97	24.1345
1370.47	16.2891
1375.97	12.1733
1381.46	11.8376
1386.96	13.385
1392.44	14.5288
1397.92	15.8193
1403.4	16.3845
1408.88	19.3751
1414.35	20.3599
1419.81	18.3174
1425.27	17.3374
1430.73	17.2537
1436.18	17.7441
1441.63	17.6451
1447.08	15.4005
1452.52	13.2858
1457.96	11.1179
1463.39	7.14618
1468.82	3.02527
1474.24	0.539612
1479.66	-1.34332
1485.08	-0.705688
1490.49	2.67786
1495.9	9.41913
1501.3	15.8531
1506.7	19.4827
1512.09	20.808
1517.49	21.6755
1522.87	24.0521
1528.26	21.9531
1533.63	19.4464
1539.01	17.7921
1544.38	15.5178
1549.75	14.4268
1555.11	14.5159
1560.47	16.6478
1565.82	20.4431
1571.17	24.6129
1576.52	28.5887
1581.86	32.1613
1587.2	34.4885
1592.54	34.0772
1597.86	30.28
1603.19	25.4629
1608.51	23.3307
1613.83	22.067
1619.15	21.0596
1624.46	21.3792
1629.76	22.3922
1635.06	22.2338
1640.36	20.4973
1645.66	13.8127
1650.95	11.1145
1656.23	9.55981
1661.52	10.567
1666.79	12.7712
1672.07	19.6746
1677.34	23.9064
1682.6	24.6776
1687.87	23.0242
1693.13	17.7273
1698.38	13.0546
1703.63	11.816
1708.88	12.1733
1714.12	11.3333
1719.36	12.2437
1724.59	10.0334
1729.82	9.01099
1735.05	7.60803
1740.27	7.06256
1745.49	5.3512
1750.71	6.26123
1755.92	9.3255
1761.13	11.5897
1766.33	11.8761
1771.53	9.56964
1776.73	5.63562
1781.92	2.10986
1787.11	1.58954
1792.29	2.5285
1797.47	6.04803
1802.65	9.49847
1807.82	10.4397
1812.99	10.6163
1818.15	9.74786
1823.32	9.80609
1828.47	9.12634
1833.63	8.42035
1838.78	9.83167
1843.92	10.2386
1849.06	10.4463
1854.2	9.94781
1859.34	7.0957
1864.47	6.51251
1869.59	6.78522
1874.72	6.48969
1879.84	3.48804
1884.95	-1.08087
1890.06	-3.5235
1895.17	-2.1264
1900.27	0.53595
1905.37	1.98187
1910.47	3.9162
1915.56	6.87805
1920.65	10.4048
1925.74	14.4234
1930.82	15.0994
1935.9	15.316
1940.97	15.7136
1946.04	16.7083
1951.11	13.5823
1956.17	13.5231
1961.23	15.4736
1966.28	16.375
1971.33	16.5986
1976.38	14.9911
1981.43	13.1154
1986.47	10.1221
1991.5	8.59955
1996.54	8.89673
2001.57	10.5378
2006.59	12.8423
2011.61	16.1403
2016.63	19.2905
2021.65	22.1149
2026.66	22.8857
2031.66	25.2646
2036.67	27.4691
2041.67	29.9261
2046.66	29.3806
2051.66	28.82
2056.65	28.2882
2061.63	26.3925
2066.61	26.2155
2071.59	27.5779
2076.56	28.8835
2081.53	30.5012
2086.5	29.3458
2091.46	29.9556
2096.42	31.7232
2101.38	35.1218
2106.33	41.4753
2111.28	47.171
2116.23	46.226
2121.17	45.2343
2126.11	40.3085
2131.04	36.7074
2135.97	35.279
2140.9	33.2514
2145.82	30.5172
2150.74	31.3146
2155.66	33.9573
2160.57	38.4632
2165.48	41.7733
2170.39	43.1365
2175.29	41.7859
2180.19	39.2215
2185.09	36.6814
2189.98	33.9086
2194.86	34.8642
2199.75	41.1917
2204.63	48.3984
2209.51	57.3091
2214.38	62.0266
2219.25	62.9096
2224.12	62.764
2228.98	60.975
2233.84	59.7764
2238.7	59.9877
2243.55	65.1151
2248.4	70.6765
2253.25	69.4126
2258.09	64.9958
2262.93	61.1151
2267.76	58.6235
2272.6	56.3282
2277.43	52.5073
2282.25	48.739
2287.07	48.153
2291.89	52.2799
2296.7	53.4921
2301.52	53.5761
2306.32	56.8975
2311.13	60.3079
2315.93	62.3779
2320.73	59.9462
2325.52	59.7332
2330.31	62.1642
2335.1	65.2558
2339.88	66.1157
2344.66	70.7023
2349.44	74.2809
2354.21	77.7495
2358.98	79.1238
2363.75	76.2624
2368.51	71.2901
2373.27	64.5615
2378.03	59.1207
2382.78	55.5212
2387.53	54.0767
2392.28	53.5752
2397.02	53.6927
2401.76	53.5897
2406.49	53.9575
2411.23	57.5259
2415.95	59.7448
2420.68	62.5172
2425.4	62.7318
2430.12	63.8765
2434.84	59.9402
2439.55	56.8244
2444.26	59.8735
2448.96	63.2706
2453.67	62.8956
2458.37	56.767
2463.06	51.9666
2467.75	50.2862
2472.44	49.5756
2477.13	46.6691
2481.81	46.9903
2486.49	49.1122
2491.17	55.6904
2495.84	61.0338
2500.51	66.1211
2505.17	67.7188
2509.84	67.5908
2514.5	63.2563
2519.15	56.5129
2523.8	51.5508
2528.45	46.296
2533.1	44.4457
2537.74	47.4651
2542.38	51.9825
2547.02	51.0642
2551.65	49.9722
2556.28	49.2855
2560.91	47.4344
2565.53	45.0851
2570.15	43.5553
2574.77	41.2754
2579.38	41.5812
2583.99	50.9133
2588.6	51.8395
2593.2	46.8237
2597.8	43.1238
2602.4	36.742
2606.99	34.9041
2611.58	33.0676
2616.17	31.0178
2620.75	29.7681
2625.33	29.7063
2629.91	30.058
2634.49	29.7603
2639.06	29.756
2643.63	30.9977
2648.19	31.5731
2652.75	31.0281
2657.31	30.1776
2661.87	29.996
2666.42	30.8806
2670.97	31.141
2675.51	32.8939
2680.06	31.8893
2684.6	31.8569
2689.13	32.5124
2693.67	32.1353
2698.2	33.1278
2702.72	26.8141
2707.25	18.7856
2711.77	13.3525
2716.28	9.81116
2720.8	6.43597
2725.31	4.72949
2729.82	5.17761
2734.32	8.26233
2738.83	11.9235
2743.32	14.9623
2747.82	14.9885
2752.31	12.7585
2756.8	11.0202
2761.29	10.134
2765.77	10.442
2770.25	12.629
2774.73	14.7387
2779.2	14.7189
2783.67	13.3877
2788.14	13.1273
2792.6	13.5145
2797.06	12.7189
2801.52	12.8164
2805.98	14.0639
2810.43	13.8259
2814.88	12.0809
2819.32	12.7207
2823.77	13.9915
2828.2	15.6139
2832.64	15.0392
2837.08	11.7519
2841.51	7.95911
2845.93	8.16882
2850.36	8.01227
2854.78	7.70172
2859.2	9.55646
2863.61	10.6044
2868.02	8.07227
2872.43	2.65472
2876.84	1.35748
2881.24	2.59497
2885.64	4.6781
2890.04	5.08148
2894.43	7.76392
2898.82	10.4789
2903.21	12.7281
2907.6	11.8069
2911.98	9.14258
2916.36	9.66956
2920.74	10.8992
2925.11	10.3933
2929.48	13.2625
2933.84	11.2328
2938.21	7.38458
2942.57	2.40204
2946.93	-0.381165
2951.28	-3.57776
2955.64	-4.56097
2959.98	-3.31799
2964.33	5.67102
2968.67	7.49963
2973.01	0.243408
2977.35	-0.405762
2981.68	17.6614
2986.02	20.1386
2990.34	19.4866
2994.67	18.3304
2998.99	4.84448
3003.31	1.46356
3007.63	6.39557
3011.94	8.86011
3016.25	8.68671
3020.56	2.71484
3024.86	5.00348
3029.17	8.51984
3033.47	9.5639
3037.76	6.45862
3042.05	7.36554
3046.34	10.4969
3050.63	11.2936
3054.92	9.79333
3059.2	6.30975
3063.48	4.22247
3067.75	5.73926
3072.02	7.28735
3076.29	7.3703
3080.56	6.56128
3084.82	2.87311
3089.09	3.06458
3093.34	1.54962
3097.6	-0.341492
3101.85	0.768066
3106.1	4.53845
3110.35	8.79755
3114.59	12.8941
3118.83	14.2567
3123.07	13.3646
3127.31	11.352
3131.54	8.26196
3135.77	2.448
3140	2.19592
3144.22	5.79816
3148.44	19.7386
3152.66	18.6088
3156.87	17.0591
3161.09	16.8033
3165.29	15.4557
3169.5	9.54248
3173.71	7.68109
3177.91	7.60254
3182.11	10.0695
3186.3	14.1949
3190.49	12.9967
3194.68	13.2037
3198.87	15.5063
3203.05	19.2789
3207.24	23.8833
3211.41	28.4647
3215.59	31.5314
3219.76	35.5109
3223.93	30.711
3228.1	32.4529
3232.27	36.528
3236.43	42.0897
3240.59	43.7111
3244.74	41.9894
3248.9	45.149
3253.05	47.1509
3257.2	49.6133
3261.34	48.3633
3265.48	44.645
3269.62	39.7421
3273.76	38.0047
3277.89	31.5654
3282.02	25.3161
3286.15	20.3632
3290.28	17.8175
3294.4	20.2226
3298.52	25.7305
3302.64	30.3714
3306.75	33.5322
3310.87	36.4993
3314.98	37.5616
3319.08	43.3118
3323.19	38.8265
3327.29	39.4781
3331.39	46.1627
3335.48	66.4695
3339.58	114.309
3343.67	179.629
3347.75	268.617
3351.84	373.299
3355.92	513.04
3360	714.861
3364.08	1045.4
3368.15	1470.69
3372.22	1931.12
3376.29	2313.8
3380.36	2419.9
3384.42	1972.7
3388.48	1339.28
3392.54	797.308
3396.59	621.776
3400.65	480.546
3404.7	404.883
3408.74	366.784
3412.79	320.991
3416.83	300.399
3420.87	290.92
3424.91	258.021
3428.94	209.363
3432.97	149.015
3437	100.491
3441.02	68.9391
3445.05	50.5643
3449.07	33.8364
3453.09	27.6188
3457.1	24.252
3461.11	26.6451
3465.13	32.58
3469.13	36.8528
3473.14	39.6928
3477.14	40.9427
3481.14	40.577
3485.14	41.1725
3489.13	44.5082
3493.12	46.1688
3497.11	46.3941
3501.1	47.8116
3505.08	46.3299
3509.06	44.8435
3513.04	45.136
3517.02	42.3224
3520.99	39.3994
3524.96	37.9556
3528.93	34.7585
3532.89	32.9612
3536.86	31.9306
3540.82	33.0908
3544.78	31.7609
3548.73	28.0694
3552.68	26.9216
3556.63	27.3337
3560.58	26.6816
3564.53	27.6527
3568.47	32.1649
3572.41	33.611
3576.34	30.7412
3580.28	31.8532
3584.21	31.9738
3588.14	33.5826
3592.07	27.5864
3595.99	19.5066
3599.91	11.7433
3603.83	9.76331
3607.75	9.49237
3611.66	14.3546
3615.58	16.4716
3619.49	17.4732
3623.39	17.3885
3627.3	15.9497
3631.2	9.69769
3635.1	7.33765
3638.99	4.66351
3642.89	3.09686
3646.78	5.80719
3650.67	9.44971
3654.55	14.5183
3658.44	15.3554
3662.32	11.7136
3666.2	13.4797
3670.07	9.49414
3673.95	4.61597
3677.82	0.817871
3681.69	-1.62213
3685.55	-2.96448
3689.42	-0.717346
3693.28	2.26965
3697.14	7.43829
3700.99	9.86285
3704.85	16.2935
3708.7	15.4852
3712.55	14.3506
3716.39	12.0137
3720.24	8.63263
3724.08	6.64294
3727.92	5.22174
3731.76	5.30475
3735.59	3.85938
3739.42	1.28467
3743.25	1.3587
3747.08	3.5954
3750.9	3.74066
3754.72	9.73505
3758.54	10.8907
3762.36	10.0409
3766.17	12.2394
3769.99	13.0909
3773.79	10.3813
3777.6	5.64038
3781.41	6.32733
3785.21	11.2289
3789.01	16.7931
3792.81	3.06067
3796.6	2.78265
3800.39	13.5299
3804.18	26.4094
3807.97	27.5168
3811.76	19.6147
3815.54	7.02637
3819.32	-2.30988
3823.1	0.858215
3826.87	7.38635
3830.65	10.0975
3834.42	15.942
3838.18	17.0128
3841.95	14.3043
3845.71	14.1838
3849.48	15.0882
3853.23	16.0612
3856.99	19.7358
3860.74	25.2365
3864.5	26.0447
3868.24	23.8089
3871.99	21.9891
3875.74	13.256
3879.48	11.5931
3883.22	13.1313
3886.95	14.0947
3890.69	15.7397
3894.42	19.243
3898.15	25.1395
3901.88	24.651
3905.61	23.6271
3909.33	25.3436
3913.05	23.9542
3916.77	23.492
3920.48	18.3823
3924.2	14.7726
3927.91	13.7798
3931.62	13.9642
3935.32	12.3494
3939.03	9.94464
3942.73	8.75226
3946.43	9.87292
3950.13	11.9521
3953.82	15.9996
3957.51	20.6382
3961.2	22.0181
3964.89	21.117
3968.58	12.9015
3972.26	7.01825
3975.94	2.6546
3979.62	-0.0360107
3983.3	0.558411
3986.97	0.00158691
3990.64	-0.980042
3994.31	-0.604004
3997.98	1.1485
3999.81	6.38068