File: Data/Raman/processed/muscovite_150 (500nm)_633nm_edge_100%_x50_vis_lwd_h30um_15sx2_01.txt
#Acq. time (s)=	15
#Accumulations=	2
#Range (cm-¹)=	100...4000
#Windows=	1
#Auto scanning=	Off
#Autofocus=	Off
#Macrospot=	Off
#AutoExposure=	Off
#Spike filter=	Multiple accum.
#Delay time (s)=	2
#Binning=	1
#Readout mode=	Signal
#DeNoise=	Standard
#ICS correction=	On
#Dark correction=	Off
#Inst. Process=	Off
#Detector Gain=	Best Dynamic
#Detector ADC=	50 kHz EM
#Detector EM gain=	500
#Detector temperature (°C)=	-60.09
#Instrument=	LabRAM HR Evol
#Detector=	SIN-EM FIVIS
#Objective=	x50_VIS_LWD
#Grating=	150 (500nm)
#ND Filter=	100%
#Laser=	633nm_Edge
#Hole=	30.0125
#Temperature=	0
#Range=	Visible
#StageXY=	75x50mm Scan+
#StageZ=	Z motor
#X (µm)=	0
#Y (µm)=	0
#Z (µm)=	-2.1
#Full time(s)=	34
#Project=	20_11_11
#Sample=	BU18FA04
#Site=
#Title=	BU04-area1-mid_beige_150 (500nm)_633nm_Edge_100%_x50_VIS_LWD_H30um_15sX2
#Remark=
#Date=	11.11.2020 17:42
#Acquired=	11.11.2020 17:42:54
#Data Range:Extract=	01.07.2021 19:23:37
#Base:Fit=	01.07.2021 19:24:15
#Base:Fit=	01.07.2021 19:24:39
#Base:Fit=	01.07.2021 19:24:47
#Base:Sub=	01.07.2021 19:24:50
100.804	3573.44
107.32	2649.29
113.83	847.599
120.336	464.596
126.836	311.121
133.33	183.972
139.819	61.5947
146.303	-2.92969
152.781	-1.07813
159.254	48.1182
165.722	125.157
172.184	290.2
178.64	511.252
185.091	770.604
191.538	1383.63
197.979	1759.14
204.414	1422.84
210.843	871.414
217.268	476.288
223.688	143.905
230.103	-1.58789
236.51	10.7178
242.914	185.149
249.313	788.189
255.705	2300.75
262.093	5297.29
268.475	4558.04
274.852	1856.75
281.225	857.202
287.59	495.48
293.952	307.937
300.308	240.508
306.658	195.646
313.004	167.076
319.344	150.768
325.68	120.027
332.009	88.124
338.335	65.2373
344.654	62.5449
350.968	88.6445
357.278	148.269
363.581	240.303
369.88	362.007
376.173	514.063
382.462	675.314
388.745	868.071
395.023	1084.03
401.296	1351.54
407.564	1410.49
413.826	1244.73
420.085	921.955
426.337	622.729
432.585	355.697
438.827	194.613
445.064	78.6846
451.296	13.9033
457.523	-5.73633
463.745	17.3574
469.962	60.3945
476.174	96.5
482.381	123.73
488.581	145.064
494.778	152.112
500.97	129.159
507.157	95.0088
513.338	70.0703
519.515	58.126
525.686	57.7939
531.852	69.9082
538.014	90.1875
544.171	112.02
550.322	125.834
556.469	130.706
562.611	125.651
568.746	112.771
574.878	113.597
581.004	170.421
587.126	114.5
593.244	91.0596
599.355	293.69
605.462	453.221
611.563	341.557
617.661	365.549
623.752	593.471
629.839	715.385
635.922	705.423
641.999	618.28
648.072	485.735
654.139	368.669
660.201	298.735
666.26	273.793
672.312	336.725
678.36	479.361
684.403	750.212
690.442	1222.92
696.475	1920.57
702.503	2002.84
708.527	1517.06
714.546	1019.72
720.56	612.69
726.569	486.671
732.574	422.268
738.574	461.308
744.569	557.408
750.559	648.49
756.544	719.702
762.524	708.566
768.5	599.174
774.47	500.962
780.436	382.738
786.398	276.85
792.354	204.826
798.306	164.867
804.254	160.787
810.196	165.968
816.133	143.358
822.066	120.379
827.995	99.667
833.918	72.957
839.836	32.1748
845.751	-8.80957
851.66	-13.5303
857.564	-7.47754
863.465	4.24121
869.359	21.5977
875.25	47.5801
881.137	72.4824
887.017	109.495
892.894	160.591
898.766	211.818
904.634	255.402
910.496	277.794
916.353	248.678
922.207	225.454
928.055	207.861
933.9	175.599
939.739	166.563
945.573	178.711
951.403	192.078
957.23	200.485
963.051	204.678
968.867	200.53
974.678	187.936
980.487	167.479
986.289	115.056
992.087	88.1045
997.88	94.7471
1003.67	128.69
1009.45	188.861
1015.23	270.647
1021.01	338.143
1026.78	374.777
1032.55	377.212
1038.31	359.992
1044.06	357.787
1049.82	378.274
1055.57	416.009
1061.31	441.422
1067.05	438.435
1072.78	389.976
1078.51	309.542
1084.24	234.998
1089.96	185.341
1095.68	157.285
1101.39	150.107
1107.1	162.556
1112.8	194.639
1118.5	240.304
1124.19	257.735
1129.88	236.777
1135.57	221.448
1141.25	202.622
1146.93	171.341
1152.6	125.189
1158.27	69.3486
1163.93	40.0869
1169.59	35.1016
1175.24	39.5088
1180.89	20.0166
1186.54	29.4609
1192.18	74.6563
1197.82	124.742
1203.45	172.489
1209.08	214.284
1214.7	248.266
1220.32	272.66
1225.94	288.578
1231.55	302.43
1237.16	316.651
1242.76	320.681
1248.36	281.457
1253.95	231.031
1259.54	184.127
1265.12	147.857
1270.7	117.725
1276.28	82.5908
1281.85	102.956
1287.42	167.45
1292.98	258.431
1298.54	311.016
1304.1	342.098
1309.65	361.654
1315.19	367.154
1320.73	346.284
1326.27	323.56
1331.81	302.762
1337.33	266.047
1342.86	208.705
1348.38	139.672
1353.9	83.3848
1359.41	60.4277
1364.92	58.1201
1370.42	64.9463
1375.92	66.4736
1381.41	69.6768
1386.91	61.9893
1392.39	49.8066
1397.88	48.583
1403.35	40.79
1408.83	58.9131
1414.3	90.4443
1419.76	115.896
1425.22	125.74
1430.68	124.956
1436.14	134.705
1441.58	148.692
1447.03	178.053
1452.47	196.138
1457.91	202.049
1463.34	194.518
1468.77	168.365
1474.19	143.911
1479.61	140.896
1485.03	145.238
1490.44	157.692
1495.85	168.051
1501.25	169.223
1506.65	161.583
1512.05	147.576
1517.44	135.726
1522.82	148.018
1528.21	166.499
1533.59	183.676
1538.96	207.392
1544.33	228.635
1549.7	236.224
1555.06	235.72
1560.42	236.226
1565.77	247.032
1571.13	257.771
1576.47	272.974
1581.81	248.35
1587.15	210.595
1592.49	183.249
1597.82	156.601
1603.14	133.024
1608.47	111.675
1613.78	165.42
1619.1	-83.4443
1624.41	309.081
1629.71	346.813
1635.02	340.748
1640.31	328.061
1645.61	306.011
1650.9	341.572
1656.19	333.196
1661.47	305.152
1666.75	270.414
1672.02	233.755
1677.29	194.937
1682.56	155.095
1687.82	116.519
1693.08	92.6621
1698.33	115.388
1703.58	155.307
1708.83	201.687
1714.07	252.311
1719.31	298.989
1724.55	335.197
1729.78	344.091
1735	313.226
1740.23	248.73
1745.45	156.776
1750.66	65.4541
1755.87	9.55762
1761.08	-14.4365
1766.29	-7.5918
1771.48	11.5283
1776.68	46.1543
1781.87	70.9258
1787.06	59.9541
1792.24	47.6064
1797.42	50.541
1802.6	66.6025
1807.77	92.7539
1812.94	125.759
1818.11	153.659
1823.27	178.86
1828.43	182.159
1833.58	153.436
1838.73	97.458
1843.87	47.3799
1849.02	15.9258
1854.16	7.86133
1859.29	22.6514
1864.42	51.3525
1869.55	123.714
1874.67	158.38
1879.79	166.729
1884.9	163.603
1890.02	96.9541
1895.12	78.8916
1900.23	108.912
1905.33	199.822
1910.42	209.263
1915.52	171.984
1920.61	103.893
1925.69	9.43945
1930.77	28.9277
1935.85	48.9141
1940.92	60.75
1945.99	79.541
1951.06	101.061
1956.12	121.113
1961.18	136.975
1966.24	148.545
1971.29	153.228
1976.34	152.027
1981.38	167.589
1986.42	138.731
1991.46	108.59
1996.49	100.313
2001.52	107.435
2006.55	126.419
2011.57	153.682
2016.59	182.59
2021.6	211.395
2026.61	221.723
2031.62	191.698
2036.62	136
2041.62	82.4209
2046.62	43.875
2051.61	21.418
2056.6	16.8926
2061.58	37.2012
2066.57	42.0205
2071.54	23.6309
2076.52	19.3555
2081.49	12.916
2086.46	21.0791
2091.42	44.9717
2096.38	77.4414
2101.34	117.941
2106.29	151.628
2111.24	160.256
2116.18	152.77
2121.12	152.604
2126.06	126.182
2131	88.7178
2135.93	59.4072
2140.85	34.3906
2145.78	18.3711
2150.7	3.44336
2155.62	-4.86035
2160.53	-5.63477
2165.44	-6.83398
2170.34	0.884766
2175.25	24.3164
2180.15	56.1621
2185.04	91.5938
2189.93	127.332
2194.82	173.27
2199.71	148.304
2204.59	142.063
2209.46	149.877
2214.34	149.968
2219.21	137.643
2224.08	131.664
2228.94	141.913
2233.8	137.113
2238.66	146.991
2243.51	154.915
2248.36	143.243
2253.2	119.756
2258.05	97.9824
2262.89	76.2148
2267.72	64.6602
2272.55	66.0156
2277.38	76.7285
2282.21	105.749
2287.03	137.756
2291.85	153.014
2296.66	147.5
2301.47	134.498
2306.28	127.29
2311.08	115.323
2315.88	124.296
2320.68	129.738
2325.48	133.983
2330.27	135.177
2335.05	122.177
2339.84	107.477
2344.62	89.73
2349.4	89.0439
2354.17	104.845
2358.94	135.032
2363.7	138.693
2368.47	129.748
2373.23	116.051
2377.98	106.161
2382.74	98.1123
2387.49	68.5132
2392.23	31.6572
2396.97	23.209
2401.71	46.4741
2406.45	89.2939
2411.18	140.66
2415.91	205.397
2420.64	269.674
2425.36	316.727
2430.08	343.806
2434.79	348.241
2439.51	335.159
2444.22	308.183
2448.92	267.315
2453.62	218.939
2458.32	205.589
2463.02	204.44
2467.71	213.99
2472.4	228.122
2477.09	246.639
2481.77	268.636
2486.45	309.06
2491.12	352.085
2495.8	383.481
2500.47	406.792
2505.13	409.757
2509.79	363.038
2514.45	283.751
2519.11	207.663
2523.76	147.938
2528.41	94.876
2533.06	43.9922
2537.7	46.1016
2542.34	97.3457
2546.98	148.598
2551.61	202.746
2556.24	249.146
2560.86	282.932
2565.49	296.789
2570.11	298.274
2574.72	290.275
2579.34	279.027
2583.95	262.578
2588.55	237.195
2593.16	210.948
2597.76	189.933
2602.36	176.576
2606.95	179.987
2611.54	220.649
2616.13	253.871
2620.71	273.351
2625.29	271.754
2629.87	255.373
2634.45	229.091
2639.02	199.287
2643.59	153.819
2648.15	170.423
2652.71	301.472
2657.27	318.077
2661.83	270.794
2666.38	170.776
2670.93	115.836
2675.47	98.6738
2680.02	86.7822
2684.56	93.4927
2689.09	133.557
2693.63	195.841
2698.16	268.241
2702.68	307.726
2707.21	271.734
2711.73	255.815
2716.24	240.424
2720.76	231.943
2725.27	225.8
2729.78	229.749
2734.28	250.722
2738.78	289.494
2743.28	328.642
2747.78	329.799
2752.27	325.895
2756.76	319.333
2761.25	306.534
2765.73	287.55
2770.21	261.555
2774.69	233.788
2779.16	230.785
2783.63	257.534
2788.1	299.713
2792.56	309.289
2797.02	309.185
2801.48	240.142
2805.94	163.35
2810.39	106.457
2814.84	52.9023
2819.28	-10.7002
2823.73	-13.1909
2828.16	7.02734
2832.6	31.7847
2837.04	62.7803
2841.47	97.9736
2845.89	136.184
2850.32	177.545
2854.74	223.287
2859.16	279.119
2863.57	318.148
2867.99	344.41
2872.39	291.238
2876.8	258.913
2881.2	235.128
2885.6	220.345
2890	222.995
2894.39	247.798
2898.79	303.101
2903.17	357.766
2907.56	352.857
2911.94	316.579
2916.32	258.993
2920.7	189.192
2925.07	141.133
2929.44	114.868
2933.81	111.571
2938.17	135.977
2942.53	184.839
2946.89	227.899
2951.24	243.904
2955.6	247.018
2959.94	247.128
2964.29	243.441
2968.63	203.889
2972.97	173.618
2977.31	176.773
2981.65	178.27
2985.98	177.512
2990.31	159.515
2994.63	142.938
2998.95	162.537
3003.27	162.738
3007.59	144.927
3011.9	132.614
3016.21	117.934
3020.52	97.3735
3024.83	65.022
3029.13	34.0161
3033.43	58.292
3037.72	88.0405
3042.02	113.168
3046.31	121.977
3050.59	156.415
3054.88	189.721
3059.16	213.104
3063.44	240.25
3067.71	213.711
3071.99	293.701
3076.26	218.535
3080.52	176.33
3084.79	174.062
3089.05	201.188
3093.31	139.792
3097.56	320.875
3101.81	306.937
3106.06	245.919
3110.31	156.151
3114.55	66.189
3118.79	89.0059
3123.03	118.305
3127.27	113.627
3131.5	147.375
3135.73	199.624
3139.96	233.386
3144.18	216.855
3148.4	169.646
3152.62	150.32
3156.83	140.49
3161.05	141.448
3165.26	146.484
3169.46	145.942
3173.67	131.511
3177.87	100.624
3182.07	80.5737
3186.26	75.2344
3190.46	76.4395
3194.65	80.8257
3198.83	83.9321
3203.02	88.584
3207.2	87.7793
3211.38	78.4385
3215.55	55.2651
3219.73	32.4644
3223.9	45.0391
3228.06	18.0137
3232.23	43.3628
3236.39	75.7344
3240.55	114.015
3244.71	179.87
3248.86	188.799
3253.01	155.011
3257.16	148.655
3261.3	145.099
3265.44	149.943
3269.58	164.951
3273.72	185.259
3277.86	216.385
3281.99	263.555
3286.12	305.6
3290.24	319.882
3294.36	299.776
3298.48	251.996
3302.6	179.043
3306.72	113.399
3310.83	138.613
3314.94	112.441
3319.05	77.8721
3323.15	88.0537
3327.25	104.013
3331.35	135.514
3335.45	191.341
3339.54	260.736
3343.63	319.554
3347.72	347.451
3351.8	314.985
3355.88	252.532
3359.96	194.763
3364.04	134.967
3368.11	75.8374
3372.19	45.8354
3376.25	19.4492
3380.32	1.41016
3384.38	-5.84961
3388.44	-1.64795
3392.5	18.6426
3396.56	52.207
3400.61	91.0273
3404.66	135.751
3408.71	171.608
3412.75	168.354
3416.79	129.35
3420.83	111.754
3424.87	65.7354
3428.9	11.2588
3432.93	7.10254
3436.96	18.5151
3440.99	20.1089
3445.01	10.1748
3449.03	-12.9873
3453.05	-18.4937
3457.07	3.91162
3461.08	56.8481
3465.09	109.269
3469.1	173.604
3473.1	192.777
3477.1	180.118
3481.1	141.469
3485.1	86.7651
3489.09	65.4233
3493.08	103.021
3497.07	120.06
3501.06	133.363
3505.04	125.789
3509.03	121.284
3513	117.983
3516.98	114.512
3520.95	146.345
3524.92	150.547
3528.89	125.572
3532.86	101.93
3536.82	97.9976
3540.78	92.1367
3544.74	66.2275
3548.69	65.2256
3552.65	84.9653
3556.6	102.738
3560.55	88.748
3564.49	62.8213
3568.43	29.4888
3572.37	3.73486
3576.31	-4.49268
3580.24	5.63574
3584.18	48.9048
3588.11	93.5054
3592.03	138.566
3595.96	185.568
3599.88	238.643
3603.8	304.26
3607.71	386.347
3611.63	487.011
3615.54	598.751
3619.45	711.818
3623.36	816.21
3627.26	826.486
3631.16	789.316
3635.06	727.801
3638.96	657.222
3642.85	614.356
3646.74	580.404
3650.63	550.46
3654.52	529.243
3658.4	481.692
3662.28	393.621
3666.16	296.44
3670.04	234.152
3673.91	171.066
3677.78	125.578
3681.65	113.062
3685.52	93.4224
3689.38	71.2515
3693.24	21.0132
3697.1	-9.14502
3700.96	-1.37598
3704.81	23.4961
3708.66	38.5327
3712.51	30.769
3716.36	58.7803
3720.2	76.7524
3724.05	92.3452
3727.88	99.3389
3731.72	127.463
3735.56	166.144
3739.39	197.623
3743.22	254.908
3747.04	230.545
3750.87	102.825
3754.69	27.4253
3758.51	18.8042
3762.32	104.685
3766.14	185.844
3769.95	213.849
3773.76	155.149
3777.57	103.414
3781.37	69.0264
3785.17	81.4663
3788.97	127.483
3792.77	164.602
3796.57	208.043
3800.36	240.002
3804.15	236.239
3807.94	188.462
3811.72	100.653
3815.5	31.6501
3819.28	2.13477
3823.06	-9.31226
3826.84	44.9434
3830.61	127.122
3834.38	179.347
3838.15	190.884
3841.92	181.952
3845.68	157.684
3849.44	119.923
3853.2	87.4082
3856.96	69.8823
3860.71	66.5703
3864.46	80.6296
3868.21	120.103
3871.96	98.2412
3875.7	73.7656
3879.44	152.79
3883.18	213.112
3886.92	248.906
3890.66	251.749
3894.39	164.288
3898.12	163.188
3901.85	203.878
3905.57	235.942
3909.29	258.824
3913.02	270.318
3916.73	240.432
3920.45	202.586
3924.16	106.503
3927.88	36.5286
3931.58	29.8457
3935.29	86.6201
3938.99	152.341
3942.7	224.653
3946.4	244.743
3950.09	237.241
3953.79	179.658
3957.48	169.731
3961.17	170.813
3964.86	174.546
3968.54	172.551
3972.23	156.672
3975.91	110.933
3979.59	75.2588
3983.26	33.0244
3986.94	-8.77515
3990.61	8.42944
3994.28	77.6348
3997.95	185.349
3999.78	221.748