File: Data/Raman/processed/quartz_150 (500nm)_532nm_Edge_50%_x50_VIS_LWD_H50um_20sX2.txt
#Acq. time (s)=	20
#Accumulations=	2
#Range (cm-¹)=	100...5300
#Windows=	1
#Auto scanning=	Off
#Autofocus=	Off
#Macrospot=	Off
#AutoExposure=	Off
#Spike filter=	Single accum. (Size=4)
#Delay time (s)=	0
#Binning=	1
#Readout mode=	Signal
#DeNoise=	Standard
#ICS correction=	On
#Dark correction=	Off
#Inst. Process=	On
#Detector Gain=	Best Dynamic
#Detector ADC=	50 kHz HS
#Detector temperature (°C)=	-60.09
#Instrument=	LabRAM HR Evol
#Detector=	SIN-EM FIVIS
#Objective=	x50_VIS_LWD
#Grating=	150 (500nm)
#ND Filter=	50%
#Laser=	532nm_Edge
#Hole=	49.98
#Temperature=	0
#Range=	Visible
#StageXY=	75x50mm Scan+
#StageZ=	Z motor
#X (µm)=	0
#Y (µm)=	0
#Z (µm)=	83.7
#Project=	20_05_11
#Sample=	BU19w
#Site=
#Title=	BU19w-area5_quartz_mid_150 (500nm)_532nm_Edge_50%_x50_VIS_LWD_H50um_20sX2
#Remark=
#Date=	11.05.2020 11:57
#Acquired=	11.05.2020 11:57:49
#Data Range:Extract=	01.07.2021 19:23:36
#Base:Fit=	01.07.2021 19:24:15
#Base:Fit=	01.07.2021 19:24:39
#Base:Fit=	01.07.2021 19:24:47
#Base:Sub=	01.07.2021 19:24:50
100.18	0.3349
104.803	-0.339905
109.425	4.03491
114.045	21.2073
118.662	59.4661
123.277	122.726
127.888	364.842
132.499	1527.44
137.107	2552.37
141.713	1158.73
146.315	408.199
150.917	288.225
155.516	274.982
160.113	235.92
164.706	206.643
169.298	203.729
173.888	230.679
178.476	288.866
183.06	365.677
187.644	483.891
192.225	659.359
196.804	935.485
201.378	1439.42
205.953	2155.87
210.525	2951.9
215.093	3406.28
219.661	3101.67
224.226	2337.22
228.789	1629.69
233.348	1130.02
237.907	811.159
242.463	602.295
247.015	447.902
251.568	348.997
256.117	292.123
260.663	281.786
265.208	310.677
269.749	584.527
274.29	676.294
278.829	324.163
283.363	125.347
287.897	74.4832
292.429	54.8373
296.957	53.0132
301.484	44.6104
306.008	31.3764
310.531	23.6636
315.052	13.3843
319.568	12.6339
324.085	11.563
328.597	13.567
333.109	12.4817
337.619	15.9442
342.124	21.2767
346.63	33.8616
351.131	62.4341
355.632	151.327
360.129	590.504
364.626	737.492
369.12	230.981
373.61	64.3294
378.1	23.5372
382.586	5.08734
387.072	6.64087
391.553	32.5723
396.035	109.953
400.512	388.223
404.989	288.596
409.462	172.99
413.934	88.8038
418.403	47.0842
422.871	37.2891
427.335	46.0618
431.799	57.2283
436.259	76.2038
440.718	107.057
445.174	157.477
449.629	253.053
454.08	473.073
458.531	848.781
462.978	1966.1
467.422	5625.35
471.867	11764.6
476.307	9714.84
480.747	4370.52
485.183	2069.31
489.619	1264.76
494.051	801.388
498.482	582.603
502.91	428.174
507.335	335.265
511.76	279.912
516.181	251.986
520.602	235.006
525.019	230.067
529.433	213.04
533.848	186.429
538.258	162.695
542.666	141.455
547.074	122.767
551.478	106.337
555.88	91.679
560.282	79.1127
564.679	68.7733
569.077	59.3036
573.47	51.0283
577.861	44.8931
582.252	41.0792
586.639	39.9147
591.024	39.4244
595.407	39.075
599.789	38.8174
604.168	38.4668
608.544	38.0766
612.92	37.326
617.293	36.5939
621.663	34.1161
626.033	31.4827
630.398	28.595
634.762	25.4534
639.124	22.1848
643.486	18.6399
647.843	15.2324
652.198	11.6827
656.552	8.16498
660.905	4.39838
665.254	1.09875
669.601	-1.75128
673.946	0.212952
678.291	6.77417
682.632	0.402222
686.97	6.68738
691.307	4.802
695.642	39.4808
699.976	90.7388
704.307	145.527
708.635	95.4402
712.961	51.2935
717.285	32.6553
721.609	21.3615
725.93	17.3884
730.248	14.7906
734.563	10.7334
738.877	7.63428
743.189	6.49127
747.501	6.99023
751.809	5.05408
756.114	3.44293
760.418	2.83142
764.719	3.46252
769.019	3.92871
773.316	5.24109
777.612	7.89148
781.907	11.8859
786.198	20.0866
790.487	29.4177
794.775	39.6274
799.06	51.9012
803.343	69.8038
807.624	122.836
811.903	300.742
816.18	397.283
820.455	214.696
824.728	93.4701
829.001	66.0367
833.27	52.4418
837.536	40.5338
841.801	35.4451
846.064	28.5923
850.325	24.6472
854.584	23.4272
858.84	20.7618
863.095	20.2678
867.348	22.7476
871.598	23.2073
875.847	19.5948
880.094	17.9038
884.338	13.8915
888.581	15.0811
892.822	20.0762
897.06	22.7561
901.297	24.5255
905.531	24.8176
909.764	23.5568
913.994	21.3763
918.223	19.215
922.45	17.3419
926.674	15.5743
930.895	14.2745
935.115	13.1207
939.334	12.1962
943.551	11.1683
947.765	10.1733
951.978	9.2262
956.188	8.20105
960.397	7.17932
964.604	5.84473
968.808	4.69788
973.011	3.43286
977.212	2.08496
981.409	0.817505
985.605	-0.345825
989.8	-0.854248
993.993	-0.555054
998.184	-0.0957031
1002.37	0.194336
1006.56	0.314697
1010.74	0.431763
1014.93	0.291992
1019.11	0.175659
1023.29	0.0914307
1027.46	0.124023
1031.64	0.317627
1035.81	0.59314
1039.98	-1.67407
1044.15	-1.3866
1048.32	0.777222
1052.48	3.80188
1056.64	7.71326
1060.8	12.238
1064.96	19.3666
1069.12	25.575
1073.28	31.2256
1077.43	35.4559
1081.58	37.3335
1085.73	37.6095
1089.88	36.1213
1094.02	34.7719
1098.17	28.1602
1102.31	23.9264
1106.45	18.9152
1110.58	11.6752
1114.72	6.03223
1118.85	4.42847
1122.99	6.52844
1127.11	7.17627
1131.24	12.2466
1135.37	16.5071
1139.49	15.8364
1143.61	16.9796
1147.73	18.0801
1151.85	32.0234
1155.97	57.4773
1160.08	99.6586
1164.2	217.795
1168.31	266.859
1172.41	179.503
1176.52	79.9421
1180.63	40.3612
1184.73	22.2993
1188.83	11.7217
1192.93	6.12659
1197.03	4.10999
1201.12	4.60522
1205.21	6.41101
1209.31	10.0469
1213.39	11.7668
1217.48	17.8735
1221.57	24.5952
1225.65	32.3829
1229.73	38.9132
1233.81	43.9426
1237.89	47.7834
1241.97	49.7056
1246.04	49.228
1250.11	45.2064
1254.18	40.7942
1258.25	35.9725
1262.32	31.1821
1266.38	26.4302
1270.44	21.8468
1274.51	17.6674
1278.56	13.726
1282.62	10.3256
1286.68	7.53723
1290.73	6.44287
1294.78	5.78381
1298.83	5.2323
1302.88	4.18848
1306.92	3.73071
1310.97	3.35291
1315.01	3.26636
1319.05	3.09558
1323.09	2.72852
1327.12	1.72498
1331.16	-2.9303
1335.19	-2.36536
1339.22	-1.57141
1343.25	-0.487183
1347.28	0.638184
1351.3	2.12537
1355.32	4.09058
1359.35	5.86304
1363.37	7.14185
1367.38	6.54993
1371.4	5.81921
1375.41	5.42273
1379.43	5.6886
1383.44	6.11035
1387.44	6.47095
1391.45	6.75488
1395.45	7.07642
1399.46	7.43298
1403.46	7.8324
1407.46	8.50598
1411.46	9.18726
1415.45	10.3529
1419.44	11.4309
1423.44	12.5667
1427.43	13.5673
1431.41	14.0891
1435.4	15.1392
1439.38	16.468
1443.37	17.9769
1447.35	19.2527
1451.33	20.3132
1455.3	21.0118
1459.28	21.0317
1463.25	20.314
1467.22	19.1974
1471.19	17.7028
1475.16	16.2251
1479.13	15.3917
1483.09	14.5336
1487.05	14.2996
1491.01	14.9009
1494.97	14.7611
1498.93	14.6737
1502.88	14.5927
1506.84	15.0941
1510.79	15.5435
1514.74	15.9244
1518.68	15.2939
1522.63	15.6237
1526.58	16.4288
1530.52	17.9465
1534.46	20.0204
1538.4	22.7081
1542.33	24.5615
1546.27	26.3003
1550.2	29.5845
1554.13	35.3513
1558.06	35.8091
1561.99	33.999
1565.92	30.3837
1569.84	28.0328
1573.76	25.3225
1577.69	24.868
1581.6	26.2124
1585.52	27.2211
1589.44	28.5559
1593.35	29.631
1597.26	30.3778
1601.17	31.0204
1605.08	31.6476
1608.99	32.1665
1612.89	32.6592
1616.79	33.3188
1620.69	34.1659
1624.59	34.8396
1628.49	35.1913
1632.39	35.573
1636.28	35.1305
1640.17	34.4418
1644.06	33.7043
1647.95	33.1377
1651.84	33.051
1655.72	32.7375
1659.61	32.1053
1663.49	31.3053
1667.37	29.9857
1671.25	28.4963
1675.12	26.5922
1679	24.4927
1682.87	22.1027
1686.74	19.8079
1690.61	17.8137
1694.48	16.3391
1698.34	15.6573
1702.21	15.0309
1706.07	14.8794
1709.93	15.0073
1713.79	15.3969
1717.65	16.0447
1721.5	17.1138
1725.35	18.5778
1729.2	20.2994
1733.05	22.5232
1736.9	24.7817
1740.75	27.0948
1744.59	29.3292
1748.44	31.3823
1752.28	33.3457
1756.12	34.5967
1759.96	35.3822
1763.79	35.8468
1767.63	36.0107
1771.46	36.2213
1775.29	36.2433
1779.12	36.0222
1782.95	35.8373
1786.77	36.0134
1790.6	36.5023
1794.42	37.0624
1798.24	37.3616
1802.06	37.5117
1805.87	37.4259
1809.69	37.2394
1813.5	36.8969
1817.31	36.3207
1821.12	35.6843
1824.93	34.897
1828.74	33.9646
1832.54	32.9553
1836.35	31.9807
1840.15	30.9579
1843.95	29.7683
1847.75	28.6255
1851.54	27.634
1855.34	26.9027
1859.13	26.4193
1862.92	26.1432
1866.71	26.2502
1870.5	26.9451
1874.28	27.6887
1878.07	28.6743
1881.85	29.6532
1885.63	30.7316
1889.41	31.7185
1893.19	32.4332
1896.96	33.0151
1900.74	33.3905
1904.51	33.7241
1908.28	33.7283
1912.05	33.6348
1915.82	33.671
1919.58	33.7079
1923.35	34.0798
1927.11	34.5079
1930.87	34.689
1934.63	35.0112
1938.39	35.5121
1942.14	35.9347
1945.89	36.1245
1949.65	35.8654
1953.4	34.6116
1957.15	32.4725
1960.89	30.3683
1964.64	28.2926
1968.38	26.5974
1972.13	24.9597
1975.87	24.002
1979.61	23.3799
1983.34	23.3303
1987.08	23.5957
1990.81	23.9104
1994.54	24.53
1998.27	24.8696
2002	26.8611
2005.73	27.8573
2009.45	28.0387
2013.18	27.8763
2016.9	27.2509
2020.62	26.2861
2024.34	25.2731
2028.06	24.3374
2031.77	23.4661
2035.49	22.6597
2039.2	22.1873
2042.91	22.1841
2046.62	22.228
2050.33	22.4272
2054.03	22.7834
2057.74	23.3502
2061.44	23.9136
2065.14	24.5519
2068.84	25.1162
2072.53	25.7186
2076.23	26.0769
2079.92	26.3542
2083.62	26.6306
2087.31	27.3909
2091	29.114
2094.68	29.6667
2098.37	29.3441
2102.05	28.9802
2105.74	27.6638
2109.42	25.824
2113.1	23.9515
2116.77	22.2107
2120.45	21.6415
2124.12	21.4941
2127.8	21.5969
2131.47	22.4933
2135.14	23.4124
2138.81	24.0385
2142.47	24.406
2146.14	24.3756
2149.8	24.2661
2153.46	23.9904
2157.12	23.5353
2160.78	23.2246
2164.43	22.6448
2168.09	22.384
2171.74	22.4568
2175.4	22.7876
2179.04	23.5253
2182.69	25.0377
2186.34	26.5266
2189.99	28.0829
2193.63	29.454
2197.27	30.6171
2200.91	31.106
2204.55	31.1602
2208.19	30.6055
2211.82	29.7461
2215.46	28.5535
2219.09	27.2047
2222.72	25.7799
2226.35	24.6569
2229.98	24.5476
2233.6	25.2324
2237.23	26.4056
2240.85	27.8671
2244.47	29.41
2248.09	30.629
2251.71	31.3041
2255.33	31.3383
2258.94	30.9928
2262.55	30.5294
2266.17	30.0276
2269.78	29.5345
2273.38	29.0774
2276.99	28.7074
2280.6	28.3766
2284.2	28.0626
2287.8	27.9414
2291.4	27.6151
2295	28.0837
2298.6	28.5854
2302.2	29.2584
2305.79	29.4272
2309.38	29.5823
2312.97	28.5227
2316.56	26.4246
2320.15	23.9482
2323.74	20.943
2327.32	17.7729
2330.9	15.006
2334.49	12.1549
2338.07	9.25598
2341.64	6.86877
2345.22	5.21594
2348.8	4.71399
2352.37	6.00891
2355.94	8.52344
2359.51	10.4883
2363.08	11.9858
2366.65	13.2668
2370.22	14.5081
2373.78	15.6571
2377.34	16.8392
2380.91	17.9744
2384.47	19.0304
2388.02	19.8665
2391.58	20.4875
2395.14	20.8057
2398.69	20.8433
2402.24	20.52
2405.79	19.7816
2409.34	18.5676
2412.89	17.4044
2416.43	16.4828
2419.98	15.8329
2423.52	15.4335
2427.06	15.3975
2430.6	15.8875
2434.14	16.6504
2437.68	17.531
2441.21	18.4021
2444.75	18.9995
2448.28	19.8406
2451.81	20.2415
2455.34	20.4924
2458.87	20.4222
2462.39	19.8777
2465.92	18.9819
2469.44	17.9589
2472.96	16.8904
2476.48	16.009
2480	14.3707
2483.51	11.9558
2487.03	8.89075
2490.54	5.98145
2494.05	3.57996
2497.57	1.96375
2501.08	1.00305
2504.58	0.320068
2508.09	-0.21814
2511.59	-0.560547
2515.1	-0.688721
2518.6	-0.462158
2522.1	0.417236
2525.6	2.61987
2529.09	5.27991
2532.59	7.72278
2536.08	9.94397
2539.58	11.5383
2543.07	12.7896
2546.55	13.9856
2550.04	14.6547
2553.53	15.1141
2557.01	15.6134
2560.5	16.0795
2563.98	16.6373
2567.46	17.0212
2570.94	17.483
2574.42	17.9794
2577.89	18.3704
2581.37	18.6946
2584.84	18.8365
2588.31	18.833
2591.78	18.6678
2595.25	18.4999
2598.72	18.1552
2602.18	17.8008
2605.64	17.0497
2609.11	16.1141
2612.57	15.0654
2616.03	14.1406
2619.49	13.1218
2622.94	11.5853
2626.4	10.1489
2629.85	9.25
2633.3	8.3866
2636.75	7.47607
2640.2	6.63245
2643.65	5.80188
2647.1	4.79919
2650.54	3.11218
2653.98	2.44897
2657.42	1.95984
2660.87	2.0697
2664.3	2.12915
2667.74	2.26685
2671.18	2.39746
2674.61	2.51965
2678.04	2.52234
2681.47	2.64319
2684.9	2.91321
2688.33	2.85974
2691.76	2.79639
2695.19	3.11279
2698.61	3.64355
2702.03	4.82776
2705.45	5.58423
2708.87	6.57703
2712.29	7.68616
2715.71	8.61768
2719.12	9.52942
2722.54	10.2252
2725.95	10.7949
2729.36	11.218
2732.77	11.455
2736.18	11.2372
2739.58	10.9066
2742.99	10.3298
2746.39	10.1648
2749.79	9.9928
2753.19	9.91028
2756.59	9.93396
2759.99	9.97559
2763.39	10.1985
2766.78	10.4065
2770.18	10.8247
2773.57	11.2438
2776.96	11.6183
2780.35	11.8698
2783.73	12.0067
2787.12	12.363
2790.5	12.0638
2793.89	11.2461
2797.27	10.5881
2800.65	10.079
2804.03	9.13196
2807.41	8.82104
2810.78	9.03748
2814.16	9.46265
2817.53	9.96228
2820.9	10.5641
2824.27	11.4218
2827.64	12.3789
2831.01	13.3123
2834.38	14.1614
2837.74	15.0043
2841.1	15.7452
2844.46	16.3855
2847.82	16.8063
2851.18	17.2814
2854.54	17.7562
2857.9	17.8958
2861.25	17.9039
2864.61	17.6791
2867.96	17.1349
2871.31	15.9442
2874.66	14.7676
2878	13.6786
2881.35	12.6555
2884.69	11.9331
2888.04	11.1456
2891.38	10.5148
2894.72	10.1119
2898.06	9.71191
2901.4	9.39856
2904.73	9.38037
2908.07	9.78162
2911.4	10.3242
2914.73	11.255
2918.06	12.2739
2921.39	13.249
2924.72	14.4044
2928.05	15.7881
2931.37	16.7832
2934.7	17.3616
2938.02	17.4103
2941.34	17.2295
2944.66	16.5742
2947.98	15.7252
2951.29	14.7433
2954.61	13.4481
2957.92	12.189
2961.23	10.4551
2964.55	9.20911
2967.85	8.79211
2971.16	8.78943
2974.47	9.15271
2977.78	10.0608
2981.08	13.0607
2984.38	14.8199
2987.68	16.2051
2990.98	17.2175
2994.28	17.5369
2997.58	17.2156
3000.87	16.4897
3004.17	15.3505
3007.46	14.0664
3010.75	12.6757
3014.04	11.1096
3017.33	9.02075
3020.62	6.9187
3023.9	4.87317
3027.19	3.32971
3030.47	2.15442
3033.76	1.43103
3037.04	1.20959
3040.31	1.4917
3043.59	2.04883
3046.87	2.94763
3050.14	3.96692
3053.42	5.00818
3056.69	6.11023
3059.96	6.91858
3063.23	7.30786
3066.5	7.93616
3069.77	8.36755
3073.03	8.74414
3076.29	8.72791
3079.56	8.50061
3082.82	8.03174
3086.08	7.36658
3089.34	6.60901
3092.59	5.84058
3095.85	5.03418
3099.1	4.39612
3102.36	3.66199
3105.61	2.87073
3108.86	1.80127
3112.11	0.682617
3115.36	-0.508057
3118.6	-1.68982
3121.85	0.568848
3125.09	0.947388
3128.33	0.489136
3131.57	-0.201538
3134.82	-0.549194
3138.05	-0.494751
3141.29	-0.263184
3144.53	0.62439
3147.76	1.30945
3150.99	1.90515
3154.22	2.55798
3157.45	3.71338
3160.68	4.51367
3163.91	5.13013
3167.14	5.46948
3170.36	5.3551
3173.59	6.39355
3176.81	5.90906
3180.03	4.82471
3183.25	3.82446
3186.47	2.95105
3189.68	1.84375
3192.9	0.788452
3196.11	-0.00311279
3199.32	-0.17688
3202.54	-0.103638
3205.75	0.0587158
3208.96	0.125916
3212.16	0.254578
3215.37	0.563538
3218.57	0.97522
3221.78	1.33594
3224.98	1.66846
3228.18	1.84558
3231.38	1.78259
3234.58	1.771
3237.77	1.77148
3240.97	1.77344
3244.16	1.86786
3247.36	1.85712
3250.55	2.16083
3253.74	2.46545
3256.93	3.17358
3260.12	4.46448
3263.3	5.64404
3266.49	6.61969
3269.67	7.61499
3272.85	8.15088
3276.03	8.57935
3279.21	8.89703
3282.39	9.11981
3285.57	9.2663
3288.75	9.37372
3291.92	9.33002
3295.09	9.09698
3298.26	8.73248
3301.44	8.32336
3304.6	7.99762
3307.77	7.91394
3310.94	7.78589
3314.1	7.69452
3317.27	7.47546
3320.43	7.01294
3323.59	6.22919
3326.75	4.84833
3329.91	3.6004
3333.07	2.71753
3336.23	1.61157
3339.38	0.630188
3342.53	-0.351868
3345.69	-0.668884
3348.84	-0.821777
3351.99	-0.458252
3355.14	1.03381
3358.28	3.56042
3361.43	7.02777
3364.57	10.3369
3367.72	13.2893
3370.86	15.6731
3374	17.2835
3377.14	18.4062
3380.28	18.8763
3383.41	18.312
3386.55	16.0983
3389.68	13.2242
3392.82	11.4424
3395.95	10.8234
3399.08	11.1103
3402.21	10.5505
3405.33	9.54999
3408.46	8.39886
3411.59	7.17651
3414.71	6.55524
3417.83	6.07672
3420.95	5.75543
3424.07	5.40509
3427.19	4.90436
3430.31	4.47205
3433.43	4.02924
3436.54	3.69916
3439.66	3.34174
3442.77	2.91724
3445.88	2.08606
3448.99	1.16998
3452.1	0.509766
3455.21	-0.256592
3458.31	-0.320862
3461.42	-0.384766
3464.52	-0.400024
3467.62	-0.605713
3470.72	-0.865601
3473.82	-0.979858
3476.92	-0.922119
3480.02	-0.58783
3483.12	0.223999
3486.21	1.17249
3489.3	2.23553
3492.4	3.32642
3495.49	4.63141
3498.58	5.46234
3501.67	6.17938
3504.75	6.77496
3507.84	7.21967
3510.92	7.60803
3514.01	7.87653
3517.09	8.08728
3520.17	8.16504
3523.25	8.20667
3526.33	8.09265
3529.41	7.64972
3532.48	6.55133
3535.56	6.42859
3538.63	6.41779
3541.7	6.64258
3544.77	6.82379
3547.84	6.8717
3550.91	6.95917
3553.98	7.05157
3557.05	7.41602
3560.11	7.4693
3563.17	7.8255
3566.24	7.74109
3569.3	7.7381
3572.36	7.57257
3575.42	7.47272
3578.47	7.33807
3581.53	6.6759
3584.58	6.00946
3587.64	5.33813
3590.69	4.74573
3593.74	4.35065
3596.79	4.32257
3599.84	4.59265
3602.89	4.91461
3605.93	5.53107
3608.98	6.52606
3612.02	7.44403
3615.06	8.22144
3618.1	8.81012
3621.15	9.09143
3624.18	8.90802
3627.22	8.61121
3630.26	7.82379
3633.29	6.87585
3636.33	5.80396
3639.36	4.70697
3642.39	3.45801
3645.42	2.39478
3648.45	1.56183
3651.48	1.34821
3654.5	1.37445
3657.53	1.63635
3660.55	1.8363
3663.58	2.07092
3666.6	1.80835
3669.62	2.22864
3672.64	2.77527
3675.66	3.39325
3678.67	4.0329
3681.69	4.54926
3684.7	4.88092
3687.72	5.23193
3690.73	5.78693
3693.74	6.63885
3696.75	7.59705
3699.76	8.98926
3702.76	10.4192
3705.77	11.7598
3708.77	12.3962
3711.78	12.7193
3714.78	12.5569
3717.78	12.0563
3720.78	10.7951
3723.78	9.0423
3726.78	7.14368
3729.77	5.24585
3732.77	3.48895
3735.76	1.88184
3738.76	0.43866
3741.75	-0.618286
3744.74	-1.21429
3747.73	-1.53735
3750.71	-1.59515
3753.7	-1.3429
3756.69	-0.618103
3759.67	0.24469
3762.65	1.11322
3765.64	1.72302
3768.62	2.32617
3771.6	2.90155
3774.57	3.21722
3777.55	3.20746
3780.53	3.12799
3783.5	2.99689
3786.48	2.95374
3789.45	3.3208
3792.42	4.11035
3795.39	4.45563
3798.36	4.56323
3801.33	4.27588
3804.29	3.38855
3807.26	2.08813
3810.22	1.32678
3813.19	0.228699
3816.15	-0.2547
3819.11	0.0862427
3822.07	0.845581
3825.03	1.22839
3827.98	1.7326
3830.94	2.12921
3833.89	2.56012
3836.85	3.24127
3839.8	4.25354
3842.75	5.53192
3845.7	6.82562
3848.65	8.08966
3851.6	9.45758
3854.54	10.3032
3857.49	11.1839
3860.43	11.8218
3863.38	12.6325
3866.32	11.397
3869.26	7.9505
3872.2	5.65137
3875.14	3.84668
3878.07	2.52631
3881.01	1.43939
3883.94	0.762512
3886.88	0.495667
3889.81	2.46558
3892.74	5.76617
3895.67	6.85254
3898.6	6.98737
3901.53	6.5097
3904.46	6.50537
3907.38	4.81006
3910.3	3.79816
3913.23	2.52686
3916.15	1.47784
3919.07	0.523315
3921.99	-0.196289
3924.91	-0.616638
3927.83	-0.733398
3930.74	-0.656799
3933.66	-0.423218
3936.57	-0.109375
3939.48	-0.024353
3942.4	0.010437
3945.31	0.017334
3948.22	0.0912476
3951.12	-0.02948
3954.03	-0.168762
3956.94	-0.299866
3959.84	-0.37793
3962.75	-0.523254
3965.65	-0.239807
3968.55	0.298523
3971.45	0.865845
3974.35	1.4353
3977.25	2.14465
3980.14	2.79376
3983.04	3.44861
3985.93	4.04834
3988.83	4.30005
3991.72	3.85101
3994.61	3.35004
3997.5	2.73932
4000.39	2.03198