File: Data/Raman/processed/samuelsonite_150 (500nm)_633nm_Edge_100%_x50_VIS_LWD_H100um_15sX2.txt
#Acq. time (s)=	15
#Accumulations=	2
#Range (cm-¹)=	100...4000
#Windows=	1
#Auto scanning=	Off
#Autofocus=	Off
#Macrospot=	Off
#AutoExposure=	Off
#Spike filter=	Single accum. (Size=4)
#Delay time (s)=	0
#Binning=	1
#Readout mode=	Signal
#DeNoise=	Standard
#ICS correction=	On
#Dark correction=	Off
#Inst. Process=	On
#Detector Gain=	Best Dynamic
#Detector ADC=	50 kHz HS
#Detector temperature (°C)=	-60.09
#Instrument=	LabRAM HR Evol
#Detector=	SIN-EM FIVIS
#Objective=	x50_VIS_LWD
#Grating=	150 (500nm)
#ND Filter=	100%
#Laser=	633nm_Edge
#Hole=	100.021
#Temperature=	0
#Range=	Visible
#StageXY=	75x50mm Scan+
#StageZ=	Z motor
#X (µm)=	0
#Y (µm)=	0
#Z (µm)=	-23.9
#Project=	20_05_11
#Sample=	BU19TS
#Site=
#Title=	BU19TS-area5-samuelsonite_150 (500nm)_633nm_Edge_100%_x50_VIS_LWD_H100um_15sX2
#Remark=
#Date=	11.05.2020 19:35
#Acquired=	11.05.2020 19:35:43
#Data Range:Extract=	01.07.2021 19:23:36
#Base:Fit=	01.07.2021 19:24:15
#Base:Fit=	01.07.2021 19:24:39
#Base:Fit=	01.07.2021 19:24:47
#Base:Fit=	01.07.2021 19:25:04
#Base:Fit=	01.07.2021 19:25:10
#Base:Fit=	01.07.2021 19:25:18
#Base:Fit=	01.07.2021 19:25:26
#Base:Fit=	01.07.2021 19:25:33
#Base:Fit=	01.07.2021 19:25:34
#Base:Fit=	01.07.2021 19:25:34
#Base:Fit=	01.07.2021 19:25:34
#Base:Fit=	01.07.2021 19:25:34
#Base:Sub=	01.07.2021 19:25:38
#Edit:Shape=	01.07.2021 19:25:48
#Edit:Shape=	01.07.2021 19:25:50
100.862	644.853
107.378	594.192
113.889	455.098
120.394	317.898
126.894	217.848
133.388	146.945
139.878	102.454
146.361	76.9893
152.84	61.7969
159.313	64.293
165.78	61.9854
172.242	50.666
178.699	33.3984
185.149	11.0801
191.596	-6.26465
198.037	0.0400391
204.472	38.0479
210.903	94.3398
217.326	156.249
223.746	218.707
230.16	253.554
236.568	222.955
242.972	171.749
249.371	129.965
255.762	79.791
262.151	86.5615
268.533	106.246
274.91	133.348
281.282	157.624
287.648	169.981
294.01	162.593
300.365	141.116
306.716	111.133
313.061	87.9766
319.401	75.6035
325.737	71.6992
332.066	73.9395
338.392	88.8291
344.711	86.4502
351.024	68.6748
357.335	48.084
363.638	16.5059
369.936	-5.09961
376.23	-11.0166
382.519	-0.44043
388.802	34.5
395.08	117.805
401.353	269.572
407.62	489.913
413.884	745.821
420.141	824.845
426.394	714.336
432.641	649.108
438.883	613.859
445.12	597.528
451.352	583.377
457.579	564.862
463.801	543.031
470.018	518.239
476.23	483.936
482.437	467.593
488.638	482.854
494.834	472.452
501.026	407.492
507.212	330.097
513.394	266.558
519.571	226.937
525.743	213.397
531.908	212.609
538.07	230.123
544.227	256.478
550.377	318.668
556.524	392.959
562.666	488.785
568.801	532.659
574.933	516.204
581.061	509.098
587.181	498.2
593.299	483.146
599.41	471.829
605.517	465.937
611.618	459.498
617.716	446.756
623.807	451.251
629.895	456.765
635.977	473.098
642.053	464.826
648.127	394.079
654.193	272.974
660.256	170.221
666.314	112.779
672.367	89.3613
678.414	98.084
684.457	103.698
690.496	108.42
696.529	108.698
702.558	101.344
708.581	80.6631
714.6	55.8838
720.614	30.8564
726.624	10.6963
732.628	-0.805664
738.628	-5.24512
744.623	-5.2793
750.613	-3.79492
756.598	14.4014
762.578	33.5762
768.554	46.1006
774.525	62.5908
780.49	75.8682
786.451	63.3535
792.408	51.9365
798.36	49.1807
804.307	67.6875
810.25	92.292
816.186	125.29
822.119	170.534
828.048	223.637
833.972	276.826
839.889	321.266
845.804	346.239
851.714	351.684
857.617	340.599
863.518	308.774
869.413	268.023
875.303	222.965
881.19	162.516
887.07	160.388
892.947	131.476
898.818	229.248
904.686	402.48
910.548	854.787
916.406	1527.77
922.26	1828.16
928.108	1101.09
933.953	517.542
939.792	449.15
945.626	666.575
951.457	1553.37
957.282	3922.6
963.103	4583.18
968.919	2179.9
974.731	1212.46
980.539	1192.88
986.341	1428.01
992.139	1614.15
997.932	1553.58
1003.72	1127.62
1009.51	907.197
1015.29	790.708
1021.06	727.644
1026.83	678.725
1032.6	635.804
1038.36	613.39
1044.12	596.592
1049.87	577.815
1055.62	537.635
1061.36	499.399
1067.1	463.045
1072.84	434.023
1078.56	389.546
1084.29	338.146
1090.01	284.266
1095.73	249.413
1101.44	235.248
1107.15	240.904
1112.85	254.874
1118.55	259.397
1124.24	245.886
1129.94	227.473
1135.62	205.369
1141.3	190.808
1146.98	186.024
1152.65	179.644
1158.32	167.925
1163.98	152.506
1169.64	132.395
1175.3	114.991
1180.95	115.649
1186.59	116.628
1192.23	122.722
1197.87	133.875
1203.5	148.54
1209.13	162.568
1214.75	175.467
1220.37	190.714
1225.99	201.935
1231.6	205.982
1237.21	199.814
1242.81	170.053
1248.41	139.502
1254	93.3916
1259.59	45.8701
1265.17	6.72168
1270.75	-10.208
1276.33	-9.92871
1281.9	-3.22461
1287.47	13.2246
1293.03	33.1309
1298.59	55.7607
1304.15	78.7676
1309.7	98.8965
1315.24	109.861
1320.78	117.195
1326.32	121.514
1331.85	121.963
1337.38	113.886
1342.91	92.1904
1348.43	70.8789
1353.95	53.209
1359.46	40.4434
1364.97	32.0791
1370.47	32.3457
1375.97	37.6592
1381.46	39.708
1386.96	35.8027
1392.44	28.8457
1397.92	21.4561
1403.4	16.6875
1408.88	13.6006
1414.35	12.9707
1419.81	11.7158
1425.27	8.3584
1430.73	6.40527
1436.18	3.70703
1441.63	2.8584
1447.08	5.85352
1452.52	8.83398
1457.96	7.96484
1463.39	1.80762
1468.82	-7.54102
1474.24	-16.1631
1479.66	-18.2061
1485.08	-17.3457
1490.49	-12.5928
1495.9	1.85547
1501.3	16.9424
1506.7	26.751
1512.09	31.5117
1517.49	38.8516
1522.87	50.7012
1528.26	63.042
1533.63	71.0977
1539.01	64.2168
1544.38	44.3564
1549.75	18.7637
1555.11	-0.338867
1560.47	-12.2031
1565.82	-17.8613
1571.17	-16.2041
1576.52	-6.10352
1581.86	13.9775
1587.2	44.0469
1592.54	69.4023
1597.86	105.424
1603.19	143.258
1608.51	183.031
1613.83	215.171
1619.15	221.592
1624.46	203.708
1629.76	187.034
1635.06	171.2
1640.36	153.949
1645.66	136.519
1650.95	120.955
1656.23	107.967
1661.52	96.0752
1666.79	82.5029
1672.07	68.2803
1677.34	54.2598
1682.6	41.124
1687.87	33.9102
1693.13	39.1992
1698.38	55.3203
1703.63	79.1162
1708.88	104.027
1714.12	119.729
1719.36	134.576
1724.59	156.066
1729.82	154.994
1735.05	143.699
1740.27	133.879
1745.49	123.488
1750.71	107.738
1755.92	83.9336
1761.13	55.8164
1766.33	33.4922
1771.53	24.6211
1776.73	29.5176
1781.92	44.9727
1787.11	68.2559
1792.29	97.7539
1797.47	130.518
1802.65	159.313
1807.82	176.582
1812.99	179.18
1818.15	171.127
1823.32	158.326
1828.47	147.795
1833.63	131.023
1838.78	116.273
1843.92	99.7441
1849.06	82.3691
1854.2	68.0586
1859.34	61.0176
1864.47	58.9844
1869.59	62.5742
1874.72	72.0078
1879.84	83.4609
1884.95	90.1895
1890.06	98.3926
1895.17	107.758
1900.27	114.344
1905.37	121.691
1910.47	131.443
1915.56	143.736
1920.65	154.408
1925.74	152.537
1930.82	144.207
1935.9	130.074
1940.97	115.662
1946.04	94.5801
1951.11	61.6406
1956.17	29.3125
1961.23	8.63867
1966.28	-1.51172
1971.33	-3.11914
1976.38	0.601563
1981.43	12.248
1986.47	29.2871
1991.5	32.5625
1996.54	51.0234
2001.57	47.7051
2006.59	56.2754
2011.61	72.3379
2016.63	87.8613
2021.65	109.088
2026.66	131.961
2031.66	142.762
2036.67	124.074
2041.67	118.26
2046.66	132.797
2051.66	134.551
2056.65	137.064
2061.63	143.184
2066.61	152.205
2071.59	162.482
2076.56	167.904
2081.53	167.438
2086.5	162.035
2091.46	133.193
2096.42	118.592
2101.38	142.006
2106.33	153.291
2111.28	156.475
2116.23	155.711
2121.17	139.66
2126.11	123.723
2131.04	108.41
2135.97	91.9941
2140.9	76.1973
2145.82	63.3086
2150.74	57.1836
2155.66	53.7227
2160.57	51.4609
2165.48	47.5566
2170.39	47.2676
2175.29	51.8125
2180.19	77.1738
2185.09	80.6523
2189.98	77.8945
2194.86	75.0176
2199.75	75.8594
2204.63	79.0645
2209.51	92.9531
2214.38	113.205
2219.25	125.457
2224.12	123.924
2228.98	111.26
2233.84	98.793
2238.7	81.0449
2243.55	69.084
2248.4	63.834
2253.25	57.2129
2258.09	48.1445
2262.93	40.0293
2267.76	27.043
2272.6	12.2363
2277.43	-3.07031
2282.25	-16.209
2287.07	-29.5742
2291.89	-10.2988
2296.7	-8.11719
2301.52	-2.48047
2306.32	20.5352
2311.13	51.3516
2315.93	103.037
2320.73	109.145
2325.52	86.5059
2330.31	99.7793
2335.1	117.992
2339.88	137.703
2344.66	161.619
2349.44	182.758
2354.21	183.58
2358.98	164.238
2363.75	136.254
2368.51	118.461
2373.27	104.023
2378.03	89.5664
2382.78	73.7949
2387.53	56.6621
2392.28	38.5176
2397.02	21.3203
2401.76	13.6777
2406.49	18.6172
2411.23	30.8906
2415.95	53
2420.68	81.3574
2425.4	109.814
2430.12	135.188
2434.84	158.949
2439.55	185.268
2444.26	211.967
2448.96	225.865
2453.67	227.078
2458.37	224.352
2463.06	219.316
2467.75	210.242
2472.44	194.682
2477.13	170.42
2481.81	150.018
2486.49	139.676
2491.17	137.959
2495.84	142.932
2500.51	151.844
2505.17	165.613
2509.84	180.797
2514.5	191.811
2519.15	195.547
2523.8	191.049
2528.45	182.119
2533.1	175.293
2537.74	170.662
2542.38	161.996
2547.02	159.131
2551.65	164.201
2556.28	173.793
2560.91	183.178
2565.53	192.668
2570.15	191.738
2574.77	181.678
2579.38	176.709
2583.99	168.293
2588.6	153.785
2593.2	142.402
2597.8	140.174
2602.4	128.258
2606.99	119.666
2611.58	119.389
2616.17	129.584
2620.75	128.854
2625.33	149.297
2629.91	171.945
2634.49	192.816
2639.06	195.184
2643.63	169.195
2648.19	145.746
2652.75	119.115
2657.31	94.9902
2661.87	79.7344
2666.42	62.7793
2670.97	93.8711
2675.51	140.469
2680.06	169.955
2684.6	192.6
2689.13	206.875
2693.67	196.209
2698.2	168.699
2702.72	137.416
2707.25	113.494
2711.77	99.7441
2716.28	91.1719
2720.8	83.6484
2725.31	72.3516
2729.82	24.5762
2734.32	19.1433
2738.83	19.7403
2743.32	45.7641
2747.82	71.7709
2752.31	97.765
2756.8	123.735
2761.29	149.688
2765.77	157.096
2770.25	146.955
2774.73	136.82
2779.2	131.889
2783.67	91.4061
2788.14	87.106
2792.6	147.348
2797.06	150.629
2801.52	108.273
2805.98	88.1011
2810.43	67.9436
2814.88	63.0093
2819.32	78.1075
2823.77	93.2256
2828.2	107.581
2832.64	121.93
2837.08	136.27
2841.51	150.6
2845.93	157.63
2850.36	160.134
2854.78	162.636
2859.2	165.137
2863.61	167.636
2868.02	168.533
2872.43	165.582
2876.84	158.102
2881.24	150.88
2885.64	140.919
2890.04	137.41
2894.43	137.41
2898.82	137.41
2903.21	139.749
2907.6	144.261
2911.98	148.77
2916.36	153.277
2920.74	157.78
2925.11	162.28
2929.48	166.777
2933.84	171.27
2938.21	175.762
2942.57	180.249
2946.93	184.734
2951.28	189.215
2955.64	193.694
2959.98	198.169
2964.33	199.656
2968.67	199.656
2973.01	199.656
2977.35	201.146
2981.68	189.931
2986.02	178.725
2990.34	167.525
2994.67	156.333
2998.99	140.248
3003.31	117.429
3007.63	116.284
3011.94	135.811
3016.25	143.886
3020.56	137.385
3024.86	130.887
3029.17	124.396
3033.47	117.491
3037.76	103.328
3042.05	120.753
3046.34	130.465
3050.63	140.17
3054.92	142.076
3059.2	139.653
3063.48	137.231
3067.75	134.812
3072.02	132.393
3076.29	122.318
3080.56	104.609
3084.82	86.9117
3089.09	69.2253
3093.34	44.0416
3097.6	52.2257
3101.85	76.2936
3106.1	100.346
3110.35	124.383
3114.59	142.906
3118.83	154.908
3123.07	168.533
3127.31	168.533
3131.54	168.533
3135.77	164.721
3140	150.366
3144.22	136.025
3148.44	121.69
3152.66	107.365
3156.87	93.0516
3161.09	78.7451
3165.29	64.4511
3169.5	22.1745
3173.71	139.552
3177.91	155.406
3182.11	168.859
3186.3	170.758
3190.49	172.657
3194.68	176.032
3198.87	164.184
3203.05	152.344
3207.24	140.509
3211.41	128.684
3215.59	116.868
3219.76	100.587
3223.93	81.705
3228.1	75.1044
3232.27	89.5624
3236.43	114.06
3240.59	138.542
3244.74	162.309
3248.9	162.309
3253.05	156.634
3257.2	148.585
3261.34	140.543
3265.48	132.504
3269.62	123.674
3273.76	102.6
3277.89	81.5441
3282.02	68.9682
3286.15	84.5483
3290.28	98.3565
3294.4	109.559
3298.52	120.751
3302.64	131.186
3306.75	131.186
3310.87	131.186
3314.98	131.186
3319.08	131.186
3323.19	129.655
3327.29	125.676
3331.39	121.699
3335.48	117.726
3339.58	113.754
3343.67	106.15
3347.75	96.8957
3351.84	96.9332
3355.92	101.554
3360	106.287
3364.08	106.287
3368.15	106.287
3372.22	106.287
3376.29	104.708
3380.36	102.078
3384.42	99.4496
3388.48	96.8236
3392.54	94.4691
3396.59	89.8782
3400.65	81.389
3404.7	81.389
3408.74	82.3502
3412.79	77.7715
3416.83	73.1969
3420.87	68.624
3424.91	64.0556
3428.94	62.7153
3432.97	62.7153
3437	62.7153
3441.02	62.7153
3445.05	62.7153
3449.07	62.7153
3453.09	62.7153
3457.1	62.7153
3461.11	74.9473
3465.13	69.124
3469.13	71.8857
3473.14	76.8408
3477.14	74.085
3481.14	78.377
3485.14	88.6309
3489.13	98.5234
3493.12	106.945
3497.11	116.464
3501.1	124.732
3505.08	120.799
3509.06	96.4004
3513.04	68.5254
3517.02	37.5605
3520.99	11.54
3524.96	-1.91309
3528.93	8.25684
3532.89	11.126
3536.86	23.8711
3540.82	38.2676
3544.78	43.3936
3548.73	37.2871
3552.68	24.8105
3556.63	26.2227
3560.58	33.8516
3564.53	38.4336
3568.47	38.3213
3572.41	23.5615
3576.34	0.233398
3580.28	7.64746
3584.21	25.1729
3588.14	34.8545
3592.07	54.6006
3595.99	59.9922
3599.91	66.0645
3603.83	59.3271
3607.75	40.1406
3611.66	21.0264
3615.58	-0.524414
3619.49	-21.9814
3623.39	-30.958
3627.3	-30.1055
3631.2	-17.0537
3635.1	-2.57422
3638.99	11.1602
3642.89	25.7383
3646.78	35.3525
3650.67	34.2891
3654.55	30.0908
3658.44	25.8945
3662.32	21.5811
3666.2	13.3232
3670.07	6.29492
3673.95	3.10156
3677.82	0.303711
3681.69	-2.51953
3685.55	0.879883
3689.42	10.3809
3693.28	24.7139
3697.14	41.1523
3700.99	61.5918
3704.85	61.4717
3708.7	58.6514
3712.55	62.3809
3716.39	70.9951
3720.24	80.9082
3724.08	84.0479
3727.92	75.0918
3731.76	68.4688
3735.59	58.5605
3739.42	38.0576
3743.25	43.7002
3747.08	76.9717
3750.9	89.8291
3754.72	83.3193
3758.54	29.5791
3762.36	36.2852
3766.17	75.8711
3769.99	104.229
3773.79	113.88
3777.6	93.335
3781.41	71.0322
3785.21	51.1602
3789.01	34.4424
3792.81	27.8281
3796.6	33.209
3800.39	47.1992
3804.18	65.0791
3807.97	66.625
3811.76	63.2744
3815.54	59.9082
3819.32	56.5098
3823.1	74.2012
3826.87	74.7715
3830.65	60.6992
3834.42	48.7314
3838.18	54.0381
3841.95	48.1406
3845.71	37.5664
3849.48	21.7246
3853.23	1.55078
3856.99	-23.5596
3860.74	-36.8779
3864.5	-30.6396
3868.24	-14.2139
3871.99	0.455078
3875.74	7.70898
3879.48	11.6553
3883.22	14.8252
3886.95	17.0879
3890.69	14.4053
3894.42	9.91992
3898.15	9.7832
3901.88	15.0771
3905.61	24.7773
3909.33	33.125
3913.05	45.3193
3916.77	58.4951
3920.48	64.2861
3924.2	52.9248
3927.91	30.7246
3931.62	6.70801
3935.32	-8.23242
3939.03	-13.542
3942.73	-9.3877
3946.43	6.00977
3950.13	27.3506
3953.82	49.1563
3957.51	61.1904
3961.2	56.3594
3964.89	72.5176
3968.58	88.8291
3972.26	108.281
3975.94	128.222
3979.62	150.858
3983.3	179.324
3986.97	197.413
3990.64	219.051
3994.31	244.499
3997.98	269.734
3999.81	283.381