File: Data/Raman/processed/tourmaline-core_150 (500nm)_633nm_edge_100%_x50_vis_lwd_h30um_30sx2_01.txt
#Acq. time (s)=	30
#Accumulations=	2
#Range (cm-¹)=	100...4000
#Windows=	1
#Auto scanning=	Off
#Autofocus=	Off
#Macrospot=	Off
#AutoExposure=	Off
#Spike filter=	Multiple accum.
#Delay time (s)=	2
#Binning=	1
#Readout mode=	Signal
#DeNoise=	Standard
#ICS correction=	On
#Dark correction=	Off
#Inst. Process=	Off
#Detector Gain=	Best Dynamic
#Detector ADC=	50 kHz HS
#Detector temperature (°C)=	-60.09
#Instrument=	LabRAM HR Evol
#Detector=	SIN-EM FIVIS
#Objective=	x50_VIS_LWD
#Grating=	150 (500nm)
#ND Filter=	100%
#Laser=	633nm_Edge
#Hole=	30.0125
#Temperature=	0
#Range=	Visible
#StageXY=	75x50mm Scan+
#StageZ=	Z motor
#X (µm)=	0
#Y (µm)=	0
#Z (µm)=	59.3
#Full time(mm:ss)=	1:06
#Project=	20_10_27
#Sample=	BU24
#Site=
#Title=	BU24-Turm1-core_150 (500nm)_633nm_Edge_100%_x50_VIS_LWD_H30um_30sX2
#Remark=
#Date=	27.10.2020 18:23
#Acquired=	27.10.2020 18:23:04
#Data Range:Extract=	01.07.2021 19:23:37
#Base:Fit=	01.07.2021 19:24:15
#Base:Fit=	01.07.2021 19:24:39
#Base:Fit=	01.07.2021 19:24:47
#Base:Sub=	01.07.2021 19:24:50
100.764	321.389
107.281	380.541
113.791	404.38
120.297	438.714
126.797	507.819
133.291	593.066
139.78	654.35
146.264	677.047
152.741	686.039
159.214	676.461
165.682	731.059
172.144	721.89
178.601	676.948
185.053	566.586
191.499	409.314
197.939	342.796
204.374	309.369
210.805	288.456
217.23	266.462
223.648	240.485
230.063	194.877
236.472	143.002
242.874	92.8474
249.273	46.1716
255.667	10.2584
262.053	0.569824
268.436	-0.759155
274.813	3.83777
281.185	14.7982
287.552	32.4678
293.913	55.2626
300.27	79.0082
306.62	103.14
312.965	128.62
319.306	154.562
325.64	179.395
331.971	202.809
338.295	223.178
344.614	242.83
350.93	264.99
357.238	292.027
363.542	407.782
369.842	438.797
376.135	398.462
382.423	318.795
388.706	280.625
394.984	255.497
401.258	242.757
407.526	246.013
413.789	234.399
420.046	219.061
426.299	197.757
432.546	174.63
438.788	158.932
445.025	150.436
451.257	156.449
457.484	168.876
463.706	186.451
469.923	206.342
476.135	226.753
482.342	248.432
488.544	273.049
494.741	301.342
500.933	332.608
507.12	365.056
513.3	396.378
519.477	423.881
525.649	448.01
531.815	465.68
537.976	477.372
544.133	474.446
550.285	459.436
556.43	434.771
562.572	403.976
568.709	375.636
574.84	347.96
580.967	323.563
587.09	306.712
593.205	296.361
599.318	290.421
605.424	276.658
611.527	250.272
617.623	234.181
623.716	260.304
629.802	255.383
635.884	248.047
641.962	244.233
648.034	232.14
654.101	222.571
660.165	202.759
666.222	184.346
672.274	176.66
678.324	169.442
684.366	163.841
690.404	169.758
696.438	193.999
702.466	232.21
708.491	234.455
714.51	210.108
720.523	162.462
726.533	121.741
732.537	98.6759
738.537	84.4512
744.531	78.7375
750.521	77.4174
756.507	77.2562
762.487	78.157
768.463	75.8738
774.434	67.7681
780.4	59.1346
786.362	51.0519
792.319	43.7523
798.269	37.423
804.217	31.7909
810.159	27.8567
816.097	23.9963
822.03	21.9282
827.958	20.1879
833.881	21.546
839.801	24.1365
845.714	23.8818
851.624	21.7905
857.529	18.3685
863.428	14.0995
869.324	9.13745
875.215	3.91919
881.1	0.559692
886.982	-0.650757
892.858	0.590332
898.73	1.40784
904.597	3.2207
910.459	5.67932
916.318	8.0238
922.171	11.5553
928.02	17.1438
933.864	25.359
939.703	33.5071
945.539	40.6654
951.368	47.0984
957.194	52.662
963.014	57.3385
968.832	61.5808
974.643	66.2419
980.45	71.0378
986.253	75.9043
992.051	80.9944
997.844	86.5643
1003.63	92.7662
1009.42	99.7058
1015.2	104.62
1020.97	105.638
1026.74	107.448
1032.51	111.588
1038.27	115.96
1044.03	118.633
1049.78	122.695
1055.53	118.471
1061.27	108.844
1067.01	95.6749
1072.75	78.6615
1078.48	66.7225
1084.2	60.5165
1089.92	60.3451
1095.64	65.1383
1101.35	66.1154
1107.06	68.212
1112.77	65.9572
1118.46	60.7073
1124.16	52.4777
1129.85	41.9897
1135.53	30.9762
1141.22	22.4432
1146.89	16.7573
1152.56	14.0044
1158.23	12.3999
1163.9	10.4055
1169.56	7.48596
1175.21	6.1571
1180.86	6.47217
1186.51	7.77295
1192.15	9.71204
1197.78	8.68994
1203.42	10.5604
1209.04	15.4851
1214.67	20.4757
1220.29	26.7841
1225.9	29.3424
1231.51	28.5704
1237.12	24.306
1242.72	17.4249
1248.32	15.9219
1253.92	17.7717
1259.5	22.2191
1265.09	29.0969
1270.67	36.5946
1276.25	43.4406
1281.82	47.4839
1287.39	46.5488
1292.95	46.8522
1298.51	48.0717
1304.06	51.0168
1309.61	53.6654
1315.16	53.9357
1320.7	52.2921
1326.24	45.5833
1331.77	42.9235
1337.3	44.4777
1342.83	45.0384
1348.35	45.4031
1353.86	45.3525
1359.37	43.8393
1364.88	40.3003
1370.39	35.1403
1375.89	31.1537
1381.38	29.3636
1386.87	28.7176
1392.36	27.5331
1397.84	25.3919
1403.32	21.7262
1408.79	19.0413
1414.26	16.3056
1419.73	13.3672
1425.19	9.60986
1430.65	5.59387
1436.1	2.1449
1441.55	0.175537
1447	-0.570251
1452.44	1.11713
1457.87	6.91101
1463.31	9.13092
1468.73	9.14185
1474.16	8.40558
1479.58	8.1554
1484.99	8.95673
1490.41	10.7755
1495.81	13.8555
1501.22	16.0075
1506.62	16.3256
1512.01	13.8323
1517.4	12.3712
1522.79	13.1534
1528.17	16.8585
1533.55	17.9379
1538.93	19.1652
1544.3	18.4863
1549.67	15.9241
1555.03	11.2025
1560.39	7.33972
1565.74	5.56213
1571.09	6.1933
1576.44	10.0655
1581.78	16.3295
1587.12	20.243
1592.45	21.7399
1597.78	21.1782
1603.11	19.2802
1608.43	16.7661
1613.75	14.6821
1619.07	13.385
1624.38	13.3632
1629.68	15.7342
1634.98	17.5779
1640.28	18.4637
1645.58	18.5562
1650.87	18.101
1656.15	17.2452
1661.44	16.1321
1666.71	14.8552
1671.99	13.2578
1677.26	11.6108
1682.53	10.1686
1687.79	9.72211
1693.05	9.86462
1698.3	10.4647
1703.55	10.2851
1708.8	10.0542
1714.04	10.986
1719.28	12.7889
1724.51	14.8513
1729.75	15.818
1734.97	16.4105
1740.2	19.1868
1745.42	19.244
1750.63	17.8072
1755.84	17.8466
1761.05	18.2368
1766.25	18.1696
1771.45	16.8036
1776.65	14.7393
1781.84	11.8352
1787.03	12.4621
1792.21	14.1165
1797.39	15.8906
1802.57	17.6216
1807.74	19.1733
1812.91	19.801
1818.08	19.0334
1823.24	18.4416
1828.39	17.1846
1833.55	17.3017
1838.7	19.1744
1843.84	19.3904
1848.99	20.5464
1854.12	21.9865
1859.26	22.1552
1864.39	20.5615
1869.52	18.3317
1874.64	16.9376
1879.76	16.4777
1884.87	16.1522
1889.98	15.2006
1895.09	15.311
1900.2	17.8422
1905.3	20.5667
1910.39	22.4697
1915.49	24.4218
1920.57	26.0703
1925.66	26.754
1930.74	25.1878
1935.82	20.8892
1940.89	15.5588
1945.96	12.0313
1951.03	10.7617
1956.09	11.4024
1961.15	6.16052
1966.21	12.895
1971.26	14.0286
1976.31	15.2537
1981.35	16.6012
1986.39	13.8297
1991.43	13.6207
1996.46	13.7996
2001.49	14.1619
2006.52	13.7492
2011.54	12.9478
2016.56	12.0463
2021.57	11.6551
2026.58	12.512
2031.59	13.579
2036.59	14.6018
2041.59	15.0225
2046.59	14.8299
2051.58	14.302
2056.57	13.142
2061.55	12.2592
2066.54	11.6713
2071.51	12.7333
2076.49	13.6147
2081.46	13.9686
2086.43	13.7479
2091.39	13.1647
2096.35	12.2521
2101.3	11.0696
2106.26	9.38116
2111.21	7.33472
2116.15	8.18591
2121.09	10.0768
2126.03	11.5299
2130.97	11.3963
2135.9	9.59772
2140.83	7.12921
2145.75	4.78516
2150.67	2.25079
2155.59	-0.235107
2160.5	0.436096
2165.41	3.06635
2170.31	6.88245
2175.22	11.7875
2180.12	17.7701
2185.01	21.7269
2189.9	21.7274
2194.79	20.577
2199.68	18.4048
2204.56	12.0187
2209.43	8.14377
2214.31	2.81512
2219.18	-0.628204
2224.05	4.35205
2228.91	7.96277
2233.77	9.51511
2238.63	9.258
2243.48	7.34427
2248.33	5.39001
2253.17	8.4332
2258.02	11.289
2262.86	13.1667
2267.69	14.1405
2272.52	14.4937
2277.35	14.2387
2282.18	13.6596
2287	13.2824
2291.82	13.6251
2296.63	15.4954
2301.44	16.4386
2306.25	14.7319
2311.05	13.0876
2315.86	13.311
2320.65	13.7163
2325.45	13.955
2330.24	13.5486
2335.03	13.0724
2339.81	13.3746
2344.59	13.7984
2349.37	12.5332
2354.14	9.96933
2358.91	9.37192
2363.67	9.34564
2368.44	9.70319
2373.2	10.2807
2377.95	11.9775
2382.71	13.5023
2387.46	11.8477
2392.2	8.80115
2396.95	5.6998
2401.68	2.38867
2406.42	0.210846
2411.15	0.127869
2415.88	5.14917
2420.61	6.9194
2425.33	8.2529
2430.05	9.02267
2434.77	9.4321
2439.48	9.28751
2444.19	8.83252
2448.89	8.27829
2453.6	8.32007
2458.29	8.87076
2462.99	9.34949
2467.68	8.37231
2472.37	8.24094
2477.06	9.32816
2481.74	10.7783
2486.42	10.9888
2491.1	10.9579
2495.77	10.7361
2500.44	10.6079
2505.1	10.3254
2509.76	9.58618
2514.42	8.1525
2519.08	6.87033
2523.73	5.71512
2528.38	4.57526
2533.03	3.3801
2537.67	3.12512
2542.31	5.7193
2546.95	9.38998
2551.58	10.5513
2556.21	10.2704
2560.84	9.11633
2565.46	7.54745
2570.08	4.16446
2574.7	3.48492
2579.31	5.72446
2583.92	8.83362
2588.53	10.1085
2593.13	9.75012
2597.73	7.71234
2602.33	4.57709
2606.92	2.92276
2611.51	2.93881
2616.1	3.89099
2620.68	5.82541
2625.26	10.8866
2629.84	11.2754
2634.42	10.0051
2638.99	7.42999
2643.56	10.1479
2648.12	10.6092
2652.68	4.78876
2657.24	-1.0271
2661.8	0.554871
2666.35	8.65665
2670.9	7.77673
2675.45	9.61478
2679.99	10.5692
2684.53	10.9818
2689.06	10.5739
2693.6	9.35144
2698.13	6.71585
2702.66	3.81204
2707.18	4.34415
2711.7	5.87033
2716.22	7.043
2720.73	5.47601
2725.24	0.739716
2729.75	4.28418
2734.26	7.3345
2738.76	4.1026
2743.25	1.17325
2747.75	-0.219238
2752.24	1.00314
2756.73	3.41959
2761.22	5.4101
2765.7	7.15341
2770.18	7.78986
2774.66	5.66364
2779.13	3.14209
2783.6	2.13089
2788.07	2.09256
2792.53	3.41815
2797	6.39749
2801.45	10.4128
2805.91	13.022
2810.36	13.1635
2814.81	10.9061
2819.26	7.17493
2823.7	5.59671
2828.14	5.48996
2832.57	5.44968
2837.01	5.79608
2841.44	6.03149
2845.87	6.20145
2850.29	6.18011
2854.71	6.06387
2859.13	4.87039
2863.55	3.3382
2867.96	2.15079
2872.37	1.92825
2876.77	2.33279
2881.18	3.57111
2885.58	5.48514
2889.97	7.91467
2894.37	8.72955
2898.76	8.4364
2903.15	8.17203
2907.53	7.8981
2911.91	7.44629
2916.29	7.20453
2920.67	3.30093
2925.04	6.04141
2929.41	8.89612
2933.78	9.4234
2938.14	10.7361
2942.5	13.2559
2946.86	15.6488
2951.22	13.5331
2955.57	11.1428
2959.92	9.62955
2964.26	9.25589
2968.61	9.54199
2972.95	9.79794
2977.28	9.71457
2981.62	9.50635
2985.95	9.00089
2990.28	8.49362
2994.6	6.97586
2998.93	5.60156
3003.25	5.37244
3007.56	6.4368
3011.88	8.42484
3016.19	11.4025
3020.49	14.5505
3024.8	14.8083
3029.1	13.8248
3033.4	12.119
3037.7	10.8196
3041.99	11.0904
3046.28	11.7406
3050.57	12.3636
3054.85	12.7888
3059.13	12.488
3063.41	11.6561
3067.69	9.70831
3071.96	6.24011
3076.23	1.68222
3080.5	-0.176666
3084.76	0.236206
3089.02	2.41496
3093.28	7.34491
3097.53	10.7803
3101.79	13.2875
3106.04	16.4697
3110.28	17.323
3114.53	16.4936
3118.77	14.9047
3123.01	10.6972
3127.24	7.30385
3131.47	6.10545
3135.7	6.35016
3139.93	9.09428
3144.15	13.8744
3148.38	13.1167
3152.59	12.1206
3156.81	11.1156
3161.02	10.2531
3165.23	9.85857
3169.44	10.1682
3173.64	10.7137
3177.84	11.8013
3182.04	13.3881
3186.24	14.6654
3190.43	14.4548
3194.62	13.9221
3198.81	12.7984
3202.99	12.2623
3207.17	12.7144
3211.35	12.2535
3215.53	11.0327
3219.7	9.40535
3223.87	6.72581
3228.04	3.756
3232.2	1.5358
3236.36	1.36404
3240.52	2.36661
3244.68	4.70631
3248.83	7.87694
3252.98	9.04524
3257.13	8.01788
3261.28	5.11455
3265.42	0.992401
3269.56	-1.58687
3273.7	-1.20471
3277.83	0.120758
3281.96	1.7296
3286.09	3.93768
3290.22	6.33777
3294.34	7.18269
3298.46	7.44614
3302.58	6.34827
3306.69	8.99765
3310.8	7.56195
3314.91	6.44806
3319.02	5.40868
3323.12	4.18835
3327.23	3.37633
3331.32	3.84782
3335.42	4.80353
3339.51	6.70975
3343.6	8.99957
3347.69	9.44373
3351.78	9.97762
3355.86	10.1966
3359.94	9.95015
3364.02	8.30949
3368.09	5.29886
3372.16	1.91722
3376.23	-0.282562
3380.29	-0.663162
3384.36	-0.590088
3388.42	0.411041
3392.48	1.5938
3396.53	2.6669
3400.58	3.30537
3404.63	2.70436
3408.68	1.4803
3412.73	0.559219
3416.77	0.577911
3420.81	0.583572
3424.84	0.0213928
3428.88	-0.299026
3432.91	-0.174469
3436.94	1.29111
3440.96	1.51631
3444.99	0.650955
3449.01	0.45253
3453.03	1.4166
3457.04	3.32204
3461.05	5.40642
3465.06	3.61194
3469.07	5.38765
3473.08	6.4801
3477.08	7.80826
3481.08	9.84727
3485.07	12.8554
3489.07	15.2266
3493.06	15.9003
3497.05	15.1369
3501.04	13.5409
3505.02	12.3131
3509	11.9965
3512.98	11.7511
3516.96	12.3625
3520.93	14.6393
3524.9	17.2796
3528.87	18.0281
3532.83	17.1072
3536.8	16.3071
3540.76	17.4863
3544.71	19.1642
3548.67	19.2019
3552.62	21.3737
3556.57	25.4895
3560.52	29.7596
3564.47	32.4755
3568.41	33.4691
3572.35	30.9512
3576.29	26.7788
3580.22	22.9985
3584.15	18.8046
3588.08	15.152
3592.01	12.1134
3595.93	9.715
3599.85	8.08696
3603.77	7.27919
3607.69	7.20738
3611.61	7.71576
3615.52	7.56252
3619.43	5.771
3623.33	5.13806
3627.24	4.78885
3631.14	3.66914
3635.04	1.83104
3638.93	-0.257248
3642.83	-0.725082
3646.72	0.0139313
3650.61	1.51727
3654.49	3.01941
3658.38	0.986877
3662.26	-0.0888519
3666.14	0.842819
3670.01	1.53932
3673.89	2.4511
3677.76	3.21268
3681.63	3.95558
3685.5	4.61739
3689.36	4.7336
3693.22	4.14632
3697.08	3.31798
3700.94	3.78574
3704.79	4.21309
3708.64	4.4115
3712.49	4.43538
3716.34	4.52892
3720.18	3.62759
3724.02	2.65495
3727.86	2.00285
3731.7	1.57854
3735.53	1.52553
3739.36	2.15405
3743.19	3.78796
3747.02	6.60323
3750.84	7.62875
3754.66	7.12038
3758.48	6.75055
3762.3	7.80827
3766.12	8.94989
3769.93	9.67885
3773.74	9.99748
3777.54	9.98303
3781.35	9.51115
3785.15	8.61546
3788.95	7.27356
3792.75	5.42589
3796.54	5.96492
3800.34	6.94737
3804.13	7.33003
3807.91	7.09949
3811.7	6.26138
3815.48	4.97772
3819.26	2.31683
3823.04	-1.90706
3826.82	-2.1386
3830.59	1.38284
3834.36	6.16545
3838.13	7.64474
3841.89	8.7146
3845.66	10.3151
3849.42	10.0538
3853.18	8.70303
3856.93	5.66586
3860.69	3.19469
3864.44	1.71985
3868.19	1.21223
3871.93	1.36844
3875.68	2.19345
3879.42	3.03726
3883.16	1.86313
3886.9	3.41647
3890.63	7.55702
3894.37	6.69398
3898.1	6.01865
3901.82	6.0601
3905.55	5.26936
3909.27	4.39087
3912.99	4.16409
3916.71	5.28563
3920.43	4.95708
3924.14	5.65796
3927.85	7.32207
3931.56	7.07246
3935.27	6.31673
3938.97	4.86966
3942.67	3.15991
3946.37	1.49214
3950.07	0.511475
3953.77	-0.178772
3957.46	-0.446091
3961.15	-0.367325
3964.84	-0.0496979
3968.52	0.603607
3972.2	1.45914
3975.89	2.38966
3979.56	3.06589
3983.24	3.23137
3986.92	1.55902
3990.59	0.471207
3994.26	3.35408
3997.92	8.17661
3999.76	12.8311