File: Data/Raman/processed/tourmaline-rim_150 (500nm)_633nm_edge_100%_x50_vis_lwd_h30um_10sx2_01.txt
#Acq. time (s)=	10
#Accumulations=	2
#Range (cm-¹)=	100...4000
#Windows=	1
#Auto scanning=	Off
#Autofocus=	Off
#Macrospot=	Off
#AutoExposure=	Off
#Spike filter=	Multiple accum.
#Delay time (s)=	2
#Binning=	1
#Readout mode=	Signal
#DeNoise=	Standard
#ICS correction=	On
#Dark correction=	Off
#Inst. Process=	Off
#Detector Gain=	Best Dynamic
#Detector ADC=	50 kHz HS
#Detector temperature (°C)=	-60.09
#Instrument=	LabRAM HR Evol
#Detector=	SIN-EM FIVIS
#Objective=	x50_VIS_LWD
#Grating=	150 (500nm)
#ND Filter=	100%
#Laser=	633nm_Edge
#Hole=	30.0125
#Temperature=	0
#Range=	Visible
#StageXY=	75x50mm Scan+
#StageZ=	Z motor
#X (µm)=	0
#Y (µm)=	0
#Z (µm)=	60
#Full time(s)=	26
#Project=	20_10_27
#Sample=	BU24
#Site=
#Title=	BU24-Turm2-rim_150 (500nm)_633nm_Edge_100%_x50_VIS_LWD_H30um_10sX2
#Remark=
#Date=	27.10.2020 18:33
#Acquired=	27.10.2020 18:33:45
#Data Range:Extract=	01.07.2021 19:23:37
#Base:Fit=	01.07.2021 19:24:15
#Base:Fit=	01.07.2021 19:24:39
#Base:Fit=	01.07.2021 19:24:47
#Base:Sub=	01.07.2021 19:24:50
100.764	25.9905
107.281	38.722
113.791	51.1714
120.297	61.6846
126.797	70.0032
133.291	76.2072
139.78	78.9996
146.264	78.2731
152.741	75.8373
159.214	73.5822
165.682	72.1839
172.144	71.3856
178.601	68.9009
185.053	62.3475
191.499	54.5384
197.939	46.815
204.374	39.8793
210.805	34.5278
217.23	33.8847
223.648	47.6399
230.063	65.5232
236.472	76.7977
242.874	69.7591
249.273	48.562
255.667	31.1109
262.053	21.5571
268.436	13.0389
274.813	5.55692
281.185	1.00333
287.552	-0.0226746
293.913	3.22656
300.27	8.27917
306.62	12.9655
312.965	17.4886
319.306	19.6606
325.64	22.3817
331.971	25.0888
338.295	30.9448
344.614	38.6326
350.93	47.7241
357.238	61.9136
363.542	117.328
369.842	121.512
376.135	96.9286
382.423	75.156
388.706	63.1784
394.984	55.6233
401.258	49.1601
407.526	44.6669
413.789	40.5963
420.046	36.5114
426.299	33.2521
432.546	30.9996
438.788	29.5056
445.025	26.8803
451.257	26.2465
457.484	27.2254
463.706	29.4605
469.923	33.1965
476.135	38.3671
482.342	42.7474
488.544	45.5762
494.741	47.6047
500.933	49.4291
507.12	51.2573
513.3	53.312
519.477	54.7307
525.649	56.4315
531.815	59.2869
537.976	59.823
544.133	59.0685
550.285	56.9394
556.43	54.1777
562.572	51.9152
568.709	50.3939
574.84	48.6052
580.967	46.1303
587.09	43.7421
593.205	41.9526
599.318	41.3362
605.424	41.6049
611.527	44.0652
617.623	47.8034
623.716	50.7395
629.802	52.9305
635.884	54.9353
641.962	55.1165
648.034	51.8663
654.101	48.4038
660.165	45.1109
666.222	43.9209
672.274	43.9329
678.324	42.5398
684.366	41.2113
690.404	41.7318
696.438	44.7332
702.466	48.4893
708.491	45.3872
714.51	38.1833
720.523	29.8769
726.533	22.0007
732.537	16.101
738.537	12.2727
744.531	10.1179
750.521	10.4808
756.507	10.0075
762.487	8.92815
768.463	8.10051
774.434	7.14154
780.4	6.23546
786.362	3.85124
792.319	2.01729
798.269	0.828796
804.217	0.124344
810.159	-0.135178
816.097	-0.103653
822.03	0.102844
827.958	0.467697
833.881	0.781143
839.801	1.06715
845.714	1.17578
851.624	1.23941
857.529	1.46687
863.428	1.80807
869.324	2.18042
875.215	2.65407
881.1	2.77484
886.982	2.75906
892.858	2.38828
898.73	2.10529
904.597	1.87936
910.459	1.80785
916.318	1.75171
922.171	1.83223
928.02	2.14
933.864	2.83652
939.703	4.29828
945.539	6.69913
951.368	9.24391
957.194	10.4842
963.014	10.585
968.832	9.79832
974.643	8.51405
980.45	7.35469
986.253	7.84683
992.051	9.0697
997.844	10.7975
1003.63	12.8968
1009.42	15.2532
1015.2	15.8995
1020.97	17.1944
1026.74	19.1756
1032.51	21.6133
1038.27	24.3617
1044.03	27.2592
1049.78	29.2407
1055.53	27.8212
1061.27	24.8694
1067.01	20.2814
1072.75	15.8532
1078.48	12.4007
1084.2	10.3319
1089.92	9.00877
1095.64	8.60918
1101.35	8.85474
1107.06	9.17542
1112.77	8.79124
1118.46	7.53357
1124.16	5.26096
1129.85	3.14255
1135.53	1.79131
1141.22	1.23083
1146.89	1.17358
1152.56	2.00627
1158.23	3.03181
1163.9	2.73312
1169.56	2.14615
1175.21	0.769028
1180.86	-0.00343323
1186.51	-0.132446
1192.15	0.790329
1197.78	1.99855
1203.42	1.19827
1209.04	0.569061
1214.67	0.393036
1220.29	-0.00595093
1225.9	0.129501
1231.51	0.669716
1237.12	0.894829
1242.72	1.10371
1248.32	1.43877
1253.92	1.83061
1259.5	2.29971
1265.09	2.89613
1270.67	2.07635
1276.25	1.49251
1281.82	2.69762
1287.39	4.61606
1292.95	7.21341
1298.51	8.31604
1304.06	7.89967
1309.61	7.30808
1315.16	6.6294
1320.7	6.25054
1326.24	6.32687
1331.77	6.30486
1337.3	5.13259
1342.83	4.34889
1348.35	4.87158
1353.86	5.16286
1359.37	5.07371
1364.88	4.58016
1370.39	4.58178
1375.89	4.97112
1381.38	4.74437
1386.87	4.26849
1392.36	4.1572
1397.84	4.43635
1403.32	4.83302
1408.79	4.76553
1414.26	4.2317
1419.73	3.16681
1425.19	2.16351
1430.65	0.990486
1436.1	1.12881
1441.55	2.41507
1447	3.55379
1452.44	3.2066
1457.87	2.74374
1463.31	2.67744
1468.73	3.25414
1474.16	4.07349
1479.58	3.46828
1484.99	3.8355
1490.41	3.07337
1495.81	2.39458
1501.22	2.05758
1506.62	1.89823
1512.01	2.01968
1517.4	2.63231
1522.79	3.17082
1528.17	3.78152
1533.55	4.39159
1538.93	4.74324
1544.3	4.29412
1549.67	3.39362
1555.03	1.60771
1560.39	1.41042
1565.74	2.05284
1571.09	2.94289
1576.44	3.75853
1581.78	3.25236
1587.12	2.75735
1592.45	2.35165
1597.78	2.24602
1603.11	2.68112
1608.43	3.92819
1613.75	6.4717
1619.07	6.94861
1624.38	6.5319
1629.68	6.02724
1634.98	5.27209
1640.28	4.57822
1645.58	4.06603
1650.87	3.88475
1656.15	4.19417
1661.44	4.69006
1666.71	5.29137
1671.99	5.92686
1677.26	6.50042
1682.53	4.16071
1687.79	5.33451
1693.05	5.64436
1698.3	2.05756
1703.55	0.509605
1708.8	5.48385
1714.04	7.3949
1719.28	7.36817
1724.51	4.43813
1729.75	0.0630035
1734.97	0.809937
1740.2	2.60118
1745.42	4.83682
1750.63	4.85895
1755.84	4.51884
1761.05	4.64735
1766.25	4.97517
1771.45	5.53052
1776.65	5.74248
1781.84	5.62324
1787.03	5.84697
1792.21	6.19312
1797.39	6.6646
1802.57	7.19047
1807.74	7.74805
1812.91	8.23055
1818.08	7.65811
1823.24	7.27069
1828.39	6.9233
1833.55	6.47903
1838.7	6.39728
1843.84	7.31057
1848.99	7.80718
1854.12	6.91179
1859.26	6.38023
1864.39	6.11008
1869.52	6.02312
1874.64	4.43867
1879.76	4.02567
1884.87	2.88022
1889.98	2.58913
1895.09	4.23431
1900.2	6.68086
1905.3	7.0787
1910.39	5.49929
1915.49	5.97093
1920.57	6.44497
1925.66	6.83538
1930.74	7.1608
1935.82	7.40918
1940.89	7.57222
1945.96	7.64941
1951.03	7.67564
1956.09	7.19746
1961.15	5.54093
1966.21	4.0778
1971.26	3.56929
1976.31	5.15803
1981.35	5.72325
1986.39	5.09074
1991.43	4.89055
1996.46	6.31147
2001.49	7.84591
2006.52	8.33394
2011.54	7.63146
2016.56	6.83828
2021.57	6.25629
2026.58	5.48559
2031.59	4.81802
2036.59	3.32149
2041.59	2.8146
2046.59	3.28867
2051.58	4.07887
2056.57	5.00797
2061.55	5.73375
2066.54	5.58394
2071.51	5.23447
2076.49	4.92408
2081.46	4.63812
2086.43	4.4697
2091.39	4.53971
2096.35	4.94164
2101.3	5.52792
2106.26	6.08445
2111.21	6.58295
2116.15	6.73519
2121.09	5.12888
2126.03	3.36946
2130.97	0.349926
2135.9	-0.159878
2140.83	0.553238
2145.75	4.08276
2150.67	5.80241
2155.59	6.18488
2160.5	5.86308
2165.41	4.74744
2170.31	4.03296
2175.22	3.54381
2180.12	3.22524
2185.01	3.01488
2189.9	2.86353
2194.79	2.92926
2199.68	3.29944
2204.56	3.72651
2209.43	3.69735
2214.31	3.55157
2219.18	3.41052
2224.05	3.26976
2228.91	3.11901
2233.77	2.97349
2238.63	2.71585
2243.48	2.15692
2248.33	2.51522
2253.17	3.07139
2258.02	3.38942
2262.86	3.82957
2267.69	4.09927
2272.52	4.21983
2277.35	3.75647
2282.18	3.2886
2287	3.02737
2291.82	3.63111
2296.63	4.27162
2301.44	4.6247
2306.25	5.30949
2311.05	5.86239
2315.86	5.62244
2320.65	5.16915
2325.45	4.67623
2330.24	4.32984
2335.03	4.37128
2339.81	3.85719
2344.59	2.53066
2349.37	1.56831
2354.14	1.02961
2358.91	0.924736
2363.67	1.35412
2368.44	2.05094
2373.2	2.84013
2377.95	3.26853
2382.71	2.65949
2387.46	2.04009
2392.2	1.75806
2396.95	1.80218
2401.68	0.630775
2406.42	0.198246
2411.15	0.00964737
2415.88	-0.0124855
2420.61	0.112408
2425.33	0.330864
2430.05	0.62212
2434.77	0.956425
2439.48	1.33522
2444.19	1.66548
2448.89	2.35726
2453.6	3.08748
2458.29	3.83536
2462.99	3.6443
2467.68	3.35233
2472.37	2.79438
2477.06	2.19118
2481.74	1.60166
2486.42	1.02981
2491.1	0.669579
2495.77	0.612629
2500.44	1.30283
2505.1	2.18633
2509.76	3.03378
2514.42	3.78588
2519.08	3.99597
2523.73	4.05368
2528.38	3.77654
2533.03	3.26656
2537.67	2.63675
2542.31	2.24557
2546.95	1.73993
2551.58	0.988247
2556.21	0.730064
2560.84	0.757774
2565.46	0.292717
2570.08	1.09172
2574.7	1.49173
2579.31	1.14034
2583.92	1.06506
2588.53	1.46469
2593.13	1.84978
2597.73	1.98777
2602.33	1.94519
2606.92	0.766888
2611.51	-0.133686
2616.1	-0.26231
2620.68	0.339016
2625.26	1.31435
2629.84	1.41596
2634.42	3.09715
2638.99	2.81565
2643.56	2.09543
2648.12	1.32766
2652.68	1.2831
2657.24	1.76578
2661.8	1.46855
2666.35	1.24463
2670.9	1.17635
2675.45	1.20797
2679.99	1.32077
2684.53	1.49
2689.06	1.83313
2693.6	1.08831
2698.13	0.502296
2702.66	0.0798073
2707.18	0.154655
2711.7	0.408218
2716.22	0.37582
2720.73	0.435295
2725.24	0.638714
2729.75	0.882072
2734.26	1.14861
2738.76	1.41805
2743.25	1.59584
2747.75	1.92733
2752.24	1.70042
2756.73	-1.13747
2761.22	2.49582
2765.7	2.54745
2770.18	0.723625
2774.66	0.182209
2779.13	0.898956
2783.6	1.40711
2788.07	0.840691
2792.53	0.230042
2797	-0.224812
2801.45	0.192253
2805.91	0.440121
2810.36	0.630859
2814.81	0.715813
2819.26	0.372986
2823.7	-0.176025
2828.14	0.298195
2832.57	0.581169
2837.01	0.139645
2841.44	1.3857
2845.87	1.17548
2850.29	0.924191
2854.71	0.645649
2859.13	0.48061
2863.55	0.269943
2867.96	0.0762253
2872.37	-0.0730133
2876.77	-0.0673065
2881.18	0.023674
2885.58	-0.0464172
2889.97	0.347015
2894.37	1.53655
2898.76	2.09478
2903.15	2.07117
2907.53	1.73431
2911.91	1.19792
2916.29	0.337879
2920.67	-0.0665817
2925.04	0.58852
2929.41	0.661236
2933.78	0.911671
2938.14	1.23842
2942.5	1.58084
2946.86	1.67228
2951.22	1.6632
2955.57	1.2737
2959.92	0.996174
2964.26	0.836349
2968.61	1.02452
2972.95	1.24197
2977.28	1.47496
2981.62	1.70228
2985.95	1.90557
2990.28	2.01996
2994.6	1.95873
2998.93	1.47384
3003.25	2.07984
3007.56	3.51342
3011.88	4.17871
3016.19	3.45174
3020.49	1.09175
3024.8	-0.185375
3029.1	-0.0769539
3033.4	1.55359
3037.7	2.80599
3041.99	3.14277
3046.28	2.00625
3050.57	1.30116
3054.85	1.14072
3059.13	1.27232
3063.41	1.60877
3067.69	1.99483
3071.96	2.17762
3076.23	1.76468
3080.5	1.47161
3084.76	0.96928
3089.02	0.683422
3093.28	0.894215
3097.53	0.746113
3101.79	0.663841
3106.04	0.487339
3110.28	0.217117
3114.53	0.0583611
3118.77	0.260509
3123.01	0.887455
3127.24	1.44554
3131.47	1.03557
3135.7	0.727753
3139.93	0.57206
3144.15	0.600163
3148.38	1.22118
3152.59	1.9444
3156.81	2.71374
3161.02	1.64577
3165.23	0.984413
3169.44	0.943256
3173.64	1.51633
3177.84	2.19916
3182.04	2.92728
3186.24	3.58496
3190.43	3.93306
3194.62	3.98513
3198.81	3.50268
3202.99	3.00233
3207.17	2.56379
3211.35	2.47737
3215.53	3.14493
3219.7	3.08416
3223.87	3.54879
3228.04	4.25096
3232.2	4.46116
3236.36	4.29625
3240.52	4.02306
3244.68	3.78392
3248.83	3.54434
3252.98	3.33569
3257.13	3.34324
3261.28	2.72344
3265.42	2.68087
3269.56	3.09357
3273.7	4.37572
3277.83	3.86876
3281.96	4.52197
3286.09	4.40388
3290.22	4.39674
3294.34	4.40352
3298.46	3.39401
3302.58	3.13622
3306.69	3.70816
3310.8	3.63824
3314.91	4.52256
3319.02	4.36383
3323.12	4.21044
3327.23	4.03919
3331.32	3.99599
3335.42	4.1759
3339.51	4.51435
3343.6	3.64177
3347.69	3.21854
3351.78	3.38333
3355.86	4.07312
3359.94	5.1389
3364.02	5.2565
3368.09	4.61362
3372.16	4.0558
3376.23	3.9067
3380.29	3.88687
3384.36	3.98233
3388.42	3.48029
3392.48	1.87947
3396.53	-0.0305252
3400.58	0.0997505
3404.63	3.60464
3408.68	2.91801
3412.73	2.97547
3416.77	3.43708
3420.81	4.17885
3424.84	4.58209
3428.88	4.55775
3432.91	3.59038
3436.94	2.87155
3440.96	2.6191
3444.99	2.60877
3449.01	3.24093
3453.03	3.97536
3457.04	4.74454
3461.05	4.75211
3465.06	4.72754
3469.07	4.68158
3473.08	4.68026
3477.08	4.74206
3481.08	4.89767
3485.07	5.12982
3489.07	5.86485
3493.06	6.73887
3497.05	7.23854
3501.04	6.87196
3505.02	6.51744
3509	6.20203
3512.98	5.94388
3516.96	6.36493
3520.93	6.51537
3524.9	6.78111
3528.87	8.373
3532.83	10.0933
3536.8	12.0358
3540.76	14.1376
3544.71	16.2323
3548.67	15.8941
3552.62	17.0627
3556.57	18.1821
3560.52	19.8618
3564.47	19.6463
3568.41	19.255
3572.35	18.3543
3576.29	15.3144
3580.22	11.4475
3584.15	7.3612
3588.08	6.24808
3592.01	3.76707
3595.93	3.71828
3599.85	4.14306
3603.77	3.62932
3607.69	1.93644
3611.61	-0.152134
3615.52	0.297153
3619.43	2.00539
3623.33	3.33739
3627.24	3.23133
3631.14	3.12629
3635.04	3.01423
3638.93	2.91367
3642.83	2.1007
3646.72	1.1735
3650.61	0.738979
3654.49	0.719696
3658.38	1.13247
3662.26	1.95198
3666.14	2.58384
3670.01	2.52546
3673.89	2.45134
3677.76	2.36898
3681.63	0.716763
3685.5	1.9506
3689.36	1.80505
3693.22	1.27396
3697.08	0.871365
3700.94	0.645916
3704.79	1.83974
3708.64	3.04385
3712.49	3.31694
3716.34	3.25439
3720.18	3.24146
3724.02	3.21019
3727.86	2.51309
3731.7	1.60559
3735.53	1.14197
3739.36	0.618397
3743.19	1.82543
3747.02	2.97689
3750.84	3.04944
3754.66	2.29333
3758.48	1.45043
3762.3	0.644894
3766.12	0.0861244
3769.93	0.695251
3773.74	1.30856
3777.54	1.35367
3781.35	1.54589
3785.15	1.82024
3788.95	2.1401
3792.75	2.48073
3796.54	2.80753
3800.34	1.05899
3804.13	0.704674
3807.91	1.64889
3811.7	2.86243
3815.48	2.65204
3819.26	1.85259
3823.04	1.52473
3826.82	1.48011
3830.59	1.5916
3834.36	1.76928
3838.13	2.0483
3841.89	2.37155
3845.66	2.65548
3849.42	2.91735
3853.18	3.09951
3856.93	3.29715
3860.69	3.41344
3864.44	1.2164
3868.19	2.4264
3871.93	3.152
3875.68	3.88347
3879.42	4.41814
3883.16	4.28877
3886.9	4.12167
3890.63	3.96161
3894.37	3.82504
3898.1	3.69933
3901.82	3.58595
3905.55	3.47581
3909.27	3.36483
3912.99	3.3377
3916.71	3.14114
3920.43	2.91073
3924.14	2.6434
3927.85	2.30591
3931.56	2.15274
3935.27	2.09075
3938.97	2.10666
3942.67	1.45881
3946.37	0.534599
3950.07	-0.125038
3953.77	0.146763
3957.46	0.85553
3961.15	1.98903
3964.84	3.41402
3968.52	4.9326
3972.2	6.51074
3975.89	7.19346
3979.56	7.10712
3983.24	6.4276
3986.92	5.36406
3990.59	4.02819
3994.26	2.71545
3997.92	3.14338
3999.76	5.51085