File: Data/Raman/NTO-peaks/rutile_bu19w-ore2-a_150 (500nm)_532nm_edge_10%_x50_vis_lwd_h30um_30sx2_peaks.txt
Description: #Acq. time (s)=	30
X Variable: #Accumulations=	2
Y Variable: #Range (cm-¹)=	100...4000
File Source: c:\users\u0125722\box sync\buranga\_article2-buranga_mineral_evolution\raman_spectra\raw_files\bu19w-ore2-a_150 (500nm)_532nm_edge_10%_x50_vis_lwd_h30um_30sx2_01.txt

Fitted Parameters
r^2 Coef Det  DF Adj r^2    Fit Std Err  F-value
0.99954195   0.99944980   9.30888827   11241.5880
 Peak  Type                  a0          a1          a2          a3
    1  Gauss+Lor Amp   87.2627551  128.241992  25.0396945  1.00000000
    2  Gauss+Lor Amp   123.838529  146.509593  10.2667258  1.00000000
    3  Gauss+Lor Amp   136.130982  207.124727  33.4675049  1.00000000
    4  Gauss+Lor Amp   466.717535  243.990887  62.2701443  1.00000000
    5  Gauss+Lor Amp   160.569907  373.503220  48.1317543  1.00000000
    6  Gauss+Lor Amp   503.063302  414.122863  43.3365126  1.00000000
    7  Gauss+Lor Amp   1895.84940  444.233512  41.7934627  1.00000000
    8  Gauss+Lor Amp   184.066912  486.789395  48.6046501  1.00000000
    9  Gauss+Lor Amp   120.666954  588.404799  26.9594175  1.00000000
   10  Gauss+Lor Amp   513.071762  615.482734  32.4731025  1.00000000
   11  Gauss+Lor Amp   193.449377  843.006372  51.6510276  1.00000000

Measured Values
 Peak  Type             Amplitude    Center       FWHM       Asym50     FW Base      Asym10
    1  Gauss+Lor Amp   87.2627551  128.241992  25.0396945  1.00000000  50.1221626  1.00000000
    2  Gauss+Lor Amp   123.838529  146.509593  10.2667258  1.00000000  20.5509894  1.00000000
    3  Gauss+Lor Amp   136.130982  207.124727  33.4675049  1.00000000  66.9921798  1.00000000
    4  Gauss+Lor Amp   466.717535  243.990888  62.2701443  0.99999994  124.646660  0.99999997
    5  Gauss+Lor Amp   160.569907  373.503219  48.1317543  1.00000014  96.3457287  1.00000007
    6  Gauss+Lor Amp   503.063302  414.122863  43.3365126  1.00000000  86.7470539  1.00000000
    7  Gauss+Lor Amp   1895.84940  444.233512  41.7934627  1.00000000  83.6583181  1.00000000
    8  Gauss+Lor Amp   184.066912  486.789395  48.6046501  1.00000001  97.2923280  1.00000001
    9  Gauss+Lor Amp   120.666954  588.404799  26.9594175  1.00000000  53.9648878  1.00000000
   10  Gauss+Lor Amp   513.071762  615.482735  32.4731025  0.99999987  65.0016764  0.99999993
   11  Gauss+Lor Amp   193.449377  843.006368  51.6510276  1.00000030  103.390287  1.00000016

 Peak  Type            Anlytc Area   % Area     Int Area     % Area     Centroid    Moment2
    1  Gauss+Lor Amp   2325.89528  1.18307404  2299.14550  1.16962684  128.565814  105.135822
    2  Gauss+Lor Amp   1353.38063  0.68840137  1353.38063  0.68849506  146.509593  19.0085275
    3  Gauss+Lor Amp   4849.67375  2.46680200  4849.67375  2.46713771  207.124727  201.990629
    4  Gauss+Lor Amp   30936.1454  15.7357689  30936.1435  15.7379094  243.990896  699.267804
    5  Gauss+Lor Amp   8226.74540  4.18456025  8226.74540  4.18512974  373.503220  417.780278
    6  Gauss+Lor Amp   23206.4552  11.8040374  23206.4552  11.8056438  414.122863  338.682278
    7  Gauss+Lor Amp   84342.0981  42.9008769  84342.0981  42.9067153  444.233512  314.993260
    8  Gauss+Lor Amp   9523.26257  4.84403784  9523.26257  4.84469707  486.789395  426.030012
    9  Gauss+Lor Amp   3462.82915  1.76137908  3462.82915  1.76161879  588.404799  131.070682
   10  Gauss+Lor Amp   17735.1190  9.02102477  17735.1190  9.02225245  615.482734  190.165670
   11  Gauss+Lor Amp   10636.0045  5.41003754  10636.0045  5.41077380  843.006372  481.107895
       Total           1.966e+05   100.000000  1.9657e+05  100.000000

Parameter Statistics
Peak 1  Gauss+Lor Amp
 Parm  Value       Std Error   t-value     90
  Amp  87.2627551  5.92802948  14.7203646  77.4585868  97.0669234
  Ctr  128.241992  1.59061730  80.6240394  125.611323  130.872660
  Wid  25.0396945  3.68218119  6.80023423  18.9498591  31.1295300
 Shpe  1.00000000  0.03341947  29.9226727  0.94472866  1.05527134

Peak 2  Gauss+Lor Amp
 Parm  Value       Std Error   t-value     90
  Amp  123.838529  13.9681218  8.86579679  100.737123  146.939936
  Ctr  146.509593  0.45546668  321.669179  145.756312  147.262874
  Wid  10.2667258  1.24190879  8.26689193  8.21277464  12.3206769
 Shpe  1.00000000  0.03341947  29.9226727  0.94472866  1.05527134

Peak 3  Gauss+Lor Amp
 Parm  Value       Std Error   t-value     90
  Amp  136.130982  29.2127348  4.65998761  87.8170240  184.444940
  Ctr  207.124727  1.31415287  157.610831  204.951294  209.298160
  Wid  33.4675049  3.69901540  9.04767924  27.3498279  39.5851819
 Shpe  1.00000000  0.03341947  29.9226727  0.94472866  1.05527134

Peak 4  Gauss+Lor Amp
 Parm  Value       Std Error   t-value     90
  Amp  466.717535  8.72695409  53.4800035  452.284319  481.150750
  Ctr  243.990887  1.55068526  157.343913  241.426261  246.555513
  Wid  62.2701443  2.41278190  25.8084431  58.2797256  66.2605630
 Shpe  1.00000000  0.03341947  29.9226727  0.94472866  1.05527134

Peak 5  Gauss+Lor Amp
 Parm  Value       Std Error   t-value     90
  Amp  160.569907  67.6929372  2.37203338  48.6148380  272.524976
  Ctr  373.503220  12.1240559  30.8067881  353.451653  393.554788
  Wid  48.1317543  11.6051248  4.14745687  28.9384294  67.3250793
 Shpe  1.00000000  0.03341947  29.9226727  0.94472866  1.05527134

Peak 6  Gauss+Lor Amp
 Parm  Value       Std Error   t-value     90
  Amp  503.063302  365.768031  1.37536160  -101.86812  1107.99473
  Ctr  414.122863  11.6977335  35.4019744  394.776375  433.469350
  Wid  43.3365126  17.8499994  2.42781592  13.8149998  72.8580254
 Shpe  1.00000000  0.03341947  29.9226727  0.94472866  1.05527134

Peak 7  Gauss+Lor Amp
 Parm  Value       Std Error   t-value     90
  Amp  1895.84940  394.296065  4.80818747  1243.73642  2547.96238
  Ctr  444.233512  2.97096827  149.524826  439.319928  449.147097
  Wid  41.7934627  3.45986938  12.0794915  36.0713012  47.5156241
 Shpe  1.00000000  0.03341947  29.9226727  0.94472866  1.05527134

Peak 8  Gauss+Lor Amp
 Parm  Value       Std Error   t-value     90
  Amp  184.066912  38.0081132  4.84283214  121.206574  246.927251
  Ctr  486.789395  6.99542756  69.5867967  475.219893  498.358897
  Wid  48.6046501  7.99461103  6.07967666  35.3826322  61.8266680
 Shpe  1.00000000  0.03341947  29.9226727  0.94472866  1.05527134

Peak 9  Gauss+Lor Amp
 Parm  Value       Std Error   t-value     90
  Amp  120.666954  20.4538082  5.89948595  86.8390896  154.494819
  Ctr  588.404799  2.63443898  223.351083  584.047789  592.761809
  Wid  26.9594175  3.49086303  7.72285170  21.1859967  32.7328383
 Shpe  1.00000000  0.03341947  29.9226727  0.94472866  1.05527134

Peak 10  Gauss+Lor Amp
 Parm  Value       Std Error   t-value     90
  Amp  513.071762  12.3549867  41.5275042  492.638266  533.505259
  Ctr  615.482734  0.80850346  761.261724  614.145578  616.819891
  Wid  32.4731025  1.15308127  28.1620242  30.5660602  34.3801448
 Shpe  1.00000000  0.03341947  29.9226727  0.94472866  1.05527134

Peak 11  Gauss+Lor Amp
 Parm  Value       Std Error   t-value     90
  Amp  193.449377  3.79182793  51.0174459  187.178200  199.720553
  Ctr  843.006372  0.49426276  1705.58342  842.188928  843.823817
  Wid  51.6510276  1.17833472  43.8339180  49.7022194  53.5998357
 Shpe  1.00000000  0.03341947  29.9226727  0.94472866  1.05527134

Analysis of Variance
r^2 Coef Det  DF Adj r^2    Fit Std Err
0.99954195   0.99944980   9.30888827
Source   Sum of Squares    DF      Mean Square        F
Regr     32146762          33      974144.32          11241.588
Error    14731.418         170     86.655401
Total    32161494          203

Details of Fit
Set Convergence    State     Iterations   Minimization   Extent
    1E-6          Stopped        500     Least Squares    1/1
Curvature Matrix                Constraints                Violated
    Sparse-Roots  25.0000-5.00000-50.0000- None  - None        0