File: Data/Raman/peak_data/rutile_bu19ts(2)-ore2-rim_1800 (450-850nm)_532nm_edge_10%_x100_vis_swd_h30um_60sx2_peaks.txt
Description: #Acq. time (s)=	60
X Variable: #Accumulations=	2
Y Variable: #Range (cm-¹)=	100...1030
File Source: c:\users\u0125722\box sync\buranga\_article2-buranga_mineral_evolution\raman_spectra\raw_files\bu19ts(2)-ore2-rim_1800 (450-850nm)_532nm_edge_10%_x100_vis_h30um_60sx2_01.txt

Fitted Parameters
r^2 Coef Det  DF Adj r^2    Fit Std Err  F-value
0.99461198   0.99435190   6.12168677   3913.45167
 Peak  Type                  a0          a1          a2          a3
    1  Gauss+Lor Amp   7.87552910  121.329410  4.71156827  1.00000000
    2  Gauss+Lor Amp   22.5499732  138.681696  21.5258481  1.00000000
    3  Gauss+Lor Amp   10.8546180  195.884632  24.9050325  1.00000000
    4  Gauss+Lor Amp   57.8257569  255.658098  60.7171686  1.00000000
    5  Gauss+Lor Amp   56.7276323  299.840046  36.3493362  1.00000000
    6  Gauss+Lor Amp   55.5771614  421.907627  73.6470901  1.00000000
    7  Gauss+Lor Amp   23.6485088  468.585174  30.8952867  1.00000000
    8  Gauss+Lor Amp   51.7137251  489.452093  51.4752323  1.00000000
    9  Gauss+Lor Amp   62.1789422  586.410160  48.8394414  1.00000000
   10  Gauss+Lor Amp   98.5715282  610.453583  38.9588103  1.00000000
   11  Gauss+Lor Amp   298.293660  642.073945  57.0852578  1.00000000
   12  Gauss+Lor Amp   104.901176  683.430373  62.8076837  1.00000000
   13  Gauss+Lor Amp   23.0305151  800.330984  18.6975720  1.00000000
   14  Gauss+Lor Amp   26.9347070  825.118100  27.6933717  1.00000000
   15  Gauss+Lor Amp   46.1635423  845.780700  45.8939391  1.00000000

Measured Values
 Peak  Type             Amplitude    Center       FWHM       Asym50     FW Base      Asym10
    1  Gauss+Lor Amp   7.87552910  121.329410  4.71156828  1.00000000  9.43118497  1.00000000
    2  Gauss+Lor Amp   22.5499732  138.681696  21.5258481  1.00000000  43.0884673  1.00000000
    3  Gauss+Lor Amp   10.8546180  195.884632  24.9050325  0.99999999  49.8526085  0.99999999
    4  Gauss+Lor Amp   57.8257569  255.658098  60.7171686  1.00000000  121.538056  1.00000000
    5  Gauss+Lor Amp   56.7276323  299.840046  36.3493362  1.00000004  72.7607653  1.00000002
    6  Gauss+Lor Amp   55.5771614  421.907628  73.6470901  0.99999993  147.419986  0.99999996
    7  Gauss+Lor Amp   23.6485088  468.585175  30.8952867  0.99999992  61.8433495  0.99999996
    8  Gauss+Lor Amp   51.7137251  489.452093  51.4752323  0.99999999  103.038396  1.00000000
    9  Gauss+Lor Amp   62.1789422  586.410160  48.8394414  0.99999999  97.7623116  0.99999999
   10  Gauss+Lor Amp   98.5715282  610.453583  38.9588103  0.99999997  77.9841712  0.99999998
   11  Gauss+Lor Amp   298.293660  642.073945  57.0852578  1.00000000  114.268030  1.00000000
   12  Gauss+Lor Amp   104.901176  683.430373  62.8076837  1.00000000  125.722657  1.00000000
   13  Gauss+Lor Amp   23.0305151  800.330984  18.6975720  1.00000000  37.4270837  1.00000000
   14  Gauss+Lor Amp   26.9347070  825.118099  27.6933717  1.00000021  55.4340501  1.00000011
   15  Gauss+Lor Amp   46.1635423  845.780699  45.8939391  1.00000011  91.8662755  1.00000006

 Peak  Type            Anlytc Area   % Area     Int Area     % Area     Centroid    Moment2
    1  Gauss+Lor Amp   39.4982123  0.07788768  39.4982123  0.07788769  121.329410  4.00327596
    2  Gauss+Lor Amp   516.700059  1.01889600  516.693112  1.01888244  138.682239  83.5404576
    3  Gauss+Lor Amp   287.762282  0.56744688  287.762282  0.56744696  195.884632  111.855870
    4  Gauss+Lor Amp   3737.36099  7.36981172  3737.36098  7.36981273  255.658098  664.825335
    5  Gauss+Lor Amp   2194.94353  4.32827351  2194.94353  4.32827411  299.840046  238.274475
    6  Gauss+Lor Amp   4356.96592  8.59162887  4356.96592  8.59163004  421.907627  978.128099
    7  Gauss+Lor Amp   777.728834  1.53362629  777.728834  1.53362650  468.585174  172.134931
    8  Gauss+Lor Amp   2833.58567  5.58763068  2833.58567  5.58763145  489.452093  477.838549
    9  Gauss+Lor Amp   3232.55727  6.37437447  3232.55727  6.37437534  586.410160  430.155943
   10  Gauss+Lor Amp   4087.79762  8.06084800  4087.79762  8.06084910  610.453583  273.713316
   11  Gauss+Lor Amp   18125.9259  35.7430447  18125.9259  35.7430496  642.073945  587.668599
   12  Gauss+Lor Amp   7013.34726  13.8298251  7013.34726  13.8298270  683.430373  711.393850
   13  Gauss+Lor Amp   458.375162  0.90388342  458.375162  0.90388355  800.330984  63.0456286
   14  Gauss+Lor Amp   793.999632  1.56571116  793.999632  1.56571137  825.118100  138.304472
   15  Gauss+Lor Amp   2255.20835  4.44711148  2255.20835  4.44711209  845.780700  379.835212
       Total           50711.7567  100.000000  50711.7497  100.000000

Parameter Statistics
Peak 1  Gauss+Lor Amp
 Parm  Value       Std Error   t-value     90
  Amp  7.87552910  4.05401210  1.94265061  1.20079102  14.5502672
  Ctr  121.329410  1.15190137  105.329687  119.432859  123.225961
  Wid  4.71156827  2.97631743  1.58301941  -0.1887968  9.61193334
 Shpe  1.00000000  0.06100374  16.3924364  0.89956024  1.10043976

Peak 2  Gauss+Lor Amp
 Parm  Value       Std Error   t-value     90
  Amp  22.5499732  1.85527531  12.1545158  19.4953506  25.6045957
  Ctr  138.681696  0.95227110  145.632578  137.113827  140.249565
  Wid  21.5258481  2.51905321  8.54521374  17.3783468  25.6733494
 Shpe  1.00000000  0.06100374  16.3924364  0.89956024  1.10043976

Peak 3  Gauss+Lor Amp
 Parm  Value       Std Error   t-value     90
  Amp  10.8546180  2.11268470  5.13783152  7.37618317  14.3330529
  Ctr  195.884632  2.42905907  80.6421854  191.885301  199.883962
  Wid  24.9050325  6.04768707  4.11810866  14.9478034  34.8622616
 Shpe  1.00000000  0.06100374  16.3924364  0.89956024  1.10043976

Peak 4  Gauss+Lor Amp
 Parm  Value       Std Error   t-value     90
  Amp  57.8257569  1.52400763  37.9432200  55.3165509  60.3349630
  Ctr  255.658098  2.76482753  92.4680094  251.105941  260.210255
  Wid  60.7171686  6.57529809  9.23413171  49.8912531  71.5430842
 Shpe  1.00000000  0.06100374  16.3924364  0.89956024  1.10043976

Peak 5  Gauss+Lor Amp
 Parm  Value       Std Error   t-value     90
  Amp  56.7276323  6.62460257  8.56317518  45.8205393  67.6347253
  Ctr  299.840046  1.29511203  231.516687  297.707706  301.972387
  Wid  36.3493362  2.42817384  14.9698245  32.3514635  40.3472089
 Shpe  1.00000000  0.06100374  16.3924364  0.89956024  1.10043976

Peak 6  Gauss+Lor Amp
 Parm  Value       Std Error   t-value     90
  Amp  55.5771614  3.39129897  16.3881633  49.9935490  61.1607738
  Ctr  421.907627  4.68925620  89.9732514  414.186990  429.628264
  Wid  73.6470901  6.48448301  11.3574343  62.9706972  84.3234829
 Shpe  1.00000000  0.06100374  16.3924364  0.89956024  1.10043976

Peak 7  Gauss+Lor Amp
 Parm  Value       Std Error   t-value     90
  Amp  23.6485088  47.9988233  0.49268934  -55.379271  102.676288
  Ctr  468.585174  3.09194489  151.550300  463.494434  473.675914
  Wid  30.8952867  17.6922816  1.74625790  1.76578654  60.0247868
 Shpe  1.00000000  0.06100374  16.3924364  0.89956024  1.10043976

Peak 8  Gauss+Lor Amp
 Parm  Value       Std Error   t-value     90
  Amp  51.7137251  28.4602637  1.81705011  4.85525480  98.5721954
  Ctr  489.452093  18.9304236  25.8553164  458.284051  520.620135
  Wid  51.4752323  18.7022568  2.75235406  20.6828562  82.2676085
 Shpe  1.00000000  0.06100374  16.3924364  0.89956024  1.10043976

Peak 9  Gauss+Lor Amp
 Parm  Value       Std Error   t-value     90
  Amp  62.1789422  95.0923195  0.65387975  -94.386038  218.743923
  Ctr  586.410160  37.9556389  15.4498825  523.918006  648.902314
  Wid  48.8394414  29.8802942  1.63450336  -0.3570417  98.0359244
 Shpe  1.00000000  0.06100374  16.3924364  0.89956024  1.10043976

Peak 10  Gauss+Lor Amp
 Parm  Value       Std Error   t-value     90
  Amp  98.5715282  249.891707  0.39445698  -312.86328  510.006337
  Ctr  610.453583  6.78008110  90.0363245  599.290502  621.616664
  Wid  38.9588103  18.6520221  2.08871779  8.24914321  69.6684775
 Shpe  1.00000000  0.06100374  16.3924364  0.89956024  1.10043976

Peak 11  Gauss+Lor Amp
 Parm  Value       Std Error   t-value     90
  Amp  298.293660  170.751835  1.74694263  17.1588857  579.428433
  Ctr  642.073945  5.69082104  112.826241  632.704278  651.443611
  Wid  57.0852578  24.9536408  2.28765246  16.0002752  98.1702404
 Shpe  1.00000000  0.06100374  16.3924364  0.89956024  1.10043976

Peak 12  Gauss+Lor Amp
 Parm  Value       Std Error   t-value     90
  Amp  104.901176  133.631546  0.78500308  -115.11681  324.919160
  Ctr  683.430373  33.1819210  20.5964680  628.797919  738.062828
  Wid  62.8076837  22.2243416  2.82607624  26.2163624  99.3990050
 Shpe  1.00000000  0.06100374  16.3924364  0.89956024  1.10043976

Peak 13  Gauss+Lor Amp
 Parm  Value       Std Error   t-value     90
  Amp  23.0305151  4.26741831  5.39682625  16.0044139  30.0566164
  Ctr  800.330984  2.11473968  378.453666  796.849165  803.812802
  Wid  18.6975720  3.42272333  5.46277633  13.0622208  24.3329231
 Shpe  1.00000000  0.06100374  16.3924364  0.89956024  1.10043976

Peak 14  Gauss+Lor Amp
 Parm  Value       Std Error   t-value     90
  Amp  26.9347070  38.1798351  0.70546944  -35.926575  89.7959893
  Ctr  825.118100  2.59471362  317.999680  820.846028  829.390173
  Wid  27.6933717  14.9424557  1.85333470  3.09132915  52.2954143
 Shpe  1.00000000  0.06100374  16.3924364  0.89956024  1.10043976

Peak 15  Gauss+Lor Amp
 Parm  Value       Std Error   t-value     90
  Amp  46.1635423  19.1755909  2.40741172  14.5918440  77.7352405
  Ctr  845.780700  13.6851955  61.8026025  823.248677  868.312724
  Wid  45.8939391  13.2876606  3.45387653  24.0164380  67.7714402
 Shpe  1.00000000  0.06100374  16.3924364  0.89956024  1.10043976

Analysis of Variance
r^2 Coef Det  DF Adj r^2    Fit Std Err
0.99461198   0.99435190   6.12168677
Source   Sum of Squares    DF      Mean Square        F
Regr     6599555.7         45      146656.79          3913.4517
Error    35751.197         954     37.475049
Total    6635306.9         999

Details of Fit
Set Convergence    State     Iterations   Minimization   Extent
    1E-6          Stopped        500     Least Squares    1/1
Curvature Matrix                Constraints                Violated
    Sparse-Roots  25.0000-5.00000-50.0000- None  - None        0