File: Data/Raman/peak_data/rutile_bu04-ore2-bright_150 (500nm)_532nm_edge_10%_x50_vis_lwd_h30um_40sx2_peaks.txt
Description: #Acq. time (s)=	40
X Variable: #Accumulations=	2
Y Variable: #Range (cm-¹)=	100...4000
File Source: c:\users\u0125722\box sync\buranga\_article2-buranga_mineral_evolution\raman_spectra\raw_files\bu04-ore2-bright_150 (500nm)_532nm_edge_10%_x10_vis_h30um_40sx2_01.txt

Fitted Parameters
r^2 Coef Det  DF Adj r^2    Fit Std Err  F-value
0.99788637   0.99727100   2.82980672   1668.15259
 Peak  Type                  a0          a1          a2          a3
    1  Gauss+Lor Amp   8.32725267  152.061976  23.7408492  0.95257221
    2  Gauss+Lor Amp   22.0209748  205.125305  31.6483563  0.95257221
    3  Gauss+Lor Amp   30.4239652  217.945052  6.99882228  0.95257221
    4  Gauss+Lor Amp   17.8832239  240.931626  21.5672474  0.95257221
    5  Gauss+Lor Amp   72.4076365  264.572072  50.6981401  0.95257221
    6  Gauss+Lor Amp   28.2295672  301.885149  40.2974423  0.95257221
    7  Gauss+Lor Amp   35.1753109  392.126240  29.4434839  0.95257221
    8  Gauss+Lor Amp   175.220312  428.149939  60.9284461  0.95257221
    9  Gauss+Lor Amp   60.1831721  474.582085  33.6945962  0.95257221
   10  Gauss+Lor Amp   64.8915043  502.032931  42.2675156  0.95257221
   11  Gauss+Lor Amp   22.0011424  598.424288  49.2148642  0.95257221
   12  Gauss+Lor Amp   156.939982  637.293673  73.0278601  0.95257221
   13  Gauss+Lor Amp   22.9082209  683.455459  53.7814160  0.95257221
   14  Gauss+Lor Amp   66.2890081  803.171979  49.6147264  0.95257221
   15  Gauss+Lor Amp   138.935250  842.231803  46.3849246  0.95257221

Measured Values
 Peak  Type             Amplitude    Center       FWHM       Asym50     FW Base      Asym10
    1  Gauss+Lor Amp   8.32725267  152.061976  23.7408492  1.00000010  47.9931007  1.00000006
    2  Gauss+Lor Amp   22.0209748  205.125305  31.6483563  0.99999999  63.9784505  1.00000000
    3  Gauss+Lor Amp   30.4239652  217.945052  6.99882229  1.00000005  14.1484064  1.00000002
    4  Gauss+Lor Amp   17.8832239  240.931626  21.5672474  1.00000001  43.5990754  1.00000000
    5  Gauss+Lor Amp   72.4076365  264.572072  50.6981401  1.00000000  102.488370  1.00000000
    6  Gauss+Lor Amp   28.2295672  301.885149  40.2974423  1.00000001  81.4629327  1.00000000
    7  Gauss+Lor Amp   35.1753109  392.126238  29.4434839  1.00000024  59.5212105  1.00000013
    8  Gauss+Lor Amp   175.220312  428.149940  60.9284461  0.99999993  123.169353  0.99999996
    9  Gauss+Lor Amp   60.1831721  474.582085  33.6945962  1.00000000  68.1150085  1.00000000
   10  Gauss+Lor Amp   64.8915043  502.032929  42.2675156  1.00000017  85.4455167  1.00000009
   11  Gauss+Lor Amp   22.0011424  598.424288  49.2148642  0.99999996  99.4898668  0.99999998
   12  Gauss+Lor Amp   156.939982  637.293673  73.0278601  1.00000000  147.628815  1.00000000
   13  Gauss+Lor Amp   22.9082209  683.455459  53.7814160  1.00000000  108.721339  1.00000000
   14  Gauss+Lor Amp   66.2890081  803.171980  49.6147264  0.99999997  100.298205  0.99999998
   15  Gauss+Lor Amp   138.935250  842.231800  46.3849246  1.00000027  93.7690279  1.00000015

 Peak  Type            Anlytc Area   % Area     Int Area     % Area     Centroid    Moment2
    1  Gauss+Lor Amp   213.708060  0.42705187  212.882772  0.42637588  152.573103  252.223234
    2  Gauss+Lor Amp   753.373963  1.50546384  751.383853  1.50492192  205.616555  375.996120
    3  Gauss+Lor Amp   230.177935  0.45996354  230.055798  0.46077117  218.046901  55.2715579
    4  Gauss+Lor Amp   416.930284  0.83314993  416.346641  0.83388695  241.210545  220.887310
    5  Gauss+Lor Amp   3968.25258  7.92974150  3956.81666  7.92497751  265.152140  758.207608
    6  Gauss+Lor Amp   1229.71540  2.45733481  1227.29774  2.45811415  302.268424  534.393030
    7  Gauss+Lor Amp   1119.56690  2.23722556  1118.29595  2.23979806  392.292575  338.706370
    8  Gauss+Lor Amp   11540.5753  23.0614804  11515.0027  23.0630188  428.411224  1010.67008
    9  Gauss+Lor Amp   2192.08928  4.38044228  2189.52816  4.38533370  474.671467  410.630815
   10  Gauss+Lor Amp   2964.95067  5.92484775  2960.68346  5.92985519  502.105161  573.513351
   11  Gauss+Lor Amp   1170.48117  2.33896732  1168.52482  2.34039981  598.348341  722.971822
   12  Gauss+Lor Amp   12389.2519  24.7573870  12357.7722  24.7509741  637.084133  1354.40128
   13  Gauss+Lor Amp   1331.82298  2.66137594  1329.19412  2.66219904  683.212247  829.918598
   14  Gauss+Lor Amp   3555.28998  7.10452017  3546.70370  7.10357581  802.701377  732.821084
   15  Gauss+Lor Amp   6966.46100  13.9210481  6947.93908  13.9157979  841.696603  661.221725
       Total           50042.6474  100.000000  49928.4276  100.000000

Parameter Statistics
Peak 1  Gauss+Lor Amp
 Parm  Value       Std Error   t-value     90
  Amp  8.32725267  1.79590420  4.63680226  5.35594084  11.2985645
  Ctr  152.061976  2.55258431  59.5717741  147.838742  156.285210
  Wid  23.7408492  6.28368087  3.77817552  13.3445401  34.1371584
 Shpe  0.95257221  0.04167410  22.8576536  0.88362268  1.02152174

Peak 2  Gauss+Lor Amp
 Parm  Value       Std Error   t-value     90
  Amp  22.0209748  12.8675232  1.71136080  0.73174126  43.3102083
  Ctr  205.125305  9.72666466  21.0889665  189.032601  221.218008
  Wid  31.6483563  11.3721668  2.78296623  12.8331801  50.4635325
 Shpe  0.95257221  0.04167410  22.8576536  0.88362268  1.02152174

Peak 3  Gauss+Lor Amp
 Parm  Value       Std Error   t-value     90
  Amp  30.4239652  6.41588490  4.74197491  19.8089253  41.0390051
  Ctr  217.945052  0.59996105  363.265337  216.952421  218.937684
  Wid  6.99882228  1.63332088  4.28502589  4.29650349  9.70114108
 Shpe  0.95257221  0.04167410  22.8576536  0.88362268  1.02152174

Peak 4  Gauss+Lor Amp
 Parm  Value       Std Error   t-value     90
  Amp  17.8832239  54.5902415  0.32759012  -72.435976  108.202424
  Ctr  240.931626  4.54033310  53.0647469  233.419675  248.443578
  Wid  21.5672474  24.9286888  0.86515772  -19.677106  62.8116011
 Shpe  0.95257221  0.04167410  22.8576536  0.88362268  1.02152174

Peak 5  Gauss+Lor Amp
 Parm  Value       Std Error   t-value     90
  Amp  72.4076365  21.6308761  3.34742043  36.6194926  108.195781
  Ctr  264.572072  6.81771058  38.8065860  253.292214  275.851929
  Wid  50.6981401  50.6239297  1.00146592  -33.058823  134.455103
 Shpe  0.95257221  0.04167410  22.8576536  0.88362268  1.02152174

Peak 6  Gauss+Lor Amp
 Parm  Value       Std Error   t-value     90
  Amp  28.2295672  54.6798811  0.51626973  -62.237941  118.697075
  Ctr  301.885149  18.9844204  15.9017312  270.475549  333.294749
  Wid  40.2974423  14.3078586  2.81645516  16.6251831  63.9697014
 Shpe  0.95257221  0.04167410  22.8576536  0.88362268  1.02152174

Peak 7  Gauss+Lor Amp
 Parm  Value       Std Error   t-value     90
  Amp  35.1753109  13.5941112  2.58754033  12.6839423  57.6666796
  Ctr  392.126240  1.25002179  313.695524  390.058087  394.194393
  Wid  29.4434839  5.66498371  5.19745252  20.0708051  38.8161626
 Shpe  0.95257221  0.04167410  22.8576536  0.88362268  1.02152174

Peak 8  Gauss+Lor Amp
 Parm  Value       Std Error   t-value     90
  Amp  175.220312  2.44642165  71.6231041  171.172724  179.267901
  Ctr  428.149939  1.34987951  317.176412  425.916572  430.383306
  Wid  60.9284461  5.27005728  11.5612493  52.2091706  69.6477217
 Shpe  0.95257221  0.04167410  22.8576536  0.88362268  1.02152174

Peak 9  Gauss+Lor Amp
 Parm  Value       Std Error   t-value     90
  Amp  60.1831721  31.9847736  1.88161945  7.26457194  113.101772
  Ctr  474.582085  4.18286687  113.458568  467.661559  481.502611
  Wid  33.6945962  6.85770381  4.91339334  22.3485698  45.0406226
 Shpe  0.95257221  0.04167410  22.8576536  0.88362268  1.02152174

Peak 10  Gauss+Lor Amp
 Parm  Value       Std Error   t-value     90
  Amp  64.8915043  17.0210634  3.81242364  36.7302655  93.0527431
  Ctr  502.032931  7.68597214  65.3180784  489.316540  514.749322
  Wid  42.2675156  8.78579763  4.81089110  27.7314705  56.8035607
 Shpe  0.95257221  0.04167410  22.8576536  0.88362268  1.02152174

Peak 11  Gauss+Lor Amp
 Parm  Value       Std Error   t-value     90
  Amp  22.0011424  107.969112  0.20377256  -156.63305  200.635337
  Ctr  598.424288  20.4866120  29.2105052  564.529321  632.319254
  Wid  49.2148642  52.3062029  0.94089920  -37.325409  135.755137
 Shpe  0.95257221  0.04167410  22.8576536  0.88362268  1.02152174

Peak 12  Gauss+Lor Amp
 Parm  Value       Std Error   t-value     90
  Amp  156.939982  47.4737078  3.30582947  78.3950411  235.484923
  Ctr  637.293673  15.2246841  41.8592378  612.104532  662.482814
  Wid  73.0278601  34.2744370  2.13068008  16.3210268  129.734693
 Shpe  0.95257221  0.04167410  22.8576536  0.88362268  1.02152174

Peak 13  Gauss+Lor Amp
 Parm  Value       Std Error   t-value     90
  Amp  22.9082209  50.0548164  0.45766267  -59.907148  105.723590
  Ctr  683.455459  18.0581605  37.8474573  653.578349  713.332568
  Wid  53.7814160  19.6757045  2.73339214  21.2280907  86.3347412
 Shpe  0.95257221  0.04167410  22.8576536  0.88362268  1.02152174

Peak 14  Gauss+Lor Amp
 Parm  Value       Std Error   t-value     90
  Amp  66.2890081  7.25685068  9.13467991  54.2825958  78.2954204
  Ctr  803.171979  3.72469522  215.634282  797.009495  809.334463
  Wid  49.6147264  4.27536762  11.6047860  42.5411584  56.6882943
 Shpe  0.95257221  0.04167410  22.8576536  0.88362268  1.02152174

Peak 15  Gauss+Lor Amp
 Parm  Value       Std Error   t-value     90
  Amp  138.935250  8.68622205  15.9948997  124.563952  153.306548
  Ctr  842.231803  1.56118402  539.482722  839.648835  844.814772
  Wid  46.3849246  1.70940304  27.1351597  43.5567283  49.2131208
 Shpe  0.95257221  0.04167410  22.8576536  0.88362268  1.02152174

Analysis of Variance
r^2 Coef Det  DF Adj r^2    Fit Std Err
0.99788637   0.99727100   2.82980672
Source   Sum of Squares    DF      Mean Square        F
Regr     601120.91         45      13358.242          1668.1526
Error    1273.2412         159     8.0078061
Total    602394.15         204

Details of Fit
Set Convergence    State     Iterations   Minimization   Extent
    1E-6         Converged        51     Least Squares    1/1
Curvature Matrix                Constraints                Violated
    Sparse-Roots  25.0000-5.00000-50.0000- None  - None        0