File: Data/Raman/peak_data/rutile_bu02a-area1-top-rutile-opaq2_150 (500nm)_633nm_edge_50%_x50_vis_lwd_h100um_10sx2_peaks.txt
Description: #Acq. time (s)=	10
X Variable: #Accumulations=	2
Y Variable: #Range (cm-¹)=	100...2500
File Source: c:\users\u0125722\box sync\buranga\_article2-buranga_mineral_evolution\raman_spectra\raw_files\bu02a-area1-top-rutile-opaq2_150 (500nm)_633nm_edge_50%_x50_vis_lwd_h100um_10sx2_01.txt

Fitted Parameters
r^2 Coef Det  DF Adj r^2    Fit Std Err  F-value
0.99964461   0.99958349   18.5989020   16810.1081
 Peak  Type                  a0          a1          a2          a3
    1  Gauss+Lor Amp   136.525384  125.327177  24.2236171  0.87616707
    2  Gauss+Lor Amp   368.489492  138.756556  10.1655593  0.87616707
    3  Gauss+Lor Amp   171.451037  190.131831  24.1572821  0.87616707
    4  Gauss+Lor Amp   330.898279  211.101646  37.0787622  0.87616707
    5  Gauss+Lor Amp   728.377329  239.674902  48.9395067  0.87616707
    6  Gauss+Lor Amp   73.1381848  352.350416  33.3824762  0.87616707
    7  Gauss+Lor Amp   713.103800  423.960828  64.0986379  0.87616707
    8  Gauss+Lor Amp   1628.15784  440.498780  34.3323531  0.87616707
    9  Gauss+Lor Amp   242.440798  454.143089  35.6980060  0.87616707
   10  Gauss+Lor Amp   725.373351  572.804814  38.9709935  0.87616707
   11  Gauss+Lor Amp   4325.77999  611.011992  43.9578324  0.87616707
   12  Gauss+Lor Amp   595.721585  652.212848  36.2900130  0.87616707
   13  Gauss+Lor Amp   431.111458  683.203359  56.7549453  0.87616707
   14  Gauss+Lor Amp   58.5917486  820.293151  45.0107020  0.87616707

Measured Values
 Peak  Type             Amplitude    Center       FWHM       Asym50     FW Base      Asym10
    1  Gauss+Lor Amp   136.525384  125.327177  24.2236171  1.00000003  49.8300846  1.00000002
    2  Gauss+Lor Amp   368.489492  138.756556  10.1655594  1.00000000  20.9114386  1.00000000
    3  Gauss+Lor Amp   171.451037  190.131831  24.1572821  1.00000000  49.6936278  1.00000000
    4  Gauss+Lor Amp   330.898279  211.101646  37.0787622  1.00000000  76.2742349  1.00000000
    5  Gauss+Lor Amp   728.377329  239.674902  48.9395067  1.00000000  100.672817  1.00000000
    6  Gauss+Lor Amp   73.1381848  352.350416  33.3824762  1.00000000  68.6706533  1.00000000
    7  Gauss+Lor Amp   713.103800  423.960828  64.0986379  1.00000000  131.856466  1.00000000
    8  Gauss+Lor Amp   1628.15784  440.498780  34.3323531  0.99999998  70.6246327  0.99999999
    9  Gauss+Lor Amp   242.440798  454.143089  35.6980060  1.00000000  73.4338994  1.00000000
   10  Gauss+Lor Amp   725.373351  572.804814  38.9709935  1.00000000  80.1667189  1.00000000
   11  Gauss+Lor Amp   4325.77999  611.011992  43.9578324  1.00000000  90.4250798  1.00000000
   12  Gauss+Lor Amp   595.721585  652.212848  36.2900130  1.00000000  74.6517091  1.00000000
   13  Gauss+Lor Amp   431.111458  683.203357  56.7549453  1.00000015  116.749853  1.00000008
   14  Gauss+Lor Amp   58.5917486  820.293150  45.0107020  1.00000001  92.5909239  1.00000000

 Peak  Type            Anlytc Area   % Area     Int Area     % Area     Centroid    Moment2
    1  Gauss+Lor Amp   3666.70082  0.61975892  3552.05756  0.84055363  127.378040  510.733222
    2  Gauss+Lor Amp   4153.16766  0.70198328  4129.42137  0.97718015  139.393272  194.256348
    3  Gauss+Lor Amp   4592.09922  0.77617307  4564.62288  1.08016559  191.193655  505.313182
    4  Gauss+Lor Amp   13603.2541  2.29927078  13500.0548  3.19463295  212.553342  839.091103
    5  Gauss+Lor Amp   39522.0153  6.68015270  39197.1011  9.27554388  241.328290  1184.10785
    6  Gauss+Lor Amp   2706.98469  0.45754426  2697.12815  0.63824441  352.980338  736.874226
    7  Gauss+Lor Amp   50678.6021  8.56587898  50369.5222  11.9193690  424.702753  1674.62143
    8  Gauss+Lor Amp   61975.9441  10.4753962  61777.3643  14.6189039  440.843026  761.855775
    9  Gauss+Lor Amp   9595.61331  1.62188496  9564.12025  2.26323923  454.455813  798.525923
   10  Gauss+Lor Amp   31341.9598  5.29753039  31234.7916  7.39135475  572.734868  888.379072
   11  Gauss+Lor Amp   2.1083e+05  35.6345336  2.1e+05     49.6942124  610.784496  1030.89831
   12  Gauss+Lor Amp   23969.1998  4.05136006  23889.0959  5.65308023  651.889497  814.588258
   13  Gauss+Lor Amp   27127.9108  4.58525673  26980.8442  6.38470696  682.532864  1427.36143
   14  Gauss+Lor Amp   2923.98621  0.49422263  2906.19130  0.68771680  819.074579  1063.67525
       Total           5.9163e+05  100.000000  4.2259e+05  100.000000

Parameter Statistics
Peak 1  Gauss+Lor Amp
 Parm  Value       Std Error   t-value     90
  Amp  136.525384  14.4859827  9.42465466  112.609794  160.440974
  Ctr  125.327177  3.25549830  38.4970795  119.952522  130.701832
  Wid  24.2236171  5.49963006  4.40459028  15.1440192  33.3032150
 Shpe  0.87616707  0.02101855  41.6854265  0.84146656  0.91086757

Peak 2  Gauss+Lor Amp
 Parm  Value       Std Error   t-value     90
  Amp  368.489492  45.4191035  8.11309479  293.504958  443.474026
  Ctr  138.756556  0.25376134  546.799435  138.337609  139.175502
  Wid  10.1655593  1.04857343  9.69465661  8.43442016  11.8966985
 Shpe  0.87616707  0.02101855  41.6854265  0.84146656  0.91086757

Peak 3  Gauss+Lor Amp
 Parm  Value       Std Error   t-value     90
  Amp  171.451037  362.517638  0.47294537  -427.04638  769.948454
  Ctr  190.131831  5.29634859  35.8986626  181.387840  198.875822
  Wid  24.1572821  13.7772539  1.75341780  1.41176579  46.9027985
 Shpe  0.87616707  0.02101855  41.6854265  0.84146656  0.91086757

Peak 4  Gauss+Lor Amp
 Parm  Value       Std Error   t-value     90
  Amp  330.898279  434.222433  0.76204787  -385.97995  1047.77651
  Ctr  211.101646  7.49537310  28.1642612  198.727182  223.476110
  Wid  37.0787622  34.7334980  1.06752168  -20.264403  94.4219274
 Shpe  0.87616707  0.02101855  41.6854265  0.84146656  0.91086757

Peak 5  Gauss+Lor Amp
 Parm  Value       Std Error   t-value     90
  Amp  728.377329  251.495497  2.89618437  313.171586  1143.58307
  Ctr  239.674902  8.84970371  27.0828165  225.064510  254.285294
  Wid  48.9395067  6.92705921  7.06497595  37.5032989  60.3757145
 Shpe  0.87616707  0.02101855  41.6854265  0.84146656  0.91086757

Peak 6  Gauss+Lor Amp
 Parm  Value       Std Error   t-value     90
  Amp  73.1381848  9.96135751  7.34219053  56.6925113  89.5838584
  Ctr  352.350416  2.98880234  117.890170  347.416062  357.284771
  Wid  33.3824762  6.65096076  5.01919608  22.4020923  44.3628600
 Shpe  0.87616707  0.02101855  41.6854265  0.84146656  0.91086757

Peak 7  Gauss+Lor Amp
 Parm  Value       Std Error   t-value     90
  Amp  713.103800  145.181371  4.91181336  473.417046  952.790553
  Ctr  423.960828  6.00683472  70.5797392  414.043862  433.877794
  Wid  64.0986379  5.53087320  11.5892438  54.9674593  73.2298166
 Shpe  0.87616707  0.02101855  41.6854265  0.84146656  0.91086757

Peak 8  Gauss+Lor Amp
 Parm  Value       Std Error   t-value     90
  Amp  1628.15784  1575.62587  1.03334039  -973.11700  4229.43268
  Ctr  440.498780  6.00962689  73.2988567  430.577205  450.420356
  Wid  34.3323531  4.05599095  8.46460299  27.6361269  41.0285793
 Shpe  0.87616707  0.02101855  41.6854265  0.84146656  0.91086757

Peak 9  Gauss+Lor Amp
 Parm  Value       Std Error   t-value     90
  Amp  242.440798  1525.05921  0.15897140  -2275.3512  2760.23277
  Ctr  454.143089  51.0691157  8.89271496  369.830684  538.455493
  Wid  35.6980060  27.7560663  1.28613348  -10.125789  81.5218011
 Shpe  0.87616707  0.02101855  41.6854265  0.84146656  0.91086757

Peak 10  Gauss+Lor Amp
 Parm  Value       Std Error   t-value     90
  Amp  725.373351  81.1219093  8.94176872  591.445376  859.301326
  Ctr  572.804814  1.94298464  294.806661  569.597050  576.012579
  Wid  38.9709935  2.19894525  17.7225847  35.3406513  42.6013356
 Shpe  0.87616707  0.02101855  41.6854265  0.84146656  0.91086757

Peak 11  Gauss+Lor Amp
 Parm  Value       Std Error   t-value     90
  Amp  4325.77999  43.9496708  98.4257653  4253.22141  4398.33856
  Ctr  611.011992  0.23607816  2588.17670  610.622239  611.401745
  Wid  43.9578324  1.28105397  34.3138021  41.8428802  46.0727847
 Shpe  0.87616707  0.02101855  41.6854265  0.84146656  0.91086757

Peak 12  Gauss+Lor Amp
 Parm  Value       Std Error   t-value     90
  Amp  595.721585  152.415269  3.90854269  344.092050  847.351120
  Ctr  652.212848  1.52581592  427.451858  649.693807  654.731890
  Wid  36.2900130  4.86115536  7.46530614  28.2645030  44.3155230
 Shpe  0.87616707  0.02101855  41.6854265  0.84146656  0.91086757

Peak 13  Gauss+Lor Amp
 Parm  Value       Std Error   t-value     90
  Amp  431.111458  66.1042635  6.52168914  321.976820  540.246095
  Ctr  683.203359  6.37389999  107.187650  672.680388  693.726330
  Wid  56.7549453  6.68109822  8.49485270  45.7248060  67.7850845
 Shpe  0.87616707  0.02101855  41.6854265  0.84146656  0.91086757

Peak 14  Gauss+Lor Amp
 Parm  Value       Std Error   t-value     90
  Amp  58.5917486  6.85200260  8.55104004  47.2794553  69.9040419
  Ctr  820.293151  2.58483586  317.348255  816.025723  824.560578
  Wid  45.0107020  6.40352733  7.02904816  34.4388176  55.5825864
 Shpe  0.87616707  0.02101855  41.6854265  0.84146656  0.91086757

Analysis of Variance
r^2 Coef Det  DF Adj r^2    Fit Std Err
0.99964461   0.99958349   18.5989020
Source   Sum of Squares    DF      Mean Square        F
Regr     2.4422741e+08     42      5814938.4          16810.108
Error    86825.708         251     345.91916
Total    2.4431424e+08     293

Details of Fit
Set Convergence    State     Iterations   Minimization   Extent
    1E-6         Converged        73     Least Squares    1/1
Curvature Matrix                Constraints                Violated
    Sparse-Roots  25.0000-5.00000-50.0000- None  - None        0