File: Data/Raman/peak_data/rutile_bu19ts(2)-ore2-core_1800 (450-850nm)_532nm_edge_10%_x100_vis_swd_h30um_60sx2_peaks.txt
Description: #Acq. time (s)=	60
X Variable: #Accumulations=	2
Y Variable: #Range (cm-¹)=	100...1030
File Source: c:\users\u0125722\box sync\buranga\_article2-buranga_mineral_evolution\raman_spectra\raw_files\bu19ts(2)-ore2-core_1800 (450-850nm)_532nm_edge_10%_x100_vis_h30um_60sx2_01.txt

Fitted Parameters
r^2 Coef Det  DF Adj r^2    Fit Std Err  F-value
0.99693079   0.99678264   7.21633172   6886.10624
 Peak  Type                  a0          a1          a2          a3
    1  Gauss+Lor Amp   42.0593060  113.613193  19.8667162  1.00000000
    2  Gauss+Lor Amp   64.2771267  136.691529  20.5439490  1.00000000
    3  Gauss+Lor Amp   35.5114084  200.076102  31.6955880  1.00000000
    4  Gauss+Lor Amp   98.3242116  256.530942  61.0367496  1.00000000
    5  Gauss+Lor Amp   75.8451473  301.289863  27.3577324  1.00000000
    6  Gauss+Lor Amp   90.2089073  436.556877  60.1283263  1.00000000
    7  Gauss+Lor Amp   31.1198916  469.062618  29.2152880  1.00000000
    8  Gauss+Lor Amp   74.8154068  490.365586  34.9977864  1.00000000
    9  Gauss+Lor Amp   181.915581  586.283987  43.1022066  1.00000000
   10  Gauss+Lor Amp   422.172547  614.764956  36.0483730  1.00000000
   11  Gauss+Lor Amp   323.497813  648.837831  44.6400957  1.00000000
   12  Gauss+Lor Amp   143.377336  675.750807  66.8321322  1.00000000
   13  Gauss+Lor Amp   19.7174569  794.210443  15.4392093  1.00000000
   14  Gauss+Lor Amp   51.6277959  817.177182  32.5095598  1.00000000
   15  Gauss+Lor Amp   84.4832192  844.977771  36.4110674  1.00000000

Measured Values
 Peak  Type             Amplitude    Center       FWHM       Asym50     FW Base      Asym10
    1  Gauss+Lor Amp   42.0593060  113.613193  19.8667162  0.99999999  39.7673693  1.00000000
    2  Gauss+Lor Amp   64.2771267  136.691529  20.5439490  0.99999996  41.1229918  0.99999998
    3  Gauss+Lor Amp   35.5114084  200.076102  31.6955880  1.00000000  63.4453192  1.00000000
    4  Gauss+Lor Amp   98.3242116  256.530944  61.0367496  0.99999992  122.177764  0.99999996
    5  Gauss+Lor Amp   75.8451473  301.289863  27.3577324  1.00000003  54.7621981  1.00000001
    6  Gauss+Lor Amp   90.2089073  436.556877  60.1283263  1.00000000  120.359366  1.00000000
    7  Gauss+Lor Amp   31.1198916  469.062618  29.2152880  1.00000001  58.4804824  1.00000001
    8  Gauss+Lor Amp   74.8154068  490.365586  34.9977864  1.00000001  70.0553569  1.00000000
    9  Gauss+Lor Amp   181.915581  586.283987  43.1022066  0.99999999  86.2780415  1.00000000
   10  Gauss+Lor Amp   422.172547  614.764956  36.0483730  1.00000000  72.1583248  1.00000000
   11  Gauss+Lor Amp   323.497813  648.837831  44.6400957  1.00000000  89.3564468  1.00000000
   12  Gauss+Lor Amp   143.377336  675.750807  66.8321322  1.00000000  133.778429  1.00000000
   13  Gauss+Lor Amp   19.7174569  794.210442  15.4392093  1.00000032  30.9047922  1.00000018
   14  Gauss+Lor Amp   51.6277959  817.177182  32.5095598  0.99999998  65.0746533  0.99999999
   15  Gauss+Lor Amp   84.4832192  844.977773  36.4110674  0.99999981  72.8843332  0.99999990

 Peak  Type            Anlytc Area   % Area     Int Area     % Area     Centroid    Moment2
    1  Gauss+Lor Amp   889.447669  1.15329814  838.451700  1.08789412  114.641952  56.4262170
    2  Gauss+Lor Amp   1405.63510  1.82261015  1405.61378  1.82378896  136.692110  76.0907342
    3  Gauss+Lor Amp   1198.11614  1.55353167  1198.11614  1.55456003  200.076102  181.168287
    4  Gauss+Lor Amp   6388.28203  8.28333589  6388.28202  8.28881905  256.530943  671.842286
    5  Gauss+Lor Amp   2208.71717  2.86392274  2208.71717  2.86581852  301.289863  134.972331
    6  Gauss+Lor Amp   5773.78686  7.48655362  5773.78686  7.49150935  436.556877  651.992775
    7  Gauss+Lor Amp   967.788502  1.25487842  967.788502  1.25570908  469.062618  153.923488
    8  Gauss+Lor Amp   2787.17237  3.61397396  2787.17237  3.61636623  490.365586  220.884735
    9  Gauss+Lor Amp   8346.44645  10.8223806  8346.44645  10.8295445  586.283987  335.029894
   10  Gauss+Lor Amp   16199.7334  21.0053082  16199.7334  21.0192127  614.764956  234.345106
   11  Gauss+Lor Amp   15371.9398  19.9319536  15371.9398  19.9451475  648.837831  359.364179
   12  Gauss+Lor Amp   10199.9498  13.2257170  10199.9498  13.2344717  675.750807  805.480788
   13  Gauss+Lor Amp   324.047119  0.42017417  324.047119  0.42045231  794.210443  42.9867547
   14  Gauss+Lor Amp   1786.59816  2.31658412  1786.59816  2.31811758  817.177182  190.592905
   15  Gauss+Lor Amp   3274.43275  4.24577784  3274.43275  4.24858834  844.977771  239.084474
       Total           77122.0932  100.000000  77071.0759  100.000000

Parameter Statistics
Peak 1  Gauss+Lor Amp
 Parm  Value       Std Error   t-value     90
  Amp  42.0593060  2.56834759  16.3760179  37.8306439  46.2879682
  Ctr  113.613193  1.22568272  92.6938034  111.595164  115.631221
  Wid  19.8667162  2.80448198  7.08391653  15.2492701  24.4841624
 Shpe  1.00000000  0.03960864  25.2470163  0.93478626  1.06521374

Peak 2  Gauss+Lor Amp
 Parm  Value       Std Error   t-value     90
  Amp  64.2771267  2.56081385  25.1002730  60.0608686  68.4933849
  Ctr  136.691529  0.86380074  158.244284  135.269322  138.113736
  Wid  20.5439490  1.65482303  12.4145897  17.8193616  23.2685364
 Shpe  1.00000000  0.03960864  25.2470163  0.93478626  1.06521374

Peak 3  Gauss+Lor Amp
 Parm  Value       Std Error   t-value     90
  Amp  35.5114084  2.96887467  11.9612353  30.6232975  40.3995193
  Ctr  200.076102  1.34575406  148.672114  197.860382  202.291822
  Wid  31.6955880  2.87449710  11.0264811  26.9628652  36.4283107
 Shpe  1.00000000  0.03960864  25.2470163  0.93478626  1.06521374

Peak 4  Gauss+Lor Amp
 Parm  Value       Std Error   t-value     90
  Amp  98.3242116  1.56412637  62.8620639  95.7489519  100.899471
  Ctr  256.530942  0.91340322  280.851803  255.027067  258.034817
  Wid  61.0367496  4.31047144  14.1601100  53.9397634  68.1337358
 Shpe  1.00000000  0.03960864  25.2470163  0.93478626  1.06521374

Peak 5  Gauss+Lor Amp
 Parm  Value       Std Error   t-value     90
  Amp  75.8451473  5.26792086  14.3975487  67.1717662  84.5185284
  Ctr  301.289863  0.53461142  563.567954  300.409651  302.170076
  Wid  27.3577324  1.53317936  17.8437912  24.8334256  29.8820393
 Shpe  1.00000000  0.03960864  25.2470163  0.93478626  1.06521374

Peak 6  Gauss+Lor Amp
 Parm  Value       Std Error   t-value     90
  Amp  90.2089073  4.28042227  21.0747682  83.1613956  97.2564190
  Ctr  436.556877  3.31281944  131.778047  431.102478  442.011277
  Wid  60.1283263  4.63760890  12.9653724  52.4927239  67.7639288
 Shpe  1.00000000  0.03960864  25.2470163  0.93478626  1.06521374

Peak 7  Gauss+Lor Amp
 Parm  Value       Std Error   t-value     90
  Amp  31.1198916  60.9211182  0.51082273  -69.183832  131.423615
  Ctr  469.062618  13.1349090  35.7111433  447.436615  490.688621
  Wid  29.2152880  16.4432617  1.77673315  2.14223990  56.2883361
 Shpe  1.00000000  0.03960864  25.2470163  0.93478626  1.06521374

Peak 8  Gauss+Lor Amp
 Parm  Value       Std Error   t-value     90
  Amp  74.8154068  35.6054352  2.10123557  16.1927515  133.438062
  Ctr  490.365586  10.0067446  49.0035075  473.889957  506.841215
  Wid  34.9977864  9.20089681  3.80373643  19.8489474  50.1466253
 Shpe  1.00000000  0.03960864  25.2470163  0.93478626  1.06521374

Peak 9  Gauss+Lor Amp
 Parm  Value       Std Error   t-value     90
  Amp  181.915581  41.5709405  4.37602754  113.471005  250.360157
  Ctr  586.283987  5.51094280  106.385424  577.210482  595.357492
  Wid  43.1022066  5.14434731  8.37855688  34.6322834  51.5721297
 Shpe  1.00000000  0.03960864  25.2470163  0.93478626  1.06521374

Peak 10  Gauss+Lor Amp
 Parm  Value       Std Error   t-value     90
  Amp  422.172547  80.2042206  5.26371983  290.120113  554.224981
  Ctr  614.764956  1.04424238  588.718642  613.045661  616.484252
  Wid  36.0483730  3.08488719  11.6854753  30.9692530  41.1274930
 Shpe  1.00000000  0.03960864  25.2470163  0.93478626  1.06521374

Peak 11  Gauss+Lor Amp
 Parm  Value       Std Error   t-value     90
  Amp  323.497813  126.979601  2.54763608  114.431940  532.563685
  Ctr  648.837831  1.92371536  337.283698  645.670525  652.005137
  Wid  44.6400957  6.39075125  6.98510925  34.1180277  55.1621636
 Shpe  1.00000000  0.03960864  25.2470163  0.93478626  1.06521374

Peak 12  Gauss+Lor Amp
 Parm  Value       Std Error   t-value     90
  Amp  143.377336  72.8223026  1.96886573  23.4788785  263.275793
  Ctr  675.750807  18.0291472  37.4810189  646.066674  705.434940
  Wid  66.8321322  13.9189212  4.80153103  43.9152905  89.7489739
 Shpe  1.00000000  0.03960864  25.2470163  0.93478626  1.06521374

Peak 13  Gauss+Lor Amp
 Parm  Value       Std Error   t-value     90
  Amp  19.7174569  12.6402427  1.55989543  -1.0941015  40.5290153
  Ctr  794.210443  1.76993159  448.723809  791.296335  797.124551
  Wid  15.4392093  5.92341191  2.60647233  5.68659331  25.1918252
 Shpe  1.00000000  0.03960864  25.2470163  0.93478626  1.06521374

Peak 14  Gauss+Lor Amp
 Parm  Value       Std Error   t-value     90
  Amp  51.6277959  23.2910561  2.21663610  13.2801799  89.9754118
  Ctr  817.177182  6.27612949  130.204003  806.843834  827.510531
  Wid  32.5095598  14.9875036  2.16911105  7.83334795  57.1857716
 Shpe  1.00000000  0.03960864  25.2470163  0.93478626  1.06521374

Peak 15  Gauss+Lor Amp
 Parm  Value       Std Error   t-value     90
  Amp  84.4832192  22.2255737  3.80117158  47.8898693  121.076569
  Ctr  844.977771  5.86259353  144.130369  835.325290  854.630253
  Wid  36.4110674  5.49492773  6.62630507  27.3639303  45.4582045
 Shpe  1.00000000  0.03960864  25.2470163  0.93478626  1.06521374

Analysis of Variance
r^2 Coef Det  DF Adj r^2    Fit Std Err
0.99693079   0.99678264   7.21633172
Source   Sum of Squares    DF      Mean Square        F
Regr     16136867          45      358597.04          6886.1062
Error    49679.973         954     52.075443
Total    16186547          999

Details of Fit
Set Convergence    State     Iterations   Minimization   Extent
    1E-6          Stopped        500     Least Squares    1/1
Curvature Matrix                Constraints                Violated
    Sparse-Roots  25.0000-5.00000-50.0000- None  - None        0