File: Data/Raman/raw/albite_150 (500nm)_633nm_edge_100%_x50_vis_lwd_h30um_30sx2_01.txt
#Acq. time (s)=	30
#Accumulations=	2
#Range (cm-¹)=	100...4000
#Windows=	1
#Auto scanning=	Off
#Autofocus=	Off
#Macrospot=	Off
#AutoExposure=	Off
#Spike filter=	Multiple accum.
#Delay time (s)=	2
#Binning=	1
#Readout mode=	Signal
#DeNoise=	Standard
#ICS correction=	On
#Dark correction=	Off
#Inst. Process=	Off
#Detector Gain=	Best Dynamic
#Detector ADC=	50 kHz HS
#Detector temperature (°C)=	-60.09
#Instrument=	LabRAM HR Evol
#Detector=	SIN-EM FIVIS
#Objective=	x50_VIS_LWD
#Grating=	150 (500nm)
#ND Filter=	100%
#Laser=	633nm_Edge
#Hole=	30.0125
#Temperature=	0
#Range=	Visible
#StageXY=	75x50mm Scan+
#StageZ=	Z motor
#X (µm)=	0
#Y (µm)=	0
#Z (µm)=	59.3
#Full time(mm:ss)=	1:04
#Project=	20_10_27
#Sample=	BU24
#Site=
#Title=	BU24-Turm1-host_150 (500nm)_633nm_Edge_100%_x50_VIS_LWD_H30um_30sX2
#Remark=
#Date=	27.10.2020 18:26
#Acquired=	27.10.2020 18:26:54
100.764	536.378
107.281	576.385
113.791	972.373
120.297	671.713
126.797	572.778
133.291	545.788
139.78	566.685
146.264	680.119
152.741	986.304
159.214	828.246
165.682	943.077
172.144	797.576
178.601	653.617
185.053	727.1
191.499	732.023
197.939	696.068
204.374	699.731
210.805	760.953
217.23	677.778
223.648	633.737
230.063	626.119
236.472	643.327
242.874	681.144
249.273	802.938
255.667	884.207
262.053	763.378
268.436	956.831
274.813	926.605
281.185	860.556
287.552	1140.02
293.913	1397.57
300.27	905.743
306.62	829.117
312.965	808.675
319.306	797.528
325.64	799.911
331.971	803.892
338.295	803.392
344.614	803.803
350.93	806.111
357.238	809.58
363.542	814.289
369.842	820.801
376.135	830.567
382.423	847.081
388.706	872.093
394.984	908.65
401.258	958.055
407.526	1037.8
413.789	1119.26
420.046	1094.39
426.299	978.946
432.546	967.02
438.788	976.786
445.025	994.059
451.257	1017.95
457.484	1048.59
463.706	1092.38
469.923	1177.95
476.135	1685.3
482.342	2176.64
488.544	1403.7
494.741	1292.78
500.933	1500.63
507.12	2838.51
513.3	2132.12
519.477	1403.1
525.649	1298.23
531.815	1256.76
537.976	1240.82
544.133	1239.11
550.285	1246.88
556.43	1259.81
562.572	1273.93
568.709	1288.36
574.84	1302.95
580.967	1317.04
587.09	1331.47
593.205	1347.44
599.318	1367.25
605.424	1391.13
611.527	1417.67
617.623	1444.67
623.716	1469.4
629.802	1490.68
635.884	1506.06
641.962	1518.23
648.034	1530.97
654.101	1547.43
660.165	1567.36
666.222	1591.85
672.274	1619.61
678.324	1648.11
684.366	1674.21
690.404	1696.25
696.438	1715.45
702.466	1733.5
708.491	1751.38
714.51	1769.54
720.523	1789.28
726.533	1810.27
732.537	1834.12
738.537	1861.46
744.531	1897.95
750.521	1924.51
756.507	1996.68
762.487	2160.27
768.463	2149.17
774.434	2103.15
780.4	2087.8
786.362	2098.92
792.319	2116.84
798.269	2142.55
804.217	2173.87
810.159	2206.59
816.097	2235.63
822.03	2262.61
827.958	2289.47
833.881	2317.62
839.801	2347.8
845.714	2379.6
851.624	2412.39
857.529	2445.31
863.428	2477
869.324	2506.14
875.215	2533.36
881.1	2560.41
886.982	2589.21
892.858	2620.19
898.73	2653.05
904.597	2687.1
910.459	2721.67
916.318	2756.67
922.171	2793.78
928.02	2833.72
933.864	2868.12
939.703	2903.69
945.539	2945.46
951.368	2996.35
957.194	3055.7
963.014	3107.34
968.832	3154.25
974.643	3194.96
980.45	3227.8
986.253	3252.02
992.051	3272.95
997.844	3298.66
1003.63	3328.35
1009.42	3368.77
1015.2	3415.89
1020.97	3464.88
1026.74	3515.04
1032.51	3565.79
1038.27	3614.3
1044.03	3658.09
1049.78	3695.61
1055.53	3725.33
1061.27	3752.15
1067.01	3787.88
1072.75	3818.92
1078.48	3872.71
1084.2	3941.16
1089.92	4019.63
1095.64	4097.16
1101.35	4164.5
1107.06	4214.95
1112.77	4247.97
1118.46	4267.79
1124.16	4290.29
1129.85	4314.95
1135.53	4345.24
1141.22	4383.02
1146.89	4426.33
1152.56	4470.69
1158.23	4512.22
1163.9	4553.5
1169.56	4596.81
1175.21	4641.12
1180.86	4678.42
1186.51	4727.44
1192.15	4787.24
1197.78	4855.6
1203.42	4924.51
1209.04	4990.97
1214.67	5061.41
1220.29	5119.15
1225.9	5163.7
1231.51	5199.74
1237.12	5235.76
1242.72	5272.93
1248.32	5310.07
1253.92	5341.63
1259.5	5372.68
1265.09	5414.46
1270.67	5466.9
1276.25	5523.13
1281.82	5581.45
1287.39	5645.18
1292.95	5707.71
1298.51	5762.6
1304.06	5812.89
1309.61	5858.8
1315.16	5901.31
1320.7	5944.49
1326.24	5991.26
1331.77	6039.14
1337.3	6088.69
1342.83	6145.02
1348.35	6188.9
1353.86	6232.57
1359.37	6279.37
1364.88	6331.72
1370.39	6379.93
1375.89	6431.72
1381.38	6485.62
1386.87	6531.66
1392.36	6580.8
1397.84	6633.81
1403.32	6694.04
1408.79	6772.72
1414.26	6841.94
1419.73	6901.82
1425.19	6951.04
1430.65	6989.66
1436.1	7023.32
1441.55	7054.06
1447	7080.03
1452.44	7105.75
1457.87	7142.67
1463.31	7194.36
1468.73	7251.69
1474.16	7308.25
1479.58	7365.42
1484.99	7423.04
1490.41	7480.15
1495.81	7538.15
1501.22	7597.66
1506.62	7656.95
1512.01	7714.37
1517.4	7767.64
1522.79	7815.8
1528.17	7866.45
1533.55	7922.74
1538.93	7974.27
1544.3	8011.5
1549.67	8043.5
1555.03	8077.09
1560.39	8110.84
1565.74	8151.16
1571.09	8199.93
1576.44	8253.11
1581.78	8312.87
1587.12	8372.51
1592.45	8425.44
1597.78	8475.39
1603.11	8521.85
1608.43	8577.66
1613.75	8631.99
1619.07	8686.2
1624.38	8739.66
1629.68	8790.88
1634.98	8838.28
1640.28	8881.14
1645.58	8921.08
1650.87	8957.71
1656.15	8992.54
1661.44	9026.33
1666.71	9058.7
1671.99	9090.21
1677.26	9121.21
1682.53	9150.75
1687.79	9183.05
1693.05	9229.4
1698.3	9278.18
1703.55	9323.96
1708.8	9367.73
1714.04	9404.66
1719.28	9445.76
1724.51	9492.3
1729.75	9536.47
1734.97	9575.92
1740.2	9612.13
1745.42	9642.63
1750.63	9667.19
1755.84	9680.52
1761.05	9689.22
1766.25	9702.08
1771.45	9717.84
1776.65	9735.67
1781.84	9761
1787.03	9801.78
1792.21	9858.48
1797.39	9918.13
1802.57	9971.14
1807.74	10014.6
1812.91	10049.3
1818.08	10073
1823.24	10088
1828.39	10101.5
1833.55	10110
1838.7	10119.8
1843.84	10138.6
1848.99	10160.3
1854.12	10183
1859.26	10211.1
1864.39	10244.1
1869.52	10277
1874.64	10308.2
1879.76	10335.5
1884.87	10363.7
1889.98	10390.7
1895.09	10413.1
1900.2	10428.5
1905.3	10438.6
1910.39	10455.3
1915.49	10475.1
1920.57	10495.3
1925.66	10515.4
1930.74	10535.7
1935.82	10556
1940.89	10575.8
1945.96	10589.2
1951.03	10599
1956.09	10602.9
1961.15	10595
1966.21	10581
1971.26	10576.4
1976.31	10580.2
1981.35	10593.2
1986.39	10616.8
1991.43	10647.5
1996.46	10677
2001.49	10685.6
2006.52	10707
2011.54	10731
2016.56	10755.2
2021.57	10770.6
2026.58	10779.5
2031.59	10780.5
2036.59	10781
2041.59	10784.1
2046.59	10788.9
2051.58	10796.2
2056.57	10805.6
2061.55	10818.4
2066.54	10818.3
2071.51	10815.6
2076.49	10811
2081.46	10795.1
2086.43	10777.4
2091.39	10767.6
2096.35	10767.4
2101.3	10771.9
2106.26	10775.2
2111.21	10775
2116.15	10771.3
2121.09	10768.6
2126.03	10763.4
2130.97	10753.7
2135.9	10735.3
2140.83	10716.7
2145.75	10702.2
2150.67	10690.4
2155.59	10681.2
2160.5	10673.6
2165.41	10668.1
2170.31	10661.7
2175.22	10652.7
2180.12	10644.7
2185.01	10639.6
2189.9	10637.9
2194.79	10639.7
2199.68	10641.3
2204.56	10645.3
2209.43	10647.3
2214.31	10642.2
2219.18	10631.1
2224.05	10614.9
2228.91	10596.4
2233.77	10578.5
2238.63	10562.2
2243.48	10545
2248.33	10526.6
2253.17	10504.2
2258.02	10479.1
2262.86	10449.5
2267.69	10419.8
2272.52	10395.5
2277.35	10375
2282.18	10358.1
2287	10345
2291.82	10335.9
2296.63	10327.6
2301.44	10313.1
2306.25	10309
2311.05	10301.3
2315.86	10293.4
2320.65	10283.8
2325.45	10260.1
2330.24	10247.6
2335.03	10235.3
2339.81	10222.8
2344.59	10212.9
2349.37	10199.3
2354.14	10171.8
2358.91	10137.7
2363.67	10106.2
2368.44	10071.9
2373.2	10036.1
2377.95	9998.78
2382.71	9960.35
2387.46	9921.7
2392.2	9885.32
2396.95	9830.3
2401.68	9811.41
2406.42	9800.96
2411.15	9786.91
2415.88	9774.75
2420.61	9765.67
2425.33	9756.98
2430.05	9748.23
2434.77	9741.21
2439.48	9735.25
2444.19	9716.2
2448.89	9681
2453.6	9646.97
2458.29	9608.81
2462.99	9565.89
2467.68	9524.53
2472.37	9492.06
2477.06	9468.23
2481.74	9450.31
2486.42	9432.15
2491.1	9408.96
2495.77	9386.68
2500.44	9360.59
2505.1	9324.8
2509.76	9281.9
2514.42	9248.78
2519.08	9213.33
2523.73	9173.37
2528.38	9132.32
2533.03	9092.99
2537.67	9054.17
2542.31	9018.06
2546.95	8985.12
2551.58	8958.97
2556.21	8942.17
2560.84	8928.82
2565.46	8909.58
2570.08	8876.96
2574.7	8832.48
2579.31	8776.1
2583.92	8714.33
2588.53	8661.59
2593.13	8612.74
2597.73	8574.27
2602.33	8539.92
2606.92	8509.08
2611.51	8481.52
2616.1	8457.46
2620.68	8434.65
2625.26	8399.43
2629.84	8413
2634.42	8428.32
2638.99	8381.36
2643.56	8308.75
2648.12	8241.59
2652.68	8221.65
2657.24	8191.23
2661.8	8153.19
2666.35	8123.86
2670.9	8096.22
2675.45	8067.41
2679.99	8036.56
2684.53	8000.69
2689.06	7957.16
2693.6	7908.77
2698.13	7859.63
2702.66	7817.48
2707.18	7783.45
2711.7	7756.7
2716.22	7732.85
2720.73	7712.55
2725.24	7692.3
2729.75	7659.41
2734.26	7618.08
2738.76	7569.8
2743.25	7522.69
2747.75	7482.05
2752.24	7448.6
2756.73	7423.15
2761.22	7401.52
2765.7	7379.04
2770.18	7356.1
2774.66	7331.15
2779.13	7304.31
2783.6	7274.59
2788.07	7241.19
2792.53	7205.33
2797	7166.99
2801.45	7125.41
2805.91	7080.82
2810.36	7033.28
2814.81	6987.69
2819.26	6954.1
2823.7	6922.5
2828.14	6891.65
2832.57	6864.9
2837.01	6840.71
2841.44	6812.68
2845.87	6778.58
2850.29	6740.77
2854.71	6696.6
2859.13	6656.44
2863.55	6625.87
2867.96	6601.08
2872.37	6582.89
2876.77	6568.07
2881.18	6552.16
2885.58	6515.7
2889.97	6467.3
2894.37	6411.95
2898.76	6354.19
2903.15	6312.02
2907.53	6278.5
2911.91	6249.21
2916.29	6221.46
2920.67	6195.13
2925.04	6172.64
2929.41	6155.94
2933.78	6141.88
2938.14	6125.99
2942.5	6108.14
2946.86	6082.79
2951.22	6046.14
2955.57	6007.97
2959.92	5967.81
2964.26	5930.83
2968.61	5899.9
2972.95	5871.39
2977.28	5843.25
2981.62	5812.73
2985.95	5783.2
2990.28	5750.85
2994.6	5723.85
2998.93	5702.2
3003.25	5676.72
3007.56	5645.95
3011.88	5609.72
3016.19	5571.43
3020.49	5530.87
3024.8	5490.38
3029.1	5452.49
3033.4	5418.86
3037.7	5391.14
3041.99	5366.96
3046.28	5341.25
3050.57	5312.91
3054.85	5292.98
3059.13	5313.55
3063.41	5260.67
3067.69	5208.1
3071.96	5164.99
3076.23	5135.06
3080.5	5118.09
3084.76	5108.5
3089.02	5091.22
3093.28	5074.69
3097.53	5059.3
3101.79	5043.65
3106.04	5025.22
3110.28	4992.88
3114.53	4955.45
3118.77	4915.71
3123.01	4878.3
3127.24	4845.48
3131.47	4817.3
3135.7	4792.67
3139.93	4771.3
3144.15	4752.02
3148.38	4736.56
3152.59	4715.91
3156.81	4683.66
3161.02	4648.82
3165.23	4612.31
3169.44	4575.46
3173.64	4537.31
3177.84	4499.77
3182.04	4468.28
3186.24	4447.93
3190.43	4425.11
3194.62	4405.44
3198.81	4384.17
3202.99	4357.52
3207.17	4329.37
3211.35	4304.6
3215.53	4282.09
3219.7	4262.74
3223.87	4245.36
3228.04	4227.55
3232.2	4208.36
3236.36	4188.54
3240.52	4168.86
3244.68	4149.9
3248.83	4128.58
3252.98	4097.39
3257.13	4062.97
3261.28	4033.18
3265.42	4007.31
3269.56	3977.94
3273.7	3952.63
3277.83	3937.76
3281.96	3919.84
3286.09	3896.5
3290.22	3867.81
3294.34	3834.26
3298.46	3798.26
3302.58	3765.97
3306.69	3734.51
3310.8	3696.42
3314.91	3668.31
3319.02	3642.43
3323.12	3622.58
3327.23	3614.28
3331.32	3614.26
3335.42	3602.43
3339.51	3578.31
3343.6	3550.31
3347.69	3525.11
3351.78	3503.6
3355.86	3486.35
3359.94	3471.99
3364.02	3459.83
3368.09	3454.28
3372.16	3447.78
3376.23	3433.22
3380.29	3412.43
3384.36	3386.45
3388.42	3358.88
3392.48	3333.56
3396.53	3309.07
3400.58	3285.95
3404.63	3265.21
3408.68	3248.56
3412.73	3236.43
3416.77	3232.84
3420.81	3225.32
3424.84	3214.27
3428.88	3200.36
3432.91	3182.87
3436.94	3162.76
3440.96	3138.67
3444.99	3113.01
3449.01	3088.09
3453.03	3066
3457.04	3046.45
3461.05	3030.45
3465.06	3017.1
3469.07	3006.16
3473.08	2998.85
3477.08	2996.5
3481.08	2988.74
3485.07	2969.78
3489.07	2944.01
3493.06	2912.08
3497.05	2880.53
3501.04	2852.68
3505.02	2830.37
3509	2814.17
3512.98	2801.07
3516.96	2788.06
3520.93	2774.33
3524.9	2760.37
3528.87	2748.67
3532.83	2739.74
3536.8	2731.25
3540.76	2722.27
3544.71	2710.69
3548.67	2695.03
3552.62	2660.22
3556.57	2621.25
3560.52	2594.53
3564.47	2566.11
3568.41	2539.23
3572.35	2519.84
3576.29	2509.08
3580.22	2506.62
3584.15	2506.18
3588.08	2498.54
3592.01	2478.7
3595.93	2465.83
3599.85	2452.9
3603.77	2439.14
3607.69	2425.9
3611.61	2413.25
3615.52	2400.78
3619.43	2389.06
3623.33	2376.74
3627.24	2362.45
3631.14	2345.24
3635.04	2330.02
3638.93	2317.06
3642.83	2302.58
3646.72	2286.2
3650.61	2266.64
3654.49	2246.5
3658.38	2226.3
3662.26	2207.63
3666.14	2192.28
3670.01	2180.74
3673.89	2173.88
3677.76	2167.61
3681.63	2159.94
3685.5	2146.06
3689.36	2132.83
3693.22	2122.11
3697.08	2111.6
3700.94	2100.08
3704.79	2087.07
3708.64	2072.98
3712.49	2056.83
3716.34	2039.85
3720.18	2023.1
3724.02	2007.02
3727.86	1994.41
3731.7	1983.25
3735.53	1971.36
3739.36	1958.27
3743.19	1945.57
3747.02	1935.39
3750.84	1929.15
3754.66	1926.28
3758.48	1925.04
3762.3	1923.94
3766.12	1916.64
3769.93	1898.52
3773.74	1876.58
3777.54	1857.51
3781.35	1841.44
3785.15	1823.89
3788.95	1806.93
3792.75	1800.24
3796.54	1795.77
3800.34	1788.56
3804.13	1779.26
3807.91	1768.44
3811.7	1757.96
3815.48	1754
3819.26	1746.64
3823.04	1734.89
3826.82	1722.55
3830.59	1711.85
3834.36	1704.92
3838.13	1693.52
3841.89	1680.1
3845.66	1671.5
3849.42	1668.09
3853.18	1664.27
3856.93	1655.43
3860.69	1645.22
3864.44	1632.19
3868.19	1617.56
3871.93	1602.58
3875.68	1588.44
3879.42	1577.88
3883.16	1575.22
3886.9	1569.53
3890.63	1560.8
3894.37	1554.28
3898.1	1537.67
3901.82	1519.52
3905.55	1505.75
3909.27	1498.38
3912.99	1498.12
3916.71	1497.5
3920.43	1493.81
3924.14	1485.81
3927.85	1475.59
3931.56	1460.62
3935.27	1445.77
3938.97	1435.12
3942.67	1429.77
3946.37	1424.98
3950.07	1413.52
3953.77	1396.13
3957.46	1381.31
3961.15	1375.38
3964.84	1367.19
3968.52	1358.56
3972.2	1349.7
3975.89	1341.24
3979.56	1333.84
3983.24	1328.48
3986.92	1325.63
3990.59	1325.19
3994.26	1329.4
3997.92	1328.43
3999.76	1320.45