File: Data/Raman/raw/apatite-F_150 (500nm)_633nm_Edge_50%_x50_VIS_LWD_H100um_15sX2.txt
#Acq. time (s)=	15
#Accumulations=	2
#Range (cm-¹)=	100...4000
#Windows=	1
#Auto scanning=	Off
#Autofocus=	Off
#Macrospot=	Off
#AutoExposure=	Off
#Spike filter=	Multiple accum.
#Delay time (s)=	0
#Binning=	1
#Readout mode=	Signal
#DeNoise=	Standard
#ICS correction=	On
#Dark correction=	Off
#Inst. Process=	On
#Detector Gain=	Best Dynamic
#Detector ADC=	50 kHz HS
#Detector temperature (°C)=	-60.09
#Instrument=	LabRAM HR Evol
#Detector=	SIN-EM FIVIS
#Objective=	x50_VIS_LWD
#Grating=	150 (500nm)
#ND Filter=	50%
#Laser=	633nm_Edge
#Hole=	100.021
#Temperature=	0
#Range=	Visible
#StageXY=	75x50mm Scan+
#StageZ=	Z motor
#X (µm)=	0
#Y (µm)=	0
#Z (µm)=	83.3
#Project=	20_05_11
#Sample=	BU20b
#Site=
#Title=	BU20b-area1-apatite_clear-top_150 (500nm)_633nm_Edge_50%_x50_VIS_LWD_H100um_15sX2
#Remark=
#Date=	11.05.2020 18:09
#Acquired=	11.05.2020 18:09:27
100.862	1109.16
107.378	1136.63
113.889	1135.88
120.394	1131.73
126.894	1143.47
133.388	1157.86
139.878	1162.92
146.361	1159.32
152.84	1154.89
159.313	1162.41
165.78	1171.08
172.242	1178.07
178.699	1192.12
185.149	1185.99
191.596	1178.87
198.037	1170.81
204.472	1264.06
210.903	1378.42
217.326	1377.95
223.746	1316.58
230.16	1273.92
236.568	1230.64
242.972	1188.23
249.371	1142.22
255.762	1116.73
262.151	1102.63
268.533	1098
274.91	1116.87
281.282	1144.5
287.648	1169.59
294.01	1189.44
300.365	1209.31
306.716	1199.9
313.061	1173.06
319.401	1133.59
325.737	1090.79
332.066	1054.52
338.392	1033.02
344.711	1020.06
351.024	1008.04
357.335	1000.17
363.638	995.898
369.936	993.808
376.23	992.867
382.519	992.703
388.802	991.92
395.08	1005.2
401.353	1003.27
407.62	1018.33
413.884	1033.63
420.141	1126.8
426.394	1449.76
432.641	1991.99
438.883	1756.22
445.12	1433.34
451.352	1357.36
457.579	1287.54
463.801	1202.2
470.018	1120.88
476.23	1059.94
482.437	1015.67
488.638	986.571
494.834	971.891
501.026	960.401
507.212	953.889
513.394	951.422
519.571	948.803
525.743	943.751
531.908	941.732
538.07	939.672
544.227	938.077
550.377	937.614
556.524	945.621
562.666	943.73
568.801	962.409
574.933	978.208
581.061	1104.72
587.181	1430.47
593.299	2379.71
599.41	1648.62
605.517	1203.58
611.618	1409.6
617.716	1091.71
623.807	984.126
629.895	939.476
635.977	914.579
642.053	896.005
648.127	885.752
654.193	880.488
660.256	878.173
666.314	878.042
672.367	879.204
678.414	881.414
684.457	883.885
690.496	886.095
696.529	887.012
702.558	885.648
708.581	881.545
714.6	875.512
720.614	868.427
726.624	861.457
732.628	856.019
738.628	853.223
744.623	853.243
750.613	854.519
756.598	856.776
762.578	859.613
768.554	862.005
774.525	862.814
780.49	861.334
786.451	858.134
792.408	854.284
798.36	850.294
804.307	846.888
810.25	844.844
816.186	844.775
822.119	847.145
828.048	851.822
833.972	856.482
839.889	859.075
845.804	861.087
851.714	862.877
857.617	864.81
863.518	866.685
869.413	867.252
875.303	863.303
881.19	860.471
887.07	859.308
892.947	857.427
898.818	857.996
904.686	863.963
910.548	866.942
916.406	877.632
922.26	889.114
928.108	904.112
933.953	920.304
939.792	944.152
945.626	1046.99
951.457	1396.38
957.282	2696.1
963.103	6411.11
968.919	9201.99
974.731	3867.28
980.539	1540.57
986.341	1018.74
992.139	937.232
997.932	905.268
1003.72	905.096
1009.51	916.763
1015.29	944.648
1021.06	988.52
1026.83	1036.04
1032.6	1093.73
1038.36	1208.27
1044.12	1578.18
1049.87	2214.17
1055.62	2448.26
1061.36	1449.22
1067.1	1086.3
1072.84	1068.15
1078.56	1258.16
1084.29	1516.3
1090.01	1279.11
1095.73	1043.82
1101.44	959.686
1107.15	930.334
1112.85	918.734
1118.55	909.301
1124.24	904.669
1129.94	901.404
1135.62	897.546
1141.3	894.321
1146.98	891.889
1152.65	890.907
1158.32	891.842
1163.98	893.865
1169.64	896.053
1175.3	897.07
1180.95	897.39
1186.59	896.992
1192.23	895.884
1197.87	895.026
1203.5	896.943
1209.13	900.444
1214.75	904.217
1220.37	906.35
1225.99	906.578
1231.6	905.286
1237.21	903.567
1242.81	901.684
1248.41	898.752
1254	895.173
1259.59	891.714
1265.17	889.146
1270.75	887.203
1276.33	885.416
1281.9	881.276
1287.47	877.4
1293.03	876.708
1298.59	878.349
1304.15	882.992
1309.7	887.822
1315.24	889.342
1320.78	889.527
1326.32	887.636
1331.85	884.568
1337.38	881.251
1342.91	878.761
1348.43	877.488
1353.95	878.79
1359.46	881.32
1364.97	883.373
1370.47	884.675
1375.97	885.818
1381.46	885.952
1386.96	885.578
1392.44	884.997
1397.92	884.455
1403.4	883.829
1408.88	883.281
1414.35	882.291
1419.81	877.294
1425.27	876.734
1430.73	877.368
1436.18	877.56
1441.63	878.012
1447.08	878.26
1452.52	877.273
1457.96	873.597
1463.39	869.757
1468.82	867.783
1474.24	867.457
1479.66	868.246
1485.08	869.496
1490.49	872.341
1495.9	876.376
1501.3	879.878
1506.7	881.595
1512.09	882.804
1517.49	883.955
1522.87	884.817
1528.26	884.609
1533.63	883.386
1539.01	881.81
1544.38	879.306
1549.75	875.127
1555.11	867.996
1560.47	865.131
1565.82	865.361
1571.17	868.342
1576.52	872.804
1581.86	877.512
1587.2	883.598
1592.54	888.282
1597.86	887.51
1603.19	884.892
1608.51	882.714
1613.83	881.624
1619.15	880.604
1624.46	878.778
1629.76	876.834
1635.06	877.331
1640.36	880.019
1645.66	880.517
1650.95	879.36
1656.23	877.432
1661.52	874.908
1666.79	871.936
1672.07	868.9
1677.34	867.658
1682.6	870.714
1687.87	874.87
1693.13	878.288
1698.38	880.166
1703.63	879.996
1708.88	877.76
1714.12	874.264
1719.36	870.216
1724.59	866.96
1729.82	865.184
1735.05	864.373
1740.27	863.446
1745.49	863.675
1750.71	865.462
1755.92	868.355
1761.13	870.628
1766.33	870.553
1771.53	868.765
1776.73	865.805
1781.92	862.639
1787.11	860.464
1792.29	859.618
1797.47	859.191
1802.65	858.314
1807.82	857.014
1812.99	856.668
1818.15	857.981
1823.32	859.63
1828.47	861.339
1833.63	860.79
1838.78	854.939
1843.92	854.318
1849.06	853.382
1854.2	852.504
1859.34	852.058
1864.47	851.393
1869.59	850.55
1874.72	849.505
1879.84	846.411
1884.95	842.103
1890.06	839.422
1895.17	839.613
1900.27	842.052
1905.37	842.919
1910.47	844.222
1915.56	846.118
1920.65	848.147
1925.74	849.535
1930.82	850.016
1935.9	849.569
1940.97	847.498
1946.04	844.466
1951.11	841.157
1956.17	839.974
1961.23	839.525
1966.28	839.341
1971.33	839.163
1976.38	838.681
1981.43	838.025
1986.47	837.204
1991.5	835.975
1996.54	833.833
2001.57	830.325
2006.59	828.834
2011.61	830.547
2016.63	833.072
2021.65	835.526
2026.66	837.308
2031.66	839.114
2036.67	843.391
2041.67	846.164
2046.66	845.689
2051.66	844.129
2056.65	841.897
2061.63	839.383
2066.61	836.754
2071.59	834.532
2076.56	833.151
2081.53	831.861
2086.5	830.582
2091.46	829.991
2096.42	830.661
2101.38	831.051
2106.33	829.912
2111.28	827.938
2116.23	825.552
2121.17	822.65
2126.11	820.292
2131.04	819.573
2135.97	820.912
2140.9	823.068
2145.82	826.448
2150.74	829.615
2155.66	831.631
2160.57	830.904
2165.48	827.565
2170.39	822.963
2175.29	819.166
2180.19	817.021
2185.09	816.299
2189.98	816.991
2194.86	819.414
2199.75	821.699
2204.63	819.04
2209.51	816.231
2214.38	814.236
2219.25	812.835
2224.12	812.366
2228.98	812.833
2233.84	814.39
2238.7	816.702
2243.55	817.8
2248.4	816.297
2253.25	811.102
2258.09	805.471
2262.93	802.15
2267.76	801.544
2272.6	803.321
2277.43	805.973
2282.25	806.664
2287.07	804.532
2291.89	801.273
2296.7	796.068
2301.52	789.505
2306.32	787.182
2311.13	788.072
2315.93	792.281
2320.73	796.795
2325.52	800.351
2330.31	802.315
2335.1	803.114
2339.88	802.894
2344.66	801.376
2349.44	797.906
2354.21	793.686
2358.98	790.761
2363.75	790.434
2368.51	790.506
2373.27	789.811
2378.03	787.898
2382.78	785.989
2387.53	785.544
2392.28	786.464
2397.02	787.455
2401.76	788.386
2406.49	789.01
2411.23	788.799
2415.95	787.149
2420.68	784.737
2425.4	781.986
2430.12	779.6
2434.84	778.416
2439.55	777.829
2444.26	777.83
2448.96	777.226
2453.67	775.803
2458.37	776.735
2463.06	778.404
2467.75	779.434
2472.44	779.557
2477.13	778.877
2481.81	777.699
2486.49	776.522
2491.17	774.862
2495.84	770.572
2500.51	766.811
2505.17	766.532
2509.84	766.406
2514.5	766.428
2519.15	766.962
2523.8	767.734
2528.45	769.391
2533.1	771.472
2537.74	772.687
2542.38	772.619
2547.02	770.87
2551.65	768.408
2556.28	766.533
2560.91	765.339
2565.53	763.82
2570.15	761.343
2574.77	758.505
2579.38	755.858
2583.99	755.232
2588.6	756.055
2593.2	756.834
2597.8	757.035
2602.4	757.96
2606.99	759.496
2611.58	761.001
2616.17	761.64
2620.75	761.127
2625.33	759.781
2629.91	758.231
2634.49	757.04
2639.06	756.655
2643.63	756.791
2648.19	756.537
2652.75	755.429
2657.31	753.425
2661.87	750.893
2666.42	747.877
2670.97	745.145
2675.51	743.702
2680.06	745.788
2684.6	746.059
2689.13	744.09
2693.67	741.527
2698.2	738.917
2702.72	737.069
2707.25	735.476
2711.77	735.197
2716.28	741.759
2720.8	736.982
2725.31	731.867
2729.82	726.8
2734.32	722.592
2738.83	722.426
2743.32	726.299
2747.82	728.889
2752.31	732.179
2756.8	733.542
2761.29	732.858
2765.77	731.203
2770.25	728.387
2774.73	724.933
2779.2	721.391
2783.67	718.716
2788.14	718.394
2792.6	718.628
2797.06	720.232
2801.52	720.203
2805.98	720.559
2810.43	720.464
2814.88	719.113
2819.32	714.433
2823.77	707.856
2828.2	703.026
2832.64	700.831
2837.08	702.047
2841.51	705.946
2845.93	712.766
2850.36	719.192
2854.78	721.914
2859.2	720.271
2863.61	715.234
2868.02	708.888
2872.43	705.977
2876.84	705.38
2881.24	706.679
2885.64	709.47
2890.04	712.043
2894.43	713.619
2898.82	712.098
2903.21	709.619
2907.6	707.416
2911.98	707.245
2916.36	706.288
2920.74	705.269
2925.11	705.961
2929.48	709.314
2933.84	713.596
2938.21	714.554
2942.57	710.784
2946.93	704.101
2951.28	697.498
2955.64	693.378
2959.98	692.183
2964.33	693.826
2968.67	697.75
2973.01	704.484
2977.35	710.411
2981.68	711.552
2986.02	709.205
2990.34	704.861
2994.67	700.72
2998.99	698.675
3003.31	698.674
3007.63	699.361
3011.94	697.206
3016.25	693.027
3020.56	697.139
3024.86	691.799
3029.17	689.763
3033.47	688.392
3037.76	686.252
3042.05	686.049
3046.34	686.319
3050.63	685.494
3054.92	683.019
3059.2	679.778
3063.48	676.815
3067.75	675.782
3072.02	677.555
3076.29	679.667
3080.56	681.3
3084.82	683.645
3089.09	685.95
3093.34	686.899
3097.6	688.159
3101.85	690.679
3106.1	687.881
3110.35	685.237
3114.59	686.968
3118.83	691.069
3123.07	692.309
3127.31	687.511
3131.54	681.995
3135.77	677.106
3140	673.619
3144.22	669.986
3148.44	665.297
3152.66	664.021
3156.87	663.423
3161.09	662.979
3165.29	664.37
3169.5	666.786
3173.71	669.255
3177.91	670.964
3182.11	671.729
3186.3	671.694
3190.49	671.393
3194.68	671.262
3198.87	672.146
3203.05	672.801
3207.24	673.559
3211.41	674.875
3215.59	675.434
3219.76	672.897
3223.93	672.659
3228.1	670.735
3232.27	664.341
3236.43	660.063
3240.59	656.815
3244.74	655.836
3248.9	658.121
3253.05	662.562
3257.2	667.508
3261.34	667.553
3265.48	665.073
3269.62	662.353
3273.76	660.534
3277.89	658.503
3282.02	656.864
3286.15	656.26
3290.28	651.052
3294.4	648.537
3298.52	647.528
3302.64	647.425
3306.75	649.373
3310.87	651.243
3314.98	651.984
3319.08	650.275
3323.19	647.021
3327.29	644.243
3331.39	644.14
3335.48	644.049
3339.58	644.044
3343.67	643.97
3347.75	643.992
3351.84	643.685
3355.92	643.174
3360	642.784
3364.08	642.707
3368.15	643.22
3372.22	636.008
3376.29	632.037
3380.36	632.709
3384.42	638.744
3388.48	636.42
3392.54	632.923
3396.59	630.701
3400.65	629.785
3404.7	632.371
3408.74	634.395
3412.79	634.594
3416.83	634.3
3420.87	633.854
3424.91	632.991
3428.94	632.397
3432.97	627.334
3437	621.947
3441.02	617.84
3445.05	617.768
3449.07	618.879
3453.09	621.174
3457.1	625.07
3461.11	628.638
3465.13	631.442
3469.13	633.086
3473.14	622.761
3477.14	623.487
3481.14	632.308
3485.14	629.445
3489.13	627.944
3493.12	628.394
3497.11	628.104
3501.1	628.486
3505.08	629.561
3509.06	631.689
3513.04	635.323
3517.02	640.157
3520.99	642.888
3524.96	647.706
3528.93	655.859
3532.89	663.382
3536.86	669.293
3540.82	664.487
3544.78	655.142
3548.73	644.821
3552.68	636.373
3556.63	630.372
3560.58	627.004
3564.53	624.612
3568.47	621.478
3572.41	618.187
3576.34	615.037
3580.28	612.28
3584.21	609.723
3588.14	605.337
3592.07	600.46
3595.99	597.68
3599.91	596.203
3603.83	594.879
3607.75	593.761
3611.66	593.002
3615.58	590.173
3619.49	586.732
3623.39	584.005
3627.3	582.627
3631.2	583.173
3635.1	583.806
3638.99	583.639
3642.89	583.262
3646.78	579.693
3650.67	576.74
3654.55	576.604
3658.44	578.432
3662.32	580.481
3666.2	578.119
3670.07	575.328
3673.95	572.427
3677.82	569.244
3681.69	566.263
3685.55	563.958
3689.42	563.413
3693.28	564.001
3697.14	565.254
3700.99	567.179
3704.85	569.017
3708.7	570.612
3712.55	571.528
3716.39	571.728
3720.24	571.461
3724.08	569.762
3727.92	567.81
3731.76	565.701
3735.59	562.68
3739.42	564.854
3743.25	566.965
3747.08	565.613
3750.9	563.383
3754.72	560.376
3758.54	556.525
3762.36	551.531
3766.17	547.616
3769.99	548.101
3773.79	549.766
3777.6	550.265
3781.41	549.961
3785.21	550.286
3789.01	550.707
3792.81	550.47
3796.6	549.157
3800.39	545.905
3804.18	542.004
3807.97	538.391
3811.76	537.633
3815.54	537.26
3819.32	536.531
3823.1	536.014
3826.87	536.915
3830.65	538.423
3834.42	537.235
3838.18	535.58
3841.95	531.992
3845.71	529.501
3849.48	528.159
3853.23	527.388
3856.99	526.95
3860.74	526.134
3864.5	524.719
3868.24	522.061
3871.99	519.856
3875.74	519.289
3879.48	522.33
3883.22	517.684
3886.95	517.121
3890.69	516.532
3894.42	518.066
3898.15	493.449
3901.88	522.739
3905.61	523.319
3909.33	520.354
3913.05	517.458
3916.77	515.75
3920.48	516.552
3924.2	509.61
3927.91	504.545
3931.62	504.412
3935.32	504.098
3939.03	506.328
3942.73	506.828
3946.43	505.052
3950.13	501.508
3953.82	502.012
3957.51	508.428
3961.2	504.855
3964.89	496.45
3968.58	489.644
3972.26	486.159
3975.94	486.055
3979.62	483.921
3983.3	485.414
3986.97	488.516
3990.64	490.534
3994.31	488.397
3997.98	483.565
3999.81	484.207