File: Data/Raman/raw/apatite-OH_150 (500nm)_633nm_edge_100%_x50_vis_lwd_h30um_30sx2_01.txt
#Acq. time (s)=	30
#Accumulations=	2
#Range (cm-¹)=	100...4000
#Windows=	1
#Auto scanning=	Off
#Autofocus=	Off
#Macrospot=	Off
#AutoExposure=	Off
#Spike filter=	Multiple accum.
#Delay time (s)=	2
#Binning=	1
#Readout mode=	Signal
#DeNoise=	Standard
#ICS correction=	On
#Dark correction=	Off
#Inst. Process=	Off
#Detector Gain=	Best Dynamic
#Detector ADC=	50 kHz HS
#Detector temperature (°C)=	-60.09
#Instrument=	LabRAM HR Evol
#Detector=	SIN-EM FIVIS
#Objective=	x50_VIS_LWD
#Grating=	150 (500nm)
#ND Filter=	100%
#Laser=	633nm_Edge
#Hole=	30.0125
#Temperature=	0
#Range=	Visible
#StageXY=	75x50mm Scan+
#StageZ=	Z motor
#X (µm)=	0
#Y (µm)=	0
#Z (µm)=	-46.1
#Full time(mm:ss)=	1:04
#Project=	21_02_17
#Sample=	BU19_TS(1)
#Site=
#Title=	BU19TS(1)-Area1_fibrousINclorful_150 (500nm)_633nm_Edge_100%_x50_VIS_LWD_H30um_30sX2
#Remark=
#Date=	17.02.2021 19:27
#Acquired=	17.02.2021 19:27:21
100.892	630.001
107.408	635.146
113.919	631.14
120.424	637.223
126.924	660.542
133.418	721.165
139.907	785.29
146.391	765.976
152.868	746.295
159.341	739.802
165.808	729.287
172.271	744.877
178.728	782.735
185.179	813.583
191.625	815.075
198.065	831.553
204.501	875.113
210.931	894.005
217.356	858.486
223.774	862.932
230.188	869.804
236.598	869.855
243	856.845
249.399	840.874
255.792	833.504
262.179	836.928
268.561	857.445
274.938	882.328
281.31	912.939
287.677	937.673
294.038	952.656
300.394	948.601
306.744	944.009
313.089	936.381
319.43	930.632
325.765	927.293
332.095	933.021
338.419	935.046
344.738	936.706
351.054	938.491
357.362	943.833
363.666	951.446
369.965	961.008
376.259	973.132
382.547	990.018
388.83	999.879
395.107	1024.41
401.381	1034.23
407.649	1033.7
413.911	1061.38
420.169	1150.35
426.421	1409.9
432.668	1704.58
438.911	1432.04
445.148	1351.42
451.38	1326.68
457.607	1221.94
463.828	1164.4
470.045	1131.77
476.257	1123.98
482.464	1115.42
488.666	1109.85
494.862	1110.86
501.054	1115.88
507.241	1122.72
513.421	1130.56
519.598	1138.89
525.77	1147.3
531.936	1155.56
538.097	1161.2
544.253	1169.18
550.405	1171.18
556.551	1167.77
562.693	1174.49
568.83	1183.06
574.96	1255.99
581.087	1381.79
587.21	1552.37
593.325	1801.35
599.438	1370.92
605.544	1341.16
611.646	1378.65
617.743	1282.46
623.835	1245.78
629.922	1233.55
636.003	1231.33
642.081	1235.18
648.153	1239.21
654.22	1240.67
660.284	1243.02
666.341	1245.76
672.393	1248.89
678.442	1252.36
684.485	1256
690.523	1259.86
696.556	1263.73
702.584	1268.46
708.609	1272.94
714.628	1275.51
720.641	1275.68
726.651	1275.24
732.655	1274.74
738.654	1275.27
744.649	1277.49
750.639	1282.12
756.624	1287.78
762.604	1293.55
768.58	1298.48
774.551	1304.84
780.517	1310.56
786.479	1313.37
792.435	1315.02
798.386	1316.29
804.333	1317.9
810.276	1319.02
816.214	1319.84
822.147	1321.6
828.074	1325.46
833.998	1330.75
839.917	1335.88
845.83	1339.9
851.74	1341.56
857.645	1342.2
863.544	1342.87
869.439	1344.27
875.329	1345.58
881.215	1346.47
887.097	1347.25
892.973	1348.32
898.846	1350.17
904.712	1353.89
910.574	1359.3
916.433	1366.5
922.285	1378.03
928.135	1394.83
933.978	1397.19
939.817	1426.19
945.653	1502.05
951.483	1719.01
957.308	2357.94
963.129	7220.52
968.946	3304.98
974.757	1596.57
980.564	1457.35
986.367	1401.13
992.165	1364.74
997.958	1346.62
1003.75	1347.1
1009.53	1360.67
1015.31	1379.57
1021.09	1406.71
1026.86	1452.35
1032.62	1489.92
1038.39	1581.59
1044.14	1813.99
1049.89	2044.21
1055.64	1633.99
1061.39	1462.95
1067.13	1407.9
1072.86	1483.8
1078.59	1730.18
1084.32	1466.12
1090.04	1406.55
1095.75	1377.18
1101.47	1358.27
1107.17	1356.43
1112.88	1362.55
1118.58	1368.67
1124.27	1372.82
1129.96	1375.01
1135.65	1376.07
1141.33	1376.28
1147	1376.65
1152.68	1376.59
1158.34	1376.08
1164.01	1374.78
1169.67	1371.86
1175.32	1364.15
1180.97	1364.22
1186.62	1363.17
1192.26	1361.52
1197.89	1360.33
1203.53	1359.27
1209.16	1360.98
1214.78	1370.02
1220.4	1371.5
1226.01	1369.77
1231.62	1367.76
1237.23	1366.17
1242.83	1363.78
1248.43	1359.98
1254.02	1354.42
1259.61	1350.07
1265.2	1351.08
1270.78	1353.64
1276.35	1355.93
1281.93	1357.29
1287.49	1358.27
1293.06	1358.99
1298.62	1359.18
1304.17	1356.87
1309.72	1352.87
1315.27	1349.22
1320.81	1346.19
1326.35	1343.82
1331.88	1341.98
1337.41	1340.87
1342.93	1340.49
1348.45	1340.92
1353.97	1342.14
1359.48	1344.35
1364.99	1347.24
1370.49	1351.04
1375.99	1353.06
1381.49	1352.84
1386.98	1349.45
1392.47	1345.16
1397.95	1341.02
1403.43	1337.64
1408.9	1335.5
1414.37	1334.25
1419.84	1334.47
1425.3	1336.1
1430.76	1338.67
1436.21	1340.01
1441.66	1338.83
1447.1	1336.66
1452.54	1334.1
1457.98	1330.89
1463.41	1327.3
1468.84	1321.31
1474.27	1318.49
1479.69	1317.62
1485.1	1317.8
1490.51	1318.92
1495.92	1320.68
1501.32	1324.44
1506.72	1329.3
1512.12	1330.64
1517.51	1329.94
1522.9	1327.69
1528.28	1329.62
1533.66	1329.45
1539.03	1327.24
1544.4	1323.86
1549.77	1319.65
1555.13	1314.61
1560.49	1310.45
1565.85	1305.17
1571.2	1299.64
1576.54	1302.02
1581.89	1304.81
1587.22	1306.05
1592.56	1307.54
1597.89	1311.33
1603.21	1311.86
1608.54	1308.16
1613.86	1301.71
1619.17	1295.54
1624.48	1290.2
1629.79	1285.63
1635.09	1282.75
1640.39	1280.44
1645.68	1277.65
1650.97	1274.48
1656.26	1271.01
1661.54	1266.89
1666.82	1263.93
1672.09	1261.71
1677.36	1259.68
1682.63	1257.79
1687.89	1255.98
1693.15	1253.77
1698.4	1250.74
1703.65	1246.64
1708.9	1242.26
1714.14	1242.56
1719.38	1241.13
1724.62	1239.96
1729.85	1238.65
1735.08	1237.42
1740.3	1240.88
1745.52	1239.98
1750.73	1231.01
1755.94	1220.22
1761.15	1207.1
1766.35	1197.75
1771.55	1193.93
1776.75	1195.25
1781.94	1200.66
1787.13	1206.06
1792.31	1211.47
1797.5	1216.82
1802.67	1217.05
1807.84	1214.54
1813.01	1211.7
1818.18	1208.44
1823.34	1202.06
1828.5	1195.65
1833.65	1190.66
1838.8	1187.13
1843.94	1184.85
1849.09	1183.23
1854.23	1182.58
1859.36	1182.78
1864.49	1181.43
1869.62	1176.19
1874.74	1169.46
1879.86	1163.07
1884.97	1156.91
1890.09	1153.17
1895.19	1152.56
1900.3	1152.19
1905.4	1152.59
1910.49	1152.86
1915.59	1152.05
1920.67	1149.36
1925.76	1145.49
1930.84	1138.49
1935.92	1131.03
1940.99	1125.41
1946.06	1121.49
1951.13	1119.03
1956.19	1117.7
1961.25	1116.51
1966.31	1114.74
1971.36	1113.06
1976.4	1113.04
1981.45	1112.34
1986.49	1105.31
1991.53	1100.73
1996.56	1096.82
2001.59	1093.67
2006.61	1091.46
2011.64	1087.85
2016.65	1083.38
2021.67	1078.88
2026.68	1074.96
2031.69	1071.54
2036.69	1068.92
2041.69	1067.11
2046.69	1066.29
2051.68	1066.35
2056.67	1067.86
2061.65	1067.81
2066.63	1066.39
2071.61	1064.95
2076.59	1060.72
2081.56	1055.59
2086.52	1049.99
2091.49	1043.15
2096.45	1035.79
2101.4	1031.99
2106.36	1028.01
2111.3	1025.31
2116.25	1026.49
2121.19	1028.26
2126.13	1027.81
2131.06	1025.67
2135.99	1019.16
2140.92	1011.73
2145.85	1005.98
2150.77	1001.89
2155.68	999.292
2160.59	997.972
2165.5	997.643
2170.41	993.141
2175.31	990.783
2180.21	994.135
2185.11	998.672
2190	1000.08
2194.89	999.139
2199.77	994.72
2204.65	988.303
2209.53	981.635
2214.4	976.133
2219.28	973.932
2224.14	971.582
2229.01	968.44
2233.86	965.032
2238.72	961.577
2243.57	957.294
2248.42	950.802
2253.27	943.319
2258.11	939.097
2262.95	936.093
2267.79	933.87
2272.62	933.458
2277.45	932.412
2282.27	930.193
2287.09	927.124
2291.91	923.34
2296.73	918.54
2301.54	912.735
2306.35	906.37
2311.15	901.306
2315.95	898.506
2320.75	896.969
2325.54	896.529
2330.33	896.755
2335.12	896.414
2339.9	893.767
2344.68	888.635
2349.46	881.437
2354.23	873.609
2359	868.778
2363.77	862.804
2368.53	856.462
2373.29	852.96
2378.05	849.524
2382.8	845.818
2387.55	843.673
2392.3	843.979
2397.04	844.519
2401.78	844.135
2406.51	843.152
2411.25	839.663
2415.98	835.729
2420.7	834.007
2425.42	832.442
2430.14	832.259
2434.86	834.383
2439.57	835.078
2444.28	831.025
2448.99	827.247
2453.69	820.827
2458.39	815.827
2463.08	811.907
2467.77	808.307
2472.46	804.559
2477.15	800.684
2481.83	794.916
2486.51	789.991
2491.19	786.207
2495.86	783.398
2500.53	781.392
2505.19	780.111
2509.86	780.066
2514.52	780.256
2519.17	778.677
2523.82	776.402
2528.47	774.422
2533.12	772.179
2537.76	767.759
2542.4	762.748
2547.04	758.231
2551.67	753.296
2556.3	747.167
2560.93	739.959
2565.55	733.976
2570.17	729.91
2574.79	727.852
2579.4	727.862
2584.01	730.45
2588.62	733.329
2593.22	734.726
2597.82	735.132
2602.42	733.871
2607.01	732.469
2611.6	728.003
2616.19	721.132
2620.77	713.56
2625.35	707.734
2629.93	704.257
2634.51	703.509
2639.08	703.651
2643.65	702.713
2648.21	701.865
2652.77	699.971
2657.33	694.793
2661.89	691.228
2666.44	689.662
2670.99	689.741
2675.53	689.146
2680.08	687.683
2684.62	685.326
2689.15	682.342
2693.69	678.802
2698.22	674.856
2702.74	670.565
2707.27	666.154
2711.79	661.595
2716.3	656.73
2720.82	651.352
2725.33	648.742
2729.84	649.635
2734.34	649.892
2738.84	648.486
2743.34	645.829
2747.84	642.681
2752.33	640.045
2756.82	636.852
2761.31	634.784
2765.79	633.547
2770.27	632.805
2774.75	629.789
2779.22	625.599
2783.69	621.506
2788.16	617.605
2792.62	613.584
2797.08	609.107
2801.54	606.353
2806	607.492
2810.45	606.517
2814.9	606.217
2819.34	604.277
2823.79	601.207
2828.23	597.883
2832.66	593.52
2837.09	588.49
2841.53	584.205
2845.95	582.807
2850.38	581.428
2854.8	580.879
2859.22	580.645
2863.63	580.171
2868.04	582.336
2872.45	580.533
2876.86	576.527
2881.26	572.913
2885.66	570.272
2890.06	567.292
2894.45	566.578
2898.85	564.776
2903.23	561.834
2907.62	558.934
2912	556.181
2916.38	553.606
2920.75	551.377
2925.13	549.682
2929.5	548.252
2933.86	547.047
2938.23	545.966
2942.59	544.752
2946.95	541.821
2951.3	538.269
2955.65	534.746
2960	530.377
2964.35	527.941
2968.69	528.986
2973.03	529.133
2977.37	527.579
2981.7	524.197
2986.03	519.095
2990.36	511.641
2994.69	506.098
2999.01	503.624
3003.33	504.06
3007.65	507.073
3011.96	512.305
3016.27	516.848
3020.58	518.17
3024.88	516.396
3029.19	512.143
3033.48	506.141
3037.78	500.254
3042.07	495.333
3046.36	492.393
3050.65	490.052
3054.93	489.638
3059.22	487.646
3063.49	483.608
3067.77	479.804
3072.04	478.279
3076.31	477.287
3080.58	475.394
3084.84	472.068
3089.1	470.509
3093.36	470.782
3097.62	472.534
3101.87	473.211
3106.12	473.779
3110.37	479.426
3114.61	475.053
3118.85	468.827
3123.09	461.266
3127.33	455.242
3131.56	455.075
3135.79	459.984
3140.01	460.642
3144.24	458.738
3148.46	455.593
3152.68	450.244
3156.89	447.204
3161.1	444.798
3165.31	443.533
3169.52	443.843
3173.72	445.501
3177.93	446.2
3182.12	443.032
3186.32	438.99
3190.51	435.902
3194.7	433.424
3198.89	430.916
3203.07	428.786
3207.25	426.969
3211.43	425.426
3215.61	424.107
3219.78	422.819
3223.95	420.673
3228.12	417.391
3232.28	414.988
3236.45	413.54
3240.6	412.468
3244.76	409.328
3248.91	405.062
3253.07	402.47
3257.21	402.301
3261.36	400.787
3265.5	398.027
3269.64	395.903
3273.78	395.557
3277.91	395.31
3282.04	393.138
3286.17	391.727
3290.3	391.212
3294.42	391.906
3298.54	392.371
3302.66	390.849
3306.77	389.249
3310.89	388.495
3314.99	388.381
3319.1	388.155
3323.21	388.335
3327.31	388.741
3331.4	386.784
3335.5	382.988
3339.59	377.082
3343.68	370.737
3347.77	365.886
3351.86	363.629
3355.94	362.66
3360.02	362.48
3364.09	363.142
3368.17	363.718
3372.24	362.866
3376.31	360.198
3380.37	355.499
3384.44	348.975
3388.5	345.917
3392.56	345.421
3396.61	347.09
3400.66	349.136
3404.71	349.289
3408.76	347.621
3412.81	345.397
3416.85	344.206
3420.89	347.936
3424.92	349.22
3428.96	347.79
3432.99	343.75
3437.02	337.529
3441.04	329.772
3445.07	326.803
3449.09	328.334
3453.1	327.999
3457.12	328.079
3461.13	329.04
3465.14	330.167
3469.15	329.308
3473.15	325.225
3477.16	323.751
3481.16	321.899
3485.15	319.619
3489.15	318.509
3493.14	321.059
3497.13	324.758
3501.11	326.946
3505.1	327.454
3509.08	326.052
3513.06	322.595
3517.03	317.041
3521.01	310.689
3524.98	306.056
3528.95	305.588
3532.91	307.473
3536.87	310.262
3540.84	313.303
3544.79	316.456
3548.75	316.023
3552.7	310.543
3556.65	313.465
3560.6	316.952
3564.54	338.505
3568.49	391.648
3572.43	458.788
3576.36	370.503
3580.3	338.321
3584.23	323.293
3588.16	305.176
3592.09	294.729
3596.01	287.192
3599.93	283.973
3603.85	283.246
3607.77	283.682
3611.68	284.53
3615.59	283.729
3619.5	276.875
3623.41	276.088
3627.31	276.793
3631.21	278.253
3635.11	280.143
3639.01	281.105
3642.9	280.406
3646.8	278.315
3650.68	274.607
3654.57	270.164
3658.45	266.835
3662.34	264.879
3666.22	264.048
3670.09	263.848
3673.97	263.047
3677.84	260.763
3681.7	258.142
3685.57	256.519
3689.44	256.717
3693.3	256.045
3697.16	254.248
3701.01	252.808
3704.87	251.194
3708.72	249.094
3712.57	252.734
3716.41	252.997
3720.26	252.907
3724.1	252.316
3727.94	251.373
3731.77	250.332
3735.61	251.963
3739.44	248.984
3743.27	246.311
3747.09	244.634
3750.92	243.663
3754.74	243.654
3758.56	242.665
3762.38	241.039
3766.19	239.457
3770	239.558
3773.81	238.849
3777.62	237.997
3781.42	238.206
3785.23	237.931
3789.03	236.857
3792.82	233.723
3796.62	230.043
3800.41	227.9
3804.2	227.91
3807.99	229.186
3811.77	229.515
3815.56	229.255
3819.34	228.074
3823.11	225.924
3826.89	222.743
3830.66	219.257
3834.43	218.286
3838.2	219.745
3841.97	220.002
3845.73	219.92
3849.49	218.941
3853.25	218.931
3857.01	215.872
3860.76	212.108
3864.51	210.859
3868.26	209.923
3872.01	208.883
3875.75	207.624
3879.49	206.966
3883.23	208.619
3886.97	207.406
3890.71	206.119
3894.44	205.516
3898.17	205.764
3901.9	204.163
3905.62	202.567
3909.35	201.337
3913.07	200.852
3916.78	200.825
3920.5	201.171
3924.21	201.719
3927.93	202.345
3931.63	202.605
3935.34	200.778
3939.04	197.908
3942.75	196.202
3946.45	195.945
3950.14	195.612
3953.84	194.566
3957.53	194.711
3961.22	194.949
3964.91	193.898
3968.59	191.68
3972.28	189.31
3975.96	187.611
3979.64	187.299
3983.31	187.285
3986.99	186.717
3990.66	185.451
3994.33	185.228
3997.99	187.14
3999.83	191.687