File: Data/Raman/raw/augelite_150 (500nm)_633nm_edge_100%_x50_vis_lwd_h30um_30sx2_01.txt
#Acq. time (s)=	30
#Accumulations=	2
#Range (cm-¹)=	100...4000
#Windows=	1
#Auto scanning=	Off
#Autofocus=	Off
#Macrospot=	Off
#AutoExposure=	Off
#Spike filter=	Multiple accum.
#Delay time (s)=	2
#Binning=	1
#Readout mode=	Signal
#DeNoise=	Standard
#ICS correction=	On
#Dark correction=	Off
#Inst. Process=	Off
#Detector Gain=	Best Dynamic
#Detector ADC=	50 kHz HS
#Detector temperature (°C)=	-60.09
#Instrument=	LabRAM HR Evol
#Detector=	SIN-EM FIVIS
#Objective=	x50_VIS_LWD
#Grating=	150 (500nm)
#ND Filter=	100%
#Laser=	633nm_Edge
#Hole=	30.0125
#Temperature=	0
#Range=	Visible
#StageXY=	75x50mm Scan+
#StageZ=	Z motor
#X (µm)=	0
#Y (µm)=	0
#Z (µm)=	58.4
#Full time(mm:ss)=	1:04
#Project=	21_02_17
#Sample=	BU19w
#Site=
#Title=	BU19w-Area11-augelite_overBrt_150 (500nm)_633nm_Edge_100%_x50_VIS_LWD_H30um_30sX2
#Remark=
#Date=	17.02.2021 10:31
#Acquired=	17.02.2021 10:31:38
100.724	207.785
107.24	213.695
113.751	210.388
120.256	230.151
126.756	333.37
133.251	382.427
139.74	291.617
146.224	284.504
152.702	348.91
159.175	572.058
165.643	951.035
172.105	858.608
178.561	490.799
185.013	349.739
191.459	293.207
197.9	262.947
204.336	251.136
210.765	249.75
217.19	273.893
223.61	342.348
230.024	535.731
236.432	311.587
242.836	270.933
249.233	358.791
255.627	641.887
262.015	346.642
268.397	245.838
274.774	225.442
281.145	221.232
287.513	224.352
293.873	229.091
300.23	229.895
306.58	228.772
312.927	226.755
319.266	225.711
325.602	226.873
331.932	235.661
338.256	245.487
344.577	261.02
350.89	296.46
357.199	315.142
363.504	320.382
369.803	434.074
376.096	415.311
382.384	304.003
388.669	261.352
394.947	252.881
401.219	265.761
407.487	308.607
413.75	354.929
420.007	380.43
426.261	356.289
432.508	325.841
438.751	323.371
444.988	343.846
451.22	368.444
457.447	386.762
463.669	387.241
469.886	413.283
476.098	356.298
482.303	305.257
488.505	280.145
494.702	269.499
500.894	272.255
507.081	292.381
513.263	329.96
519.44	395.019
525.61	464.28
531.777	510.272
537.939	479.804
544.096	447.777
550.246	442.964
556.393	468.678
562.535	496.096
568.671	509.011
574.803	475.824
580.929	430.744
587.051	374.145
593.167	321.077
599.28	294.66
605.387	301.909
611.489	330.301
617.585	373.563
623.678	417.415
629.764	557.256
635.847	941.193
641.924	1068.7
647.998	594.157
654.065	378.773
660.127	322.134
666.184	292.257
672.238	270.771
678.286	254.036
684.329	241.609
690.367	235.619
696.401	234.065
702.43	235.555
708.453	238.11
714.472	241.642
720.486	244.858
726.495	246.669
732.5	246.625
738.501	245.297
744.495	244.033
750.485	240.131
756.471	236.066
762.451	231.241
768.426	227.957
774.397	229.24
780.363	232.093
786.325	233.946
792.281	237.653
798.234	238.516
804.181	237.197
810.124	234.651
816.06	232.624
821.993	231.832
827.922	233.962
833.846	240.24
839.764	249.585
845.678	265.949
851.588	285.724
857.492	304.995
863.392	313.545
869.287	300.601
875.178	278.06
881.063	271.416
886.945	268.21
892.822	271.409
898.694	276.88
904.56	273.126
910.424	259.244
916.281	242.669
922.135	231.095
927.984	232.279
933.827	234.754
939.668	235.882
945.502	234.09
951.332	234.208
957.159	231.855
962.979	232.247
968.796	232.23
974.607	232.919
980.414	234.835
986.218	237.113
992.016	235.242
997.809	240.798
1003.6	251.277
1009.38	270.104
1015.16	281.203
1020.94	286.644
1026.71	274.738
1032.48	265.863
1038.24	259.699
1043.99	255.244
1049.75	267.102
1055.5	273.296
1061.24	288.938
1066.98	303.816
1072.71	296.132
1078.44	285.863
1084.17	290.785
1089.89	309.363
1095.61	345.229
1101.32	418.608
1107.03	560.546
1112.73	722.033
1118.43	617.34
1124.12	424.421
1129.81	342.52
1135.5	305.146
1141.18	292.081
1146.86	291.691
1152.53	307.8
1158.2	331.873
1163.86	345.8
1169.52	329.353
1175.17	298.974
1180.83	267.488
1186.47	247.632
1192.11	240.062
1197.75	235.607
1203.38	229.665
1209.01	226.246
1214.63	225.823
1220.25	224.775
1225.87	222.589
1231.48	221.125
1237.09	220.212
1242.69	218.834
1248.29	217.416
1253.88	216.909
1259.47	215.748
1265.05	214.122
1270.63	211.735
1276.21	209.836
1281.78	210.169
1287.35	211.993
1292.91	213.304
1298.47	213.501
1304.03	212.997
1309.58	211.783
1315.13	209.958
1320.67	207.55
1326.2	204.629
1331.74	204.379
1337.27	204.561
1342.79	204.716
1348.31	204.684
1353.83	204.498
1359.34	204.249
1364.85	203.826
1370.35	203.177
1375.85	202.35
1381.35	201.447
1386.84	200.798
1392.32	200.699
1397.81	199.305
1403.29	199.253
1408.76	199.697
1414.23	200.666
1419.7	199.232
1425.16	199.177
1430.61	199.088
1436.07	198.315
1441.52	196.648
1446.96	194.65
1452.4	194.837
1457.84	196.49
1463.27	196.749
1468.7	196.231
1474.12	196.731
1479.55	197.855
1484.96	198.925
1490.37	199.916
1495.78	199.891
1501.18	199.429
1506.58	197.986
1511.98	196.136
1517.37	194.715
1522.76	193.957
1528.14	193.507
1533.52	192.973
1538.9	192.357
1544.27	191.403
1549.63	190.11
1555	189.296
1560.35	188.829
1565.71	189.399
1571.06	190.166
1576.41	190.851
1581.75	191.481
1587.09	191.798
1592.42	191.997
1597.75	192.157
1603.08	192.221
1608.4	192.194
1613.72	192.093
1619.03	191.944
1624.34	191.849
1629.65	191.5
1634.95	191.037
1640.25	190.486
1645.54	189.849
1650.83	189.144
1656.12	188.397
1661.4	187.615
1666.68	186.869
1671.96	186.09
1677.23	185.32
1682.49	184.581
1687.75	183.93
1693.01	183.259
1698.27	182.575
1703.52	181.87
1708.77	181.212
1714.01	180.664
1719.25	179.882
1724.48	180.164
1729.71	181.197
1734.94	182.206
1740.16	182.482
1745.38	182.406
1750.6	182.116
1755.81	181.597
1761.02	180.98
1766.22	180.432
1771.42	179.85
1776.62	179.495
1781.81	178.967
1787	178.283
1792.18	177.247
1797.36	176.123
1802.54	174.916
1807.71	173.677
1812.88	172.541
1818.05	171.773
1823.21	172.439
1828.36	173.879
1833.52	174.333
1838.67	174.258
1843.81	174.014
1848.95	173.356
1854.09	171.855
1859.23	170.908
1864.36	170.468
1869.48	170.901
1874.61	172.154
1879.73	171.653
1884.84	170.506
1889.95	169.324
1895.06	168.511
1900.17	167.943
1905.27	167.737
1910.36	168.067
1915.45	169.309
1920.54	169.969
1925.63	169.09
1930.71	167.13
1935.79	165.126
1940.86	163.4
1945.93	161.877
1951	162.48
1956.06	156.516
1961.12	165.988
1966.18	166.667
1971.23	166.205
1976.28	165.608
1981.32	165.006
1986.36	164.411
1991.4	164.062
1996.43	163.962
2001.46	163.937
2006.48	163.961
2011.51	163.975
2016.52	163.944
2021.54	163.834
2026.55	163.63
2031.56	163.07
2036.56	162.367
2041.56	161.43
2046.56	161.272
2051.55	160.094
2056.54	157.742
2061.52	153.936
2066.51	151.963
2071.48	150.655
2076.46	149.884
2081.43	150.314
2086.4	152.492
2091.36	154.317
2096.32	154.179
2101.28	152.001
2106.23	150.471
2111.18	148.787
2116.12	146.979
2121.06	144.691
2126	143.844
2130.94	145.133
2135.87	145.901
2140.79	146.37
2145.72	146.492
2150.64	146.411
2155.56	146.088
2160.47	145.655
2165.38	145.05
2170.28	144.42
2175.19	143.812
2180.09	143.314
2184.98	142.752
2189.87	142.669
2194.76	142.965
2199.65	143.425
2204.53	143.729
2209.4	143.973
2214.28	143.036
2219.15	141.744
2224.02	140.294
2228.88	139.807
2233.74	139.556
2238.6	139.361
2243.45	139.064
2248.3	138.435
2253.14	137.68
2257.99	137.033
2262.83	135.679
2267.66	134.219
2272.49	132.801
2277.32	131.955
2282.15	131.725
2286.97	131.875
2291.79	132.279
2296.6	133.123
2301.41	134.282
2306.22	135.494
2311.02	136.448
2315.83	137.006
2320.62	137.084
2325.42	136.783
2330.21	136.096
2335	135.096
2339.78	133.923
2344.56	132.635
2349.34	131.396
2354.11	129.977
2358.88	128.409
2363.65	126.86
2368.41	125.458
2373.17	124.296
2377.93	123.726
2382.68	123.802
2387.43	125.177
2392.17	127.068
2396.92	127.415
2401.66	126.242
2406.39	125.001
2411.13	124.275
2415.85	123.964
2420.58	124.038
2425.3	124.413
2430.02	125.355
2434.74	126.466
2439.45	127.591
2444.16	127.651
2448.86	127.032
2453.57	126.469
2458.27	126.069
2462.96	124.95
2467.65	123.08
2472.34	121.374
2477.03	120.182
2481.71	119.514
2486.39	119.864
2491.07	120.345
2495.74	120.799
2500.41	121.074
2505.07	120.461
2509.74	119.313
2514.4	117.411
2519.05	115.443
2523.7	113.706
2528.35	113.152
2533	113.075
2537.64	113.41
2542.28	114.426
2546.92	115.919
2551.55	117.464
2556.18	118.779
2560.81	119.538
2565.43	119.466
2570.05	118.638
2574.67	116.981
2579.28	115.246
2583.89	113.526
2588.5	112.348
2593.1	111.325
2597.7	110.558
2602.3	110.123
2606.89	110.034
2611.48	110.16
2616.07	110.569
2620.66	111.211
2625.24	112.23
2629.82	113.302
2634.39	114.321
2638.96	114.797
2643.53	114.398
2648.09	113.179
2652.66	111.247
2657.21	109.22
2661.77	108.338
2666.32	108.797
2670.87	108.775
2675.42	108.265
2679.96	108.057
2684.5	108.092
2689.04	108.168
2693.57	108.173
2698.1	108.135
2702.63	108.112
2707.15	108.413
2711.67	108.452
2716.19	106.812
2720.7	107.801
2725.21	110.131
2729.72	112.458
2734.23	110.578
2738.73	103.321
2743.23	101.223
2747.72	105.652
2752.22	106.971
2756.7	106.615
2761.19	104.695
2765.67	104.419
2770.15	104.285
2774.63	104.269
2779.1	104.3
2783.57	104.42
2788.04	104.546
2792.51	104.635
2796.97	104.69
2801.43	104.607
2805.88	104.3
2810.33	103.648
2814.78	102.433
2819.23	100.873
2823.67	98.0069
2828.11	96.0715
2832.55	94.2502
2836.98	95.0095
2841.41	96.6862
2845.84	98.6607
2850.26	102.195
2854.69	102.145
2859.1	99.5879
2863.52	99.5505
2867.93	98.8631
2872.34	98.1465
2876.75	97.6839
2881.15	97.7382
2885.55	97.8945
2889.95	98.15
2894.34	98.6756
2898.73	99.2821
2903.12	99.9727
2907.5	100.212
2911.89	99.6849
2916.27	98.8191
2920.64	98.0379
2925.01	97.5548
2929.38	96.9937
2933.75	96.5302
2938.12	96.2223
2942.48	96.056
2946.84	96.0625
2951.19	96.2537
2955.54	96.6093
2959.89	97.2114
2964.24	97.9552
2968.58	98.5292
2972.92	97.9896
2977.26	97.1115
2981.59	95.8078
2985.92	94.3936
2990.25	93.5501
2994.58	92.7555
2998.9	91.8541
3003.22	93.4173
3007.54	94.1271
3011.85	93.1857
3016.16	91.3375
3020.47	91.2315
3024.77	91.4612
3029.07	91.7542
3033.37	91.924
3037.67	91.9156
3041.96	91.7486
3046.25	91.4436
3050.54	91.0833
3054.82	90.6989
3059.11	90.4273
3063.38	90.3399
3067.66	90.6168
3071.93	91.4645
3076.2	94.4893
3080.47	97.2189
3084.73	97.8977
3088.99	96.4254
3093.25	94.5362
3097.51	93.4595
3101.76	93.2759
3106.01	93.2039
3110.26	93.1897
3114.5	93.2672
3118.74	93.1165
3122.98	92.7314
3127.22	92.1349
3131.45	91.424
3135.68	90.7774
3139.91	90.6814
3144.13	91.195
3148.35	91.7987
3152.57	92.2973
3156.78	92.347
3161	92.2489
3165.21	92.1854
3169.41	92.2027
3173.62	92.3758
3177.82	92.5953
3182.02	93.7021
3186.21	94.9494
3190.4	95.4978
3194.59	94.8173
3198.78	94.7822
3202.96	93.4686
3207.15	91.7425
3211.33	89.9397
3215.5	88.5304
3219.67	86.5972
3223.84	88.7229
3228.01	91.7471
3232.18	94.5577
3236.34	96.262
3240.5	96.2334
3244.65	93.3997
3248.81	91.2644
3252.96	90.0981
3257.11	89.8701
3261.25	90.0782
3265.39	90.2636
3269.53	90.5224
3273.67	90.8869
3277.8	91.2721
3281.94	91.5969
3286.06	91.7692
3290.19	92.4976
3294.31	93.6818
3298.43	95.2975
3302.55	96.7617
3306.67	98.2886
3310.78	99.5119
3314.89	100.551
3319	101.457
3323.1	102.193
3327.2	102.792
3331.3	103.341
3335.39	103.736
3339.49	104.04
3343.58	104.314
3347.67	104.67
3351.75	104.963
3355.83	105.314
3359.91	105.738
3363.99	107.256
3368.06	111.779
3372.14	114.788
3376.2	117.44
3380.27	120.118
3384.33	123.024
3388.39	126.361
3392.45	129.723
3396.51	130.205
3400.56	134.959
3404.61	142.523
3408.66	144.873
3412.7	147.506
3416.74	151.439
3420.78	157.026
3424.82	164.413
3428.85	173.361
3432.88	183.948
3436.91	196.055
3440.94	211.028
3444.96	227.962
3448.98	241.437
3453	256.43
3457.02	275.636
3461.03	305.277
3465.04	380.807
3469.05	500.525
3473.05	506.269
3477.05	436.954
3481.05	360.294
3485.05	311.622
3489.04	284.999
3493.04	270.505
3497.03	263.577
3501.01	257.01
3505	254.54
3508.98	253.954
3512.96	256.048
3516.93	260.242
3520.9	266.093
3524.88	271.161
3528.84	283.445
3532.81	307.222
3536.77	331.929
3540.73	352.644
3544.69	363.647
3548.65	371.654
3552.6	357.641
3556.55	332.792
3560.5	300.173
3564.44	263.201
3568.38	225.892
3572.32	193.694
3576.26	168.38
3580.2	153.283
3584.13	142.289
3588.06	133.45
3591.98	126.844
3595.91	122.145
3599.83	118.282
3603.75	114.226
3607.67	110.144
3611.58	105.776
3615.49	103.493
3619.4	102.751
3623.31	103.382
3627.21	103.981
3631.11	101.15
3635.01	98.8074
3638.91	97.3259
3642.8	95.6173
3646.69	94.5504
3650.58	93.6066
3654.47	92.6537
3658.35	91.7334
3662.24	90.5419
3666.11	88.463
3669.99	86.1236
3673.86	83.8483
3677.74	81.7928
3681.6	80.7603
3685.47	80.5615
3689.34	81.0366
3693.2	82.3661
3697.06	84.2812
3700.91	83.6793
3704.77	83.9644
3708.62	83.1919
3712.47	80.3239
3716.31	77.3252
3720.16	75.8449
3724	75.1882
3727.84	75.3731
3731.67	77.2512
3735.51	79.2187
3739.34	79.2634
3743.17	78.0397
3747	78.5299
3750.82	79.3459
3754.64	79.2758
3758.46	78.2279
3762.28	77.2766
3766.09	76.5485
3769.9	76.1297
3773.71	75.9634
3777.52	76.1384
3781.33	76.3996
3785.13	76.744
3788.93	77.2093
3792.72	77.8207
3796.52	78.2537
3800.31	77.934
3804.1	76.0724
3807.89	74.0264
3811.68	71.7863
3815.46	70.1723
3819.24	69.0623
3823.02	68.8794
3826.79	70.0193
3830.56	71.4242
3834.34	72.8442
3838.1	73.6224
3841.87	74.1795
3845.63	75.067
3849.39	75.8343
3853.15	76.2552
3856.91	76.2811
3860.66	75.4987
3864.42	74.0806
3868.16	71.9849
3871.91	70.0487
3875.66	69.6462
3879.4	70.4443
3883.14	72.162
3886.88	73.4596
3890.61	72.0399
3894.34	71.3907
3898.07	71.1445
3901.8	71.5581
3905.53	72.8892
3909.25	71.4471
3912.97	70.5824
3916.69	69.8177
3920.4	69.5624
3924.12	71.1932
3927.83	70.3258
3931.54	68.7393
3935.24	67.737
3938.95	67.38
3942.65	67.7066
3946.35	68.5861
3950.05	70.1722
3953.74	72.0289
3957.44	73.6224
3961.13	73.2114
3964.81	72.3765
3968.5	71.5494
3972.18	70.7385
3975.86	69.9444
3979.54	69.2161
3983.22	68.5757
3986.89	67.9761
3990.56	67.3613
3994.23	66.6676
3997.9	65.6265
3999.73	65.1452