File: Data/Raman/raw/augelite_150 (500nm)_633nm_Edge_100%_x50_VIS_LWD_H100um_15sX2.txt
#Acq. time (s)=	15
#Accumulations=	2
#Range (cm-¹)=	100...4000
#Windows=	1
#Auto scanning=	Off
#Autofocus=	Off
#Macrospot=	Off
#AutoExposure=	Off
#Spike filter=	Single accum. (Size=4)
#Delay time (s)=	0
#Binning=	1
#Readout mode=	Signal
#DeNoise=	Standard
#ICS correction=	On
#Dark correction=	Off
#Inst. Process=	On
#Detector Gain=	Best Dynamic
#Detector ADC=	50 kHz HS
#Detector temperature (°C)=	-60.09
#Instrument=	LabRAM HR Evol
#Detector=	SIN-EM FIVIS
#Objective=	x50_VIS_LWD
#Grating=	150 (500nm)
#ND Filter=	100%
#Laser=	633nm_Edge
#Hole=	100.021
#Temperature=	0
#Range=	Visible
#StageXY=	75x50mm Scan+
#StageZ=	Z motor
#X (µm)=	0
#Y (µm)=	0
#Z (µm)=	76.8
#Project=	20_05_11
#Sample=	BU20b
#Site=
#Title=	BU20b-area3-blue-rim-on-Scz_bottom_150 (500nm)_633nm_Edge_100%_x50_VIS_LWD_H100um_15sX2
#Remark=
#Date=	11.05.2020 19:20
#Acquired=	11.05.2020 19:20:54
100.862	1061.68
107.378	1242.46
113.889	1116.23
120.394	951.03
126.894	834.136
133.388	780.624
139.878	808.193
146.361	847.509
152.84	923.039
159.313	874.811
165.78	888.748
172.242	1010.33
178.699	1212.43
185.149	944.27
191.596	850.142
198.037	854.691
204.472	883.725
210.903	916.704
217.326	952.11
223.746	981.782
230.16	959.051
236.568	944.487
242.972	923.33
249.371	929.736
255.762	978.714
262.151	926.146
268.533	857.903
274.91	928.659
281.282	1051.27
287.648	1037.21
294.01	912.471
300.365	916.935
306.716	856.608
313.061	891.832
319.401	1059.89
325.737	966.043
332.066	870.697
338.392	841.435
344.711	829.871
351.024	844.593
357.335	906.303
363.638	1049.22
369.936	952.486
376.23	836.706
382.519	797.756
388.802	760.719
395.08	752.139
401.353	782.793
407.62	850.193
413.884	974.093
420.141	978.748
426.394	918.551
432.641	873.891
438.883	958.476
445.12	1096.98
451.352	962.682
457.579	920.038
463.801	988.601
470.018	1074.58
476.23	1009.62
482.437	969.222
488.638	1023.58
494.834	1105.98
501.026	1203.54
507.212	1310.94
513.394	1389.09
519.571	1411.45
525.743	1410.15
531.908	1509.22
538.07	1615
544.227	1549.67
550.377	1408.24
556.524	1437.95
562.666	1729.66
568.801	1845.56
574.933	1636.89
581.061	1298.21
587.181	1167.6
593.299	1233.38
599.41	1524.32
605.517	1820.72
611.618	1496.5
617.716	1090.02
623.807	960.603
629.895	910.567
635.977	907.688
642.053	894.491
648.127	837.521
654.193	814.369
660.256	824.413
666.314	810.477
672.367	759.241
678.414	702.522
684.457	655.806
690.496	625.757
696.529	606.135
702.558	594.096
708.581	588.314
714.6	585.353
720.614	583.875
726.624	583.51
732.628	578.733
738.628	578.201
744.623	580.241
750.613	583.919
756.598	589.258
762.578	596.318
768.554	603.435
774.525	608.3
780.49	611.681
786.451	615.556
792.408	621.478
798.36	631.315
804.307	632.045
810.25	625.412
816.186	607.12
822.119	588.224
828.048	571.178
833.972	558.288
839.889	547.893
845.804	540.726
851.714	536.872
857.617	534.6
863.518	531.971
869.413	529.594
875.303	528.005
881.19	526.641
887.07	524.609
892.947	521.887
898.818	519.435
904.686	518.529
910.548	519.31
916.406	522.008
922.26	529.108
928.108	542.789
933.953	563.54
939.792	594.506
945.626	629.643
951.457	681.239
957.282	741.214
963.103	810.559
968.919	925.223
974.731	1175.88
980.539	1342.7
986.341	1520.14
992.139	1770.29
997.932	1681.27
1003.72	1337.81
1009.51	1276.2
1015.29	1500.36
1021.06	2046.24
1026.83	2113.63
1032.6	1777.3
1038.36	1504.97
1044.12	1380.31
1049.87	1264.1
1055.62	1118.84
1061.36	1081.45
1067.1	1066.71
1072.84	1051.86
1078.56	1015.79
1084.29	968.295
1090.01	903.315
1095.73	823.295
1101.44	753.129
1107.15	742.223
1112.85	807.384
1118.55	965.514
1124.24	1020.68
1129.94	869.391
1135.62	754.56
1141.3	715.696
1146.98	753.041
1152.65	769.839
1158.32	691.967
1163.98	620.842
1169.64	584.875
1175.3	559.73
1180.95	539.393
1186.59	524.517
1192.23	513.751
1197.87	505.483
1203.5	499.734
1209.13	495.123
1214.75	490.598
1220.37	486.708
1225.99	483.515
1231.6	481.06
1237.21	478.956
1242.81	476.396
1248.41	473.839
1254	470.723
1259.59	468.013
1265.17	466.173
1270.75	465.326
1276.33	465.286
1281.9	465.169
1287.47	464.949
1293.03	464.634
1298.59	464.812
1304.15	465.022
1309.7	464.759
1315.24	464.094
1320.78	463.211
1326.32	462.705
1331.85	462.779
1337.38	462.737
1342.91	461.225
1348.43	461.621
1353.95	461.919
1359.46	461.289
1364.97	460.899
1370.47	459.283
1375.97	457.065
1381.46	454.221
1386.96	451.521
1392.44	450.403
1397.92	450.567
1403.4	450.811
1408.88	450.681
1414.35	449.999
1419.81	448.838
1425.27	447.116
1430.73	444.699
1436.18	442.584
1441.63	441.666
1447.08	441.39
1452.52	440.894
1457.96	440.525
1463.39	440.419
1468.82	440.318
1474.24	439.708
1479.66	438.487
1485.08	437.759
1490.49	437.627
1495.9	438.693
1501.3	438.599
1506.7	438.598
1512.09	437.755
1517.49	435.716
1522.87	433.297
1528.26	431.352
1533.63	430.336
1539.01	430.025
1544.38	430.367
1549.75	429.881
1555.11	434.169
1560.47	434.835
1565.82	431.556
1571.17	426.412
1576.52	423.308
1581.86	423.001
1587.2	423.255
1592.54	423.83
1597.86	425.013
1603.19	425.765
1608.51	425.909
1613.83	425.318
1619.15	424.336
1624.46	423.478
1629.76	423.47
1635.06	424.103
1640.36	422.629
1645.66	419.527
1650.95	417.842
1656.23	416.694
1661.52	416.153
1666.79	415.692
1672.07	415.31
1677.34	415.112
1682.6	414.757
1687.87	414.117
1693.13	412.842
1698.38	411.268
1703.63	409.569
1708.88	408.285
1714.12	406.62
1719.36	403.935
1724.59	402.232
1729.82	402.472
1735.05	403.349
1740.27	403.996
1745.49	404
1750.71	401.772
1755.92	398.611
1761.13	395.487
1766.33	393.139
1771.53	391.847
1776.73	390.831
1781.92	391.39
1787.11	392.464
1792.29	393.437
1797.47	394.218
1802.65	393.494
1807.82	392.143
1812.99	391.502
1818.15	391.365
1823.32	390.911
1828.47	389.493
1833.63	386.468
1838.78	384.189
1843.92	382.544
1849.06	381.213
1854.2	380.087
1859.34	379.08
1864.47	378.177
1869.59	377.669
1874.72	376.484
1879.84	375.238
1884.95	374.343
1890.06	374.14
1895.17	374.26
1900.27	374.669
1905.37	374.963
1910.47	375.042
1915.56	375.396
1920.65	374.852
1925.74	373.189
1930.82	371.164
1935.9	369.281
1940.97	368.126
1946.04	368.024
1951.11	368.551
1956.17	369.015
1961.23	368.957
1966.28	368.301
1971.33	365.275
1976.38	362.005
1981.43	359.662
1986.47	358.088
1991.5	357.406
1996.54	357.686
2001.57	358.071
2006.59	356.761
2011.61	355.287
2016.63	355.015
2021.65	356.018
2026.66	356.228
2031.66	355.831
2036.67	354.157
2041.67	352.155
2046.66	350.295
2051.66	348.827
2056.65	349.096
2061.63	349.805
2066.61	350.598
2071.59	351.388
2076.56	351.719
2081.53	350.954
2086.5	349.363
2091.46	348.235
2096.42	347.426
2101.38	346.893
2106.33	346.837
2111.28	347.409
2116.23	347.978
2121.17	348.242
2126.11	348.056
2131.04	346.938
2135.97	344.765
2140.9	342.712
2145.82	341.823
2150.74	341.297
2155.66	340.746
2160.57	340.144
2165.48	339.197
2170.39	337.077
2175.29	332.38
2180.19	328.369
2185.09	324.573
2189.98	324.762
2194.86	327.519
2199.75	332.029
2204.63	334.159
2209.51	333.699
2214.38	332.699
2219.25	331.878
2224.12	329.833
2228.98	327.918
2233.84	326.405
2238.7	325.44
2243.55	325.038
2248.4	325.43
2253.25	326.823
2258.09	327.655
2262.93	327.408
2267.76	326.586
2272.6	324.743
2277.43	322.728
2282.25	320.16
2287.07	317.885
2291.89	316.371
2296.7	315.42
2301.52	315.17
2306.32	315.373
2311.13	315.401
2315.93	318.209
2320.73	318.831
2325.52	317.707
2330.31	315.165
2335.1	312.443
2339.88	311.296
2344.66	310.557
2349.44	309.549
2354.21	309.313
2358.98	309.338
2363.75	309.392
2368.51	309.263
2373.27	308.959
2378.03	308.187
2382.78	307.338
2387.53	307.496
2392.28	305.848
2397.02	302.683
2401.76	299.786
2406.49	298.017
2411.23	297.482
2415.95	297.655
2420.68	298.271
2425.4	299.372
2430.12	299.929
2434.84	299.718
2439.55	299.091
2444.26	298.603
2448.96	298.579
2453.67	299.068
2458.37	297.907
2463.06	295.952
2467.75	293.888
2472.44	292.759
2477.13	293.624
2481.81	295.16
2486.49	297.933
2491.17	301.303
2495.84	301.064
2500.51	298.797
2505.17	294.804
2509.84	290.577
2514.5	289.613
2519.15	289.012
2523.8	288.556
2528.45	288.39
2533.1	288.53
2537.74	288.698
2542.38	288.642
2547.02	287.956
2551.65	287.377
2556.28	286.992
2560.91	286.867
2565.53	286.916
2570.15	287.364
2574.77	288.437
2579.38	289.505
2583.99	289.496
2588.6	288.415
2593.2	286.99
2597.8	285.545
2602.4	284.402
2606.99	283.29
2611.58	282.043
2616.17	281.01
2620.75	280.028
2625.33	279.621
2629.91	278.993
2634.49	278.047
2639.06	277.147
2643.63	276.309
2648.19	275.572
2652.75	275.22
2657.31	276.163
2661.87	276.328
2666.42	276.654
2670.97	277.208
2675.51	277.102
2680.06	276.373
2684.6	275.891
2689.13	275.004
2693.67	274.061
2698.2	272.538
2702.72	271.078
2707.25	269.631
2711.77	268.336
2716.28	267.405
2720.8	267.03
2725.31	267.69
2729.82	269.259
2734.32	270.749
2738.83	271.986
2743.32	272.23
2747.82	272.021
2752.31	271.167
2756.8	270.441
2761.29	269.775
2765.77	268.731
2770.25	267.774
2774.73	266.622
2779.2	265.509
2783.67	264.675
2788.14	264.592
2792.6	265.159
2797.06	266.486
2801.52	267.898
2805.98	267.946
2810.43	267.592
2814.88	266.591
2819.32	265.296
2823.77	264.554
2828.2	264.341
2832.64	264.534
2837.08	265.275
2841.51	266.134
2845.93	266.871
2850.36	266.926
2854.78	266.631
2859.2	265.788
2863.61	265.022
2868.02	265.12
2872.43	265.737
2876.84	266.869
2881.24	267.617
2885.64	267.456
2890.04	266.689
2894.43	265.54
2898.82	264.357
2903.21	264.545
2907.6	265.54
2911.98	266.114
2916.36	266.472
2920.74	266.349
2925.11	266.137
2929.48	265.965
2933.84	265.544
2938.21	264.813
2942.57	264.778
2946.93	263.759
2951.28	262.225
2955.64	261.071
2959.98	260.916
2964.33	261.366
2968.67	261.636
2973.01	262.498
2977.35	264.357
2981.68	265.621
2986.02	265.38
2990.34	265.55
2994.67	266.12
2998.99	266.467
3003.31	265.847
3007.63	265.299
3011.94	265.008
3016.25	263.38
3020.56	261.41
3024.86	260.276
3029.17	260.205
3033.47	261.038
3037.76	262.602
3042.05	264.338
3046.34	265.278
3050.63	265.683
3054.92	265.199
3059.2	263.613
3063.48	262.055
3067.75	260.919
3072.02	260.848
3076.29	261.677
3080.56	264.078
3084.82	266.842
3089.09	269.111
3093.34	271.329
3097.6	273.014
3101.85	274.596
3106.1	278.47
3110.35	279.682
3114.59	279.663
3118.83	279.518
3123.07	280.307
3127.31	282.666
3131.54	285.955
3135.77	289.68
3140	293.777
3144.22	298.126
3148.44	302.036
3152.66	304.897
3156.87	306.294
3161.09	307.797
3165.29	308.628
3169.5	309.102
3173.71	309.987
3177.91	311.47
3182.11	313.955
3186.3	318.523
3190.49	324.975
3194.68	333.455
3198.87	344.308
3203.05	357.122
3207.24	371.738
3211.41	387.792
3215.59	406.695
3219.76	426.981
3223.93	448.639
3228.1	472.141
3232.27	495.873
3236.43	515.738
3240.59	533.99
3244.74	548.192
3248.9	557.664
3253.05	558.927
3257.2	554.651
3261.34	546.892
3265.48	536.825
3269.62	526.747
3273.76	513.956
3277.89	499.712
3282.02	484.309
3286.15	468.877
3290.28	453.911
3294.4	439.855
3298.52	426.786
3302.64	415.307
3306.75	406.096
3310.87	398.632
3314.98	392.712
3319.08	388.574
3323.19	386.291
3327.29	384.942
3331.39	384.217
3335.48	383.802
3339.58	383.379
3343.67	383.072
3347.75	383.068
3351.84	384.42
3355.92	387.463
3360	392.888
3364.08	399.518
3368.15	407.23
3372.22	415.658
3376.29	418.846
3380.36	422.296
3384.42	428.491
3388.48	440.152
3392.54	464.759
3396.59	494.904
3400.65	551.812
3404.7	624.051
3408.74	710.836
3412.79	810.072
3416.83	882.852
3420.87	950.51
3424.91	916.491
3428.94	876.948
3432.97	818.066
3437	753.711
3441.02	733.403
3445.05	765.213
3449.07	814.081
3453.09	880.132
3457.1	1020.81
3461.11	1213.54
3465.13	1348.54
3469.13	1386.66
3473.14	1318.4
3477.14	1206.88
3481.14	1080.47
3485.14	957.999
3489.13	843.983
3493.12	743.104
3497.11	653.443
3501.1	587.871
3505.08	538.824
3509.06	508.089
3513.04	486.148
3517.02	467.379
3520.99	450.352
3524.96	434.4
3528.93	417.773
3532.89	401.174
3536.86	383.591
3540.82	371.4
3544.78	361.002
3548.73	351.084
3552.68	341.694
3556.63	333.706
3560.58	326.825
3564.53	320.132
3568.47	313.93
3572.41	307.717
3576.34	302.945
3580.28	300.299
3584.21	298.676
3588.14	296.206
3592.07	292.328
3595.99	285.578
3599.91	281.813
3603.83	279.208
3607.75	277.669
3611.66	276.482
3615.58	272.972
3619.49	268.622
3623.39	263.586
3627.3	258.29
3631.2	253.311
3635.1	248.977
3638.99	245.038
3642.89	243.45
3646.78	242.563
3650.67	240.779
3654.55	239.128
3658.44	237.783
3662.32	236.494
3666.2	233.725
3670.07	231.798
3673.95	230.406
3677.82	228.038
3681.69	224.325
3685.55	221.231
3689.42	219.54
3693.28	218.834
3697.14	219.566
3700.99	221.98
3704.85	223.905
3708.7	225.376
3712.55	226.179
3716.39	225.315
3720.24	223.181
3724.08	220.817
3727.92	217.934
3731.76	215.35
3735.59	213.008
3739.42	211.43
3743.25	210.447
3747.08	210.408
3750.9	209.881
3754.72	209.122
3758.54	208.256
3762.36	208.852
3766.17	209.867
3769.99	211.471
3773.79	213.022
3777.6	213.219
3781.41	211.905
3785.21	209.114
3789.01	206.46
3792.81	204.722
3796.6	203.759
3800.39	204.002
3804.18	205.029
3807.97	206.201
3811.76	206.496
3815.54	204.847
3819.32	202.492
3823.1	200.846
3826.87	202.648
3830.65	202.192
3834.42	199.15
3838.18	195.337
3841.95	193.482
3845.71	193.074
3849.48	193.48
3853.23	194.232
3856.99	194.923
3860.74	195.415
3864.5	195.783
3868.24	198.635
3871.99	194.128
3875.74	192.142
3879.48	194.998
3883.22	195.299
3886.95	193.784
3890.69	192.132
3894.42	193.785
3898.15	194.753
3901.88	191.216
3905.61	190.825
3909.33	190.656
3913.05	189.836
3916.77	189.615
3920.48	189.347
3924.2	189.509
3927.91	189.587
3931.62	189.047
3935.32	187.833
3939.03	185.83
3942.73	182.867
3946.43	180.309
3950.13	179.07
3953.82	178.9
3957.51	179.655
3961.2	181.004
3964.89	182.446
3968.58	183.197
3972.26	182.741
3975.94	181.189
3979.62	179.839
3983.3	178.947
3986.97	178.5
3990.64	178.062
3994.31	177.584
3997.98	175.378
3999.81	174.137