File: Data/Raman/raw/bertossaite_150 (500nm)_633nm_edge_100%_x50_vis_lwd_h30um_30sx2_01.txt
#Acq. time (s)=	30
#Accumulations=	2
#Range (cm-¹)=	100...4000
#Windows=	1
#Auto scanning=	Off
#Autofocus=	Off
#Macrospot=	Off
#AutoExposure=	Off
#Spike filter=	Multiple accum.
#Delay time (s)=	2
#Binning=	1
#Readout mode=	Signal
#DeNoise=	Standard
#ICS correction=	On
#Dark correction=	Off
#Inst. Process=	Off
#Detector Gain=	Best Dynamic
#Detector ADC=	50 kHz HS
#Detector temperature (°C)=	-60.09
#Instrument=	LabRAM HR Evol
#Detector=	SIN-EM FIVIS
#Objective=	x50_VIS_LWD
#Grating=	150 (500nm)
#ND Filter=	100%
#Laser=	633nm_Edge
#Hole=	30.0125
#Temperature=	0
#Range=	Visible
#StageXY=	75x50mm Scan+
#StageZ=	Z motor
#X (µm)=	0
#Y (µm)=	0
#Z (µm)=	58.5
#Full time(mm:ss)=	1:04
#Project=	21_02_17
#Sample=	BU19w
#Site=
#Title=	BU19w-Area11-bertossaite-bottom_150 (500nm)_633nm_Edge_100%_x50_VIS_LWD_H30um_30sX2
#Remark=
#Date=	17.02.2021 10:27
#Acquired=	17.02.2021 10:27:54
100.724	550.723
107.24	494.379
113.751	472.198
120.256	468.435
126.756	473.544
133.251	476.329
139.74	488.438
146.224	513.609
152.702	523.489
159.175	507.613
165.643	532.639
172.105	676.668
178.561	594.997
185.013	464.458
191.459	434.344
197.9	430.037
204.336	432.3
210.765	429.59
217.19	425.423
223.61	428.581
230.024	449.391
236.432	522.963
242.836	693.234
249.233	714.172
255.627	566.885
262.015	543.489
268.397	551.874
274.774	549.656
281.145	525.284
287.513	538.703
293.873	581.656
300.23	543.185
306.58	496.991
312.927	492.913
319.266	523.431
325.602	634.684
331.932	921.186
338.256	1123.79
344.577	788.511
350.89	589.097
357.199	528.876
363.504	537.391
369.803	567.706
376.096	573.743
382.384	537.565
388.669	480.677
394.947	470.602
401.219	472.811
407.487	475.972
413.75	482.389
420.007	493.731
426.261	523.514
432.508	571.851
438.751	634.185
444.988	687.733
451.22	635.191
457.447	615.745
463.669	658.757
469.886	610.36
476.098	555.134
482.303	516.216
488.505	504.687
494.702	498.917
500.894	501.126
507.081	517.846
513.263	549.122
519.44	582.406
525.61	601.839
531.777	592.594
537.939	575.444
544.096	560.901
550.246	547.41
556.393	532.096
562.535	518.258
568.671	503.261
574.803	487.961
580.929	475.889
587.051	471.669
593.167	473.438
599.28	483.611
605.387	497.518
611.489	513.857
617.585	534.521
623.678	552.308
629.764	561.175
635.847	552.673
641.924	528.091
647.998	488.116
654.065	486.854
660.127	493.16
666.184	493.561
672.238	485.763
678.286	472.343
684.329	456.607
690.367	441.822
696.401	430.656
702.43	422.772
708.453	421.68
714.472	420.71
720.486	419.947
726.495	420.69
732.5	417.578
738.501	415.117
744.495	411.686
750.485	411.323
756.471	412.97
762.451	413.59
768.426	414.808
774.397	415.63
780.363	414.67
786.325	412.988
792.281	411.928
798.234	412.258
804.181	411.515
810.124	410.86
816.06	410.9
821.993	411.319
827.922	412.107
833.846	413.301
839.764	414.618
845.678	416.623
851.588	420.317
857.492	425.473
863.392	432.325
869.287	440.654
875.178	448.317
881.063	454.793
886.945	456.159
892.822	453.564
898.694	451.14
904.56	446.085
910.424	442.584
916.281	440.452
922.135	442.955
927.984	451.18
933.827	467.512
939.668	488.097
945.502	524.54
951.332	580.183
957.159	646.4
962.979	694.471
968.796	673.757
974.607	650.238
980.414	661.672
986.218	725.713
992.016	826.072
997.809	973.132
1003.6	855.23
1009.38	757.627
1015.16	727.839
1020.94	747.204
1026.71	813.458
1032.48	916.316
1038.24	808.684
1043.99	673.611
1049.75	589.232
1055.5	547.901
1061.24	524.611
1066.98	509.795
1072.71	487.924
1078.44	479.892
1084.17	488.827
1089.89	522.778
1095.61	573.665
1101.32	648.455
1107.03	772.001
1112.73	720.899
1118.43	576.061
1124.12	515.08
1129.81	491.492
1135.5	495.464
1141.18	527.358
1146.86	585.299
1152.53	650.256
1158.2	749.97
1163.86	863.675
1169.52	617.05
1175.17	509.227
1180.83	472.603
1186.47	454.982
1192.11	435.22
1197.75	420.184
1203.38	406.963
1209.01	399.913
1214.63	394.715
1220.25	390.517
1225.87	387.962
1231.48	384.048
1237.09	380.047
1242.69	377.344
1248.29	375.17
1253.88	373.804
1259.47	372.911
1265.05	372.285
1270.63	371.704
1276.21	371.34
1281.78	371.038
1287.35	370.68
1292.91	370.678
1298.47	370.631
1304.03	369.678
1309.58	368.8
1315.13	368.129
1320.67	367.901
1326.2	368.142
1331.74	366.433
1337.27	363.097
1342.79	359.853
1348.31	357.032
1353.83	354.496
1359.34	352.493
1364.85	352.702
1370.35	359.61
1375.85	361.214
1381.35	358.998
1386.84	354.118
1392.32	347.739
1397.81	349.034
1403.29	352.225
1408.76	355.581
1414.23	357.681
1419.7	358.679
1425.16	358.306
1430.61	357.008
1436.07	353.037
1441.52	348.829
1446.96	345.179
1452.4	342.139
1457.84	339.801
1463.27	338.348
1468.7	337.817
1474.12	338.729
1479.55	341.399
1484.96	343.063
1490.37	343.343
1495.78	342.581
1501.18	340.885
1506.58	338.298
1511.98	335.217
1517.37	333.111
1522.76	332.29
1528.14	333.869
1533.52	335.947
1538.9	337.195
1544.27	337.775
1549.63	337.306
1555	336.199
1560.35	334.802
1565.71	333.146
1571.06	331.593
1576.41	329.913
1581.75	330.282
1587.09	330.768
1592.42	330.601
1597.75	329.634
1603.08	328.486
1608.4	327.354
1613.72	326.348
1619.03	325.654
1624.34	325.076
1629.65	324.542
1634.95	324.2
1640.25	323.62
1645.54	322.037
1650.83	319.961
1656.12	317.778
1661.4	316.617
1666.68	316.43
1671.96	316.819
1677.23	317.565
1682.49	317.244
1687.75	316.38
1693.01	314.952
1698.27	313.137
1703.52	311.867
1708.77	311.906
1714.01	312.029
1719.25	312.247
1724.48	312.501
1729.71	313.414
1734.94	314.381
1740.16	312.298
1745.38	309.274
1750.6	305.86
1755.81	302.65
1761.02	300.045
1766.22	298.848
1771.42	299.376
1776.62	299.486
1781.81	301.945
1787	304.342
1792.18	305.988
1797.36	305.752
1802.54	304.521
1807.71	302.8
1812.88	298.113
1818.05	296.69
1823.21	295.016
1828.36	295.133
1833.52	296.879
1838.67	297.017
1843.81	296.025
1848.95	295.964
1854.09	295.495
1859.23	294.795
1864.36	293.894
1869.48	292.446
1874.61	291.327
1879.73	292.393
1884.84	293.903
1889.95	292.795
1895.06	290.89
1900.17	288.642
1905.27	286.324
1910.36	283.928
1915.45	281.509
1920.54	279.242
1925.63	277.352
1930.71	276.707
1935.79	276.414
1940.86	277.502
1945.93	279.511
1951	281.046
1956.06	281.603
1961.12	281.495
1966.18	280.384
1971.23	278.788
1976.28	276.817
1981.32	274.597
1986.36	272.471
1991.4	270.276
1996.43	267.617
2001.46	264.867
2006.48	262.168
2011.51	260.202
2016.52	259.164
2021.54	260.305
2026.55	261.66
2031.56	262.861
2036.56	263.833
2041.56	264.421
2046.56	264.491
2051.55	264.233
2056.54	264.408
2061.52	265.314
2066.51	265.418
2071.48	264.82
2076.46	264.409
2081.43	263.163
2086.4	261.595
2091.36	260.287
2096.32	259.281
2101.28	258.422
2106.23	257.709
2111.18	256.995
2116.12	256.414
2121.06	256.224
2126	257.02
2130.94	256.936
2135.87	255.196
2140.79	254.313
2145.72	253.555
2150.64	252.896
2155.56	251.63
2160.47	250.101
2165.38	248.839
2170.28	247.9
2175.19	246.518
2180.09	244.458
2184.98	243.035
2189.87	243.312
2194.76	244.478
2199.65	245.558
2204.53	246.395
2209.4	246.902
2214.28	247.024
2219.15	246.597
2224.02	245.604
2228.88	244.162
2233.74	242.355
2238.6	240.058
2243.45	237.656
2248.3	235.237
2253.14	233.505
2257.99	232.073
2262.83	231.036
2267.66	229.941
2272.49	228.906
2277.32	227.798
2282.15	226.483
2286.97	225.465
2291.79	224.863
2296.6	224.693
2301.41	225.134
2306.22	226.443
2311.02	227.344
2315.83	226.736
2320.62	225.049
2325.42	222.55
2330.21	221.522
2335	221.887
2339.78	222.708
2344.56	224.765
2349.34	225.783
2354.11	225.247
2358.88	223.092
2363.65	219.637
2368.41	215.654
2373.17	213.395
2377.93	212.584
2382.68	213.415
2387.43	217.828
2392.17	221.116
2396.92	222.085
2401.66	221.063
2406.39	217.958
2411.13	214.629
2415.85	212.906
2420.58	211.817
2425.3	211.109
2430.02	211.403
2434.74	212.25
2439.45	212.83
2444.16	212.746
2448.86	211.467
2453.57	210.318
2458.27	209.678
2462.96	208.244
2467.65	206.022
2472.34	203.991
2477.03	203.213
2481.71	203.372
2486.39	204.313
2491.07	205.588
2495.74	206.453
2500.41	205.904
2505.07	208.595
2509.74	209.502
2514.4	209.749
2519.05	207.446
2523.7	205.52
2528.35	204.985
2533	203.814
2537.64	203.204
2542.28	202.837
2546.92	201.663
2551.55	200.235
2556.18	196.921
2560.81	194.778
2565.43	193.238
2570.05	192.316
2574.67	191.914
2579.28	191.786
2583.89	192.154
2588.5	192.682
2593.1	193.28
2597.7	193.802
2602.3	193.869
2606.89	193.333
2611.48	192.575
2616.07	191.33
2620.66	189.72
2625.24	187.973
2629.82	187.138
2634.39	187.334
2638.96	185.776
2643.53	184.61
2648.09	184.34
2652.66	184.735
2657.21	185.517
2661.77	185.923
2666.32	185.689
2670.87	183.955
2675.42	182.311
2679.96	181.539
2684.5	180.901
2689.04	180.286
2693.57	179.924
2698.1	180.874
2702.63	181.505
2707.15	180.769
2711.67	177.647
2716.19	175.062
2720.7	174.122
2725.21	174.718
2729.72	176.254
2734.23	177.78
2738.73	179.22
2743.23	179.834
2747.72	178.955
2752.22	177.801
2756.7	176.394
2761.19	175.425
2765.67	175.011
2770.15	174.92
2774.63	175.041
2779.1	174.836
2783.57	174.435
2788.04	174.689
2792.51	175.949
2796.97	177.06
2801.43	176.708
2805.88	177.213
2810.33	177.452
2814.78	176.592
2819.23	174.562
2823.67	172.555
2828.11	171.723
2832.55	171.257
2836.98	171
2841.41	170.856
2845.84	170.783
2850.26	170.604
2854.69	170.164
2859.1	169.812
2863.52	169.222
2867.93	168.846
2872.34	167.111
2876.75	166.353
2881.15	166.831
2885.55	167.659
2889.95	167.119
2894.34	166.009
2898.73	165.184
2903.12	164.438
2907.5	162.829
2911.89	162.44
2916.27	163.178
2920.64	164.734
2925.01	165.922
2929.38	165.293
2933.75	164.824
2938.12	164.234
2942.48	163.438
2946.84	162.547
2951.19	161.595
2955.54	160.505
2959.89	158.99
2964.24	157.394
2968.58	156.482
2972.92	156.557
2977.26	157.508
2981.59	157.783
2985.92	158.251
2990.25	160.377
2994.58	162.403
2998.9	163.564
3003.22	163.514
3007.54	162.819
3011.85	161.82
3016.16	161.417
3020.47	161.102
3024.77	160.792
3029.07	160.608
3033.37	161.968
3037.67	163.446
3041.96	164.256
3046.25	164.502
3050.54	164.746
3054.82	165.905
3059.11	166.291
3063.38	167.219
3067.66	169.415
3071.93	172.613
3076.2	176.098
3080.47	179.002
3084.73	179.892
3088.99	180.228
3093.25	180.704
3097.51	181.428
3101.76	182.461
3106.01	183.901
3110.26	185.895
3114.5	188.441
3118.74	191.703
3122.98	193.208
3127.22	192.676
3131.45	193.087
3135.68	195.222
3139.91	198.119
3144.13	201.085
3148.35	204.204
3152.57	207.485
3156.78	211.111
3161	215.034
3165.21	219.755
3169.41	224.714
3173.62	229.792
3177.82	233.874
3182.02	237.398
3186.21	240.253
3190.4	242.19
3194.59	242.17
3198.78	242.133
3202.96	243.76
3207.15	245.911
3211.33	245.907
3215.5	243.301
3219.67	240.016
3223.84	235.846
3228.01	231.06
3232.18	225.711
3236.34	222.465
3240.5	216.86
3244.65	209.631
3248.81	202.096
3252.96	194.682
3257.11	189.531
3261.25	186.45
3265.39	185.26
3269.53	184.908
3273.67	183.752
3277.8	181.268
3281.94	177.754
3286.06	173.253
3290.19	167.884
3294.31	162.875
3298.43	160.423
3302.55	159.668
3306.67	160.178
3310.78	161.024
3314.89	161.863
3319	162.999
3323.1	164.851
3327.2	164.769
3331.3	162.184
3335.39	158.63
3339.49	155.081
3343.58	151.865
3347.67	149.522
3351.75	148.759
3355.83	147.938
3359.91	147.282
3363.99	146.808
3368.06	145.259
3372.14	144.098
3376.2	143.815
3380.27	144.013
3384.33	145.108
3388.39	146.325
3392.45	144.782
3396.51	142.557
3400.56	140.307
3404.61	138.119
3408.66	136.948
3412.7	137.376
3416.74	137.713
3420.78	137.512
3424.82	136.924
3428.85	135.729
3432.88	134.225
3436.91	132.68
3440.94	130.717
3444.96	128.148
3448.98	125.502
3453	125.332
3457.02	125.175
3461.03	125.582
3465.04	126.119
3469.05	125.657
3473.05	126.798
3477.05	127.45
3481.05	127.724
3485.05	127.937
3489.04	126.235
3493.04	122.043
3497.03	120.467
3501.01	119.8
3505	121.053
3508.98	122.809
3512.96	124.38
3516.93	126.003
3520.9	126.903
3524.88	125.835
3528.84	123.331
3532.81	120.794
3536.77	118.342
3540.73	116.975
3544.69	117.288
3548.65	119.002
3552.6	121.154
3556.55	123.048
3560.5	124.399
3564.44	124.792
3568.38	124.907
3572.32	125.432
3576.26	126.473
3580.2	127.883
3584.13	130.291
3588.06	131.754
3591.98	131.529
3595.91	130.304
3599.83	127.189
3603.75	123.203
3607.67	120.601
3611.58	119.266
3615.49	118.812
3619.4	118.781
3623.31	118.008
3627.21	115.465
3631.11	112.587
3635.01	109.224
3638.91	105.703
3642.8	103.941
3646.69	103.774
3650.58	105.244
3654.47	107.542
3658.35	109.202
3662.24	109.642
3666.11	108.77
3669.99	106.656
3673.86	105.259
3677.74	105.172
3681.6	105.328
3685.47	104.353
3689.34	103.328
3693.2	102.747
3697.06	102.552
3700.91	102.588
3704.77	102.887
3708.62	103.396
3712.47	104.395
3716.31	104.783
3720.16	104.256
3724	103.191
3727.84	102.454
3731.67	103.098
3735.51	104.114
3739.34	103.946
3743.17	104.817
3747	106.022
3750.82	106.824
3754.64	106.783
3758.46	106.362
3762.28	105.682
3766.09	104.814
3769.9	103.884
3773.71	103.154
3777.52	102.586
3781.33	102.92
3785.13	103.175
3788.93	102.758
3792.72	100.748
3796.52	98.8477
3800.31	97.1976
3804.1	95.2637
3807.89	94.6601
3811.68	95.3668
3815.46	97.1816
3819.24	99.0871
3823.02	100.716
3826.79	101.722
3830.56	101.9
3834.34	101.758
3838.1	101.283
3841.87	101.087
3845.63	101.504
3849.39	101.762
3853.15	101.761
3856.91	101.464
3860.66	100.811
3864.42	100.056
3868.16	99.8889
3871.91	100.226
3875.66	100.488
3879.4	100.641
3883.14	100.359
3886.88	99.1383
3890.61	97.6437
3894.34	96.0591
3898.07	94.6868
3901.8	93.6512
3905.53	92.9158
3909.25	92.5246
3912.97	92.3519
3916.69	92.5903
3920.4	93.1704
3924.12	93.8905
3927.83	94.8554
3931.54	94.827
3935.24	94.2894
3938.95	93.7537
3942.65	93.1983
3946.35	92.7593
3950.05	92.5886
3953.74	92.5883
3957.44	92.4911
3961.13	92.7184
3964.81	93.0602
3968.5	93.4432
3972.18	93.8464
3975.86	93.0539
3979.54	92.4439
3983.22	92.1973
3986.89	92.5937
3990.56	93.2405
3994.23	92.9969
3997.9	94.9933
3999.73	97.3848