File: Data/Raman/raw/beryl_150 (500nm)_633nm_Edge_100%_x50_VIS_LWD_H100um_15sx2.txt
#Acq. time (s)=	15
#Accumulations=	2
#Range (cm-¹)=	100...4000
#Windows=	1
#Auto scanning=	Off
#Autofocus=	Off
#Macrospot=	Off
#AutoExposure=	Off
#Spike filter=	Multiple accum.
#Delay time (s)=	0
#Binning=	1
#Readout mode=	Signal
#DeNoise=	Standard
#ICS correction=	On
#Dark correction=	Off
#Inst. Process=	On
#Detector Gain=	Best Dynamic
#Detector ADC=	50 kHz HS
#Detector temperature (°C)=	-60.09
#Instrument=	LabRAM HR Evol
#Detector=	SIN-EM FIVIS
#Objective=	x50_VIS_LWD
#Grating=	150 (500nm)
#ND Filter=	100%
#Laser=	633nm_Edge
#Hole=	100.021
#Temperature=	0
#Range=	Visible
#StageXY=	75x50mm Scan+
#StageZ=	Z motor
#X (µm)=	0
#Y (µm)=	0
#Z (µm)=	875.9
#Project=	20_09_03
#Sample=	BU18FA12
#Site=
#Title=	BU12-mineralA-3_150 (500nm)_633nm_Edge_100%_x50_VIS_LWD_H100um_15sx2
#Remark=
#Date=	03.09.2020 11:22
#Acquired=	03.09.2020 11:22:12
100.474	1879.27
106.99	1881.25
113.501	1899.13
120.007	1915.69
126.507	1930.93
133.002	1945.37
139.491	1952.94
145.975	1946.71
152.454	1929.6
158.927	1893.1
165.395	1877.42
171.858	1871.86
178.315	1874.49
184.765	1878.47
191.212	1880.37
197.653	1886.81
204.089	1884.82
210.52	1879.17
216.944	1868.82
223.364	1860.14
229.779	1854.16
236.187	1852.58
242.591	1855.05
248.99	1847.88
255.382	1839.5
261.77	1830
268.152	1820.99
274.53	1813.82
280.903	1806.17
287.269	1814.04
293.631	1830.86
299.987	1825.53
306.338	1822.04
312.684	1829.31
319.024	1872.88
325.36	2008.14
331.689	1864.97
338.015	1787.91
344.335	1762.51
350.649	1753.26
356.959	1748.94
363.263	1739.42
369.561	1735.67
375.855	1737.26
382.145	1747.25
388.428	1791.37
394.706	1962.02
400.979	2230.57
407.247	1973.85
413.511	1817.09
419.769	1816.83
426.022	1833.9
432.269	1783.74
438.512	1775.21
444.749	1782.94
450.981	1781.22
457.209	1756.66
463.431	1720.06
469.648	1700.03
475.86	1687.11
482.067	1678.39
488.269	1681.66
494.465	1683
500.657	1680.56
506.844	1677.88
513.026	1679.49
519.203	1696.32
525.375	1735.38
531.541	1741.9
537.703	1737.48
543.86	1698.1
550.011	1671.89
556.158	1658.2
562.3	1656.85
568.436	1658.26
574.568	1662.05
580.696	1670.65
586.817	1677.02
592.934	1677.27
599.046	1670.88
605.153	1659.58
611.255	1646.7
617.353	1632.31
623.444	1619.44
629.533	1609.61
635.614	1602
641.691	1596.51
647.765	1595.73
653.832	1600.19
659.895	1607.94
665.954	1625.02
672.006	1634.36
678.054	1722.59
684.097	2225.04
690.137	2654.63
696.17	2024.63
702.199	1746.62
708.222	1669.39
714.241	1625.72
720.256	1600.41
726.266	1578.28
732.271	1572.82
738.271	1568.99
744.266	1571.57
750.256	1571.86
756.241	1572.57
762.222	1574.78
768.198	1604.31
774.169	1626.69
780.136	1611.3
786.096	1599.85
792.053	1586.52
798.005	1574.45
803.953	1563.22
809.896	1552.22
815.834	1546.64
821.766	1544.02
827.695	1548.95
833.619	1557.76
839.537	1567.91
845.452	1576.3
851.362	1579.41
857.266	1577.35
863.166	1570.2
869.062	1563.12
874.952	1560.44
880.839	1559.12
886.72	1560
892.597	1563.54
898.469	1570.17
904.337	1579.73
910.199	1584.58
916.058	1587.03
921.911	1589.31
927.76	1590.47
933.605	1581.69
939.444	1580.26
945.279	1581.04
951.11	1583.81
956.935	1586.26
962.756	1579.56
968.573	1577.02
974.386	1579.04
980.193	1585.51
985.996	1596.43
991.794	1616.32
997.587	1633.77
1003.38	1677.87
1009.16	1727.46
1014.94	1766.34
1020.72	1738.36
1026.49	1684.63
1032.25	1654.68
1038.02	1637.82
1043.77	1634.88
1049.53	1640.74
1055.28	1665.92
1061.02	1703.14
1066.76	1730.73
1072.49	1747.03
1078.22	1727.7
1083.95	1706.64
1089.67	1682.48
1095.39	1660.71
1101.1	1641.96
1106.81	1640.16
1112.51	1640.7
1118.21	1646.39
1123.91	1656.93
1129.6	1668.8
1135.28	1678.87
1140.96	1685.58
1146.64	1685.55
1152.31	1682.86
1157.98	1667.75
1163.64	1662.94
1169.3	1664.95
1174.96	1672.7
1180.61	1677.78
1186.25	1681.37
1191.9	1691.06
1197.53	1698.5
1203.17	1705.53
1208.8	1713.58
1214.42	1723.11
1220.04	1733.8
1225.65	1745.4
1231.27	1757.55
1236.87	1769.29
1242.47	1779.32
1248.07	1779.76
1253.67	1768.01
1259.26	1751.46
1264.84	1732.55
1270.42	1717.65
1276	1707.92
1281.57	1703.74
1287.14	1706.36
1292.7	1716.35
1298.26	1725.95
1303.81	1734.28
1309.37	1739.5
1314.91	1739.04
1320.45	1736.07
1325.99	1732.14
1331.53	1729.32
1337.05	1728.54
1342.58	1730.1
1348.1	1733.94
1353.62	1739.6
1359.13	1740.7
1364.64	1740.93
1370.14	1740.55
1375.64	1738.96
1381.14	1735.65
1386.63	1730.66
1392.12	1726.18
1397.6	1724.74
1403.08	1725.61
1408.55	1726.81
1414.02	1727.73
1419.49	1728.26
1424.95	1728.15
1430.41	1727.25
1435.86	1725.29
1441.31	1722.05
1446.75	1720.02
1452.2	1719.34
1457.63	1719.38
1463.06	1719.74
1468.49	1720.45
1473.92	1721.91
1479.34	1724.39
1484.75	1727.5
1490.17	1730.62
1495.57	1732.74
1500.98	1736.12
1506.38	1744.73
1511.77	1744.19
1517.16	1741.06
1522.55	1738.77
1527.94	1736.72
1533.31	1734.18
1538.69	1730.97
1544.06	1730.87
1549.43	1731.47
1554.79	1730.51
1560.15	1728.16
1565.5	1725.91
1570.85	1724.14
1576.2	1723.45
1581.54	1723.28
1586.88	1723.23
1592.22	1723.18
1597.55	1723.02
1602.87	1722.43
1608.2	1721.59
1613.51	1720.44
1618.83	1719.13
1624.14	1717.69
1629.45	1716.23
1634.75	1714.81
1640.05	1713.91
1645.34	1713.01
1650.63	1712.51
1655.92	1712.47
1661.2	1712.25
1666.48	1710.47
1671.75	1704.16
1677.02	1696.03
1682.29	1687.89
1687.55	1677.71
1692.81	1673.15
1698.07	1677.08
1703.32	1684.82
1708.56	1688.74
1713.81	1688.07
1719.05	1682.49
1724.28	1680.46
1729.51	1686.41
1734.74	1685.73
1739.96	1683.36
1745.18	1678.59
1750.4	1673.39
1755.61	1669.19
1760.82	1665.72
1766.02	1662.74
1771.22	1660.13
1776.42	1657.78
1781.61	1655.62
1786.8	1654
1791.98	1652.6
1797.16	1651.28
1802.34	1649.25
1807.51	1647.02
1812.68	1644.43
1817.85	1641.51
1823.01	1638.38
1828.17	1635.19
1833.32	1637.54
1838.47	1635.29
1843.62	1632.55
1848.76	1621.01
1853.9	1602.59
1859.03	1593.72
1864.16	1599.69
1869.29	1607.52
1874.41	1610.85
1879.53	1603.95
1884.65	1596.23
1889.76	1590.6
1894.87	1588.55
1899.97	1587.42
1905.07	1587.04
1910.17	1587.71
1915.26	1587.05
1920.35	1581.48
1925.43	1577.66
1930.52	1575.26
1935.59	1574.06
1940.67	1575.59
1945.74	1576.19
1950.8	1574.69
1955.87	1570.9
1960.93	1565.01
1965.98	1556.77
1971.03	1547.37
1976.08	1539.84
1981.13	1534.56
1986.17	1530.76
1991.2	1527.81
1996.24	1523.39
2001.27	1523.59
2006.29	1530.56
2011.31	1540.44
2016.33	1545.57
2021.35	1532.23
2026.36	1519.24
2031.36	1507.56
2036.37	1499.58
2041.37	1495.6
2046.37	1495.09
2051.36	1497.77
2056.35	1502.47
2061.33	1506.85
2066.31	1509.85
2071.29	1512.15
2076.27	1511.46
2081.24	1507.5
2086.21	1502.87
2091.17	1497.26
2096.13	1490.86
2101.08	1483.88
2106.04	1477.39
2110.99	1472.48
2115.93	1468.08
2120.88	1463.75
2125.81	1459.72
2130.75	1457.1
2135.68	1457.26
2140.61	1454.21
2145.53	1449.77
2150.45	1447.15
2155.37	1445.18
2160.28	1442.2
2165.19	1438.36
2170.1	1436.7
2175	1436.19
2179.9	1435.55
2184.79	1433.56
2189.69	1428.78
2194.57	1426.56
2199.46	1427.45
2204.34	1427.72
2209.22	1427.33
2214.09	1427.12
2218.96	1428.54
2223.83	1429.62
2228.69	1428.99
2233.55	1426.29
2238.41	1420.6
2243.26	1414.44
2248.11	1409.22
2252.96	1405.17
2257.8	1401.58
2262.64	1398.29
2267.48	1395.21
2272.31	1391.99
2277.14	1388.97
2281.96	1386.18
2286.78	1384.19
2291.6	1382.28
2296.42	1380.43
2301.23	1377.9
2306.04	1375.33
2310.84	1372.55
2315.64	1369.56
2320.44	1366.36
2325.23	1362.99
2330.02	1359.44
2334.81	1355.66
2339.6	1351.62
2344.38	1347.32
2349.15	1342.75
2353.93	1337.88
2358.7	1333.93
2363.46	1332.24
2368.23	1332.13
2372.99	1331.8
2377.74	1329.37
2382.5	1326.16
2387.25	1323.8
2391.99	1320.98
2396.73	1316.51
2401.47	1311.4
2406.21	1309.35
2410.94	1309.8
2415.67	1312.56
2420.4	1315.61
2425.12	1319.94
2429.84	1324.39
2434.56	1326.46
2439.27	1324.11
2443.98	1315.77
2448.68	1309.16
2453.39	1305.6
2458.09	1302.34
2462.78	1299.12
2467.47	1295.78
2472.16	1292.2
2476.85	1288.32
2481.53	1284.08
2486.21	1279.5
2490.89	1277.51
2495.56	1278.91
2500.23	1280.21
2504.89	1280.88
2509.56	1279.3
2514.22	1274.96
2518.87	1269.83
2523.53	1264.77
2528.18	1260.74
2532.82	1257.22
2537.46	1254.04
2542.1	1250.36
2546.74	1246.49
2551.37	1242.64
2556	1238.95
2560.63	1235.52
2565.25	1232.44
2569.87	1229.94
2574.49	1228.24
2579.1	1230.11
2583.71	1231.11
2588.32	1230.06
2592.93	1228.39
2597.53	1226.23
2602.12	1223.85
2606.72	1221.52
2611.31	1219.44
2615.9	1216.96
2620.48	1214.31
2625.06	1211.48
2629.64	1208.46
2634.21	1206.96
2638.79	1205.81
2643.35	1204.72
2647.92	1203.55
2652.48	1201.55
2657.04	1197.5
2661.6	1192.36
2666.15	1186.72
2670.7	1181.76
2675.24	1178.11
2679.79	1175.67
2684.33	1171.99
2688.86	1169.14
2693.4	1168.55
2697.93	1161.87
2702.45	1154.71
2706.98	1152.68
2711.5	1153.76
2716.02	1156.16
2720.53	1160.56
2725.04	1158.08
2729.55	1151.8
2734.05	1137.52
2738.56	1125.27
2743.05	1116.48
2747.55	1123.24
2752.04	1127.29
2756.53	1126.68
2761.02	1127
2765.5	1128.11
2769.98	1127.47
2774.46	1131.64
2778.93	1135.79
2783.4	1140.65
2787.87	1153.65
2792.34	1159.98
2796.8	1156.1
2801.26	1142.89
2805.71	1120.94
2810.16	1106.06
2814.61	1110.11
2819.06	1115.31
2823.5	1119.26
2827.94	1106.94
2832.38	1096.66
2836.81	1096.62
2841.24	1100.96
2845.67	1103.67
2850.09	1104.82
2854.52	1104.4
2858.93	1097.79
2863.35	1090.25
2867.76	1085.66
2872.17	1083.44
2876.58	1082.63
2880.98	1082.69
2885.38	1083.28
2889.78	1084.72
2894.17	1086.01
2898.56	1083.78
2902.95	1078.77
2907.34	1076.41
2911.72	1075.45
2916.1	1073.99
2920.47	1072.13
2924.85	1070.06
2929.22	1067.77
2933.58	1065.24
2937.95	1062.45
2942.31	1059.4
2946.67	1055.44
2951.02	1053.76
2955.38	1055.42
2959.72	1055.26
2964.07	1054.67
2968.41	1067.05
2972.75	1055.92
2977.09	1041.35
2981.43	1039.25
2985.76	1033.71
2990.09	1033.89
2994.41	1029.37
2998.73	1037.89
3003.05	1050.19
3007.37	1048.23
3011.68	1039.96
3015.99	1030.06
3020.3	1024.27
3024.61	1021.01
3028.91	1019.71
3033.21	1018.76
3037.51	1016.47
3041.8	1012.19
3046.09	1007.3
3050.38	1004.19
3054.66	1003.57
3058.94	1005.01
3063.22	1007.45
3067.5	1008.9
3071.77	1008.59
3076.04	1005.07
3080.31	1000.97
3084.57	999.086
3088.83	998.777
3093.09	999.356
3097.35	1000.06
3101.6	999.981
3105.85	998.643
3110.09	995.863
3114.34	992.037
3118.58	987.578
3122.82	982.76
3127.05	978.318
3131.29	974.058
3135.52	970.473
3139.74	969.514
3143.97	972.141
3148.19	977.082
3152.41	979.811
3156.62	978.498
3160.83	974.467
3165.04	969.116
3169.25	963.883
3173.45	959.779
3177.66	957.079
3181.85	955.984
3186.05	956.253
3190.24	957.48
3194.43	957.901
3198.62	956.764
3202.81	953.995
3206.99	949.978
3211.17	945.547
3215.34	942.08
3219.51	939.657
3223.69	938.076
3227.85	937.53
3232.02	937.022
3236.18	934.659
3240.34	933.186
3244.49	931.804
3248.65	930.32
3252.8	930.05
3256.95	932.653
3261.09	934.263
3265.24	931.969
3269.38	925.68
3273.51	914.794
3277.65	905.699
3281.78	902.166
3285.91	904.353
3290.03	910.129
3294.16	917.993
3298.28	921.669
3302.39	920.137
3306.51	912.161
3310.62	900.325
3314.73	892.403
3318.84	887.343
3322.94	885.34
3327.04	886.302
3331.14	889.469
3335.24	892.52
3339.33	892.736
3343.42	890.901
3347.51	889.607
3351.59	888.719
3355.68	892.398
3359.76	890.622
3363.83	882.155
3367.91	875.367
3371.98	870.773
3376.05	868.797
3380.11	869.783
3384.18	873.627
3388.24	874.916
3392.3	873.232
3396.35	868.259
3400.4	860.997
3404.45	855.87
3408.5	852.986
3412.55	852.413
3416.59	854.485
3420.63	860.837
3424.66	864.774
3428.7	865.132
3432.73	862.11
3436.76	854.589
3440.79	848.774
3444.81	846.15
3448.83	845.521
3452.85	846.974
3456.86	850.152
3460.88	850.898
3464.89	849.482
3468.89	846.541
3472.9	851.804
3476.9	853.13
3480.9	854.484
3484.9	853.075
3488.89	839.634
3492.88	830.414
3496.87	826.836
3500.86	825.656
3504.84	825.468
3508.82	825.74
3512.8	825.706
3516.78	825.171
3520.75	824.015
3524.72	822.245
3528.69	819.856
3532.66	816.859
3536.62	813.236
3540.58	808.917
3544.54	803.792
3548.49	800.041
3552.45	800.187
3556.4	801.819
3560.34	804.188
3564.29	806.817
3568.23	807.159
3572.17	804.864
3576.11	802.779
3580.04	800.955
3583.98	803.193
3587.91	810.879
3591.83	823.597
3595.76	846.929
3599.68	902.476
3603.6	961.915
3607.52	1202.41
3611.43	1408.92
3615.34	968.461
3619.25	836.168
3623.16	802.277
3627.06	793.66
3630.96	786.744
3634.86	784.343
3638.76	780.633
3642.65	780.676
3646.55	777.256
3650.44	774.034
3654.32	771.686
3658.21	769.674
3662.09	766.778
3665.97	765.754
3669.84	767.765
3673.72	770.013
3677.59	771.382
3681.46	771.9
3685.32	766.004
3689.19	769.057
3693.05	769.354
3696.91	766.247
3700.76	760.321
3704.62	753.636
3708.47	747.619
3712.32	744.081
3716.16	739.743
3720.01	733.694
3723.85	730.282
3727.69	731.989
3731.53	735.84
3735.36	740.703
3739.19	742.941
3743.02	741.48
3746.85	738.871
3750.67	736.698
3754.49	732.594
3758.31	729.827
3762.13	726.412
3765.95	727.708
3769.76	724.922
3773.57	720.26
3777.37	717.872
3781.18	718.2
3784.98	719.139
3788.78	719.635
3792.58	719.765
3796.37	719.377
3800.17	718.192
3803.96	715.937
3807.74	713.314
3811.53	711.952
3815.31	709.562
3819.09	702.539
3822.87	693.961
3826.65	688.5
3830.42	685.826
3834.19	684.248
3837.96	683.805
3841.73	685.957
3845.49	687.964
3849.25	688.142
3853.01	686.836
3856.77	683.471
3860.52	679.776
3864.27	679.704
3868.02	679.565
3871.77	672.501
3875.51	668.664
3879.25	670.944
3882.99	676.36
3886.73	674.531
3890.47	669.292
3894.2	664.668
3897.93	660.431
3901.66	656.605
3905.38	653.237
3909.11	650.454
3912.83	648.355
3916.55	644.254
3920.26	638.023
3923.98	633.3
3927.69	631.069
3931.4	632.399
3935.1	637.212
3938.81	641.021
3942.51	643.1
3946.21	643.559
3949.91	641.898
3953.6	638.704
3957.29	635.153
3960.98	632.133
3964.67	629.228
3968.36	626.559
3972.04	624.185
3975.72	622.133
3979.4	620.405
3983.08	619.098
3986.75	617.907
3990.42	611.244
3994.09	606.018
3997.76	601.645
3999.59	599.914