File: Data/Raman/raw/bu02a-area1-top-rutile-opaq_150 (500nm)_633nm_edge_50%_x50_vis_lwd_h100um_10sx2_01.txt
#Acq. time (s)=	10
#Accumulations=	2
#Range (cm-¹)=	100...4000
#Windows=	1
#Auto scanning=	Off
#Autofocus=	Off
#Macrospot=	Off
#AutoExposure=	Off
#Spike filter=	Multiple accum.
#Delay time (s)=	1
#Binning=	1
#Readout mode=	Signal
#DeNoise=	Standard
#ICS correction=	On
#Dark correction=	Off
#Inst. Process=	Off
#Detector Gain=	Best Dynamic
#Detector ADC=	50 kHz HS
#Detector temperature (°C)=	-60.09
#Instrument=	LabRAM HR Evol
#Detector=	SIN-EM FIVIS
#Objective=	x50_VIS_LWD
#Grating=	150 (500nm)
#ND Filter=	50%
#Laser=	633nm_Edge
#Hole=	100.021
#Temperature=	0
#Range=	Visible
#StageXY=	75x50mm Scan+
#StageZ=	Z motor
#X (µm)=	0
#Y (µm)=	0
#Z (µm)=	-149.4
#Full time(s)=	25
#Project=	20_10_20
#Sample=	BU18FA02a
#Site=
#Title=	BU02a-Area1-top-opaq_150 (500nm)_633nm_Edge_50%_x50_VIS_LWD_H100um_10sX2
#Remark=
#Date=	20.10.2020 16:54
#Acquired=	20.10.2020 16:54:56
100.676	2327.56
107.192	2418.53
113.703	2471.5
120.208	2495.73
126.708	2487.37
133.203	2522.06
139.692	2769.26
146.176	2472.22
152.654	2235.73
159.127	2185.65
165.595	2240.03
172.058	2376.3
178.515	2586.77
184.966	2861.3
191.411	3159.4
197.852	3446.81
204.288	3738.31
210.719	3990.07
217.142	4187.59
223.562	4353.4
229.977	4465.91
236.386	4483.84
242.789	4436.13
249.188	4304.7
255.58	4118.73
261.968	3906.87
268.351	3701.81
274.727	3503.66
281.1	3340.95
287.466	3201.57
293.828	3123.64
300.183	3080.8
306.535	3075.33
312.88	3100.54
319.221	3146.42
325.556	3203.99
331.885	3256.92
338.211	3319.21
344.53	3374.54
350.844	3436.65
357.154	3480.57
363.458	3523.52
369.756	3560.92
376.051	3617.42
382.339	3738.5
388.622	3972.46
394.9	4287.69
401.173	4743.82
407.442	5375.37
413.705	6233.16
419.962	7315.9
426.215	8573.2
432.462	9698.03
438.705	10421.6
444.942	10389.1
451.174	9277.33
457.401	7583.88
463.623	5975.95
469.84	4805.3
476.052	4036.09
482.259	3539.48
488.461	3192.2
494.658	3002.86
500.848	2873.98
507.035	2784.7
513.217	2731.2
519.394	2688.65
525.566	2648.33
531.731	2639.11
537.893	2634.72
544.05	2665.93
550.202	2735.85
556.348	2858.3
562.49	3044.98
568.626	3302.42
574.758	3655.12
580.885	4050.57
587.006	4558.67
593.124	5154.61
599.235	5828.76
605.342	6415.26
611.444	6600.8
617.541	6291.25
623.633	5576.76
629.721	4672.09
635.803	3882.69
641.879	3280.12
647.953	2904.6
654.02	2610.02
660.083	2415.49
666.141	2289.39
672.193	2187.45
678.241	2100.55
684.285	2025.48
690.324	1995.93
696.357	1928.58
702.385	1832.32
708.409	1726.42
714.428	1627.47
720.443	1538.51
726.452	1447.86
732.457	1369.26
738.456	1299.29
744.451	1243.26
750.441	1186.58
756.427	1141.4
762.407	1104.92
768.383	1076.5
774.354	1051.82
780.32	1030.71
786.282	1014.55
792.237	1004.26
798.19	997.611
804.137	991.279
810.08	982.991
816.018	974.842
821.95	960.473
827.878	940.815
833.802	917.047
839.721	878.364
845.635	829.579
851.544	773.324
857.448	715.617
863.349	656.927
869.245	607.534
875.135	568.071
881.021	544
886.902	523.731
892.779	509.466
898.65	497.893
904.518	487.119
910.38	475.492
916.239	463.341
922.092	454.087
927.94	445.458
933.785	437.505
939.625	429.727
945.459	421.606
951.29	413.513
957.116	403.997
962.936	395.329
968.753	386.41
974.566	377.245
980.373	367.426
986.175	359.314
991.973	352.342
997.767	345.712
1003.56	339.221
1009.34	332.723
1015.12	327.007
1020.9	322.555
1026.67	316.716
1032.43	310.184
1038.19	303.369
1043.95	298.382
1049.7	294.878
1055.45	291.482
1061.2	288.27
1066.94	285.266
1072.67	282.879
1078.4	278.505
1084.13	273.869
1089.85	269.338
1095.57	265.119
1101.28	262.093
1106.98	260.32
1112.69	259.636
1118.39	260.185
1124.08	262.126
1129.77	263.198
1135.46	262.576
1141.14	261.086
1146.82	259.585
1152.49	258.527
1158.16	258.089
1163.82	257.419
1169.48	256.38
1175.13	255.993
1180.78	255.281
1186.43	252.749
1192.07	250.605
1197.71	248.387
1203.34	246.069
1208.97	244.908
1214.59	245.01
1220.21	246.611
1225.83	247.569
1231.44	247.997
1237.05	248.147
1242.65	247.749
1248.25	245.967
1253.84	243.735
1259.43	241.709
1265.01	241.184
1270.59	241.633
1276.17	242.084
1281.74	241.391
1287.31	242.49
1292.87	243.075
1298.43	242.92
1303.99	242.612
1309.54	241.161
1315.08	239.233
1320.63	237.062
1326.16	235.799
1331.7	233.652
1337.23	231.67
1342.75	230.459
1348.27	230.602
1353.79	231.199
1359.3	230.863
1364.81	230.82
1370.31	231.349
1375.81	231.768
1381.31	230.483
1386.8	227.918
1392.29	225.035
1397.77	221.663
1403.25	217.777
1408.72	214.018
1414.19	219.296
1419.66	218.992
1425.12	220.755
1430.58	222.982
1436.03	222.051
1441.48	221.318
1446.92	222.205
1452.36	223.847
1457.8	226.408
1463.23	229.086
1468.66	230.878
1474.09	231.789
1479.51	231.8
1484.92	232.464
1490.33	232.933
1495.74	232.753
1501.14	232.855
1506.54	233.669
1511.94	234.531
1517.33	234.68
1522.72	234.696
1528.1	236.727
1533.48	237.659
1538.86	238.105
1544.23	238.265
1549.59	238.37
1554.96	238.792
1560.32	238.655
1565.67	238.256
1571.02	238.251
1576.37	238.969
1581.71	239.648
1587.05	240.224
1592.38	240.933
1597.71	239.147
1603.04	244.208
1608.36	253.261
1613.68	228.079
1618.99	231.088
1624.3	227.798
1629.61	229.223
1634.91	228.307
1640.21	224.883
1645.51	219.085
1650.8	215.292
1656.08	210.035
1661.36	206.043
1666.64	201.835
1671.92	197.813
1677.19	194.882
1682.45	192.676
1687.72	190.328
1692.98	188.911
1698.23	187.284
1703.48	185.347
1708.73	183.164
1713.97	180.791
1719.21	178.399
1724.44	176.347
1729.67	174.786
1734.9	173.984
1740.12	173.882
1745.34	174.313
1750.56	174.449
1755.77	173.419
1760.98	171.525
1766.18	169.37
1771.38	167.705
1776.58	166.653
1781.77	166.1
1786.96	166.84
1792.14	168.207
1797.32	169.876
1802.5	170.853
1807.67	171.351
1812.84	171.643
1818.01	171.719
1823.17	170.889
1828.33	169.323
1833.48	167.344
1838.63	165.363
1843.77	163.601
1848.92	161.99
1854.06	160.324
1859.19	160.273
1864.32	162.149
1869.45	165.365
1874.57	168.409
1879.69	170.21
1884.8	168.672
1889.92	167.64
1895.02	167.175
1900.13	166.994
1905.23	167.358
1910.33	167.158
1915.42	167.415
1920.51	167.54
1925.59	166.172
1930.67	164.13
1935.75	162.408
1940.82	162.137
1945.9	162.2
1950.96	162.297
1956.02	162.371
1961.08	162.386
1966.14	162.372
1971.19	162.256
1976.24	161.995
1981.28	161.513
1986.32	160.862
1991.36	162.127
1996.39	163.625
2001.42	164.836
2006.45	165.611
2011.47	165.975
2016.49	165.983
2021.5	165.601
2026.51	165.016
2031.52	164.708
2036.52	164.11
2041.52	161.28
2046.52	158.596
2051.51	157.183
2056.5	157.707
2061.49	158.206
2066.47	159.039
2071.45	159.801
2076.42	159.931
2081.39	159.805
2086.36	159.749
2091.32	159.438
2096.28	159.352
2101.24	159.397
2106.19	160.094
2111.14	160.003
2116.09	158.574
2121.03	157.422
2125.97	157.166
2130.9	158.097
2135.83	159.126
2140.76	159.886
2145.68	159.299
2150.6	159.102
2155.52	157.861
2160.43	156.294
2165.34	155.023
2170.25	154.763
2175.15	154.806
2180.05	154.928
2184.95	155.029
2189.84	154.953
2194.73	154.797
2199.61	154.612
2204.49	154.379
2209.37	154.072
2214.24	153.637
2219.11	153.186
2223.98	152.738
2228.84	152.272
2233.7	151.844
2238.56	151.661
2243.41	151.876
2248.26	151.901
2253.11	151.885
2257.95	151.579
2262.79	150.792
2267.63	149.962
2272.46	149.206
2277.29	148.52
2282.11	147.958
2286.93	147.752
2291.75	147.597
2296.57	147.583
2301.38	147.892
2306.19	148.377
2310.99	149.395
2315.79	150.48
2320.59	151.499
2325.38	152.346
2330.17	151.997
2334.96	150.83
2339.74	149.412
2344.52	147.957
2349.3	146.613
2354.07	146.253
2358.84	146.359
2363.61	146.962
2368.37	147.935
2373.13	149.057
2377.89	149.634
2382.64	150.891
2387.39	149.631
2392.14	147.654
2396.88	145.475
2401.62	146.387
2406.36	146.084
2411.09	145.979
2415.82	144.358
2420.55	142.676
2425.27	142.042
2429.99	142.153
2434.7	142.817
2439.42	143.91
2444.12	145.421
2448.83	147.307
2453.53	149.314
2458.23	151.517
2462.93	152.448
2467.62	152.432
2472.31	151.777
2476.99	150.211
2481.68	147.565
2486.36	145.572
2491.03	145.301
2495.7	146.156
2500.37	146.977
2505.04	147.732
2509.7	147.811
2514.36	147.564
2519.02	147.057
2523.67	146.423
2528.32	145.398
2532.97	144.292
2537.61	143.165
2542.25	142.173
2546.88	141.306
2551.52	140.654
2556.15	140.611
2560.77	140.732
2565.4	141.033
2570.02	141.495
2574.63	142.41
2579.25	142.516
2583.86	142.231
2588.46	141.921
2593.07	141.858
2597.67	141.747
2602.27	141.648
2606.86	141.129
2611.45	140.34
2616.04	140.4
2620.62	139.707
2625.2	138.102
2629.78	137.648
2634.36	137.504
2638.93	137.509
2643.5	137.544
2648.06	137.517
2652.62	137.33
2657.18	137.204
2661.74	137.066
2666.29	136.943
2670.84	136.834
2675.38	136.733
2679.93	136.67
2684.47	136.641
2689	136.664
2693.54	136.707
2698.07	136.751
2702.59	136.711
2707.12	136.582
2711.64	136.388
2716.16	135.945
2720.67	135.645
2725.18	137.209
2729.69	138.3
2734.19	138.616
2738.7	138.521
2743.19	138.324
2747.69	137.908
2752.18	137.379
2756.67	136.803
2761.16	136.238
2765.64	135.667
2770.12	135.124
2774.6	134.524
2779.07	133.973
2783.54	133.488
2788.01	133.066
2792.47	132.545
2796.94	132.397
2801.39	132.355
2805.85	132.463
2810.3	132.624
2814.75	133.058
2819.2	133.16
2823.64	133.248
2828.08	132.882
2832.52	132.627
2836.95	132.497
2841.38	132.445
2845.81	132.493
2850.23	132.574
2854.65	132.899
2859.07	133
2863.49	133.057
2867.9	132.704
2872.31	131.615
2876.71	130.579
2881.12	129.504
2885.52	128.553
2889.91	128.362
2894.31	128.352
2898.7	128.633
2903.09	129.226
2907.47	129.931
2911.86	131
2916.23	132.185
2920.61	133.322
2924.98	133.92
2929.35	133.786
2933.72	132.35
2938.08	129.895
2942.45	127.557
2946.8	125.725
2951.16	124.657
2955.51	124.241
2959.86	124.47
2964.21	125.268
2968.55	126.656
2972.89	128.777
2977.23	131.279
2981.56	131.389
2985.89	126.136
2990.22	124.662
2994.55	124.225
2998.87	124.589
3003.19	125.253
3007.5	125.773
3011.82	125.732
3016.13	125.141
3020.44	123.864
3024.74	122.647
3029.04	122.033
3033.34	122.625
3037.64	125.235
3041.93	126.671
3046.22	126.89
3050.51	126.072
3054.79	125.063
3059.07	123.921
3063.35	122.772
3067.63	121.454
3071.9	121.382
3076.17	121.524
3080.44	120.471
3084.7	119.483
3088.96	117.547
3093.22	116.44
3097.48	116.034
3101.73	116.173
3105.98	117.93
3110.23	122.749
3114.47	122.621
3118.71	120.883
3122.95	118.259
3127.19	114.638
3131.42	111.516
3135.65	115.063
3139.87	116.141
3144.1	117.186
3148.32	118.142
3152.54	119.066
3156.75	119.746
3160.96	120.09
3165.17	119.913
3169.38	119.119
3173.58	116.059
3177.79	114.52
3181.98	114.33
3186.18	116.807
3190.37	118.821
3194.56	119.816
3198.75	118.132
3202.93	115.693
3207.12	114.715
3211.29	114.894
3215.47	114.323
3219.64	115.425
3223.81	116.806
3227.98	118.303
3232.15	119.496
3236.31	119.852
3240.47	116.287
3244.62	115.683
3248.78	116.711
3252.93	116.745
3257.08	113.561
3261.22	112.464
3265.36	114.37
3269.5	115.654
3273.64	114.235
3277.78	113.358
3281.91	112.387
3286.03	111.21
3290.16	109.795
3294.28	109.868
3298.4	110.369
3302.52	110.423
3306.64	110.129
3310.75	110.12
3314.86	110.185
3318.97	110.262
3323.07	110.355
3327.17	110.405
3331.27	110.396
3335.37	110.339
3339.46	110.206
3343.55	110.007
3347.64	109.739
3351.72	109.456
3355.8	109.158
3359.88	108.784
3363.96	108.124
3368.03	107.412
3372.1	106.685
3376.17	105.992
3380.24	105.37
3384.3	105.38
3388.36	105.731
3392.42	106.415
3396.48	107.328
3400.53	108.487
3404.58	109.641
3408.63	109.52
3412.67	108.73
3416.71	107.429
3420.75	105.999
3424.79	105.016
3428.82	102.95
3432.86	101.594
3436.88	101.665
3440.91	103.137
3444.93	104.903
3448.95	105.952
3452.97	106.426
3456.99	105.734
3461	104.436
3465.01	104.987
3469.02	105.325
3473.02	105.244
3477.02	104.966
3481.02	104.572
3485.02	104.164
3489.02	103.767
3493.01	103.346
3497	102.917
3500.98	102.583
3504.97	102.431
3508.95	102.733
3512.93	103.222
3516.9	103.769
3520.88	104.519
3524.85	105.744
3528.81	105.549
3532.78	104.309
3536.74	102.771
3540.7	101.33
3544.66	100.262
3548.62	99.6738
3552.57	99.6632
3556.52	100.125
3560.47	101.198
3564.41	101.505
3568.35	100.653
3572.29	99.9638
3576.23	99.4344
3580.17	98.7265
3584.1	97.1648
3588.03	95.8285
3591.96	95.2242
3595.88	95.1046
3599.8	95.3629
3603.72	96.8423
3607.64	98.5735
3611.55	99.5617
3615.46	99.3613
3619.37	98.7496
3623.28	98.0588
3627.18	97.9815
3631.09	98.2934
3634.98	99.077
3638.88	100.551
3642.77	102.743
3646.67	103.059
3650.56	101.99
3654.44	100.564
3658.33	99.9276
3662.21	99.4113
3666.09	98.9538
3669.96	98.386
3673.84	97.629
3677.71	96.6016
3681.58	95.4019
3685.44	94.0781
3689.31	92.7229
3693.17	91.7985
3697.03	92.8988
3700.88	93.8688
3704.74	93.5377
3708.59	92.9263
3712.44	92.4303
3716.28	92.0607
3720.13	91.8672
3723.97	91.5965
3727.81	91.8317
3731.65	93.6167
3735.48	94.145
3739.31	93.8938
3743.14	93.8246
3746.97	94.9847
3750.79	95.8502
3754.61	96.8149
3758.43	98.1302
3762.25	99.3958
3766.06	99.1084
3769.88	96.6114
3773.69	93.8398
3777.49	91.4658
3781.3	89.5767
3785.1	88.344
3788.9	87.9496
3792.7	88.0841
3796.49	88.6527
3800.28	89.5149
3804.07	90.451
3807.86	91.3244
3811.65	92.1164
3815.43	92.3949
3819.21	92.5049
3822.99	92.4881
3826.76	92.3559
3830.54	92.3138
3834.31	92.2932
3838.08	92.7486
3841.84	92.481
3845.61	91.8103
3849.37	92.5244
3853.13	93.9459
3856.88	93.8396
3860.64	92.3441
3864.39	88.8951
3868.14	86.9846
3871.88	85.8981
3875.63	86.5505
3879.37	87.8616
3883.11	89.0471
3886.85	90.3109
3890.58	91.3288
3894.31	91.8614
3898.05	89.4556
3901.77	87.7304
3905.5	85.8788
3909.22	84.9189
3912.94	84.8646
3916.66	85.3099
3920.38	86.0916
3924.09	86.6466
3927.8	86.6909
3931.51	85.8084
3935.22	84.0661
3938.92	82.7104
3942.62	82.1236
3946.32	82.0947
3950.02	82.4626
3953.72	83.4134
3957.41	84.4028
3961.1	85.261
3964.79	85.2777
3968.47	84.7708
3972.16	84.2838
3975.84	83.8014
3979.51	83.409
3983.19	83.3424
3986.87	83.9461
3990.54	84.3848
3994.21	83.5794
3997.87	80.925
3999.71	78.6907