File: Data/Raman/raw/bu02a-area1-rutile-reflective_prism_150 (500nm)_633nm_edge_25%_x50_vis_lwd_h100um_30sx2_01.txt
#Acq. time (s)=	30
#Accumulations=	2
#Range (cm-¹)=	100...4000
#Windows=	1
#Auto scanning=	Off
#Autofocus=	Off
#Macrospot=	Off
#AutoExposure=	Off
#Spike filter=	Multiple accum.
#Delay time (s)=	1
#Binning=	1
#Readout mode=	Signal
#DeNoise=	Standard
#ICS correction=	On
#Dark correction=	Off
#Inst. Process=	Off
#Detector Gain=	Best Dynamic
#Detector ADC=	50 kHz EM
#Detector EM gain=	100
#Detector temperature (°C)=	-60.09
#Instrument=	LabRAM HR Evol
#Detector=	SIN-EM FIVIS
#Objective=	x50_VIS_LWD
#Grating=	150 (500nm)
#ND Filter=	25%
#Laser=	633nm_Edge
#Hole=	100.021
#Temperature=	0
#Range=	Visible
#StageXY=	75x50mm Scan+
#StageZ=	Z motor
#X (µm)=	0
#Y (µm)=	0
#Z (µm)=	-150.1
#Full time(mm:ss)=	1:03
#Project=	20_10_20
#Sample=	BU18FA02a
#Site=
#Title=	BU02a-Area1-reflective_prism_150 (500nm)_633nm_Edge_25%_x50_VIS_LWD_H100um_30sX2
#Remark=
#Date=	20.10.2020 16:37
#Acquired=	20.10.2020 16:37:19
100.676	3023.03
107.192	3094.95
113.703	3104.53
120.208	3078.47
126.708	3029.41
133.203	2960.94
139.692	2902.25
146.176	2793.73
152.654	2601.75
159.127	2491.43
165.595	2484.36
172.058	2566.03
178.515	2712.36
184.966	2894.47
191.411	3088.79
197.852	3278.64
204.288	3437.8
210.719	3583.41
217.142	3710.22
223.562	3813.99
229.977	3891
236.386	3942.19
242.789	3961.27
249.188	3936.39
255.58	3870.57
261.968	3769.92
268.351	3648.43
274.727	3516.44
281.1	3400.96
287.466	3308.85
293.828	3242.31
300.183	3198.8
306.535	3179.86
312.88	3183.84
319.221	3198.03
325.556	3208.57
331.885	3223.21
338.211	3251.84
344.53	3279.33
350.844	3300
357.154	3326.61
363.458	3365.59
369.756	3420.36
376.051	3500.93
382.339	3631.37
388.622	3822.42
394.9	4087.4
401.173	4432.06
407.442	4853.13
413.705	5371.43
419.962	5959.2
426.215	6615.58
432.462	7364.4
438.705	7839.07
444.942	7936.73
451.174	7548.67
457.401	6621
463.623	5531.05
469.84	4840.96
476.052	4302.03
482.259	3948.1
488.461	3719.37
494.658	3570.76
500.848	3469.62
507.035	3385.21
513.217	3319.83
519.394	3258.31
525.566	3209.72
531.731	3171.13
537.893	3136.12
544.05	3106.38
550.202	3082.79
556.348	3067.4
562.49	3057.44
568.626	3047.91
574.758	3041.61
580.885	3046.3
587.006	3056.57
593.124	3067.06
599.235	3058.44
605.342	3020.02
611.444	2975.37
617.541	2808.04
623.633	2624.35
629.721	2456.96
635.803	2374.46
641.879	2329.85
647.953	2302.19
654.02	2297.66
660.083	2254.14
666.141	2192.09
672.193	2127.5
678.241	2068.2
684.285	2017.09
690.324	1976.02
696.357	1942.86
702.385	1918.7
708.409	1900.41
714.428	1884.29
720.443	1865.31
726.452	1845.48
732.457	1827.67
738.456	1814.81
744.451	1809.81
750.441	1813.22
756.427	1825.04
762.407	1840.47
768.383	1861.63
774.354	1879.11
780.32	1898.78
786.282	1930.46
792.237	1974.45
798.19	2029.6
804.137	2076.19
810.08	2147.01
816.018	2237.54
821.95	2337.49
827.878	2397.43
833.802	2474.09
839.721	2526.66
845.635	2532.85
851.544	2382.8
857.448	2151.62
863.349	1927.78
869.245	1723.86
875.135	1523.21
881.021	1373.48
886.902	1274.35
892.779	1199.92
898.65	1141.9
904.518	1106
910.38	1076.48
916.239	1052.79
922.092	1043.67
927.94	1041.61
933.785	1020.8
939.625	1001.59
945.459	989.115
951.29	980.924
957.116	976.326
962.936	974.143
968.753	967.024
974.566	957.519
980.373	946.376
986.175	933.783
991.973	920.443
997.767	907.638
1003.56	892.91
1009.34	879.696
1015.12	869.137
1020.9	862.612
1026.67	861.882
1032.43	859.582
1038.19	857.218
1043.95	856.83
1049.7	856.639
1055.45	851.978
1061.2	846.939
1066.94	844.136
1072.67	842.145
1078.4	840.254
1084.13	839.052
1089.85	840.641
1095.57	844.534
1101.28	844.201
1106.98	847.835
1112.69	855.864
1118.39	867.278
1124.08	877.402
1129.77	876.588
1135.46	874.342
1141.14	872.08
1146.82	870.436
1152.49	868.776
1158.16	867.85
1163.82	867.939
1169.48	869.226
1175.13	873.411
1180.78	872.515
1186.43	869.694
1192.07	868.294
1197.71	868.264
1203.34	868.466
1208.97	867.676
1214.59	868.679
1220.21	871.113
1225.83	873.771
1231.44	875.771
1237.05	876.784
1242.65	875.59
1248.25	877.235
1253.84	876.774
1259.43	875.162
1265.01	875.532
1270.59	878.369
1276.17	883.191
1281.74	889.467
1287.31	892.653
1292.87	894.778
1298.43	893.338
1303.99	895.968
1309.54	901.491
1315.08	905.998
1320.63	909.395
1326.16	911.261
1331.7	911.39
1337.23	905.764
1342.75	897.284
1348.27	889.159
1353.79	879.99
1359.3	867.139
1364.81	854.51
1370.31	846.89
1375.81	847.658
1381.31	851.111
1386.8	854.995
1392.29	859.19
1397.77	857.845
1403.25	853.706
1408.72	846.445
1414.19	838.178
1419.66	832.379
1425.12	830.279
1430.58	831.81
1436.03	829.498
1441.48	831.573
1446.92	835.425
1452.36	835.605
1457.8	830.519
1463.23	824.223
1468.66	823.174
1474.09	826.755
1479.51	835.329
1484.92	832.809
1490.33	837.565
1495.74	836.731
1501.14	833.46
1506.54	828.251
1511.94	825.17
1517.33	823.469
1522.72	818.283
1528.1	809.768
1533.48	801.525
1538.86	796.835
1544.23	792.251
1549.59	786.757
1554.96	781.79
1560.32	779.534
1565.67	778.525
1571.02	776.677
1576.37	773.4
1581.71	768.372
1587.05	760.254
1592.38	752.216
1597.71	748.597
1603.04	746.343
1608.36	742.487
1613.68	738.145
1618.99	733.457
1624.3	728.965
1629.61	724.836
1634.91	719.679
1640.21	712.572
1645.51	705.051
1650.8	700.697
1656.08	697.678
1661.36	693.135
1666.64	688.612
1671.92	685.431
1677.19	684.103
1682.45	683.334
1687.72	679.234
1692.98	675.172
1698.23	671.689
1703.48	669.448
1708.73	667.664
1713.97	666.163
1719.21	665.455
1724.44	669.306
1729.67	668.74
1734.9	660.082
1740.12	650.897
1745.34	645.594
1750.56	644.229
1755.77	644.275
1760.98	644.789
1766.18	644.128
1771.38	642.685
1776.58	640.082
1781.77	636.689
1786.96	634.99
1792.14	637.356
1797.32	642.891
1802.5	648.413
1807.67	651.785
1812.84	650.036
1818.01	646.953
1823.17	645.999
1828.33	641.483
1833.48	637.304
1838.63	634.991
1843.77	635.388
1848.92	638.36
1854.06	641.263
1859.19	639.392
1864.32	639.68
1869.45	641.635
1874.57	644.91
1879.69	648.987
1884.8	650.002
1889.92	650.622
1895.02	651.494
1900.13	653.191
1905.23	653.575
1910.33	649.282
1915.42	644.359
1920.51	639.056
1925.59	634.625
1930.67	632.517
1935.75	634.513
1940.82	639.779
1945.9	645.525
1950.96	649.083
1956.02	651.969
1961.08	653.786
1966.14	653.947
1971.19	653.094
1976.24	649.034
1981.28	640.827
1986.32	633.881
1991.36	629.914
1996.39	629.588
2001.42	632.149
2006.45	635.442
2011.47	635.148
2016.49	635.079
2021.5	636.291
2026.51	637.546
2031.52	633.287
2036.52	630.225
2041.52	630.908
2046.52	626.9
2051.51	622.518
2056.5	622.448
2061.49	624.471
2066.47	626.592
2071.45	629.664
2076.42	632.152
2081.39	633.132
2086.36	632.195
2091.32	628.45
2096.28	624.314
2101.24	622.035
2106.19	620.576
2111.14	620.222
2116.09	622.57
2121.03	626.941
2125.97	630.461
2130.9	632.285
2135.83	629.034
2140.76	626.387
2145.68	626.418
2150.6	625.349
2155.52	623.956
2160.43	624.098
2165.34	620.299
2170.25	618.633
2175.15	620.266
2180.05	624.667
2184.95	629.102
2189.84	627.005
2194.73	625.315
2199.61	623.043
2204.49	619.401
2209.37	617.089
2214.24	613.7
2219.11	611.659
2223.98	612.34
2228.84	613.317
2233.7	613.357
2238.56	613.819
2243.41	614.181
2248.26	611.938
2253.11	609.759
2257.95	607.492
2262.79	606.647
2267.63	607.22
2272.46	609.036
2277.29	611.415
2282.11	613.518
2286.93	610.658
2291.75	605.112
2296.57	600.069
2301.38	599.104
2306.19	601.191
2310.99	606.518
2315.79	614.868
2320.59	622.879
2325.38	621.57
2330.17	609.24
2334.96	609.347
2339.74	610.308
2344.52	603.965
2349.3	601.546
2354.07	600.585
2358.84	601.02
2363.61	603.67
2368.37	608.849
2373.13	610.51
2377.89	611.206
2382.64	615.539
2387.39	619.84
2392.14	621.99
2396.88	619.926
2401.62	617.01
2406.36	614.372
2411.09	612.378
2415.82	610.935
2420.55	609.811
2425.27	609.395
2429.99	610.252
2434.7	610.504
2439.42	611.391
2444.12	612.989
2448.83	615.724
2453.53	619.492
2458.23	623.303
2462.93	625.312
2467.62	626.933
2472.31	628.948
2476.99	628.881
2481.68	627.622
2486.36	626.844
2491.03	626.357
2495.7	624.616
2500.37	623.748
2505.04	625.278
2509.7	623.933
2514.36	621.987
2519.02	620.776
2523.67	620.408
2528.32	625.348
2532.97	629.19
2537.61	628.651
2542.25	627.077
2546.88	628.053
2551.52	630.987
2556.15	631.388
2560.77	632.149
2565.4	633.721
2570.02	631.379
2574.63	625.814
2579.25	620.611
2583.86	617.329
2588.46	616.45
2593.07	618.225
2597.67	622.379
2602.27	626.635
2606.86	625.653
2611.45	625.781
2616.04	626.454
2620.62	625.781
2625.2	625.097
2629.78	624.994
2634.36	626.257
2638.93	626.988
2643.5	625.487
2648.06	623.534
2652.62	623.072
2657.18	625.336
2661.74	630.16
2666.29	635.091
2670.84	638.235
2675.38	641.113
2679.93	643.424
2684.47	645.311
2689	645.406
2693.54	642.289
2698.07	640.182
2702.59	642.241
2707.12	644.012
2711.64	643.554
2716.16	643.624
2720.67	644.251
2725.18	645.143
2729.69	645.297
2734.19	641.786
2738.7	637.692
2743.19	636.439
2747.69	636.603
2752.18	639.07
2756.67	642.712
2761.16	646.33
2765.64	649.066
2770.12	644.961
2774.6	642.125
2779.07	642.358
2783.54	645.646
2788.01	650.475
2792.47	654.904
2796.94	658.046
2801.39	659.804
2805.85	658.031
2810.3	655.214
2814.75	655.712
2819.2	655.975
2823.64	656.478
2828.08	657.061
2832.52	656.316
2836.95	651.163
2841.38	648.099
2845.81	648.815
2850.23	652.453
2854.65	655.424
2859.07	658.478
2863.49	662.293
2867.9	665.08
2872.31	662.982
2876.71	659.51
2881.12	658.74
2885.52	661.316
2889.91	665.389
2894.31	669.512
2898.7	677.157
2903.09	682.397
2907.47	684.341
2911.86	685.14
2916.23	684.079
2920.61	682.827
2924.98	682.776
2929.35	677.984
2933.72	673.382
2938.08	672.052
2942.45	674.106
2946.8	678.565
2951.16	682.626
2955.51	684.992
2959.86	686.409
2964.21	687.416
2968.55	690.616
2972.89	690.199
2977.23	686.804
2981.56	685.276
2985.89	686.267
2990.22	689.897
2994.55	689.982
2998.87	691.49
3003.19	694.22
3007.5	696.758
3011.82	698.591
3016.13	700.228
3020.44	701.759
3024.74	703.053
3029.04	704.271
3033.34	700.491
3037.64	700.527
3041.93	703.803
3046.22	709.162
3050.51	710.77
3054.79	713.431
3059.07	716.211
3063.35	717.518
3067.63	718.341
3071.9	715.755
3076.17	714.469
3080.44	714.478
3084.7	715.296
3088.96	717.292
3093.22	721.08
3097.48	727.312
3101.73	724.928
3105.98	722.752
3110.23	722.601
3114.47	724.245
3118.71	727.839
3122.95	733.487
3127.19	739.772
3131.42	743.181
3135.65	743.814
3139.87	742.632
3144.1	741.338
3148.32	742.929
3152.54	745.359
3156.75	746.76
3160.96	750.696
3165.17	754.368
3169.38	757.329
3173.58	759.381
3177.79	759.477
3181.98	758.669
3186.18	758.464
3190.37	760.524
3194.56	761.248
3198.75	762.994
3202.93	765.461
3207.12	767.447
3211.29	768.737
3215.47	768.833
3219.64	769.23
3223.81	769.616
3227.98	771.276
3232.15	773.959
3236.31	777.101
3240.47	779.818
3244.62	779.503
3248.78	779.529
3252.93	781.242
3257.08	782.734
3261.22	784.828
3265.36	788.358
3269.5	791.896
3273.64	793.965
3277.78	794.877
3281.91	794.881
3286.03	794.657
3290.16	794.917
3294.28	796.077
3298.4	799.159
3302.52	803.605
3306.64	807.605
3310.75	810.63
3314.86	812.835
3318.97	814.428
3323.07	814.984
3327.17	814.402
3331.27	813.102
3335.37	812.976
3339.46	814.962
3343.55	817.092
3347.64	818.469
3351.72	819.9
3355.8	821.967
3359.88	823.823
3363.96	824.597
3368.03	824.487
3372.1	824.456
3376.17	824.709
3380.24	825.852
3384.3	827.987
3388.36	829.635
3392.42	829.503
3396.48	827.345
3400.53	824.583
3404.58	822.833
3408.63	823.997
3412.67	827.963
3416.71	833.554
3420.75	839.435
3424.79	841.609
3428.82	844.202
3432.86	843.577
3436.88	837.404
3440.91	832.063
3444.93	829.322
3448.95	830.531
3452.97	832.112
3456.99	836.332
3461	845.138
3465.01	852.418
3469.02	856.692
3473.02	851.612
3477.02	849.209
3481.02	849.908
3485.02	848.418
3489.02	849.631
3493.01	855.055
3497	864.047
3500.98	867.746
3504.97	870.933
3508.95	873.975
3512.93	876.198
3516.9	876.861
3520.88	870.702
3524.85	860.344
3528.81	852.013
3532.78	847.282
3536.74	847.303
3540.7	853.102
3544.66	862.153
3548.62	872.641
3552.57	880.637
3556.52	885.155
3560.47	886.778
3564.41	883.445
3568.35	880.896
3572.29	877.518
3576.23	876.05
3580.17	876.423
3584.1	878.458
3588.03	885.177
3591.96	884.511
3595.88	883.27
3599.8	883.199
3603.72	884.057
3607.64	886.568
3611.55	892.712
3615.46	898.239
3619.37	900.66
3623.28	903.457
3627.18	903.953
3631.09	899.741
3634.98	894.783
3638.88	891.769
3642.77	891.511
3646.67	894.28
3650.56	894.792
3654.44	895.819
3658.33	900.216
3662.21	905.253
3666.09	905.367
3669.96	905.292
3673.84	906.607
3677.71	908.722
3681.58	908.989
3685.44	908.099
3689.31	907.285
3693.17	907.368
3697.03	909.871
3700.88	913.467
3704.74	918.078
3708.59	923.57
3712.44	928.435
3716.28	931.007
3720.13	931.943
3723.97	930.489
3727.81	928.804
3731.65	928.192
3735.48	928.38
3739.31	929.295
3743.14	930.979
3746.97	932.732
3750.79	933.511
3754.61	932.22
3758.43	930.11
3762.25	928.911
3766.06	930.536
3769.88	933.932
3773.69	938.317
3777.49	942.6
3781.3	945.863
3785.1	947.646
3788.9	946.048
3792.7	939.478
3796.49	932.881
3800.28	930.427
3804.07	934.185
3807.86	943.511
3811.65	954.644
3815.43	960.933
3819.21	962.627
3822.99	964.861
3826.76	967.497
3830.54	962.609
3834.31	957.311
3838.08	956.865
3841.84	955.664
3845.61	954.861
3849.37	954.242
3853.13	961.643
3856.88	971.386
3860.64	971.715
3864.39	966.454
3868.14	960.961
3871.88	957.296
3875.63	957.187
3879.37	961.126
3883.11	967.181
3886.85	973.976
3890.58	974.703
3894.31	975.046
3898.05	974.894
3901.77	974.52
3905.5	974.117
3909.22	973.777
3912.94	973.715
3916.66	974.732
3920.38	978.246
3924.09	982.936
3927.8	982.057
3931.51	982.037
3935.22	983.696
3938.92	981.358
3942.62	980.849
3946.32	982.767
3950.02	986.332
3953.72	990.487
3957.41	994.514
3961.1	997.434
3964.79	998.288
3968.47	993.79
3972.16	988.31
3975.84	983.848
3979.51	981.835
3983.19	982.549
3986.87	984.524
3990.54	988.869
3994.21	997.214
3997.87	1001.59
3999.71	999.564