File: Data/Raman/raw/bu02a-area1-rutile-reflective_prism2_150 (500nm)_633nm_edge_50%_x50_vis_lwd_h100um_10sx2_01.txt
#Acq. time (s)=	10
#Accumulations=	2
#Range (cm-¹)=	100...4000
#Windows=	1
#Auto scanning=	Off
#Autofocus=	Off
#Macrospot=	Off
#AutoExposure=	Off
#Spike filter=	Multiple accum.
#Delay time (s)=	1
#Binning=	1
#Readout mode=	Signal
#DeNoise=	Standard
#ICS correction=	On
#Dark correction=	Off
#Inst. Process=	Off
#Detector Gain=	Best Dynamic
#Detector ADC=	50 kHz HS
#Detector temperature (°C)=	-60.09
#Instrument=	LabRAM HR Evol
#Detector=	SIN-EM FIVIS
#Objective=	x50_VIS_LWD
#Grating=	150 (500nm)
#ND Filter=	50%
#Laser=	633nm_Edge
#Hole=	100.021
#Temperature=	0
#Range=	Visible
#StageXY=	75x50mm Scan+
#StageZ=	Z motor
#X (µm)=	0
#Y (µm)=	0
#Z (µm)=	-149.8
#Full time(s)=	24
#Project=	20_10_20
#Sample=	BU18FA02a
#Site=
#Title=	BU02a-Area1-rutile-reflective_prism2_150 (500nm)_633nm_Edge_50%_x50_VIS_LWD_H100um_10sX2
#Remark=
#Date=	20.10.2020 16:41
#Acquired=	20.10.2020 16:41:33
100.676	6647.79
107.192	6826.51
113.703	6943.89
120.208	7030.27
126.708	7090.93
133.203	7119.06
139.692	7083.69
146.176	6959.76
152.654	6824.56
159.127	6767.2
165.595	6925.54
172.058	7265.26
178.515	7724.98
184.966	8214.22
191.411	8865.35
197.852	9557.5
204.288	10213
210.719	10741.5
217.142	11155.1
223.562	11432.8
229.977	11587.6
236.386	11611.6
242.789	11488.4
249.188	11271.6
255.58	10973
261.968	10697.2
268.351	10372.1
274.727	9987.22
281.1	9584.52
287.466	9211.03
293.828	8859.76
300.183	8706.58
306.535	8700.69
312.88	8765.01
319.221	8874.5
325.556	9043.58
331.885	9201.39
338.211	9357.28
344.53	9503.32
350.844	9591.94
357.154	9652.76
363.458	9676.76
369.756	9689.48
376.051	9821.7
382.339	10069.1
388.622	10455.8
394.9	10994.9
401.173	11705
407.442	12699.6
413.705	14117.9
419.962	15878.8
426.215	18001.3
432.462	20385.3
438.705	22213.6
444.942	22711.1
451.174	21090
457.401	18026.2
463.623	14927.2
469.84	12558.9
476.052	10989.9
482.259	10068.2
488.461	9533.17
494.658	9192.82
500.848	8981.13
507.035	8893.55
513.217	8834.54
519.394	8812.89
525.566	8739.85
531.731	8661.1
537.893	8573.66
544.05	8491.61
550.202	8429.08
556.348	8393.12
562.49	8405.82
568.626	8453.14
574.758	8565.76
580.885	8734
587.006	8946.55
593.124	9207.58
599.235	9443.52
605.342	9459.26
611.444	9077.71
617.541	8327.51
623.633	7400.62
629.721	6576.56
635.803	5978.31
641.879	5618.34
647.953	5410.04
654.02	5324.02
660.083	5332
666.141	5362.84
672.193	5440.18
678.241	5523.47
684.285	5604.65
690.324	5661.82
696.357	5701.82
702.385	5699.9
708.409	5663.69
714.428	5586.53
720.443	5482.51
726.452	5370.14
732.457	5258.9
738.456	5157.08
744.451	5079.82
750.441	5007.85
756.427	4955.65
762.407	4904.56
768.383	4861.76
774.354	4828.46
780.32	4807.98
786.282	4796.21
792.237	4787.88
798.19	4780.71
804.137	4773.35
810.08	4767.26
816.018	4748.79
821.95	4718.35
827.878	4674.81
833.802	4630.76
839.721	4579.67
845.635	4524.48
851.544	4466.97
857.448	4415.95
863.349	4373.77
869.245	4339.56
875.135	4311.54
881.021	4287.58
886.902	4268.2
892.779	4253.17
898.65	4240.58
904.518	4231.62
910.38	4226.74
916.239	4224.07
922.092	4225.69
927.94	4227.37
933.785	4227.55
939.625	4228.44
945.459	4228.26
951.29	4230.55
957.116	4229.94
962.936	4221.08
968.753	4211.32
974.566	4197.85
980.373	4184.46
986.175	4169.07
991.973	4159.22
997.767	4159.25
1003.56	4163.12
1009.34	4169.99
1015.12	4173.7
1020.9	4174.29
1026.67	4170.75
1032.43	4165.8
1038.19	4166.54
1043.95	4168.41
1049.7	4178.24
1055.45	4184.54
1061.2	4184.18
1066.94	4178.58
1072.67	4167.5
1078.4	4162.14
1084.13	4163.63
1089.85	4173.23
1095.57	4187.75
1101.28	4206.2
1106.98	4224.47
1112.69	4240.14
1118.39	4249.49
1124.08	4254.47
1129.77	4258.92
1135.46	4264.27
1141.14	4269.64
1146.82	4273.03
1152.49	4274.1
1158.16	4269.19
1163.82	4267.01
1169.48	4268.83
1175.13	4273.14
1180.78	4284.32
1186.43	4301.61
1192.07	4318.62
1197.71	4336.6
1203.34	4353.36
1208.97	4363.4
1214.59	4373.95
1220.21	4383.62
1225.83	4383.55
1231.44	4385.81
1237.05	4383.6
1242.65	4380.37
1248.25	4379.5
1253.84	4380.75
1259.43	4375.02
1265.01	4370.98
1270.59	4368.23
1276.17	4366.89
1281.74	4369.48
1287.31	4379.66
1292.87	4391.61
1298.43	4402.63
1303.99	4415.24
1309.54	4427.7
1315.08	4424.44
1320.63	4414.85
1326.16	4408.61
1331.7	4412.08
1337.23	4422.7
1342.75	4437.23
1348.27	4447.08
1353.79	4447.94
1359.3	4445.53
1364.81	4437.35
1370.31	4428.07
1375.81	4420.82
1381.31	4420.1
1386.8	4425.02
1392.29	4433.88
1397.77	4438.32
1403.25	4447.83
1408.72	4455.63
1414.19	4460.98
1419.66	4464.24
1425.12	4468.69
1430.58	4477.61
1436.03	4495.51
1441.48	4513.9
1446.92	4520.51
1452.36	4518.42
1457.8	4507.66
1463.23	4494.7
1468.66	4486.65
1474.09	4483.89
1479.51	4484.65
1484.92	4495.79
1490.33	4510.44
1495.74	4515.95
1501.14	4517.97
1506.54	4518.53
1511.94	4518.38
1517.33	4518.68
1522.72	4524.89
1528.1	4536.75
1533.48	4536.33
1538.86	4536.34
1544.23	4528.41
1549.59	4516.44
1554.96	4515.96
1560.32	4510.33
1565.67	4512.55
1571.02	4515.73
1576.37	4515.91
1581.71	4516.21
1587.05	4516.71
1592.38	4507.38
1597.71	4519.71
1603.04	4530.07
1608.36	4538.89
1613.68	4529
1618.99	4517.66
1624.3	4506.17
1629.61	4491.59
1634.91	4477.57
1640.21	4463.9
1645.51	4453.14
1650.8	4444.63
1656.08	4436.36
1661.36	4426.42
1666.64	4412.98
1671.92	4406.42
1677.19	4399.41
1682.45	4389.64
1687.72	4378.46
1692.98	4368.96
1698.23	4362.56
1703.48	4355.86
1708.73	4345.52
1713.97	4336.13
1719.21	4331.9
1724.44	4329.39
1729.67	4325.55
1734.9	4319.77
1740.12	4319.09
1745.34	4315.68
1750.56	4300.99
1755.77	4283.06
1760.98	4265.76
1766.18	4250.94
1771.38	4235.68
1776.58	4222.6
1781.77	4216.3
1786.96	4216.63
1792.14	4221.67
1797.32	4224.02
1802.5	4228.65
1807.67	4235.34
1812.84	4241.1
1818.01	4239.6
1823.17	4232.1
1828.33	4220.76
1833.48	4205.44
1838.63	4184.94
1843.77	4165.36
1848.92	4149.69
1854.06	4143.75
1859.19	4141.21
1864.32	4138.68
1869.45	4136.18
1874.57	4129.72
1879.69	4116.24
1884.8	4103.58
1889.92	4089.86
1895.02	4084.76
1900.13	4087.01
1905.23	4087.43
1910.33	4090.05
1915.42	4090.01
1920.51	4084.85
1925.59	4077.09
1930.67	4065.77
1935.75	4050.27
1940.82	4040.03
1945.9	4025.08
1950.96	4014.77
1956.02	4010.72
1961.08	4011.43
1966.14	4003.35
1971.19	3995.04
1976.24	3988.26
1981.28	3979.81
1986.32	3972.43
1991.36	3963.3
1996.39	3949.77
2001.42	3941.73
2006.45	3938.18
2011.47	3936.15
2016.49	3932.93
2021.5	3915.57
2026.51	3898.98
2031.52	3887.18
2036.52	3876.23
2041.52	3869.11
2046.52	3871.19
2051.51	3874.3
2056.5	3874.76
2061.49	3873.97
2066.47	3866.01
2071.45	3848.57
2076.42	3832.38
2081.39	3816.86
2086.36	3803.02
2091.32	3794.9
2096.28	3789.26
2101.24	3780.01
2106.19	3770.01
2111.14	3759.9
2116.09	3745.14
2121.03	3736.33
2125.97	3734.03
2130.9	3733.78
2135.83	3729.45
2140.76	3719.47
2145.68	3706.37
2150.6	3696.41
2155.52	3684.52
2160.43	3672.39
2165.34	3667.97
2170.25	3667.21
2175.15	3671.09
2180.05	3668.77
2184.95	3665.7
2189.84	3662.37
2194.73	3659.96
2199.61	3656.47
2204.49	3653.04
2209.37	3646.08
2214.24	3639.25
2219.11	3634.5
2223.98	3629.43
2228.84	3620.16
2233.7	3597.04
2238.56	3606.18
2243.41	3614.96
2248.26	3593.11
2253.11	3578.65
2257.95	3582.99
2262.79	3611.92
2267.63	3610.76
2272.46	3591.45
2277.29	3568.38
2282.11	3542.95
2286.93	3527.38
2291.75	3517.46
2296.57	3513.98
2301.38	3508.98
2306.19	3503.91
2310.99	3498.11
2315.79	3489.36
2320.59	3480.98
2325.38	3470.63
2330.17	3466.21
2334.96	3465.69
2339.74	3468.75
2344.52	3467.87
2349.3	3458.6
2354.07	3455.63
2358.84	3452.35
2363.61	3448.65
2368.37	3444.97
2373.13	3440.84
2377.89	3433.34
2382.64	3425.03
2387.39	3418.12
2392.14	3405.97
2396.88	3392.55
2401.62	3382.9
2406.36	3373.9
2411.09	3372.98
2415.82	3375.8
2420.55	3376.67
2425.27	3372.66
2429.99	3369.14
2434.7	3368.83
2439.42	3364.54
2444.12	3355.82
2448.83	3346.76
2453.53	3334.03
2458.23	3333.5
2462.93	3339.85
2467.62	3333.01
2472.31	3322.1
2476.99	3319.4
2481.68	3313.4
2486.36	3304.19
2491.03	3292.29
2495.7	3294.49
2500.37	3299.72
2505.04	3304.37
2509.7	3301.75
2514.36	3295.44
2519.02	3290.78
2523.67	3284.94
2528.32	3276.18
2532.97	3265.47
2537.61	3253.73
2542.25	3246.7
2546.88	3238.23
2551.52	3227.97
2556.15	3218.77
2560.77	3211.9
2565.4	3205.45
2570.02	3203.87
2574.63	3200.86
2579.25	3194.6
2583.86	3188.45
2588.46	3181.52
2593.07	3178
2597.67	3179.02
2602.27	3183
2606.86	3182.05
2611.45	3181.38
2616.04	3177.65
2620.62	3171.64
2625.2	3155.13
2629.78	3139.56
2634.36	3128.92
2638.93	3119.81
2643.5	3117.48
2648.06	3120.69
2652.62	3121.57
2657.18	3121.77
2661.74	3115.53
2666.29	3106.53
2670.84	3103.13
2675.38	3094.95
2679.93	3086.45
2684.47	3077.18
2689	3076.09
2693.54	3052.45
2698.07	3057.9
2702.59	3070.73
2707.12	3041.57
2711.64	3033.49
2716.16	3029.6
2720.67	3018.71
2725.18	3011.1
2729.69	3004.42
2734.19	2999.43
2738.7	2993.18
2743.19	2988.02
2747.69	2983.19
2752.18	2978.17
2756.67	2973.35
2761.16	2963.53
2765.64	2958.23
2770.12	2957.89
2774.6	2951.66
2779.07	2949.72
2783.54	2946.95
2788.01	2944.07
2792.47	2945.31
2796.94	2944
2801.39	2935.89
2805.85	2926.25
2810.3	2919.14
2814.75	2914.26
2819.2	2908.36
2823.64	2910.25
2828.08	2910.57
2832.52	2906.48
2836.95	2899.29
2841.38	2888.41
2845.81	2876.32
2850.23	2869.51
2854.65	2868.42
2859.07	2873.58
2863.49	2884.76
2867.9	2893.64
2872.31	2889.41
2876.71	2885.49
2881.12	2876.75
2885.52	2863.59
2889.91	2852
2894.31	2845.88
2898.7	2840.93
2903.09	2832.03
2907.47	2820.72
2911.86	2809.71
2916.23	2804.32
2920.61	2800.75
2924.98	2797.43
2929.35	2800.02
2933.72	2803.24
2938.08	2807.23
2942.45	2805.33
2946.8	2802
2951.16	2792.43
2955.51	2779.12
2959.86	2767.75
2964.21	2757.84
2968.55	2748.87
2972.89	2741.7
2977.23	2733.99
2981.56	2725.8
2985.89	2713.27
2990.22	2704.69
2994.55	2695.92
2998.87	2686.74
3003.19	2680.45
3007.5	2670.06
3011.82	2657.68
3016.13	2644.34
3020.44	2630.74
3024.74	2620
3029.04	2619.66
3033.34	2628.01
3037.64	2620.07
3041.93	2607.06
3046.22	2592.82
3050.51	2584.33
3054.79	2598.11
3059.07	2602.22
3063.35	2601.87
3067.63	2595.03
3071.9	2590.09
3076.17	2585.49
3080.44	2575.05
3084.7	2560.87
3088.96	2544.67
3093.22	2527.64
3097.48	2508.32
3101.73	2495.39
3105.98	2484.01
3110.23	2482.83
3114.47	2481.67
3118.71	2482.19
3122.95	2481.35
3127.19	2478.1
3131.42	2474.59
3135.65	2467.02
3139.87	2459.97
3144.1	2451.13
3148.32	2445.16
3152.54	2440.19
3156.75	2428.17
3160.96	2418.32
3165.17	2412.45
3169.38	2410.23
3173.58	2404.3
3177.79	2398.14
3181.98	2385.87
3186.18	2373.58
3190.37	2365.83
3194.56	2354.89
3198.75	2341.44
3202.93	2337.41
3207.12	2335.17
3211.29	2333.74
3215.47	2333.65
3219.64	2328.91
3223.81	2319.75
3227.98	2312.05
3232.15	2298.52
3236.31	2287.65
3240.47	2278.35
3244.62	2271.56
3248.78	2263.73
3252.93	2255.37
3257.08	2245.51
3261.22	2237.82
3265.36	2229.84
3269.5	2217.51
3273.64	2209.98
3277.78	2200.93
3281.91	2189.33
3286.03	2174.81
3290.16	2158.96
3294.28	2151.03
3298.4	2151.06
3302.52	2153.57
3306.64	2154.59
3310.75	2156.93
3314.86	2154.66
3318.97	2152.25
3323.07	2146.53
3327.17	2142.43
3331.27	2135.87
3335.37	2137.17
3339.46	2125.29
3343.55	2107.96
3347.64	2091.02
3351.72	2075.61
3355.8	2061.07
3359.88	2055
3363.96	2056.24
3368.03	2064.51
3372.1	2067.65
3376.17	2068.01
3380.24	2061.45
3384.3	2050.26
3388.36	2044
3392.42	2031.98
3396.48	2023.53
3400.53	2019.57
3404.58	2011.03
3408.63	1999.74
3412.67	1991.33
3416.71	1978.37
3420.75	1965.17
3424.79	1957.79
3428.82	1962.97
3432.86	1966.45
3436.88	1974.82
3440.91	1975.54
3444.93	1973.21
3448.95	1970.46
3452.97	1964.95
3456.99	1959.04
3461	1947.53
3465.01	1941.18
3469.02	1940.02
3473.02	1941.04
3477.02	1935.37
3481.02	1928.38
3485.02	1923.29
3489.02	1919.28
3493.01	1921.16
3497	1899.6
3500.98	1876.15
3504.97	1862.15
3508.95	1849.91
3512.93	1841.01
3516.9	1845.86
3520.88	1845.08
3524.85	1842.63
3528.81	1834.9
3532.78	1827.57
3536.74	1822.78
3540.7	1821.13
3544.66	1816.79
3548.62	1812.45
3552.57	1808.42
3556.52	1799.64
3560.47	1789.76
3564.41	1778.66
3568.35	1765.03
3572.29	1757.98
3576.23	1751.54
3580.17	1745.51
3584.1	1740.78
3588.03	1741.36
3591.96	1738.63
3595.88	1731.75
3599.8	1722.6
3603.72	1714.37
3607.64	1708.22
3611.55	1700.78
3615.46	1689.92
3619.37	1679.42
3623.28	1675.51
3627.18	1673.2
3631.09	1672.17
3634.98	1672.2
3638.88	1668.59
3642.77	1662.78
3646.67	1654.56
3650.56	1646.69
3654.44	1643.93
3658.33	1644.65
3662.21	1645.85
3666.09	1640.08
3669.96	1631.92
3673.84	1620.71
3677.71	1607.31
3681.58	1598.88
3685.44	1594.92
3689.31	1596.01
3693.17	1597.92
3697.03	1598.02
3700.88	1598.15
3704.74	1597.75
3708.59	1596.39
3712.44	1594.42
3716.28	1589.23
3720.13	1578.55
3723.97	1566.14
3727.81	1552.52
3731.65	1543.23
3735.48	1533.71
3739.31	1527.95
3743.14	1524.78
3746.97	1518.72
3750.79	1507.2
3754.61	1503.81
3758.43	1502.82
3762.25	1507.26
3766.06	1506.08
3769.88	1495.67
3773.69	1488.05
3777.49	1489.16
3781.3	1488.62
3785.1	1485.88
3788.9	1485.32
3792.7	1484.44
3796.49	1480.12
3800.28	1475.65
3804.07	1468.02
3807.86	1457.47
3811.65	1446.32
3815.43	1432.77
3819.21	1419.34
3822.99	1415.7
3826.76	1413.46
3830.54	1411.23
3834.31	1411.12
3838.08	1413.33
3841.84	1417.28
3845.61	1418.35
3849.37	1418.61
3853.13	1414.02
3856.88	1409.42
3860.64	1400.42
3864.39	1388.23
3868.14	1376.43
3871.88	1369.39
3875.63	1365.25
3879.37	1364.12
3883.11	1363.1
3886.85	1367.99
3890.58	1367.67
3894.31	1358.14
3898.05	1345.54
3901.77	1328.3
3905.5	1320.68
3909.22	1321.94
3912.94	1341
3916.66	1343.09
3920.38	1338.57
3924.09	1332.85
3927.8	1324.85
3931.51	1319.94
3935.22	1320.76
3938.92	1317.04
3942.62	1311.56
3946.32	1305.48
3950.02	1299.23
3953.72	1292.55
3957.41	1288.33
3961.1	1285.46
3964.79	1278.78
3968.47	1270.37
3972.16	1262.76
3975.84	1252.28
3979.51	1245.39
3983.19	1238.96
3986.87	1236.04
3990.54	1232.4
3994.21	1231.09
3997.87	1228.55
3999.71	1221.09