File: Data/Raman/raw/bu19w-area6-ore_150 (500nm)_633nm_edge_25%_x100_vis_h100um_15sx2_01.txt
#Acq. time (s)=	15
#Accumulations=	2
#Range (cm-¹)=	100...4000
#Windows=	1
#Auto scanning=	Off
#Autofocus=	Off
#Macrospot=	Off
#AutoExposure=	Off
#Spike filter=	Multiple accum.
#Delay time (s)=	1
#Binning=	1
#Readout mode=	Signal
#DeNoise=	Standard
#ICS correction=	On
#Dark correction=	Off
#Inst. Process=	Off
#Detector Gain=	Best Dynamic
#Detector ADC=	50 kHz HS
#Detector temperature (°C)=	-60.09
#Instrument=	LabRAM HR Evol
#Detector=	SIN-EM FIVIS
#Objective=	x100_VIS
#Grating=	150 (500nm)
#ND Filter=	25%
#Laser=	633nm_Edge
#Hole=	100.021
#Temperature=	0
#Range=	Visible
#StageXY=	75x50mm Scan+
#StageZ=	Z motor
#X (µm)=	0
#Y (µm)=	0
#Z (µm)=	-13.9
#Full time(s)=	34
#Project=	20_10_20
#Sample=	BU19w
#Site=
#Title=	BU19w-Area6-ore_150 (500nm)_633nm_Edge_25%_x100_VIS_H100um_15sX2
#Remark=
#Date=	20.10.2020 17:31
#Acquired=	20.10.2020 17:31:40
100.676	1010.17
107.192	1006.79
113.703	1007.71
120.208	999.978
126.708	996.178
133.203	1018.36
139.692	975.197
146.176	886.267
152.654	819.451
159.127	795.935
165.595	787.065
172.058	788.467
178.515	797.541
184.966	819.245
191.411	837.238
197.852	854.151
204.288	864.268
210.719	867.724
217.142	890.465
223.562	916.572
229.977	940.708
236.386	959.091
242.789	960.682
249.188	953.365
255.58	940.497
261.968	925.612
268.351	912.012
274.727	899.746
281.1	889.855
287.466	885.405
293.828	883.967
300.183	880.603
306.535	875.061
312.88	865.966
319.221	854.385
325.556	845.997
331.885	840.311
338.211	837.569
344.53	837.768
350.844	841.691
357.154	851.267
363.458	866.665
369.756	890.494
376.051	924.094
382.339	969.367
388.622	1028.32
394.9	1096.78
401.173	1182.84
407.442	1267.01
413.705	1343.92
419.962	1402.06
426.215	1415.46
432.462	1410.8
438.705	1375.92
444.942	1314.84
451.174	1240.17
457.401	1160.93
463.623	1094.94
469.84	1049.12
476.052	1015.73
482.259	987.618
488.461	963.318
494.658	952.722
500.848	932.573
507.035	911.684
513.217	890.409
519.394	873.403
525.566	867.639
531.731	876.666
537.893	893.981
544.05	919.216
550.202	953.093
556.348	995.399
562.49	1049.33
568.626	1116.18
574.758	1192.53
580.885	1281.11
587.006	1381.27
593.124	1489.74
599.235	1619.71
605.342	1745.68
611.444	1851.55
617.541	1908.48
623.633	1859.35
629.721	1753.1
635.803	1596.49
641.879	1453.7
647.953	1376.81
654.02	1305.29
660.083	1224.76
666.141	1145.29
672.193	1060.1
678.241	987.576
684.285	926.881
690.324	884.108
696.357	847.157
702.385	808.354
708.409	773.961
714.428	743.927
720.443	717.435
726.452	695.02
732.457	676.354
738.456	661.374
744.451	650.542
750.441	643.365
756.427	637.503
762.407	636.98
768.383	640.708
774.354	646.91
780.32	655.652
786.282	662.998
792.237	669.526
798.19	675.494
804.137	678.666
810.08	685.412
816.018	689.495
821.95	688.424
827.878	684.245
833.802	680.202
839.721	671.026
845.635	641.575
851.544	597.799
857.448	551.356
863.349	508.111
869.245	466.305
875.135	434.671
881.021	411.132
886.902	393.197
892.779	378.312
898.65	367.578
904.518	359.141
910.38	351.677
916.239	345.303
922.092	341.555
927.94	339.364
933.785	336.546
939.625	333.661
945.459	331.527
951.29	330.812
957.116	330.689
962.936	329.278
968.753	326.338
974.566	322.599
980.373	318.702
986.175	314.406
991.973	310.089
997.767	306.141
1003.56	302.601
1009.34	299.443
1015.12	296.579
1020.9	294.14
1026.67	294.286
1032.43	296.849
1038.19	297.366
1043.95	293.056
1049.7	289.295
1055.45	285.92
1061.2	283.219
1066.94	281.603
1072.67	281.557
1078.4	283.039
1084.13	284.251
1089.85	284.376
1095.57	282.979
1101.28	280.4
1106.98	277.937
1112.69	277.217
1118.39	277.413
1124.08	278.861
1129.77	280.861
1135.46	282.713
1141.14	284.03
1146.82	284.633
1152.49	284.48
1158.16	283.596
1163.82	281.86
1169.48	279.567
1175.13	277.194
1180.78	276.22
1186.43	276.669
1192.07	277.775
1197.71	278.702
1203.34	279.043
1208.97	278.79
1214.59	277.635
1220.21	275.746
1225.83	273.948
1231.44	274.046
1237.05	275.903
1242.65	277.571
1248.25	278.851
1253.84	279.967
1259.43	281.064
1265.01	281.375
1270.59	281.418
1276.17	281.415
1281.74	281.323
1287.31	281.91
1292.87	282.341
1298.43	282.54
1303.99	282.414
1309.54	281.539
1315.08	279.753
1320.63	277.085
1326.16	274.385
1331.7	272.878
1337.23	272.911
1342.75	274.428
1348.27	276.143
1353.79	275.103
1359.3	272.103
1364.81	271.143
1370.31	270.432
1375.81	268.426
1381.31	266.42
1386.8	264.891
1392.29	265.613
1397.77	266.862
1403.25	267.494
1408.72	267.242
1414.19	266.843
1419.66	266.421
1425.12	266.229
1430.58	266.38
1436.03	266.591
1441.48	267.239
1446.92	267.904
1452.36	268.526
1457.8	267.935
1463.23	266.363
1468.66	264.823
1474.09	263.66
1479.51	263.114
1484.92	262.874
1490.33	262.775
1495.74	262.661
1501.14	262.401
1506.54	262.389
1511.94	262.546
1517.33	262.843
1522.72	263.108
1528.1	263.142
1533.48	262.65
1538.86	261.804
1544.23	260.458
1549.59	258.85
1554.96	257.836
1560.32	257.262
1565.67	257.065
1571.02	257.256
1576.37	257.454
1581.71	257.694
1587.05	257.66
1592.38	257.729
1597.71	258.253
1603.04	258.771
1608.36	259.232
1613.68	259.33
1618.99	258.195
1624.3	256.568
1629.61	254.471
1634.91	252.057
1640.21	250.391
1645.51	250.155
1650.8	249.325
1656.08	247.465
1661.36	244.113
1666.64	240.543
1671.92	237.73
1677.19	235.392
1682.45	233.517
1687.72	233.44
1692.98	233.852
1698.23	234.288
1703.48	234.04
1708.73	233.737
1713.97	233.265
1719.21	233.183
1724.44	233.048
1729.67	232.789
1734.9	232.376
1740.12	231.701
1745.34	230.464
1750.56	228.516
1755.77	226.399
1760.98	224.021
1766.18	221.865
1771.38	221.321
1776.58	222.428
1781.77	224.142
1786.96	225.175
1792.14	225.651
1797.32	224.972
1802.5	223.431
1807.67	222.041
1812.84	221.765
1818.01	222.405
1823.17	223.624
1828.33	224.579
1833.48	223.78
1838.63	221.493
1843.77	218.016
1848.92	215.628
1854.06	215.793
1859.19	217.569
1864.32	219.515
1869.45	221.172
1874.57	222.265
1879.69	222.562
1884.8	222.312
1889.92	221.81
1895.02	221.2
1900.13	220.92
1905.23	221.256
1910.33	221.812
1915.42	222.444
1920.51	222.896
1925.59	222.808
1930.67	222.41
1935.75	222.131
1940.82	221.694
1945.9	220.479
1950.96	217.589
1956.02	216.371
1961.08	216.646
1966.14	217.244
1971.19	214.872
1976.24	214.26
1981.28	217.262
1986.32	217.458
1991.36	217.363
1996.39	217.188
2001.42	217.078
2006.45	217.168
2011.47	217.37
2016.49	216.781
2021.5	216.82
2026.51	217.783
2031.52	217.895
2036.52	216.937
2041.52	215.796
2046.52	214.726
2051.51	213.858
2056.5	213.592
2061.49	214.555
2066.47	215.743
2071.45	216.923
2076.42	216.926
2081.39	216.459
2086.36	215.469
2091.32	214.006
2096.28	212.513
2101.24	212.23
2106.19	212.152
2111.14	212.081
2116.09	211.864
2121.03	211.552
2125.97	211.184
2130.9	210.738
2135.83	210.256
2140.76	209.796
2145.68	209.541
2150.6	210.229
2155.52	210.982
2160.43	211.75
2165.34	211.895
2170.25	212.716
2175.15	213.472
2180.05	214.256
2184.95	213.686
2189.84	212.291
2194.73	210.76
2199.61	209.265
2204.49	207.931
2209.37	206.657
2214.24	206.112
2219.11	205.839
2223.98	205.802
2228.84	205.857
2233.7	206.069
2238.56	206.073
2243.41	205.42
2248.26	204.834
2253.11	204.081
2257.95	203.797
2262.79	204.012
2267.63	204.089
2272.46	203.432
2277.29	202.724
2282.11	201.545
2286.93	200.19
2291.75	199.135
2296.57	199.041
2301.38	199.098
2306.19	199.271
2310.99	199.502
2315.79	199.627
2320.59	199.51
2325.38	199.187
2330.17	198.131
2334.96	197.008
2339.74	196.22
2344.52	196.633
2349.3	197.08
2354.07	197.854
2358.84	198.849
2363.61	200.006
2368.37	201.231
2373.13	201.592
2377.89	198.891
2382.64	196.315
2387.39	194.541
2392.14	193.159
2396.88	192.168
2401.62	191.4
2406.36	191.98
2411.09	192.91
2415.82	193.794
2420.55	193.603
2425.27	192.797
2429.99	191.673
2434.7	190.427
2439.42	188.938
2444.12	187.724
2448.83	188.045
2453.53	190.167
2458.23	192.424
2462.93	194.138
2467.62	195.319
2472.31	196.105
2476.99	196.294
2481.68	196.144
2486.36	195.727
2491.03	195.13
2495.7	194.838
2500.37	194.091
2505.04	193.164
2509.7	192.129
2514.36	191.117
2519.02	190.147
2523.67	189.467
2528.32	188.353
2532.97	188.82
2537.61	191.214
2542.25	193.43
2546.88	194.684
2551.52	193.29
2556.15	189.642
2560.77	187.995
2565.4	187.874
2570.02	187.929
2574.63	187.984
2579.25	187.664
2583.86	187.367
2588.46	187.202
2593.07	187.309
2597.67	187.783
2602.27	189.585
2606.86	191.18
2611.45	191.861
2616.04	191.207
2620.62	188.986
2625.2	185.26
2629.78	181.459
2634.36	178.841
2638.93	177.136
2643.5	176.4
2648.06	176.256
2652.62	177.033
2657.18	178.151
2661.74	179.282
2666.29	179.699
2670.84	179.662
2675.38	179.579
2679.93	178.903
2684.47	178.061
2689	177.081
2693.54	176.299
2698.07	176.382
2702.59	176.934
2707.12	177.489
2711.64	178.145
2716.16	178.521
2720.67	178.332
2725.18	177.903
2729.69	177.302
2734.19	176.626
2738.7	176.269
2743.19	175.771
2747.69	175.251
2752.18	174.901
2756.67	175.223
2761.16	176.669
2765.64	175.641
2770.12	173.203
2774.6	171.437
2779.07	172.493
2783.54	174.186
2788.01	175.164
2792.47	175.896
2796.94	176.421
2801.39	174.78
2805.85	176.105
2810.3	173.074
2814.75	170.138
2819.2	173.527
2823.64	170.714
2828.08	171.811
2832.52	174.214
2836.95	175.593
2841.38	176.264
2845.81	175.881
2850.23	174.391
2854.65	173.014
2859.07	172.768
2863.49	172.826
2867.9	173.302
2872.31	174.965
2876.71	176.823
2881.12	178.426
2885.52	178.515
2889.91	177.504
2894.31	175.839
2898.7	173.878
2903.09	171.985
2907.47	170.56
2911.86	169.896
2916.23	169.966
2920.61	170.561
2924.98	171.451
2929.35	172.487
2933.72	173.409
2938.08	174.641
2942.45	175.575
2946.8	175.973
2951.16	173.781
2955.51	171.22
2959.86	168.63
2964.21	166.442
2968.55	164.295
2972.89	162.305
2977.23	160.627
2981.56	159.472
2985.89	158.867
2990.22	159.39
2994.55	160.041
2998.87	160.741
3003.19	161.27
3007.5	161.462
3011.82	161.003
3016.13	160.152
3020.44	159.121
3024.74	158.08
3029.04	157.28
3033.34	158.188
3037.64	163.152
3041.93	161.13
3046.22	156.771
3050.51	154.634
3054.79	146.024
3059.07	250.153
3063.35	406.371
3067.63	453.715
3071.9	187.699
3076.17	151.625
3080.44	162.438
3084.7	164.387
3088.96	164.253
3093.22	162.154
3097.48	159.896
3101.73	158.029
3105.98	156.796
3110.23	156.087
3114.47	155.905
3118.71	155.551
3122.95	155.668
3127.19	156.935
3131.42	158.154
3135.65	158.067
3139.87	157.517
3144.1	156.794
3148.32	155.954
3152.54	155.319
3156.75	154.948
3160.96	154.216
3165.17	153.528
3169.38	152.893
3173.58	152.268
3177.79	151.903
3181.98	152.15
3186.18	152.632
3190.37	153.185
3194.56	153.571
3198.75	153.78
3202.93	153.16
3207.12	152.47
3211.29	151.428
3215.47	150.513
3219.64	149.816
3223.81	150.568
3227.98	152.175
3232.15	153.473
3236.31	153.624
3240.47	153.257
3244.62	152.319
3248.78	150.508
3252.93	148.797
3257.08	148.201
3261.22	148.414
3265.36	148.598
3269.5	147.331
3273.64	146.264
3277.78	145.66
3281.91	145.784
3286.03	146.029
3290.16	146.982
3294.28	152.151
3298.4	153.444
3302.52	150.87
3306.64	144.85
3310.75	142.214
3314.86	142.676
3318.97	146.426
3323.07	149.546
3327.17	150.722
3331.27	150.066
3335.37	147.913
3339.46	145.153
3343.55	143.451
3347.64	142.412
3351.72	144.739
3355.8	145.639
3359.88	145.987
3363.96	146.794
3368.03	147.153
3372.1	146.273
3376.17	144.827
3380.24	142.693
3384.3	140.787
3388.36	139.833
3392.42	140.182
3396.48	141.793
3400.53	144.179
3404.58	146.114
3408.63	146.821
3412.67	146.763
3416.71	146.283
3420.75	145.505
3424.79	144.621
3428.82	144.018
3432.86	143.51
3436.88	144.302
3440.91	144.975
3444.93	144.039
3448.95	141.831
3452.97	138.7
3456.99	135.531
3461	133.094
3465.01	131.542
3469.02	131.137
3473.02	131.467
3477.02	132.877
3481.02	135.642
3485.02	138.457
3489.02	140.396
3493.01	141.335
3497	141.518
3500.98	141.022
3504.97	139.779
3508.95	137.374
3512.93	134.932
3516.9	133.41
3520.88	133.246
3524.85	133.677
3528.81	134.672
3532.78	135.768
3536.74	136.695
3540.7	137.296
3544.66	137.769
3548.62	138.079
3552.57	137.5
3556.52	136.645
3560.47	135.53
3564.41	134.879
3568.35	135.218
3572.29	135.41
3576.23	135.593
3580.17	135.268
3584.1	134.233
3588.03	133.455
3591.96	133.025
3595.88	133.671
3599.8	135.013
3603.72	137.096
3607.64	139.236
3611.55	139.508
3615.46	138.463
3619.37	136.861
3623.28	134.973
3627.18	132.67
3631.09	129.659
3634.98	126.891
3638.88	126.153
3642.77	126.452
3646.67	127.688
3650.56	129.068
3654.44	130.121
3658.33	130.833
3662.21	130.549
3666.09	129.878
3669.96	128.983
3673.84	127.874
3677.71	126.729
3681.58	126.057
3685.44	125.608
3689.31	124.376
3693.17	122.566
3697.03	122.093
3700.88	122.419
3704.74	123.163
3708.59	124.13
3712.44	125.041
3716.28	126.479
3720.13	127.793
3723.97	127.629
3727.81	127.629
3731.65	126.361
3735.48	124.616
3739.31	123.599
3743.14	122.724
3746.97	122.595
3750.79	122.792
3754.61	122.859
3758.43	122.628
3762.25	121.493
3766.06	120.117
3769.88	118.885
3773.69	120.602
3777.49	122.703
3781.3	123.794
3785.1	123.94
3788.9	123.377
3792.7	122.34
3796.49	121.228
3800.28	120.152
3804.07	119.531
3807.86	119.113
3811.65	118.841
3815.43	118.687
3819.21	118.773
3822.99	118.914
3826.76	119.572
3830.54	120.312
3834.31	118.958
3838.08	121.312
3841.84	122.43
3845.61	122.239
3849.37	121.9
3853.13	121.526
3856.88	118.576
3860.64	119.709
3864.39	118.571
3868.14	116.492
3871.88	114.682
3875.63	113.554
3879.37	113.642
3883.11	114.352
3886.85	115.194
3890.58	115.829
3894.31	116.233
3898.05	116.552
3901.77	116.025
3905.5	115.127
3909.22	114.274
3912.94	113.721
3916.66	113.549
3920.38	113.458
3924.09	113.448
3927.8	113.421
3931.51	113.308
3935.22	112.992
3938.92	112.496
3942.62	111.742
3946.32	110.996
3950.02	110.065
3953.72	109.161
3957.41	108.387
3961.1	107.895
3964.79	107.662
3968.47	107.525
3972.16	107.38
3975.84	107.123
3979.51	106.881
3983.19	106.476
3986.87	105.258
3990.54	103.427
3994.21	103.844
3997.87	108.116
3999.71	107.206