File: Data/Raman/raw/bu19ts(2)-ore2-rim_1800 (450-850nm)_532nm_edge_10%_x100_vis_h30um_60sx2_01.txt
#Acq. time (s)=	60
#Accumulations=	2
#Range (cm-¹)=	100...1030
#Windows=	2
#Auto scanning=	Off
#Autofocus=	Off
#Macrospot=	Off
#AutoExposure=	Off
#Spike filter=	Multiple accum.
#Delay time (s)=	2
#Binning=	1
#Readout mode=	Signal
#DeNoise=	Standard
#ICS correction=	On
#Dark correction=	Off
#Inst. Process=	Off
#Detector Gain=	Best Dynamic
#Detector ADC=	50 kHz EM
#Detector EM gain=	100
#Detector temperature (°C)=	-60.09
#Instrument=	LabRAM HR Evol
#Detector=	SIN-EM FIVIS
#Objective=	x100_VIS
#Grating=	1800 (450-850nm)
#ND Filter=	10%
#Laser=	532nm_Edge
#Hole=	30.0125
#Temperature=	0
#Range=	Visible
#StageXY=	75x50mm Scan+
#StageZ=	Z motor
#X (µm)=	0
#Y (µm)=	0
#Z (µm)=	332.4
#Full time(mm:ss)=	4:17
#Project=	23022021
#Sample=
#Site=
#Title=	BU19TS(2)-Ore2-rim_1800 (450-850nm)_532nm_Edge_10%_x100_VIS_H30um_60sX2
#Remark=
#Date=	23.02.2021 10:34
#Acquired=	23.02.2021 10:34:41
100.304	714.907
101.27	710.081
102.233	704.301
103.198	704.222
104.162	704.643
105.127	706.725
106.09	709.265
107.052	711.513
108.017	708.555
108.98	703.976
109.942	698.207
110.907	698.512
111.869	703.682
112.831	706.152
113.793	707.467
114.757	710.459
115.719	703.625
116.681	700.043
117.643	701.993
118.604	704.427
119.566	705.596
120.529	706.75
121.491	707.318
122.452	707.014
123.413	704.352
124.374	706.041
125.335	702.474
126.296	693.761
127.256	691.413
128.217	696.849
129.178	698.834
130.138	712.372
131.098	694.137
132.059	686.566
133.016	715.281
133.977	720.579
134.936	711.131
135.896	710.073
136.856	711.235
137.816	711.255
138.773	704.28
139.732	701.096
140.692	698.214
141.651	695.565
142.608	698.447
143.567	693.284
144.526	691.221
145.483	690.249
146.441	689.425
147.4	677.657
148.356	672.898
149.315	678.384
150.271	693.654
151.229	693.843
152.185	689.124
153.143	678.775
154.099	675.676
155.057	673.378
156.013	673.615
156.97	672.803
157.926	671.56
158.883	667.345
159.838	663.832
160.794	659.688
161.751	658.693
162.706	663.663
163.66	657.321
164.617	652.556
165.572	655.531
166.527	660.339
167.481	662.282
168.437	660.801
169.392	660.341
170.346	652.94
171.3	648.482
172.254	649.772
173.21	655.235
174.164	661.163
175.117	661.102
176.071	660.751
177.024	660.049
177.978	659.475
178.931	660.599
179.884	663.105
180.837	663.449
181.79	668.209
182.743	669.527
183.696	664.387
184.649	662.692
185.601	670.15
186.554	666.977
187.504	663.68
188.456	660.076
189.408	659.621
190.361	663.449
191.313	673.788
192.262	673.265
193.214	670.321
194.166	669.364
195.118	669.833
196.067	665.04
197.018	662.988
197.97	666.987
198.919	672.452
199.87	677.691
200.821	677.577
201.77	672.919
202.721	670.917
203.669	672.351
204.62	676.612
205.568	680.646
206.519	677.133
207.467	675.715
208.417	674.637
209.365	675.248
210.315	677.855
211.263	673.459
212.213	670.401
213.161	673.612
214.108	673.346
215.058	664.809
216.005	664.904
216.953	673.288
217.902	675.538
218.849	675.003
219.796	676.712
220.743	675.608
221.692	676.296
222.639	677.386
223.585	682.956
224.532	681.405
225.478	680.559
226.424	689.609
227.371	700.455
228.319	701.899
229.265	697.796
230.211	691.604
231.157	686.535
232.102	688.65
233.048	703.646
233.994	711.315
234.939	721.538
235.884	724.07
236.827	716.581
237.773	702.304
238.718	694.003
239.663	694.524
240.608	694.579
241.552	698.985
242.497	701.666
243.439	706.629
244.384	710.298
245.328	713.307
246.273	708.943
247.215	703.811
248.159	701.989
249.103	704.645
250.045	712.436
250.988	716.986
251.932	716.348
252.874	714.449
253.817	714.303
254.761	714.95
255.702	713.49
256.645	719.136
257.586	715.481
258.529	717.894
259.47	724.008
260.413	726.075
261.354	724.937
262.294	721.196
263.237	708.555
264.177	709.488
265.119	727.484
266.06	728.415
267	720.623
267.942	713.293
268.882	707.105
269.822	708.777
270.761	709.802
271.703	703.142
272.642	705.694
273.582	716.893
274.521	723.116
275.46	730.543
276.402	730.632
277.341	717.866
278.28	709.89
279.218	712.324
280.157	719.089
281.096	724.052
282.034	727.303
282.973	730.485
283.911	730.462
284.85	724.078
285.788	715.577
286.726	710.968
287.664	713.225
288.602	727.807
289.539	728.096
290.477	730.779
291.413	735.033
292.35	732.813
293.288	728.836
294.225	729.726
295.162	733.173
296.097	730.093
297.034	725.654
297.971	730.86
298.908	735.632
299.843	730.693
300.779	726.875
301.716	725.246
302.65	725.838
303.587	722.608
304.521	717.049
305.457	721.881
306.393	726.038
307.327	711.883
308.263	709.988
309.197	714.352
310.133	718.776
311.066	713.013
312.002	709.241
312.935	700.417
313.868	694.526
314.803	689.136
315.736	689.226
316.669	695.599
317.604	690.959
318.537	688.197
319.47	685.256
320.405	683.302
321.337	682.514
322.269	683.957
323.202	683.61
324.136	678.277
325.068	664.742
326	659.492
326.932	662.784
327.864	669.969
328.796	677.312
329.727	681.198
330.659	678.646
331.592	677.887
332.524	675.626
333.455	674.273
334.386	675.835
335.317	673.758
336.246	671.262
337.177	659.718
338.108	651.445
339.039	651.424
339.969	658.255
340.9	669.002
341.83	672.193
342.761	673.303
343.689	673.564
344.619	672.529
345.549	669.487
346.479	665.227
347.407	664.466
348.336	670.725
349.266	672.101
350.196	668.2
351.123	668.466
352.053	669.819
352.98	669.282
353.909	665.619
354.838	666.996
355.765	665.783
356.694	663.976
357.621	659.195
358.55	658.257
359.476	662.097
360.405	672.748
361.331	679.102
362.259	683.34
363.186	682.26
364.112	676.838
365.04	676.251
365.966	675.911
366.892	681.005
367.819	687.528
368.745	688.552
369.671	690.174
370.598	690.806
371.523	691.287
372.449	699.392
373.374	702.413
374.299	697.372
375.226	689.908
376.151	685.911
377.076	684.426
378	692.746
378.925	704.868
379.85	710.978
380.774	714.222
381.698	713.795
382.623	712.546
383.547	706.363
384.471	699.009
385.395	702.257
386.319	712.127
387.243	719.196
388.166	718.466
389.09	718.477
390.013	718.554
390.935	720.005
391.858	723.815
392.781	726.019
393.704	724.849
394.627	723.335
395.548	723.194
396.471	726.394
397.394	730.652
398.315	731.013
399.237	725.528
400.16	722.791
401.08	723.252
402.002	727.251
402.924	731.328
403.845	729.464
404.767	727.401
405.686	730.09
406.608	734
407.528	738.544
408.45	743.91
409.369	745.818
410.291	746.628
411.21	748.227
412.129	746.033
413.05	742.43
413.969	743.992
414.89	749.58
415.809	756.132
416.728	760.546
417.647	760.402
418.567	760.596
419.486	756.517
420.404	751.508
421.323	747.253
422.243	754.813
423.161	757.785
424.079	760.962
424.997	758.424
425.915	756.695
426.833	755.702
427.75	756.173
428.668	756.563
429.585	757.369
430.503	759.956
431.42	761.813
432.337	757.871
433.254	754.338
434.171	754.734
435.088	758.681
436.005	764.303
436.922	767.402
437.839	766.116
438.755	761.292
439.669	759.294
440.586	762.997
441.502	768.943
442.418	770.385
443.332	767.073
444.248	760.102
445.164	752.164
446.08	749.896
446.994	759.635
447.91	773.28
448.825	774.979
449.739	775.754
450.654	769.599
451.567	765.608
452.482	767.833
453.395	772.352
454.31	775.395
455.223	778.439
456.138	780.5
457.051	781.766
457.965	783.244
458.878	781.888
459.792	785.715
460.705	796.288
461.617	798.588
462.531	795.146
463.443	787.287
464.355	788.884
465.267	794.735
466.181	791.716
467.093	788.508
468.004	793.718
468.916	806.36
469.829	800.365
470.74	794.918
471.652	801.586
472.563	803.113
473.474	798.492
474.385	801.709
475.296	794.49
476.207	803.558
477.117	803.428
478.028	811.729
478.938	809.323
479.849	803.847
480.759	801.538
481.669	805.995
482.579	797.913
483.49	791.966
484.399	796.282
485.309	794.027
486.217	801.189
487.127	804.033
488.036	804.644
488.946	802.232
489.855	798.378
490.763	799.885
491.672	800.768
492.581	804.985
493.488	803.118
494.397	801.663
495.306	793.603
496.213	795.827
497.121	794.489
498.028	795.722
498.936	796.277
499.843	790.095
500.751	775.277
501.659	776.966
502.566	788.66
503.472	781.615
504.38	795.795
505.285	789.699
506.193	781.289
507.099	775.25
508.004	774.402
508.912	776.631
509.817	779.43
510.723	782.438
511.63	784.965
512.535	780.508
513.44	776.239
514.345	776.433
515.252	779.954
516.157	788.917
517.061	784.654
517.966	775.667
518.871	774.645
519.775	771.07
520.679	768.937
521.584	768.534
522.488	769.744
523.392	769.883
524.296	766.064
525.2	763.347
526.103	760.353
527.007	760.279
527.911	764.119
528.814	765.543
529.718	767.426
530.621	772.052
531.524	776.982
532.427	782.711
533.328	784.183
534.231	774.297
535.134	764.505
536.037	763.453
536.938	766.948
537.84	771.233
538.743	778.435
539.643	780.701
540.546	774.948
541.448	775.998
542.348	774.774
543.25	762.586
544.15	759.411
545.052	762.929
545.952	771.917
546.854	780.392
547.753	779.374
548.655	776.106
549.554	770.617
550.456	772.212
551.355	775.775
552.256	772.516
553.155	769.54
554.054	775.81
554.955	778.257
555.854	782.201
556.753	789.546
557.651	785.675
558.552	787.297
559.45	795.681
560.349	799.644
561.247	798.78
562.145	793.849
563.045	788.58
563.943	787.664
564.841	795.927
565.739	804.318
566.637	808.878
567.535	810.063
568.432	809.805
569.33	809.158
570.227	806.804
571.124	805.772
572.022	808.966
572.919	811.941
573.816	814.09
574.713	814.763
575.61	812.128
576.504	807.991
577.401	812.279
578.298	825.97
579.194	836.479
580.091	841.213
580.985	841.456
581.881	839.235
582.777	842.861
583.671	849.939
584.567	850.422
585.463	854.082
586.357	861.872
587.253	858.992
588.148	856.904
589.042	861.349
589.938	872.827
590.831	882.242
591.726	894.574
592.619	901.985
593.514	900.679
594.407	899.635
595.26	903.867
596.165	905.627
597.068	914.529
597.972	926.398
598.875	929.26
599.78	927.423
600.682	934.522
601.585	944.188
602.489	949.349
603.391	948.811
604.293	951.326
605.195	960.347
606.099	968.001
607.001	967.504
607.903	970.074
608.805	974.24
609.706	981.056
610.61	987.875
611.511	984.82
612.412	980.541
613.314	986.543
614.215	1000.19
615.116	1004.58
616.017	1008.31
616.918	1010.55
617.818	1021.24
618.719	1025.25
619.62	1021.93
620.52	1021.57
621.421	1030.92
622.321	1041.55
623.221	1053.84
624.121	1059.04
625.021	1055
625.921	1043.22
626.819	1037.17
627.719	1037.83
628.619	1039.36
629.518	1040.86
630.418	1044.9
631.315	1055.42
632.215	1056.4
633.114	1051.61
634.011	1055.08
634.91	1066.2
635.809	1063.89
636.706	1058.51
637.605	1055.07
638.504	1052.25
639.4	1038.85
640.299	1030.62
641.195	1034.05
642.094	1048.6
642.99	1067.88
643.888	1057.36
644.784	1046.87
645.682	1042.09
646.578	1043.75
647.474	1048.11
648.372	1059.63
649.267	1050.72
650.165	1039.29
651.06	1034.76
651.956	1034.5
652.853	1032.98
653.748	1026.65
654.643	1023.04
655.539	1022.55
656.435	1026.41
657.33	1012.95
658.225	1010.71
659.12	998.618
660.014	995.04
660.909	990.816
661.805	987.656
662.7	983.934
663.594	985.369
664.488	984.77
665.382	976.973
666.276	967.361
667.17	962.096
668.064	955.989
668.957	944.558
669.851	933.181
670.745	931.435
671.638	928.383
672.529	930.786
673.423	926.693
674.316	913.761
675.209	903.235
676.102	895.672
676.995	891.157
677.886	885.624
678.779	882.303
679.671	876.214
680.564	868.434
681.454	863.465
682.347	859.089
683.239	856.797
684.129	855.121
685.021	849.273
685.913	841.62
686.803	834.434
687.695	830.849
688.585	830.743
689.477	827.68
690.366	823.301
691.258	817.566
692.147	816.314
693.038	812.233
693.928	810.046
694.819	813.405
695.708	808.868
696.597	804.243
697.488	791.935
698.377	782.024
699.267	779.16
700.156	781.697
701.045	782.658
701.933	776.724
702.823	778.665
703.712	770.81
704.6	761.712
705.488	741.033
706.378	737.943
707.266	741.726
708.154	752.341
709.042	748.997
709.929	744.613
710.817	741.935
711.704	739.677
712.592	742.999
713.479	739.7
714.366	733.417
715.254	727.391
716.141	722.357
717.028	713.967
717.914	712.979
718.801	715.704
719.688	716.76
720.575	714.174
721.461	709.481
722.348	700.151
723.232	699.631
724.118	704.452
725.005	703.466
725.891	700.825
726.777	700.973
727.661	695.869
728.546	687.645
729.432	681.24
730.316	677.542
731.201	682.821
732.087	691.956
732.97	678.157
733.856	670.62
734.739	672.286
735.624	656.769
736.509	649.144
737.392	652.084
738.277	657.581
739.16	660.941
740.045	670.92
740.927	663.735
741.81	655.751
742.694	653.845
743.577	656.151
744.461	660.476
745.343	665.072
746.225	669.372
747.109	662.515
747.991	655.352
748.873	653.269
749.755	654.322
750.639	649.815
751.52	643.941
752.402	638.518
753.283	638.191
754.165	640.741
755.048	653.407
755.929	653.892
756.81	653.664
757.691	647.434
758.572	648.134
759.453	647.346
760.334	641.693
761.214	639.088
762.095	636.685
762.975	638.67
763.856	642.308
764.736	640.684
765.616	630.853
766.497	630
767.377	636.04
768.255	637.594
769.135	643.113
770.014	641.01
770.894	635.147
771.774	628.451
772.651	630.159
773.531	637.731
774.41	640.561
775.289	638.748
776.167	637.264
777.046	637.732
777.925	641.482
778.802	644.442
779.681	639.37
780.557	632.375
781.436	629.8
782.315	627.991
783.191	629.685
784.07	628.792
784.946	635.687
785.824	625.099
786.701	617.168
787.577	621.65
788.455	630.812
789.331	632.402
790.208	639.49
791.084	640.719
791.96	633.785
792.838	632.197
793.713	635.769
794.588	642.426
795.466	640.61
796.341	639.392
797.216	633.52
798.091	633.931
798.966	638.905
799.843	639.247
800.718	637.555
801.593	633.724
802.467	631.674
803.342	632.667
804.217	634.237
805.091	635.915
805.965	636.712
806.84	637.707
807.714	633.731
808.588	631.928
809.462	630.363
810.336	627.429
811.209	625.703
812.083	626.686
812.957	634.519
813.83	627.951
814.702	624.88
815.575	627.687
816.449	630.085
817.322	628.248
818.195	624.528
819.066	626.181
819.939	629.68
820.812	633.485
821.685	630.942
822.555	628.81
823.428	632.678
824.299	636.397
825.171	636.604
826.043	629.964
826.914	625.876
827.786	626.245
828.656	631.953
829.528	637.525
830.398	637.872
831.27	635.068
832.14	633.026
833.012	630.137
833.881	625.638
834.751	624.118
835.622	624.148
836.492	620.566
837.363	617.381
838.232	617.153
839.101	620.058
839.97	621.066
840.841	616.776
841.71	612.237
842.579	615.569
843.448	611.283
844.316	610.904
845.187	607.475
846.055	604.04
846.924	601.739
847.792	604.391
848.66	595.255
849.528	591.383
850.396	592.842
851.264	593.016
852.132	593.917
853	594.434
853.868	592.522
854.735	588.019
855.603	584.68
856.47	582.506
857.338	584.368
858.205	580.893
859.072	576.64
859.937	570.729
860.804	566.804
861.671	565.898
862.538	563.602
863.403	562.455
864.27	560.435
865.136	559.581
866.003	558.878
866.867	555.309
867.734	550.892
868.6	547.262
869.464	544.068
870.33	541.827
871.194	539.667
872.06	539.154
872.924	539.828
873.79	539.943
874.654	540.987
875.519	540.42
876.383	539.251
877.248	535.851
878.112	536.818
878.977	531.907
879.84	521.841
880.704	515.132
881.569	516.247
882.432	513.879
883.294	512.249
884.159	510.451
885.022	507.409
885.885	503.587
886.747	503.627
887.61	502.757
888.474	499.592
889.336	502.701
890.199	504.018
891.061	504.129
891.923	504.131
892.785	503.369
893.647	501.879
894.509	496.859
895.37	492.672
896.232	492.211
897.094	494.224
897.955	496.718
898.817	497.179
899.678	493.036
900.539	487.615
901.4	486.489
902.261	484.353
903.122	482.204
903.981	479.138
904.842	479
905.703	478.925
906.564	479.304
907.424	479.346
908.283	481.102
909.143	483.138
910.003	483.977
910.862	482.167
911.722	478.125
912.582	474.353
913.44	475.052
914.3	476.866
915.158	479.973
916.018	481.409
916.875	482.185
917.735	477.869
918.593	473.921
919.452	469.705
920.309	467.593
921.169	469.018
922.026	474.114
922.885	473.941
923.742	475.062
924.599	475.603
925.458	472.108
926.315	470.606
927.171	466.831
928.028	463.94
928.887	462.903
929.743	457.702
930.599	457.099
931.456	464.528
932.312	468.67
933.17	466.953
934.026	463.883
934.882	460.538
935.738	458.731
936.594	460.391
937.45	462.344
938.305	466.345
939.161	467.329
940.016	465.21
940.872	464.196
941.727	465.359
942.583	466.284
943.438	466.589
944.293	466.117
945.148	465.314
946.001	464.006
946.856	461.342
947.71	459.342
948.565	455.289
949.42	450.629
950.272	452.009
951.127	455.555
951.981	460.64
952.833	460.105
953.688	462.203
954.542	457.304
955.394	453.772
956.248	455.318
957.102	458.517
957.953	459.074
958.807	459.18
959.659	455.718
960.512	449.676
961.364	446.688
962.217	451.419
963.069	454.205
963.92	454.735
964.773	454.37
965.624	457.997
966.477	454.088
967.328	450.083
968.179	447.962
969.032	447.204
969.882	445.406
970.733	445.491
971.584	446.949
972.436	450.376
973.286	449.867
974.137	451.398
974.987	451.935
975.837	450.457
976.687	450.496
977.537	453.494
978.389	450.181
979.239	446.561
980.088	445.311
980.938	445.599
981.788	441.573
982.637	442.119
983.487	446.107
984.336	450.252
985.183	451.641
986.032	448.092
986.881	443.774
987.73	439.638
988.579	440.847
989.428	443.402
990.277	444.99
991.124	447.176
991.972	439.775
992.821	439.141
993.669	442.924
994.516	443.351
995.364	445.096
996.212	446.112
997.058	446.817
997.906	446.983
998.752	446.463
999.6	447.158
1000.45	447.835
1001.29	447.004
1002.14	444.227
1002.99	439.49
1003.83	435.219
1004.68	436.506
1005.53	441.158
1006.37	445.749
1007.22	448.469
1008.06	447.224
1008.91	446.043
1009.75	445.467
1010.6	444.012
1011.45	443.203
1012.29	441.087
1013.14	437.133
1013.98	435.281
1014.83	436.43
1015.67	439.263
1016.52	441.272
1017.36	438.76
1018.2	440.806
1019.05	439.031
1019.89	429.463
1020.74	430.838
1021.58	446.043
1022.43	451.186
1023.27	450.187
1024.11	447.885
1024.96	443.745
1025.8	440.486
1026.64	438.419
1027.48	437.047
1028.33	436.054
1028.89	432.187