File: Data/Raman/raw/bu19ts(2)-ore2-core_1800 (450-850nm)_532nm_edge_10%_x100_vis_h30um_60sx2_01.txt
#Acq. time (s)=	60
#Accumulations=	2
#Range (cm-¹)=	100...1030
#Windows=	2
#Auto scanning=	Off
#Autofocus=	Off
#Macrospot=	Off
#AutoExposure=	Off
#Spike filter=	Multiple accum.
#Delay time (s)=	2
#Binning=	1
#Readout mode=	Signal
#DeNoise=	Standard
#ICS correction=	On
#Dark correction=	Off
#Inst. Process=	Off
#Detector Gain=	Best Dynamic
#Detector ADC=	50 kHz EM
#Detector EM gain=	100
#Detector temperature (°C)=	-60.09
#Instrument=	LabRAM HR Evol
#Detector=	SIN-EM FIVIS
#Objective=	x100_VIS
#Grating=	1800 (450-850nm)
#ND Filter=	10%
#Laser=	532nm_Edge
#Hole=	30.0125
#Temperature=	0
#Range=	Visible
#StageXY=	75x50mm Scan+
#StageZ=	Z motor
#X (µm)=	0
#Y (µm)=	0
#Z (µm)=	332.9
#Full time(mm:ss)=	4:12
#Project=	23022021
#Sample=
#Site=
#Title=	BU19TS(2)-Ore2-core_1800 (450-850nm)_532nm_Edge_10%_x100_VIS_H30um_60sX2
#Remark=
#Date=	23.02.2021 10:27
#Acquired=	23.02.2021 10:27:30
100.304	732.15
101.27	728.554
102.233	739.008
103.198	748.749
104.162	749.066
105.127	746.662
106.09	759.742
107.052	759.189
108.017	753.757
108.98	747.895
109.942	743.585
110.907	746.839
111.869	757.873
112.831	760.477
113.793	766.144
114.757	767.294
115.719	766.741
116.681	767.93
117.643	760.729
118.604	751.863
119.566	746.288
120.529	747.072
121.491	758.111
122.452	765.789
123.413	768.451
124.374	765.251
125.335	758.793
126.296	753.298
127.256	752.705
128.217	756.63
129.178	762.288
130.138	765.772
131.098	763.787
132.059	763.328
133.016	769.743
133.977	775.402
134.936	777.609
135.896	788.596
136.856	798.779
137.816	791.83
138.773	780.718
139.732	761.313
140.692	755.165
141.651	753.591
142.608	750.073
143.567	746.889
144.526	742.283
145.483	737.645
146.441	742.035
147.4	744.954
148.356	741.692
149.315	738.011
150.271	735.885
151.229	734.789
152.185	731.539
153.143	719.994
154.099	708.244
155.057	716.391
156.013	711.237
156.97	706.156
157.926	701.97
158.883	694.977
159.838	692.486
160.794	699.596
161.751	704.781
162.706	712.651
163.66	711.615
164.617	708.455
165.572	713.141
166.527	713.416
167.481	716.073
168.437	711.345
169.392	706.507
170.346	702.051
171.3	704.594
172.254	698.499
173.21	696.07
174.164	702.801
175.117	707.824
176.071	708.199
177.024	710.381
177.978	714.495
178.931	721.727
179.884	720.591
180.837	723.7
181.79	726.949
182.743	721.231
183.696	714.964
184.649	728.165
185.601	732.034
186.554	732.039
187.504	735.967
188.456	743.478
189.408	721.805
190.361	724.935
191.313	737.788
192.262	742.152
193.214	736.845
194.166	743.168
195.118	749.164
196.067	742.597
197.018	738.696
197.97	745.379
198.919	739.367
199.87	738.701
200.821	747.273
201.77	758.33
202.721	763.354
203.669	763.061
204.62	766.283
205.568	769.534
206.519	772.829
207.467	766.784
208.417	755.69
209.365	751.615
210.315	746.266
211.263	745.008
212.213	750.209
213.161	751.82
214.108	756.272
215.058	762.034
216.005	755.153
216.953	752.764
217.902	755.734
218.849	762.962
219.796	758.923
220.743	763.877
221.692	772.291
222.639	769.613
223.585	769.267
224.532	767.415
225.478	768.039
226.424	771.641
227.371	768.136
228.319	776.731
229.265	774.346
230.211	773.822
231.157	762.731
232.102	777.155
233.048	780.989
233.994	780.052
234.939	786.94
235.884	791.34
236.827	797.19
237.773	796.929
238.718	793.983
239.663	789.454
240.608	793.639
241.552	802.256
242.497	816.546
243.439	817.735
244.384	814.561
245.328	808.445
246.273	808.255
247.215	811.08
248.159	817.188
249.103	831.743
250.045	827.564
250.988	806.996
251.932	806.824
252.874	814.513
253.817	818.242
254.761	820.201
255.702	812.603
256.645	816.913
257.586	827.679
258.529	833.325
259.47	827.594
260.413	820.679
261.354	815.995
262.294	803.29
263.237	801.203
264.177	810.277
265.119	818.511
266.06	810.309
267	798.605
267.942	808.078
268.882	814.391
269.822	808.847
270.761	812.647
271.703	818.099
272.642	811.898
273.582	811.039
274.521	808.364
275.46	810.795
276.402	806.072
277.341	802.023
278.28	804.149
279.218	809.401
280.157	815.335
281.096	820.492
282.034	821.255
282.973	817.499
283.911	815.038
284.85	815.409
285.788	813.288
286.726	818.306
287.664	821.275
288.602	819.005
289.539	815.81
290.477	817.965
291.413	821.339
292.35	819.687
293.288	819.509
294.225	816.807
295.162	814.887
296.097	813.848
297.034	819.78
297.971	830.516
298.908	835.995
299.843	832.62
300.779	830.515
301.716	825.883
302.65	824.764
303.587	827.265
304.521	826.613
305.457	825.491
306.393	829.018
307.327	822.409
308.263	810.661
309.197	803.725
310.133	801.837
311.066	804.606
312.002	806.079
312.935	803.745
313.868	788.354
314.803	775.694
315.736	774.635
316.669	784.437
317.604	773.005
318.537	760.552
319.47	751.333
320.405	741.32
321.337	741.832
322.269	750.321
323.202	750.322
324.136	740.474
325.068	735.329
326	738.844
326.932	741.551
327.864	749.007
328.796	748.239
329.727	739.426
330.659	732.154
331.592	731.081
332.524	731.213
333.455	727.892
334.386	725.842
335.317	723.344
336.246	725.826
337.177	731.883
338.108	740.073
339.039	749.073
339.969	749.516
340.9	749.283
341.83	747.275
342.761	738.622
343.689	736.78
344.619	740.286
345.549	744.989
346.479	748.046
347.407	748.012
348.336	740.29
349.266	740.574
350.196	741.865
351.123	743.14
352.053	741.516
352.98	739.509
353.909	742.274
354.838	744.676
355.765	747.512
356.694	749.527
357.621	750.493
358.55	757.661
359.476	761.474
360.405	761.255
361.331	761.147
362.259	757.981
363.186	754.668
364.112	748.292
365.04	749.451
365.966	752.944
366.892	760.8
367.819	761.143
368.745	760.668
369.671	760.492
370.598	762.918
371.523	763.091
372.449	766.193
373.374	769.866
374.299	771.103
375.226	763.581
376.151	769.356
377.076	775.449
378	775.373
378.925	771.474
379.85	775.252
380.774	773.148
381.698	770.212
382.623	766.863
383.547	776.167
384.471	765.31
385.395	772.077
386.319	785.363
387.243	789.715
388.166	786.844
389.09	785.31
390.013	776.549
390.935	779.977
391.858	789.428
392.781	793.692
393.704	795.89
394.627	795.842
395.548	796.995
396.471	805.489
397.394	811.244
398.315	823.735
399.237	820.811
400.16	812.369
401.08	806.562
402.002	813.799
402.924	818.413
403.845	812.053
404.767	812.164
405.686	813.017
406.608	824.473
407.528	831.596
408.45	833.428
409.369	835.166
410.291	838.663
411.21	833.904
412.129	827.685
413.05	831.594
413.969	839.425
414.89	848.867
415.809	852.63
416.728	858.6
417.647	870.155
418.567	878.867
419.486	882.164
420.404	879.445
421.323	867.613
422.243	863.177
423.161	863.318
424.079	871.543
424.997	881.284
425.915	884.622
426.833	882.899
427.75	879.882
428.668	874.363
429.585	872.098
430.503	879.537
431.42	894.903
432.337	896.877
433.254	897.25
434.171	900.17
435.088	900.534
436.005	907.981
436.922	908.455
437.839	895.921
438.755	895.48
439.669	895.535
440.586	912.465
441.502	887.216
442.418	883.895
443.332	893.241
444.248	888.534
445.164	892.42
446.08	894.572
446.994	897.577
447.91	901.127
448.825	900.86
449.739	900.147
450.654	898.838
451.567	904.759
452.482	913.775
453.395	915.71
454.31	919.543
455.223	918.396
456.138	913.426
457.051	911.888
457.965	918.621
458.878	914.289
459.792	909.005
460.705	903.654
461.617	910.407
462.531	900.643
463.443	907.683
464.355	917.028
465.267	928.536
466.181	927.76
467.093	930.081
468.004	922.939
468.916	921.521
469.829	923.736
470.74	936.137
471.652	937.308
472.563	931.627
473.474	928.779
474.385	923.084
475.296	923.682
476.207	925.97
477.117	930.904
478.028	935.825
478.938	939.125
479.849	941.228
480.759	945.064
481.669	944.112
482.579	940.628
483.49	934.712
484.399	934.532
485.309	934.04
486.217	932.714
487.127	940.804
488.036	938.215
488.946	937.199
489.855	935.944
490.763	932.654
491.672	924.222
492.581	934.844
493.488	947.029
494.397	933.649
495.306	927.42
496.213	916.303
497.121	917.036
498.028	920.612
498.936	921.281
499.843	917.193
500.751	906.352
501.659	901.729
502.566	905.212
503.472	907.402
504.38	895.532
505.285	890.094
506.193	894.226
507.099	904.838
508.004	907.476
508.912	907.784
509.817	906.2
510.723	900.676
511.63	891.33
512.535	884.002
513.44	876.505
514.345	872.692
515.252	870.349
516.157	872.704
517.061	876.724
517.966	876.015
518.871	880.921
519.775	882.831
520.679	879.686
521.584	875.813
522.488	869.994
523.392	868.677
524.296	866.732
525.2	868.261
526.103	870.423
527.007	868.714
527.911	868.682
528.814	871.429
529.718	875.254
530.621	871.554
531.524	869.243
532.427	867.002
533.328	882.739
534.231	877.175
535.134	876.789
536.037	874.625
536.938	876.96
537.84	877.586
538.743	874.405
539.643	874.656
540.546	880.113
541.448	876.544
542.348	869.995
543.25	871.158
544.15	879.8
545.052	876.911
545.952	880.087
546.854	895.193
547.753	893.773
548.655	891.824
549.554	888.064
550.456	892.881
551.355	894.902
552.256	883.453
553.155	890.792
554.054	902.79
554.955	918.176
555.854	920.816
556.753	913.555
557.651	919.295
558.552	924.207
559.45	932.124
560.349	921.575
561.247	914.879
562.145	915.982
563.045	926.607
563.943	938.844
564.841	944.469
565.739	956.725
566.637	958.902
567.535	957.877
568.432	960.743
569.33	961.368
570.227	956.71
571.124	966.184
572.022	982.597
572.919	998.145
573.816	1006.84
574.713	1010.37
575.61	1012.91
576.504	1020.72
577.401	1028.6
578.298	1029.92
579.194	1027.77
580.091	1034.97
580.985	1045.5
581.881	1059.81
582.777	1067.53
583.671	1074.33
584.567	1080.28
585.463	1085.07
586.357	1092.28
587.253	1104.56
588.148	1109.64
589.042	1116.36
589.938	1127.45
590.831	1136.24
591.726	1142.66
592.619	1153.76
593.514	1164.9
594.407	1172.58
595.26	1181.76
596.165	1198.67
597.068	1201.76
597.972	1209.62
598.875	1222.62
599.78	1235.25
600.682	1245.82
601.585	1250.13
602.489	1257.97
603.391	1268.41
604.293	1291.27
605.195	1310.19
606.099	1318.48
607.001	1315.82
607.903	1314.74
608.805	1318.49
609.706	1327.79
610.61	1342.87
611.511	1355.9
612.412	1360.77
613.314	1367.67
614.215	1373.5
615.116	1369.86
616.017	1375.96
616.918	1372.62
617.818	1367.25
618.719	1355.09
619.62	1352.46
620.52	1349.66
621.421	1345.83
622.321	1329.8
623.221	1323.42
624.121	1324.91
625.021	1335.24
625.921	1345.53
626.819	1338.17
627.719	1318.23
628.619	1301.14
629.518	1294.12
630.418	1280.09
631.315	1278.81
632.215	1281.18
633.114	1286.14
634.011	1280.2
634.91	1271.39
635.809	1267.55
636.706	1269.93
637.605	1270.88
638.504	1267.21
639.4	1260.69
640.299	1250.3
641.195	1241.71
642.094	1236.58
642.99	1230.82
643.888	1227.61
644.784	1224.55
645.682	1219.75
646.578	1218.42
647.474	1226.08
648.372	1239.19
649.267	1243.97
650.165	1243.09
651.06	1236.61
651.956	1226.92
652.853	1206.52
653.748	1208.22
654.643	1211.11
655.539	1205.61
656.435	1197.23
657.33	1187.71
658.225	1175.71
659.12	1161.67
660.014	1147.39
660.909	1159.52
661.805	1167.73
662.7	1156.96
663.594	1139.91
664.488	1128.93
665.382	1101.93
666.276	1104.26
667.17	1098.23
668.064	1091.49
668.957	1083.59
669.851	1070.84
670.745	1058.35
671.638	1047.46
672.529	1038.45
673.423	1051.76
674.316	1027.15
675.209	993.478
676.102	990.566
676.995	1010.18
677.886	1012.73
678.779	1002.93
679.671	988.791
680.564	973.815
681.454	960.126
682.347	953.539
683.239	956.533
684.129	956.794
685.021	950.222
685.913	937.457
686.803	917.626
687.695	904.009
688.585	898.253
689.477	902.883
690.366	903.333
691.258	895.471
692.147	880.151
693.038	870.798
693.928	865.191
694.819	859.029
695.708	866.762
696.597	854.218
697.488	845.672
698.377	843.924
699.267	834.468
700.156	827.285
701.045	826.431
701.933	824.148
702.823	826.799
703.712	829.021
704.6	825.473
705.488	821.129
706.378	816.088
707.266	810.977
708.154	804.986
709.042	797.043
709.929	786.23
710.817	781.403
711.704	784.05
712.592	791.861
713.479	788.077
714.366	781.703
715.254	769.812
716.141	762.24
717.028	759.721
717.914	759.159
718.801	757.139
719.688	755.179
720.575	756.074
721.461	758.926
722.348	752.735
723.232	746.696
724.118	741.924
725.005	739.683
725.891	732.828
726.777	728.379
727.661	731.44
728.546	737.017
729.432	733.739
730.316	728.431
731.201	728.528
732.087	728.28
732.97	726.877
733.856	724.745
734.739	716.247
735.624	715.394
736.509	721.57
737.392	716.289
738.277	717.601
739.16	716.904
740.045	708.446
740.927	705.87
741.81	708.653
742.694	713.718
743.577	703.917
744.461	693.879
745.343	691.998
746.225	697.552
747.109	704.388
747.991	706.773
748.873	698.441
749.755	686.426
750.639	679.539
751.52	683.19
752.402	687.216
753.283	685.276
754.165	677.348
755.048	671.192
755.929	675.491
756.81	681.339
757.691	680.214
758.572	685.221
759.453	689.988
760.334	689.011
761.214	685.147
762.095	681.53
762.975	677.692
763.856	676.568
764.736	677.674
765.616	677.162
766.497	678.073
767.377	676.967
768.255	669.164
769.135	668.38
770.014	668.189
770.894	665.536
771.774	666.709
772.651	670.854
773.531	673.585
774.41	673.207
775.289	663.812
776.167	656.021
777.046	657.052
777.925	663.17
778.802	661.914
779.681	661.523
780.557	662.178
781.436	663.521
782.315	665.381
783.191	663.169
784.07	663.031
784.946	662.942
785.824	662.075
786.701	662.184
787.577	668.572
788.455	672.684
789.331	673.65
790.208	673.092
791.084	672.26
791.96	671.258
792.838	674.958
793.713	675.877
794.588	674.401
795.466	670.153
796.341	672.272
797.216	675.651
798.091	680.09
798.966	674.685
799.843	673.276
800.718	666.357
801.593	675.331
802.467	672.813
803.342	670.426
804.217	669.046
805.091	673.298
805.965	669.011
806.84	669.115
807.714	679.251
808.588	680.775
809.462	676.707
810.336	675.208
811.209	676.799
812.083	678.312
812.957	677.238
813.83	680.986
814.702	677.213
815.575	676.256
816.449	677.629
817.322	679.871
818.195	682.24
819.066	684.006
819.939	686.883
820.812	684.175
821.685	681.279
822.555	680.685
823.428	682.352
824.299	685.031
825.171	683.121
826.043	680.346
826.914	684.869
827.786	683.645
828.656	685.55
829.528	688.553
830.398	686.831
831.27	687.432
832.14	688.916
833.012	689.468
833.881	690.472
834.751	687.035
835.622	676.278
836.492	669.236
837.363	672.324
838.232	679.15
839.101	686.821
839.97	687.299
840.841	678.452
841.71	664.099
842.579	657.32
843.448	657.949
844.316	663.458
845.187	669.796
846.055	671.598
846.924	667.805
847.792	667.958
848.66	668.363
849.528	669.111
850.396	667.144
851.264	662.211
852.132	655.59
853	647.637
853.868	641.014
854.735	632.88
855.603	622.697
856.47	619.147
857.338	618.262
858.205	616.786
859.072	615.682
859.937	611.247
860.804	605.666
861.671	605.309
862.538	611.226
863.403	610.615
864.27	601.628
865.136	584.716
866.003	571.504
866.867	564.737
867.734	564.825
868.6	572.35
869.464	581.868
870.33	575.306
871.194	571.15
872.06	568.013
872.924	562.65
873.79	559.396
874.654	555.722
875.519	550.766
876.383	550.339
877.248	552.353
878.112	548.95
878.977	549.47
879.84	544.259
880.704	542.991
881.569	542.594
882.432	538.264
883.294	533.993
884.159	530.708
885.022	528.131
885.885	527.279
886.747	525.122
887.61	526.326
888.474	526.066
889.336	520.76
890.199	517.715
891.061	518.181
891.923	522.274
892.785	523.348
893.647	521.227
894.509	517.705
895.37	512.711
896.232	509.454
897.094	511.693
897.955	511.513
898.817	508.797
899.678	508.727
900.539	511.163
901.4	507.577
902.261	503.896
903.122	500.26
903.981	497.064
904.842	494.912
905.703	494.846
906.564	494.775
907.424	494.683
908.283	496.49
909.143	500.49
910.003	503.228
910.862	503.274
911.722	504.035
912.582	498.422
913.44	492.058
914.3	488.485
915.158	488.638
916.018	492.623
916.875	500.412
917.735	503.836
918.593	499.517
919.452	494.291
920.309	490.058
921.169	487.302
922.026	486.73
922.885	487.502
923.742	486.452
924.599	486.682
925.458	488.602
926.315	491.641
927.171	486.796
928.028	480.423
928.887	476.353
929.743	477.08
930.599	479.446
931.456	482.043
932.312	483.079
933.17	488.186
934.026	492.951
934.882	488.77
935.738	490.431
936.594	487.436
937.45	485.231
938.305	482.796
939.161	478.065
940.016	475.327
940.872	480.073
941.727	479.164
942.583	480.389
943.438	487.012
944.293	491.984
945.148	490.1
946.001	487.747
946.856	480.684
947.71	475.426
948.565	472.687
949.42	471.042
950.272	470.826
951.127	472.679
951.981	474.148
952.833	475.367
953.688	477.393
954.542	480.755
955.394	479.62
956.248	475.59
957.102	472.958
957.953	472.011
958.807	470.512
959.659	464.05
960.512	466.043
961.364	475.122
962.217	474.592
963.069	464.475
963.92	463.116
964.773	466.556
965.624	469.685
966.477	472.858
967.328	473.719
968.179	471.865
969.032	473.174
969.882	474.247
970.733	472.975
971.584	470.607
972.436	467.226
973.286	465.778
974.137	464.75
974.987	464.268
975.837	466.816
976.687	472.322
977.537	473.174
978.389	467.805
979.239	461.061
980.088	459.027
980.938	462.329
981.788	465.441
982.637	466.968
983.487	465.831
984.336	460.981
985.183	455.348
986.032	450.666
986.881	457.223
987.73	456.539
988.579	457.209
989.428	461.689
990.277	464.3
991.124	466.848
991.972	466.79
992.821	460.355
993.669	457.179
994.516	458.793
995.364	458.747
996.212	460.541
997.058	460.675
997.906	461.737
998.752	463.751
999.6	462.599
1000.45	460.814
1001.29	460.086
1002.14	460.477
1002.99	461.665
1003.83	462.675
1004.68	461.828
1005.53	459.906
1006.37	460.502
1007.22	461.225
1008.06	461.615
1008.91	463.046
1009.75	461.647
1010.6	457.955
1011.45	454.126
1012.29	453.327
1013.14	456.15
1013.98	458.594
1014.83	459.733
1015.67	459.82
1016.52	460.361
1017.36	459.97
1018.2	457.749
1019.05	452.809
1019.89	450.067
1020.74	452.708
1021.58	455.601
1022.43	456.872
1023.27	455.421
1024.11	453.534
1024.96	451.394
1025.8	450.194
1026.64	453.148
1027.48	456.148
1028.33	448.619
1028.89	430.686