File: Data/Raman/raw/bu19ts-coltan3-core_150 (500nm)_633nm_edge_10%_x100_vis_h30um_10sx2_01.txt
#Acq. time (s)=	10
#Accumulations=	2
#Range (cm-¹)=	100...4000
#Windows=	1
#Auto scanning=	Off
#Autofocus=	Off
#Macrospot=	Off
#AutoExposure=	Off
#Spike filter=	Multiple accum.
#Delay time (s)=	2
#Binning=	1
#Readout mode=	Signal
#DeNoise=	Standard
#ICS correction=	On
#Dark correction=	Off
#Inst. Process=	Off
#Detector Gain=	Best Dynamic
#Detector ADC=	50 kHz HS
#Detector temperature (°C)=	-60.09
#Instrument=	LabRAM HR Evol
#Detector=	SIN-EM FIVIS
#Objective=	x100_VIS
#Grating=	150 (500nm)
#ND Filter=	10%
#Laser=	633nm_Edge
#Hole=	30.0125
#Temperature=	0
#Range=	Visible
#StageXY=	75x50mm Scan+
#StageZ=	Z motor
#X (µm)=	0
#Y (µm)=	0
#Z (µm)=	-2.5
#Full time(s)=	24
#Project=	20_10_27
#Sample=	BU19TS
#Site=
#Title=	BU19TS-Coltan2-core_150 (500nm)_633nm_Edge_10%_x100_VIS_H30um_10sX2
#Remark=
#Date=	27.10.2020 16:55
#Acquired=	27.10.2020 16:55:08
100.764	69.824
107.281	71.8657
113.791	77.6472
120.297	89.146
126.797	105.876
133.291	109.514
139.78	98.3074
146.264	85.2584
152.741	77.9058
159.214	85.3867
165.682	86.1723
172.144	85.4434
178.601	85.4392
185.053	81.6908
191.499	78.7089
197.939	84.7708
204.374	109.519
210.805	111.346
217.23	85.6964
223.648	79.5887
230.063	82.4753
236.472	94.0599
242.874	107.311
249.273	121.314
255.667	136.876
262.053	157.024
268.436	189.448
274.813	220.291
281.185	190.261
287.552	145.437
293.913	125.277
300.27	124.325
306.62	129.462
312.965	109.85
319.306	112.568
325.64	104.165
331.971	94.1472
338.295	83.8984
344.614	77.5503
350.93	73.002
357.238	71.4286
363.542	73.4163
369.842	76.9616
376.135	83.2235
382.423	90.8441
388.706	96.9641
394.984	100.924
401.258	98.9978
407.526	93.0676
413.789	87.8509
420.046	84.7173
426.299	84.4293
432.546	84.9588
438.788	87.5932
445.025	90.711
451.257	94.9051
457.484	98.8234
463.706	102.388
469.923	108.149
476.135	114.569
482.342	121.502
488.544	127.578
494.741	131.744
500.933	132.567
507.12	128.891
513.3	129.922
519.477	131.778
525.649	137.492
531.815	139.927
537.976	135.501
544.133	123.532
550.285	112.753
556.43	106.915
562.572	105.161
568.709	104.343
574.84	103.539
580.967	103.652
587.09	103.51
593.205	105.168
599.318	108.825
605.424	114.712
611.527	125.45
617.623	139.367
623.716	155.5
629.802	172.195
635.884	192.089
641.962	184.994
648.034	163.2
654.101	142.21
660.165	124.731
666.222	112.973
672.274	104.602
678.324	98.7358
684.366	95.6425
690.404	94.5059
696.438	94.5973
702.466	95.3513
708.491	96.666
714.51	96.6286
720.523	96.584
726.533	96.8732
732.537	96.6397
738.537	97.2337
744.531	97.8112
750.521	98.3869
756.507	98.6371
762.487	97.7333
768.463	96.9668
774.434	96.2232
780.4	96.1194
786.362	97.5725
792.319	100.118
798.269	104.437
804.217	111.678
810.159	122.562
816.097	136.355
822.03	154.244
827.958	174.829
833.881	193.025
839.801	213.428
845.714	243.734
851.624	310.041
857.529	413.6
863.428	623.899
869.324	955.67
875.215	1535.77
881.1	1699.02
886.982	950.282
892.858	426.25
898.73	234.873
904.597	160.685
910.459	121.334
916.318	107.889
922.171	94.4472
928.02	86.2246
933.864	79.6943
939.703	75.1289
945.539	71.765
951.368	69.6185
957.194	67.1495
963.014	64.5625
968.832	62.7616
974.643	61.518
980.45	60.3786
986.253	59.6371
992.051	59.1206
997.844	58.3893
1003.63	57.9384
1009.42	57.8779
1015.2	57.7977
1020.97	57.7397
1026.74	57.6008
1032.51	56.5944
1038.27	55.8655
1044.03	55.3789
1049.78	55.2196
1055.53	54.9559
1061.27	55.1181
1067.01	54.8868
1072.75	54.919
1078.48	54.3351
1084.2	54.0465
1089.92	54.4283
1095.64	55.1105
1101.35	54.5849
1107.06	53.9504
1112.77	53.3232
1118.46	52.6986
1124.16	52.0923
1129.85	51.507
1135.53	50.9469
1141.22	50.4105
1146.89	50.0372
1152.56	48.9079
1158.23	47.4512
1163.9	46.2697
1169.56	45.8324
1175.21	45.7475
1180.86	46.1567
1186.51	46.7985
1192.15	46.4155
1197.78	45.8905
1203.42	45.3829
1209.04	44.8801
1214.67	44.408
1220.29	43.9786
1225.9	43.5995
1231.51	43.2713
1237.12	42.9454
1242.72	42.2261
1248.32	42.167
1253.92	42.6401
1259.5	42.5727
1265.09	42.5289
1270.67	42.5016
1276.25	42.4822
1281.82	42.4625
1287.39	41.8279
1292.95	41.1185
1298.51	40.6989
1304.06	40.2352
1309.61	39.5493
1315.16	39.1568
1320.7	39.3954
1326.24	39.9258
1331.77	39.4935
1337.3	39.117
1342.83	38.8593
1348.35	39.5121
1353.86	40.2155
1359.37	39.345
1364.88	38.4578
1370.39	37.8158
1375.89	37.4444
1381.38	37.3704
1386.87	38.2136
1392.36	38.7705
1397.84	39.0848
1403.32	38.7482
1408.79	39.0045
1414.26	39.8618
1419.73	40.0058
1425.19	39.8894
1430.65	40.0581
1436.1	40.1512
1441.55	40.2488
1447	40.4201
1452.44	39.7963
1457.87	39.2681
1463.31	38.8573
1468.73	38.4558
1474.16	38.1631
1479.58	37.9529
1484.99	37.7941
1490.41	37.6932
1495.81	37.6452
1501.22	37.6654
1506.62	37.7508
1512.01	37.6331
1517.4	37.4435
1522.79	37.3578
1528.17	36.894
1533.55	36.2965
1538.93	35.9599
1544.3	35.8429
1549.67	35.5878
1555.03	35.7442
1560.39	35.7516
1565.74	35.4118
1571.09	34.9396
1576.44	34.6159
1581.78	34.43
1587.12	34.333
1592.45	34.6114
1597.78	35.0398
1603.11	35.4676
1608.43	35.8885
1613.75	36.2251
1619.07	36.197
1624.38	36.1683
1629.68	35.6525
1634.98	35.2348
1640.28	35.1943
1645.58	34.8578
1650.87	34.7228
1656.15	34.8101
1661.44	34.7216
1666.71	34.5129
1671.99	33.5458
1677.26	32.6503
1682.53	31.9297
1687.79	32.6823
1693.05	33.6596
1698.3	34.7258
1703.55	35.8164
1708.8	36.6876
1714.04	37.2261
1719.28	36.7966
1724.51	36.9255
1729.75	37.5197
1734.97	37.8676
1740.2	38.2266
1745.42	38.4497
1750.63	38.3893
1755.84	36.7345
1761.05	31.8775
1766.25	31.7182
1771.45	32.3205
1776.65	31.1067
1781.84	29.0726
1787.03	29.5561
1792.21	29.6853
1797.39	29.7587
1802.57	29.6976
1807.74	29.4399
1812.91	29.2845
1818.08	29.0274
1823.24	28.7505
1828.39	28.4621
1833.55	28.1707
1838.7	27.8858
1843.84	27.616
1848.99	27.3712
1854.12	27.1577
1859.26	26.9809
1864.39	26.8578
1869.52	26.757
1874.64	26.6878
1879.76	26.6457
1884.87	26.6377
1889.98	26.6345
1895.09	26.6427
1900.2	26.6619
1905.3	26.6758
1910.39	26.6805
1915.49	26.6738
1920.57	26.6552
1925.66	26.626
1930.74	26.5917
1935.82	26.5698
1940.89	26.545
1945.96	26.2767
1951.03	26.5103
1956.09	26.5076
1961.15	26.514
1966.21	26.5264
1971.26	26.5396
1976.31	26.5467
1981.35	26.3929
1986.39	26.5337
1991.43	26.4832
1996.46	26.3253
2001.49	26.0736
2006.52	25.7786
2011.54	25.4578
2016.56	25.0925
2021.57	24.7979
2026.58	24.3433
2031.59	24.3277
2036.59	24.5556
2041.59	25.1301
2046.59	25.6836
2051.58	26.0885
2056.57	26.0961
2061.55	25.6102
2066.54	25.0965
2071.51	24.8693
2076.49	24.77
2081.46	24.8949
2086.43	25.2784
2091.39	25.7023
2096.35	25.7301
2101.3	25.5598
2106.26	25.3937
2111.21	25.2353
2116.15	24.8254
2121.09	24.3678
2126.03	23.9942
2130.97	23.7961
2135.9	23.7275
2140.83	23.8203
2145.75	23.9852
2150.67	24.1093
2155.59	24.2848
2160.5	24.455
2165.41	24.5766
2170.31	24.6996
2175.22	24.8633
2180.12	25.0993
2185.01	25.3552
2189.9	25.8005
2194.79	25.7565
2199.68	25.4763
2204.56	25.1215
2209.43	24.7195
2214.31	24.0995
2219.18	23.899
2224.05	23.772
2228.91	23.8619
2233.77	24.0143
2238.63	24.1508
2243.48	24.2535
2248.33	24.2319
2253.17	24.1175
2258.02	24.2644
2262.86	24.5427
2267.69	24.5058
2272.52	24.4584
2277.35	24.3778
2282.18	24.3603
2287	24.3504
2291.82	24.0039
2296.63	23.4598
2301.44	23.2734
2306.25	23.2048
2311.05	23.2957
2315.86	23.4861
2320.65	23.796
2325.45	24.0213
2330.24	24.0859
2335.03	23.8882
2339.81	24.1982
2344.59	24.0691
2349.37	23.9297
2354.14	23.7803
2358.91	22.9178
2363.67	23.5068
2368.44	23.4118
2373.2	22.6016
2377.95	21.5222
2382.71	22.178
2387.46	23.0825
2392.2	23.5041
2396.95	23.4727
2401.68	23.4253
2406.42	23.368
2411.15	23.3054
2415.88	23.0533
2420.61	22.7943
2425.33	22.7673
2430.05	22.8042
2434.77	22.7555
2439.48	22.7786
2444.19	22.4594
2448.89	22.3595
2453.6	22.0544
2458.29	21.769
2462.99	22.1184
2467.68	22.486
2472.37	23.0712
2477.06	23.568
2481.74	23.9874
2486.42	24.2076
2491.1	24.4328
2495.77	24.508
2500.44	24.1198
2505.1	23.3966
2509.76	23.1071
2514.42	22.6526
2519.08	22.0485
2523.73	22.3164
2528.38	22.5742
2533.03	22.8143
2537.67	23.0091
2542.31	23.3497
2546.95	23.5302
2551.58	23.6882
2556.21	23.8158
2560.84	23.2175
2565.46	22.7483
2570.08	23.4918
2574.7	23.6385
2579.31	23.5805
2583.92	23.525
2588.53	23.4775
2593.13	23.1464
2597.73	22.9143
2602.33	22.7138
2606.92	22.9901
2611.51	23.0557
2616.1	23.1172
2620.68	23.597
2625.26	23.4676
2629.84	23.3013
2634.42	23.0889
2638.99	22.6614
2643.56	22.0512
2648.12	21.6579
2652.68	21.881
2657.24	22.1288
2661.8	22.3022
2666.35	22.5946
2670.9	22.8825
2675.45	22.9957
2679.99	23.0708
2684.53	23.0994
2689.06	22.9708
2693.6	22.8305
2698.13	22.6157
2702.66	22.4947
2707.18	22.4034
2711.7	22.3484
2716.22	22.3322
2720.73	22.3997
2725.24	22.4618
2729.75	22.5758
2734.26	22.6708
2738.76	22.766
2743.25	22.8429
2747.75	22.7487
2752.24	22.4781
2756.73	22.9641
2761.22	22.9936
2765.7	22.9794
2770.18	22.9368
2774.66	22.8694
2779.13	22.786
2783.6	22.6862
2788.07	22.6212
2792.53	22.5556
2797	22.51
2801.45	22.4921
2805.91	22.5047
2810.36	22.5472
2814.81	22.5825
2819.26	22.6915
2823.7	22.7809
2828.14	22.8728
2832.57	22.9613
2837.01	23.055
2841.44	23.0925
2845.87	22.8869
2850.29	22.5381
2854.71	22.621
2859.13	22.7226
2863.55	23.1527
2867.96	23.479
2872.37	23.5856
2876.77	23.4658
2881.18	23.0852
2885.58	22.8668
2889.97	23.2366
2894.37	23.543
2898.76	24.1592
2903.15	24.1435
2907.53	23.9594
2911.91	23.7404
2916.29	23.2572
2920.67	23.0786
2925.04	22.7498
2929.41	22.6272
2933.78	22.5443
2938.14	22.4995
2942.5	22.9276
2946.86	23.0649
2951.22	22.0246
2955.57	21.6133
2959.92	21.6724
2964.26	22.0053
2968.61	22.3437
2972.95	22.7154
2977.28	23.2343
2981.62	23.0965
2985.95	23.0472
2990.28	23.0189
2994.6	23.2965
2998.93	23.9619
3003.25	24.4501
3007.56	24.9502
3011.88	25.1186
3016.19	25.0134
3020.49	24.7324
3024.8	24.3517
3029.1	23.971
3033.4	23.6253
3037.7	23.3326
3041.99	23.1459
3046.28	23.4727
3050.57	23.8357
3054.85	24.1718
3059.13	24.2656
3063.41	24.2929
3067.69	24.1806
3071.96	24.0803
3076.23	24.0068
3080.5	24.0753
3084.76	24.4015
3089.02	24.7204
3093.28	24.8875
3097.53	24.8556
3101.79	24.8104
3106.04	24.4835
3110.28	24.1266
3114.53	23.6548
3118.77	23.0837
3123.01	22.6748
3127.24	22.5436
3131.47	22.655
3135.7	23.3993
3139.93	24.1716
3144.15	24.7277
3148.38	24.9748
3152.59	24.7745
3156.81	24.369
3161.02	24.2329
3165.23	24.6762
3169.44	25.3996
3173.64	25.1733
3177.84	24.9354
3182.04	24.6635
3186.24	24.7178
3190.43	24.7889
3194.62	25.579
3198.81	26.1191
3202.99	25.9295
3207.17	25.7391
3211.35	25.7841
3215.53	26.0929
3219.7	26.3745
3223.87	26.6911
3228.04	27.0382
3232.2	27.3678
3236.36	27.6317
3240.52	27.8525
3244.68	27.813
3248.83	27.3605
3252.98	27.0199
3257.13	26.6766
3261.28	26.3834
3265.42	26.1164
3269.56	25.9529
3273.7	25.9885
3277.83	26.2351
3281.96	26.552
3286.09	26.9001
3290.22	27.2569
3294.34	27.6187
3298.46	27.4999
3302.58	26.4984
3306.69	25.6126
3310.8	25.6403
3314.91	26.0647
3319.02	26.1572
3323.12	26.4538
3327.23	26.7298
3331.32	26.6449
3335.42	26.4827
3339.51	26.4168
3343.6	26.4856
3347.69	27.0008
3351.78	27.7738
3355.86	27.7226
3359.94	27.3339
3364.02	27.3918
3368.09	27.2905
3372.16	27.1812
3376.23	27.0654
3380.29	27.2942
3384.36	27.6217
3388.42	27.9599
3392.48	28.0901
3396.53	28.2168
3400.58	28.2349
3404.63	28.0893
3408.68	28.036
3412.73	27.7674
3416.77	27.6866
3420.81	27.6754
3424.84	27.4979
3428.88	27.6602
3432.91	27.8382
3436.94	27.7389
3440.96	27.6129
3444.99	27.616
3449.01	27.649
3453.03	27.731
3457.04	27.9536
3461.05	28.1099
3465.06	27.881
3469.07	27.9996
3473.08	28.1195
3477.08	28.0473
3481.08	28.0423
3485.07	27.8505
3489.07	27.7855
3493.06	27.9344
3497.05	27.8854
3501.04	27.8075
3505.02	27.9559
3509	28.1588
3512.98	28.7161
3516.96	29.1231
3520.93	29.5452
3524.9	29.9086
3528.87	30.1714
3532.83	29.3555
3536.8	28.5368
3540.76	27.9373
3544.71	27.4346
3548.67	26.9717
3552.62	27.0246
3556.57	27.5327
3560.52	26.9052
3564.47	26.5042
3568.41	26.455
3572.35	26.8808
3576.29	27.8595
3580.22	28.7837
3584.15	28.8699
3588.08	28.3974
3592.01	28.4009
3595.93	28.3858
3599.85	28.3089
3603.77	28.6351
3607.69	29.058
3611.61	29.0778
3615.52	29.0005
3619.43	28.9721
3623.33	28.9959
3627.24	29.07
3631.14	29.1888
3635.04	29.3515
3638.93	29.5219
3642.83	29.7004
3646.72	29.8803
3650.61	30.0552
3654.49	30.2119
3658.38	29.8002
3662.26	29.5946
3666.14	29.4072
3670.01	29.5739
3673.89	29.4141
3677.76	28.801
3681.63	28.3376
3685.5	27.7799
3689.36	27.9456
3693.22	28.6502
3697.08	29.245
3700.94	29.2156
3704.79	29.0123
3708.64	29.1191
3712.49	29.6169
3716.34	29.9807
3720.18	30.5504
3724.02	30.814
3727.86	30.0278
3731.7	30.6633
3735.53	31.0668
3739.36	31.0031
3743.19	30.9931
3747.02	31.0076
3750.84	31.0582
3754.66	30.8064
3758.48	30.4819
3762.3	30.1785
3766.12	30.2178
3769.93	30.4287
3773.74	30.9707
3777.54	32.3554
3781.35	32.9273
3785.15	32.8213
3788.95	32.6417
3792.75	32.2047
3796.54	31.6766
3800.34	30.7506
3804.13	28.9943
3807.91	30.2966
3811.7	29.9151
3815.48	29.6656
3819.26	29.4443
3823.04	29.6185
3826.82	29.8612
3830.59	30.1627
3834.36	30.4979
3838.13	31.0789
3841.89	31.2185
3845.66	31.3109
3849.42	31.0334
3853.18	30.8667
3856.93	30.6914
3860.69	30.5683
3864.44	30.4883
3868.19	30.4428
3871.93	30.4202
3875.68	30.4841
3879.42	30.5164
3883.16	30.5802
3886.9	30.6603
3890.63	30.6938
3894.37	30.82
3898.1	30.9825
3901.82	31.1798
3905.55	31.4136
3909.27	31.6581
3912.99	31.9081
3916.71	32.1609
3920.43	32.4012
3924.14	31.936
3927.85	31.3768
3931.56	31.1785
3935.27	31.3697
3938.97	31.9635
3942.67	32.8226
3946.37	33.0066
3950.07	32.8473
3953.77	32.606
3957.46	32.1401
3961.15	31.6873
3964.84	31.2221
3968.52	30.758
3972.2	30.3628
3975.89	30.0816
3979.56	30.5786
3983.24	31.0622
3986.92	31.7644
3990.59	31.5711
3994.26	31.126
3997.92	33.3956
3999.76	34.5991