File: Data/Raman/raw/bu19w-ore3-innerhost_150 (500nm)_633nm_edge_100%_x100_vis_h30um_30sx2_01_0.txt
#Acq. time (s)=	30
#Accumulations=	2
#Range (cm-¹)=	100...4000
#Windows=	1
#Auto scanning=	Off
#Autofocus=	Off
#Macrospot=	Off
#AutoExposure=	Off
#Spike filter=	Multiple accum.
#Delay time (s)=	2
#Binning=	1
#Readout mode=	Signal
#DeNoise=	Standard
#ICS correction=	On
#Dark correction=	Off
#Inst. Process=	Off
#Detector Gain=	Best Dynamic
#Detector ADC=	50 kHz HS
#Detector temperature (°C)=	-60.09
#Instrument=	LabRAM HR Evol
#Detector=	SIN-EM FIVIS
#Objective=	x100_VIS
#Grating=	150 (500nm)
#ND Filter=	100%
#Laser=	633nm_Edge
#Hole=	30.0125
#Temperature=	0
#Range=	Visible
#StageXY=	75x50mm Scan+
#StageZ=	Z motor
#X (µm)=	0
#Y (µm)=	0
#Z (µm)=	68.5
#Full time(mm:ss)=	1:05
#Project=	21_02_17
#Sample=	BU19w
#Site=
#Title=	BU19w-Ore3-innerHost_150 (500nm)_633nm_Edge_100%_x100_VIS_H30um_30sX2
#Remark=
#Date=	17.02.2021 10:50
#Acquired=	17.02.2021 10:50:03
100.724	630.209
107.24	649.976
113.751	667.799
120.256	680.88
126.756	692.266
133.251	695.733
139.74	693.977
146.224	690.394
152.702	684.273
159.175	679.735
165.643	677.441
172.105	677.343
178.561	679.743
185.013	681.642
191.459	681.803
197.9	695.268
204.336	705.246
210.765	703.34
217.19	697.881
223.61	692.849
230.024	691.296
236.432	692.345
242.836	692.983
249.233	692.005
255.627	691.499
262.015	692.816
268.397	695.122
274.774	698.507
281.145	703.186
287.513	708.541
293.873	711.256
300.23	709.531
306.58	705.182
312.927	700.938
319.266	695.513
325.602	686.99
331.932	676.497
338.256	666.863
344.577	658.633
350.89	652.48
357.199	647.923
363.504	645.024
369.803	643.991
376.096	644.781
382.384	646.381
388.669	650.172
394.947	661.111
401.219	665.456
407.487	683.459
413.75	701.495
420.007	746.327
426.261	901.316
432.508	1069.81
438.751	953.439
444.988	863.656
451.22	830.396
457.447	799.227
463.669	768.918
469.886	739.759
476.098	713.442
482.303	691.501
488.505	674.297
494.702	661.422
500.894	653.025
507.081	649.244
513.263	649.872
519.44	651.353
525.61	652.197
531.777	653.737
537.939	656.415
544.096	661.36
550.246	667.76
556.393	675.69
562.535	683.821
568.671	708.314
574.803	755.234
580.929	821.368
587.051	887.919
593.167	924.207
599.28	771.744
605.387	738.775
611.489	753.736
617.585	768.573
623.678	743.875
629.764	717.214
635.847	696.744
641.924	688.833
647.998	685.564
654.065	685.17
660.127	686.958
666.184	690.847
672.238	695.47
678.286	699.53
684.329	703.249
690.367	705.253
696.401	704.179
702.43	699.44
708.453	692.774
714.472	688.632
720.486	685.207
726.495	682.826
732.5	680.623
738.501	673.697
744.495	666.015
750.485	657.572
756.471	649.744
762.451	647.702
768.426	649.71
774.397	654.95
780.363	661.747
786.325	671.649
792.281	674.808
798.234	674.633
804.181	667.2
810.124	662.045
816.06	659.95
821.993	662.29
827.922	664.219
833.846	665.801
839.764	667.197
845.678	668.228
851.588	669.373
857.492	670.175
863.392	670.481
869.287	670.247
875.178	669.427
881.063	667.439
886.945	664.937
892.822	661.711
898.694	658.701
904.56	659.08
910.424	661.995
916.281	666.583
922.135	675.285
927.984	696.034
933.827	705.076
939.668	758.24
945.502	909.795
951.332	1294.54
957.159	2031.14
962.979	2414.04
968.796	1815.23
974.607	1181.79
980.414	811.337
986.218	733.943
992.016	716.792
997.809	716.115
1003.6	723.941
1009.38	736.319
1015.16	754.834
1020.94	774.367
1026.71	796.295
1032.48	829.885
1038.24	874.771
1043.99	901.527
1049.75	811.845
1055.5	772.268
1061.24	751.123
1066.98	744.511
1072.71	740.991
1078.44	737.532
1084.17	728.502
1089.89	715.938
1095.61	700.942
1101.32	686.444
1107.03	682.968
1112.73	688.349
1118.43	692.705
1124.12	699.875
1129.81	704.182
1135.5	700.883
1141.18	690.024
1146.86	674.85
1152.53	665.405
1158.2	657.376
1163.86	652.623
1169.52	654.616
1175.17	654.904
1180.83	652.318
1186.47	648.719
1192.11	647.233
1197.75	645.981
1203.38	644.499
1209.01	643.709
1214.63	645.177
1220.25	648.795
1225.87	651.42
1231.48	651.613
1237.09	650.543
1242.69	648.683
1248.29	647.498
1253.88	643.654
1259.47	638.218
1265.05	634.031
1270.63	631.523
1276.21	630.14
1281.78	629.723
1287.35	630.263
1292.91	631.987
1298.47	634.689
1304.03	637.335
1309.58	638.092
1315.13	638.481
1320.67	638.522
1326.2	637.949
1331.74	637.365
1337.27	637.968
1342.79	639.471
1348.31	639.913
1353.83	638.943
1359.34	635.99
1364.85	631.692
1370.35	626.997
1375.85	623.204
1381.35	620.423
1386.84	619.144
1392.32	617.332
1397.81	615.003
1403.29	612.94
1408.76	611.319
1414.23	610.002
1419.7	609
1425.16	608.316
1430.61	607.728
1436.07	607.411
1441.52	606.391
1446.96	604.134
1452.4	601.946
1457.84	600.879
1463.27	601.179
1468.7	601.075
1474.12	599.547
1479.55	598.043
1484.96	597.138
1490.37	595.952
1495.78	592.847
1501.18	590.4
1506.58	589.606
1511.98	590.198
1517.37	595.701
1522.76	597.577
1528.14	596.101
1533.52	593.587
1538.9	589.233
1544.27	585.917
1549.63	584.105
1555	583.9
1560.35	585.278
1565.71	586.987
1571.06	587.114
1576.41	585.807
1581.75	582.159
1587.09	578.705
1592.42	575.891
1597.75	571.928
1603.08	567.368
1608.4	563.577
1613.72	560.374
1619.03	559.298
1624.34	558.969
1629.65	558.218
1634.95	557.136
1640.25	555.68
1645.54	553.156
1650.83	549.711
1656.12	546.082
1661.4	542.95
1666.68	539.877
1671.96	537.002
1677.23	534.319
1682.49	531.7
1687.75	529.082
1693.01	526.539
1698.27	524.108
1703.52	521.434
1708.77	527.025
1714.01	527.789
1719.25	512.063
1724.48	506.017
1729.71	507.584
1734.94	508.517
1740.16	510.227
1745.38	510.409
1750.6	509.163
1755.81	507.258
1761.02	505.145
1766.22	502.641
1771.42	499.964
1776.62	498.827
1781.81	499.925
1787	501.94
1792.18	501.816
1797.36	500.37
1802.54	498.801
1807.71	497
1812.88	495.854
1818.05	494.82
1823.21	493.082
1828.36	491.015
1833.52	488.448
1838.67	485.319
1843.81	482.353
1848.95	480.033
1854.09	478.979
1859.23	478.442
1864.36	478.55
1869.48	478.579
1874.61	476.197
1879.73	472.92
1884.84	468.465
1889.95	464.509
1895.06	462.717
1900.17	461.552
1905.27	459.438
1910.36	456.906
1915.45	454.102
1920.54	456.711
1925.63	462.098
1930.71	464.541
1935.79	459.101
1940.86	455.22
1945.93	454.266
1951	453.313
1956.06	452.087
1961.12	450.628
1966.18	448.825
1971.23	446.901
1976.28	445.598
1981.32	445.037
1986.36	443.699
1991.4	443.107
1996.43	441.48
2001.46	438.186
2006.48	435.777
2011.51	434.398
2016.52	433.829
2021.54	433.847
2026.55	434.181
2031.56	434.294
2036.56	433.304
2041.56	431.781
2046.56	429.602
2051.55	426.009
2056.54	422.683
2061.52	421.127
2066.51	419.616
2071.48	418.143
2076.46	416.692
2081.43	415.469
2086.4	414.379
2091.36	413.35
2096.32	412.868
2101.28	414.185
2106.23	415.683
2111.18	415.861
2116.12	414.288
2121.06	411.848
2126	408.959
2130.94	405.439
2135.87	401.732
2140.79	400.32
2145.72	400.655
2150.64	398.82
2155.56	396.774
2160.47	394.663
2165.38	392.953
2170.28	391.514
2175.19	390.349
2180.09	389.321
2184.98	388.485
2189.87	387.701
2194.76	387.131
2199.65	385.863
2204.53	382.024
2209.4	377.537
2214.28	375.066
2219.15	375.819
2224.02	378.333
2228.88	381.66
2233.74	383.75
2238.6	383.152
2243.45	380.832
2248.3	377.004
2253.14	373.217
2257.99	370.715
2262.83	369.673
2267.66	368.996
2272.49	368.139
2277.32	366.971
2282.15	365.141
2286.97	362.661
2291.79	360.22
2296.6	358.117
2301.41	357.269
2306.22	356.775
2311.02	356.648
2315.83	356.315
2320.62	354.804
2325.42	352.217
2330.21	348.993
2335	345.952
2339.78	343.899
2344.56	342.415
2349.34	342.284
2354.11	342.486
2358.88	342.698
2363.65	341.852
2368.41	340.62
2373.17	338.814
2377.93	336.188
2382.68	334.876
2387.43	336
2392.17	340.578
2396.92	343.07
2401.66	343.758
2406.39	331.022
2411.13	329.245
2415.85	330.802
2420.58	330.184
2425.3	329.236
2430.02	328.547
2434.74	328.135
2439.45	327.146
2444.16	322.632
2448.86	319.961
2453.57	319.081
2458.27	319.269
2462.96	319.564
2467.65	318.064
2472.34	315.843
2477.03	313.577
2481.71	311.813
2486.39	310.779
2491.07	310.569
2495.74	311.898
2500.41	313.964
2505.07	315.119
2509.74	314.635
2514.4	312.074
2519.05	309.302
2523.7	306.628
2528.35	303.587
2533	300.892
2537.64	299.183
2542.28	298.302
2546.92	297.586
2551.55	296.93
2556.18	296.19
2560.81	295.465
2565.43	294.904
2570.05	294.259
2574.67	293.638
2579.28	293.417
2583.89	292.926
2588.5	290.459
2593.1	288.134
2597.7	286.523
2602.3	285.271
2606.89	284.23
2611.48	283.919
2616.07	283.804
2620.66	283.022
2625.24	280.52
2629.82	278.227
2634.39	276.638
2638.96	275.595
2643.53	274.498
2648.09	273.568
2652.66	272.844
2657.21	273.469
2661.77	274.639
2666.32	275.072
2670.87	275.108
2675.42	274.589
2679.96	273.477
2684.5	271.786
2689.04	269.715
2693.57	267.5
2698.1	266.082
2702.63	265.138
2707.15	262.833
2711.67	260.376
2716.19	258.828
2720.7	258.135
2725.21	258.254
2729.72	258.662
2734.23	259.198
2738.73	259.754
2743.23	259.955
2747.72	259.499
2752.22	258.227
2756.7	255.826
2761.19	252.769
2765.67	251.758
2770.15	250.849
2774.63	249.757
2779.1	248.58
2783.57	246.875
2788.04	245.65
2792.51	245.578
2796.97	245.501
2801.43	244.658
2805.88	243.987
2810.33	243.678
2814.78	243.14
2819.23	242.586
2823.67	241.929
2828.11	240.915
2832.55	239.754
2836.98	238.618
2841.41	237.679
2845.84	237.476
2850.26	236.957
2854.69	234.623
2859.1	235.252
2863.52	236.286
2867.93	235.972
2872.34	232.76
2876.75	229.603
2881.15	227.348
2885.55	226.084
2889.95	225.499
2894.34	225.743
2898.73	226.087
2903.12	225.987
2907.5	224.524
2911.89	223.423
2916.27	223.504
2920.64	223.528
2925.01	223.958
2929.38	226.488
2933.75	228.737
2938.12	229.432
2942.48	229.17
2946.84	227.677
2951.19	225.65
2955.54	223.359
2959.89	221.778
2964.24	219.621
2968.58	218.312
2972.92	218.235
2977.26	216.311
2981.59	214.824
2985.92	213.713
2990.25	212.847
2994.58	212.131
2998.9	211.393
3003.22	210.566
3007.54	209.651
3011.85	208.912
3016.16	208.043
3020.47	207.614
3024.77	208.209
3029.07	209.261
3033.37	210.638
3037.67	211.779
3041.96	211.472
3046.25	210.099
3050.54	208.204
3054.82	206.453
3059.11	205.815
3063.38	205.346
3067.66	204.181
3071.93	203.058
3076.2	202.264
3080.47	201.627
3084.73	200.922
3088.99	199.944
3093.25	198.416
3097.51	197.509
3101.76	199.668
3106.01	200.976
3110.26	201.409
3114.5	201.436
3118.74	200.566
3122.98	199.357
3127.22	198.674
3131.45	197.15
3135.68	196.752
3139.91	198.24
3144.13	198.953
3148.35	199.045
3152.57	198.297
3156.78	197.56
3161	197.075
3165.21	197.382
3169.41	197.925
3173.62	198.259
3177.82	198.113
3182.02	196.39
3186.21	193.866
3190.4	190.881
3194.59	187.644
3198.78	185.364
3202.96	185.013
3207.15	185.457
3211.33	185.946
3215.5	186.288
3219.67	185.873
3223.84	185.185
3228.01	184.812
3232.18	184.806
3236.34	185.589
3240.5	187.261
3244.65	188.808
3248.81	189.294
3252.96	188.408
3257.11	186.894
3261.25	185.096
3265.39	183.526
3269.53	184.905
3273.67	185.791
3277.8	185.741
3281.94	184.733
3286.06	183.013
3290.19	179.928
3294.31	176.25
3298.43	173.761
3302.55	174.921
3306.67	176.073
3310.78	177.162
3314.89	176.756
3319	176.225
3323.1	175.978
3327.2	176.115
3331.3	176.202
3335.39	176.561
3339.49	176.781
3343.58	176.128
3347.67	173.894
3351.75	169.914
3355.83	167.589
3359.91	166.535
3363.99	167.027
3368.06	168.93
3372.14	171.763
3376.2	174.661
3380.27	176.002
3384.33	175.667
3388.39	173.494
3392.45	170.315
3396.51	167.6
3400.56	165.952
3404.61	165.808
3408.66	167.571
3412.7	170.925
3416.74	177.362
3420.78	184.191
3424.82	209.354
3428.85	318.856
3432.88	354.088
3436.91	215.707
3440.94	187.017
3444.96	179.229
3448.98	174.697
3453	169.567
3457.02	167.034
3461.03	165.847
3465.04	164.93
3469.05	166.104
3473.05	168.065
3477.05	170.453
3481.05	172.476
3485.05	174.297
3489.04	175.328
3493.04	174.881
3497.03	175.041
3501.01	177.85
3505	180.711
3508.98	182.58
3512.96	184.38
3516.93	184.271
3520.9	181.85
3524.88	176.407
3528.84	171.226
3532.81	168.305
3536.77	167.858
3540.73	170.061
3544.69	175.131
3548.65	178.103
3552.6	178.565
3556.55	176.701
3560.5	172.642
3564.44	168.004
3568.38	164.196
3572.32	161.882
3576.26	163.29
3580.2	161.446
3584.13	159.507
3588.06	156.964
3591.98	155.22
3595.91	155.375
3599.83	156.868
3603.75	157.671
3607.67	157.342
3611.58	156.1
3615.49	153.797
3619.4	150.313
3623.31	145.584
3627.21	140.884
3631.11	139.807
3635.01	141.273
3638.91	143.664
3642.8	145.357
3646.69	146.121
3650.58	146.675
3654.47	147.479
3658.35	146.173
3662.24	144.005
3666.11	142.714
3669.99	141.961
3673.86	144.278
3677.74	146.549
3681.6	147.655
3685.47	147.816
3689.34	146.816
3693.2	145.56
3697.06	143.792
3700.91	142.637
3704.77	142.432
3708.62	142.099
3712.47	141.789
3716.31	141.249
3720.16	140.292
3724	140.583
3727.84	141.342
3731.67	141.613
3735.51	141.414
3739.34	140.948
3743.17	140.411
3747	139.845
3750.82	139.221
3754.64	138.686
3758.46	138.216
3762.28	138.233
3766.09	138.347
3769.9	138.431
3773.71	138.457
3777.52	138.321
3781.33	137.6
3785.13	136.768
3788.93	135.477
3792.72	133.927
3796.52	132.454
3800.31	132.367
3804.1	133.576
3807.89	133.194
3811.68	132.377
3815.46	131.612
3819.24	131.036
3823.02	130.645
3826.79	130.885
3830.56	131.581
3834.34	132.467
3838.1	133.473
3841.87	134.22
3845.63	134.024
3849.39	133.863
3853.15	133.781
3856.91	133.943
3860.66	134.839
3864.42	135.893
3868.16	136.329
3871.91	134.239
3875.66	131.804
3879.4	129.884
3883.14	129.26
3886.88	129.038
3890.61	128.715
3894.34	128.254
3898.07	127.959
3901.8	128.047
3905.53	128.068
3909.25	127.287
3912.97	125.24
3916.69	125.205
3920.4	126.711
3924.12	128.304
3927.83	129.567
3931.54	131.882
3935.24	133.588
3938.95	133.939
3942.65	133.102
3946.35	129.521
3950.05	128.069
3953.74	127.062
3957.44	128.414
3961.13	127.334
3964.81	124.232
3968.5	119.991
3972.18	118.424
3975.86	119.347
3979.54	120.19
3983.22	121.868
3986.89	122.158
3990.56	121.694
3994.23	121.959
3997.9	122.387
3999.73	121.866