File: Data/Raman/raw/bu19ts-coltan_150 (500nm)_633nm_edge_25%_x20_vis_h30um_10sx2_01.txt
#Acq. time (s)=	10
#Accumulations=	2
#Range (cm-¹)=	100...4000
#Windows=	1
#Auto scanning=	Off
#Autofocus=	Off
#Macrospot=	Off
#AutoExposure=	Off
#Spike filter=	Single accum. (Size=4)
#Delay time (s)=	2
#Binning=	1
#Readout mode=	Signal
#DeNoise=	Standard
#ICS correction=	On
#Dark correction=	Off
#Inst. Process=	Off
#Detector Gain=	Best Dynamic
#Detector ADC=	50 kHz HS
#Detector temperature (°C)=	-60.09
#Instrument=	LabRAM HR Evol
#Detector=	SIN-EM FIVIS
#Objective=	x20_VIS
#Grating=	150 (500nm)
#ND Filter=	25%
#Laser=	633nm_Edge
#Hole=	30.0125
#Temperature=	0
#Range=	Visible
#StageXY=	75x50mm Scan+
#StageZ=	Z motor
#X (µm)=	0
#Y (µm)=	0
#Z (µm)=	-54.9
#Full time(s)=	24
#Project=	20_10_27
#Sample=	BU19TS
#Site=
#Title=	BU19TS-Coltan_150 (500nm)_633nm_Edge_25%_x20_VIS_H30um_10sX2
#Remark=
#Date=	27.10.2020 13:52
#Acquired=	27.10.2020 13:52:36
100.764	34.0083
107.281	37.1781
113.791	43.2839
120.297	54.0325
126.797	63.1005
133.291	67.8882
139.78	57.4019
146.264	43.7861
152.741	38.3846
159.214	39.6725
165.682	43.1579
172.144	47.7143
178.601	48.2554
185.053	46.4008
191.499	44.9245
197.939	45.2994
204.374	46.9928
210.805	46.8752
217.23	42.831
223.648	42.981
230.063	44.7336
236.472	52.0692
242.874	75.3272
249.273	77.0538
255.667	74.8426
262.053	75.11
268.436	75.219
274.813	74.7043
281.185	69.8055
287.552	63.7127
293.913	57.4965
300.27	51.4186
306.62	47.3953
312.965	45.9275
319.306	45.0003
325.64	44.2191
331.971	42.3609
338.295	39.8919
344.614	38.1479
350.93	37.7733
357.238	37.7326
363.542	37.7777
369.842	37.6865
376.135	37.3828
382.423	36.953
388.706	36.5076
394.984	36.1421
401.258	35.9243
407.526	36.1224
413.789	36.487
420.046	36.9965
426.299	37.6983
432.546	38.4855
438.788	39.5444
445.025	41.0972
451.257	43.0613
457.484	44.9443
463.706	47.443
469.923	49.9789
476.135	52.9151
482.342	55.1311
488.544	57.073
494.741	58.8228
500.933	60.462
507.12	61.9665
513.3	63.6027
519.477	68.2567
525.649	76.8068
531.815	86.0011
537.976	79.2823
544.133	67.1346
550.285	56.3695
556.43	50.0119
562.572	45.8096
568.709	43.4022
574.84	42.3568
580.967	42.3088
587.09	42.8264
593.205	43.6647
599.318	44.5748
605.424	45.5644
611.527	46.8475
617.623	48.0441
623.716	48.9896
629.802	49.354
635.884	48.9627
641.962	47.5781
648.034	45.9001
654.101	44.0305
660.165	42.3261
666.222	40.849
672.274	39.7848
678.324	39.2961
684.366	39.2333
690.404	39.5442
696.438	40.0928
702.466	40.7984
708.491	41.44
714.51	41.9262
720.523	42.1434
726.533	42.0833
732.537	41.8737
738.537	41.6797
744.531	41.4864
750.521	41.4228
756.507	41.47
762.487	41.4374
768.463	41.4339
774.434	41.4346
780.4	41.4673
786.362	41.5628
792.319	41.74
798.269	42.0349
804.217	42.8626
810.159	44.4964
816.097	46.6184
822.03	49.699
827.958	53.5444
833.881	58.3676
839.801	65.429
845.714	73.2923
851.624	88.2348
857.529	121.128
863.428	178.795
869.324	277.804
875.215	396.665
881.1	373.711
886.982	197.084
892.858	99.3384
898.73	72.5444
904.597	57.1952
910.459	46.2411
916.318	39.6207
922.171	36.8217
928.02	35.191
933.864	34.112
939.703	33.5059
945.539	32.9589
951.368	32.4686
957.194	31.989
963.014	31.4557
968.832	30.7423
974.643	29.9553
980.45	29.2642
986.253	28.6612
992.051	28.1424
997.844	27.9465
1003.63	28.0386
1009.42	28.2562
1015.2	28.5116
1020.97	28.698
1026.74	28.5425
1032.51	28.3832
1038.27	28.2029
1044.03	28.0216
1049.78	28.0666
1055.53	28.3111
1061.27	28.594
1067.01	28.8889
1072.75	29.0768
1078.48	28.929
1084.2	28.613
1089.92	28.2214
1095.64	27.7854
1101.35	27.3496
1107.06	26.9763
1112.77	27.0387
1118.46	27.5392
1124.16	27.92
1129.85	28.3112
1135.53	28.6342
1141.22	28.4215
1146.89	27.894
1152.56	27.251
1158.23	26.6954
1163.9	26.3039
1169.56	26.1778
1175.21	26.3351
1180.86	26.477
1186.51	26.6572
1192.15	26.8998
1197.78	27.0109
1203.42	27.0554
1209.04	26.9608
1214.67	26.9363
1220.29	26.9205
1225.9	26.9165
1231.51	26.9118
1237.12	26.8592
1242.72	26.9158
1248.32	26.9732
1253.92	27.0194
1259.5	26.8201
1265.09	26.6651
1270.67	26.9239
1276.25	26.8749
1281.82	26.5949
1287.39	26.2054
1292.95	26.0694
1298.51	26.1698
1304.06	25.9611
1309.61	25.8106
1315.16	25.6605
1320.7	25.6228
1326.24	25.6877
1331.77	25.757
1337.3	25.8061
1342.83	26.0193
1348.35	26.7297
1353.86	26.6031
1359.37	26.3182
1364.88	25.9788
1370.39	26.0263
1375.89	26.2454
1381.38	26.547
1386.87	26.8599
1392.36	27.1673
1397.84	27.4514
1403.32	27.6271
1408.79	27.7758
1414.26	27.8158
1419.73	27.769
1425.19	27.8153
1430.65	27.6397
1436.1	27.3511
1441.55	27.0373
1447	27.0186
1452.44	27.2343
1457.87	27.5792
1463.31	27.9942
1468.73	28.0073
1474.16	27.9791
1479.58	27.8579
1484.99	27.5762
1490.41	27.2283
1495.81	26.8869
1501.22	26.4957
1506.62	25.9915
1512.01	26.0105
1517.4	27.3087
1522.79	28.858
1528.17	27.4752
1533.55	27.337
1538.93	27.2356
1544.3	26.9741
1549.67	26.6904
1555.03	26.4103
1560.39	26.16
1565.74	25.9436
1571.09	25.7119
1576.44	25.8418
1581.78	26.0922
1587.12	26.442
1592.45	26.8297
1597.78	27.2108
1603.11	27.1902
1608.43	27.0939
1613.75	26.9839
1619.07	26.8207
1624.38	26.784
1629.68	26.7724
1634.98	26.8569
1640.28	26.9303
1645.58	26.9776
1650.87	27.036
1656.15	26.9864
1661.44	26.6378
1666.71	26.4341
1671.99	26.2812
1677.26	26.0406
1682.53	26.0323
1687.79	26.2255
1693.05	26.4752
1698.3	26.699
1703.55	26.9121
1708.8	26.995
1714.04	27.1255
1719.28	27.1739
1724.51	27.4364
1729.75	27.6427
1734.97	27.9072
1740.2	28.1709
1745.42	28.5265
1750.63	28.6609
1755.84	28.5524
1761.05	28.1558
1766.25	27.5614
1771.45	26.9052
1776.65	26.4046
1781.84	26.1854
1787.03	26.0561
1792.21	25.9952
1797.39	26.2528
1802.57	26.8211
1807.74	27.2763
1812.91	27.7538
1818.08	28.0081
1823.24	27.9775
1828.39	27.6737
1833.55	27.1704
1838.7	26.5486
1843.84	26.0191
1848.99	25.7255
1854.12	25.6503
1859.26	25.8492
1864.39	26.1328
1869.52	26.5026
1874.64	26.8621
1879.76	27.2181
1884.87	27.2494
1889.98	27.2172
1895.09	27.0959
1900.2	26.8309
1905.3	26.7282
1910.39	26.6396
1915.49	26.6413
1920.57	26.6719
1925.66	26.6773
1930.74	26.6681
1935.82	26.6479
1940.89	26.6219
1945.96	26.5558
1951.03	26.5441
1956.09	26.585
1961.15	26.7962
1966.21	26.9525
1971.26	27.0627
1976.31	27.1051
1981.35	27.4703
1986.39	27.4355
1991.43	27.218
1996.46	26.8872
2001.49	26.7223
2006.52	26.7208
2011.54	27.0602
2016.56	26.8166
2021.57	26.8761
2026.58	27.0181
2031.59	26.242
2036.59	25.9558
2041.59	25.7628
2046.59	25.9504
2051.58	26.9709
2056.57	26.9709
2061.55	26.2031
2066.54	25.6759
2071.51	25.4315
2076.49	25.4839
2081.46	25.6294
2086.43	26.1052
2091.39	27.9598
2096.35	28.5494
2101.3	28.4649
2106.26	27.7403
2111.21	26.9967
2116.15	26.8143
2121.09	27.0189
2126.03	27.095
2130.97	26.9641
2135.9	26.9679
2140.83	27.1484
2145.75	26.8771
2150.67	26.5582
2155.59	26.457
2160.5	26.4165
2165.41	26.2169
2170.31	26.1275
2175.22	26.3172
2180.12	26.746
2185.01	27.0015
2189.9	26.9172
2194.79	27.2127
2199.68	27.5551
2204.56	27.9147
2209.43	27.923
2214.31	27.9195
2219.18	27.6965
2224.05	27.4219
2228.91	27.0924
2233.77	26.7394
2238.63	26.6186
2243.48	26.7236
2248.33	26.7468
2253.17	26.7808
2258.02	26.9459
2262.86	27.0514
2267.69	27.069
2272.52	27.0785
2277.35	27.0707
2282.18	27.0429
2287	27.113
2291.82	27.2203
2296.63	27.3504
2301.44	27.4904
2306.25	27.6766
2311.05	27.8396
2315.86	27.8085
2320.65	27.6644
2325.45	27.4488
2330.24	27.3046
2335.03	27.2427
2339.81	27.1623
2344.59	27.1081
2349.37	27.1886
2354.14	27.2177
2358.91	27.2341
2363.67	27.1499
2368.44	27.1082
2373.2	27.0807
2377.95	27.0706
2382.71	26.98
2387.46	26.8691
2392.2	26.7331
2396.95	26.5787
2401.68	26.4269
2406.42	26.2739
2411.15	27.7923
2415.88	29.8625
2420.61	29.0178
2425.33	27.8336
2430.05	28.0088
2434.77	27.9968
2439.48	28.2397
2444.19	28.0544
2448.89	27.759
2453.6	27.4193
2458.29	27.1171
2462.99	27.0175
2467.68	26.991
2472.37	27.0068
2477.06	26.7969
2481.74	26.9156
2486.42	27.0812
2491.1	27.4012
2495.77	27.6214
2500.44	27.4142
2505.1	26.7013
2509.76	26.3409
2514.42	26.8708
2519.08	27.5459
2523.73	28.0334
2528.38	28.4395
2533.03	28.3003
2537.67	27.6806
2542.31	27.0789
2546.95	26.5113
2551.58	26.1897
2556.21	26.1905
2560.84	26.4022
2565.46	26.5658
2570.08	26.7277
2574.7	26.6732
2579.31	26.5887
2583.92	26.5085
2588.53	26.409
2593.13	26.2175
2597.73	26.3942
2602.33	26.7676
2606.92	26.9383
2611.51	26.8119
2616.1	26.642
2620.68	26.7109
2625.26	26.7619
2629.84	26.6749
2634.42	26.8031
2638.99	26.8272
2643.56	26.8296
2648.12	26.7864
2652.68	26.5734
2657.24	26.4062
2661.8	26.2254
2666.35	26.0512
2670.9	25.9248
2675.45	25.9399
2679.99	25.9806
2684.53	26.1058
2689.06	26.1529
2693.6	26.2057
2698.13	26.3398
2702.66	26.4778
2707.18	26.7113
2711.7	26.5938
2716.22	26.5552
2720.73	26.8229
2725.24	29.2255
2729.75	27.1229
2734.26	25.7253
2738.76	26.8727
2743.25	27.5542
2747.75	24.3023
2752.24	25.4667
2756.73	26.5951
2761.22	26.7304
2765.7	27.0326
2770.18	26.9243
2774.66	26.8277
2779.13	26.9698
2783.6	27.8329
2788.07	27.8167
2792.53	27.1501
2797	26.4498
2801.45	26.8463
2805.91	27.3287
2810.36	27.8387
2814.81	28.2047
2819.26	28.3796
2823.7	28.112
2828.14	27.7312
2832.57	27.3001
2837.01	26.7902
2841.44	26.6421
2845.87	26.6419
2850.29	26.8548
2854.71	27.2301
2859.13	27.6358
2863.55	27.9891
2867.96	28.1494
2872.37	28.2294
2876.77	27.8355
2881.18	27.3995
2885.58	27.1358
2889.97	27.0266
2894.37	27.2397
2898.76	27.4542
2903.15	27.6319
2907.53	27.2947
2911.91	27.2217
2916.29	27.3179
2920.67	27.4675
2925.04	27.6732
2929.41	28.4275
2933.78	27.9152
2938.14	27.3797
2942.5	26.738
2946.86	26.1864
2951.22	26.3886
2955.57	26.7808
2959.92	27.2752
2964.26	27.5633
2968.61	27.7685
2972.95	28.0865
2977.28	28.4904
2981.62	28.6701
2985.95	28.5071
2990.28	28.2003
2994.6	27.7078
2998.93	27.016
3003.25	26.4489
3007.56	26.1911
3011.88	26.0182
3016.19	26.2408
3020.49	26.5913
3024.8	27.0539
3029.1	27.5497
3033.4	28.1225
3037.7	28.3798
3041.99	28.569
3046.28	28.7148
3050.57	28.7681
3054.85	28.7054
3059.13	28.0722
3063.41	27.1344
3067.69	26.0753
3071.96	25.2511
3076.23	25.6556
3080.5	26.2004
3084.76	26.9691
3089.02	27.8679
3093.28	28.5993
3097.53	29.131
3101.79	29.0362
3106.04	28.7073
3110.28	28.2788
3114.53	27.7122
3118.77	27.2965
3123.01	27.5261
3127.24	28.3396
3131.47	29.1236
3135.7	29.9763
3139.93	30.8231
3144.15	30.6139
3148.38	30.048
3152.59	29.4094
3156.81	28.8576
3161.02	28.3742
3165.23	28.1715
3169.44	28.353
3173.64	28.465
3177.84	28.7954
3182.04	29.1731
3186.24	29.4565
3190.43	29.3407
3194.62	29.1579
3198.81	28.9854
3202.99	28.8449
3207.17	28.8534
3211.35	29.0065
3215.53	29.2506
3219.7	29.5115
3223.87	29.8246
3228.04	29.6365
3232.2	29.2431
3236.36	28.9463
3240.52	29.301
3244.68	29.062
3248.83	28.3347
3252.98	28.1607
3257.13	28.0033
3261.28	28.4399
3265.42	29.2762
3269.56	30.3893
3273.7	31.428
3277.83	32.2752
3281.96	32.788
3286.09	32.7287
3290.22	32.0278
3294.34	31.2702
3298.46	30.8084
3302.58	30.1462
3306.69	29.5858
3310.8	29.2619
3314.91	29.1934
3319.02	29.3249
3323.12	29.4891
3327.23	29.3731
3331.32	29.1462
3335.42	29.2149
3339.51	29.1626
3343.6	29.1073
3347.69	29.222
3351.78	29.4037
3355.86	29.6441
3359.94	29.9745
3364.02	30.3217
3368.09	30.5053
3372.16	30.8445
3376.23	31.253
3380.29	31.3218
3384.36	31.1289
3388.42	30.6115
3392.48	29.8976
3396.53	29.1765
3400.58	28.4982
3404.63	28.021
3408.68	27.9862
3412.73	28.3241
3416.77	29.0779
3420.81	29.8855
3424.84	30.6766
3428.88	31.2595
3432.91	31.7102
3436.94	31.668
3440.96	31.496
3444.99	31.0983
3449.01	30.6117
3453.03	30.1094
3457.04	29.6401
3461.05	29.6037
3465.06	29.9046
3469.07	30.3672
3473.08	30.9424
3477.08	31.3033
3481.08	31.4113
3485.07	31.511
3489.07	31.4956
3493.06	31.5988
3497.05	31.9797
3501.04	32.4519
3505.02	32.9582
3509	33.5142
3512.98	33.7239
3516.96	33.4441
3520.93	32.8822
3524.9	32.2609
3528.87	31.6281
3532.83	31.0137
3536.8	30.5618
3540.76	30.2086
3544.71	30.1537
3548.67	30.0089
3552.62	29.9497
3556.57	29.9758
3560.52	30.0281
3564.47	30.4147
3568.41	30.8564
3572.35	31.315
3576.29	31.7235
3580.22	31.8397
3584.15	31.933
3588.08	32.4403
3592.01	32.6662
3595.93	32.7054
3599.85	32.7438
3603.77	32.3906
3607.69	31.9963
3611.61	31.6071
3615.52	31.3106
3619.43	31.612
3623.33	31.9758
3627.24	32.3143
3631.14	32.6002
3635.04	32.8601
3638.93	32.7572
3642.83	32.3837
3646.72	32.1383
3650.61	31.893
3654.49	31.8664
3658.38	32.4485
3662.26	32.9277
3666.14	33.3656
3670.01	33.7535
3673.89	33.6892
3677.76	33.5124
3681.63	33.4532
3685.5	33.2545
3689.36	32.9332
3693.22	32.5952
3697.08	32.2904
3700.94	31.9175
3704.79	31.8593
3708.64	31.9919
3712.49	32.3255
3716.34	32.6035
3720.18	32.6603
3724.02	32.4085
3727.86	32.0612
3731.7	31.7172
3735.53	31.4156
3739.36	31.3403
3743.19	31.7755
3747.02	32.2919
3750.84	32.814
3754.66	33.247
3758.48	33.3471
3762.3	33.0374
3766.12	32.413
3769.93	31.7049
3773.74	31.1052
3777.54	30.6434
3781.35	31.1292
3785.15	31.8783
3788.95	32.7924
3792.75	33.8681
3796.54	34.2003
3800.34	33.7306
3804.13	32.8287
3807.91	32.0009
3811.7	31.3667
3815.48	31.1164
3819.26	31.5105
3823.04	32.1298
3826.82	32.8165
3830.59	33.5054
3834.36	34.1835
3838.13	34.7827
3841.89	34.43
3845.66	34.394
3849.42	34.387
3853.18	34.6073
3856.93	34.3883
3860.69	34.2402
3864.44	34.2144
3868.19	34.3638
3871.93	34.2445
3875.68	34.2542
3879.42	33.952
3883.16	33.5818
3886.9	33.1304
3890.63	32.6138
3894.37	32.4026
3898.1	32.7843
3901.82	33.114
3905.55	33.3578
3909.27	33.9731
3912.99	34.5173
3916.71	34.5222
3920.43	34.1826
3924.14	33.4588
3927.85	33.4875
3931.56	33.7788
3935.27	34.0304
3938.97	34.2019
3942.67	34.1005
3946.37	34.096
3950.07	33.8933
3953.77	33.6046
3957.46	33.5962
3961.15	33.8201
3964.84	34.0228
3968.52	34.1755
3972.2	34.2796
3975.89	34.3062
3979.56	34.2503
3983.24	34.113
3986.92	33.9491
3990.59	33.7874
3994.26	33.5756
3997.92	33.2953
3999.76	32.8135