File: Data/Raman/raw/bu19ts-coltan2-darker_core_150 (500nm)_633nm_edge_10%_x100_vis_h30um_10sx2_01.txt
#Acq. time (s)=	10
#Accumulations=	2
#Range (cm-¹)=	100...4000
#Windows=	1
#Auto scanning=	Off
#Autofocus=	Off
#Macrospot=	Off
#AutoExposure=	Off
#Spike filter=	Multiple accum.
#Delay time (s)=	2
#Binning=	1
#Readout mode=	Signal
#DeNoise=	Standard
#ICS correction=	On
#Dark correction=	Off
#Inst. Process=	Off
#Detector Gain=	Best Dynamic
#Detector ADC=	50 kHz HS
#Detector temperature (°C)=	-60.09
#Instrument=	LabRAM HR Evol
#Detector=	SIN-EM FIVIS
#Objective=	x100_VIS
#Grating=	150 (500nm)
#ND Filter=	10%
#Laser=	633nm_Edge
#Hole=	30.0125
#Temperature=	0
#Range=	Visible
#StageXY=	75x50mm Scan+
#StageZ=	Z motor
#X (µm)=	0
#Y (µm)=	0
#Z (µm)=	-1
#Full time(s)=	24
#Project=	20_10_27
#Sample=	BU19TS
#Site=
#Title=	BU19TS-Coltan3-darker_core_150 (500nm)_633nm_Edge_10%_x100_VIS_H30um_10sX2
#Remark=
#Date=	27.10.2020 17:03
#Acquired=	27.10.2020 17:03:35
100.764	74.1479
107.281	78.4608
113.791	83.5227
120.297	100.579
126.797	118.868
133.291	129.009
139.78	120.861
146.264	102.097
152.741	96.3049
159.214	104.435
165.682	105.139
172.144	100.045
178.601	91.408
185.053	84.2285
191.499	88.068
197.939	97.1616
204.374	120.881
210.805	114.158
217.23	98.8121
223.648	94.1032
230.063	98.8218
236.472	109.87
242.874	127.746
249.273	148.856
255.667	166.23
262.053	196.549
268.436	247.74
274.813	285.231
281.185	238.47
287.552	167.083
293.913	154.754
300.27	156.537
306.62	149.48
312.965	142.618
319.306	132.035
325.64	119.864
331.971	107.671
338.295	97.4799
344.614	89.9011
350.93	87.8617
357.238	88.2512
363.542	92.1758
369.842	92.4124
376.135	97.62
382.423	113.379
388.706	133.943
394.984	128.398
401.258	119.122
407.526	110.773
413.789	104.051
420.046	102.386
426.299	102.967
432.546	105.406
438.788	108.703
445.025	113.416
451.257	118.376
457.484	123.875
463.706	129.952
469.923	136.968
476.135	144.417
482.342	151.524
488.544	156.933
494.741	159.383
500.933	158.941
507.12	156.532
513.3	154.621
519.477	155.758
525.649	171.413
531.815	172.033
537.976	160.17
544.133	148.489
550.285	139.012
556.43	129.28
562.572	124.276
568.709	124.911
574.84	132.088
580.967	135.796
587.09	135.57
593.205	136.93
599.318	136.053
605.424	141.213
611.527	154.819
617.623	170.155
623.716	188.888
629.802	216.325
635.884	229.806
641.962	223.269
648.034	198.324
654.101	170.56
660.165	150.334
666.222	135.75
672.274	125.801
678.324	119.203
684.366	115.526
690.404	114.43
696.438	112.941
702.466	113.207
708.491	113.956
714.51	114.886
720.523	116.048
726.533	117.071
732.537	119.087
738.537	120.007
744.531	120.83
750.521	121.647
756.507	122.433
762.487	122.833
768.463	122.161
774.434	121.564
780.4	120.999
786.362	121.651
792.319	123.483
798.269	129.073
804.217	140.652
810.159	158.143
816.097	180.54
822.03	205.589
827.958	231.901
833.881	257.875
839.801	280.502
845.714	308.393
851.624	385.163
857.529	552.912
863.428	829.823
869.324	1374.52
875.215	2106.77
881.1	1937.2
886.982	964.514
892.858	467.477
898.73	283.877
904.597	197.215
910.459	151.721
916.318	129.948
922.171	116.815
928.02	104.833
933.864	95.3253
939.703	90.2501
945.539	87.7173
951.368	86.2746
957.194	84.8978
963.014	82.5046
968.832	80.413
974.643	78.5381
980.45	76.7744
986.253	75.0675
992.051	73.5117
997.844	72.7792
1003.63	71.5209
1009.42	69.5962
1015.2	68.6501
1020.97	68.2489
1026.74	68.7683
1032.51	69.4753
1038.27	70.2327
1044.03	70.7802
1049.78	71.0354
1055.53	71.2038
1061.27	71.1724
1067.01	70.9235
1072.75	70.4325
1078.48	69.5996
1084.2	68.687
1089.92	67.7846
1095.64	66.9612
1101.35	66.3982
1107.06	66.5191
1112.77	67.1204
1118.46	67.8349
1124.16	67.88
1129.85	67.6838
1135.53	67.4146
1141.22	67.0735
1146.89	65.6524
1152.56	63.9241
1158.23	62.2352
1163.9	60.9444
1169.56	60.2944
1175.21	60.3675
1180.86	59.9223
1186.51	59.3202
1192.15	59.2042
1197.78	59.6898
1203.42	60.32
1209.04	60.9001
1214.67	60.8672
1220.29	60.4771
1225.9	60.0073
1231.51	58.9382
1237.12	57.8348
1242.72	56.7402
1248.32	55.6922
1253.92	54.7641
1259.5	53.7817
1265.09	53.2032
1270.67	53.2571
1276.25	52.8724
1281.82	52.5886
1287.39	52.4096
1292.95	52.3381
1298.51	52.3437
1304.06	52.4082
1309.61	52.521
1315.16	52.6576
1320.7	52.7537
1326.24	52.9345
1331.77	52.6981
1337.3	52.2272
1342.83	51.7877
1348.35	51.3783
1353.86	51.1845
1359.37	50.943
1364.88	50.7785
1370.39	50.6813
1375.89	50.6432
1381.38	50.374
1386.87	47.8628
1392.36	48.4748
1397.84	49.5826
1403.32	50.0643
1408.79	49.219
1414.26	52.5373
1419.73	52.9332
1425.19	51.4462
1430.65	49.5967
1436.1	50.0934
1441.55	51.0427
1447	50.5599
1452.44	49.8925
1457.87	49.236
1463.31	49.047
1468.73	48.6968
1474.16	48.4181
1479.58	48.3115
1484.99	48.2675
1490.41	48.2625
1495.81	48.2581
1501.22	48.2505
1506.62	48.2481
1512.01	48.079
1517.4	47.4808
1522.79	47.2142
1528.17	47.0019
1533.55	46.5451
1538.93	45.8623
1544.3	45.471
1549.67	45.2603
1555.03	45.3818
1560.39	45.4958
1565.74	45.5728
1571.09	45.6325
1576.44	45.6569
1581.78	45.4867
1587.12	45.2601
1592.45	45.0635
1597.78	44.9705
1603.11	44.7037
1608.43	44.5166
1613.75	44.2804
1619.07	44.0385
1624.38	43.7932
1629.68	43.5629
1634.98	43.3088
1640.28	43.0517
1645.58	42.7605
1650.87	42.8001
1656.15	43.7169
1661.44	44.906
1666.71	45.0147
1671.99	44.561
1677.26	44.073
1682.53	44.5885
1687.79	45.8456
1693.05	45.0931
1698.3	44.5297
1703.55	44.8185
1708.8	45.7465
1714.04	46.899
1719.28	48.0271
1724.51	49.4173
1729.75	50.5058
1734.97	50.6278
1740.2	50.424
1745.42	49.9635
1750.63	48.918
1755.84	46.8774
1761.05	45.1556
1766.25	43.6124
1771.45	41.6634
1776.65	40.3239
1781.84	39.2362
1787.03	38.3752
1792.21	39.0723
1797.39	38.3214
1802.57	37.4881
1807.74	36.7069
1812.91	36.0722
1818.08	35.7634
1823.24	35.4443
1828.39	35.0434
1833.55	34.7343
1838.7	34.4933
1843.84	34.2557
1848.99	34.1694
1854.12	34.1664
1859.26	34.2623
1864.39	34.4412
1869.52	34.6426
1874.64	34.1115
1879.76	33.8338
1884.87	33.9718
1889.98	34.2297
1895.09	34.2882
1900.2	34.5375
1905.3	34.4337
1910.39	34.3063
1915.49	34.1374
1920.57	33.8474
1925.66	33.4619
1930.74	33.0457
1935.82	32.5673
1940.89	32.4309
1945.96	32.7727
1951.03	32.6847
1956.09	32.2398
1961.15	32.0182
1966.21	31.7156
1971.26	31.5336
1976.31	30.4562
1981.35	30.4357
1986.39	31.2832
1991.43	31.0922
1996.46	30.8526
2001.49	30.851
2006.52	30.9136
2011.54	31.057
2016.56	31.235
2021.57	31.5618
2026.58	31.4646
2031.59	31.3288
2036.59	30.8686
2041.59	30.5038
2046.59	30.0985
2051.58	29.789
2056.57	29.5379
2061.55	29.5774
2066.54	29.5723
2071.51	29.5831
2076.49	29.6252
2081.46	29.6784
2086.43	29.7392
2091.39	29.7088
2096.35	29.9293
2101.3	30.1625
2106.26	30.4012
2111.21	30.5264
2116.15	30.4603
2121.09	30.4432
2126.03	29.9361
2130.97	28.777
2135.9	27.9235
2140.83	27.261
2145.75	26.9986
2150.67	27.0206
2155.59	27.4406
2160.5	28.0069
2165.41	29.0802
2170.31	30.1902
2175.22	31.2766
2180.12	31.5528
2185.01	31.5593
2189.9	31.5103
2194.79	31.4074
2199.68	30.9836
2204.56	29.965
2209.43	29.0157
2214.31	28.3625
2219.18	28.5386
2224.05	28.7697
2228.91	29.0592
2233.77	29.3364
2238.63	28.9378
2243.48	28.5145
2248.33	28.0087
2253.17	27.8595
2258.02	27.7948
2262.86	28.1545
2267.69	28.3451
2272.52	28.5221
2277.35	28.5182
2282.18	27.9632
2287	27.3873
2291.82	26.8085
2296.63	26.2384
2301.44	25.7225
2306.25	25.2876
2311.05	25.0507
2315.86	25.182
2320.65	25.658
2325.45	26.3295
2330.24	27.1197
2335.03	27.9557
2339.81	28.8172
2344.59	28.7868
2349.37	28.5329
2354.14	28.2296
2358.91	27.8884
2363.67	27.5251
2368.44	27.0486
2373.2	26.7602
2377.95	26.4686
2382.71	26.4065
2387.46	26.7539
2392.2	27.1583
2396.95	27.0444
2401.68	26.4942
2406.42	26.0451
2411.15	26.0251
2415.88	25.8981
2420.61	25.7864
2425.33	25.5958
2430.05	25.5855
2434.77	25.6319
2439.48	25.7303
2444.19	25.8776
2448.89	26.0837
2453.6	26.3037
2458.29	26.4383
2462.99	26.1964
2467.68	25.5834
2472.37	24.9988
2477.06	24.2477
2481.74	24.1099
2486.42	24.4172
2491.1	24.8141
2495.77	25.254
2500.44	25.6406
2505.1	25.8685
2509.76	26.0112
2514.42	26.1225
2519.08	26.2082
2523.73	26.2942
2528.38	26.3726
2533.03	26.425
2537.67	26.1039
2542.31	25.7043
2546.95	25.2203
2551.58	24.7229
2556.21	24.0946
2560.84	23.8708
2565.46	24.2398
2570.08	24.5581
2574.7	24.967
2579.31	25.3219
2583.92	25.649
2588.53	26.0051
2593.13	25.8349
2597.73	25.5032
2602.33	25.278
2606.92	25.0067
2611.51	24.9555
2616.1	24.9779
2620.68	25.3565
2625.26	25.6264
2629.84	25.8962
2634.42	26.1314
2638.99	26.5368
2643.56	26.4912
2648.12	26.143
2652.68	25.8016
2657.24	25.5158
2661.8	25.5453
2666.35	25.3483
2670.9	25.2468
2675.45	24.9715
2679.99	24.6699
2684.53	24.3922
2689.06	24.2564
2693.6	24.2465
2698.13	24.3686
2702.66	24.9015
2707.18	25.2171
2711.7	25.4808
2716.22	25.5598
2720.73	25.1885
2725.24	24.863
2729.75	24.9754
2734.26	25.4642
2738.76	25.7425
2743.25	25.6957
2747.75	25.9022
2752.24	25.0533
2756.73	24.2751
2761.22	24.4938
2765.7	24.9112
2770.18	25.3469
2774.66	25.0232
2779.13	24.7702
2783.6	24.5431
2788.07	24.3604
2792.53	24.0223
2797	23.4972
2801.45	23.0509
2805.91	22.7937
2810.36	23.0028
2814.81	23.5589
2819.26	23.7557
2823.7	23.7224
2828.14	23.7085
2832.57	23.9579
2837.01	24.3124
2841.44	24.9183
2845.87	25.5724
2850.29	25.4476
2854.71	25.3557
2859.13	25.5174
2863.55	25.6255
2867.96	25.967
2872.37	25.8877
2876.77	25.7636
2881.18	25.585
2885.58	25.1584
2889.97	24.8157
2894.37	24.5923
2898.76	24.5255
2903.15	24.5136
2907.53	24.7368
2911.91	24.9272
2916.29	25.0945
2920.67	25.2523
2925.04	25.397
2929.41	25.5298
2933.78	25.6596
2938.14	25.7816
2942.5	25.8381
2946.86	25.4991
2951.22	24.8123
2955.57	24.4171
2959.92	24.2775
2964.26	24.206
2968.61	24.2036
2972.95	24.2518
2977.28	24.3367
2981.62	24.4442
2985.95	24.5698
2990.28	24.8278
2994.6	24.8097
2998.93	24.7678
3003.25	24.2408
3007.56	23.7115
3011.88	23.2934
3016.19	22.9916
3020.49	23.0898
3024.8	23.1557
3029.1	23.572
3033.4	24.1424
3037.7	24.7384
3041.99	24.9634
3046.28	25.1761
3050.57	25.4271
3054.85	25.6239
3059.13	25.6381
3063.41	25.5888
3067.69	25.2586
3071.96	24.9525
3076.23	24.5954
3080.5	24.3794
3084.76	24.2014
3089.02	24.4377
3093.28	24.5741
3097.53	24.6197
3101.79	24.6236
3106.04	24.5937
3110.28	24.3919
3114.53	24.1671
3118.77	24.1189
3123.01	24.3745
3127.24	24.959
3131.47	25.6042
3135.7	26.0273
3139.93	26.3716
3144.15	26.5178
3148.38	26.5066
3152.59	26.4881
3156.81	26.4053
3161.02	26.2824
3165.23	25.6081
3169.44	25.3133
3173.64	25.311
3177.84	25.4012
3182.04	25.7502
3186.24	26.2925
3190.43	26.8518
3194.62	26.7104
3198.81	26.7001
3202.99	26.7649
3207.17	27.2273
3211.35	27.4657
3215.53	27.6541
3219.7	27.803
3223.87	27.1133
3228.04	26.3089
3232.2	25.8613
3236.36	26.0439
3240.52	26.5442
3244.68	27.0478
3248.83	27.586
3252.98	28.0562
3257.13	27.9985
3261.28	27.8043
3265.42	27.3638
3269.56	27.1337
3273.7	26.9332
3277.83	26.7745
3281.96	26.6582
3286.09	26.3764
3290.22	26.0615
3294.34	25.8172
3298.46	25.6612
3302.58	25.8379
3306.69	25.9991
3310.8	26.606
3314.91	27.0471
3319.02	27.0886
3323.12	27.1524
3327.23	27.2425
3331.32	27.4038
3335.42	27.4429
3339.51	27.4578
3343.6	27.4436
3347.69	27.3756
3351.78	27.2725
3355.86	27.2986
3359.94	27.2219
3364.02	27.0709
3368.09	27.1119
3372.16	27.0312
3376.23	27.0358
3380.29	27.1333
3384.36	27.0112
3388.42	27.0521
3392.48	27.7942
3396.53	28.3527
3400.58	28.2369
3404.63	28.1044
3408.68	27.7449
3412.73	27.3352
3416.77	26.7676
3420.81	26.8373
3424.84	27.4746
3428.88	27.8557
3432.91	27.2487
3436.94	26.7066
3440.96	26.3357
3444.99	26.656
3449.01	27.3255
3453.03	27.9992
3457.04	28.4978
3461.05	28.3432
3465.06	28.1704
3469.07	28.0393
3473.08	27.6895
3477.08	27.2794
3481.08	27.3416
3485.07	27.7777
3489.07	28.221
3493.06	28.6507
3497.05	28.7705
3501.04	28.6103
3505.02	28.415
3509	27.9399
3512.98	27.5221
3516.96	27.2145
3520.93	26.9942
3524.9	27.5053
3528.87	28.1199
3532.83	28.7495
3536.8	28.9524
3540.76	29.0616
3544.71	29.0817
3548.67	29.128
3552.62	29.1788
3556.57	29.233
3560.52	29.2943
3564.47	29.3566
3568.41	29.3211
3572.35	28.9191
3576.29	28.5463
3580.22	28.272
3584.15	28.2493
3588.08	28.6434
3592.01	28.967
3595.93	28.7854
3599.85	28.6129
3603.77	28.5475
3607.69	28.5391
3611.61	28.863
3615.52	29.142
3619.43	29.421
3623.33	29.706
3627.24	30.0077
3631.14	30.1447
3635.04	30.0729
3638.93	29.9051
3642.83	29.7223
3646.72	29.5246
3650.61	29.1917
3654.49	29.189
3658.38	29.3153
3662.26	29.6749
3666.14	29.6729
3670.01	29.4237
3673.89	29.1972
3677.76	29.0221
3681.63	28.9285
3685.5	28.4519
3689.36	28.3915
3693.22	28.4235
3697.08	28.7944
3700.94	29.167
3704.79	29.5366
3708.64	29.8963
3712.49	30.1773
3716.34	30.3058
3720.18	29.287
3724.02	28.9536
3727.86	29.3382
3731.7	30.3217
3735.53	31.3086
3739.36	31.7588
3743.19	31.8929
3747.02	31.1486
3750.84	29.9889
3754.66	28.9083
3758.48	28.3292
3762.3	28.3257
3766.12	28.9585
3769.93	30.0104
3773.74	31.2231
3777.54	32.3594
3781.35	32.6613
3785.15	32.4065
3788.95	31.0188
3792.75	30.3374
3796.54	30.7452
3800.34	31.375
3804.13	32.1515
3807.91	31.5809
3811.7	30.9836
3815.48	30.3976
3819.26	29.8487
3823.04	29.1711
3826.82	29.2091
3830.59	29.949
3834.36	30.5582
3838.13	30.7242
3841.89	31.3128
3845.66	31.458
3849.42	31.5268
3853.18	32.0824
3856.93	32.0309
3860.69	31.9412
3864.44	31.7626
3868.19	31.0027
3871.93	30.816
3875.68	30.8423
3879.42	30.6712
3883.16	30.4113
3886.9	30.3007
3890.63	30.2492
3894.37	30.1779
3898.1	30.0332
3901.82	30.2433
3905.55	30.8129
3909.27	31.2256
3912.99	31.5189
3916.71	31.7288
3920.43	31.4513
3924.14	31.1857
3927.85	31.1354
3931.56	30.8928
3935.27	30.6705
3938.97	30.2212
3942.67	29.7985
3946.37	29.446
3950.07	29.2307
3953.77	29.3145
3957.46	30.8141
3961.15	32.075
3964.84	33.0084
3968.52	32.9953
3972.2	33.0207
3975.89	33.1762
3979.56	32.6243
3983.24	31.8724
3986.92	31.7468
3990.59	31.6644
3994.26	31.9082
3997.92	32.0682
3999.76	31.8788