File: Data/Raman/raw/bu19ts-coltan3-overgrowth_150 (500nm)_633nm_edge_10%_x100_vis_h30um_10sx2_01.txt
#Acq. time (s)=	10
#Accumulations=	2
#Range (cm-¹)=	100...4000
#Windows=	1
#Auto scanning=	Off
#Autofocus=	Off
#Macrospot=	Off
#AutoExposure=	Off
#Spike filter=	Multiple accum.
#Delay time (s)=	2
#Binning=	1
#Readout mode=	Signal
#DeNoise=	Standard
#ICS correction=	On
#Dark correction=	Off
#Inst. Process=	Off
#Detector Gain=	Best Dynamic
#Detector ADC=	50 kHz HS
#Detector temperature (°C)=	-60.09
#Instrument=	LabRAM HR Evol
#Detector=	SIN-EM FIVIS
#Objective=	x100_VIS
#Grating=	150 (500nm)
#ND Filter=	10%
#Laser=	633nm_Edge
#Hole=	30.0125
#Temperature=	0
#Range=	Visible
#StageXY=	75x50mm Scan+
#StageZ=	Z motor
#X (µm)=	0
#Y (µm)=	0
#Z (µm)=	-2.5
#Full time(s)=	24
#Project=	20_10_27
#Sample=	BU19TS
#Site=
#Title=	BU19TS-Coltan2-overgrowth_150 (500nm)_633nm_Edge_10%_x100_VIS_H30um_10sX2
#Remark=
#Date=	27.10.2020 16:57
#Acquired=	27.10.2020 16:57:36
100.764	64.4815
107.281	68.0566
113.791	78.9681
120.297	91.4547
126.797	113.669
133.291	125.486
139.78	118.123
146.264	96.5166
152.741	78.0423
159.214	80.4902
165.682	85.9538
172.144	91.9137
178.601	91.7737
185.053	84.9655
191.499	78.6613
197.939	85.1111
204.374	99.6068
210.805	98.8397
217.23	85.3742
223.648	79.5373
230.063	84.8976
236.472	95.2905
242.874	112.082
249.273	131.311
255.667	145.932
262.053	155.385
268.436	192.904
274.813	213.421
281.185	199.83
287.552	156.666
293.913	135.878
300.27	126.005
306.62	119.952
312.965	115.093
319.306	108.505
325.64	100.934
331.971	92.871
338.295	85.7169
344.614	79.5272
350.93	76.81
357.238	75.7884
363.542	76.7119
369.842	79.9853
376.135	84.8285
382.423	90.0227
388.706	96.4106
394.984	99.7433
401.258	98.6205
407.526	91.8152
413.789	86.7756
420.046	83.9346
426.299	85.9139
432.546	87.8519
438.788	92.156
445.025	96.5036
451.257	100.775
457.484	104.926
463.706	109.361
469.923	115.568
476.135	122.004
482.342	129.362
488.544	133.79
494.741	135.979
500.933	136.896
507.12	136.797
513.3	133.563
519.477	140.591
525.649	156.469
531.815	157.869
537.976	150.412
544.133	133.612
550.285	122.159
556.43	114.866
562.572	108.279
568.709	105.461
574.84	103.787
580.967	104.044
587.09	106.107
593.205	109.779
599.318	113.983
605.424	120.639
611.527	128.96
617.623	139.863
623.716	155.263
629.802	178.166
635.884	189.334
641.962	178.165
648.034	158.794
654.101	136.379
660.165	121.742
666.222	110.581
672.274	103.622
678.324	99.1844
684.366	95.9977
690.404	94.6944
696.438	95.5998
702.466	96.6196
708.491	97.5706
714.51	98.2397
720.523	98.9751
726.533	99.3725
732.537	99.5957
738.537	99.6823
744.531	99.6584
750.521	99.5413
756.507	99.3674
762.487	97.9073
768.463	96.6618
774.434	96.094
780.4	96.0148
786.362	95.3283
792.319	96.9347
798.269	102.064
804.217	109.375
810.159	120.174
816.097	133.849
822.03	150.056
827.958	173.251
833.881	193.846
839.801	217.862
845.714	249.824
851.624	308.021
857.529	477.327
863.428	679.21
869.324	1103.87
875.215	1679.82
881.1	1616.47
886.982	861.353
892.858	392.493
898.73	234.823
904.597	160.827
910.459	129.607
916.318	110.443
922.171	96.2658
928.02	87.9741
933.864	81.2991
939.703	77.8212
945.539	74.1511
951.368	72.8521
957.194	70.9217
963.014	69.1623
968.832	67.4714
974.643	66.303
980.45	65.2943
986.253	64.422
992.051	63.66
997.844	62.8822
1003.63	62.2015
1009.42	61.8419
1015.2	61.3386
1020.97	60.8591
1026.74	60.268
1032.51	59.7109
1038.27	58.769
1044.03	57.5411
1049.78	56.7085
1055.53	56.5061
1061.27	56.6742
1067.01	56.9883
1072.75	57.3443
1078.48	57.6462
1084.2	57.7406
1089.92	57.8243
1095.64	57.6912
1101.35	57.0508
1107.06	56.6461
1112.77	55.9572
1118.46	55.1555
1124.16	54.22
1129.85	53.7529
1135.53	53.3085
1141.22	53.1448
1146.89	52.9483
1152.56	52.748
1158.23	54.4766
1163.9	54.0165
1169.56	53.2852
1175.21	52.5454
1180.86	51.8246
1186.51	51.1279
1192.15	50.4438
1197.78	49.7785
1203.42	49.1352
1209.04	48.5269
1214.67	48.0001
1220.29	47.3042
1225.9	47.065
1231.51	46.9119
1237.12	46.8287
1242.72	46.7988
1248.32	46.7616
1253.92	45.6206
1259.5	44.7557
1265.09	44.2037
1270.67	43.8032
1276.25	43.541
1281.82	43.8995
1287.39	44.3944
1292.95	45.0012
1298.51	45.4905
1304.06	45.1756
1309.61	44.8542
1315.16	44.5298
1320.7	44.2067
1326.24	43.8888
1331.77	43.5772
1337.3	43.285
1342.83	43.0032
1348.35	42.7845
1353.86	42.6268
1359.37	42.4077
1364.88	42.5338
1370.39	42.5677
1375.89	42.4386
1381.38	42.3385
1386.87	42.2747
1392.36	42.2584
1397.84	42.2772
1403.32	42.379
1408.79	42.5782
1414.26	43.0075
1419.73	43.6737
1425.19	43.8214
1430.65	43.6681
1436.1	43.5129
1441.55	43.3736
1447	43.2383
1452.44	43.1071
1457.87	42.9796
1463.31	42.9486
1468.73	42.8734
1474.16	42.783
1479.58	42.6671
1484.99	42.5333
1490.41	42.3773
1495.81	42.1979
1501.22	41.9914
1506.62	41.7617
1512.01	41.4026
1517.4	40.9795
1522.79	40.5443
1528.17	40.1818
1533.55	39.8658
1538.93	39.6061
1544.3	39.3791
1549.67	39.2683
1555.03	39.3374
1560.39	39.125
1565.74	38.882
1571.09	38.7007
1576.44	38.5135
1581.78	38.4577
1587.12	38.4567
1592.45	38.527
1597.78	38.6508
1603.11	38.1468
1608.43	37.7225
1613.75	37.6208
1619.07	37.5216
1624.38	37.4611
1629.68	37.4523
1634.98	37.4867
1640.28	37.5397
1645.58	37.6226
1650.87	37.8293
1656.15	38.019
1661.44	38.244
1666.71	38.5018
1671.99	38.7894
1677.26	39.1034
1682.53	38.9754
1687.79	38.6763
1693.05	38.6235
1698.3	39.1708
1703.55	40.2723
1708.8	41.2213
1714.04	41.6027
1719.28	41.9768
1724.51	42.3412
1729.75	42.6956
1734.97	43.0304
1740.2	43.3332
1745.42	43.3604
1750.63	42.0763
1755.84	41.0862
1761.05	39.2817
1766.25	35.9456
1771.45	32.93
1776.65	31.422
1781.84	31.9226
1787.03	31.1967
1792.21	30.7652
1797.39	30.8677
1802.57	31.3485
1807.74	32.1384
1812.91	32.829
1818.08	32.008
1823.24	30.8897
1828.39	29.512
1833.55	28.662
1838.7	28.1406
1843.84	27.298
1848.99	28.5878
1854.12	29.768
1859.26	30.3715
1864.39	29.7
1869.52	29.2174
1874.64	28.9644
1879.76	28.9685
1884.87	29.0683
1889.98	29.2353
1895.09	29.4454
1900.2	29.1899
1905.3	28.9528
1910.39	28.7489
1915.49	28.5905
1920.57	28.4692
1925.66	28.3719
1930.74	28.3172
1935.82	28.2707
1940.89	28.2298
1945.96	28.1772
1951.03	28.129
1956.09	28.0825
1961.15	28.0342
1966.21	27.9815
1971.26	27.9066
1976.31	27.8144
1981.35	27.6901
1986.39	27.568
1991.43	27.457
1996.46	27.2692
2001.49	27.3067
2006.52	27.1703
2011.54	27.0542
2016.56	27.0084
2021.57	27.0159
2026.58	27.1281
2031.59	27.1998
2036.59	27.2847
2041.59	27.3899
2046.59	27.4979
2051.58	27.5974
2056.57	27.6768
2061.55	27.5444
2066.54	27.239
2071.51	27.0378
2076.49	26.8633
2081.46	26.7098
2086.43	26.7928
2091.39	26.8223
2096.35	26.7735
2101.3	26.7523
2106.26	26.7368
2111.21	26.689
2116.15	26.3991
2121.09	26.2166
2126.03	26.0354
2130.97	25.8945
2135.9	25.8685
2140.83	25.7728
2145.75	25.6841
2150.67	25.6549
2155.59	25.6447
2160.5	25.6066
2165.41	25.67
2170.31	26.5435
2175.22	27.4107
2180.12	28.2674
2185.01	29.1088
2189.9	29.4468
2194.79	28.9926
2199.68	28.0545
2204.56	26.5638
2209.43	25.8315
2214.31	25.6853
2219.18	25.5315
2224.05	25.4143
2228.91	25.4315
2233.77	25.5864
2238.63	25.7985
2243.48	26.0427
2248.33	26.1045
2253.17	26.095
2258.02	26.2803
2262.86	26.0742
2267.69	25.6517
2272.52	25.4975
2277.35	25.3693
2282.18	25.2655
2287	25.3036
2291.82	24.9963
2296.63	24.5571
2301.44	24.6374
2306.25	25.2083
2311.05	25.6874
2315.86	25.1716
2320.65	24.4384
2325.45	23.8094
2330.24	23.3065
2335.03	22.9518
2339.81	22.7277
2344.59	22.6537
2349.37	23.0681
2354.14	23.6033
2358.91	24.2368
2363.67	24.9459
2368.44	25.2639
2373.2	24.5737
2377.95	24.4648
2382.71	24.6747
2387.46	25.1356
2392.2	25.5073
2396.95	25.8042
2401.68	25.9435
2406.42	26.1516
2411.15	25.9576
2415.88	25.8747
2420.61	25.7497
2425.33	25.1106
2430.05	24.4646
2434.77	23.8168
2439.48	23.7865
2444.19	24.241
2448.89	24.7708
2453.6	25.1172
2458.29	25.4036
2462.99	25.6139
2467.68	25.4733
2472.37	25.3521
2477.06	25.2384
2481.74	24.972
2486.42	24.6412
2491.1	24.3023
2495.77	24.108
2500.44	24.3247
2505.1	24.6011
2509.76	24.8876
2514.42	25.096
2519.08	24.8117
2523.73	24.0945
2528.38	23.6226
2533.03	23.2363
2537.67	23.3401
2542.31	23.9806
2546.95	24.5559
2551.58	25.1149
2556.21	25.1171
2560.84	24.7225
2565.46	24.2968
2570.08	23.8901
2574.7	23.5675
2579.31	23.3685
2583.92	23.5769
2588.53	23.9274
2593.13	24.1358
2597.73	24.3172
2602.33	24.4832
2606.92	24.6352
2611.51	24.6414
2616.1	23.8392
2620.68	22.2063
2625.26	22.4317
2629.84	23.2474
2634.42	24.549
2638.99	24.9911
2643.56	25.1061
2648.12	25.2181
2652.68	25.3179
2657.24	25.399
2661.8	25.382
2666.35	25.0625
2670.9	24.7671
2675.45	24.5132
2679.99	23.9698
2684.53	23.1923
2689.06	22.565
2693.6	22.1213
2698.13	21.814
2702.66	21.4886
2707.18	21.722
2711.7	22.0333
2716.22	22.4087
2720.73	22.8261
2725.24	23.1961
2729.75	23.5973
2734.26	23.9226
2738.76	24.0497
2743.25	24.0426
2747.75	23.9346
2752.24	23.7093
2756.73	23.6012
2761.22	23.5356
2765.7	23.5083
2770.18	23.5192
2774.66	23.566
2779.13	23.6449
2783.6	23.7501
2788.07	23.8738
2792.53	24.0025
2797	23.8652
2801.45	23.6237
2805.91	23.3867
2810.36	23.2365
2814.81	23.1349
2819.26	23.092
2823.7	23.0904
2828.14	23.2521
2832.57	23.3391
2837.01	23.4454
2841.44	23.584
2845.87	23.7278
2850.29	23.8603
2854.71	23.9946
2859.13	24.1287
2863.55	24.1273
2867.96	24.107
2872.37	24.2012
2876.77	24.3243
2881.18	24.4723
2885.58	24.5257
2889.97	24.5329
2894.37	24.5267
2898.76	24.5051
2903.15	24.4734
2907.53	24.4018
2911.91	24.3502
2916.29	24.3017
2920.67	23.8285
2925.04	23.1442
2929.41	22.5537
2933.78	24.0896
2938.14	24.4155
2942.5	24.5415
2946.86	24.6907
2951.22	24.9188
2955.57	24.8509
2959.92	24.0465
2964.26	23.6402
2968.61	23.6032
2972.95	23.3884
2977.28	23.2512
2981.62	23.3517
2985.95	23.4556
2990.28	23.5427
2994.6	23.6467
2998.93	23.7188
3003.25	23.7637
3007.56	23.8997
3011.88	24.0783
3016.19	24.291
3020.49	24.499
3024.8	24.3484
3029.1	24.6069
3033.4	24.8058
3037.7	24.9178
3041.99	24.9514
3046.28	24.9157
3050.57	24.9505
3054.85	24.7032
3059.13	24.4302
3063.41	24.1469
3067.69	23.8674
3071.96	23.6051
3076.23	23.3516
3080.5	23.1774
3084.76	23.0676
3089.02	22.8416
3093.28	23.0413
3097.53	23.3206
3101.79	23.8408
3106.04	24.2612
3110.28	24.6957
3114.53	25.1032
3118.77	25.4853
3123.01	25.8391
3127.24	25.9465
3131.47	25.8831
3135.7	25.8039
3139.93	25.7374
3144.15	25.676
3148.38	25.6312
3152.59	25.6077
3156.81	25.6093
3161.02	25.7033
3165.23	25.513
3169.44	25.2627
3173.64	25.0177
3177.84	24.8002
3182.04	24.6348
3186.24	24.5401
3190.43	24.5283
3194.62	24.6401
3198.81	25.0181
3202.99	25.5761
3207.17	26.1495
3211.35	26.4461
3215.53	26.4403
3219.7	26.406
3223.87	26.3416
3228.04	26.2572
3232.2	26.155
3236.36	25.9797
3240.52	25.8474
3244.68	25.7098
3248.83	26
3252.98	26.2444
3257.13	26.4976
3261.28	26.8164
3265.42	26.9397
3269.56	27.0044
3273.7	26.8645
3277.83	26.7543
3281.96	26.4777
3286.09	26.1412
3290.22	26.4024
3294.34	26.948
3298.46	27.0898
3302.58	27.1614
3306.69	27.2411
3310.8	27.3422
3314.91	27.4654
3319.02	27.6068
3323.12	27.7755
3327.23	27.9529
3331.32	28.1263
3335.42	28.1637
3339.51	28.1294
3343.6	28.0347
3347.69	27.9374
3351.78	27.7668
3355.86	27.5729
3359.94	27.3634
3364.02	27.1444
3368.09	26.9482
3372.16	26.8095
3376.23	26.7625
3380.29	26.845
3384.36	27.6555
3388.42	28.0396
3392.48	27.9565
3396.53	27.8793
3400.58	27.5
3404.63	25.7449
3408.68	24.8599
3412.73	26.6095
3416.77	27.587
3420.81	27.5958
3424.84	27.8404
3428.88	28.4525
3432.91	27.8593
3436.94	27.4448
3440.96	27.1567
3444.99	26.7688
3449.01	26.6364
3453.03	25.5376
3457.04	24.9921
3461.05	25.5347
3465.06	26.8287
3469.07	28.181
3473.08	28.2267
3477.08	28.138
3481.08	28.0658
3485.07	28.1716
3489.07	28.2819
3493.06	28.546
3497.05	28.51
3501.04	28.1781
3505.02	27.5734
3509	27.0746
3512.98	27.1837
3516.96	27.6961
3520.93	28.2197
3524.9	28.5062
3528.87	28.2796
3532.83	28.1038
3536.8	28.0956
3540.76	28.1076
3544.71	28.151
3548.67	28.3298
3552.62	28.545
3556.57	28.754
3560.52	28.9438
3564.47	29.0511
3568.41	29.0751
3572.35	28.8262
3576.29	28.0619
3580.22	27.0345
3584.15	26.6444
3588.08	28.2469
3592.01	30.0957
3595.93	30.1789
3599.85	30.2025
3603.77	30.1273
3607.69	29.9164
3611.61	29.7214
3615.52	29.5709
3619.43	29.3556
3623.33	28.8081
3627.24	28.1571
3631.14	28.0295
3635.04	27.5925
3638.93	26.2348
3642.83	25.7621
3646.72	27.6124
3650.61	29.5648
3654.49	30.9998
3658.38	30.9708
3662.26	30.2312
3666.14	29.833
3670.01	29.798
3673.89	29.8545
3677.76	29.2921
3681.63	29.4087
3685.5	29.631
3689.36	29.9399
3693.22	30.2335
3697.08	29.3255
3700.94	27.973
3704.79	27.448
3708.64	28.0357
3712.49	28.8474
3716.34	29.8732
3720.18	30.0887
3724.02	29.8593
3727.86	29.5207
3731.7	29.1893
3735.53	28.8747
3739.36	28.582
3743.19	28.4527
3747.02	28.321
3750.84	28.2496
3754.66	28.2424
3758.48	28.3623
3762.3	28.8401
3766.12	29.4345
3769.93	30.1423
3773.74	30.9676
3777.54	31.5249
3781.35	31.9552
3785.15	31.9841
3788.95	32.0862
3792.75	31.9158
3796.54	31.6262
3800.34	31.3092
3804.13	30.9793
3807.91	30.6517
3811.7	30.2799
3815.48	30.2052
3819.26	30.234
3823.04	29.8254
3826.82	30.0547
3830.59	30.645
3834.36	31.3363
3838.13	31.5177
3841.89	31.6698
3845.66	31.5932
3849.42	31.4398
3853.18	31.6157
3856.93	31.8177
3860.69	32.2107
3864.44	32.1888
3868.19	32.036
3871.93	32.0096
3875.68	32.0673
3879.42	31.8003
3883.16	31.5372
3886.9	31.3035
3890.63	31.098
3894.37	30.9729
3898.1	30.9247
3901.82	31.2418
3905.55	31.6303
3909.27	32.0624
3912.99	32.0023
3916.71	31.9536
3920.43	31.9299
3924.14	31.982
3927.85	31.9924
3931.56	31.5356
3935.27	31.0628
3938.97	30.7439
3942.67	30.921
3946.37	30.7246
3950.07	30.7995
3953.77	32.1465
3957.46	33.7946
3961.15	35.6576
3964.84	35.5456
3968.52	35.0225
3972.2	33.0176
3975.89	31.7488
3979.56	30.9972
3983.24	30.5807
3986.92	30.2565
3990.59	29.9852
3994.26	29.888
3997.92	29.7215
3999.76	29.7091