File: Data/Raman/raw/bu19w-ore4-rim_150 (500nm)_532nm_edge_10%_x100_vis_h30um_30sx2_01.txt
#Acq. time (s)=	30
#Accumulations=	2
#Range (cm-¹)=	100...4000
#Windows=	1
#Auto scanning=	Off
#Autofocus=	Off
#Macrospot=	Off
#AutoExposure=	Off
#Spike filter=	Multiple accum.
#Delay time (s)=	2
#Binning=	1
#Readout mode=	Signal
#DeNoise=	Standard
#ICS correction=	On
#Dark correction=	Off
#Inst. Process=	Off
#Detector Gain=	Best Dynamic
#Detector ADC=	50 kHz HS
#Detector temperature (°C)=	-60.09
#Instrument=	LabRAM HR Evol
#Detector=	SIN-EM FIVIS
#Objective=	x100_VIS
#Grating=	150 (500nm)
#ND Filter=	10%
#Laser=	532nm_Edge
#Hole=	30.0125
#Temperature=	0
#Range=	Visible
#StageXY=	75x50mm Scan+
#StageZ=	Z motor
#X (µm)=	0
#Y (µm)=	0
#Z (µm)=	71.4
#Full time(mm:ss)=	1:04
#Project=	21_02_17
#Sample=	BU19w
#Site=
#Title=	BU19w-Ore4-rim_150 (500nm)_532nm_Edge_10%_x100_VIS_H30um_30sX2
#Remark=
#Date=	17.02.2021 11:34
#Acquired=	17.02.2021 11:34:18
104.068	1127.24
108.69	1142.89
113.309	1160.94
117.926	1176.51
122.541	1187.49
127.152	1194.78
131.762	1189.9
136.37	1177.28
140.976	1142.42
145.577	1106.58
150.179	1056.08
154.778	1010.3
159.374	983.744
163.967	965.476
168.559	956.973
173.149	959.02
177.736	967.57
182.32	978.841
186.903	992.766
191.484	1008.91
196.062	1019.08
200.637	1032.06
205.211	1048.05
209.783	1065.01
214.35	1082.37
218.918	1098.07
223.483	1116.41
228.043	1134.31
232.604	1152.94
237.162	1170.59
241.719	1188.34
246.271	1203.4
250.822	1217.73
255.37	1230.37
259.917	1240.83
264.462	1249.55
269.002	1255.97
273.543	1258.4
278.081	1259.37
282.615	1260.07
287.149	1259.03
291.681	1258.72
296.208	1258.04
300.735	1263.32
305.258	1245.66
309.781	1218.77
314.302	1181.83
318.818	1114.07
323.334	1076.7
327.846	1049.11
332.358	1034.53
336.867	1036.27
341.373	1039.38
345.878	1044.16
350.379	1051.2
354.879	1059.76
359.376	1069.54
363.872	1080.3
368.366	1091.86
372.856	1109.01
377.346	1130.88
381.832	1153.88
386.317	1181.64
390.798	1208.79
395.279	1243.41
399.756	1278.74
404.233	1314.65
408.705	1350.81
413.177	1387.25
417.645	1428.83
422.113	1461.36
426.577	1491.67
431.041	1510.53
435.5	1531.2
439.959	1548.54
444.415	1551.55
448.87	1555.13
453.32	1564.39
457.771	1571.15
462.217	1576.71
466.662	1583.76
471.106	1587.78
475.546	1598.14
479.986	1599.67
484.421	1603.31
488.857	1599.56
493.288	1592.71
497.717	1581.87
502.146	1559.26
506.571	1542.43
510.996	1522.05
515.417	1504.14
519.835	1489.08
524.254	1474.16
528.668	1462.56
533.082	1451.69
537.492	1446.82
541.9	1453.36
546.308	1462.55
550.711	1478.6
555.113	1499.21
559.514	1524
563.911	1552.24
568.307	1587.51
572.702	1629.25
577.092	1661.75
581.481	1721.34
585.87	1804.76
590.254	1895.84
594.637	1992.05
599.019	2092.03
603.397	2192.99
607.773	2288.87
612.149	2364.89
616.521	2422.14
620.891	2453.47
625.261	2474.71
629.626	2491.43
633.99	2488.99
638.351	2478.14
642.712	2456.55
647.07	2424.87
651.425	2384.04
655.778	2363.16
660.13	2279
664.479	2185.63
668.826	2084.8
673.171	1977.9
677.515	1867.79
681.856	1760.1
686.194	1674.15
690.531	1585.81
694.865	1508.06
699.199	1438.69
703.529	1379.4
707.857	1318.47
712.183	1263.94
716.507	1213.3
720.831	1167.85
725.151	1127.29
729.468	1090.62
733.784	1058.16
738.097	1029.82
742.409	1005.83
746.718	985.827
751.028	966.247
755.333	949.407
759.636	936.58
763.938	922.433
768.237	917.431
772.534	911.5
776.829	911.079
781.124	912.457
785.415	916.247
789.704	921.739
793.991	928.546
798.276	936.859
802.558	946.226
806.839	955.018
811.118	961.911
815.395	966.815
819.669	969.512
823.942	967.552
828.213	962.808
832.481	967.93
836.75	947.49
841.014	926.897
845.277	908.211
849.537	878.822
853.796	840.334
858.052	803.62
862.306	762.85
866.559	721.56
870.809	681.982
875.058	641.53
879.304	602.874
883.548	571.288
887.791	544.437
892.031	520.582
896.269	500.754
900.505	482.308
904.74	468.674
908.972	454.995
913.202	445.154
917.431	436.396
921.657	430.013
925.879	423.401
930.102	418.765
934.322	414.841
938.54	410.212
942.756	406.697
946.971	402.054
951.183	398.208
955.393	394.689
959.602	390.72
963.808	387.106
968.013	381.291
972.215	376.753
976.413	373.486
980.612	370.107
984.808	366.752
989.003	363.259
993.195	359.778
997.386	357.45
1001.57	354.845
1005.76	351.967
1009.94	348.699
1014.13	344.571
1018.31	340.486
1022.49	336.52
1026.66	332.243
1030.84	328.58
1035.01	325.227
1039.18	322.258
1043.35	319.662
1047.51	317.447
1051.68	315.601
1055.84	314.386
1060	313.456
1064.16	312.752
1068.32	311.954
1072.47	311.23
1076.63	310.472
1080.78	309.928
1084.93	308.702
1089.07	307.121
1093.22	305.494
1097.36	304.215
1101.5	303.246
1105.64	301.621
1109.78	300.954
1113.91	300.36
1118.05	299.823
1122.18	299.349
1126.31	298.943
1130.44	298.723
1134.56	298.485
1138.68	298.168
1142.81	297.642
1146.93	296.743
1151.04	295.531
1155.16	293.932
1159.27	291.987
1163.39	289.641
1167.5	286.679
1171.6	283.858
1175.71	282.88
1179.81	282.025
1183.92	281.242
1188.02	280.441
1192.12	279.713
1196.21	278.988
1200.31	278.237
1204.4	277.446
1208.49	276.658
1212.58	275.86
1216.67	275.067
1220.75	274.261
1224.84	273.477
1228.92	272.674
1233	271.842
1237.08	271.063
1241.15	270.29
1245.22	269.559
1249.3	268.865
1253.37	268.21
1257.43	267.599
1261.5	267.013
1265.56	266.57
1269.63	266.141
1273.69	265.859
1277.75	265.695
1281.8	265.424
1285.86	264.661
1289.91	264.603
1293.96	264.541
1298.01	264.642
1302.06	264.594
1306.1	264.391
1310.15	264.097
1314.19	263.558
1318.23	262.857
1322.27	261.833
1326.3	260.79
1330.34	259.471
1334.37	258.108
1338.4	256.572
1342.43	255.004
1346.45	253.144
1350.48	251.237
1354.5	249.342
1358.52	247.433
1362.54	245.593
1366.56	243.868
1370.58	242.287
1374.59	240.827
1378.6	239.645
1382.61	238.396
1386.62	237.646
1390.63	237.061
1394.63	236.551
1398.63	236.101
1402.63	235.711
1406.63	235.383
1410.63	235.084
1414.62	234.82
1418.62	234.529
1422.61	233.936
1426.6	233.393
1430.58	232.738
1434.57	232
1438.56	231.119
1442.54	230.135
1446.52	229.187
1450.5	228.224
1454.47	227.65
1458.45	227.292
1462.42	227.14
1466.39	227.319
1470.36	227.429
1474.33	227.196
1478.3	227.2
1482.26	227.33
1486.22	227.493
1490.18	227.598
1494.14	227.502
1498.1	227.048
1502.05	225.844
1506	224.331
1509.96	223.464
1513.9	222.535
1517.85	221.361
1521.8	220.035
1525.74	218.524
1529.68	216.556
1533.62	214.44
1537.56	213.056
1541.5	212.327
1545.43	212.606
1549.37	213.701
1553.3	212.977
1557.23	212.23
1561.15	212.086
1565.08	211.686
1569.01	210.959
1572.93	210.092
1576.85	209.196
1580.77	208.169
1584.68	207.152
1588.6	206.364
1592.51	205.792
1596.42	205.37
1600.33	205.173
1604.24	205.098
1608.15	205.124
1612.05	205.196
1615.95	205.266
1619.85	205.337
1623.75	205.361
1627.65	205.247
1631.55	204.952
1635.44	204.64
1639.33	204.275
1643.22	203.809
1647.11	203.184
1651	202.515
1654.88	201.879
1658.77	201.139
1662.65	200.589
1666.53	198.944
1670.4	197.401
1674.28	195.943
1678.15	194.565
1682.03	192.62
1685.9	190.661
1689.77	188.446
1693.63	185.539
1697.5	182.241
1701.36	179.591
1705.22	177.055
1709.08	174.813
1712.94	172.801
1716.8	171.081
1720.65	169.665
1724.51	168.561
1728.36	167.637
1732.21	166.883
1736.06	166.157
1739.9	165.332
1743.75	164.416
1747.59	164.596
1751.43	163.88
1755.27	163.112
1759.11	162.304
1762.94	161.453
1766.78	160.556
1770.61	159.635
1774.44	158.669
1778.27	157.663
1782.09	156.691
1785.92	155.644
1789.74	153.626
1793.56	153.026
1797.38	152.2
1801.2	152.139
1805.02	152.792
1808.83	152.985
1812.65	154.392
1816.46	155.564
1820.27	155.441
1824.08	154.518
1827.88	152.687
1831.69	150.862
1835.49	149.255
1839.29	147.554
1843.09	146.346
1846.89	145.319
1850.69	144.435
1854.48	143.7
1858.27	143.05
1862.06	142.489
1865.85	142.021
1869.64	141.628
1873.43	141.325
1877.21	141.05
1880.99	140.861
1884.77	140.685
1888.55	140.591
1892.33	140.441
1896.11	140.382
1899.88	140.558
1903.65	140.732
1907.42	140.954
1911.19	141.161
1914.96	141.384
1918.72	141.574
1922.49	141.746
1926.25	141.846
1930.01	141.846
1933.77	141.368
1937.52	140.921
1941.28	140.17
1945.03	139.383
1948.79	138.282
1952.53	137.133
1956.28	136.018
1960.03	135.271
1963.78	134.76
1967.52	134.554
1971.26	134.566
1975	134.824
1978.74	135.216
1982.48	135.692
1986.21	136.118
1989.95	136.353
1993.68	136.572
1997.41	137.013
2001.14	136.92
2004.86	136.263
2008.59	135.489
2012.31	134.755
2016.03	134.023
2019.76	133.344
2023.47	132.718
2027.19	132.151
2030.91	131.693
2034.62	131.259
2038.33	130.922
2042.04	130.602
2045.75	130.373
2049.46	130.182
2053.16	129.949
2056.86	129.731
2060.57	129.573
2064.27	129.478
2067.97	129.444
2071.66	129.619
2075.36	129.794
2079.05	130.027
2082.74	130.366
2086.44	130.66
2090.12	130.771
2093.81	130.383
2097.5	129.908
2101.18	129.44
2104.86	129.131
2108.54	128.75
2112.22	128.354
2115.9	127.995
2119.58	127.557
2123.25	127.112
2126.92	126.746
2130.59	126.859
2134.26	126.994
2137.93	127.021
2141.6	126.997
2145.26	126.191
2148.92	125.249
2152.58	124.172
2156.24	123.245
2159.9	122.518
2163.56	121.926
2167.21	121.301
2170.87	121.332
2174.52	121.46
2178.17	121.623
2181.82	121.827
2185.46	122.062
2189.11	122.569
2192.75	122.614
2196.39	122.627
2200.03	122.515
2203.67	122.376
2207.31	122.198
2210.94	121.977
2214.58	121.744
2218.21	121.5
2221.84	121.247
2225.47	120.971
2229.1	120.711
2232.72	120.414
2236.35	120.139
2239.97	119.824
2243.59	119.529
2247.21	119.193
2250.83	118.883
2254.44	118.538
2258.06	118.214
2261.67	117.957
2265.28	117.632
2268.89	117.277
2272.5	116.913
2276.11	116.536
2279.71	116.162
2283.32	115.778
2286.92	115.348
2290.52	115.055
2294.12	114.559
2297.71	114.025
2301.31	113.486
2304.9	112.943
2308.5	112.385
2312.09	111.833
2315.68	111.297
2319.26	110.77
2322.85	110.258
2326.44	109.605
2330.02	109.332
2333.6	109.084
2337.18	109.216
2340.76	109.326
2344.33	109.446
2347.91	109.487
2351.48	109.573
2355.06	109.624
2358.63	109.673
2362.19	109.715
2365.76	109.711
2369.33	109.535
2372.89	109.309
2376.46	109.129
2380.02	108.921
2383.58	108.746
2387.13	108.552
2390.69	108.346
2394.25	108.211
2397.8	108.025
2401.35	107.741
2404.9	107.443
2408.45	107.13
2412	106.804
2415.54	106.462
2419.09	106.107
2422.63	105.741
2426.17	105.363
2429.71	104.882
2433.25	104.564
2436.78	104.231
2440.32	103.922
2443.85	103.624
2447.38	103.595
2450.91	103.382
2454.44	103.245
2457.97	103.061
2461.5	102.919
2465.02	102.758
2468.54	102.637
2472.06	102.514
2475.58	102.4
2479.1	102.304
2482.62	102.323
2486.13	102.068
2489.65	101.838
2493.16	101.54
2496.67	101.26
2500.18	100.663
2503.68	100.225
2507.19	99.4857
2510.69	99.3286
2514.2	99.219
2517.7	99.1251
2521.2	99.0291
2524.7	99.3837
2528.19	99.4821
2531.69	99.579
2535.18	99.6454
2538.67	99.7934
2542.17	99.8534
2545.65	99.8485
2549.14	99.6478
2552.63	99.4815
2556.11	99.2738
2559.6	99.0006
2563.08	98.7487
2566.56	98.4351
2570.04	98.103
2573.51	97.7358
2576.99	97.3864
2580.46	96.9835
2583.94	96.6041
2587.41	96.1487
2590.88	95.6922
2594.34	95.2292
2597.81	94.7649
2601.28	94.2987
2604.74	93.8307
2608.2	93.3636
2611.66	92.8957
2615.12	92.4312
2618.58	91.9682
2622.04	91.5184
2625.49	91.1701
2628.94	90.728
2632.4	90.2411
2635.85	89.9409
2639.3	89.6544
2642.74	89.4338
2646.19	89.1874
2649.63	89.0266
2653.07	88.9148
2656.52	88.8546
2659.96	88.8288
2663.4	88.8135
2666.83	88.8146
2670.27	88.8818
2673.7	88.9318
2677.14	89.085
2680.57	89.1292
2684	89.1921
2687.42	89.2237
2690.85	89.2744
2694.28	89.3062
2697.7	89.1873
2701.12	89.0851
2704.54	89.0446
2707.96	88.9406
2711.38	88.8306
2714.8	88.7335
2718.21	88.6061
2721.62	88.4953
2725.04	88.3496
2728.45	88.2144
2731.86	88.0666
2735.26	87.9216
2738.67	87.8166
2742.07	87.8135
2745.48	87.793
2748.88	87.8989
2752.28	87.9284
2755.68	87.9686
2759.08	88.0194
2762.47	88.1192
2765.87	88.2182
2769.26	88.4494
2772.65	88.3971
2776.04	87.9855
2779.43	87.4311
2782.82	86.9386
2786.21	86.5751
2789.59	86.3033
2792.97	86.0618
2796.35	85.8743
2799.73	85.7378
2803.11	85.7511
2806.49	85.598
2809.87	85.2941
2813.24	85.0255
2816.61	84.761
2819.99	84.4983
2823.35	84.4076
2826.72	84.2406
2830.09	84.057
2833.46	83.8727
2836.82	83.6821
2840.18	83.4966
2843.55	83.3116
2846.91	83.1435
2850.26	82.9508
2853.62	82.7309
2856.98	82.4737
2860.33	82.1612
2863.68	81.8079
2867.04	81.39
2870.39	80.6982
2873.74	80.142
2877.08	79.5866
2880.43	79.0707
2883.77	78.5858
2887.12	78.1378
2890.46	77.7706
2893.8	77.9067
2897.14	78.068
2900.47	78.4047
2903.81	78.9133
2907.14	79.5271
2910.48	80.2908
2913.81	81.0954
2917.14	81.7576
2920.47	82.4445
2923.8	82.6963
2927.12	82.1296
2930.45	81.5725
2933.77	81.0592
2937.09	80.679
2940.41	80.2447
2943.73	80.0757
2947.05	79.2663
2950.37	78.4873
2953.68	77.8204
2957	77.3881
2960.31	77.0921
2963.62	77.0021
2966.93	77.0153
2970.24	77.2711
2973.54	77.7722
2976.85	79.5556
2980.15	79.4444
2983.45	79.3494
2986.76	79.1979
2990.05	78.8924
2993.35	78.6213
2996.65	78.3047
2999.94	78.0234
3003.24	77.7052
3006.53	77.4095
3009.82	77.0937
3013.11	76.7881
3016.4	76.4815
3019.69	76.1819
3022.97	75.8938
3026.26	75.6118
3029.54	75.3519
3032.82	75.0983
3036.1	74.8541
3039.38	74.6357
3042.66	74.4349
3045.94	74.2809
3049.21	74.1082
3052.49	74.0518
3055.76	73.9453
3059.03	74.0338
3062.3	74.0876
3065.57	74.2227
3068.83	74.3663
3072.1	74.5365
3075.36	74.6819
3078.62	74.8608
3081.88	75.0242
3085.14	75.2108
3088.4	75.3656
3091.66	75.5163
3094.92	75.6621
3098.17	75.7639
3101.42	75.5594
3104.67	75.4023
3107.93	75.3118
3111.17	75.0097
3114.42	74.6913
3117.67	74.3189
3120.91	73.9539
3124.16	73.5368
3127.4	72.9664
3130.64	72.5456
3133.88	72.0028
3137.12	71.7404
3140.35	71.469
3143.59	71.4097
3146.82	71.3518
3150.05	71.3068
3153.29	71.2364
3156.52	71.2305
3159.74	71.2285
3162.97	71.2465
3166.2	71.2285
3169.42	71.2197
3172.65	71.1947
3175.87	71.1645
3179.09	71.1657
3182.31	71.0124
3185.53	70.8683
3188.74	70.7974
3191.96	70.609
3195.17	70.3452
3198.38	70.1168
3201.59	69.8221
3204.81	69.5261
3208.01	69.2151
3211.22	68.9235
3214.43	68.6166
3217.63	68.3181
3220.83	68.0096
3224.04	67.7452
3227.24	67.4343
3230.44	67.2218
3233.64	66.9009
3236.83	66.8154
3240.03	66.8783
3243.22	67.0797
3246.41	67.2026
3249.6	67.2768
3252.8	67.4208
3255.98	67.5823
3259.17	67.6334
3262.36	67.7117
3265.54	67.9248
3268.72	67.7353
3271.91	67.2401
3275.09	66.7372
3278.27	66.3094
3281.45	65.7703
3284.62	65.2926
3287.8	64.8108
3290.97	64.3608
3294.15	63.9575
3297.32	63.6269
3300.49	63.2912
3303.66	62.8324
3306.83	62.9791
3309.99	63.1551
3313.16	63.3443
3316.32	63.5432
3319.48	63.771
3322.64	63.9965
3325.8	64.2409
3328.96	64.4794
3332.12	64.7227
3335.27	64.9618
3338.43	65.189
3341.58	65.418
3344.74	65.6154
3347.89	65.699
3351.04	65.8048
3354.18	65.8847
3357.33	65.9355
3360.48	65.9484
3363.62	65.9757
3366.76	65.971
3369.91	65.9532
3373.05	65.9245
3376.19	65.8611
3379.32	65.7929
3382.46	65.6836
3385.6	65.5742
3388.73	65.4386
3391.86	65.2806
3394.99	65.0872
3398.13	64.928
3401.25	64.6114
3404.38	64.3118
3407.51	63.9584
3410.63	63.4964
3413.76	62.6736
3416.88	62.0344
3420	61.6211
3423.12	61.5378
3426.24	61.709
3429.36	61.332
3432.47	60.949
3435.59	60.6208
3438.7	60.4381
3441.81	60.6377
3444.93	60.8365
3448.03	60.9955
3451.14	61.2024
3454.25	61.4238
3457.36	61.6294
3460.46	61.7868
3463.56	61.9803
3466.67	62.0274
3469.77	61.654
3472.87	61.3332
3475.97	60.9557
3479.06	60.5525
3482.16	60.1628
3485.25	59.7607
3488.35	59.3571
3491.44	58.9654
3494.53	58.576
3497.62	58.2518
3500.71	58.1355
3503.79	57.9197
3506.88	57.8771
3509.96	57.9061
3513.05	57.9517
3516.13	58.0407
3519.21	58.1192
3522.29	58.2369
3525.37	58.3564
3528.45	58.5044
3531.52	58.636
3534.6	58.8846
3537.67	58.8626
3540.74	58.8195
3543.81	58.6366
3546.88	58.4042
3549.95	58.1719
3553.02	57.9447
3556.08	57.7206
3559.15	57.4968
3562.21	56.9219
3565.27	56.8528
3568.33	56.8019
3571.39	56.7609
3574.45	56.7575
3577.51	56.921
3580.56	57.0102
3583.62	57.1027
3586.67	57.1895
3589.72	57.2432
3592.78	57.3121
3595.83	57.3566
3598.87	57.3989
3601.92	57.4401
3604.97	57.2307
3608.01	57.2217
3611.06	57.4284
3614.1	57.3542
3617.14	57.2851
3620.18	57.1623
3623.22	57.0811
3626.25	57.0033
3629.29	56.8808
3632.32	56.7692
3635.36	56.6453
3638.39	56.5132
3641.42	56.3424
3644.45	56.1889
3647.48	56.0223
3650.51	55.8446
3653.54	55.7034
3656.56	55.4627
3659.58	55.2415
3662.61	54.9915
3665.63	54.7599
3668.65	54.5068
3671.67	54.2692
3674.69	54.0191
3677.7	53.7808
3680.72	53.5402
3683.73	53.3069
3686.75	53.0826
3689.76	52.8722
3692.77	52.6789
3695.78	52.4996
3698.79	52.3456
3701.79	52.2099
3704.8	52.1055
3707.8	52.0264
3710.81	52.0435
3713.81	52.119
3716.81	52.2158
3719.81	52.3261
3722.81	52.3915
3725.81	52.7006
3728.8	53.0423
3731.8	53.4658
3734.79	53.8797
3737.78	54.2885
3740.77	54.7178
3743.76	55.105
3746.75	55.236
3749.74	55.1006
3752.73	54.9503
3755.71	54.7794
3758.7	54.3154
3761.68	53.8008
3764.66	53.3046
3767.64	52.6276
3770.62	52.192
3773.6	51.7856
3776.58	51.4261
3779.55	51.2185
3782.53	51.0002
3785.5	50.7904
3788.47	50.5934
3791.44	50.4242
3794.41	50.266
3797.38	50.1275
3800.35	50.0017
3803.32	49.8871
3806.28	49.7885
3809.25	49.6924
3812.21	49.6166
3815.17	49.5346
3818.13	49.4782
3821.09	49.412
3824.05	49.3725
3827	49.3219
3829.96	49.2969
3832.92	49.261
3835.87	49.2481
3838.82	49.224
3841.77	49.2198
3844.72	49.2068
3847.67	49.1762
3850.62	49.1683
3853.56	49.1615
3856.51	49.1583
3859.45	49.1487
3862.4	49.1424
3865.34	49.1276
3868.28	49.1161
3871.22	49.0943
3874.16	49.076
3877.09	49.046
3880.03	49.0194
3882.96	48.985
3885.9	48.956
3888.83	48.9168
3891.76	48.8747
3894.69	48.8302
3897.62	48.7841
3900.55	48.6692
3903.47	48.6134
3906.4	48.5527
3909.32	48.5017
3912.24	48.4387
3915.17	48.3895
3918.09	48.3269
3921.01	48.2812
3923.92	48.2235
3926.84	48.183
3929.76	48.133
3932.67	48.0811
3935.59	48.0614
3938.5	48.0179
3941.41	48.0095
3944.32	47.9756
3947.23	47.9777
3950.14	47.9542
3953.05	47.9488
3955.95	47.9535
3958.86	47.9692
3961.76	47.9676
3964.66	47.9762
3967.56	47.98
3970.46	47.9776
3973.36	47.9672
3976.26	47.9469
3979.16	47.9242
3982.05	47.8831
3984.94	47.8214
3987.84	47.7366
3990.73	47.6273
3993.62	47.4914
3996.51	46.7326
3999.4	45.6969