File: Data/Raman/raw/bu19w-ore1-core_150 (500nm)_532nm_edge_10%_x100_vis_h30um_30sx2_01.txt
#Acq. time (s)=	30
#Accumulations=	2
#Range (cm-¹)=	100...4000
#Windows=	1
#Auto scanning=	Off
#Autofocus=	Off
#Macrospot=	Off
#AutoExposure=	Off
#Spike filter=	Multiple accum.
#Delay time (s)=	2
#Binning=	1
#Readout mode=	Signal
#DeNoise=	Standard
#ICS correction=	On
#Dark correction=	Off
#Inst. Process=	Off
#Detector Gain=	Best Dynamic
#Detector ADC=	50 kHz HS
#Detector temperature (°C)=	-60.09
#Instrument=	LabRAM HR Evol
#Detector=	SIN-EM FIVIS
#Objective=	x100_VIS
#Grating=	150 (500nm)
#ND Filter=	10%
#Laser=	532nm_Edge
#Hole=	30.0125
#Temperature=	0
#Range=	Visible
#StageXY=	75x50mm Scan+
#StageZ=	Z motor
#X (µm)=	0
#Y (µm)=	0
#Z (µm)=	71
#Full time(mm:ss)=	1:04
#Project=	21_02_17
#Sample=	BU19w
#Site=
#Title=	BU19w-Ore1-core_150 (500nm)_532nm_Edge_10%_x100_VIS_H30um_30sX2
#Remark=
#Date=	17.02.2021 12:03
#Acquired=	17.02.2021 12:03:03
104.068	2245.3
108.69	2252.03
113.309	2254.58
117.926	2252
122.541	2244.87
127.152	2246.42
131.762	2235.54
136.37	2266.77
140.976	2187.12
145.577	2036.5
150.179	1943.52
154.778	1895.33
159.374	1854.03
163.967	1835.94
168.559	1839.75
173.149	1859.63
177.736	1881.59
182.32	1910.07
186.903	1948.32
191.484	1992.11
196.062	2036.15
200.637	2083.45
205.211	2128.73
209.783	2174.14
214.35	2216.88
218.918	2258.58
223.483	2294.62
228.043	2325
232.604	2350.85
237.162	2373.06
241.719	2393.06
246.271	2405.61
250.822	2416.52
255.37	2416.98
259.917	2405.66
264.462	2376.6
269.002	2349.38
273.543	2313.13
278.081	2292.91
282.615	2272.95
287.149	2248.15
291.681	2232.74
296.208	2240.88
300.735	2263.94
305.258	2217.66
309.781	2173.84
314.302	2122.13
318.818	2075.68
323.334	2028.31
327.846	2014.02
332.358	2017.91
336.867	2034.55
341.373	2057.45
345.878	2083.84
350.379	2128.26
354.879	2146.23
359.376	2152.03
363.872	2163.49
368.366	2188.5
372.856	2222.65
377.346	2267.98
381.832	2354.01
386.317	2435.41
390.798	2551.03
395.279	2672.64
399.756	2809.53
404.233	2952.92
408.705	3107.67
413.177	3262.92
417.645	3413.7
422.113	3518.43
426.577	3595.37
431.041	3642.44
435.5	3601.56
439.959	3539.27
444.415	3427.11
448.87	3291.01
453.32	3142.86
457.771	3000.86
462.217	2873.91
466.662	2777.29
471.106	2696.55
475.546	2631.86
479.986	2573.99
484.421	2521.12
488.857	2490.85
493.288	2443.04
497.717	2393.7
502.146	2347.26
506.571	2304.46
510.996	2266.44
515.417	2233.1
519.835	2206.09
524.254	2188.96
528.668	2181.73
533.082	2186.06
537.492	2207.82
541.9	2238.35
546.308	2280.89
550.711	2335.57
555.113	2408.84
559.514	2490.27
563.911	2585.75
568.307	2695.16
572.702	2819.8
577.092	2958.12
581.481	3111.08
585.87	3278.08
590.254	3459.36
594.637	3664.98
599.019	3883.4
603.397	4122.5
607.773	4352.57
612.149	4542.62
616.521	4703.24
620.891	4613.71
625.261	4470.12
629.626	4299.42
633.99	4109.47
638.351	3930.65
642.712	3767.9
647.07	3607.75
651.425	3443.37
655.778	3287.63
660.13	3132.26
664.479	2979.46
668.826	2833.46
673.171	2694.08
677.515	2562.34
681.856	2438.58
686.194	2322.62
690.531	2215.06
694.865	2115
699.199	2024.47
703.529	1941.6
707.857	1863.18
712.183	1790.63
716.507	1724.48
720.831	1663.44
725.151	1608.04
729.468	1557.76
733.784	1510.26
738.097	1466.18
742.409	1428.47
746.718	1395.72
751.028	1369.57
755.333	1348.48
759.636	1332.09
763.938	1319.95
768.237	1311.47
772.534	1305.58
776.829	1303.02
781.124	1303.64
785.415	1308.14
789.704	1313.53
793.991	1315.57
798.276	1316.65
802.558	1316.56
806.839	1314.67
811.118	1313.87
815.395	1319.49
819.669	1326.98
823.942	1329.02
828.213	1323.67
832.481	1311.59
836.75	1295.15
841.014	1261.54
845.277	1251.26
849.537	1185.69
853.796	1118.93
858.052	1043.83
862.306	972.328
866.559	908.498
870.809	843.933
875.058	794.665
879.304	743.941
883.548	705.221
887.791	671.596
892.031	643.462
896.269	619.873
900.505	600.528
904.74	584.002
908.972	572.767
913.202	563.585
917.431	555.319
921.657	547.643
925.879	539.808
930.102	532.705
934.322	526.044
938.54	519.74
942.756	513.752
946.971	508.039
951.183	502.176
955.393	497.282
959.602	492.743
963.808	488.729
968.013	484.956
972.215	480.874
976.413	477.334
980.612	473.684
984.808	470.325
989.003	466.315
993.195	462.746
997.386	457.421
1001.57	451.192
1005.76	444.52
1009.94	437.636
1014.13	430.778
1018.31	423.386
1022.49	416.162
1026.66	409.251
1030.84	402.66
1035.01	396.479
1039.18	390.657
1043.35	385.438
1047.51	380.824
1051.68	376.841
1055.84	373.464
1060	370.821
1064.16	368.368
1068.32	366.756
1072.47	365.436
1076.63	364.316
1080.78	363.25
1084.93	362.232
1089.07	361.225
1093.22	360.215
1097.36	359.2
1101.5	358.163
1105.64	357.131
1109.78	356.024
1113.91	354.941
1118.05	353.896
1122.18	352.909
1126.31	351.984
1130.44	351.105
1134.56	350.221
1138.68	349.264
1142.81	348.167
1146.93	346.88
1151.04	345.3
1155.16	342.755
1159.27	340.107
1163.39	337.163
1167.5	334.05
1171.6	330.871
1175.71	327.589
1179.81	324.602
1183.92	321.794
1188.02	319.242
1192.12	317.105
1196.21	315.515
1200.31	314.425
1204.4	313.864
1208.49	313.668
1212.58	313.681
1216.67	313.887
1220.75	314.168
1224.84	314.212
1228.92	314.209
1233	313.614
1237.08	312.85
1241.15	312.011
1245.22	311.127
1249.3	310.242
1253.37	309.379
1257.43	308.524
1261.5	307.715
1265.56	306.941
1269.63	306.496
1273.69	306.212
1277.75	305.998
1281.8	305.864
1285.86	305.652
1289.91	305.444
1293.96	305.155
1298.01	304.483
1302.06	303.698
1306.1	302.915
1310.15	302.158
1314.19	301.474
1318.23	300.863
1322.27	300.346
1326.3	299.645
1330.34	298.371
1334.37	296.638
1338.4	294.64
1342.43	292.452
1346.45	290.174
1350.48	287.888
1354.5	285.692
1358.52	283.823
1362.54	281.629
1366.56	279.476
1370.58	277.412
1374.59	275.437
1378.6	273.576
1382.61	271.811
1386.62	270.408
1390.63	269.241
1394.63	268.492
1398.63	267.993
1402.63	267.67
1406.63	267.525
1410.63	267.546
1414.62	267.741
1418.62	268.12
1422.61	268.638
1426.6	269.105
1430.58	269.273
1434.57	269.408
1438.56	269.517
1442.54	268.773
1446.52	267.757
1450.5	266.31
1454.47	264.769
1458.45	263.184
1462.42	261.647
1466.39	260.342
1470.36	259.774
1474.33	259.373
1478.3	259.184
1482.26	259.214
1486.22	259.329
1490.18	259.416
1494.14	259.525
1498.1	259.419
1502.05	259.436
1506	258.538
1509.96	257.546
1513.9	256.533
1517.85	255.513
1521.8	254.485
1525.74	253.518
1529.68	252.66
1533.62	251.971
1537.56	251.411
1541.5	250.96
1545.43	250.635
1549.37	250.388
1553.3	250.228
1557.23	250.175
1561.15	250.306
1565.08	250.614
1569.01	251.032
1572.93	251.553
1576.85	252.086
1580.77	252.716
1584.68	253.355
1588.6	253.951
1592.51	254.153
1596.42	254.224
1600.33	254.105
1604.24	253.811
1608.15	253.258
1612.05	252.407
1615.95	251.25
1619.85	249.774
1623.75	248.008
1627.65	245.86
1631.55	243.58
1635.44	241.086
1639.33	238.477
1643.22	235.847
1647.11	233.183
1651	230.496
1654.88	227.801
1658.77	225.142
1662.65	222.502
1666.53	220.138
1670.4	217.472
1674.28	214.846
1678.15	212.235
1682.03	209.68
1685.9	207.167
1689.77	204.7
1693.63	202.306
1697.5	199.978
1701.36	197.764
1705.22	195.674
1709.08	193.768
1712.94	192.068
1716.8	190.451
1720.65	188.927
1724.51	187.438
1728.36	186.146
1732.21	184.93
1736.06	183.786
1739.9	182.684
1743.75	181.626
1747.59	180.612
1751.43	179.626
1755.27	178.681
1759.11	177.766
1762.94	176.897
1766.78	175.639
1770.61	174.348
1774.44	172.994
1778.27	171.5
1782.09	170.113
1785.92	168.713
1789.74	167.352
1793.56	166.062
1797.38	164.907
1801.2	163.698
1805.02	162.93
1808.83	162.243
1812.65	161.591
1816.46	160.99
1820.27	160.443
1824.08	159.922
1827.88	159.433
1831.69	158.966
1835.49	158.502
1839.29	158.031
1843.09	157.561
1846.89	157.066
1850.69	156.391
1854.48	155.7
1858.27	155.079
1862.06	154.415
1865.85	153.766
1869.64	153.162
1873.43	152.619
1877.21	152.149
1880.99	151.772
1884.77	151.625
1888.55	151.557
1892.33	151.363
1896.11	151.095
1899.88	150.34
1903.65	150.284
1907.42	150.739
1911.19	151.603
1914.96	152.524
1918.72	152.479
1922.49	150.981
1926.25	140.756
1930.01	135.075
1933.77	141.128
1937.52	142.668
1941.28	143.65
1945.03	144.801
1948.79	145.246
1952.53	145.558
1956.28	145.771
1960.03	145.878
1963.78	145.902
1967.52	145.882
1971.26	145.77
1975	145.671
1978.74	145.47
1982.48	145.329
1986.21	145.079
1989.95	144.89
1993.68	144.675
1997.41	144.372
2001.14	144.146
2004.86	143.816
2008.59	143.457
2012.31	143.166
2016.03	142.508
2019.76	141.84
2023.47	141.123
2027.19	140.402
2030.91	139.636
2034.62	138.939
2038.33	137.813
2042.04	137.386
2045.75	136.99
2049.46	136.951
2053.16	136.821
2056.86	136.702
2060.57	136.609
2064.27	136.486
2067.97	136.395
2071.66	136.278
2075.36	136.17
2079.05	136.046
2082.74	135.902
2086.44	135.76
2090.12	135.463
2093.81	135.168
2097.5	134.926
2101.18	134.639
2104.86	134.364
2108.54	134.057
2112.22	133.751
2115.9	133.428
2119.58	133.097
2123.25	132.762
2126.92	132.41
2130.59	132.067
2134.26	131.699
2137.93	131.351
2141.6	130.972
2145.26	130.622
2148.92	130.237
2152.58	129.885
2156.24	129.5
2159.9	129.15
2163.56	128.786
2167.21	128.441
2170.87	128.087
2174.52	127.671
2178.17	127.204
2181.82	126.759
2185.46	126.293
2189.11	125.843
2192.75	125.396
2196.39	125.114
2200.03	124.803
2203.67	125.238
2207.31	125.648
2210.94	126.108
2214.58	126.585
2218.21	127.048
2221.84	127.462
2225.47	127.83
2229.1	127.979
2232.72	128.086
2236.35	128.007
2239.97	127.679
2243.59	127.266
2247.21	126.68
2250.83	126.09
2254.44	125.414
2258.06	124.564
2261.67	124.029
2265.28	123.48
2268.89	122.992
2272.5	122.807
2276.11	122.562
2279.71	122.307
2283.32	122.31
2286.92	121.957
2290.52	121.59
2294.12	121.213
2297.71	120.809
2301.31	120.316
2304.9	119.836
2308.5	119.353
2312.09	118.852
2315.68	118.408
2319.26	117.971
2322.85	117.523
2326.44	117.164
2330.02	116.78
2333.6	116.453
2337.18	116.097
2340.76	115.797
2344.33	115.47
2347.91	115.23
2351.48	115.013
2355.06	114.766
2358.63	114.528
2362.19	114.295
2365.76	114.072
2369.33	113.846
2372.89	113.628
2376.46	113.403
2380.02	113.182
2383.58	112.951
2387.13	112.718
2390.69	112.473
2394.25	112.216
2397.8	111.952
2401.35	111.66
2404.9	111.37
2408.45	110.996
2412	110.579
2415.54	110.173
2419.09	109.749
2422.63	109.302
2426.17	108.88
2429.71	108.406
2433.25	107.923
2436.78	107.423
2440.32	106.75
2443.85	106.522
2447.38	107.022
2450.91	107.443
2454.44	107.815
2457.97	108.034
2461.5	108.382
2465.02	108.402
2468.54	108.187
2472.06	107.882
2475.58	107.49
2479.1	107.011
2482.62	106.484
2486.13	105.898
2489.65	105.28
2493.16	104.64
2496.67	103.974
2500.18	103.323
2503.68	102.645
2507.19	102.023
2510.69	101.541
2514.2	101.112
2517.7	100.618
2521.2	100.207
2524.7	99.7899
2528.19	99.4648
2531.69	99.1995
2535.18	98.9351
2538.67	98.9287
2542.17	98.9195
2545.65	98.9643
2549.14	99.0635
2552.63	99.2079
2556.11	99.3733
2559.6	99.55
2563.08	99.7385
2566.56	99.8853
2570.04	100.011
2573.51	99.5451
2576.99	99.2485
2580.46	98.8139
2583.94	98.4231
2587.41	97.4933
2590.88	96.5545
2594.34	95.7449
2597.81	95.4442
2601.28	95.6332
2604.74	96.0223
2608.2	96.6436
2611.66	97.4044
2615.12	98.2839
2618.58	98.0594
2622.04	97.3879
2625.49	96.6776
2628.94	95.9913
2632.4	95.3552
2635.85	94.7523
2639.3	94.2149
2642.74	93.7351
2646.19	93.3648
2649.63	93.0853
2653.07	92.7707
2656.52	92.8699
2659.96	93.0724
2663.4	93.2763
2666.83	93.5368
2670.27	93.8608
2673.7	94.083
2677.14	94.3349
2680.57	94.5552
2684	94.6919
2687.42	94.5864
2690.85	94.46
2694.28	94.3388
2697.7	93.9561
2701.12	93.554
2704.54	93.1148
2707.96	92.6827
2711.38	92.2278
2714.8	91.7679
2718.21	91.3051
2721.62	90.8737
2725.04	90.4482
2728.45	90.0291
2731.86	89.6823
2735.26	89.5247
2738.67	89.2164
2742.07	89.2841
2745.48	89.3431
2748.88	89.4622
2752.28	89.6113
2755.68	89.7884
2759.08	89.9378
2762.47	90.0932
2765.87	90.2391
2769.26	90.3568
2772.65	90.4135
2776.04	90.4417
2779.43	90.2744
2782.82	89.906
2786.21	89.492
2789.59	89.0567
2792.97	88.5949
2796.35	88.1299
2799.73	87.6977
2803.11	87.2495
2806.49	86.8195
2809.87	86.4421
2813.24	86.1087
2816.61	86.0191
2819.99	86.0667
2823.35	86.1127
2826.72	86.4332
2830.09	86.7765
2833.46	87.1575
2836.82	87.5339
2840.18	87.8912
2843.55	88.1856
2846.91	88.4693
2850.26	88.6482
2853.62	88.4304
2856.98	88.1676
2860.33	87.8988
2863.68	87.1183
2867.04	86.2317
2870.39	85.3033
2873.74	84.368
2877.08	83.4368
2880.43	82.5462
2883.77	81.6576
2887.12	81.0458
2890.46	80.5903
2893.8	80.2145
2897.14	79.9755
2900.47	79.8203
2903.81	79.8205
2907.14	80.0678
2910.48	80.391
2913.81	80.756
2917.14	81.1812
2920.47	81.5576
2923.8	82.2414
2927.12	82.4246
2930.45	82.5663
2933.77	82.3563
2937.09	82.2137
2940.41	82.0472
2943.73	81.7347
2947.05	81.5781
2950.37	81.3576
2953.68	81.1856
2957	80.9722
2960.31	80.8108
2963.62	80.6041
2966.93	80.5148
2970.24	80.4051
2973.54	80.3335
2976.85	80.2018
2980.15	80.0687
2983.45	79.9341
2986.76	79.7646
2990.05	79.6095
2993.35	79.3914
2996.65	79.1961
2999.94	78.9253
3003.24	78.6771
3006.53	78.364
3009.82	78.0697
3013.11	77.7281
3016.4	77.3976
3019.69	77.0357
3022.97	76.6784
3026.26	76.2472
3029.54	75.8659
3032.82	75.4871
3036.1	75.1119
3039.38	74.7527
3042.66	74.4071
3045.94	74.5234
3049.21	74.373
3052.49	74.1498
3055.76	74.2609
3059.03	74.4094
3062.3	74.5973
3065.57	74.806
3068.83	75.0214
3072.1	75.2667
3075.36	75.5264
3078.62	75.7812
3081.88	75.935
3085.14	76.0454
3088.4	75.5271
3091.66	75.0121
3094.92	74.514
3098.17	74.018
3101.42	73.5366
3104.67	73.0672
3107.93	72.6254
3111.17	72.2146
3114.42	71.8646
3117.67	71.9278
3120.91	72.1102
3124.16	72.347
3127.4	72.6148
3130.64	72.9069
3133.88	73.217
3137.12	73.5134
3140.35	73.8088
3143.59	74.1028
3146.82	74.3841
3150.05	74.4636
3153.29	74.1498
3156.52	73.8176
3159.74	73.4346
3162.97	73.012
3166.2	72.5703
3169.42	72.1025
3172.65	71.625
3175.87	71.1354
3179.09	70.6533
3182.31	70.1598
3185.53	69.7114
3188.74	69.5056
3191.96	69.2663
3195.17	69.0672
3198.38	68.887
3201.59	68.7575
3204.81	68.6746
3208.01	68.5989
3211.22	68.5021
3214.43	68.2761
3217.63	67.9792
3220.83	67.6075
3224.04	67.1757
3227.24	67.2272
3230.44	67.3743
3233.64	67.5547
3236.83	67.4912
3240.03	67.1289
3243.22	66.4007
3246.41	66.3462
3249.6	66.8732
3252.8	64.7549
3255.98	60.2772
3259.17	62.9471
3262.36	64.8964
3265.54	66.2621
3268.72	65.9449
3271.91	65.6246
3275.09	65.362
3278.27	65.1626
3281.45	65.0277
3284.62	64.8434
3287.8	64.958
3290.97	65.0688
3294.15	65.2484
3297.32	65.4134
3300.49	65.6053
3303.66	65.7926
3306.83	65.9606
3309.99	66.1725
3313.16	66.3189
3316.32	66.3993
3319.48	66.63
3322.64	66.5534
3325.8	66.4367
3328.96	66.2467
3332.12	66.0217
3335.27	65.7497
3338.43	65.4731
3341.58	65.1676
3344.74	64.8652
3347.89	64.584
3351.04	64.1409
3354.18	64.0076
3357.33	63.9205
3360.48	63.82
3363.62	64.0005
3366.76	64.0112
3369.91	64.0995
3373.05	64.2338
3376.19	64.3057
3379.32	64.3467
3382.46	64.4436
3385.6	64.6958
3388.73	64.5918
3391.86	64.4583
3394.99	64.3197
3398.13	64.0566
3401.25	63.7686
3404.38	63.4919
3407.51	63.2058
3410.63	62.9415
3413.76	62.6706
3416.88	62.4152
3420	62.1441
3423.12	61.8786
3426.24	61.574
3429.36	61.3483
3432.47	61.1279
3435.59	60.9365
3438.7	60.7435
3441.81	60.5854
3444.93	60.4856
3448.03	60.419
3451.14	60.3431
3454.25	60.3059
3457.36	60.2351
3460.46	60.193
3463.56	60.1552
3466.67	60.1088
3469.77	60.0762
3472.87	60.0365
3475.97	60.0008
3479.06	59.9624
3482.16	59.9201
3485.25	59.8681
3488.35	59.8211
3491.44	59.7701
3494.53	59.7176
3497.62	59.6666
3500.71	59.6084
3503.79	59.557
3506.88	59.4926
3509.96	59.4404
3513.05	59.3695
3516.13	59.2935
3519.21	59.1851
3522.29	59.1224
3525.37	59.0305
3528.45	58.9446
3531.52	58.8494
3534.6	58.7284
3537.67	58.6531
3540.74	58.5704
3543.81	58.4926
3546.88	58.4365
3549.95	58.3679
3553.02	58.2881
3556.08	58.205
3559.15	58.2094
3562.21	58.2027
3565.27	58.2182
3568.33	58.2249
3571.39	58.2461
3574.45	58.2599
3577.51	58.2795
3580.56	58.2957
3583.62	58.3035
3586.67	58.3108
3589.72	58.2928
3592.78	58.2759
3595.83	58.2391
3598.87	58.1699
3601.92	58.1695
3604.97	57.8866
3608.01	57.2863
3611.06	56.7598
3614.1	56.1749
3617.14	55.6021
3620.18	55.0622
3623.22	54.5038
3626.25	53.9781
3629.29	53.4989
3632.32	52.9067
3635.36	52.6347
3638.39	52.723
3641.42	52.706
3644.45	52.7361
3647.48	52.7847
3650.51	52.8341
3653.54	52.9175
3656.56	52.9953
3659.58	53.0929
3662.61	53.201
3665.63	53.2764
3668.65	53.3838
3671.67	53.4598
3674.69	53.5992
3677.7	53.5068
3680.72	53.5249
3683.73	53.4081
3686.75	53.2982
3689.76	53.1439
3692.77	52.9967
3695.78	52.8204
3698.79	52.67
3701.79	52.4861
3704.8	52.3197
3707.8	52.1412
3710.81	51.9699
3713.81	51.7907
3716.81	51.623
3719.81	51.4705
3722.81	51.3714
3725.81	51.2323
3728.8	51.0888
3731.8	51.1399
3734.79	51.4076
3737.78	51.6419
3740.77	51.8696
3743.76	52.1136
3746.75	52.3187
3749.74	52.5966
3752.73	52.7895
3755.71	53.0313
3758.7	53.2233
3761.68	53.3781
3764.66	53.4957
3767.64	53.304
3770.62	53.2497
3773.6	52.956
3776.58	52.6019
3779.55	52.2721
3782.53	51.898
3785.5	51.5238
3788.47	51.1509
3791.44	50.7673
3794.41	50.4014
3797.38	50.0692
3800.35	49.7643
3803.32	49.5334
3806.28	49.475
3809.25	49.3616
3812.21	49.5909
3815.17	49.8207
3818.13	50.0887
3821.09	50.3669
3824.05	50.6609
3827	50.9305
3829.96	51.2021
3832.92	51.4424
3835.87	51.6921
3838.82	51.8879
3841.77	52.0944
3844.72	52.0918
3847.67	52.1102
3850.62	52.0986
3853.56	52.0464
3856.51	51.932
3859.45	51.8286
3862.4	51.6623
3865.34	51.5504
3868.28	51.2545
3871.22	50.9166
3874.16	50.5704
3877.09	50.1929
3880.03	49.815
3882.96	49.4095
3885.9	48.9963
3888.83	48.575
3891.76	48.1876
3894.69	47.7827
3897.62	47.3873
3900.55	46.8772
3903.47	46.6276
3906.4	46.47
3909.32	46.4936
3912.24	46.5041
3915.17	46.5639
3918.09	46.5699
3921.01	46.641
3923.92	46.7142
3926.84	46.8075
3929.76	46.6537
3932.67	46.0224
3935.59	47.0545
3938.5	47.1434
3941.41	47.2347
3944.32	47.293
3947.23	47.2476
3950.14	47.2295
3953.05	47.1936
3955.95	47.1044
3958.86	47.0438
3961.76	46.9822
3964.66	46.928
3967.56	46.8594
3970.46	46.7921
3973.36	46.7177
3976.26	46.6332
3979.16	46.5538
3982.05	46.467
3984.94	46.3831
3987.84	46.2891
3990.73	46.1999
3993.62	46.0998
3996.51	46.0042
3999.4	46.0818