File: Data/Raman/raw/bu19ts-coltan-dark_spot_150 (500nm)_633nm_edge_25%_x50_vis_lwd_h100um_10sx2_02.txt
#Acq. time (s)=	10
#Accumulations=	2
#Range (cm-¹)=	100...4000
#Windows=	1
#Auto scanning=	Off
#Autofocus=	Off
#Macrospot=	Off
#AutoExposure=	Off
#Spike filter=	Multiple accum.
#Delay time (s)=	2
#Binning=	1
#Readout mode=	Signal
#DeNoise=	Standard
#ICS correction=	On
#Dark correction=	Off
#Inst. Process=	Off
#Detector Gain=	Best Dynamic
#Detector ADC=	50 kHz HS
#Detector temperature (°C)=	-60.09
#Instrument=	LabRAM HR Evol
#Detector=	SIN-EM FIVIS
#Objective=	x50_VIS_LWD
#Grating=	150 (500nm)
#ND Filter=	25%
#Laser=	633nm_Edge
#Hole=	100.021
#Temperature=	0
#Range=	Visible
#StageXY=	75x50mm Scan+
#StageZ=	Z motor
#X (µm)=	0
#Y (µm)=	0
#Z (µm)=	-51.1
#Full time(s)=	24
#Project=	20_10_27
#Sample=	BU19TS
#Site=
#Title=	BU19TS-Coltan-dark_spot_150 (500nm)_633nm_Edge_25%_x50_VIS_LWD_H100um_10sX2
#Remark=
#Date=	27.10.2020 15:12
#Acquired=	27.10.2020 15:12:03
100.764	247.204
107.281	253.183
113.791	274.541
120.297	324.651
126.797	416.488
133.291	491.501
139.78	407.256
146.264	299.73
152.741	244.863
159.214	264.359
165.682	279.268
172.144	291.164
178.601	282.418
185.053	264.731
191.499	247.662
197.939	267.812
204.374	333.919
210.805	302.027
217.23	258.859
223.648	250.922
230.063	262.031
236.472	292.064
242.874	324.331
249.273	335.995
255.667	333.917
262.053	330.648
268.436	327.048
274.813	307.656
281.185	294.044
287.552	290.883
293.913	288.23
300.27	287.078
306.62	278.44
312.965	267.815
319.306	272.963
325.64	263.604
331.971	246.274
338.295	228.609
344.614	220.144
350.93	221.523
357.238	226.065
363.542	232.948
369.842	244.742
376.135	254.992
382.423	284.662
388.706	326.744
394.984	364.724
401.258	348.019
407.526	296.92
413.789	263.853
420.046	239.687
426.299	232.237
432.546	230.075
438.788	230.078
445.025	232.047
451.257	235.157
457.484	239.585
463.706	245.411
469.923	252.109
476.135	258.104
482.342	265.012
488.544	272.771
494.741	281.219
500.933	290.442
507.12	300.411
513.3	316.389
519.477	340.927
525.649	387.438
531.815	454.436
537.976	437.669
544.133	366.24
550.285	324.489
556.43	295.262
562.572	278.257
568.709	272.004
574.84	269.231
580.967	268.172
587.09	270.508
593.205	275.39
599.318	282.785
605.424	291.376
611.527	300.494
617.623	311.06
623.716	327.141
629.802	337.233
635.884	339.989
641.962	332.902
648.034	318.649
654.101	306.629
660.165	296.309
666.222	284.452
672.274	275.226
678.324	270.019
684.366	268.931
690.404	268.275
696.438	271.134
702.466	274.93
708.491	279.212
714.51	284.142
720.523	289.554
726.533	295.715
732.537	302.474
738.537	309.513
744.531	317.046
750.521	325.047
756.507	334.825
762.487	345.837
768.463	356.662
774.434	362.183
780.4	366.183
786.362	370.699
792.319	375.919
798.269	379.446
804.217	386.377
810.159	410.025
816.097	443.378
822.03	486.914
827.958	525.841
833.881	562.937
839.801	589.115
845.714	619.845
851.624	716.446
857.529	934.001
863.428	1273.63
869.324	1936.25
875.215	2966.6
881.1	3122.39
886.982	1808.1
892.858	906.351
898.73	602.284
904.597	404.032
910.459	303.201
916.318	242.628
922.171	215.45
928.02	201.699
933.864	190.219
939.703	182.318
945.539	174.304
951.368	167.55
957.194	162.036
963.014	157.667
968.832	154.135
974.643	151.938
980.45	150.21
986.253	148.646
992.051	147.218
997.844	145.863
1003.63	144.545
1009.42	143.308
1015.2	142.216
1020.97	141.268
1026.74	140.367
1032.51	139.773
1038.27	138.881
1044.03	139.255
1049.78	139.049
1055.53	138.885
1061.27	138.466
1067.01	138.144
1072.75	137.709
1078.48	138.026
1084.2	136.388
1089.92	135.791
1095.64	135.682
1101.35	135.577
1107.06	135.46
1112.77	135.3
1118.46	134.89
1124.16	134.228
1129.85	132.368
1135.53	130.995
1141.22	130.475
1146.89	130.138
1152.56	129.958
1158.23	129.815
1163.9	129.678
1169.56	129.333
1175.21	128.926
1180.86	128.027
1186.51	127.117
1192.15	126.341
1197.78	126.555
1203.42	126.619
1209.04	126.435
1214.67	124.948
1220.29	123.692
1225.9	121.611
1231.51	119.761
1237.12	119.06
1242.72	120.057
1248.32	119.59
1253.92	119.2
1259.5	118.863
1265.09	118.468
1270.67	117.866
1276.25	116.548
1281.82	115.341
1287.39	114.398
1292.95	114.228
1298.51	114.798
1304.06	115.366
1309.61	115.07
1315.16	114.882
1320.7	114.881
1326.24	114.759
1331.77	114.651
1337.3	114.554
1342.83	113.919
1348.35	113.79
1353.86	113.957
1359.37	113.879
1364.88	113.834
1370.39	113.807
1375.89	113.846
1381.38	111.013
1386.87	109.949
1392.36	110.886
1397.84	111.937
1403.32	112.926
1408.79	113.686
1414.26	114.048
1419.73	113.971
1425.19	113.886
1430.65	113.789
1436.1	113.723
1441.55	113.914
1447	114.939
1452.44	115.539
1457.87	115.353
1463.31	114.996
1468.73	114.741
1474.16	114.626
1479.58	114.557
1484.99	114.528
1490.41	114.543
1495.81	114.789
1501.22	114.946
1506.62	115.09
1512.01	115.233
1517.4	115.359
1522.79	115.382
1528.17	115.074
1533.55	114.614
1538.93	114.159
1544.3	113.782
1549.67	113.065
1555.03	112.266
1560.39	111.494
1565.74	110.717
1571.09	110.008
1576.44	109.236
1581.78	109.019
1587.12	109.077
1592.45	109.52
1597.78	109.617
1603.11	109.246
1608.43	108.974
1613.75	108.835
1619.07	108.759
1624.38	109.008
1629.68	108.758
1634.98	108.46
1640.28	108.13
1645.58	107.979
1650.87	108.073
1656.15	108.13
1661.44	106.936
1666.71	105.371
1671.99	104.168
1677.26	104.814
1682.53	105.742
1687.79	107.059
1693.05	107.394
1698.3	107.762
1703.55	108.327
1708.8	109.024
1714.04	109.287
1719.28	110.926
1724.51	111.631
1729.75	111.051
1734.97	110.318
1740.2	109.161
1745.42	107.714
1750.63	105.874
1755.84	103.479
1761.05	100.659
1766.25	97.8031
1771.45	95.1727
1776.65	93.8571
1781.84	93.3006
1787.03	93.0417
1792.21	91.4952
1797.39	90.3452
1802.57	89.7162
1807.74	89.3105
1812.91	88.4375
1818.08	87.2764
1823.24	87.2086
1828.39	87.0444
1833.55	85.9677
1838.7	84.9085
1843.84	83.9139
1848.99	83.0628
1854.12	83.0125
1859.26	83.0762
1864.39	82.6889
1869.52	81.7817
1874.64	81.3308
1879.76	81.9638
1884.87	81.8344
1889.98	81.4115
1895.09	81.1487
1900.2	81.3846
1905.3	81.9844
1910.39	82.7222
1915.49	81.2084
1920.57	81.4657
1925.66	83.0907
1930.74	84.9739
1935.82	84.6708
1940.89	84.1312
1945.96	83.5669
1951.03	82.9751
1956.09	82.3418
1961.15	81.8893
1966.21	81.5567
1971.26	81.3526
1976.31	81.1994
1981.35	81.0779
1986.39	80.989
1991.43	80.9747
1996.46	80.7912
2001.49	80.2584
2006.52	79.7645
2011.54	79.405
2016.56	79.0646
2021.57	79.4059
2026.58	79.7069
2031.59	80.0401
2036.59	80.3925
2041.59	80.7091
2046.59	80.9593
2051.58	81.0952
2056.57	80.3158
2061.55	79.2813
2066.54	78.2389
2071.51	77.1817
2076.49	76.1887
2081.46	75.3106
2086.43	75.1707
2091.39	75.1817
2096.35	75.2951
2101.3	75.5473
2106.26	75.9195
2111.21	76.3808
2116.15	77.324
2121.09	77.5702
2126.03	77.5087
2130.97	77.5268
2135.9	77.2553
2140.83	76.9362
2145.75	76.4778
2150.67	75.9969
2155.59	75.8228
2160.5	75.7375
2165.41	76.0761
2170.31	76.4993
2175.22	76.2791
2180.12	75.7151
2185.01	75.0275
2189.9	74.4198
2194.79	73.9262
2199.68	74.0452
2204.56	74.396
2209.43	74.5885
2214.31	74.2385
2219.18	73.873
2224.05	73.8512
2228.91	73.3227
2233.77	73.0456
2238.63	73.4671
2243.48	74.1444
2248.33	74.6189
2253.17	74.5187
2258.02	74.2783
2262.86	74.0099
2267.69	73.7642
2272.52	73.5176
2277.35	73.267
2282.18	73.0094
2287	72.735
2291.82	72.435
2296.63	72.2353
2301.44	72.2688
2306.25	72.0349
2311.05	71.4752
2315.86	71.7146
2320.65	72.2785
2325.45	72.9924
2330.24	73.3401
2335.03	73.022
2339.81	72.4618
2344.59	71.8632
2349.37	71.179
2354.14	70.5108
2358.91	69.9033
2363.67	69.8046
2368.44	69.8992
2373.2	70.2324
2377.95	70.7305
2382.71	70.9019
2387.46	70.5797
2392.2	69.663
2396.95	68.851
2401.68	68.9554
2406.42	70.32
2411.15	70.817
2415.88	70.9431
2420.61	71.3659
2425.33	71.8454
2430.05	72.0144
2434.77	70.1427
2439.48	68.2838
2444.19	67.1802
2448.89	67.2774
2453.6	67.4967
2458.29	66.8566
2462.99	67.084
2467.68	67.6446
2472.37	68.4619
2477.06	69.2733
2481.74	68.6732
2486.42	68.6943
2491.1	68.874
2495.77	69.0704
2500.44	69.2259
2505.1	69.2385
2509.76	69.0563
2514.42	68.3671
2519.08	67.6163
2523.73	66.7461
2528.38	65.6628
2533.03	64.7815
2537.67	63.8546
2542.31	63.9026
2546.95	63.5842
2551.58	64.0019
2556.21	63.621
2560.84	63.4943
2565.46	63.9545
2570.08	64.7321
2574.7	65.6972
2579.31	67.241
2583.92	68.4794
2588.53	68.8699
2593.13	67.7083
2597.73	65.7677
2602.33	63.4843
2606.92	62.135
2611.51	61.3795
2616.1	61.5131
2620.68	62.0283
2625.26	63.117
2629.84	63.7483
2634.42	64.039
2638.99	64.4897
2643.56	64.6567
2648.12	64.4202
2652.68	63.8463
2657.24	63.1738
2661.8	62.7158
2666.35	60.4936
2670.9	60.8719
2675.45	61.292
2679.99	63.0037
2684.53	63.5765
2689.06	61.4728
2693.6	60.8879
2698.13	61.0033
2702.66	60.5219
2707.18	60.7596
2711.7	60.7606
2716.22	60.7805
2720.73	60.8197
2725.24	61.3116
2729.75	62.0965
2734.26	62.4948
2738.76	63.0073
2743.25	63.5628
2747.75	63.8346
2752.24	63.4775
2756.73	62.2937
2761.22	61.006
2765.7	60.0837
2770.18	59.8056
2774.66	60.3508
2779.13	60.0577
2783.6	59.0302
2788.07	58.4386
2792.53	58.323
2797	58.4983
2801.45	59.1772
2805.91	59.8843
2810.36	60.5856
2814.81	61.2303
2819.26	61.2762
2823.7	60.7858
2828.14	60.2012
2832.57	59.6383
2837.01	59.092
2841.44	58.6015
2845.87	58.3599
2850.29	58.4606
2854.71	58.8169
2859.13	59.0503
2863.55	58.2878
2867.96	57.3445
2872.37	56.7054
2876.77	57.1482
2881.18	58.0899
2885.58	59.1756
2889.97	59.7109
2894.37	59.6073
2898.76	58.8649
2903.15	57.6485
2907.53	56.4387
2911.91	55.7872
2916.29	56.0319
2920.67	57.0339
2925.04	57.3096
2929.41	58.0614
2933.78	58.851
2938.14	59.7214
2942.5	59.6473
2946.86	58.991
2951.22	58.1835
2955.57	57.3469
2959.92	56.6122
2964.26	56.2413
2968.61	56.1051
2972.95	56.2496
2977.28	57.0194
2981.62	57.3223
2985.95	56.5466
2990.28	55.8378
2994.6	55.4631
2998.93	55.4405
3003.25	55.7954
3007.56	56.3856
3011.88	56.7496
3016.19	57.3754
3020.49	58.1455
3024.8	58.5581
3029.1	58.6377
3033.4	58.5138
3037.7	58.0097
3041.99	57.8271
3046.28	58.0045
3050.57	58.5259
3054.85	58.505
3059.13	59.0265
3063.41	57.6647
3067.69	56.1755
3071.96	55.037
3076.23	54.6588
3080.5	54.5158
3084.76	54.5473
3089.02	54.7148
3093.28	54.9597
3097.53	55.2136
3101.79	55.4639
3106.04	55.8302
3110.28	55.764
3114.53	55.6209
3118.77	55.5731
3123.01	55.5313
3127.24	55.982
3131.47	57.2834
3135.7	58.6078
3139.93	59.2594
3144.15	59.9147
3148.38	61.1347
3152.59	61.0804
3156.81	60.3075
3161.02	58.7753
3165.23	57.2503
3169.44	56.8209
3173.64	57.1715
3177.84	56.5481
3182.04	55.299
3186.24	55.1089
3190.43	55.3216
3194.62	55.0197
3198.81	54.0519
3202.99	53.8567
3207.17	54.5337
3211.35	55.5344
3215.53	55.5879
3219.7	56.2759
3223.87	57.5047
3228.04	56.9705
3232.2	56.176
3236.36	55.9156
3240.52	55.9029
3244.68	56.1148
3248.83	56.4175
3252.98	56.602
3257.13	56.4137
3261.28	55.8283
3265.42	55.4373
3269.56	55.2267
3273.7	55.3053
3277.83	56.2266
3281.96	56.5576
3286.09	56.5616
3290.22	56.4998
3294.34	56.5081
3298.46	56.5708
3302.58	56.672
3306.69	56.959
3310.8	55.8225
3314.91	54.4585
3319.02	54.2414
3323.12	54.761
3327.23	55.1938
3331.32	55.436
3335.42	55.0679
3339.51	54.5784
3343.6	53.932
3347.69	53.3309
3351.78	53.3288
3355.86	53.6586
3359.94	54.0702
3364.02	54.4854
3368.09	53.2256
3372.16	51.68
3376.23	50.9216
3380.29	50.2848
3384.36	50.7315
3388.42	51.8514
3392.48	53.7756
3396.53	54.4903
3400.58	55.5837
3404.63	55.1872
3408.68	53.4414
3412.73	51.8376
3416.77	51.6546
3420.81	52.4408
3424.84	52.7536
3428.88	53.999
3432.91	53.6627
3436.94	53.4845
3440.96	53.5119
3444.99	53.8156
3449.01	54.5489
3453.03	54.2958
3457.04	53.1938
3461.05	53.3578
3465.06	53.9169
3469.07	55.2455
3473.08	57.4381
3477.08	56.7812
3481.08	55.2951
3485.07	54.8807
3489.07	54.873
3493.06	53.1656
3497.05	52.1889
3501.04	52.2072
3505.02	53.3605
3509	53.8148
3512.98	54.011
3516.96	53.5587
3520.93	53.8917
3524.9	54.3735
3528.87	53.7851
3532.83	53.37
3536.8	53.1921
3540.76	53.419
3544.71	53.7556
3548.67	53.9688
3552.62	53.2311
3556.57	52.9409
3560.52	50.444
3564.47	50.0836
3568.41	52.0815
3572.35	52.8758
3576.29	52.3569
3580.22	51.8607
3584.15	51.5955
3588.08	51.4469
3592.01	52.2505
3595.93	53.2771
3599.85	53.254
3603.77	52.889
3607.69	52.4805
3611.61	52.1899
3615.52	52.0797
3619.43	51.9036
3623.33	52.2569
3627.24	52.5527
3631.14	51.6901
3635.04	50.7447
3638.93	49.9716
3642.83	49.2167
3646.72	49.1922
3650.61	49.4994
3654.49	50.0216
3658.38	50.7744
3662.26	51.5275
3666.14	52.2303
3670.01	52.6558
3673.89	53.0821
3677.76	53.4197
3681.63	53.6764
3685.5	53.3631
3689.36	52.8116
3693.22	52.7468
3697.08	52.9516
3700.94	52.1785
3704.79	51.4144
3708.64	50.6505
3712.49	49.9264
3716.34	49.2937
3720.18	49.58
3724.02	49.6436
3727.86	49.8051
3731.7	50.03
3735.53	50.8586
3739.36	52.0137
3743.19	53.0923
3747.02	53.9334
3750.84	53.7521
3754.66	53.2342
3758.48	52.3768
3762.3	51.2143
3766.12	50.4397
3769.93	51.114
3773.74	52.9117
3777.54	54.424
3781.35	54.6949
3785.15	54.6833
3788.95	54.1115
3792.75	53.16
3796.54	52.2674
3800.34	51.4631
3804.13	50.6106
3807.91	50.5463
3811.7	50.2406
3815.48	49.5705
3819.26	48.9266
3823.04	48.3754
3826.82	47.9459
3830.59	47.819
3834.36	48.3864
3838.13	49.2149
3841.89	50.1647
3845.66	50.2808
3849.42	50.9681
3853.18	50.5679
3856.93	50.5588
3860.69	50.5491
3864.44	50.6936
3868.19	51.0676
3871.93	51.3908
3875.68	50.8179
3879.42	50.1417
3883.16	50.1626
3886.9	50.384
3890.63	50.7699
3894.37	51.7366
3898.1	52.1622
3901.82	52.0805
3905.55	51.8679
3909.27	51.5722
3912.99	51.1667
3916.71	50.5582
3920.43	49.8628
3924.14	49.17
3927.85	48.5397
3931.56	48.1948
3935.27	48.3216
3938.97	48.7319
3942.67	49.1791
3946.37	49.5491
3950.07	49.6933
3953.77	49.6385
3957.46	49.7427
3961.15	49.7001
3964.84	49.6652
3968.52	48.8776
3972.2	47.9101
3975.89	47.4841
3979.56	47.5292
3983.24	47.6343
3986.92	47.3065
3990.59	46.8263
3994.26	46.4598
3997.92	45.1483
3999.76	44.413