File: Data/Raman/raw/bu19w-area6-ore2_150 (500nm)_633nm_edge_25%_x100_vis_h100um_15sx2_01.txt
#Acq. time (s)=	15
#Accumulations=	2
#Range (cm-¹)=	100...4000
#Windows=	1
#Auto scanning=	Off
#Autofocus=	Off
#Macrospot=	Off
#AutoExposure=	Off
#Spike filter=	Multiple accum.
#Delay time (s)=	1
#Binning=	1
#Readout mode=	Signal
#DeNoise=	Standard
#ICS correction=	On
#Dark correction=	Off
#Inst. Process=	Off
#Detector Gain=	Best Dynamic
#Detector ADC=	50 kHz HS
#Detector temperature (°C)=	-60.09
#Instrument=	LabRAM HR Evol
#Detector=	SIN-EM FIVIS
#Objective=	x100_VIS
#Grating=	150 (500nm)
#ND Filter=	25%
#Laser=	633nm_Edge
#Hole=	100.021
#Temperature=	0
#Range=	Visible
#StageXY=	75x50mm Scan+
#StageZ=	Z motor
#X (µm)=	0
#Y (µm)=	0
#Z (µm)=	-13.8
#Full time(s)=	33
#Project=	20_10_20
#Sample=	BU19w
#Site=
#Title=	BU19w-Area6-ore2_150 (500nm)_633nm_Edge_25%_x100_VIS_H100um_15sX2
#Remark=
#Date=	20.10.2020 17:33
#Acquired=	20.10.2020 17:33:45
100.676	1035.21
107.192	1062.51
113.703	1066.84
120.208	1052.72
126.708	1050.14
133.203	1066.07
139.692	1026.8
146.176	927.552
152.654	856.363
159.127	810.278
165.595	802.861
172.058	817.942
178.515	845.06
184.966	872.861
191.411	897.624
197.852	920.968
204.288	941.561
210.719	958.942
217.142	982.14
223.562	1005.92
229.977	1033.33
236.386	1053.67
242.789	1056.81
249.188	1047.71
255.58	1016.23
261.968	987.082
268.351	966.508
274.727	945.044
281.1	926.396
287.466	916.756
293.828	921.541
300.183	912.016
306.535	903.26
312.88	891.229
319.221	877.218
325.556	874.759
331.885	882.417
338.211	887.612
344.53	897.489
350.844	904.861
357.154	914.197
363.458	919.42
369.756	939.85
376.051	975.77
382.339	1028.51
388.622	1098.03
394.9	1176.41
401.173	1284.57
407.442	1391.02
413.705	1501.39
419.962	1594.88
426.215	1639.03
432.462	1628.69
438.705	1580.03
444.942	1483.91
451.174	1375.64
457.401	1276.6
463.623	1189.43
469.84	1116.43
476.052	1058.85
482.259	1019.32
488.461	985.371
494.658	957.509
500.848	934.951
507.035	918.812
513.217	903.892
519.394	896.186
525.566	896.846
531.731	906.517
537.893	928.039
544.05	962.164
550.202	1010.18
556.348	1073.87
562.49	1150.98
568.626	1245.7
574.758	1356.93
580.885	1488.79
587.006	1639.61
593.124	1814.29
599.235	2004.45
605.342	2199.87
611.444	2331.47
617.541	2367.2
623.633	2225.07
629.721	1985.02
635.803	1777.96
641.879	1613.29
647.953	1473.66
654.02	1356.53
660.083	1245.63
666.141	1148.81
672.193	1071.13
678.241	1006.92
684.285	951.39
690.324	901.885
696.357	851.245
702.385	805.241
708.409	764.077
714.428	725.406
720.443	691.393
726.452	662.551
732.457	641.526
738.456	625.38
744.451	614.148
750.441	604.263
756.427	597.394
762.407	593.439
768.383	592.418
774.354	593.103
780.32	594.925
786.282	599.813
792.237	606.402
798.19	613.572
804.137	620.426
810.08	626.999
816.018	631.882
821.95	632.688
827.878	629.515
833.802	617.643
839.721	596.773
845.635	571.419
851.544	526.804
857.448	475.243
863.349	421.032
869.245	380.066
875.135	348.944
881.021	323.999
886.902	306.265
892.779	293.716
898.65	283.959
904.518	276.782
910.38	269.029
916.239	262.085
922.092	255.03
927.94	249.727
933.785	246.239
939.625	244.349
945.459	243.405
951.29	242.127
957.116	240.418
962.936	239.543
968.753	239.755
974.566	240.459
980.373	239.954
986.175	237.077
991.973	232.964
997.767	227.37
1003.56	220.184
1009.34	213.979
1015.12	209.694
1020.9	206.679
1026.67	204.46
1032.43	202.53
1038.19	200.782
1043.95	198.421
1049.7	195.695
1055.45	193.408
1061.2	190.035
1066.94	187.799
1072.67	186.172
1078.4	186.053
1084.13	187.538
1089.85	188.78
1095.57	189.956
1101.28	190.613
1106.98	190.759
1112.69	189.583
1118.39	188.662
1124.08	188.135
1129.77	188.74
1135.46	189.509
1141.14	189.33
1146.82	187.732
1152.49	186.742
1158.16	185.207
1163.82	183.49
1169.48	181.946
1175.13	181.462
1180.78	181.006
1186.43	180.579
1192.07	179.518
1197.71	179.662
1203.34	179.194
1208.97	178.771
1214.59	178.213
1220.21	177.717
1225.83	177.27
1231.44	177.296
1237.05	177.648
1242.65	177.422
1248.25	178.364
1253.84	183.819
1259.43	183.301
1265.01	183.867
1270.59	182.031
1276.17	179.809
1281.74	180.735
1287.31	180.975
1292.87	181.074
1298.43	181.337
1303.99	181.462
1309.54	180.766
1315.08	180.168
1320.63	179.462
1326.16	177.923
1331.7	178.889
1337.23	178.933
1342.75	178.366
1348.27	178.23
1353.79	176.514
1359.3	175.441
1364.81	173.542
1370.31	171.38
1375.81	169.418
1381.31	167.704
1386.8	166.103
1392.29	164.524
1397.77	164.674
1403.25	165.425
1408.72	166.072
1414.19	166.469
1419.66	167.339
1425.12	168.436
1430.58	168.563
1436.03	168.205
1441.48	167.643
1446.92	167.062
1452.36	167.209
1457.8	167.278
1463.23	166.452
1468.66	167.085
1474.09	168.562
1479.51	169.308
1484.92	169.361
1490.33	169.009
1495.74	169.014
1501.14	168.133
1506.54	167.44
1511.94	167.206
1517.33	167.061
1522.72	167.518
1528.1	167.28
1533.48	167.292
1538.86	167.67
1544.23	167.253
1549.59	165.499
1554.96	164.216
1560.32	162.928
1565.67	160.528
1571.02	159.053
1576.37	158.722
1581.71	160.083
1587.05	161.801
1592.38	162.833
1597.71	162.873
1603.04	161.658
1608.36	160.379
1613.68	158.352
1618.99	156.343
1624.3	153.971
1629.61	152.41
1634.91	149.41
1640.21	149.528
1645.51	150.99
1650.8	151.912
1656.08	152.601
1661.36	152.178
1666.64	150.265
1671.92	147.762
1677.19	145.096
1682.45	141.703
1687.72	138.876
1692.98	136.842
1698.23	134.92
1703.48	133.495
1708.73	132.063
1713.97	129.684
1719.21	127.658
1724.44	124.623
1729.67	123.23
1734.9	123.41
1740.12	124.518
1745.34	125.463
1750.56	125.828
1755.77	125.597
1760.98	125.439
1766.18	125.05
1771.38	124.594
1776.58	123.948
1781.77	124.166
1786.96	123.84
1792.14	122.982
1797.32	122.22
1802.5	122.232
1807.67	122.124
1812.84	121.999
1818.01	121.395
1823.17	120.881
1828.33	121.136
1833.48	121.528
1838.63	121.453
1843.77	121.291
1848.92	121.695
1854.06	122.316
1859.19	122.262
1864.32	121.604
1869.45	121.018
1874.57	120.443
1879.69	120.111
1884.8	119.116
1889.92	118.166
1895.02	118.083
1900.13	119.133
1905.23	120.54
1910.33	121.73
1915.42	122.956
1920.51	123.897
1925.59	123.279
1930.67	121.188
1935.75	119.812
1940.82	119.511
1945.9	120.03
1950.96	121.151
1956.02	121.926
1961.08	122.835
1966.14	121.419
1971.19	120.114
1976.24	118.711
1981.28	117.582
1986.32	117.04
1991.36	117.257
1996.39	117.432
2001.42	117.695
2006.45	118.057
2011.47	114.822
2016.49	115.895
2021.5	118.964
2026.51	121.481
2031.52	122.167
2036.52	121.48
2041.52	119.304
2046.52	116.901
2051.51	116.204
2056.5	116.433
2061.49	117.029
2066.47	119.848
2071.45	121.482
2076.42	123.462
2081.39	123.846
2086.36	123.139
2091.32	118.595
2096.28	116.664
2101.24	116.521
2106.19	115.877
2111.14	116.13
2116.09	116.506
2121.03	116.634
2125.97	116.007
2130.9	115.178
2135.83	114.298
2140.76	114.217
2145.68	115.128
2150.6	115.604
2155.52	116.06
2160.43	117.738
2165.34	119.811
2170.25	119.402
2175.15	117.685
2180.05	113.491
2184.95	111.445
2189.84	113.509
2194.73	113.984
2199.61	114.578
2204.49	114.933
2209.37	114.918
2214.24	114.776
2219.11	114.18
2223.98	114.368
2228.84	115.148
2233.7	115.568
2238.56	115.078
2243.41	114.489
2248.26	113.705
2253.11	111.456
2257.95	109.363
2262.79	107.398
2267.63	107.417
2272.46	108.634
2277.29	109.893
2282.11	111.469
2286.93	112.38
2291.75	112.238
2296.57	110.701
2301.38	110.02
2306.19	109.219
2310.99	108.666
2315.79	107.929
2320.59	108.39
2325.38	109.439
2330.17	109.984
2334.96	110.758
2339.74	111.692
2344.52	112.01
2349.3	111.014
2354.07	108.685
2358.84	107.264
2363.61	106.405
2368.37	106.365
2373.13	106.384
2377.89	107.424
2382.64	108.874
2387.39	109.971
2392.14	109.603
2396.88	109.38
2401.62	108.752
2406.36	107.903
2411.09	106.999
2415.82	106.547
2420.55	107.254
2425.27	107.67
2429.99	105.574
2434.7	106.47
2439.42	107.927
2444.12	111.701
2448.83	111.563
2453.53	109.651
2458.23	107.03
2462.93	105.476
2467.62	102.814
2472.31	101.251
2476.99	101.735
2481.68	102.882
2486.36	104.431
2491.03	105.796
2495.7	106.897
2500.37	107.415
2505.04	107.072
2509.7	105.527
2514.36	103.405
2519.02	102.248
2523.67	102.339
2528.32	102.152
2532.97	102.658
2537.61	102.991
2542.25	103.438
2546.88	104.269
2551.52	103.905
2556.15	102.895
2560.77	103.048
2565.4	103.669
2570.02	103.613
2574.63	104.091
2579.25	104.625
2583.86	104.389
2588.46	104.472
2593.07	103.873
2597.67	103.379
2602.27	103.206
2606.86	101.896
2611.45	102.041
2616.04	102.52
2620.62	103.101
2625.2	103.185
2629.78	102.139
2634.36	100.567
2638.93	99.604
2643.5	98.6856
2648.06	98.3863
2652.62	100.06
2657.18	102.018
2661.74	103.339
2666.29	103.522
2670.84	103.463
2675.38	102.773
2679.93	101.682
2684.47	100.489
2689	100.258
2693.54	100.385
2698.07	100.067
2702.59	99.2894
2707.12	98.0423
2711.64	99.3973
2716.16	100.611
2720.67	101.302
2725.18	102.705
2729.69	104.207
2734.19	104.302
2738.7	101.671
2743.19	98.9971
2747.69	98.7152
2752.18	98.534
2756.67	99.468
2761.16	98.8284
2765.64	98.0947
2770.12	97.0308
2774.6	97.0462
2779.07	97.4491
2783.54	98.7114
2788.01	100.164
2792.47	101.376
2796.94	102.023
2801.39	102.573
2805.85	102.719
2810.3	101.582
2814.75	99.5878
2819.2	98.2846
2823.64	96.8274
2828.08	95.8369
2832.52	94.9584
2836.95	94.5611
2841.38	95.4549
2845.81	96.5952
2850.23	98.5406
2854.65	99.9791
2859.07	100.197
2863.49	99.4754
2867.9	98.0889
2872.31	96.357
2876.71	95.6271
2881.12	95.159
2885.52	94.672
2889.91	95.1055
2894.31	96.0878
2898.7	96.9862
2903.09	97.5803
2907.47	99.0536
2911.86	98.5199
2916.23	97.586
2920.61	97.1149
2924.98	96.5535
2929.35	96.8389
2933.72	97.7086
2938.08	99.3397
2942.45	100.636
2946.8	100.859
2951.16	100.47
2955.51	99.3777
2959.86	98.0703
2964.21	96.1292
2968.55	95.6318
2972.89	96.3937
2977.23	96.7174
2981.56	97.7643
2985.89	97.8488
2990.22	96.8822
2994.55	96.9871
2998.87	97.0678
3003.19	96.4592
3007.5	95.5113
3011.82	94.7361
3016.13	95.1761
3020.44	94.9187
3024.74	94.888
3029.04	94.5424
3033.34	95.6776
3037.64	95.8834
3041.93	97.9231
3046.22	94.3839
3050.51	98.4625
3054.79	101.558
3059.07	169.596
3063.35	340.42
3067.63	383.763
3071.9	107.158
3076.17	98.3221
3080.44	96.3668
3084.7	93.4605
3088.96	95.0452
3093.22	96.4792
3097.48	94.0296
3101.73	93.4588
3105.98	93.1718
3110.23	92.9969
3114.47	91.6394
3118.71	90.7968
3122.95	90.888
3127.19	93.4016
3131.42	94.3961
3135.65	95.2596
3139.87	94.2397
3144.1	92.631
3148.32	91.6672
3152.54	91.1585
3156.75	92.6386
3160.96	92.8703
3165.17	93.4574
3169.38	94.1725
3173.58	92.0607
3177.79	93.551
3181.98	95.7651
3186.18	97.7378
3190.37	97.296
3194.56	96.8846
3198.75	96.564
3202.93	96.0162
3207.12	94.8661
3211.29	93.4973
3215.47	92.5085
3219.64	92.3339
3223.81	92.3331
3227.98	93.1967
3232.15	94.6469
3236.31	95.1171
3240.47	94.055
3244.62	93.345
3248.78	93.1106
3252.93	93.4539
3257.08	94.2929
3261.22	94.5272
3265.36	94.4036
3269.5	94.0084
3273.64	93.1598
3277.78	94.5732
3281.91	97.6443
3286.03	97.8125
3290.16	95.2915
3294.28	92.903
3298.4	92.3932
3302.52	90.0423
3306.64	91.2318
3310.75	92.5776
3314.86	93.3938
3318.97	95.1594
3323.07	96.2437
3327.17	94.4044
3331.27	93.8635
3335.37	93.4632
3339.46	93.0876
3343.55	92.806
3347.64	92.0815
3351.72	90.2934
3355.8	89.3502
3359.88	90.6525
3363.96	92.4276
3368.03	93.303
3372.1	93.9237
3376.17	92.6462
3380.24	91.0555
3384.3	90.1883
3388.36	89.7911
3392.42	90.5201
3396.48	91.6646
3400.53	92.7289
3404.58	91.6395
3408.63	91.7094
3412.67	91.4279
3416.71	91.1482
3420.75	91.8049
3424.79	93.6489
3428.82	94.3008
3432.86	93.6033
3436.88	93.4715
3440.91	93.0483
3444.93	92.3924
3448.95	91.4833
3452.97	90.7623
3456.99	90.6245
3461	90.5008
3465.01	90.2999
3469.02	90.1227
3473.02	92.0768
3477.02	93.9165
3481.02	93.921
3485.02	92.3175
3489.02	91.8577
3493.01	91.799
3497	91.4184
3500.98	91.2009
3504.97	91.2861
3508.95	91.6397
3512.93	92.4787
3516.9	91.108
3520.88	89.7187
3524.85	88.4245
3528.81	89.017
3532.78	90.8075
3536.74	92.6193
3540.7	94.1835
3544.66	93.0472
3548.62	92.6096
3552.57	91.2994
3556.52	90.5349
3560.47	90.5781
3564.41	91.3829
3568.35	91.9016
3572.29	91.6779
3576.23	91.2498
3580.17	90.9416
3584.1	90.347
3588.03	89.0987
3591.96	88.22
3595.88	88.5836
3599.8	89.5686
3603.72	91.1836
3607.64	91.3989
3611.55	90.5211
3615.46	88.8591
3619.37	88.0729
3623.28	87.7899
3627.18	87.5178
3631.09	87.4692
3634.98	86.6432
3638.88	84.8708
3642.77	83.8766
3646.67	83.5344
3650.56	84.7951
3654.44	86.6627
3658.33	90.9736
3662.21	92.7079
3666.09	92.8991
3669.96	91.1167
3673.84	87.9296
3677.71	85.1484
3681.58	83.6682
3685.44	84.7761
3689.31	88.2333
3693.17	89.9721
3697.03	90.3792
3700.88	90.1947
3704.74	87.9313
3708.59	85.5007
3712.44	85.2902
3716.28	84.3872
3720.13	82.6839
3723.97	82.6064
3727.81	83.2241
3731.65	83.7435
3735.48	84.2605
3739.31	85.4601
3743.14	86.6162
3746.97	87.1776
3750.79	89.6521
3754.61	88.6082
3758.43	87.7807
3762.25	86.4171
3766.06	85.3221
3769.88	83.6082
3773.69	82.8736
3777.49	83.1799
3781.3	83.0064
3785.1	82.8463
3788.9	82.3637
3792.7	82.7725
3796.49	82.6852
3800.28	83.2322
3804.07	82.1392
3807.86	81.9394
3811.65	82.1689
3815.43	82.6954
3819.21	83.5645
3822.99	83.2284
3826.76	83.3169
3830.54	84.355
3834.31	85.0981
3838.08	84.4434
3841.84	83.607
3845.61	83.3927
3849.37	83.5722
3853.13	83.2573
3856.88	82.8988
3860.64	82.5709
3864.39	82.3229
3868.14	82.0375
3871.88	81.7513
3875.63	80.873
3879.37	78.872
3883.11	78.4575
3886.85	79.5723
3890.58	81.0073
3894.31	80.9923
3898.05	81.1785
3901.77	81.7875
3905.5	83.3097
3909.22	82.8547
3912.94	80.9217
3916.66	79.4123
3920.38	78.7585
3924.09	78.9033
3927.8	78.6233
3931.51	79.6242
3935.22	80.406
3938.92	81.1475
3942.62	82.0737
3946.32	83.0869
3950.02	83.7455
3953.72	81.0311
3957.41	79.208
3961.1	78.2593
3964.79	78.6749
3968.47	80.3284
3972.16	81.466
3975.84	80.4506
3979.51	79.2724
3983.19	78.4338
3986.87	77.971
3990.54	78.8467
3994.21	79.5989
3997.87	79.2358
3999.71	78.3558