File: Data/Raman/raw/bu19w-ore3-bottomhost_150 (500nm)_633nm_edge_100%_x100_vis_h30um_30sx2_01_0.txt
#Acq. time (s)=	30
#Accumulations=	2
#Range (cm-¹)=	100...4000
#Windows=	1
#Auto scanning=	Off
#Autofocus=	Off
#Macrospot=	Off
#AutoExposure=	Off
#Spike filter=	Multiple accum.
#Delay time (s)=	2
#Binning=	1
#Readout mode=	Signal
#DeNoise=	Standard
#ICS correction=	On
#Dark correction=	Off
#Inst. Process=	Off
#Detector Gain=	Best Dynamic
#Detector ADC=	50 kHz HS
#Detector temperature (°C)=	-60.09
#Instrument=	LabRAM HR Evol
#Detector=	SIN-EM FIVIS
#Objective=	x100_VIS
#Grating=	150 (500nm)
#ND Filter=	100%
#Laser=	633nm_Edge
#Hole=	30.0125
#Temperature=	0
#Range=	Visible
#StageXY=	75x50mm Scan+
#StageZ=	Z motor
#X (µm)=	0
#Y (µm)=	0
#Z (µm)=	68.8
#Full time(mm:ss)=	1:04
#Project=	21_02_17
#Sample=	BU19w
#Site=
#Title=	BU19w-Ore3-bottomHost_150 (500nm)_633nm_Edge_100%_x100_VIS_H30um_30sX2
#Remark=
#Date=	17.02.2021 11:06
#Acquired=	17.02.2021 11:06:27
100.724	136.221
107.24	131.144
113.751	137.688
120.256	164.437
126.756	230.903
133.251	279.541
139.74	202.69
146.224	176.932
152.702	214.697
159.175	319.385
165.643	477.006
172.105	432.917
178.561	293.054
185.013	207.073
191.459	165.097
197.9	148.083
204.336	146.621
210.765	143.849
217.19	151.527
223.61	177.084
230.024	269.258
236.432	183.354
242.836	177.205
249.233	240.562
255.627	415.306
262.015	254.519
268.397	146.122
274.774	126.468
281.145	123.35
287.513	120.488
293.873	119.891
300.23	119.007
306.58	117.036
312.927	116.722
319.266	117.89
325.602	120.817
331.932	125.072
338.256	132.78
344.577	142.907
350.89	159.133
357.199	168.4
363.504	188.157
369.803	256.701
376.096	234.444
382.384	162.362
388.669	138.499
394.947	135.692
401.219	139.509
407.487	158.98
413.75	185.687
420.007	217.882
426.261	231.861
432.508	192.748
438.751	184.34
444.988	188.598
451.22	199.747
457.447	193.038
463.669	180.488
469.886	164.906
476.098	149.451
482.303	135.733
488.505	129.55
494.702	126.47
500.894	127.17
507.081	138.384
513.263	155.06
519.44	176.064
525.61	199.402
531.777	217.836
537.939	225.738
544.096	234.5
550.246	245.245
556.393	269.644
562.535	296.017
568.671	310.272
574.803	295.237
580.929	265.03
587.051	224.072
593.167	186.299
599.28	164.915
605.387	158
611.489	169.04
617.585	192.785
623.678	232.128
629.764	312.755
635.847	498.53
641.924	492.393
647.998	274.837
654.065	185.146
660.127	152.661
666.184	133.969
672.238	125.038
678.286	118.054
684.329	113.666
690.367	110.131
696.401	107.483
702.43	103.261
708.453	104.272
714.472	107.629
720.486	111.717
726.495	114.886
732.5	114.281
738.501	110.675
744.495	108.13
750.485	105.419
756.471	103.116
762.451	101.742
768.426	101.412
774.397	102.702
780.363	104.272
786.325	105.561
792.281	105.97
798.234	105.785
804.181	105.152
810.124	104.63
816.06	105.282
821.993	106.317
827.922	110.153
833.846	116.71
839.764	124.479
845.678	133.082
851.588	141.674
857.492	150.992
863.392	152.214
869.287	149.876
875.178	141.33
881.063	134.825
886.945	129.482
892.822	128.368
898.694	126.395
904.56	121.935
910.424	117.211
916.281	112.957
922.135	109.301
927.984	106.431
933.827	104.471
939.668	103.547
945.502	103.633
951.332	104.227
957.159	103.529
962.979	103.347
968.796	102.717
974.607	102.362
980.414	103.009
986.218	104.728
992.016	107.143
997.809	110.248
1003.6	114.899
1009.38	121.563
1015.16	132.174
1020.94	137.342
1026.71	131.19
1032.48	122.116
1038.24	114.197
1043.99	112.526
1049.75	116.492
1055.5	128.451
1061.24	145.697
1066.98	155.258
1072.71	144.775
1078.44	135.705
1084.17	133.238
1089.89	138.662
1095.61	155.41
1101.32	189.615
1107.03	247.077
1112.73	302.241
1118.43	240.882
1124.12	184.095
1129.81	152.598
1135.5	130.867
1141.18	121.265
1146.86	115.762
1152.53	113.957
1158.2	115.954
1163.86	117.733
1169.52	116.18
1175.17	111.532
1180.83	101.952
1186.47	95.8836
1192.11	96.0218
1197.75	99.8763
1203.38	98.4775
1209.01	97.5628
1214.63	96.2472
1220.25	94.4444
1225.87	92.8921
1231.48	93.8567
1237.09	94.6215
1242.69	94.938
1248.29	94.8966
1253.88	94.5311
1259.47	94.0697
1265.05	92.7418
1270.63	91.2167
1276.21	89.4231
1281.78	88.0222
1287.35	86.8946
1292.91	86.3887
1298.47	85.8596
1304.03	85.434
1309.58	85.0603
1315.13	84.7883
1320.67	84.5966
1326.2	84.5554
1331.74	84.7902
1337.27	84.4691
1342.79	84.1014
1348.31	83.6666
1353.83	82.8987
1359.34	82.3212
1364.85	81.785
1370.35	81.5508
1375.85	81.3735
1381.35	81.4301
1386.84	81.4951
1392.32	81.5955
1397.81	81.7229
1403.29	81.8874
1408.76	82.0849
1414.23	82.2689
1419.7	82.3852
1425.16	82.249
1430.61	81.8697
1436.07	81.5135
1441.52	81.0526
1446.96	80.6092
1452.4	80.1181
1457.84	80.5631
1463.27	80.0899
1468.7	78.7329
1474.12	76.5876
1479.55	73.9872
1484.96	74.6737
1490.37	76.7485
1495.78	78.9711
1501.18	80.728
1506.58	82.0727
1511.98	82.5109
1517.37	80.2839
1522.76	78.9049
1528.14	79.0282
1533.52	79.3287
1538.9	81.1521
1544.27	82.4952
1549.63	83.9815
1555	85.2299
1560.35	84.1614
1565.71	82.5385
1571.06	81.1118
1576.41	80.5297
1581.75	80.1502
1587.09	79.9237
1592.42	79.7859
1597.75	79.6966
1603.08	79.6184
1608.4	79.545
1613.72	79.3893
1619.03	79.2799
1624.34	79.1346
1629.65	79.0183
1634.95	78.9241
1640.25	78.8315
1645.54	78.7312
1650.83	78.6514
1656.12	78.6425
1661.4	78.7002
1666.68	79.098
1671.96	78.3089
1677.23	77.1044
1682.49	76.1801
1687.75	75.5891
1693.01	75.5019
1698.27	75.5701
1703.52	75.7059
1708.77	75.9863
1714.01	75.9597
1719.25	75.7181
1724.48	75.4424
1729.71	75.2271
1734.94	75.0784
1740.16	75.0609
1745.38	75.3478
1750.6	76.0003
1755.81	76.4721
1761.02	76.7999
1766.22	76.9011
1771.42	76.1357
1776.62	75.3265
1781.81	74.4344
1787	73.5085
1792.18	72.9082
1797.36	72.5749
1802.54	72.433
1807.71	73.373
1812.88	74.7571
1818.05	76.0337
1823.21	76.8823
1828.36	77.0984
1833.52	75.8477
1838.67	74.3025
1843.81	72.7675
1848.95	71.4348
1854.09	70.4999
1859.23	70.1413
1864.36	70.2799
1869.48	70.5994
1874.61	71.0566
1879.73	71.577
1884.84	72.2505
1889.95	72.5472
1895.06	72.4091
1900.17	72.2087
1905.27	71.9503
1910.36	71.6643
1915.45	71.3858
1920.54	71.1208
1925.63	70.8775
1930.71	70.8356
1935.79	70.9189
1940.86	70.9408
1945.93	70.8981
1951	70.7208
1956.06	70.4047
1961.12	69.5622
1966.18	67.9505
1971.23	67.4451
1976.28	68.0372
1981.32	69.9273
1986.36	72.3207
1991.4	74.2666
1996.43	75.8767
2001.46	76.4948
2006.48	76.2697
2011.51	75.6737
2016.52	74.9265
2021.54	74.0823
2026.55	73.6215
2031.56	72.8366
2036.56	72.0164
2041.56	71.2216
2046.56	70.4645
2051.55	69.7663
2056.54	69.1493
2061.52	68.6954
2066.51	68.5804
2071.48	68.8257
2076.46	69.1916
2081.43	69.4418
2086.4	69.3129
2091.36	68.5557
2096.32	67.9225
2101.28	67.2721
2106.23	66.7802
2111.18	67.0305
2116.12	67.3814
2121.06	67.8693
2126	68.3611
2130.94	68.7544
2135.87	68.7706
2140.79	68.671
2145.72	68.4016
2150.64	68.1265
2155.56	67.689
2160.47	67.0665
2165.38	66.4291
2170.28	65.8139
2175.19	65.2604
2180.09	64.9945
2184.98	64.8065
2189.87	65.0211
2194.76	65.6666
2199.65	66.461
2204.53	66.9349
2209.4	66.7517
2214.28	66.6693
2219.15	66.7229
2224.02	66.8147
2228.88	66.9706
2233.74	65.7
2238.6	63.995
2243.45	63.8128
2248.3	63.9669
2253.14	64.4401
2257.99	64.6474
2262.83	64.6688
2267.66	64.4821
2272.49	64.414
2277.32	64.3494
2282.15	64.305
2286.97	64.2838
2291.79	64.3071
2296.6	64.3615
2301.41	64.5339
2306.22	64.5844
2311.02	64.5948
2315.83	64.5712
2320.62	64.5208
2325.42	64.4612
2330.21	64.3105
2335	64.1246
2339.78	63.875
2344.56	63.7489
2349.34	63.6585
2354.11	63.778
2358.88	64.1095
2363.65	64.736
2368.41	65.148
2373.17	65.5043
2377.93	65.7722
2382.68	65.8191
2387.43	65.8025
2392.17	65.8906
2396.92	65.969
2401.66	65.9727
2406.39	65.9879
2411.13	65.2299
2415.85	64.2716
2420.58	63.0918
2425.3	61.8636
2430.02	61.7396
2434.74	62.0477
2439.45	62.4358
2444.16	62.883
2448.86	63.3287
2453.57	63.4711
2458.27	63.5263
2462.96	63.6269
2467.65	63.7238
2472.34	63.8383
2477.03	63.9892
2481.71	64.1796
2486.39	64.4117
2491.07	64.7524
2495.74	65.1277
2500.41	65.4414
2505.07	65.2478
2509.74	65.3223
2514.4	65.4529
2519.05	65.5892
2523.7	65.6851
2528.35	65.7642
2533	65.8265
2537.64	65.7677
2542.28	65.758
2546.92	65.7465
2551.55	65.7468
2556.18	65.6384
2560.81	65.4424
2565.43	65.0868
2570.05	64.6357
2574.67	64.1046
2579.28	63.4106
2583.89	62.8652
2588.5	62.4766
2593.1	62.5804
2597.7	63.1055
2602.3	62.1886
2606.89	61.4437
2611.48	61.6792
2616.07	60.2547
2620.66	61.1691
2625.24	62.3149
2629.82	62.9633
2634.39	62.7754
2638.96	62.9458
2643.53	63.3926
2648.09	63.9898
2652.66	64.7344
2657.21	65.678
2661.77	66.2977
2666.32	66.1103
2670.87	64.0286
2675.42	63.0749
2679.96	62.8896
2684.5	62.6919
2689.04	62.4357
2693.57	62.2041
2698.1	62.084
2702.63	62.0791
2707.15	62.0758
2711.67	62.7461
2716.19	63.565
2720.7	64.3287
2725.21	65.0108
2729.72	65.1636
2734.23	64.834
2738.73	64.6127
2743.23	64.0587
2747.72	63.499
2752.22	63.0645
2756.7	63.331
2761.19	63.7078
2765.67	64.2276
2770.15	63.5872
2774.63	61.7749
2779.1	60.311
2783.57	59.915
2788.04	60.8484
2792.51	62.2233
2796.97	61.8831
2801.43	60.8756
2805.88	60.9738
2810.33	61.3528
2814.78	62.7593
2819.23	65.688
2823.67	66.5053
2828.11	65.5444
2832.55	64.8787
2836.98	64.6638
2841.41	64.457
2845.84	64.3687
2850.26	64.418
2854.69	64.1144
2859.1	63.0959
2863.52	62.0539
2867.93	61.4775
2872.34	61.7125
2876.75	62.3941
2881.15	63.5416
2885.55	65.1295
2889.95	66.6832
2894.34	67.7457
2898.73	67.3287
2903.12	66.6638
2907.5	65.4989
2911.89	64.1742
2916.27	62.9363
2920.64	62.3086
2925.01	62.064
2929.38	62.1556
2933.75	62.4041
2938.12	62.8545
2942.48	63.7639
2946.84	64.7385
2951.19	65.6042
2955.54	66.2721
2959.89	66.3205
2964.24	65.9646
2968.58	65.7707
2972.92	64.7591
2977.26	63.2198
2981.59	62.1031
2985.92	63.3332
2990.25	64.4813
2994.58	65.1844
2998.9	64.3702
3003.22	64.2812
3007.54	62.6509
3011.85	62.5647
3016.16	65.2927
3020.47	65.7102
3024.77	66.177
3029.07	66.5358
3033.37	66.8723
3037.67	67.1469
3041.96	67.2644
3046.25	67.1762
3050.54	66.8999
3054.82	66.3064
3059.11	65.3996
3063.38	64.4157
3067.66	63.5653
3071.93	62.9577
3076.2	64.1491
3080.47	65.6524
3084.73	66.9253
3088.99	67.0918
3093.25	67.2321
3097.51	66.3481
3101.76	65.9589
3106.01	66.1543
3110.26	66.8499
3114.5	67.8089
3118.74	67.6485
3122.98	67.0063
3127.22	67.2597
3131.45	67.4853
3135.68	66.2063
3139.91	65.3626
3144.13	65.2084
3148.35	65.3577
3152.57	65.6695
3156.78	65.9516
3161	65.871
3165.21	65.1973
3169.41	64.0413
3173.62	63.3794
3177.82	64.3861
3182.02	65.8109
3186.21	67.5211
3190.4	69.1255
3194.59	70.0664
3198.78	69.9578
3202.96	68.998
3207.15	67.9906
3211.33	67.2184
3215.5	67.1062
3219.67	67.6209
3223.84	69.4538
3228.01	71.3114
3232.18	72.4759
3236.34	72.7742
3240.5	73.0144
3244.65	72.3599
3248.81	70.7423
3252.96	69.0837
3257.11	67.6149
3261.25	67.4652
3265.39	67.5862
3269.53	67.9463
3273.67	68.5395
3277.8	69.2784
3281.94	70.2132
3286.06	71.3304
3290.19	72.8572
3294.31	73.8096
3298.43	74.1685
3302.55	74.4372
3306.67	74.61
3310.78	74.7988
3314.89	74.9869
3319	75.3113
3323.1	75.7432
3327.2	76.4278
3331.3	77.2798
3335.39	78.7494
3339.49	80.2395
3343.58	81.9231
3347.67	82.0701
3351.75	81.7262
3355.83	82.4126
3359.91	84.0047
3363.99	86.0522
3368.06	88.5486
3372.14	91.2596
3376.2	93.9836
3380.27	96.7565
3384.33	99.4804
3388.39	101.617
3392.45	103.842
3396.51	107.595
3400.56	110.921
3404.61	112.898
3408.66	116.631
3412.7	120.535
3416.74	125.617
3420.78	131.83
3424.82	138.853
3428.85	148.189
3432.88	153.303
3436.91	158.173
3440.94	164.396
3444.96	172.6
3448.98	184.862
3453	198.401
3457.02	219.864
3461.03	269.029
3465.04	324.294
3469.05	381.469
3473.05	367.374
3477.05	327.151
3481.05	293.318
3485.05	263.216
3489.04	237.377
3493.04	222.225
3497.03	208.873
3501.01	202.471
3505	199.905
3508.98	196.213
3512.96	193.736
3516.93	193.508
3520.9	195.554
3524.88	200.309
3528.84	206.768
3532.81	215.013
3536.77	224.404
3540.73	230.074
3544.69	237.781
3548.65	235.37
3552.6	227.724
3556.55	217.17
3560.5	201.321
3564.44	181.944
3568.38	162.564
3572.32	144.132
3576.26	128.787
3580.2	117.812
3584.13	109.043
3588.06	103.946
3591.98	99.9189
3595.91	97.2842
3599.83	95.0199
3603.75	93.1896
3607.67	91.5491
3611.58	89.9741
3615.49	88.2264
3619.4	86.1044
3623.31	83.8545
3627.21	81.9952
3631.11	80.5575
3635.01	79.8328
3638.91	79.5827
3642.8	78.3427
3646.69	77.0997
3650.58	76.2174
3654.47	75.4237
3658.35	74.7301
3662.24	74.1602
3666.11	73.7231
3669.99	73.3908
3673.86	71.6572
3677.74	70.2997
3681.6	69.6462
3685.47	70.1053
3689.34	71.1717
3693.2	70.7119
3697.06	68.7446
3700.91	67.4131
3704.77	67.0665
3708.62	68.5643
3712.47	68.9528
3716.31	69.4351
3720.16	70.0767
3724	70.8463
3727.84	70.9238
3731.67	69.7187
3735.51	69.0509
3739.34	68.6662
3743.17	68.4587
3747	68.3345
3750.82	67.9758
3754.64	67.5784
3758.46	66.9467
3762.28	66.4885
3766.09	66.5279
3769.9	66.9791
3773.71	67.4706
3777.52	67.7981
3781.33	67.6254
3785.13	67.0177
3788.93	66.3836
3792.72	65.7861
3796.52	65.2128
3800.31	64.8901
3804.1	64.6291
3807.89	64.4677
3811.68	64.4601
3815.46	64.5659
3819.24	64.9406
3823.02	64.555
3826.79	64.164
3830.56	64.2118
3834.34	64.7726
3838.1	65.4744
3841.87	66.2063
3845.63	66.9433
3849.39	67.0191
3853.15	65.7752
3856.91	65.8724
3860.66	66.3829
3864.42	66.2748
3868.16	65.6271
3871.91	64.9864
3875.66	64.4078
3879.4	64.4335
3883.14	65.537
3886.88	67.6591
3890.61	67.5877
3894.34	67.1815
3898.07	65.9884
3901.8	64.6223
3905.53	63.4848
3909.25	63.4133
3912.97	62.3409
3916.69	63.1949
3920.4	65.3314
3924.12	68.1287
3927.83	69.7757
3931.54	70.9983
3935.24	70.2281
3938.95	69.2526
3942.65	68.5126
3946.35	67.7633
3950.05	67.1512
3953.74	66.7158
3957.44	66.5866
3961.13	66.896
3964.81	67.6812
3968.5	68.3566
3972.18	68.2567
3975.86	67.538
3979.54	66.2731
3983.22	64.5543
3986.89	62.3762
3990.56	59.8371
3994.23	60.8768
3997.9	65.5062
3999.73	67.4187