File: Data/Raman/raw/bu19ts(1)-ore1-inter_1800 (450-850nm)_532nm_edge_10%_x100_vis_h30um_60sx2_01.txt
#Acq. time (s)=	60
#Accumulations=	2
#Range (cm-¹)=	80...1000
#Windows=	2
#Auto scanning=	Off
#Autofocus=	Off
#Macrospot=	Off
#AutoExposure=	Off
#Spike filter=	Multiple accum.
#Delay time (s)=	2
#Binning=	1
#Readout mode=	Signal
#DeNoise=	Standard
#ICS correction=	On
#Dark correction=	Off
#Inst. Process=	Off
#Detector Gain=	Best Dynamic
#Detector ADC=	50 kHz HS
#Detector temperature (°C)=	-60.09
#Instrument=	LabRAM HR Evol
#Detector=	SIN-EM FIVIS
#Objective=	x100_VIS
#Grating=	1800 (450-850nm)
#ND Filter=	10%
#Laser=	532nm_Edge
#Hole=	30.0125
#Temperature=	0
#Range=	Visible
#StageXY=	75x50mm Scan+
#StageZ=	Z motor
#X (µm)=	0
#Y (µm)=	0
#Z (µm)=	37.5
#Full time(mm:ss)=	4:17
#Project=	21_02_17
#Sample=	BU19_TS(1)
#Site=
#Title=	BU19TS(1)-Ore1-inter_1800 (450-850nm)_532nm_Edge_10%_x100_VIS_H30um_60sX2
#Remark=
#Date=	17.02.2021 18:04
#Acquired=	17.02.2021 18:04:27
80.1379	163.03
81.1058	165.445
82.0736	163.51
83.0391	162.2
84.0067	164.663
84.9742	168.851
85.9395	174.004
86.9068	176.546
87.8718	179.877
88.8389	182.569
89.8038	181.368
90.7706	181.202
91.7353	183.284
92.702	184.9
93.6665	186.4
94.6329	187.669
95.5972	188.054
96.5614	189.083
97.5276	191.903
98.4915	194.479
99.4575	195.821
100.421	195.317
101.385	193.897
102.348	193.277
103.314	196.164
104.277	199.55
105.241	201.887
106.204	201.689
107.169	199.416
108.132	200.265
109.095	199.638
110.058	197.799
111.02	198.886
111.983	200.652
112.948	201.554
113.91	199.974
114.872	199.282
115.834	199.407
116.796	199.942
117.758	201.795
118.72	203.074
119.682	203.081
120.644	200.542
121.605	199.756
122.567	197.675
123.526	196.069
124.487	193.791
125.448	193.552
126.41	193.998
127.371	194.638
128.331	195.11
129.29	195.595
130.251	193.979
131.211	186.687
132.172	187.628
133.13	193.089
134.09	195.356
135.051	191.662
136.011	189.064
136.969	188.189
137.928	188.811
138.886	189.009
139.846	188.073
140.805	185.76
141.763	183.717
142.722	184.819
143.679	184.054
144.639	183.201
145.596	179.564
146.555	175.62
147.511	171.809
148.47	170.227
149.427	169.171
150.383	168.545
151.342	169.813
152.298	170.282
153.256	168.653
154.213	166.54
155.169	165.377
156.124	164.447
157.082	165.778
158.038	163.509
158.994	159.58
159.949	156.836
160.907	156.701
161.862	155.657
162.817	154.07
163.772	154.556
164.727	157.132
165.682	160.798
166.639	161.269
167.594	161.433
168.549	161.055
169.503	161.765
170.458	161.131
171.412	160.548
172.366	160.478
173.32	160.946
174.274	162.126
175.228	164.889
176.182	165.722
177.134	167.713
178.087	167.25
179.041	168.139
179.994	170.791
180.948	172.787
181.901	174.435
182.852	172.423
183.805	171.342
184.758	171.586
185.711	173.623
186.662	177.372
187.614	179.916
188.567	179.583
189.517	180.559
190.47	182.843
191.422	185.829
192.372	186.798
193.324	188.533
194.274	187.771
195.226	190.801
196.178	191.413
197.127	188.915
198.079	188.875
199.028	189.998
199.98	192.205
200.929	193.517
201.878	194.33
202.829	196.437
203.778	197.088
204.729	196.338
205.678	196.823
206.626	197.719
207.577	198.843
208.525	199.297
209.474	199.672
210.422	203.814
211.372	203.245
212.32	201.643
213.268	201.453
214.216	199.526
215.164	204.235
216.114	206.191
217.061	204.412
218.009	204.833
218.956	207.493
219.903	210.924
220.85	214.525
221.798	214.405
222.744	211.748
223.691	209.189
224.638	210.925
225.585	211.312
226.531	209.741
227.478	210.077
228.424	211.41
229.371	215.607
230.317	219.289
231.263	221.556
232.207	222.643
233.153	222.002
234.099	221.984
235.044	222.274
235.99	222.657
236.933	222.479
237.879	222.738
238.824	221.924
239.769	224.83
240.712	227.715
241.657	231.178
242.602	232.704
243.545	233.045
244.49	228.022
245.433	223.823
246.377	225.42
247.319	228.33
248.264	229.598
249.206	229.318
250.15	228.648
251.092	225.921
252.036	224.158
252.978	226.488
253.922	225.933
254.863	225.079
255.807	224.28
256.748	223.61
257.69	222.988
258.633	222.982
259.574	223.646
260.515	222.573
261.456	220.005
262.399	220.973
263.34	222.525
264.28	224.098
265.221	226.325
266.164	227.322
267.104	224.242
268.044	221.113
268.984	218.237
269.924	217.979
270.864	216.105
271.804	216.398
272.744	212.084
273.684	210.827
274.623	213.581
275.563	214.52
276.502	214.053
277.442	212.456
278.381	209.925
279.32	209.279
280.259	211.231
281.198	213.304
282.137	211.03
283.076	209.457
284.012	211.367
284.951	213.86
285.889	210.899
286.827	208.988
287.766	210.225
288.702	208.098
289.64	207.049
290.578	207.622
291.514	207.543
292.451	207.308
293.389	208.088
294.325	209.034
295.262	210.203
296.198	211.454
297.135	212.443
298.072	211.572
299.007	210.729
299.944	209.509
300.879	208.727
301.816	207.668
302.75	209.029
303.685	210.461
304.622	209.847
305.556	207.126
306.492	205.647
307.427	204.987
308.361	205.34
309.297	205.624
310.231	205.136
311.164	205.312
312.1	204.821
313.034	203.719
313.967	203.866
314.901	203.089
315.834	199.806
316.77	193.823
317.703	191.271
318.636	191.786
319.569	192.252
320.502	194.445
321.434	192.427
322.367	189.298
323.3	185.891
324.232	183.382
325.164	184.025
326.097	182.64
327.029	184.576
327.961	187.191
328.893	186.739
329.825	184.945
330.757	185.699
331.689	187.832
332.62	190.658
333.55	192.631
334.481	189.524
335.413	187.701
336.344	187.118
337.275	190.663
338.204	193.753
339.135	194.271
340.066	195.551
340.995	194.62
341.925	193.451
342.856	192.655
343.784	191.941
344.715	191.715
345.645	193.248
346.573	193.031
347.503	194.718
348.431	193.702
349.361	192.215
350.289	192.146
351.219	193.371
352.146	196.667
353.076	197.816
354.003	198.357
354.931	199.898
355.86	202.277
356.787	200.74
357.714	198.92
358.643	201.226
359.57	197.195
360.497	195.148
361.426	195.171
362.352	197.467
363.279	201.356
364.205	202.811
365.133	202.398
366.06	201.765
366.986	201.512
367.912	202.341
368.838	204.712
369.763	205.255
370.689	205.725
371.615	206.246
372.54	206.882
373.466	205.839
374.391	208.447
375.316	211.129
376.242	214.763
377.167	215.996
378.092	215.385
379.017	214.512
379.941	215.373
380.866	218.113
381.791	218.685
382.715	219.516
383.638	220.628
384.562	222.153
385.486	223.399
386.41	224.343
387.332	226.914
388.256	227.568
389.18	228.55
390.102	230.033
391.026	234.488
391.949	234.876
392.871	237.297
393.794	240.729
394.717	245.712
395.639	246.109
396.562	246.805
397.483	249.667
398.406	252.366
399.326	256.576
400.249	258.247
401.17	259.066
402.09	258.233
403.013	260.286
403.933	264.889
404.855	271.494
405.776	276.965
406.696	282.592
407.618	286.706
408.538	288.886
409.457	292.074
410.377	296.112
411.299	299.63
412.218	302.672
413.138	304.496
414.057	307.119
414.976	310.581
415.895	314.465
416.816	315.253
417.735	316.797
418.654	320.044
419.573	326.761
420.492	330.089
421.41	331.596
422.329	333.326
423.247	337.525
424.165	340.21
425.084	342.17
426.002	345.32
426.92	349.997
427.836	356.701
428.753	357.791
429.671	358.8
430.589	357.289
431.507	357.163
432.424	358.964
433.339	362.518
434.257	367.067
435.174	363.939
436.091	363.359
437.006	362.099
437.923	359.631
438.84	357.174
439.754	360.067
440.671	360.393
441.586	360.443
442.502	357.774
443.418	358.872
444.333	358.401
445.249	355.955
446.163	352.073
447.079	347.181
447.993	342.971
448.907	339.404
449.822	336.74
450.736	334.98
451.651	334.054
452.565	329.607
453.478	322.939
454.393	317.176
455.307	312.34
456.22	308.758
457.133	306.629
458.048	306.16
458.96	304.121
459.873	300.359
460.786	294.939
461.698	289.866
462.613	287.605
463.525	287.899
464.437	284.971
465.349	281.045
466.261	277.136
467.173	273.334
468.085	270.864
468.997	269.413
469.909	268.601
470.82	267.679
471.732	265.894
472.643	263.935
473.555	261.638
474.466	258.255
475.377	255.469
476.286	252.994
477.197	252.02
478.108	254.182
479.019	253.908
479.929	251.767
480.838	247.559
481.748	247.906
482.659	250.111
483.569	249.753
484.477	248.979
485.387	248.443
486.297	248.37
487.205	245.662
488.115	243.646
489.023	242.691
489.933	241.34
490.84	238.867
491.75	236.929
492.657	236.163
493.566	237.748
494.474	240.159
495.383	240.574
496.29	237.369
497.199	234.449
498.106	233.939
499.012	228.195
499.921	230.522
500.828	235.677
501.734	233.232
502.643	229.788
503.549	227.724
504.455	224.737
505.361	224.458
506.267	225.732
507.175	226.469
508.081	227.331
508.987	225.83
509.893	220.044
510.798	216.679
511.704	220.871
512.609	225.091
513.514	220.902
514.42	215.599
515.325	214.644
516.23	217.452
517.135	220.501
518.04	220.238
518.944	217.539
519.849	216.79
520.754	216.934
521.658	215.101
522.563	213.979
523.467	214.493
524.369	216.7
525.273	217.601
526.177	217.545
527.081	216.724
527.983	211.981
528.887	209.473
529.791	209.258
530.692	208.112
531.596	209.233
532.499	212.046
533.401	212.47
534.304	210.284
535.205	209.105
536.108	209.541
537.009	211.748
537.912	214.628
538.813	217.056
539.715	217.88
540.616	216.604
541.518	215.555
542.419	217.187
543.321	217.304
544.221	216.095
545.122	215.697
546.024	216.465
546.924	217.886
547.824	217.502
548.723	216.983
549.625	216.882
550.525	219.123
551.424	222.997
552.324	224.931
553.225	224.574
554.124	223.891
555.024	222.686
555.923	222.613
556.822	225.205
557.721	228.129
558.619	230.073
559.518	233.673
560.417	235.368
561.315	236.496
562.214	237.006
563.112	239.262
564.01	242.672
564.909	244.27
565.807	245.169
566.705	244.788
567.601	245.995
568.499	249.667
569.396	254.301
570.294	257.009
571.192	257.365
572.087	256.894
572.985	258.07
573.882	262.872
574.777	267.134
575.674	270.807
576.571	272.3
577.25	272.965
578.155	274.372
579.061	275.5
579.966	280.346
580.873	284.088
581.78	286.231
582.684	289.993
583.591	289.906
584.495	295.777
585.401	298.964
586.306	301.413
587.212	299.949
588.116	299.744
589.022	302.677
589.925	306.554
590.831	312.478
591.735	317.864
592.638	320.789
593.544	322.887
594.447	325.82
595.351	329.409
596.256	336.145
597.159	341.456
598.062	344.225
598.965	347.706
599.87	351.699
600.773	355.783
601.675	359.903
602.578	363.634
603.48	365.979
604.383	367.101
605.287	369.848
606.189	371.136
607.091	370.47
607.993	373.128
608.895	376.812
609.797	381.229
610.699	386.751
611.601	392.553
612.502	392.185
613.404	390.005
614.305	388.273
615.206	386.86
616.108	386.203
617.007	386.23
617.908	387.001
618.809	388.557
619.71	387.928
620.61	389.722
621.509	389.8
622.41	386.954
623.31	383.047
624.211	380.289
625.109	376.262
626.009	374.05
626.909	371.465
627.807	366.258
628.707	365.149
629.607	366.475
630.505	361.218
631.405	352.668
632.302	348.437
633.202	345.695
634.101	343.412
634.999	340.997
635.898	338.026
636.795	334.679
637.692	331.127
638.591	326.416
639.488	323.51
640.387	322.676
641.284	319.596
642.18	315.256
643.079	310.988
643.975	308.492
644.872	309.591
645.77	308.914
646.666	306.468
647.562	304.184
648.458	302.178
649.356	296.193
650.252	289.439
651.148	291.351
652.043	291.262
652.939	290.002
653.835	288.807
654.732	287.365
655.627	285.312
656.522	282.752
657.418	279.158
658.313	275.043
659.208	271.213
660.102	270.585
660.997	271.838
661.892	272.827
662.786	272.077
663.681	269.058
664.573	264.75
665.468	260.365
666.362	257.523
667.256	254.837
668.15	251.393
669.044	249.256
669.936	247.405
670.83	244.13
671.724	240.973
672.617	238.596
673.509	234.146
674.402	231.969
675.296	231.999
676.187	230.386
677.08	227.126
677.973	222.295
678.864	217.523
679.757	216.936
680.648	215.61
681.541	213.084
682.433	210.57
683.324	208.512
684.216	206.959
685.107	205.685
685.997	204.982
686.889	203.868
687.779	202.256
688.672	202.754
689.562	200.581
690.451	197.293
691.343	195.425
692.233	194.039
693.122	193.08
694.014	192.691
694.903	192.353
695.793	191.108
696.682	189.327
697.573	188.09
698.462	187.587
699.351	186.151
700.24	186.36
701.129	184.902
702.018	181.957
702.906	180.251
703.797	178.982
704.685	177.969
705.574	175.133
706.462	172.201
707.35	169.004
708.238	168.66
709.126	169.885
710.012	169.924
710.9	168.761
711.788	166.245
712.676	163.168
713.563	160.939
714.451	160.19
715.338	160.21
716.226	160.464
717.111	160.4
717.998	160.184
718.885	159.173
719.772	155.387
720.657	152.187
721.544	150.948
722.431	151.756
723.315	152.816
724.202	153.496
725.088	153.475
725.973	152.727
726.859	151.622
727.743	150.251
728.629	148.813
729.513	147.492
730.399	146.506
731.283	145.875
732.169	145.637
733.053	145.816
733.938	146.045
734.822	146.328
735.707	146.669
736.591	146.991
737.474	147.191
738.359	147.037
739.242	146.532
740.125	143.75
741.01	142.009
741.893	141.253
742.776	140.654
743.658	139.361
744.543	139.269
745.425	139.649
746.308	139.642
747.19	140.19
748.072	139.629
748.954	138.805
749.836	131.874
750.718	136.214
751.6	135.705
752.482	136.502
753.366	137.84
754.247	136.711
755.127	135.269
756.008	134.094
756.89	134.248
757.771	134.728
758.652	134.451
759.533	134.124
760.414	133.076
761.295	133.798
762.176	135.169
763.055	136.526
763.936	136.808
764.816	135.261
765.697	133.945
766.575	133.389
767.455	134.142
768.336	135.13
769.214	135.585
770.094	133.556
770.974	131.741
771.852	130.685
772.732	132.124
773.611	133.485
774.489	134.815
775.369	134.151
776.246	133.302
777.125	132.85
778.003	133.526
778.882	133.674
779.759	135.125
780.636	133.63
781.515	131.942
782.392	132.472
783.271	133.507
784.148	134.764
785.024	133.698
785.903	134.202
786.779	135.246
787.656	136.897
788.532	137.972
789.41	136.803
790.286	135.487
791.162	134.444
792.038	133.8
792.914	133.571
793.79	133.878
794.668	133.681
795.543	133.651
796.419	134.656
797.294	136.186
798.17	137.699
799.045	138.239
799.92	136.881
800.795	135.606
801.67	137.894
802.545	141.159
803.42	141.371
804.293	139.873
805.167	139.036
806.042	138.969
806.916	139.374
807.791	139.567
808.665	139.546
809.538	140.151
810.412	140.991
811.286	141.656
812.16	140.62
813.032	140.574
813.906	142.411
814.779	142.559
815.651	142.663
816.525	142.706
817.398	142.539
818.269	141.967
819.143	142.761
820.014	141.856
820.887	141.913
821.758	144.045
822.631	143.857
823.502	144.66
824.375	143.994
825.246	142.383
826.118	141.422
826.989	142.406
827.859	142.327
828.732	141.435
829.602	140.581
830.472	139.985
831.345	140.262
832.215	141.1
833.085	141.626
833.955	142.112
834.826	140.808
835.696	138.343
836.566	135.967
837.435	136.751
838.305	138.965
839.174	139.284
840.046	139.051
840.915	137.172
841.784	133.846
842.653	132.371
843.522	133.504
844.391	135.765
845.26	133.711
846.128	134.059
846.997	130.993
847.866	130.539
848.734	132.401
849.601	131.781
850.469	130.103
851.337	128.623
852.205	126.877
853.073	124.287
853.941	121.745
854.807	119.919
855.675	119.938
856.543	120.402
857.408	120.396
858.276	120.034
859.143	118.525
860.009	116.562
860.876	114.973
861.743	113.143
862.609	109.966
863.476	107.879
864.341	106.512
865.208	105.691
866.072	105.471
866.939	105.064
867.804	104.217
868.67	104.683
869.535	103.235
870.401	100.858
871.266	100.508
872.132	99.3011
872.996	94.8623
873.86	91.2188
874.726	91.477
875.59	91.6406
876.454	92.5727
877.318	92.6572
878.183	91.3647
879.047	89.4629
879.91	87.7938
880.774	86.6283
881.637	86.3571
882.5	85.9616
883.365	84.28
884.229	83.2534
885.091	83.0182
885.954	81.5274
886.817	80.317
887.68	80.4791
888.543	80.5313
889.405	80.4734
890.268	80.0511
891.13	79.7667
891.993	79.4779
892.855	78.5991
893.715	77.6184
894.577	77.3231
895.439	77.1297
896.301	77.2134
897.163	77.0093
898.025	76.0317
898.884	74.0763
899.746	73.8121
900.608	75.1128
901.467	74.8932
902.328	74.7359
903.19	74.6221
904.049	74.3015
904.91	73.7894
905.771	73.0667
906.63	72.3102
907.491	71.7694
908.35	71.0916
909.21	70.1212
910.069	69.3187
910.929	69.336
911.788	69.649
912.648	70.191
913.507	70.1867
914.367	69.316
915.225	69.1426
916.083	69.4202
916.943	69.6731
917.801	69.7871
918.659	69.7718
919.518	69.5685
920.376	69.4928
921.234	69.4823
922.091	69.7812
922.949	70.1958
923.808	69.1202
924.665	66.8903
925.522	66.3591
926.379	67.9936
927.236	67.3922
928.093	66.1056
928.95	66.2938
929.807	67.3535
930.664	66.7248
931.52	67.8456
932.377	69.3215
933.233	69.1392
934.089	67.5049
934.946	65.2209
935.802	64.7622
936.658	65.7024
937.514	66.9464
938.37	67.1986
939.224	66.9235
940.08	66.5158
940.935	65.6871
941.791	64.2275
942.646	62.8524
943.5	62.9818
944.355	64.6114
945.211	64.2095
946.064	63.9247
946.919	64.2987
947.774	64.9625
948.627	63.8756
949.482	63.8851
950.335	64.7852
951.189	65.2417
952.042	65.8517
952.897	66.1221
953.749	65.8526
954.603	64.5696
955.456	63.0433
956.31	61.9132
957.162	62.2743
958.014	62.7037
958.868	63.2442
959.72	63.6429
960.572	63.3623
961.426	63.0169
962.278	62.8006
963.129	62.5232
963.981	61.1403
964.834	61.6827
965.685	62.5818
966.537	63.1661
967.388	62.4117
968.239	61.3185
969.09	61.4407
969.943	61.9201
970.794	62.1547
971.645	61.9707
972.495	61.5586
973.346	60.2529
974.197	59.6197
975.047	60.7412
975.898	61.6174
976.748	62.6212
977.596	63.7481
978.446	63.6577
979.296	62.869
980.146	61.9447
980.996	60.9557
981.846	59.4416
982.696	60.4711
983.544	61.1123
984.393	61.4178
985.243	61.2932
986.09	60.9308
986.94	60.8254
987.789	60.7307
988.636	60.6377
989.485	60.5451
990.334	60.4052
991.181	60.1905
992.03	59.9712
992.877	59.6606
993.726	59.417
994.572	59.2678
995.421	58.9111
996.267	58.7
997.116	59.307
997.962	59.4308
998.81	59.3745
999.657	57.2961
999.939	55.5756