File: Data/Raman/raw/bu19w-ore3-lefthost_150 (500nm)_633nm_edge_100%_x100_vis_h30um_30sx2_01_0.txt
#Acq. time (s)=	30
#Accumulations=	2
#Range (cm-¹)=	100...4000
#Windows=	1
#Auto scanning=	Off
#Autofocus=	Off
#Macrospot=	Off
#AutoExposure=	Off
#Spike filter=	Multiple accum.
#Delay time (s)=	2
#Binning=	1
#Readout mode=	Signal
#DeNoise=	Standard
#ICS correction=	On
#Dark correction=	Off
#Inst. Process=	Off
#Detector Gain=	Best Dynamic
#Detector ADC=	50 kHz HS
#Detector temperature (°C)=	-60.09
#Instrument=	LabRAM HR Evol
#Detector=	SIN-EM FIVIS
#Objective=	x100_VIS
#Grating=	150 (500nm)
#ND Filter=	100%
#Laser=	633nm_Edge
#Hole=	30.0125
#Temperature=	0
#Range=	Visible
#StageXY=	75x50mm Scan+
#StageZ=	Z motor
#X (µm)=	0
#Y (µm)=	0
#Z (µm)=	68.4
#Full time(mm:ss)=	1:04
#Project=	21_02_17
#Sample=	BU19w
#Site=
#Title=	BU19w-Ore3-leftHost_150 (500nm)_633nm_Edge_100%_x100_VIS_H30um_30sX2
#Remark=
#Date=	17.02.2021 10:58
#Acquired=	17.02.2021 10:58:56
100.724	766.942
107.24	752.18
113.751	744.105
120.256	738.215
126.756	734.932
133.251	733.351
139.74	733.6
146.224	734.173
152.702	734.828
159.175	734.285
165.643	732.271
172.105	731.111
178.561	731.094
185.013	731.493
191.459	731.905
197.9	734.634
204.336	739.013
210.765	744.032
217.19	751.33
223.61	759.86
230.024	775.125
236.432	800.167
242.836	859.816
249.233	842.737
255.627	803.159
262.015	794.967
268.397	798.073
274.774	810.446
281.145	845.073
287.513	911.214
293.873	957.538
300.23	891.403
306.58	806.461
312.927	786.594
319.266	782.513
325.602	814.402
331.932	896.633
338.256	916.613
344.577	828.527
350.89	796.118
357.199	791.09
363.504	794.413
369.803	799.493
376.096	794.565
382.384	788.861
388.669	785.549
394.947	782.608
401.219	781.257
407.487	781.666
413.75	784.792
420.007	791.159
426.261	799.806
432.508	810.265
438.751	824.178
444.988	848.834
451.22	880.089
457.447	872.78
463.669	845.789
469.886	821.455
476.098	797.053
482.303	786.72
488.505	782.249
494.702	782.411
500.894	786.565
507.081	791.218
513.263	796.282
519.44	801.451
525.61	799.165
531.777	796.981
537.939	794.333
544.096	791.091
550.246	786.924
556.393	782.357
562.535	778.955
568.671	779.245
574.803	781.027
580.929	787.802
587.051	802.635
593.167	824.348
599.28	850.539
605.387	880.896
611.489	904.907
617.585	904.017
623.678	903.469
629.764	900.248
635.847	898.871
641.924	880.026
647.998	862.737
654.065	843.775
660.127	864.154
666.184	875.341
672.238	870.156
678.286	852.319
684.329	829.548
690.367	813.267
696.401	802.986
702.43	792.522
708.453	781.79
714.472	775.756
720.486	773.089
726.495	774.777
732.5	776.865
738.501	780.695
744.495	784.388
750.485	786.922
756.471	786.113
762.451	783.295
768.426	781.743
774.397	781.085
780.363	780.332
786.325	779.254
792.281	781.04
798.234	781.205
804.181	779.449
810.124	778.997
816.06	780.316
821.993	781.848
827.922	786.357
833.846	789.718
839.764	791.954
845.678	792.88
851.588	792.734
857.492	792.324
863.392	791.847
869.287	787.289
875.178	790.724
881.063	799.636
886.945	806.873
892.822	811.175
898.694	804.019
904.56	799.775
910.424	797.74
916.281	797.601
922.135	798.741
927.984	804.187
933.827	813.801
939.668	826.4
945.502	843.627
951.332	862.864
957.159	882.137
962.979	899.337
968.796	911.424
974.607	922.24
980.414	936.652
986.218	963.988
992.016	1016.94
997.809	1069.37
1003.6	1058.35
1009.38	1024.11
1015.16	1000.2
1020.94	1025.72
1026.71	1073.67
1032.48	1111.63
1038.24	1056.16
1043.99	977.796
1049.75	916.831
1055.5	884.875
1061.24	860.901
1066.98	846.916
1072.71	841.42
1078.44	851.964
1084.17	871.621
1089.89	893.635
1095.61	910.348
1101.32	918.198
1107.03	907.758
1112.73	888.505
1118.43	864.327
1124.12	840.629
1129.81	829.207
1135.5	829.276
1141.18	833.606
1146.86	848.654
1152.53	863.372
1158.2	864.893
1163.86	856.9
1169.52	843.055
1175.17	820.772
1180.83	801.915
1186.47	788.703
1192.11	784.667
1197.75	781.637
1203.38	781.682
1209.01	782.939
1214.63	784.997
1220.25	785.86
1225.87	783.198
1231.48	778.247
1237.09	773.07
1242.69	773.626
1248.29	775.872
1253.88	781.869
1259.47	778.682
1265.05	762.513
1270.63	755.685
1276.21	752.605
1281.78	750.206
1287.35	748.708
1292.91	749.067
1298.47	744.641
1304.03	747.17
1309.58	749.193
1315.13	753.394
1320.67	759.861
1326.2	760.276
1331.74	757.185
1337.27	755.091
1342.79	754.22
1348.31	751.589
1353.83	748.202
1359.34	742.907
1364.85	739.591
1370.35	740.174
1375.85	741.436
1381.35	741.527
1386.84	740.528
1392.32	738.77
1397.81	735.124
1403.29	732.137
1408.76	731.682
1414.23	730.217
1419.7	729.58
1425.16	730.205
1430.61	730.522
1436.07	728.875
1441.52	728.067
1446.96	727.883
1452.4	727.391
1457.84	728.377
1463.27	729.647
1468.7	728.656
1474.12	725.397
1479.55	722.707
1484.96	718.201
1490.37	717.29
1495.78	716.507
1501.18	714.973
1506.58	716.951
1511.98	719.174
1517.37	720.424
1522.76	718.585
1528.14	714.699
1533.52	712.051
1538.9	708.2
1544.27	706.934
1549.63	705.444
1555	704.727
1560.35	706.189
1565.71	704.926
1571.06	704.187
1576.41	702.739
1581.75	700.732
1587.09	697.786
1592.42	695.989
1597.75	695.15
1603.08	694.619
1608.4	696.692
1613.72	698.527
1619.03	698.217
1624.34	697.57
1629.65	696.674
1634.95	691.205
1640.25	686.073
1645.54	680.447
1650.83	677.062
1656.12	674.944
1661.4	671.418
1666.68	667.581
1671.96	664.761
1677.23	662.011
1682.49	660.806
1687.75	663.643
1693.01	663.844
1698.27	663.812
1703.52	663.482
1708.77	663.691
1714.01	663.797
1719.25	663.333
1724.48	662.092
1729.71	659.257
1734.94	653.848
1740.16	648.656
1745.38	642.52
1750.6	636.163
1755.81	632.537
1761.02	631.116
1766.22	630.867
1771.42	633.16
1776.62	633.662
1781.81	632.694
1787	632.367
1792.18	634.256
1797.36	632.974
1802.54	630.471
1807.71	627.196
1812.88	624.645
1818.05	621.356
1823.21	619.608
1828.36	618.239
1833.52	617.386
1838.67	616.691
1843.81	616.6
1848.95	613.545
1854.09	609.314
1859.23	605.156
1864.36	601.848
1869.48	600.287
1874.61	599.906
1879.73	599.587
1884.84	599.148
1889.95	597.281
1895.06	593.62
1900.17	589.848
1905.27	586.766
1910.36	582.578
1915.45	579.893
1920.54	577.354
1925.63	577.113
1930.71	577.346
1935.79	577.336
1940.86	576.184
1945.93	575.506
1951	574.837
1956.06	571.238
1961.12	567.725
1966.18	564.434
1971.23	561.159
1976.28	559.132
1981.32	557.579
1986.36	556.71
1991.4	556.545
1996.43	555.688
2001.46	553.666
2006.48	551.654
2011.51	549.516
2016.52	548.599
2021.54	548.916
2026.55	547.677
2031.56	546.527
2036.56	543.922
2041.56	541.314
2046.56	540.114
2051.55	538.726
2056.54	536.349
2061.52	533.701
2066.51	533.781
2071.48	532.048
2076.46	530.15
2081.43	526.697
2086.4	521.889
2091.36	517.441
2096.32	514.989
2101.28	515.608
2106.23	515.318
2111.18	514.557
2116.12	513.944
2121.06	512.103
2126	510.049
2130.94	506.026
2135.87	502.467
2140.79	498.257
2145.72	497.65
2150.64	495.189
2155.56	493.101
2160.47	490.697
2165.38	487.648
2170.28	484.066
2175.19	483.705
2180.09	482.36
2184.98	481.509
2189.87	480.993
2194.76	479.785
2199.65	476.661
2204.53	475.614
2209.4	475.026
2214.28	475.761
2219.15	476.241
2224.02	475.98
2228.88	474.802
2233.74	473.657
2238.6	470.741
2243.45	466.677
2248.3	462.178
2253.14	460.388
2257.99	458.879
2262.83	457.115
2267.66	457.263
2272.49	458.289
2277.32	457.869
2282.15	454.76
2286.97	451.354
2291.79	446.527
2296.6	446.903
2301.41	446.737
2306.22	447.583
2311.02	448.062
2315.83	446.23
2320.62	441.122
2325.42	436.002
2330.21	430.649
2335	429.686
2339.78	428.774
2344.56	428.957
2349.34	428.286
2354.11	427.815
2358.88	428.531
2363.65	427.506
2368.41	425.622
2373.17	423.648
2377.93	421.637
2382.68	418.698
2387.43	414.491
2392.17	410.333
2396.92	407.115
2401.66	404.732
2406.39	405.614
2411.13	407.391
2415.85	408.593
2420.58	408.825
2425.3	408.054
2430.02	405.3
2434.74	401.686
2439.45	399.658
2444.16	397.162
2448.86	394.84
2453.57	393.044
2458.27	390.463
2462.96	386.964
2467.65	383.29
2472.34	381.218
2477.03	379.691
2481.71	379.4
2486.39	378.547
2491.07	378.711
2495.74	377.811
2500.41	377.536
2505.07	375.41
2509.74	372.914
2514.4	370.501
2519.05	368.874
2523.7	367.652
2528.35	366.393
2533	366.599
2537.64	366.824
2542.28	365.383
2546.92	362.55
2551.55	358.293
2556.18	355.42
2560.81	354.177
2565.43	354.209
2570.05	354.526
2574.67	354.751
2579.28	354.309
2583.89	347.636
2588.5	342.221
2593.1	339.015
2597.7	337.508
2602.3	336.921
2606.89	337.58
2611.48	344.096
2616.07	339.994
2620.66	337.734
2625.24	337.518
2629.82	336.927
2634.39	336.135
2638.96	335.096
2643.53	333.611
2648.09	331.109
2652.66	328.868
2657.21	328.643
2661.77	327.866
2666.32	327.4
2670.87	326.34
2675.42	324.373
2679.96	322.444
2684.5	320.931
2689.04	317.044
2693.57	314.314
2698.1	314.274
2702.63	313.483
2707.15	313.308
2711.67	313.863
2716.19	313.947
2720.7	313.236
2725.21	311.832
2729.72	310.021
2734.23	307.877
2738.73	306.679
2743.23	305.392
2747.72	301.928
2752.22	298.987
2756.7	297.22
2761.19	296.702
2765.67	295.587
2770.15	293.527
2774.63	290.837
2779.1	287.185
2783.57	283.573
2788.04	280.865
2792.51	278.329
2796.97	278.748
2801.43	280.923
2805.88	283.608
2810.33	285.821
2814.78	287.56
2819.23	287.034
2823.67	286.004
2828.11	283.719
2832.55	282.393
2836.98	281.11
2841.41	279.108
2845.84	277.173
2850.26	275.793
2854.69	274.415
2859.1	271.256
2863.52	268.054
2867.93	265.855
2872.34	265.117
2876.75	265.408
2881.15	265.659
2885.55	266.142
2889.95	266.906
2894.34	265.52
2898.73	264.67
2903.12	263.699
2907.5	261.707
2911.89	259.482
2916.27	256.215
2920.64	257.41
2925.01	258.861
2929.38	259.076
2933.75	258.739
2938.12	258.848
2942.48	258.94
2946.84	258.852
2951.19	256.448
2955.54	254.762
2959.89	253.633
2964.24	253.196
2968.58	252.074
2972.92	255.093
2977.26	253.122
2981.59	242.763
2985.92	240.971
2990.25	240.315
2994.58	240.384
2998.9	240.616
3003.22	242.182
3007.54	243.456
3011.85	242.488
3016.16	240.531
3020.47	239.275
3024.77	238.855
3029.07	235.643
3033.37	232.967
3037.67	232.349
3041.96	233.488
3046.25	233.462
3050.54	232.057
3054.82	231.266
3059.11	230.204
3063.38	228.525
3067.66	226.375
3071.93	225.537
3076.2	225.202
3080.47	225.021
3084.73	223.97
3088.99	224.686
3093.25	224.857
3097.51	225.405
3101.76	224.326
3106.01	222.868
3110.26	222.524
3114.5	221.301
3118.74	219.274
3122.98	218.06
3127.22	216.662
3131.45	216.028
3135.68	215.781
3139.91	217.111
3144.13	218.713
3148.35	220.159
3152.57	220.562
3156.78	220.653
3161	220.063
3165.21	219.324
3169.41	218.575
3173.62	217.371
3177.82	218.062
3182.02	218.271
3186.21	218.597
3190.4	218.258
3194.59	216.858
3198.78	215.314
3202.96	215.545
3207.15	215.601
3211.33	216.211
3215.5	216.918
3219.67	216.749
3223.84	216.487
3228.01	214.548
3232.18	212.8
3236.34	211.468
3240.5	211.377
3244.65	211.049
3248.81	210.756
3252.96	210.501
3257.11	209.379
3261.25	207.195
3265.39	205.552
3269.53	205.088
3273.67	204.881
3277.8	204.129
3281.94	201.807
3286.06	201.753
3290.19	201.794
3294.31	200.299
3298.43	198.465
3302.55	197.058
3306.67	196.225
3310.78	194.775
3314.89	192.65
3319	190.04
3323.1	188.913
3327.2	189.45
3331.3	189.736
3335.39	189.508
3339.49	187.643
3343.58	189.171
3347.67	191.133
3351.75	191.695
3355.83	190.536
3359.91	189.74
3363.99	188.509
3368.06	185.947
3372.14	184.901
3376.2	185.537
3380.27	187.618
3384.33	189.182
3388.39	191.707
3392.45	192.685
3396.51	191.858
3400.56	191.141
3404.61	190.696
3408.66	189.821
3412.7	190.69
3416.74	194.06
3420.78	201.613
3424.82	220.265
3428.85	261.023
3432.88	247.59
3436.91	208.177
3440.94	189.443
3444.96	177.824
3448.98	173.497
3453	170.904
3457.02	168.969
3461.03	168.493
3465.04	168.838
3469.05	168.584
3473.05	169.112
3477.05	169.885
3481.05	171.648
3485.05	171.823
3489.04	171.753
3493.04	169.974
3497.03	168.688
3501.01	168.695
3505	169.436
3508.98	171.922
3512.96	173.536
3516.93	173.394
3520.9	172.53
3524.88	169.337
3528.84	164.381
3532.81	159.41
3536.77	155.963
3540.73	152.12
3544.69	149.262
3548.65	148.459
3552.6	148.925
3556.55	151.233
3560.5	153.302
3564.44	155.379
3568.38	156.747
3572.32	158.373
3576.26	159.626
3580.2	160.727
3584.13	161.317
3588.06	163.519
3591.98	164.052
3595.91	163.556
3599.83	161.262
3603.75	159.228
3607.67	157.834
3611.58	156.99
3615.49	155.864
3619.4	154.946
3623.31	155.496
3627.21	154.565
3631.11	151.035
3635.01	148.209
3638.91	144.233
3642.8	140.306
3646.69	137.947
3650.58	135.383
3654.47	133
3658.35	132.053
3662.24	131.832
3666.11	132.45
3669.99	132.671
3673.86	134.193
3677.74	135.668
3681.6	137.52
3685.47	139.355
3689.34	139.223
3693.2	138.231
3697.06	137.227
3700.91	136.673
3704.77	137.061
3708.62	137.473
3712.47	138.296
3716.31	138.31
3720.16	137.472
3724	136.87
3727.84	136.515
3731.67	135.672
3735.51	135.229
3739.34	135.217
3743.17	135.517
3747	136.956
3750.82	137.553
3754.64	136.719
3758.46	136.511
3762.28	135.507
3766.09	133.629
3769.9	131.42
3773.71	129.705
3777.52	128.324
3781.33	127.263
3785.13	126.71
3788.93	127.336
3792.72	128.683
3796.52	129.773
3800.31	130.469
3804.1	130.102
3807.89	129.794
3811.68	129.504
3815.46	128.473
3819.24	127.938
3823.02	125.719
3826.79	123.656
3830.56	121.86
3834.34	121.912
3838.1	122.168
3841.87	120.755
3845.63	120.831
3849.39	123.638
3853.15	123.235
3856.91	124.07
3860.66	124.501
3864.42	125.132
3868.16	125.135
3871.91	125.96
3875.66	125.958
3879.4	126.539
3883.14	127.163
3886.88	126.846
3890.61	126.431
3894.34	126.637
3898.07	126.431
3901.8	125.065
3905.53	124.507
3909.25	123.983
3912.97	123.411
3916.69	122.916
3920.4	121.485
3924.12	120.364
3927.83	120.424
3931.54	120.613
3935.24	120.827
3938.95	120.764
3942.65	121.778
3946.35	122.599
3950.05	122.205
3953.74	122.21
3957.44	121.386
3961.13	118.836
3964.81	117.894
3968.5	117.726
3972.18	116.704
3975.86	116.183
3979.54	115.562
3983.22	115.18
3986.89	114.857
3990.56	113.631
3994.23	113.338
3997.9	112.941
3999.73	113.273