File: Data/Raman/raw/bu19ts-coltan3-rim_150 (500nm)_633nm_edge_10%_x100_vis_h30um_10sx2_01.txt
#Acq. time (s)=	10
#Accumulations=	2
#Range (cm-¹)=	100...4000
#Windows=	1
#Auto scanning=	Off
#Autofocus=	Off
#Macrospot=	Off
#AutoExposure=	Off
#Spike filter=	Multiple accum.
#Delay time (s)=	2
#Binning=	1
#Readout mode=	Signal
#DeNoise=	Standard
#ICS correction=	On
#Dark correction=	Off
#Inst. Process=	Off
#Detector Gain=	Best Dynamic
#Detector ADC=	50 kHz HS
#Detector temperature (°C)=	-60.09
#Instrument=	LabRAM HR Evol
#Detector=	SIN-EM FIVIS
#Objective=	x100_VIS
#Grating=	150 (500nm)
#ND Filter=	10%
#Laser=	633nm_Edge
#Hole=	30.0125
#Temperature=	0
#Range=	Visible
#StageXY=	75x50mm Scan+
#StageZ=	Z motor
#X (µm)=	0
#Y (µm)=	0
#Z (µm)=	-2.5
#Full time(s)=	24
#Project=	20_10_27
#Sample=	BU19TS
#Site=
#Title=	BU19TS-Coltan2-rim_150 (500nm)_633nm_Edge_10%_x100_VIS_H30um_10sX2
#Remark=
#Date=	27.10.2020 16:56
#Acquired=	27.10.2020 16:56:06
100.764	60.0907
107.281	62.3222
113.791	73.3782
120.297	90.8073
126.797	118.054
133.291	137.912
139.78	135.446
146.264	98.4251
152.741	73.8971
159.214	91.2989
165.682	92.2528
172.144	91.983
178.601	90.2247
185.053	87.5377
191.499	82.6938
197.939	81.7341
204.374	110.128
210.805	122.549
217.23	84.333
223.648	76.4024
230.063	84.2243
236.472	98.84
242.874	124.264
249.273	137.203
255.667	150.371
262.053	178.028
268.436	234.764
274.813	302.501
281.185	238.709
287.552	171.158
293.913	142.635
300.27	142.407
306.62	135.958
312.965	127.318
319.306	125.943
325.64	115.514
331.971	100.305
338.295	89.3104
344.614	82.794
350.93	79.0451
357.238	78.1999
363.542	78.9399
369.842	82.3844
376.135	89.2383
382.423	102.082
388.706	116.545
394.984	121.32
401.258	111.9
407.526	101.558
413.789	95.2364
420.046	93.1605
426.299	93.7367
432.546	95.4824
438.788	98.6795
445.025	102.987
451.257	109.429
457.484	116.97
463.706	125.893
469.923	135.08
476.135	143.664
482.342	150.46
488.544	155.857
494.741	158.064
500.933	148.462
507.12	136.222
513.3	136.112
519.477	142.522
525.649	172.223
531.815	186.601
537.976	160.504
544.133	139.016
550.285	126.474
556.43	118.125
562.572	113.797
568.709	110.82
574.84	109.955
580.967	110.445
587.09	113.145
593.205	117.901
599.318	123.837
605.424	132.104
611.527	146.224
617.623	165.545
623.716	190.03
629.802	214.761
635.884	235.488
641.962	221.562
648.034	184.007
654.101	151.201
660.165	131.756
666.222	120.104
672.274	111.202
678.324	105.268
684.366	102.114
690.404	98.9854
696.438	98.0033
702.466	98.2493
708.491	99.3159
714.51	100.435
720.523	101.485
726.533	102.655
732.537	103.181
738.537	102.835
744.531	102.209
750.521	101.435
756.507	100.719
762.487	100.292
768.463	99.5276
774.434	99.6243
780.4	100.639
786.362	102.862
792.319	104.934
798.269	108.828
804.217	118.889
810.159	134.416
816.097	149.945
822.03	172.684
827.958	193.934
833.881	214.935
839.801	236.814
845.714	272.393
851.624	353.768
857.529	527.116
863.428	831.827
869.324	1447.57
875.215	2360.67
881.1	1981.8
886.982	874.373
892.858	433.278
898.73	279.963
904.597	190.024
910.459	137.423
916.318	117.781
922.171	106.75
928.02	97.3548
933.864	90.6976
939.703	85.4755
945.539	80.9174
951.368	77.6311
957.194	75.315
963.014	74.1647
968.832	75.4717
974.643	73.4302
980.45	70.9385
986.253	68.9792
992.051	67.297
997.844	65.9728
1003.63	64.7983
1009.42	64.1664
1015.2	64.5607
1020.97	65.3515
1026.74	65.9589
1032.51	65.3893
1038.27	65.0461
1044.03	64.8425
1049.78	64.6021
1055.53	64.0437
1061.27	62.8184
1067.01	62.3044
1072.75	61.8951
1078.48	61.8532
1084.2	62.2987
1089.92	62.1329
1095.64	62.589
1101.35	62.538
1107.06	62.3399
1112.77	61.9342
1118.46	61.5266
1124.16	61.3917
1129.85	61.5859
1135.53	61.787
1141.22	61.5194
1146.89	60.7916
1152.56	60.1729
1158.23	59.1184
1163.9	57.9086
1169.56	57.2103
1175.21	56.5732
1180.86	55.5516
1186.51	55.2288
1192.15	54.973
1197.78	54.3572
1203.42	54.1413
1209.04	54.112
1214.67	53.5778
1220.29	52.9307
1225.9	52.0472
1231.51	51.8156
1237.12	51.6497
1242.72	51.1302
1248.32	50.8144
1253.92	50.4787
1259.5	49.7375
1265.09	48.76
1270.67	47.8931
1276.25	47.4276
1281.82	47.3327
1287.39	47.3703
1292.95	47.3159
1298.51	47.1462
1304.06	47.2818
1309.61	47.7162
1315.16	47.7465
1320.7	47.4335
1326.24	47.068
1331.77	47.0608
1337.3	46.633
1342.83	46.7376
1348.35	47.0754
1353.86	47.4411
1359.37	47.7486
1364.88	47.244
1370.39	46.8014
1375.89	46.8909
1381.38	45.9156
1386.87	45.8124
1392.36	45.6966
1397.84	46.0076
1403.32	46.2896
1408.79	46.4048
1414.26	46.2504
1419.73	45.7736
1425.19	45.9426
1430.65	46.27
1436.1	46.7579
1441.55	46.6222
1447	46.4204
1452.44	46.1774
1457.87	45.914
1463.31	45.1525
1468.73	44.6659
1474.16	44.5691
1479.58	44.848
1484.99	45.3191
1490.41	45.4639
1495.81	45.2395
1501.22	44.8259
1506.62	44.111
1512.01	43.475
1517.4	43.1416
1522.79	42.8997
1528.17	43.0213
1533.55	43.2062
1538.93	42.2386
1544.3	41.1815
1549.67	40.7927
1555.03	40.9123
1560.39	41.4647
1565.74	42.1649
1571.09	42.4776
1576.44	42.8082
1581.78	42.6629
1587.12	42.4486
1592.45	42.3555
1597.78	42.4334
1603.11	42.0308
1608.43	41.6606
1613.75	41.3038
1619.07	40.8878
1624.38	40.7123
1629.68	40.7393
1634.98	40.8347
1640.28	40.9155
1645.58	41.1051
1650.87	41.3116
1656.15	41.5839
1661.44	41.7884
1666.71	41.9547
1671.99	42.1038
1677.26	42.1411
1682.53	42.0481
1687.79	41.9758
1693.05	41.861
1698.3	41.8696
1703.55	42.05
1708.8	42.7829
1714.04	44.0461
1719.28	45.3997
1724.51	46.7922
1729.75	47.9341
1734.97	47.3004
1740.2	46.7382
1745.42	45.5899
1750.63	44.2709
1755.84	42.9861
1761.05	41.803
1766.25	40.3893
1771.45	38.8705
1776.65	37.4574
1781.84	36.2783
1787.03	35.2033
1792.21	34.478
1797.39	33.6236
1802.57	32.9687
1807.74	32.4946
1812.91	32.1836
1818.08	32.0163
1823.24	32.1192
1828.39	32.4886
1833.55	32.9492
1838.7	33.2396
1843.84	33.3332
1848.99	32.7776
1854.12	32.5375
1859.26	32.2233
1864.39	31.9946
1869.52	31.3743
1874.64	30.934
1879.76	31.1227
1884.87	31.5105
1889.98	31.29
1895.09	31.2388
1900.2	31.4334
1905.3	31.705
1910.39	31.498
1915.49	31.2156
1920.57	31.0235
1925.66	30.9862
1930.74	30.873
1935.82	31.3172
1940.89	31.5729
1945.96	31.7655
1951.03	31.7685
1956.09	31.7599
1961.15	31.7785
1966.21	31.7659
1971.26	31.3015
1976.31	30.6544
1981.35	30.2202
1986.39	30.197
1991.43	30.249
1996.46	30.6049
2001.49	30.3698
2006.52	30.0844
2011.54	30.1745
2016.56	30.7353
2021.57	30.6518
2026.58	30.1406
2031.59	29.8834
2036.59	30.0859
2041.59	30.3119
2046.59	29.9062
2051.58	29.4547
2056.57	29.201
2061.55	28.9339
2066.54	28.7299
2071.51	28.6456
2076.49	28.555
2081.46	28.888
2086.43	29.3419
2091.39	28.9201
2096.35	28.5504
2101.3	28.562
2106.26	28.7509
2111.21	28.8124
2116.15	28.8673
2121.09	28.7476
2126.03	28.4642
2130.97	28.1176
2135.9	27.5188
2140.83	27.1418
2145.75	27.4049
2150.67	27.6583
2155.59	27.9755
2160.5	28.3932
2165.41	28.7383
2170.31	28.8316
2175.22	29.2728
2180.12	29.3017
2185.01	29.5935
2189.9	30.0392
2194.79	29.9842
2199.68	29.6242
2204.56	29.3938
2209.43	29.1959
2214.31	29.0886
2219.18	28.7027
2224.05	28.2479
2228.91	28.5451
2233.77	28.9064
2238.63	27.904
2243.48	25.9537
2248.33	26.2675
2253.17	27.1995
2258.02	28.0969
2262.86	28.7199
2267.69	28.0332
2272.52	27.4871
2277.35	27.3062
2282.18	27.2348
2287	27.2791
2291.82	27.5721
2296.63	27.974
2301.44	27.8798
2306.25	27.7981
2311.05	27.7971
2315.86	27.8845
2320.65	28.0187
2325.45	28.1908
2330.24	28.4275
2335.03	28.3879
2339.81	27.8961
2344.59	27.1508
2349.37	26.5953
2354.14	25.9982
2358.91	25.791
2363.67	25.7019
2368.44	26.2056
2373.2	26.9795
2377.95	27.3883
2382.71	27.516
2387.46	27.7776
2392.2	28.1701
2396.95	28.1206
2401.68	27.9116
2406.42	27.6834
2411.15	27.3683
2415.88	27.03
2420.61	26.7691
2425.33	26.6258
2430.05	26.701
2434.77	26.8124
2439.48	26.8937
2444.19	26.4713
2448.89	26.2512
2453.6	26.265
2458.29	26.8779
2462.99	26.7601
2467.68	26.5331
2472.37	26.3121
2477.06	26.1046
2481.74	26.032
2486.42	26.1545
2491.1	27.2382
2495.77	26.5972
2500.44	26.3501
2505.1	26.6279
2509.76	26.7596
2514.42	25.9851
2519.08	25.3801
2523.73	25.1641
2528.38	25.3403
2533.03	25.4099
2537.67	24.8848
2542.31	24.5546
2546.95	24.8834
2551.58	25.6112
2556.21	26.3164
2560.84	26.6414
2565.46	26.8116
2570.08	26.7575
2574.7	26.8295
2579.31	26.5582
2583.92	26.4697
2588.53	26.3156
2593.13	26.0102
2597.73	25.7231
2602.33	25.4994
2606.92	25.411
2611.51	25.5571
2616.1	26.0568
2620.68	26.5088
2625.26	26.9504
2629.84	27.5093
2634.42	27.5298
2638.99	27.2445
2643.56	27.03
2648.12	26.5392
2652.68	25.9662
2657.24	25.3837
2661.8	25.0047
2666.35	24.8078
2670.9	24.8238
2675.45	24.917
2679.99	25.0547
2684.53	25.2243
2689.06	25.416
2693.6	25.6198
2698.13	25.8007
2702.66	25.6978
2707.18	24.2743
2711.7	24.9754
2716.22	24.6899
2720.73	24.7982
2725.24	24.879
2729.75	24.905
2734.26	24.621
2738.76	24.3573
2743.25	24.3761
2747.75	24.7218
2752.24	25.0762
2756.73	25.433
2761.22	25.7596
2765.7	26.0968
2770.18	25.752
2774.66	25.0557
2779.13	24.8426
2783.6	24.6793
2788.07	24.6278
2792.53	24.4598
2797	24.3261
2801.45	24.3592
2805.91	24.4374
2810.36	24.5648
2814.81	24.5098
2819.26	24.6463
2823.7	24.7861
2828.14	25.0163
2832.57	25.2393
2837.01	25.516
2841.44	25.7493
2845.87	25.9639
2850.29	25.4461
2854.71	25.0108
2859.13	24.9396
2863.55	25.1163
2867.96	25.4496
2872.37	25.3726
2876.77	25.4251
2881.18	25.7138
2885.58	25.7551
2889.97	25.696
2894.37	25.496
2898.76	25.3837
2903.15	25.451
2907.53	25.4097
2911.91	25.2706
2916.29	25.133
2920.67	24.832
2925.04	24.7463
2929.41	25.1607
2933.78	25.4489
2938.14	25.5049
2942.5	25.5863
2946.86	25.5056
2951.22	25.5035
2955.57	25.5643
2959.92	25.7708
2964.26	25.6307
2968.61	25.6002
2972.95	25.7708
2977.28	25.3751
2981.62	24.8518
2985.95	24.6867
2990.28	25.0474
2994.6	25.8777
2998.93	26.5387
3003.25	26.5247
3007.56	26.5136
3011.88	26.5049
3016.19	26.4983
3020.49	26.4927
3024.8	26.4809
3029.1	26.459
3033.4	26.4397
3037.7	26.4181
3041.99	26.3621
3046.28	26.3708
3050.57	26.4002
3054.85	26.3923
3059.13	26.1638
3063.41	26.0087
3067.69	25.9423
3071.96	26.2362
3076.23	26.0712
3080.5	25.5335
3084.76	24.8368
3089.02	24.3135
3093.28	23.5323
3097.53	23.2005
3101.79	23.6922
3106.04	24.4704
3110.28	25.4037
3114.53	25.9097
3118.77	26.0722
3123.01	26.2883
3127.24	26.8682
3131.47	27.2348
3135.7	27.2556
3139.93	27.3777
3144.15	27.7874
3148.38	28.022
3152.59	27.7932
3156.81	26.4801
3161.02	26.2258
3165.23	26.4593
3169.44	27.1531
3173.64	26.9016
3177.84	26.6241
3182.04	26.3725
3186.24	26.163
3190.43	26.0139
3194.62	26.0669
3198.81	26.2447
3202.99	26.5493
3207.17	26.9983
3211.35	27.1124
3215.53	27.3231
3219.7	27.8687
3223.87	28.3495
3228.04	28.3502
3232.2	27.4001
3236.36	27.4466
3240.52	27.5097
3244.68	27.1034
3248.83	26.6241
3252.98	26.4549
3257.13	26.4495
3261.28	26.5368
3265.42	27.4053
3269.56	28.097
3273.7	28.8763
3277.83	29.0435
3281.96	29.3044
3286.09	29.3529
3290.22	29.0771
3294.34	28.6003
3298.46	28.1095
3302.58	27.8937
3306.69	28.0566
3310.8	27.7881
3314.91	27.7676
3319.02	27.7805
3323.12	27.748
3327.23	27.6841
3331.32	27.5836
3335.42	27.749
3339.51	28.1051
3343.6	27.9129
3347.69	27.5542
3351.78	27.5063
3355.86	27.55
3359.94	27.6547
3364.02	27.7399
3368.09	27.2447
3372.16	27.0212
3376.23	26.9792
3380.29	26.5394
3384.36	27.0414
3388.42	28.6597
3392.48	28.8781
3396.53	29.0194
3400.58	29.1388
3404.63	29.2225
3408.68	29.2579
3412.73	29.2458
3416.77	29.1905
3420.81	29.0324
3424.84	29.0709
3428.88	29.1549
3432.91	29.2103
3436.94	29.5953
3440.96	29.3392
3444.99	29.0448
3449.01	28.7042
3453.03	28.1412
3457.04	27.7974
3461.05	27.6321
3465.06	27.5639
3469.07	27.7628
3473.08	28.0304
3477.08	28.2848
3481.08	28.6142
3485.07	29.0681
3489.07	29.5319
3493.06	29.6569
3497.05	29.1594
3501.04	29.0398
3505.02	28.844
3509	28.5754
3512.98	28.5396
3516.96	28.8236
3520.93	29.9457
3524.9	30.503
3528.87	29.7407
3532.83	29.0094
3536.8	28.2849
3540.76	27.654
3544.71	27.1524
3548.67	27.4489
3552.62	27.7823
3556.57	28.5501
3560.52	29.4519
3564.47	29.8018
3568.41	30.0456
3572.35	30.4522
3576.29	30.6657
3580.22	30.0788
3584.15	30.4601
3588.08	30.2101
3592.01	30.1353
3595.93	30.1323
3599.85	29.9169
3603.77	30.2157
3607.69	30.6936
3611.61	30.9838
3615.52	31.1529
3619.43	31.3008
3623.33	31.2511
3627.24	31.1324
3631.14	30.939
3635.04	30.2258
3638.93	30.0993
3642.83	30.0515
3646.72	29.5347
3650.61	29.2427
3654.49	29.5283
3658.38	28.4229
3662.26	27.8704
3666.14	28.0075
3670.01	29.0286
3673.89	30.6133
3677.76	31.0029
3681.63	30.7006
3685.5	30.2561
3689.36	30.2144
3693.22	30.4642
3697.08	30.2756
3700.94	30.4029
3704.79	30.4368
3708.64	30.535
3712.49	31.0436
3716.34	31.0185
3720.18	30.7981
3724.02	31.1396
3727.86	31.6029
3731.7	31.5524
3735.53	31.1564
3739.36	30.6509
3743.19	30.2472
3747.02	30.7031
3750.84	31.0968
3754.66	31.2839
3758.48	31.1279
3762.3	31.2888
3766.12	31.5013
3769.93	31.7535
3773.74	32.0173
3777.54	32.382
3781.35	32.4095
3785.15	31.7161
3788.95	31.0425
3792.75	30.3978
3796.54	29.8304
3800.34	29.3958
3804.13	30.1794
3807.91	31.1062
3811.7	32.0605
3815.48	32.8426
3819.26	33.1557
3823.04	32.5094
3826.82	31.8175
3830.59	31.097
3834.36	31.0925
3838.13	31.3755
3841.89	31.8141
3845.66	32.7697
3849.42	33.5828
3853.18	33.6124
3856.93	32.9897
3860.69	31.8046
3864.44	30.9396
3868.19	30.5949
3871.93	30.4177
3875.68	31.3653
3879.42	31.4478
3883.16	31.5546
3886.9	32.1336
3890.63	31.8536
3894.37	31.1369
3898.1	30.8508
3901.82	30.7974
3905.55	30.8302
3909.27	30.7543
3912.99	30.3356
3916.71	30.0012
3920.43	29.9358
3924.14	31.6308
3927.85	32.3152
3931.56	32.2867
3935.27	31.7469
3938.97	30.7744
3942.67	29.6851
3946.37	30.5176
3950.07	30.4993
3953.77	30.5753
3957.46	30.7531
3961.15	30.9997
3964.84	31.2872
3968.52	31.5468
3972.2	31.762
3975.89	31.9682
3979.56	32.1658
3983.24	32.3325
3986.92	32.4534
3990.59	32.5285
3994.26	32.5365
3997.92	32.5149
3999.76	32.4764