File: Data/Raman/raw/bu19ts-coltan-reddish_zone_150 (500nm)_633nm_edge_25%_x50_vis_lwd_h100um_10sx2_01.txt
#Acq. time (s)=	10
#Accumulations=	2
#Range (cm-¹)=	100...4000
#Windows=	1
#Auto scanning=	Off
#Autofocus=	Off
#Macrospot=	Off
#AutoExposure=	Off
#Spike filter=	Multiple accum.
#Delay time (s)=	2
#Binning=	1
#Readout mode=	Signal
#DeNoise=	Standard
#ICS correction=	On
#Dark correction=	Off
#Inst. Process=	Off
#Detector Gain=	Best Dynamic
#Detector ADC=	50 kHz HS
#Detector temperature (°C)=	-60.09
#Instrument=	LabRAM HR Evol
#Detector=	SIN-EM FIVIS
#Objective=	x50_VIS_LWD
#Grating=	150 (500nm)
#ND Filter=	25%
#Laser=	633nm_Edge
#Hole=	100.021
#Temperature=	0
#Range=	Visible
#StageXY=	75x50mm Scan+
#StageZ=	Z motor
#X (µm)=	0
#Y (µm)=	0
#Z (µm)=	-51.1
#Full time(s)=	24
#Project=	20_10_27
#Sample=	BU19TS
#Site=
#Title=	BU19TS-Coltan-reddish_zone_150 (500nm)_633nm_Edge_25%_x50_VIS_LWD_H100um_10sX2
#Remark=
#Date=	27.10.2020 15:14
#Acquired=	27.10.2020 15:14:04
100.764	234.025
107.281	245.969
113.791	290.025
120.297	372.484
126.797	509.274
133.291	680.217
139.78	546.864
146.264	360.588
152.741	308.492
159.214	333.007
165.682	357.27
172.144	363.406
178.601	359.023
185.053	311.634
191.499	274.359
197.939	323.396
204.374	423.539
210.805	406.504
217.23	310.803
223.648	265.942
230.063	286.022
236.472	330.016
242.874	424.038
249.273	469.8
255.667	453.155
262.053	476.041
268.436	489.484
274.813	458.666
281.185	420.643
287.552	395.971
293.913	391.415
300.27	391.44
306.62	384.009
312.965	365.376
319.306	349.118
325.64	368.297
331.971	318.452
338.295	280.186
344.614	273.806
350.93	281.261
357.238	298.501
363.542	312.502
369.842	316.701
376.135	326.145
382.423	379.067
388.706	470.178
394.984	551.854
401.258	567.902
407.526	485.217
413.789	388.327
420.046	339.233
426.299	320.55
432.546	314.966
438.788	318.548
445.025	324.131
451.257	330.811
457.484	336.884
463.706	343.053
469.923	352
476.135	365.352
482.342	389.47
488.544	414.154
494.741	437.641
500.933	452.748
507.12	470.195
513.3	506.726
519.477	548.688
525.649	683.71
531.815	773.389
537.976	752.495
544.133	606.639
550.285	494.322
556.43	440.201
562.572	413.033
568.709	401.511
574.84	394.45
580.967	389.605
587.09	388.743
593.205	392.85
599.318	401.996
605.424	416.13
611.527	440.788
617.623	470.499
623.716	498.546
629.802	530.245
635.884	550.964
641.962	529.897
648.034	493.674
654.101	457.379
660.165	422.768
666.222	388.678
672.274	366.46
678.324	352.438
684.366	343.079
690.404	339.742
696.438	341.128
702.466	344.936
708.491	347.745
714.51	351.127
720.523	355.546
726.533	359.359
732.537	365.4
738.537	369.323
744.531	374.578
750.521	374.611
756.507	372.63
762.487	369.127
768.463	368.295
774.434	368.189
780.4	369.406
786.362	369.194
792.319	387.641
798.269	409.815
804.217	443.619
810.159	496.688
816.097	576.734
822.03	685.97
827.958	799.44
833.881	871.061
839.801	946.281
845.714	1016.99
851.624	1292.44
857.529	1801.16
863.428	2634.93
869.324	4305.79
875.215	6788.04
881.1	6836.42
886.982	3703.38
892.858	1736.08
898.73	1013.18
904.597	683.693
910.459	519.098
916.318	429.578
922.171	379.3
928.02	344.572
933.864	316.633
939.703	298.796
945.539	286.509
951.368	275.621
957.194	267.179
963.014	261.127
968.832	257.562
974.643	254.557
980.45	250.952
986.253	247.808
992.051	244.102
997.844	239.684
1003.63	234.777
1009.42	232.464
1015.2	231.769
1020.97	231.738
1026.74	232.053
1032.51	232.559
1038.27	233.217
1044.03	233.621
1049.78	234.103
1055.53	234.638
1061.27	235.853
1067.01	237.223
1072.75	236.998
1078.48	236.846
1084.2	238.275
1089.92	239.323
1095.64	239.669
1101.35	239.206
1107.06	237.951
1112.77	236.001
1118.46	233.532
1124.16	230.276
1129.85	228.245
1135.53	228.536
1141.22	229.676
1146.89	230.515
1152.56	230.741
1158.23	229.998
1163.9	227.909
1169.56	224.04
1175.21	220.903
1180.86	218.784
1186.51	217.476
1192.15	216.532
1197.78	218.424
1203.42	221.202
1209.04	223.128
1214.67	224.419
1220.29	224.398
1225.9	221.863
1231.51	219.008
1237.12	216.454
1242.72	214.305
1248.32	212.668
1253.92	211.602
1259.5	211.153
1265.09	211.266
1270.67	211.976
1276.25	213.401
1281.82	214.934
1287.39	216.057
1292.95	214.596
1298.51	214.867
1304.06	215.278
1309.61	214.301
1315.16	212.747
1320.7	210.57
1326.24	210.848
1331.77	212.4
1337.3	214.44
1342.83	216.309
1348.35	216.792
1353.86	215.904
1359.37	214.281
1364.88	212.716
1370.39	211.726
1375.89	211.263
1381.38	211.439
1386.87	212.591
1392.36	213.949
1397.84	215.446
1403.32	217.002
1408.79	218.328
1414.26	219.263
1419.73	220.095
1425.19	220.867
1430.65	221.483
1436.1	221.973
1441.55	222.346
1447	222.539
1452.44	223.437
1457.87	224.952
1463.31	225.238
1468.73	224.552
1474.16	223.657
1479.58	223.327
1484.99	223.56
1490.41	223.953
1495.81	224.346
1501.22	224.657
1506.62	224.672
1512.01	224.507
1517.4	223.746
1522.79	222.832
1528.17	223.147
1533.55	223.318
1538.93	221.977
1544.3	220.65
1549.67	219.65
1555.03	219.135
1560.39	218.98
1565.74	219.365
1571.09	220.237
1576.44	221.671
1581.78	223.051
1587.12	222.288
1592.45	220.707
1597.78	218.407
1603.11	216.298
1608.43	215.255
1613.75	215.539
1619.07	217.485
1624.38	219.888
1629.68	221.623
1634.98	223.149
1640.28	224.492
1645.58	225.725
1650.87	226.935
1656.15	228.197
1661.44	229.518
1666.71	230.536
1671.99	231.654
1677.26	232.909
1682.53	234.456
1687.79	236.438
1693.05	239.348
1698.3	242.789
1703.55	246.56
1708.8	250.796
1714.04	255.143
1719.28	259.275
1724.51	262.472
1729.75	265.094
1734.97	266.932
1740.2	267.61
1745.42	265.637
1750.63	261.36
1755.84	254.32
1761.05	245.756
1766.25	238.862
1771.45	233.779
1776.65	228.543
1781.84	224.398
1787.03	221.542
1792.21	220.012
1797.39	218.214
1802.57	216.329
1807.74	215.009
1812.91	214.233
1818.08	213.547
1823.24	212.296
1828.39	210.517
1833.55	208.58
1838.7	206.924
1843.84	206.233
1848.99	206.206
1854.12	207.048
1859.26	208.987
1864.39	211.318
1869.52	213
1874.64	213.942
1879.76	214.31
1884.87	213.71
1889.98	211.411
1895.09	209.25
1900.2	208.634
1905.3	208.717
1910.39	208.329
1915.49	208.017
1920.57	208.745
1925.66	211.018
1930.74	213.466
1935.82	214.855
1940.89	215.789
1945.96	216.406
1951.03	216.824
1956.09	215.878
1961.15	213.466
1966.21	211.204
1971.26	209.77
1976.31	211.053
1981.35	209.123
1986.39	207.652
1991.43	207.172
1996.46	207.793
2001.49	209.607
2006.52	212.609
2011.54	215.597
2016.56	217.698
2021.57	218.564
2026.58	218.019
2031.59	216.103
2036.59	214.032
2041.59	212.645
2046.59	211.662
2051.58	210.99
2056.57	210.525
2061.55	210.093
2066.54	210.659
2071.51	211.396
2076.49	212.203
2081.46	213.009
2086.43	213.298
2091.39	213.257
2096.35	213.028
2101.3	212.629
2106.26	212.047
2111.21	211.32
2116.15	210.59
2121.09	210.3
2126.03	209.437
2130.97	207.458
2135.9	204.934
2140.83	202.746
2145.75	204.421
2150.67	204.749
2155.59	205.586
2160.5	206.834
2165.41	208.227
2170.31	209.578
2175.22	210.335
2180.12	211.034
2185.01	212.304
2189.9	213.723
2194.79	214.741
2199.68	214.874
2204.56	214.944
2209.43	214.004
2214.31	210.935
2219.18	206.076
2224.05	203.06
2228.91	202.262
2233.77	202.842
2238.63	203.802
2243.48	204.532
2248.33	205.043
2253.17	205.396
2258.02	205.798
2262.86	206.35
2267.69	207.096
2272.52	208.245
2277.35	208.599
2282.18	208.562
2287	207.644
2291.82	203.214
2296.63	200.629
2301.44	202.121
2306.25	205.505
2311.05	207.104
2315.86	208.489
2320.65	208.63
2325.45	207.696
2330.24	202.603
2335.03	197.858
2339.81	194.863
2344.59	197.439
2349.37	202.63
2354.14	201.349
2358.91	201.128
2363.67	201.219
2368.44	197.36
2373.2	198.129
2377.95	199.669
2382.71	203.019
2387.46	202.725
2392.2	201.031
2396.95	199.825
2401.68	199.006
2406.42	198.758
2411.15	199.102
2415.88	199.909
2420.61	200.911
2425.33	202.023
2430.05	203.401
2434.77	204.704
2439.48	204.422
2444.19	201.604
2448.89	198.914
2453.6	196.864
2458.29	196.188
2462.99	194.988
2467.68	194.51
2472.37	195.377
2477.06	196.868
2481.74	197.353
2486.42	196.675
2491.1	196.551
2495.77	197.29
2500.44	196.664
2505.1	194.935
2509.76	193.91
2514.42	193.005
2519.08	192.839
2523.73	193.866
2528.38	195.142
2533.03	195.815
2537.67	196.057
2542.31	195.965
2546.95	195.634
2551.58	195.184
2556.21	194.616
2560.84	193.996
2565.46	193.681
2570.08	193.327
2574.7	192.993
2579.31	192.028
2583.92	189.854
2588.53	187.611
2593.13	186.735
2597.73	187.399
2602.33	189.526
2606.92	191.544
2611.51	193.118
2616.1	194.132
2620.68	191.669
2625.26	188.811
2629.84	187.884
2634.42	184.766
2638.99	182.856
2643.56	182.605
2648.12	183.207
2652.68	184.285
2657.24	185.138
2661.8	186.02
2666.35	186.479
2670.9	185.813
2675.45	184.252
2679.99	183.858
2684.53	183.652
2689.06	183.26
2693.6	182.655
2698.13	181.805
2702.66	180.815
2707.18	179.614
2711.7	178.28
2716.22	176.964
2720.73	175.733
2725.24	174.998
2729.75	175.54
2734.26	177.385
2738.76	178.189
2743.25	177.373
2747.75	176.401
2752.24	175.556
2756.73	173.705
2761.22	171.824
2765.7	170.694
2770.18	170.101
2774.66	170.547
2779.13	172.006
2783.6	173.665
2788.07	175.051
2792.53	175.76
2797	175.62
2801.45	175.023
2805.91	174.334
2810.36	173.689
2814.81	173.408
2819.26	173.183
2823.7	173.314
2828.14	173.496
2832.57	173.402
2837.01	172.921
2841.44	172.088
2845.87	170.808
2850.29	169.516
2854.71	168.269
2859.13	167.147
2863.55	165.959
2867.96	166.382
2872.37	167.691
2876.77	168.747
2881.18	169.295
2885.58	169.358
2889.97	168.899
2894.37	167.825
2898.76	166.497
2903.15	165.052
2907.53	163.917
2911.91	164.054
2916.29	164.978
2920.67	165.81
2925.04	168.02
2929.41	169.043
2933.78	168.709
2938.14	167.156
2942.5	165.149
2946.86	163.476
2951.22	162.024
2955.57	161.071
2959.92	160.649
2964.26	161.325
2968.61	162.303
2972.95	163.306
2977.28	164.22
2981.62	163.69
2985.95	162.696
2990.28	161.291
2994.6	159.868
2998.93	158.523
3003.25	157.907
3007.56	157.63
3011.88	157.793
3016.19	158.366
3020.49	159.443
3024.8	161.064
3029.1	162.502
3033.4	162.15
3037.7	161.977
3041.99	161.65
3046.28	160.82
3050.57	158.295
3054.85	155.614
3059.13	153.957
3063.41	153.412
3067.69	153.529
3071.96	154.423
3076.23	155.453
3080.5	156.547
3084.76	157.384
3089.02	158.099
3093.28	158.55
3097.53	158.605
3101.79	158.433
3106.04	157.997
3110.28	157.433
3114.53	156.751
3118.77	156.045
3123.01	155.147
3127.24	154.292
3131.47	153.495
3135.7	152.72
3139.93	151.882
3144.15	151.437
3148.38	151.174
3152.59	151.322
3156.81	151.621
3161.02	151.93
3165.23	152.226
3169.44	152.488
3173.64	152.422
3177.84	152.299
3182.04	152.013
3186.24	151.414
3190.43	150.919
3194.62	150.671
3198.81	149.641
3202.99	146.65
3207.17	145.168
3211.35	144.146
3215.53	146.437
3219.7	146.534
3223.87	146.569
3228.04	147.639
3232.2	149.119
3236.36	150.226
3240.52	151.251
3244.68	152.43
3248.83	154.4
3252.98	155.14
3257.13	154.515
3261.28	153.083
3265.42	151.222
3269.56	149.319
3273.7	147.493
3277.83	145.791
3281.96	144.683
3286.09	143.895
3290.22	143.386
3294.34	143.038
3298.46	142.792
3302.58	142.497
3306.69	141.605
3310.8	140.865
3314.91	140.592
3319.02	143.207
3323.12	145.739
3327.23	146.651
3331.32	147.162
3335.42	146.968
3339.51	146.199
3343.6	145.058
3347.69	143.779
3351.78	142.973
3355.86	143.392
3359.94	144.36
3364.02	144.035
3368.09	143.432
3372.16	143.188
3376.23	142.948
3380.29	142.953
3384.36	142.684
3388.42	141.853
3392.48	139.533
3396.53	137.824
3400.58	136.876
3404.63	136.471
3408.68	136.891
3412.73	138.246
3416.77	139.909
3420.81	141.665
3424.84	143.141
3428.88	144.274
3432.91	145.152
3436.94	144.374
3440.96	143.176
3444.99	142.136
3449.01	142.244
3453.03	142.86
3457.04	138.308
3461.05	132.834
3465.06	131.562
3469.07	132.823
3473.08	134.503
3477.08	136.466
3481.08	137.799
3485.07	134.655
3489.07	136.259
3493.06	137.084
3497.05	135.362
3501.04	133.928
3505.02	132.542
3509	133.843
3512.98	132.827
3516.96	133
3520.93	131.512
3524.9	129.611
3528.87	129.232
3532.83	129.841
3536.8	131.746
3540.76	133.576
3544.71	134.813
3548.67	135.512
3552.62	135.725
3556.57	135.275
3560.52	134.189
3564.47	133.167
3568.41	132.684
3572.35	132.978
3576.29	134.425
3580.22	133.947
3584.15	131.561
3588.08	130.947
3592.01	131.708
3595.93	129.655
3599.85	128.085
3603.77	127.433
3607.69	129.03
3611.61	131.392
3615.52	133.102
3619.43	133.646
3623.33	133.048
3627.24	132.339
3631.14	131.499
3635.04	130.643
3638.93	129.639
3642.83	128.354
3646.72	127.143
3650.61	127.313
3654.49	128.601
3658.38	128.688
3662.26	128.774
3666.14	128.996
3670.01	129.313
3673.89	129.773
3677.76	130.208
3681.63	130.585
3685.5	127.816
3689.36	125.36
3693.22	124.093
3697.08	123.015
3700.94	122.01
3704.79	121.35
3708.64	120.774
3712.49	120.272
3716.34	120.765
3720.18	122.049
3724.02	124.08
3727.86	126.731
3731.7	126.792
3735.53	126.49
3739.36	125.684
3743.19	124.672
3747.02	123.989
3750.84	123.457
3754.66	122.326
3758.48	120.945
3762.3	120.713
3766.12	121.373
3769.93	120.556
3773.74	119.203
3777.54	118.736
3781.35	118.425
3785.15	117.809
3788.95	117.103
3792.75	116.162
3796.54	114.837
3800.34	113.847
3804.13	113.814
3807.91	114.396
3811.7	116.12
3815.48	118.224
3819.26	120.236
3823.04	121.91
3826.82	123.005
3830.59	119.924
3834.36	117.917
3838.13	115.973
3841.89	113.759
3845.66	113.457
3849.42	114.305
3853.18	115.353
3856.93	116.471
3860.69	115.479
3864.44	114.481
3868.19	114.636
3871.93	114.898
3875.68	115.242
3879.42	115.587
3883.16	115.12
3886.9	115.46
3890.63	114.892
3894.37	113.776
3898.1	112.93
3901.82	113.361
3905.55	112.803
3909.27	112.678
3912.99	113.206
3916.71	113.168
3920.43	113.058
3924.14	113.37
3927.85	112.578
3931.56	112.668
3935.27	112.726
3938.97	112.13
3942.67	112.215
3946.37	111.968
3950.07	110.871
3953.77	109.37
3957.46	108.623
3961.15	107.706
3964.84	106.709
3968.52	106.035
3972.2	104.232
3975.89	102.555
3979.56	101.826
3983.24	102.076
3986.92	103.116
3990.59	104.92
3994.26	106.153
3997.92	106.691
3999.76	106.227