File: Data/Raman/raw/bu19w-area6-ore2_150 (500nm)_532nm_edge_5%_x100_vis_h100um_10sx2_01.txt
#Acq. time (s)=	10
#Accumulations=	2
#Range (cm-¹)=	50...5000
#Windows=	1
#Auto scanning=	Off
#Autofocus=	Off
#Macrospot=	Off
#AutoExposure=	Off
#Spike filter=	Multiple accum.
#Delay time (s)=	1
#Binning=	1
#Readout mode=	Signal
#DeNoise=	Standard
#ICS correction=	On
#Dark correction=	Off
#Inst. Process=	Off
#Detector Gain=	Best Dynamic
#Detector ADC=	50 kHz HS
#Detector temperature (°C)=	-60.09
#Instrument=	LabRAM HR Evol
#Detector=	SIN-EM FIVIS
#Objective=	x100_VIS
#Grating=	150 (500nm)
#ND Filter=	5%
#Laser=	532nm_Edge
#Hole=	100.021
#Temperature=	0
#Range=	Visible
#StageXY=	75x50mm Scan+
#StageZ=	Z motor
#X (µm)=	0
#Y (µm)=	0
#Z (µm)=	-13.8
#Full time(s)=	31
#Project=	20_10_20
#Sample=	BU19w
#Site=
#Title=	BU19w-Area6-ore2_150 (500nm)_532nm_Edge_5%_x100_VIS_H100um_10sX2
#Remark=
#Date=	20.10.2020 17:35
#Acquired=	20.10.2020 17:35:21
53.4439	1589.99
58.0898	1595.96
62.7335	1777.57
67.3748	1954.38
72.0117	2126.38
76.6485	2279.61
81.283	2419.89
85.9151	2553.63
90.545	2663.96
95.1704	2739.58
99.7957	2795.4
104.419	2835.82
109.039	2858.34
113.658	2868.39
118.272	2853.83
122.886	2826.36
127.497	2797.2
132.107	2760.25
136.712	2674.47
141.316	2566.16
145.919	2461.75
150.519	2343.93
155.115	2277.63
159.711	2286.54
164.304	2305.65
168.895	2338.08
173.482	2379.93
178.069	2435.88
182.653	2495.09
187.233	2558.03
191.813	2613.28
196.39	2661.58
200.966	2704.55
205.537	2742.18
210.107	2775.66
214.676	2813.24
219.24	2860.66
223.804	2913.93
228.366	2964.79
232.924	3009.32
237.481	3036.8
242.036	3046.59
246.587	3041.11
251.138	3021.68
255.686	2993.43
260.23	2978.96
264.774	2943.85
269.314	2899.59
273.854	2866.04
278.391	2837.21
282.924	2825.47
287.457	2827.9
291.985	2835.26
296.514	2839.27
301.04	2860.89
305.562	2805.05
310.084	2704.97
314.601	2633.25
319.118	2593.89
323.634	2583.24
328.144	2585.73
332.655	2602.06
337.162	2647.78
341.668	2665.5
346.17	2683.8
350.672	2704.7
355.17	2725.4
359.667	2756.76
364.163	2792
368.654	2846.8
373.145	2923.66
377.631	3019.71
382.118	3129.8
386.6	3273.09
391.082	3443.97
395.56	3644.7
400.038	3871.44
404.512	4106.01
408.985	4287.9
413.455	4448.88
417.924	4561.16
422.389	4644.77
426.854	4679.9
431.314	4659.1
435.773	4601.12
440.231	4459.25
444.685	4296.04
449.139	4101.4
453.589	3943.38
458.038	3814.57
462.484	3722.42
466.929	3637.69
471.37	3559.07
475.809	3484.3
480.248	3429.5
484.683	3368.56
489.117	3306.29
493.548	3256.08
497.976	3198.11
502.404	3148.2
506.828	3100.65
511.252	3062.55
515.672	3032.66
520.089	3011.31
524.507	3001.45
528.92	3003.94
533.331	3021.78
537.742	3054.01
542.149	3100.81
546.554	3164.27
550.958	3243.45
555.359	3361.34
559.757	3494.05
564.155	3645.03
568.549	3809.51
572.942	4000.28
577.333	4210.11
581.721	4436.08
586.107	4678.03
590.492	4945.68
594.874	5239.36
599.253	5549.97
603.632	5845.19
608.008	6086.55
612.381	6206.67
616.752	6085.08
621.122	5918.31
625.489	5717.74
629.854	5489.44
634.216	5277.84
638.579	5080.02
642.937	4887.46
647.293	4681.37
651.647	4487.97
656.001	4281.95
660.351	4055.79
664.699	3841.49
669.045	3644.07
673.389	3460.48
677.732	3291.28
682.072	3134.56
686.409	3017.87
690.745	2901.38
695.078	2790.69
699.411	2686.3
703.74	2588.46
708.067	2497.09
712.392	2412.56
716.715	2334.82
721.036	2263.57
725.357	2199.14
729.674	2141.24
733.989	2090.43
738.301	2045.6
742.612	2007.67
746.92	1976.5
751.227	1953.32
755.533	1933.52
759.835	1921.77
764.136	1918.27
768.434	1920.47
772.73	1928.01
777.024	1938.95
781.316	1947.25
785.606	1959.58
789.894	1955.78
794.18	1965.13
798.464	1982.08
802.748	1997.78
807.028	2011.5
811.306	2019.98
815.582	2024.81
819.855	2024.49
824.127	2018.55
828.397	2003.91
832.664	1977.6
836.93	1935.18
841.194	1873.69
845.455	1793.33
849.715	1706.69
853.972	1615.21
858.228	1516.49
862.481	1404.84
866.733	1305.63
870.982	1242.41
875.23	1182.23
879.475	1135.34
883.718	1098.68
887.96	1067.7
892.199	1038.73
896.437	1011.64
900.672	988.736
904.905	970.004
909.137	953.829
913.366	940.72
917.591	929.925
921.817	920.076
926.04	910.987
930.262	901.174
934.481	892.808
938.698	885.441
942.914	878.908
947.127	871.416
951.339	865.724
955.548	857.575
959.755	851.952
963.959	846.357
968.163	842.044
972.364	838.25
976.564	833.735
980.761	827.592
984.957	820.373
989.15	812.276
993.34	803.257
997.53	795.716
1001.72	788.589
1005.9	781.285
1010.09	774.284
1014.27	767.422
1018.45	761.218
1022.62	755.563
1026.8	750.305
1030.97	744.805
1035.15	739.539
1039.31	734.717
1043.48	730.436
1047.65	726.645
1051.81	723.337
1055.97	720.286
1060.13	717.285
1064.29	713.609
1068.45	710.04
1072.6	706.874
1076.75	704.057
1080.9	701.819
1085.05	699.877
1089.2	698.359
1093.34	696.868
1097.48	693.987
1101.62	692.349
1105.76	689.861
1109.9	688.243
1114.03	687.185
1118.17	686.533
1122.29	686.017
1126.42	685.666
1130.55	685.223
1134.67	684.94
1138.8	684.256
1142.92	682.608
1147.04	681.297
1151.15	679.729
1155.27	677.902
1159.38	675.143
1163.49	673.241
1167.6	671.235
1171.71	669.081
1175.82	666.682
1179.92	664.123
1184.02	661.487
1188.12	658.799
1192.22	655.78
1196.31	652.918
1200.41	650.357
1204.5	648.696
1208.59	647.633
1212.68	646.937
1216.76	646.297
1220.85	645.417
1224.93	644.472
1229.01	643.952
1233.09	643.755
1237.17	643.539
1241.24	643.161
1245.31	643.095
1249.38	642.927
1253.45	642.524
1257.52	641.398
1261.59	641.111
1265.65	641.762
1269.71	643.524
1273.77	644.358
1277.83	644.739
1281.88	645.008
1285.94	645.104
1289.99	644.918
1294.04	643.762
1298.09	642.162
1302.14	640.261
1306.18	638.119
1310.22	636.03
1314.26	633.67
1318.3	631.337
1322.34	628.86
1326.37	626.446
1330.41	623.16
1334.44	619.585
1338.47	616.112
1342.5	612.877
1346.52	609.817
1350.55	606.943
1354.57	604.274
1358.59	601.864
1362.61	599.752
1366.62	597.835
1370.64	596.252
1374.65	594.686
1378.66	593.581
1382.67	593.695
1386.68	593.971
1390.68	593.922
1394.69	593.437
1398.69	592.505
1402.69	591.355
1406.68	590.151
1410.68	588.981
1414.68	586.374
1418.67	586.133
1422.66	586.179
1426.65	585.839
1430.63	585.414
1434.62	584.165
1438.6	584.241
1442.58	584.792
1446.56	585.759
1450.54	586.936
1454.52	588.294
1458.49	590.124
1462.46	591.49
1466.43	592.207
1470.4	592.373
1474.37	591.681
1478.33	590.74
1482.3	589.811
1486.26	588.951
1490.22	588.053
1494.17	587.138
1498.13	586.113
1502.08	584.988
1506.04	583.58
1509.99	581.841
1513.93	579.742
1517.88	577.388
1521.83	574.985
1525.77	572.675
1529.71	570.513
1533.65	568.73
1537.59	567.662
1541.52	567.034
1545.46	567.679
1549.39	568.75
1553.32	569.469
1557.25	570.019
1561.17	570.62
1565.1	571.283
1569.02	572.896
1572.94	573.044
1576.86	572.916
1580.78	572.405
1584.7	571.509
1588.61	570.098
1592.52	568.218
1596.43	566.023
1600.34	563.482
1604.25	560.787
1608.16	558.264
1612.06	556.031
1615.96	552.365
1619.86	551.725
1623.76	556.524
1627.66	555.632
1631.55	552.598
1635.44	545.247
1639.33	540.572
1643.22	537.107
1647.11	534.728
1651	533.782
1654.88	531.414
1658.76	529.751
1662.64	527.746
1666.52	524.55
1670.4	520.601
1674.27	516.024
1678.15	510.52
1682.02	506.454
1685.89	502.711
1689.76	498.705
1693.62	494.571
1697.49	490.399
1701.35	486.194
1705.21	482.148
1709.07	478.503
1712.93	475.327
1716.78	474.052
1720.64	472.134
1724.49	469.318
1728.34	466.366
1732.19	463.489
1736.04	460.798
1739.88	458.301
1743.73	455.896
1747.57	453.497
1751.41	451.29
1755.25	449.15
1759.08	447.166
1762.92	445.258
1766.75	443.281
1770.58	440.866
1774.41	440.028
1778.24	440.141
1782.06	441.002
1785.89	441.624
1789.71	442.172
1793.53	442.562
1797.35	442.652
1801.17	442.566
1804.99	442.312
1808.8	441.843
1812.61	441.072
1816.42	439.947
1820.23	438.206
1824.04	435.846
1827.85	432.991
1831.65	430.412
1835.45	428.569
1839.25	426.961
1843.05	425.675
1846.85	424.227
1850.64	423.051
1854.44	422.208
1858.23	421.703
1862.02	421.519
1865.81	421.684
1869.59	422.052
1873.38	422.555
1877.16	423.262
1880.94	423.96
1884.72	424.584
1888.5	425.148
1892.28	425.413
1896.05	425.294
1899.82	424.893
1903.6	424.342
1907.36	423.209
1911.13	421.894
1914.9	420.52
1918.66	419.262
1922.43	418.416
1926.19	417.706
1929.95	417.255
1933.71	417.243
1937.46	417.677
1941.22	417.997
1944.97	417.476
1948.72	416.198
1952.47	414.877
1956.22	413.59
1959.96	412.931
1963.71	412.477
1967.45	412.395
1971.19	412.471
1974.93	412.564
1978.67	412.45
1982.41	412.085
1986.14	411.561
1989.87	410.855
1993.6	410.708
1997.33	411.053
2001.06	410.949
2004.79	410.764
2008.51	410.508
2012.23	410.149
2015.96	409.438
2019.67	408.711
2023.39	407.991
2027.11	407.382
2030.82	407.163
2034.54	407.202
2038.25	407.574
2041.96	407.802
2045.66	407.645
2049.37	406.685
2053.07	405.297
2056.78	403.337
2060.48	400.644
2064.18	397.796
2067.88	395.275
2071.57	393.072
2075.27	391.171
2078.96	389.348
2082.65	387.982
2086.34	387.176
2090.03	387.236
2093.72	387.417
2097.4	387.905
2101.08	388.389
2104.77	388.366
2108.44	388.717
2112.12	389.481
2115.8	390.129
2119.47	390.641
2123.15	390.869
2126.82	391.009
2130.49	390.89
2134.16	390.792
2137.83	390.536
2141.49	390.113
2145.15	389.514
2148.82	388.691
2152.48	387.255
2156.14	385.761
2159.79	384.227
2163.45	382.899
2167.1	381.383
2170.75	379.814
2174.4	378.623
2178.05	377.569
2181.7	376.776
2185.35	376.299
2188.99	375.745
2192.64	375.125
2196.28	374.722
2199.91	374.364
2203.55	373.943
2207.19	373.498
2210.82	372.266
2214.46	371.316
2218.09	370.401
2221.72	369.941
2225.35	369.594
2228.97	369.247
2232.6	368.865
2236.22	368.473
2239.84	367.896
2243.46	367.187
2247.08	366.441
2250.7	365.542
2254.31	364.586
2257.93	363.415
2261.54	362.158
2265.15	360.828
2268.76	359.434
2272.37	357.997
2275.97	356.492
2279.58	355.045
2283.18	354.301
2286.78	354.558
2290.38	355.13
2293.98	355.428
2297.57	355.531
2301.17	356.589
2304.76	357.535
2308.35	358.116
2311.94	358.481
2315.53	358.519
2319.12	358.409
2322.71	358.269
2326.29	358.073
2329.87	356.097
2333.45	355.124
2337.03	354.115
2340.61	352.732
2344.19	351.23
2347.76	348.855
2351.33	346.603
2354.9	344.902
2358.47	343.798
2362.04	342.933
2365.61	343.004
2369.17	341.578
2372.74	344.352
2376.3	349.992
2379.86	360.775
2383.42	345.065
2386.98	337.141
2390.53	333.222
2394.09	332.849
2397.64	333.884
2401.19	334.83
2404.74	335.422
2408.29	336.022
2411.83	336.413
2415.38	336.897
2418.92	335.857
2422.46	335.691
2426	335.58
2429.54	335.695
2433.08	335.738
2436.62	335.99
2440.15	335.584
2443.68	335.037
2447.21	334.311
2450.74	333.498
2454.27	332.652
2457.8	331.722
2461.32	330.819
2464.85	330.083
2468.37	329.388
2471.89	328.641
2475.41	327.899
2478.92	327.121
2482.44	326.484
2485.95	325.658
2489.47	324.888
2492.98	324.211
2496.49	324.177
2499.99	324.433
2503.5	325.012
2507.01	325.756
2510.51	326.792
2514.01	327.469
2517.51	327.244
2521.01	326.873
2524.51	326.4
2528.01	325.967
2531.5	325.551
2534.99	324.935
2538.49	324.043
2541.97	322.044
2545.46	320.002
2548.95	318.045
2552.44	316.214
2555.92	314.599
2559.4	313.2
2562.88	312.117
2566.36	311.284
2569.84	310.813
2573.32	310.838
2576.79	311.031
2580.26	310.875
2583.74	310.69
2587.21	310.594
2590.68	310.582
2594.14	310.158
2597.61	309.583
2601.07	308.814
2604.54	307.959
2608	307.193
2611.46	306.493
2614.92	306.108
2618.37	305.739
2621.83	305.419
2625.28	305.169
2628.73	304.993
2632.19	304.782
2635.64	304.643
2639.08	304.481
2642.53	304.283
2645.98	303.921
2649.42	303.496
2652.86	302.973
2656.3	302.326
2659.74	301.421
2663.18	300.346
2666.61	299.1
2670.05	297.883
2673.48	296.593
2676.92	295.647
2680.35	295.072
2683.77	294.483
2687.2	293.867
2690.63	292.362
2694.05	291.662
2697.48	291.558
2700.9	292.419
2704.32	293.482
2707.74	294.354
2711.15	294.97
2714.57	295.349
2717.98	295.706
2721.4	296.01
2724.81	296.112
2728.22	295.788
2731.63	295.234
2735.03	294.581
2738.44	293.647
2741.84	292.357
2745.25	289.847
2748.65	288.816
2752.05	287.984
2755.44	287.193
2758.84	286.382
2762.24	285.589
2765.63	284.817
2769.02	284.064
2772.41	283.239
2775.8	282.356
2779.19	281.588
2782.58	280.342
2785.96	279.143
2789.35	277.91
2792.73	276.752
2796.11	275.678
2799.49	274.73
2802.87	274.707
2806.25	274.903
2809.62	275.222
2812.99	275.608
2816.37	276.062
2819.74	276.551
2823.11	276.687
2826.47	276.995
2829.84	277.267
2833.21	277.521
2836.57	277.757
2839.93	277.937
2843.29	278.043
2846.65	278.134
2850.01	278.131
2853.37	278.13
2856.72	278.051
2860.08	277.953
2863.43	277.782
2866.78	277.572
2870.13	277.265
2873.48	276.914
2876.82	276.495
2880.17	275.987
2883.51	274.928
2886.85	273.667
2890.2	272.088
2893.53	270.339
2896.87	268.529
2900.21	266.456
2903.55	264.502
2906.88	262.869
2910.21	261.925
2913.54	261.246
2916.87	260.786
2920.2	260.355
2923.53	259.878
2926.85	259.381
2930.18	258.911
2933.5	259.06
2936.82	258.969
2940.14	258.441
2943.46	257.679
2946.78	256.597
2950.09	255.114
2953.41	253.167
2956.72	252.586
2960.03	251.601
2963.34	250.928
2966.65	250.414
2969.96	251.155
2973.26	252.321
2976.57	253.589
2979.87	254.843
2983.17	255.777
2986.47	256.635
2989.77	257.307
2993.07	257.854
2996.36	258.184
2999.66	258.377
3002.95	258.275
3006.25	258.021
3009.54	257.573
3012.83	256.815
3016.11	255.926
3019.4	254.938
3022.69	254.492
3025.97	254.199
3029.25	254.388
3032.53	254.677
3035.81	254.979
3039.09	254.104
3042.37	253.031
3045.64	251.916
3048.92	250.782
3052.19	249.745
3055.46	248.724
3058.73	247.78
3062	246.87
3065.27	246.243
3068.53	245.755
3071.8	245.357
3075.06	245.017
3078.32	244.746
3081.58	244.499
3084.84	244.281
3088.1	244.07
3091.36	243.818
3094.61	243.592
3097.86	243.255
3101.12	242.649
3104.37	242.013
3107.62	241.254
3110.87	240.329
3114.11	239.383
3117.36	237.819
3120.6	235.83
3123.84	234.008
3127.09	232.529
3130.33	231.134
3133.57	229.909
3136.8	229.431
3140.04	229.05
3143.27	228.827
3146.51	228.677
3149.74	228.626
3152.97	228.649
3156.2	228.678
3159.43	228.513
3162.65	228.481
3165.88	228.061
3169.1	228.142
3172.33	228.174
3175.55	228.226
3178.77	228.265
3181.99	228.296
3185.2	228.313
3188.42	228.321
3191.63	228.315
3194.85	228.296
3198.06	228.236
3201.27	228.127
3204.48	227.963
3207.69	227.757
3210.89	227.519
3214.1	227.003
3217.3	226.614
3220.5	226.098
3223.71	225.606
3226.91	225.061
3230.1	224.489
3233.3	223.937
3236.5	223.308
3239.69	222.605
3242.89	221.896
3246.08	221.113
3249.27	220.43
3252.46	219.521
3255.65	218.614
3258.83	217.681
3262.02	216.748
3265.2	215.822
3268.39	214.892
3271.57	214.003
3274.75	213.106
3277.93	212.397
3281.1	211.67
3284.28	210.995
3287.46	210.69
3290.63	210.396
3293.8	210.305
3296.97	210.415
3300.14	210.428
3303.31	210.499
3306.48	210.564
3309.64	210.64
3312.81	210.72
3315.97	210.778
3319.13	210.81
3322.29	210.486
3325.45	210.237
3328.61	209.949
3331.77	209.615
3334.92	209.221
3338.08	208.756
3341.23	208.061
3344.38	207.38
3347.53	206.578
3350.68	205.734
3353.83	204.911
3356.97	204.101
3360.12	203.452
3363.26	202.819
3366.4	202.692
3369.55	202.751
3372.69	202.756
3375.83	202.79
3378.96	202.785
3382.1	202.752
3385.23	202.635
3388.37	202.454
3391.5	202.252
3394.63	202.079
3397.76	201.74
3400.89	201.325
3404.01	200.881
3407.14	200.404
3410.27	199.749
3413.39	199.024
3416.51	198.299
3419.63	197.553
3422.75	196.797
3425.87	196.034
3428.98	195.286
3432.1	194.527
3435.21	193.778
3438.33	193.024
3441.44	192.312
3444.55	191.628
3447.66	191.104
3450.77	190.701
3453.87	190.262
3456.98	189.83
3460.08	189.484
3463.19	189.201
3466.29	189.004
3469.39	188.814
3472.49	188.661
3475.58	188.511
3478.68	188.557
3481.78	188.583
3484.87	188.662
3487.96	188.72
3491.05	188.784
3494.14	188.795
3497.23	188.715
3500.32	188.576
3503.41	188.319
3506.49	187.813
3509.58	187.224
3512.66	186.523
3515.74	185.576
3518.82	184.403
3521.9	183.191
3524.98	181.935
3528.05	180.833
3531.13	179.877
3534.2	179.687
3537.28	179.508
3540.35	179.471
3543.42	179.608
3546.49	179.871
3549.55	180.114
3552.62	180.775
3555.69	181.431
3558.75	181.968
3561.81	182.465
3564.87	182.683
3567.93	182.283
3570.99	181.785
3574.05	181.073
3577.11	179.981
3580.16	178.827
3583.22	177.702
3586.27	176.655
3589.32	176.243
3592.37	176.062
3595.42	176.644
3598.47	177.257
3601.51	177.896
3604.56	178.313
3607.6	178.648
3610.65	178.77
3613.69	178.795
3616.73	178.562
3619.77	178.168
3622.81	177.587
3625.84	176.72
3628.88	175.739
3631.91	174.621
3634.95	173.443
3637.98	172.234
3641.01	171.052
3644.04	170.183
3647.07	169.632
3650.09	169.147
3653.12	169.03
3656.14	169.128
3659.17	169.313
3662.19	169.514
3665.21	169.712
3668.23	169.898
3671.25	170.054
3674.27	170.041
3677.28	169.837
3680.3	169.449
3683.31	168.977
3686.32	168.167
3689.33	167.34
3692.34	166.483
3695.35	165.577
3698.36	164.712
3701.37	163.863
3704.37	163.154
3707.38	162.84
3710.38	162.595
3713.38	162.513
3716.38	162.635
3719.38	162.921
3722.38	163.367
3725.37	163.871
3728.37	164.737
3731.36	165.181
3734.36	164.426
3737.35	163.712
3740.34	162.417
3743.33	161.093
3746.32	159.919
3749.31	158.929
3752.29	158.072
3755.28	157.352
3758.26	156.902
3761.24	156.583
3764.22	156.593
3767.2	156.717
3770.18	157.435
3773.16	157.231
3776.14	156.734
3779.11	156.334
3782.09	155.94
3785.06	155.575
3788.03	155.214
3791	154.897
3793.97	154.54
3796.94	154.245
3799.91	153.887
3802.87	153.728
3805.84	153.625
3808.8	153.52
3811.76	153.442
3814.72	153.366
3817.68	153.297
3820.64	153.221
3823.6	153.141
3826.55	153.057
3829.51	152.948
3832.46	152.835
3835.42	152.674
3838.37	152.49
3841.32	152.288
3844.27	152.033
3847.22	151.653
3850.16	150.937
3853.11	150.303
3856.05	149.602
3859	148.875
3861.94	148.135
3864.88	147.435
3867.82	146.711
3870.76	146.198
3873.7	145.63
3876.63	145.904
3879.57	146.121
3882.5	146.39
3885.43	146.659
3888.37	147.032
3891.3	147.394
3894.23	147.762
3897.15	147.625
3900.08	146.875
3903.01	146.195
3905.93	145.639
3908.86	145.214
3911.78	144.908
3914.7	145.179
3917.62	145.575
3920.54	145.68
3923.46	145.22
3926.37	144.772
3929.29	144.322
3932.2	143.844
3935.12	143.392
3938.03	143.076
3940.94	142.674
3943.85	142.295
3946.76	141.824
3949.66	141.426
3952.57	140.891
3955.48	140.48
3958.38	139.767
3961.28	139.082
3964.18	138.366
3967.08	137.726
3969.98	137.088
3972.88	136.645
3975.78	136.291
3978.68	136.619
3981.57	137.053
3984.47	137.397
3987.36	137.761
3990.25	138.081
3993.14	138.338
3996.03	138.585
3998.92	138.561
4001.8	138.427
4004.69	138.11
4007.57	137.581
4010.46	137.08
4013.34	136.316
4016.22	135.548
4019.1	134.737
4021.98	133.974
4024.86	133.318
4027.73	132.706
4030.61	132.79
4033.48	132.875
4036.36	133.138
4039.23	133.511
4042.1	133.909
4044.97	134.303
4047.84	134.61
4050.71	134.954
4053.57	135.058
4056.44	135.065
4059.3	135.094
4062.17	135.024
4065.03	135.123
4067.89	134.963
4070.75	133.105
4073.61	132.217
4076.47	132.156
4079.32	131.396
4082.18	130.053
4085.03	128.828
4087.88	127.763
4090.74	126.898
4093.59	126.192
4096.44	125.663
4099.29	125.703
4102.13	125.989
4104.98	126.337
4107.82	126.725
4110.67	126.981
4113.51	127.219
4116.35	127.439
4119.19	127.608
4122.03	127.692
4124.87	127.829
4127.71	127.458
4130.55	127.093
4133.38	126.603
4136.22	126.119
4139.05	125.533
4141.88	124.987
4144.71	124.456
4147.54	124.023
4150.37	123.573
4153.2	123.7
4156.02	123.839
4158.85	124
4161.67	124.191
4164.5	124.353
4167.32	124.514
4170.14	124.662
4172.96	124.761
4175.78	124.67
4178.6	124.53
4181.41	124.231
4184.23	123.648
4187.04	122.814
4189.86	121.929
4192.67	121.009
4195.48	120.106
4198.29	119.224
4201.1	118.344
4203.91	117.59
4206.71	117.285
4209.52	117.124
4212.32	117.06
4215.13	117.447
4217.93	117.908
4220.73	118.345
4223.53	118.844
4226.33	119.189
4229.13	119.407
4231.92	119.12
4234.72	118.795
4237.52	118.427
4240.31	117.981
4243.1	117.491
4245.89	116.966
4248.68	116.44
4251.47	115.881
4254.26	115.342
4257.05	114.796
4259.83	114.365
4262.62	113.955
4265.4	113.543
4268.19	113.149
4270.97	112.799
4273.75	112.494
4276.53	112.204
4279.31	111.987
4282.08	111.836
4284.86	111.697
4287.64	111.706
4290.41	111.779
4293.19	111.938
4295.96	112.44
4298.73	112.749
4301.5	113.086
4304.27	111.321
4307.04	110.38
4309.8	109.703
4312.57	109.734
4315.33	110.215
4318.1	110.88
4320.86	111.628
4323.62	112.166
4326.38	112.573
4329.14	112.63
4331.9	111.976
4334.66	111.781
4337.41	111.668
4340.17	111.603
4342.92	111.573
4345.67	111.014
4348.43	110.635
4351.18	110.426
4353.93	110.339
4356.68	109.905
4359.42	109.484
4362.17	109.117
4364.92	108.807
4367.66	108.482
4370.4	108.144
4373.15	107.832
4375.89	107.52
4378.63	107.298
4381.37	107.047
4384.11	106.952
4386.84	106.7
4389.58	106.927
4392.31	107.22
4395.05	107.663
4397.78	108.048
4400.51	108.388
4403.24	108.703
4405.97	108.948
4408.7	109.142
4411.43	109.054
4414.16	109.01
4416.88	108.76
4419.61	108.512
4422.33	107.828
4425.05	107.439
4427.78	106.789
4430.5	106.197
4433.22	105.7
4435.93	105.526
4438.65	105.871
4441.37	106.003
4444.08	106.146
4446.8	106.059
4449.51	105.929
4452.22	105.595
4454.93	105.327
4457.64	104.916
4460.35	104.515
4463.06	104.07
4465.77	103.64
4468.47	103.198
4471.18	102.761
4473.88	102.35
4476.59	101.926
4479.29	101.608
4481.99	101.259
4484.69	101.08
4487.39	101.048
4490.08	101.09
4492.78	101.096
4495.48	101.286
4498.17	101.533
4500.87	101.92
4503.56	102.168
4506.25	102.382
4508.94	102.138
4511.63	101.065
4514.32	100.117
4517.01	99.2838
4519.69	98.8649
4522.38	98.4822
4525.06	98.6305
4527.75	98.3905
4530.43	98.1795
4533.11	98.0038
4535.79	97.2255
4538.47	95.264
4541.15	93.9292
4543.82	93.7717
4546.5	94.9202
4549.18	95.4603
4551.85	95.863
4554.52	96.1228
4557.2	96.3354
4559.87	96.3924
4562.54	96.4373
4565.21	96.3241
4567.87	96.2184
4570.54	96.1363
4573.21	96.074
4575.87	96.0248
4578.54	96.0099
4581.2	95.5333
4583.86	94.9175
4586.52	94.1921
4589.18	92.8569
4591.84	92.2483
4594.5	91.9088
4597.16	91.7361
4599.81	91.5419
4602.47	91.3754
4605.12	91.2235
4607.78	91.1398
4610.43	92.3814
4613.08	92.4986
4615.73	92.5684
4618.38	92.5367
4621.03	92.3462
4623.67	91.8865
4626.32	91.0761
4628.97	90.2482
4631.61	89.5402
4634.25	89.1249
4636.89	89.0384
4639.54	89.2909
4642.18	89.6812
4644.82	90.3015
4647.45	91.1355
4650.09	92.022
4652.73	92.2918
4655.36	92.0047
4658	92.0172
4660.63	92.1958
4663.26	92.0448
4665.89	91.9335
4668.52	91.7642
4671.15	91.6417
4673.78	91.3181
4676.41	90.8409
4679.03	90.288
4681.66	89.8304
4684.28	89.351
4686.91	88.8972
4689.53	88.4492
4692.15	87.8926
4694.77	87.5753
4697.39	87.2799
4700.01	87.0393
4702.63	86.8108
4705.24	86.6487
4707.86	86.5166
4710.47	86.4246
4713.09	86.3862
4715.7	86.3348
4718.31	86.3135
4720.92	86.2773
4723.53	86.2755
4726.14	86.2631
4728.75	86.2842
4731.35	86.1214
4733.96	86.1186
4736.56	86.1159
4739.17	85.7537
4741.77	84.7283
4744.37	84.333
4746.97	83.6759
4749.57	83.5041
4752.17	83.6951
4754.77	84.192
4757.36	85.0544
4759.96	85.918
4762.56	86.6855
4765.15	87.2403
4767.74	87.7392
4770.33	88.0836
4772.93	88.1274
4775.52	87.7003
4778.1	87.3237
4780.69	86.8138
4783.28	86.3255
4785.87	85.6218
4788.45	84.9337
4791.04	84.2167
4793.62	83.4846
4796.2	82.8026
4798.78	82.1302
4801.36	81.5336
4803.94	81.008
4806.52	80.5369
4809.1	80.2912
4811.68	80.1696
4814.25	80.0023
4816.83	79.9926
4819.4	79.9924
4821.97	80.1855
4824.54	80.5205
4827.12	80.9075
4829.69	81.3972
4832.25	81.6299
4834.82	81.7759
4837.39	81.0373
4839.96	81.059
4842.52	81.2049
4845.09	81.3189
4847.65	81.4644
4850.21	81.5586
4852.77	81.6467
4855.33	81.6148
4857.89	81.5505
4860.45	81.4832
4863.01	81.3136
4865.56	80.9387
4868.12	80.5157
4870.67	80.0619
4873.23	79.618
4875.78	79.1551
4878.33	78.7422
4880.88	78.3301
4883.43	78.0053
4885.98	77.7155
4888.53	77.4829
4891.08	77.9977
4893.62	78.4239
4896.17	78.7891
4898.71	79.2154
4901.26	79.5648
4903.8	79.8934
4906.34	80.1466
4908.88	80.1861
4911.42	80.1716
4913.96	80.1723
4916.5	79.9174
4919.03	79.6349
4921.57	79.307
4924.11	78.9616
4926.64	78.5794
4929.17	78.1991
4931.7	77.8595
4934.24	77.4885
4936.77	77.2015
4939.3	76.8839
4941.82	76.8996
4944.35	76.7666
4946.88	76.2558
4949.4	75.7566
4951.93	75.338
4954.45	74.8694
4956.97	74.5381
4959.5	74.4056
4962.02	74.5004
4964.54	74.6646
4967.06	74.8378
4969.57	75.0012
4972.09	75.3057
4974.61	75.5771
4977.12	75.888
4979.64	76.2367
4982.15	76.5987
4984.66	76.5758
4987.18	76.0142
4989.69	75.2884
4992.2	74.518
4994.7	73.5479
4997.21	72.6201
4999.72	71.3096