File: Data/Raman/raw/bu19ts-coltan2-reddish_150 (500nm)_633nm_edge_10%_x100_vis_h30um_10sx2_01.txt
#Acq. time (s)=	10
#Accumulations=	2
#Range (cm-¹)=	100...4000
#Windows=	1
#Auto scanning=	Off
#Autofocus=	Off
#Macrospot=	Off
#AutoExposure=	Off
#Spike filter=	Multiple accum.
#Delay time (s)=	2
#Binning=	1
#Readout mode=	Signal
#DeNoise=	Standard
#ICS correction=	On
#Dark correction=	Off
#Inst. Process=	Off
#Detector Gain=	Best Dynamic
#Detector ADC=	50 kHz HS
#Detector temperature (°C)=	-60.09
#Instrument=	LabRAM HR Evol
#Detector=	SIN-EM FIVIS
#Objective=	x100_VIS
#Grating=	150 (500nm)
#ND Filter=	10%
#Laser=	633nm_Edge
#Hole=	30.0125
#Temperature=	0
#Range=	Visible
#StageXY=	75x50mm Scan+
#StageZ=	Z motor
#X (µm)=	0
#Y (µm)=	0
#Z (µm)=	-1
#Full time(s)=	24
#Project=	20_10_27
#Sample=	BU19TS
#Site=
#Title=	BU19TS-Coltan3-reddish_150 (500nm)_633nm_Edge_10%_x100_VIS_H30um_10sX2
#Remark=
#Date=	27.10.2020 17:02
#Acquired=	27.10.2020 17:02:30
100.764	61.8063
107.281	62.9585
113.791	75.7516
120.297	93.9797
126.797	106.689
133.291	115.604
139.78	106.783
146.264	89.5379
152.741	80.5442
159.214	92.5599
165.682	96.5938
172.144	94.6356
178.601	87.7223
185.053	77.8658
191.499	74.1083
197.939	87.9238
204.374	107.11
210.805	101.688
217.23	84.4422
223.648	78.8368
230.063	87.1752
236.472	103.718
242.874	123.478
249.273	142.397
255.667	155.45
262.053	171.876
268.436	230.579
274.813	261.316
281.185	211.997
287.552	150.803
293.913	132.988
300.27	141.87
306.62	135.658
312.965	127.055
319.306	117.165
325.64	105.437
331.971	93.9163
338.295	85.4184
344.614	79.6205
350.93	77.1558
357.238	77.2275
363.542	80.7372
369.842	85.8549
376.135	95.1806
382.423	106.632
388.706	118.05
394.984	118.047
401.258	109.051
407.526	98.9063
413.789	92.8254
420.046	88.3203
426.299	89.2616
432.546	91.8243
438.788	95.2411
445.025	99.7941
451.257	105.196
457.484	109.474
463.706	115.774
469.923	122.53
476.135	129.75
482.342	136.984
488.544	143.625
494.741	148.744
500.933	150.214
507.12	147.036
513.3	142.583
519.477	144.551
525.649	166.573
531.815	163.57
537.976	153.628
544.133	138.077
550.285	125.987
556.43	118.222
562.572	115.596
568.709	115.25
574.84	118.085
580.967	118.126
587.09	119.03
593.205	119.989
599.318	123.404
605.424	128.975
611.527	137.924
617.623	152.01
623.716	173.298
629.802	195.274
635.884	213.472
641.962	205.187
648.034	179.266
654.101	152.309
660.165	131.892
666.222	118.153
672.274	110.243
678.324	105.564
684.366	102.855
690.404	101.885
696.438	101.507
702.466	101.752
708.491	102.253
714.51	102.773
720.523	103.232
726.533	103.704
732.537	104.037
738.537	104.118
744.531	104.05
750.521	103.96
756.507	103.764
762.487	103.392
768.463	102.932
774.434	102.828
780.4	102.905
786.362	104.115
792.319	107.236
798.269	112.404
804.217	121.312
810.159	136.943
816.097	158.887
822.03	191.8
827.958	222.88
833.881	234.677
839.801	238.614
845.714	271.62
851.624	349.795
857.529	485.467
863.428	731.587
869.324	1219.93
875.215	2003.18
881.1	2033.04
886.982	950.282
892.858	445.02
898.73	276.497
904.597	185.537
910.459	140.413
916.318	118.568
922.171	107.212
928.02	98.0727
933.864	91.9861
939.703	86.9266
945.539	82.3259
951.368	78.3215
957.194	75.1177
963.014	72.4923
968.832	70.6353
974.643	69.2132
980.45	67.3654
986.253	66.2589
992.051	65.5501
997.844	65.1675
1003.63	65.0325
1009.42	65.2713
1015.2	65.6144
1020.97	65.1014
1026.74	64.774
1032.51	64.4973
1038.27	64.5844
1044.03	64.8964
1049.78	65.2865
1055.53	64.7899
1061.27	64.1543
1067.01	63.5129
1072.75	62.872
1078.48	62.2856
1084.2	61.7545
1089.92	61.5267
1095.64	61.3179
1101.35	61.0585
1107.06	61.02
1112.77	61.0149
1118.46	61.0202
1124.16	60.6313
1129.85	60.1919
1135.53	59.4876
1141.22	58.8778
1146.89	58.3932
1152.56	57.9502
1158.23	57.2455
1163.9	56.3707
1169.56	55.5565
1175.21	55.1849
1180.86	54.9346
1186.51	55.1056
1192.15	55.3576
1197.78	55.2323
1203.42	54.9945
1209.04	54.6601
1214.67	53.974
1220.29	53.2364
1225.9	52.3338
1231.51	51.4261
1237.12	50.3351
1242.72	49.8078
1248.32	49.6659
1253.92	49.5408
1259.5	49.5184
1265.09	49.4883
1270.67	49.4192
1276.25	49.2138
1281.82	48.8828
1287.39	48.6609
1292.95	48.4775
1298.51	48.3051
1304.06	48.1336
1309.61	47.9806
1315.16	47.9938
1320.7	47.8305
1326.24	47.6205
1331.77	47.3644
1337.3	47.1643
1342.83	47.0978
1348.35	46.5946
1353.86	46.1318
1359.37	45.7272
1364.88	45.3877
1370.39	45.7259
1375.89	45.7716
1381.38	45.8361
1386.87	45.9003
1392.36	45.9532
1397.84	45.8072
1403.32	45.9043
1408.79	46.1757
1414.26	46.5129
1419.73	46.9056
1425.19	47.3119
1430.65	47.7411
1436.1	48.008
1441.55	47.6977
1447	47.3902
1452.44	46.9278
1457.87	46.3601
1463.31	45.7315
1468.73	45.9258
1474.16	45.2991
1479.58	44.7211
1484.99	44.312
1490.41	44.257
1495.81	44.2434
1501.22	44.1728
1506.62	44.4932
1512.01	45.1012
1517.4	45.769
1522.79	45.3969
1528.17	44.7745
1533.55	44.0033
1538.93	43.2402
1544.3	42.4451
1549.67	42.4806
1555.03	42.6805
1560.39	43.0235
1565.74	43.0723
1571.09	42.7046
1576.44	42.1774
1581.78	41.6477
1587.12	41.1397
1592.45	40.691
1597.78	40.3041
1603.11	39.9809
1608.43	39.7107
1613.75	39.5008
1619.07	39.3825
1624.38	39.4208
1629.68	39.9595
1634.98	40.0933
1640.28	41.2871
1645.58	41.3295
1650.87	39.7124
1656.15	40.3211
1661.44	41.0862
1666.71	40.9555
1671.99	40.5534
1677.26	40.834
1682.53	41.5933
1687.79	41.7578
1693.05	42.0547
1698.3	42.5927
1703.55	43.54
1708.8	44.5621
1714.04	45.6184
1719.28	45.5646
1724.51	45.6394
1729.75	45.9125
1734.97	46.119
1740.2	46.179
1745.42	46.0178
1750.63	45.3878
1755.84	43.5843
1761.05	42.0053
1766.25	40.6581
1771.45	39.4501
1776.65	37.981
1781.84	36.5148
1787.03	35.6231
1792.21	35.3488
1797.39	35.0688
1802.57	34.6139
1807.74	34.3096
1812.91	34.1829
1818.08	34.0518
1823.24	33.3812
1828.39	32.7471
1833.55	32.2735
1838.7	31.8311
1843.84	31.8712
1848.99	32.0374
1854.12	32.2223
1859.26	32.4514
1864.39	32.7092
1869.52	32.9978
1874.64	33.2693
1879.76	33.1444
1884.87	32.8357
1889.98	32.508
1895.09	32.1841
1900.2	31.9205
1905.3	31.7413
1910.39	31.6475
1915.49	31.6268
1920.57	31.604
1925.66	31.4385
1930.74	31.3052
1935.82	31.4258
1940.89	31.5145
1945.96	31.6285
1951.03	31.74
1956.09	31.977
1961.15	31.9978
1966.21	31.9857
1971.26	31.9545
1976.31	31.7334
1981.35	31.4141
1986.39	31.2702
1991.43	31.1417
1996.46	31.0858
2001.49	31.033
2006.52	30.9616
2011.54	30.9154
2016.56	30.8922
2021.57	31.0278
2026.58	31.0649
2031.59	31.1056
2036.59	31.1373
2041.59	31.1586
2046.59	31.1716
2051.58	31.1624
2056.57	31.0934
2061.55	30.8838
2066.54	30.1995
2071.51	29.5087
2076.49	28.8815
2081.46	28.524
2086.43	28.8308
2091.39	29.3946
2096.35	29.8806
2101.3	30.2635
2106.26	30.1993
2111.21	30.0395
2116.15	29.8546
2121.09	29.1131
2126.03	28.8863
2130.97	29.2368
2135.9	29.0888
2140.83	28.9366
2145.75	28.9889
2150.67	29.0862
2155.59	29.3478
2160.5	29.5498
2165.41	28.7986
2170.31	28.2952
2175.22	28.8313
2180.12	29.6153
2185.01	30.3237
2189.9	30.6192
2194.79	30.4054
2199.68	29.9804
2204.56	29.4921
2209.43	28.8911
2214.31	28.4538
2219.18	27.9712
2224.05	27.416
2228.91	27.2495
2233.77	27.5561
2238.63	27.7458
2243.48	27.9881
2248.33	28.263
2253.17	28.5308
2258.02	28.77
2262.86	28.5881
2267.69	28.4648
2272.52	28.3172
2277.35	28.1888
2282.18	28.0499
2287	27.9587
2291.82	27.8795
2296.63	27.7716
2301.44	27.8267
2306.25	27.9076
2311.05	28.0845
2315.86	27.9202
2320.65	27.6189
2325.45	27.3191
2330.24	27.0347
2335.03	26.8059
2339.81	26.6228
2344.59	26.6827
2349.37	27.2603
2354.14	28.0252
2358.91	28.3705
2363.67	27.9347
2368.44	27.5273
2373.2	27.1478
2377.95	26.8024
2382.71	26.5248
2387.46	26.4761
2392.2	26.8237
2396.95	27.1703
2401.68	27.5847
2406.42	27.8696
2411.15	27.7957
2415.88	27.7213
2420.61	27.5219
2425.33	27.2097
2430.05	27.0688
2434.77	27.091
2439.48	27.1304
2444.19	27.2192
2448.89	27.2463
2453.6	27.0437
2458.29	26.841
2462.99	26.5075
2467.68	26.5781
2472.37	26.6842
2477.06	26.8243
2481.74	27.0164
2486.42	27.4131
2491.1	27.798
2495.77	28.0258
2500.44	28.216
2505.1	28.3111
2509.76	28.1425
2514.42	27.847
2519.08	27.4914
2523.73	27.1319
2528.38	26.671
2533.03	26.5761
2537.67	26.5242
2542.31	26.4316
2546.95	26.1509
2551.58	26.0262
2556.21	25.9441
2560.84	26.1843
2565.46	26.2758
2570.08	26.4517
2574.7	26.6041
2579.31	26.6834
2583.92	26.7254
2588.53	26.7415
2593.13	26.4826
2597.73	26.2356
2602.33	26.2342
2606.92	26.2549
2611.51	26.3089
2616.1	26.3073
2620.68	26.2833
2625.26	26.0591
2629.84	25.6696
2634.42	24.6213
2638.99	24.1232
2643.56	24.0558
2648.12	24.457
2652.68	24.9606
2657.24	25.3949
2661.8	25.3744
2666.35	25.3766
2670.9	25.3649
2675.45	25.3297
2679.99	25.2888
2684.53	25.3427
2689.06	25.3674
2693.6	25.4057
2698.13	25.4692
2702.66	25.5764
2707.18	25.7349
2711.7	25.9546
2716.22	26.2383
2720.73	25.9051
2725.24	25.0572
2729.75	24.5277
2734.26	24.1794
2738.76	24.0152
2743.25	23.8718
2747.75	23.9385
2752.24	24.2999
2756.73	24.7324
2761.22	24.7875
2765.7	24.417
2770.18	24.3878
2774.66	24.505
2779.13	24.6668
2783.6	24.8848
2788.07	25.1483
2792.53	25.4436
2797	25.7488
2801.45	26.045
2805.91	26.0081
2810.36	25.8665
2814.81	25.7598
2819.26	25.8387
2823.7	25.8379
2828.14	25.6837
2832.57	25.5201
2837.01	25.3403
2841.44	25.197
2845.87	24.9985
2850.29	25.041
2854.71	25.1425
2859.13	25.3003
2863.55	25.5959
2867.96	26.115
2872.37	26.3684
2876.77	26.5826
2881.18	26.7557
2885.58	26.6146
2889.97	26.2482
2894.37	25.8536
2898.76	25.4322
2903.15	25.2528
2907.53	25.7258
2911.91	26.3304
2916.29	27.0226
2920.67	27.2141
2925.04	26.87
2929.41	26.464
2933.78	25.8128
2938.14	25.2583
2942.5	24.8276
2946.86	24.5004
2951.22	24.7319
2955.57	25.3247
2959.92	25.1103
2964.26	24.8703
2968.61	24.8907
2972.95	24.9861
2977.28	25.1687
2981.62	25.3692
2985.95	25.5852
2990.28	25.9158
2994.6	26.0746
2998.93	26.2956
3003.25	26.2506
3007.56	25.9761
3011.88	25.6982
3016.19	25.3539
3020.49	25.0577
3024.8	24.7823
3029.1	24.5427
3033.4	24.6085
3037.7	24.5683
3041.99	24.4374
3046.28	24.6015
3050.57	24.822
3054.85	25.1349
3059.13	25.4154
3063.41	25.6832
3067.69	25.9302
3071.96	26.1587
3076.23	26.0331
3080.5	25.8677
3084.76	25.9495
3089.02	26.1188
3093.28	26.4514
3097.53	26.4009
3101.79	26.0876
3106.04	24.6673
3110.28	23.9933
3114.53	25.8487
3118.77	25.6445
3123.01	25.4485
3127.24	25.2855
3131.47	25.1608
3135.7	25.3782
3139.93	26.3756
3144.15	27.0402
3148.38	27.508
3152.59	27.9019
3156.81	28.149
3161.02	27.8841
3165.23	27.7876
3169.44	27.7473
3173.64	27.7404
3177.84	27.5594
3182.04	27.4447
3186.24	27.6462
3190.43	27.934
3194.62	28.1792
3198.81	28.0261
3202.99	27.6899
3207.17	27.2343
3211.35	27.0273
3215.53	27.1582
3219.7	27.7
3223.87	28.2151
3228.04	28.3105
3232.2	28.0186
3236.36	27.7453
3240.52	27.5136
3244.68	27.3523
3248.83	27.3876
3252.98	27.4048
3257.13	27.4394
3261.28	27.5246
3265.42	27.6184
3269.56	27.9493
3273.7	28.5126
3277.83	28.958
3281.96	28.9382
3286.09	28.8607
3290.22	28.7767
3294.34	28.7128
3298.46	28.6122
3302.58	28.5596
3306.69	28.5167
3310.8	28.4889
3314.91	28.4902
3319.02	28.5232
3323.12	28.5752
3327.23	28.6456
3331.32	28.8445
3335.42	28.9808
3339.51	29.0716
3343.6	29.1053
3347.69	28.0188
3351.78	28.5071
3355.86	29.0424
3359.94	29.0129
3364.02	29.0763
3368.09	29.1488
3372.16	29.2364
3376.23	29.4064
3380.29	29.3844
3384.36	29.0875
3388.42	28.7139
3392.48	27.9575
3396.53	27.5216
3400.58	27.2857
3404.63	27.6206
3408.68	28.1486
3412.73	28.8686
3416.77	29.1791
3420.81	29.4139
3424.84	29.3453
3428.88	29.218
3432.91	27.6501
3436.94	26.7143
3440.96	26.7867
3444.99	27.9716
3449.01	28.7887
3453.03	29.6002
3457.04	29.4649
3461.05	28.7382
3465.06	28.4509
3469.07	28.9647
3473.08	29.5047
3477.08	29.1003
3481.08	28.7528
3485.07	28.4821
3489.07	28.6545
3493.06	28.8043
3497.05	28.8968
3501.04	29.2261
3505.02	29.6017
3509	29.9852
3512.98	30.3336
3516.96	30.6312
3520.93	30.7832
3524.9	30.6328
3528.87	29.9473
3532.83	28.9979
3536.8	28.1262
3540.76	27.674
3544.71	27.7897
3548.67	28.0571
3552.62	28.4004
3556.57	28.8589
3560.52	29.3744
3564.47	29.8791
3568.41	30.1082
3572.35	30.6874
3576.29	31.3154
3580.22	31.1156
3584.15	30.5724
3588.08	29.9776
3592.01	29.4457
3595.93	29.8117
3599.85	30.0641
3603.77	29.1913
3607.69	30.2176
3611.61	31.2886
3615.52	31.6545
3619.43	31.2697
3623.33	30.8431
3627.24	30.4044
3631.14	29.5545
3635.04	29.1151
3638.93	29.3063
3642.83	29.9069
3646.72	29.7695
3650.61	29.6824
3654.49	29.6539
3658.38	29.6942
3662.26	29.814
3666.14	30.0069
3670.01	30.2592
3673.89	30.4811
3677.76	30.7993
3681.63	31.0688
3685.5	31.4266
3689.36	31.8462
3693.22	32.275
3697.08	32.817
3700.94	32.7645
3704.79	31.9442
3708.64	31.3746
3712.49	30.7012
3716.34	30.4328
3720.18	30.4988
3724.02	30.6478
3727.86	30.8826
3731.7	31.1852
3735.53	31.3541
3739.36	31.3103
3743.19	30.8568
3747.02	30.5738
3750.84	30.2727
3754.66	30.3398
3758.48	30.523
3762.3	30.183
3766.12	29.8353
3769.93	29.1747
3773.74	28.8472
3777.54	29.2718
3781.35	30.1174
3785.15	29.9887
3788.95	30.8128
3792.75	31.3575
3796.54	32.0928
3800.34	31.5226
3804.13	30.512
3807.91	30.0185
3811.7	29.8652
3815.48	30.1481
3819.26	30.1925
3823.04	30.4359
3826.82	30.8024
3830.59	31.1958
3834.36	31.8168
3838.13	31.911
3841.89	31.7585
3845.66	31.6341
3849.42	31.3907
3853.18	31.3739
3856.93	31.3534
3860.69	31.4334
3864.44	31.5774
3868.19	31.848
3871.93	32.169
3875.68	32.4349
3879.42	32.6791
3883.16	32.9075
3886.9	33.116
3890.63	33.3003
3894.37	33.452
3898.1	33.5689
3901.82	33.385
3905.55	33.1934
3909.27	33.0023
3912.99	32.8486
3916.71	32.6403
3920.43	32.4108
3924.14	32.1709
3927.85	31.7987
3931.56	31.4915
3935.27	31.2823
3938.97	31.2448
3942.67	31.7573
3946.37	31.6344
3950.07	31.226
3953.77	31.323
3957.46	32.3211
3961.15	33.5092
3964.84	31.8191
3968.52	29.1544
3972.2	30.9247
3975.89	31.6772
3979.56	31.7753
3983.24	31.2915
3986.92	31.4259
3990.59	31.7523
3994.26	32.0333
3997.92	32.1275
3999.76	31.7895