File: Data/Raman/raw/bu19w-ore5-core_150 (500nm)_532nm_edge_10%_x100_vis_h30um_30sx2_01.txt
#Acq. time (s)=	30
#Accumulations=	2
#Range (cm-¹)=	100...4000
#Windows=	1
#Auto scanning=	Off
#Autofocus=	Off
#Macrospot=	Off
#AutoExposure=	Off
#Spike filter=	Multiple accum.
#Delay time (s)=	2
#Binning=	1
#Readout mode=	Signal
#DeNoise=	Standard
#ICS correction=	On
#Dark correction=	Off
#Inst. Process=	Off
#Detector Gain=	Best Dynamic
#Detector ADC=	50 kHz HS
#Detector temperature (°C)=	-60.09
#Instrument=	LabRAM HR Evol
#Detector=	SIN-EM FIVIS
#Objective=	x100_VIS
#Grating=	150 (500nm)
#ND Filter=	10%
#Laser=	532nm_Edge
#Hole=	30.0125
#Temperature=	0
#Range=	Visible
#StageXY=	75x50mm Scan+
#StageZ=	Z motor
#X (µm)=	0
#Y (µm)=	0
#Z (µm)=	74.8
#Full time(mm:ss)=	1:05
#Project=	21_02_17
#Sample=	BU19w
#Site=
#Title=	BU19w-Ore5-core_150 (500nm)_532nm_Edge_10%_x100_VIS_H30um_30sX2
#Remark=
#Date=	17.02.2021 11:50
#Acquired=	17.02.2021 11:50:28
104.068	2127.61
108.69	2184.89
113.309	2206.15
117.926	2216.61
122.541	2196.04
127.152	2205.07
131.762	2197.4
136.37	2191.34
140.976	2169.07
145.577	2039.8
150.179	1874.33
154.778	1770.35
159.374	1720.49
163.967	1684.05
168.559	1721.38
173.149	1779.45
177.736	1848.92
182.32	1924.45
186.903	2007.5
191.484	2088.61
196.062	2164.12
200.637	2233.32
205.211	2297
209.783	2342.71
214.35	2391.96
218.918	2448.69
223.483	2501.59
228.043	2544.99
232.604	2598.31
237.162	2636.56
241.719	2678.91
246.271	2682.4
250.822	2673.45
255.37	2654.53
259.917	2612.51
264.462	2577.44
269.002	2537.08
273.543	2486.6
278.081	2445.99
282.615	2422.16
287.149	2391.43
291.681	2387.28
296.208	2355.94
300.735	2325.6
305.258	2290.8
309.781	2255.15
314.302	2223.58
318.818	2184.76
323.334	2156.09
327.846	2130.12
332.358	2123.42
336.867	2138.34
341.373	2160.73
345.878	2179.81
350.379	2206.7
354.879	2233.04
359.376	2263.02
363.872	2281.1
368.366	2304.06
372.856	2345.84
377.346	2397.96
381.832	2433.63
386.317	2561.61
390.798	2663.19
395.279	2782.79
399.756	2922.7
404.233	3072.42
408.705	3311.71
413.177	3588.35
417.645	3865.29
422.113	4188.24
426.577	4382.37
431.041	4632.89
435.5	4821.33
439.959	4902.28
444.415	4796.65
448.87	4560.79
453.32	4236.42
457.771	3884.49
462.217	3559.59
466.662	3331.82
471.106	3158.19
475.546	3009.93
479.986	2883.69
484.421	2772.29
488.857	2670.71
493.288	2577.5
497.717	2487.47
502.146	2404.63
506.571	2324.73
510.996	2249.71
515.417	2189.75
519.835	2134.71
524.254	2079.16
528.668	2030.04
533.082	1989.71
537.492	1959.15
541.9	1937.74
546.308	1925.74
550.711	1925.22
555.113	1934.34
559.514	1957.95
563.911	1989.1
568.307	2034.8
572.702	2091.42
577.092	2163.98
581.481	2247.71
585.87	2351.66
590.254	2482.1
594.637	2603.07
599.019	2778.07
603.397	2957.48
607.773	3133.68
612.149	3238.8
616.521	3296.59
620.891	3241.13
625.261	3147.17
629.626	3033.73
633.99	2982.48
638.351	2927.89
642.712	2893.41
647.07	2854.14
651.425	2832.7
655.778	2754.9
660.13	2668.82
664.479	2562.88
668.826	2449.84
673.171	2341.59
677.515	2233.12
681.856	2128.05
686.194	2045.29
690.531	1959.41
694.865	1882.55
699.199	1802.35
703.529	1732.32
707.857	1664.81
712.183	1606.75
716.507	1552.99
720.831	1505.03
725.151	1461.09
729.468	1422.42
733.784	1388.66
738.097	1359.88
742.409	1336.37
746.718	1315.91
751.028	1295.91
755.333	1280.17
759.636	1267.81
763.938	1260.6
768.237	1253.31
772.534	1249.56
776.829	1249.01
781.124	1249.69
785.415	1253.35
789.704	1259.11
793.991	1266.36
798.276	1275.12
802.558	1283.19
806.839	1297.84
811.118	1306.97
815.395	1317.89
819.669	1329.3
823.942	1347.49
828.213	1358.97
832.481	1367
836.75	1371.71
841.014	1361.2
845.277	1342.83
849.537	1287.94
853.796	1213.75
858.052	1132.33
862.306	1045.02
866.559	960.243
870.809	893.211
875.058	842.816
879.304	796.661
883.548	760.794
887.791	723.971
892.031	697.168
896.269	675.055
900.505	655.243
904.74	638.818
908.972	625.924
913.202	616.828
917.431	608.631
921.657	601.613
925.879	588.622
930.102	581.171
934.322	575.885
938.54	572.585
942.756	570.032
946.971	567.538
951.183	564.806
955.393	560.868
959.602	555.284
963.808	548.249
968.013	542.081
972.215	533.744
976.413	527.01
980.612	518.549
984.808	510.474
989.003	501.878
993.195	495.291
997.386	488.274
1001.57	484.67
1005.76	482.661
1009.94	474.852
1014.13	470.092
1018.31	474.03
1022.49	470.867
1026.66	468.013
1030.84	463.731
1035.01	455.711
1039.18	446.954
1043.35	439.534
1047.51	433.664
1051.68	428.044
1055.84	424.84
1060	421.996
1064.16	419.666
1068.32	417.566
1072.47	415.701
1076.63	414.034
1080.78	412.605
1084.93	411.361
1089.07	410.25
1093.22	409.339
1097.36	408.54
1101.5	407.973
1105.64	407.437
1109.78	406.999
1113.91	406.604
1118.05	406.188
1122.18	405.722
1126.31	405.154
1130.44	404.346
1134.56	403.437
1138.68	402.281
1142.81	400.863
1146.93	399.135
1151.04	396.893
1155.16	394.327
1159.27	391.073
1163.39	387.465
1167.5	383.954
1171.6	380.931
1175.71	377.339
1179.81	373.801
1183.92	370.351
1188.02	367.4
1192.12	364.974
1196.21	363.079
1200.31	361.666
1204.4	360.762
1208.49	360.56
1212.58	360.877
1216.67	361.498
1220.75	361.645
1224.84	360.143
1228.92	358.207
1233	356.825
1237.08	355.527
1241.15	354.395
1245.22	353.516
1249.3	352.541
1253.37	351.929
1257.43	351.976
1261.5	352.553
1265.56	353.178
1269.63	354.142
1273.69	355.039
1277.75	355.234
1281.8	353.943
1285.86	354.514
1289.91	355.681
1293.96	357.448
1298.01	357.958
1302.06	357.949
1306.1	358.072
1310.15	357.476
1314.19	356.322
1318.23	353.978
1322.27	351.499
1326.3	348.395
1330.34	345.95
1334.37	344.529
1338.4	343.699
1342.43	340.978
1346.45	338.041
1350.48	335.119
1354.5	332.242
1358.52	329.517
1362.54	327.002
1366.56	324.881
1370.58	323.051
1374.59	321.478
1378.6	320.23
1382.61	319.136
1386.62	318.123
1390.63	317.549
1394.63	316.823
1398.63	315.477
1402.63	314.559
1406.63	313.419
1410.63	312.523
1414.62	311.375
1418.62	310.388
1422.61	309.656
1426.6	309.068
1430.58	308.295
1434.57	306.622
1438.56	305.018
1442.54	302.265
1446.52	300.979
1450.5	300.067
1454.47	299.521
1458.45	300.029
1462.42	300.043
1466.39	300.063
1470.36	300.533
1474.33	300.872
1478.3	301.537
1482.26	303.244
1486.22	305.318
1490.18	304.981
1494.14	304.407
1498.1	303.711
1502.05	302.889
1506	301.872
1509.96	300.892
1513.9	298.459
1517.85	296.193
1521.8	294.126
1525.74	292.287
1529.68	289.948
1533.62	287.645
1537.56	285.338
1541.5	283.115
1545.43	281.552
1549.37	280.735
1553.3	280.415
1557.23	279.613
1561.15	279.515
1565.08	279.3
1569.01	279.808
1572.93	280.86
1576.85	282.011
1580.77	282.786
1584.68	283.466
1588.6	282.077
1592.51	280.774
1596.42	279.703
1600.33	278.79
1604.24	277.649
1608.15	277.234
1612.05	276.85
1615.95	276.42
1619.85	275.76
1623.75	274.293
1627.65	272.849
1631.55	271.189
1635.44	270.158
1639.33	268.353
1643.22	265.91
1647.11	263.272
1651	260.491
1654.88	257.631
1658.77	254.64
1662.65	251.601
1666.53	248.634
1670.4	245.66
1674.28	242.722
1678.15	239.789
1682.03	236.808
1685.9	233.754
1689.77	230.742
1693.63	227.623
1697.5	224.6
1701.36	221.623
1705.22	218.726
1709.08	215.876
1712.94	213.129
1716.8	210.941
1720.65	209.139
1724.51	207.435
1728.36	205.877
1732.21	204.471
1736.06	203.213
1739.9	201.991
1743.75	200.773
1747.59	199.336
1751.43	197.205
1755.27	195.036
1759.11	193.072
1762.94	191.307
1766.78	189.969
1770.61	188.345
1774.44	186.855
1778.27	185.367
1782.09	184.063
1785.92	183.236
1789.74	182.177
1793.56	181.696
1797.38	180.652
1801.2	179.51
1805.02	177.878
1808.83	176.584
1812.65	175.62
1816.46	174.783
1820.27	174.667
1824.08	174.542
1827.88	174.066
1831.69	173.122
1835.49	172.544
1839.29	172.069
1843.09	171.651
1846.89	171.308
1850.69	171.012
1854.48	170.749
1858.27	170.497
1862.06	170.222
1865.85	169.903
1869.64	169.407
1873.43	169.023
1877.21	168.534
1880.99	167.809
1884.77	167.061
1888.55	166.213
1892.33	165.295
1896.11	164.467
1899.88	163.596
1903.65	162.898
1907.42	162.104
1911.19	161.609
1914.96	161.409
1918.72	161.214
1922.49	161.155
1926.25	161.059
1930.01	160.988
1933.77	160.898
1937.52	160.854
1941.28	160.736
1945.03	160.662
1948.79	160.295
1952.53	160.073
1956.28	159.554
1960.03	159.245
1963.78	158.632
1967.52	158.523
1971.26	158.156
1975	157.76
1978.74	157.364
1982.48	156.887
1986.21	156.213
1989.95	155.716
1993.68	155.213
1997.41	155.022
2001.14	154.477
2004.86	153.842
2008.59	153.161
2012.31	152.358
2016.03	151.755
2019.76	151.376
2023.47	151.097
2027.19	150.346
2030.91	149.61
2034.62	148.88
2038.33	148.024
2042.04	147.263
2045.75	146.556
2049.46	145.987
2053.16	145.631
2056.86	145.344
2060.57	145.258
2064.27	145.211
2067.97	145.335
2071.66	145.534
2075.36	145.798
2079.05	145.552
2082.74	145.265
2086.44	145.102
2090.12	145.303
2093.81	145.006
2097.5	144.777
2101.18	144.579
2104.86	144.594
2108.54	145.074
2112.22	145.772
2115.9	146.226
2119.58	145.731
2123.25	144.606
2126.92	143.59
2130.59	142.705
2134.26	141.872
2137.93	141.27
2141.6	140.667
2145.26	140.26
2148.92	140.273
2152.58	140.294
2156.24	140.431
2159.9	140.611
2163.56	140.662
2167.21	140.731
2170.87	140.238
2174.52	139.746
2178.17	139.239
2181.82	138.835
2185.46	138.333
2189.11	137.676
2192.75	136.781
2196.39	136.43
2200.03	134.956
2203.67	132.854
2207.31	132.031
2210.94	131.534
2214.58	133.088
2218.21	130.504
2221.84	130.687
2225.47	131.68
2229.1	131.215
2232.72	130.833
2236.35	130.544
2239.97	130.251
2243.59	130.048
2247.21	129.851
2250.83	129.683
2254.44	129.566
2258.06	129.382
2261.67	129.071
2265.28	129.156
2268.89	129.288
2272.5	128.511
2276.11	127.263
2279.71	126.543
2283.32	125.716
2286.92	124.943
2290.52	124.38
2294.12	124.513
2297.71	124.291
2301.31	123.959
2304.9	123.802
2308.5	123.81
2312.09	123.695
2315.68	123.756
2319.26	123.733
2322.85	123.778
2326.44	123.859
2330.02	123.7
2333.6	123.544
2337.18	122.408
2340.76	121.384
2344.33	120.593
2347.91	119.915
2351.48	119.571
2355.06	119.503
2358.63	119.623
2362.19	119.861
2365.76	120.106
2369.33	119.633
2372.89	119.527
2376.46	119.343
2380.02	118.77
2383.58	118.371
2387.13	118.255
2390.69	118.315
2394.25	118.525
2397.8	117.724
2401.35	115.851
2404.9	114.598
2408.45	113.615
2412	112.943
2415.54	112.472
2419.09	112.276
2422.63	112.264
2426.17	112.437
2429.71	112.711
2433.25	112.994
2436.78	112.736
2440.32	111.951
2443.85	111.365
2447.38	110.567
2450.91	109.75
2454.44	109.165
2457.97	108.65
2461.5	108.134
2465.02	107.764
2468.54	107.469
2472.06	107.427
2475.58	107.31
2479.1	107.219
2482.62	107.166
2486.13	106.996
2489.65	106.465
2493.16	106.231
2496.67	106.079
2500.18	105.72
2503.68	105.201
2507.19	104.792
2510.69	104.355
2514.2	103.901
2517.7	103.527
2521.2	103.178
2524.7	102.983
2528.19	102.957
2531.69	103.695
2535.18	104.214
2538.67	104.594
2542.17	104.129
2545.65	103.621
2549.14	102.823
2552.63	101.965
2556.11	100.926
2559.6	100.123
2563.08	99.5427
2566.56	99.0169
2570.04	98.3804
2573.51	97.6639
2576.99	96.9772
2580.46	96.2662
2583.94	96.2489
2587.41	96.3338
2590.88	96.4522
2594.34	96.6347
2597.81	96.8579
2601.28	97.0462
2604.74	97.104
2608.2	97.1879
2611.66	97.139
2615.12	97.1201
2618.58	96.8813
2622.04	96.6307
2625.49	96.2838
2628.94	96.4407
2632.4	96.234
2635.85	96.0104
2639.3	95.9134
2642.74	95.5868
2646.19	95.2577
2649.63	94.9068
2653.07	94.5392
2656.52	94.1536
2659.96	93.7662
2663.4	93.2967
2666.83	92.9001
2670.27	92.5502
2673.7	92.1933
2677.14	91.8603
2680.57	91.5409
2684	91.2208
2687.42	91.0065
2690.85	90.9579
2694.28	90.9765
2697.7	90.8377
2701.12	90.6972
2704.54	90.5448
2707.96	90.4057
2711.38	90.2476
2714.8	90.1035
2718.21	89.9339
2721.62	89.7781
2725.04	89.5997
2728.45	89.4567
2731.86	89.2752
2735.26	89.0286
2738.67	88.8052
2742.07	88.551
2745.48	88.1505
2748.88	87.9874
2752.28	87.8952
2755.68	87.6352
2759.08	87.5945
2762.47	87.6214
2765.87	87.7839
2769.26	87.841
2772.65	87.7363
2776.04	87.5085
2779.43	87.3636
2782.82	87.0919
2786.21	86.65
2789.59	86.3789
2792.97	86.2668
2796.35	86.2247
2799.73	86.6362
2803.11	86.3199
2806.49	86.0622
2809.87	85.8604
2813.24	85.6837
2816.61	85.7849
2819.99	85.8199
2823.35	85.5741
2826.72	85.4227
2830.09	85.2502
2833.46	85.1916
2836.82	84.7742
2840.18	84.543
2843.55	84.3209
2846.91	84.3248
2850.26	84.0436
2853.62	84.0703
2856.98	83.6715
2860.33	82.9797
2863.68	82.4337
2867.04	82.0214
2870.39	81.7017
2873.74	81.3738
2877.08	81.2239
2880.43	81.2001
2883.77	81.2522
2887.12	80.6694
2890.46	80.2466
2893.8	80.0426
2897.14	79.8759
2900.47	79.8177
2903.81	80.0664
2907.14	80.2289
2910.48	80.5673
2913.81	81.2254
2917.14	81.7629
2920.47	82.2963
2923.8	82.359
2927.12	82.3374
2930.45	81.5984
2933.77	80.8232
2937.09	80.0156
2940.41	79.2957
2943.73	78.607
2947.05	78.1363
2950.37	77.6686
2953.68	77.3072
2957	76.9704
2960.31	76.6995
2963.62	76.4819
2966.93	76.3215
2970.24	76.2242
2973.54	76.1684
2976.85	76.0933
2980.15	76.002
2983.45	75.8753
2986.76	75.6881
2990.05	75.3273
2993.35	75.1279
2996.65	74.8267
2999.94	74.514
3003.24	74.0534
3006.53	73.7678
3009.82	73.5734
3013.11	73.347
3016.4	73.1883
3019.69	73.1974
3022.97	73.3136
3026.26	73.45
3029.54	73.6866
3032.82	73.8826
3036.1	74.0864
3039.38	74.1279
3042.66	73.9283
3045.94	73.9271
3049.21	73.5767
3052.49	73.1076
3055.76	72.1565
3059.03	71.2675
3062.3	71.2231
3065.57	71.0449
3068.83	71.3283
3072.1	71.6775
3075.36	72.0424
3078.62	72.4037
3081.88	72.6419
3085.14	72.6156
3088.4	72.4856
3091.66	72.3412
3094.92	72.1409
3098.17	71.9341
3101.42	71.6865
3104.67	71.4157
3107.93	71.0131
3111.17	70.8551
3114.42	70.6887
3117.67	70.5371
3120.91	70.4235
3124.16	70.2804
3127.4	70.2906
3130.64	70.2701
3133.88	69.6284
3137.12	68.6491
3140.35	67.8211
3143.59	67.3565
3146.82	67.6462
3150.05	67.0777
3153.29	67.2106
3156.52	67.5568
3159.74	67.7766
3162.97	67.273
3166.2	66.808
3169.42	66.3762
3172.65	65.977
3175.87	65.6715
3179.09	65.4012
3182.31	65.574
3185.53	65.8849
3188.74	66.3094
3191.96	66.5132
3195.17	66.3856
3198.38	66.2224
3201.59	66.0889
3204.81	65.8778
3208.01	65.5165
3211.22	65.2799
3214.43	65.1422
3217.63	64.9001
3220.83	64.6953
3224.04	64.784
3227.24	64.5998
3230.44	64.4758
3233.64	64.4396
3236.83	64.0893
3240.03	63.3353
3243.22	62.052
3246.41	62.0228
3249.6	62.1758
3252.8	62.4853
3255.98	62.9724
3259.17	63.5136
3262.36	63.8083
3265.54	64.0976
3268.72	63.5819
3271.91	62.7071
3275.09	62.3826
3278.27	62.2411
3281.45	62.1804
3284.62	62.2647
3287.8	62.1197
3290.97	62.2387
3294.15	62.1572
3297.32	61.9585
3300.49	61.8766
3303.66	62.064
3306.83	62.0573
3309.99	62.1608
3313.16	62.2444
3316.32	62.012
3319.48	61.6145
3322.64	61.128
3325.8	61.1658
3328.96	61.2323
3332.12	60.8968
3335.27	60.6738
3338.43	60.4974
3341.58	60.1881
3344.74	60.0357
3347.89	59.811
3351.04	59.7007
3354.18	59.7027
3357.33	59.5265
3360.48	59.4401
3363.62	59.4589
3366.76	59.3271
3369.91	59.0279
3373.05	58.5751
3376.19	58.325
3379.32	57.8549
3382.46	57.3278
3385.6	56.8007
3388.73	56.3199
3391.86	55.8317
3394.99	55.4453
3398.13	55.0389
3401.25	54.8472
3404.38	54.7235
3407.51	55.0252
3410.63	55.3107
3413.76	55.6726
3416.88	56.0687
3420	56.0883
3423.12	55.9398
3426.24	55.7838
3429.36	55.617
3432.47	55.421
3435.59	54.6904
3438.7	54.7267
3441.81	55.0587
3444.93	55.3712
3448.03	55.572
3451.14	55.8189
3454.25	56.01
3457.36	56.1725
3460.46	56.0709
3463.56	56.2454
3466.67	56.5428
3469.77	56.9921
3472.87	57.1498
3475.97	57.2598
3479.06	57.3016
3482.16	57.292
3485.25	56.4987
3488.35	55.6261
3491.44	54.9579
3494.53	54.5806
3497.62	54.115
3500.71	54.088
3503.79	54.0034
3506.88	54.071
3509.96	54.2843
3513.05	54.1568
3516.13	53.6809
3519.21	53.2373
3522.29	52.6001
3525.37	52.5403
3528.45	53.3535
3531.52	53.161
3534.6	52.9896
3537.67	53.0494
3540.74	53.1098
3543.81	51.1305
3546.88	50.2114
3549.95	50.0719
3553.02	50.5991
3556.08	51.1654
3559.15	51.5164
3562.21	51.5773
3565.27	51.4815
3568.33	51.3011
3571.39	51.0767
3574.45	50.7282
3577.51	50.2628
3580.56	49.8625
3583.62	49.5818
3586.67	49.6353
3589.72	50.2766
3592.78	50.9246
3595.83	51.289
3598.87	51.5349
3601.92	51.5685
3604.97	51.3067
3608.01	50.8139
3611.06	50.6006
3614.1	50.7408
3617.14	51.4892
3620.18	51.094
3623.22	50.6695
3626.25	49.992
3629.29	49.4741
3632.32	48.9894
3635.36	48.5265
3638.39	48.2406
3641.42	48.0366
3644.45	47.912
3647.48	47.7546
3650.51	47.8957
3653.54	48.0659
3656.56	48.3283
3659.58	48.4005
3662.61	48.2293
3665.63	48.2117
3668.65	48.0542
3671.67	48.0655
3674.69	47.9762
3677.7	47.999
3680.72	47.9132
3683.73	47.8729
3686.75	47.8531
3689.76	47.8191
3692.77	47.841
3695.78	47.952
3698.79	47.93
3701.79	47.8803
3704.8	47.4801
3707.8	47.0075
3710.81	46.8934
3713.81	46.8869
3716.81	46.7117
3719.81	46.5116
3722.81	46.3754
3725.81	46.2865
3728.8	46.368
3731.8	46.261
3734.79	46.0899
3737.78	46.021
3740.77	45.8013
3743.76	45.766
3746.75	45.7055
3749.74	45.8517
3752.73	46.1866
3755.71	46.3854
3758.7	46.3626
3761.68	46.3199
3764.66	46.1855
3767.64	46.2662
3770.62	46.1134
3773.6	46.0004
3776.58	45.7918
3779.55	45.6958
3782.53	45.4783
3785.5	45.3918
3788.47	45.3119
3791.44	45.3435
3794.41	45.3793
3797.38	45.4481
3800.35	45.5427
3803.32	45.5577
3806.28	45.5046
3809.25	45.64
3812.21	45.6511
3815.17	44.8939
3818.13	44.4431
3821.09	44.0595
3824.05	43.3881
3827	43.3086
3829.96	43.2475
3832.92	43.2026
3835.87	43.4709
3838.82	43.6262
3841.77	43.8243
3844.72	44.0492
3847.67	44.278
3850.62	44.0491
3853.56	43.6868
3856.51	43.3283
3859.45	42.8051
3862.4	42.5353
3865.34	42.3075
3868.28	42.0847
3871.22	41.699
3874.16	41.6431
3877.09	41.5483
3880.03	41.4234
3882.96	41.4972
3885.9	41.6995
3888.83	42.1666
3891.76	42.4121
3894.69	42.6204
3897.62	42.8452
3900.55	43.1024
3903.47	42.9506
3906.4	42.7741
3909.32	42.603
3912.24	42.4232
3915.17	42.2607
3918.09	42.087
3921.01	41.939
3923.92	41.7572
3926.84	41.6671
3929.76	41.5006
3932.67	40.9116
3935.59	40.3754
3938.5	39.9679
3941.41	39.8639
3944.32	39.9125
3947.23	39.91
3950.14	39.822
3953.05	39.8403
3955.95	39.8636
3958.86	39.9836
3961.76	40.162
3964.66	40.2023
3967.56	40.1504
3970.46	40.1271
3973.36	40.1277
3976.26	40.149
3979.16	40.2029
3982.05	40.2919
3984.94	39.7173
3987.84	39.0137
3990.73	38.4712
3993.62	37.8729
3996.51	37.4072
3999.4	37.3524