File: Data/Raman/raw/bu19w-ore3-upperrighthost_150 (500nm)_633nm_edge_100%_x100_vis_h30um_30sx2_01_0.txt
#Acq. time (s)=	30
#Accumulations=	2
#Range (cm-¹)=	100...4000
#Windows=	1
#Auto scanning=	Off
#Autofocus=	Off
#Macrospot=	Off
#AutoExposure=	Off
#Spike filter=	Multiple accum.
#Delay time (s)=	2
#Binning=	1
#Readout mode=	Signal
#DeNoise=	Standard
#ICS correction=	On
#Dark correction=	Off
#Inst. Process=	Off
#Detector Gain=	Best Dynamic
#Detector ADC=	50 kHz HS
#Detector temperature (°C)=	-60.09
#Instrument=	LabRAM HR Evol
#Detector=	SIN-EM FIVIS
#Objective=	x100_VIS
#Grating=	150 (500nm)
#ND Filter=	100%
#Laser=	633nm_Edge
#Hole=	30.0125
#Temperature=	0
#Range=	Visible
#StageXY=	75x50mm Scan+
#StageZ=	Z motor
#X (µm)=	0
#Y (µm)=	0
#Z (µm)=	69.3
#Full time(mm:ss)=	1:04
#Project=	21_02_17
#Sample=	BU19w
#Site=
#Title=	BU19w-Ore3-upperRightHost_150 (500nm)_633nm_Edge_100%_x100_VIS_H30um_30sX2
#Remark=
#Date=	17.02.2021 11:02
#Acquired=	17.02.2021 11:02:39
100.724	243.467
107.24	232.859
113.751	224.604
120.256	220.739
126.756	217.522
133.251	217.748
139.74	220.286
146.224	224.342
152.702	226.631
159.175	227.794
165.643	228.056
172.105	224.708
178.561	219.066
185.013	213.248
191.459	209.05
197.9	207.597
204.336	209.188
210.765	212.095
217.19	218.3
223.61	227.593
230.024	238.026
236.432	263.215
242.836	284.259
249.233	280.124
255.627	267.479
262.015	254.716
268.397	252.359
274.774	256.261
281.145	278.75
287.513	333.699
293.873	361.175
300.23	287.707
306.58	242.676
312.927	224.337
319.266	228.488
325.602	255.068
331.932	299.952
338.256	314.869
344.577	269.728
350.89	245.256
357.199	238.462
363.504	248.197
369.803	262.391
376.096	256.986
382.384	242.965
388.669	226.417
394.947	214.936
401.219	210.811
407.487	210.603
413.75	214.122
420.007	220.904
426.261	228.845
432.508	244.098
438.751	258.665
444.988	271.29
451.22	282.684
457.447	284.343
463.669	271.644
469.886	248.087
476.098	231.776
482.303	220.682
488.505	214.585
494.702	216.562
500.894	218.386
507.081	221.721
513.263	224.71
519.44	227.098
525.61	227.334
531.777	227.328
537.939	227.593
544.096	227.811
550.246	228.511
556.393	229.665
562.535	231.341
568.671	232.744
574.803	233.665
580.929	235.787
587.051	235.564
593.167	237.827
599.28	273.12
605.387	311.645
611.489	320.876
617.585	321.284
623.678	317.593
629.764	317.742
635.847	326.754
641.924	313.671
647.998	297.78
654.065	282.551
660.127	284.762
666.184	282.98
672.238	275.563
678.286	261.898
684.329	248.949
690.367	236.808
696.401	227.016
702.43	220.209
708.453	218.525
714.472	215.675
720.486	214.171
726.495	212.584
732.5	211.731
738.501	210.937
744.495	209.892
750.485	208.065
756.471	207.178
762.451	206.855
768.426	206.75
774.397	206.822
780.363	207.709
786.325	209.668
792.281	212.252
798.234	214.306
804.181	215.146
810.124	215.103
816.06	214.328
821.993	213.624
827.922	211.981
833.846	211.681
839.764	212.871
845.678	215.564
851.588	218.37
857.492	221.034
863.392	224.526
869.287	227.285
875.178	230.617
881.063	232.431
886.945	233.487
892.822	234.483
898.694	234.894
904.56	235.4
910.424	235.265
916.281	236.159
922.135	238.947
927.984	243.418
933.827	249.579
939.668	257.056
945.502	265.937
951.332	275.552
957.159	288.211
962.979	303.082
968.796	315.033
974.607	327.496
980.414	349.039
986.218	384.768
992.016	453.809
997.809	504.704
1003.6	461.427
1009.38	421.666
1015.16	411.588
1020.94	424.673
1026.71	460.427
1032.48	514.097
1038.24	461.508
1043.99	371.314
1049.75	335.818
1055.5	322.903
1061.24	310.554
1066.98	302.42
1072.71	292.887
1078.44	288.778
1084.17	303.07
1089.89	315.109
1095.61	320.598
1101.32	332.223
1107.03	351.212
1112.73	327.599
1118.43	302.601
1124.12	285.297
1129.81	273.264
1135.5	270.793
1141.18	275.308
1146.86	282.794
1152.53	289.613
1158.2	292.739
1163.86	291.03
1169.52	278.726
1175.17	267.819
1180.83	257.104
1186.47	249.564
1192.11	245.532
1197.75	242.072
1203.38	240.96
1209.01	242.077
1214.63	242.855
1220.25	241.511
1225.87	242.884
1231.48	244.205
1237.09	248.747
1242.69	247.622
1248.29	244.651
1253.88	241.961
1259.47	238.763
1265.05	234.475
1270.63	231.928
1276.21	232.225
1281.78	233.624
1287.35	235.827
1292.91	237.855
1298.47	238.804
1304.03	240.039
1309.58	242.212
1315.13	244.396
1320.67	245.146
1326.2	244.648
1331.74	243.486
1337.27	241.826
1342.79	239.261
1348.31	237.158
1353.83	235.44
1359.34	235.992
1364.85	237.857
1370.35	239.59
1375.85	242.2
1381.35	244.542
1386.84	244.891
1392.32	244.089
1397.81	243.385
1403.29	242.365
1408.76	241.501
1414.23	240.818
1419.7	239.973
1425.16	241.093
1430.61	242.686
1436.07	242.419
1441.52	241.274
1446.96	240.45
1452.4	239.283
1457.84	238.741
1463.27	239.676
1468.7	240.271
1474.12	241.338
1479.55	242.618
1484.96	242.188
1490.37	240.728
1495.78	240.011
1501.18	240.52
1506.58	241.841
1511.98	242.514
1517.37	242.226
1522.76	240.803
1528.14	239.246
1533.52	238.189
1538.9	239.028
1544.27	240.358
1549.63	243.131
1555	246.266
1560.35	249.14
1565.71	250.272
1571.06	250.022
1576.41	247.466
1581.75	246.433
1587.09	245.156
1592.42	247.38
1597.75	243.602
1603.08	241.26
1608.4	240.983
1613.72	241.944
1619.03	244.001
1624.34	245.588
1629.65	246.188
1634.95	245.807
1640.25	244.769
1645.54	242.843
1650.83	239.996
1656.12	237.813
1661.4	236.413
1666.68	235.989
1671.96	236.804
1677.23	237.005
1682.49	237.339
1687.75	238.237
1693.01	239.227
1698.27	238.666
1703.52	237.805
1708.77	237.111
1714.01	236.653
1719.25	234.912
1724.48	234.598
1729.71	235.181
1734.94	236.899
1740.16	239.128
1745.38	240.164
1750.6	240.036
1755.81	239.656
1761.02	239.635
1766.22	239.982
1771.42	239.265
1776.62	237.997
1781.81	238.09
1787	238.851
1792.18	238.891
1797.36	238.244
1802.54	236.791
1807.71	235.037
1812.88	233.488
1818.05	232.511
1823.21	231.962
1828.36	231.63
1833.52	231.332
1838.67	232.697
1843.81	232.568
1848.95	231.44
1854.09	231.004
1859.23	228.427
1864.36	224.504
1869.48	224.543
1874.61	225.368
1879.73	224.742
1884.84	225.823
1889.95	225.762
1895.06	226.614
1900.17	227.333
1905.27	227.662
1910.36	227.756
1915.45	227.981
1920.54	226.774
1925.63	224.672
1930.71	222.005
1935.79	220.919
1940.86	219.855
1945.93	219.651
1951	218.009
1956.06	218.188
1961.12	217.793
1966.18	217.914
1971.23	219.102
1976.28	221.213
1981.32	223.139
1986.36	222.861
1991.4	223.391
1996.43	221.157
2001.46	219.13
2006.48	217.494
2011.51	214.931
2016.52	213.436
2021.54	211.953
2026.55	211.127
2031.56	209.758
2036.56	208.533
2041.56	207.704
2046.56	205.846
2051.55	205.211
2056.54	205.154
2061.52	205.271
2066.51	209.37
2071.48	212.037
2076.46	211.557
2081.43	207.712
2086.4	203.85
2091.36	204.304
2096.32	204.634
2101.28	205.828
2106.23	206.934
2111.18	207.278
2116.12	206.776
2121.06	206.543
2126	205.513
2130.94	203.614
2135.87	202.154
2140.79	201.745
2145.72	201.31
2150.64	201.25
2155.56	200.047
2160.47	199.049
2165.38	197.342
2170.28	196.12
2175.19	194.995
2180.09	194.188
2184.98	193.141
2189.87	193.934
2194.76	195.022
2199.65	196.074
2204.53	195.582
2209.4	193.46
2214.28	192.435
2219.15	191.007
2224.02	189.526
2228.88	188.204
2233.74	187.675
2238.6	187.915
2243.45	187.19
2248.3	185.648
2253.14	184.816
2257.99	184.523
2262.83	184.58
2267.66	185.386
2272.49	184.96
2277.32	184.214
2282.15	182.027
2286.97	179.469
2291.79	177
2296.6	176.909
2301.41	177.866
2306.22	178.98
2311.02	179.687
2315.83	180.457
2320.62	180.169
2325.42	179.32
2330.21	177.391
2335	175.908
2339.78	175.779
2344.56	175.363
2349.34	174.408
2354.11	173.514
2358.88	172.857
2363.65	171.644
2368.41	170.564
2373.17	169.545
2377.93	170.898
2382.68	169.847
2387.43	168.207
2392.17	164.777
2396.92	164.287
2401.66	166.882
2406.39	167.635
2411.13	168.587
2415.85	169.579
2420.58	169.254
2425.3	167.621
2430.02	165.435
2434.74	163.911
2439.45	164.141
2444.16	163.525
2448.86	162.833
2453.57	161.724
2458.27	161.501
2462.96	159.786
2467.65	157.889
2472.34	157.195
2477.03	158.346
2481.71	159.494
2486.39	160.834
2491.07	163.049
2495.74	165.113
2500.41	164.573
2505.07	162.484
2509.74	159.577
2514.4	156.754
2519.05	155.149
2523.7	154.293
2528.35	154.943
2533	155.137
2537.64	152.774
2542.28	152.326
2546.92	151.13
2551.55	149.866
2556.18	148.609
2560.81	147.884
2565.43	148.443
2570.05	148.895
2574.67	148.971
2579.28	147.9
2583.89	147.358
2588.5	147.187
2593.1	145.906
2597.7	144.254
2602.3	143.753
2606.89	144.226
2611.48	145.859
2616.07	145.634
2620.66	144.077
2625.24	141.381
2629.82	140.81
2634.39	150.959
2638.96	139.025
2643.53	134.891
2648.09	135.922
2652.66	138.447
2657.21	139.961
2661.77	140.151
2666.32	139.655
2670.87	139.116
2675.42	137.618
2679.96	136.296
2684.5	134.281
2689.04	134.438
2693.57	135.642
2698.1	136.266
2702.63	135.99
2707.15	134.787
2711.67	133.771
2716.19	132.881
2720.7	131.52
2725.21	130.197
2729.72	130.022
2734.23	129.736
2738.73	130.094
2743.23	129.777
2747.72	128.599
2752.22	126.973
2756.7	125.686
2761.19	125.213
2765.67	125.676
2770.15	127.572
2774.63	129.57
2779.1	130.711
2783.57	131.331
2788.04	129.891
2792.51	128.262
2796.97	127.241
2801.43	127.792
2805.88	127.9
2810.33	127.083
2814.78	126.466
2819.23	125.54
2823.67	124.974
2828.11	122.391
2832.55	123.684
2836.98	124.696
2841.41	124.621
2845.84	123.511
2850.26	123.2
2854.69	123.834
2859.1	121.971
2863.52	121.341
2867.93	121.017
2872.34	120.157
2876.75	117.943
2881.15	117.859
2885.55	115.676
2889.95	120.312
2894.34	125.014
2898.73	122.536
2903.12	120.157
2907.5	119.294
2911.89	119.968
2916.27	119.503
2920.64	118.022
2925.01	118.497
2929.38	115.304
2933.75	115.409
2938.12	114.583
2942.48	114.254
2946.84	113.931
2951.19	112.737
2955.54	112.703
2959.89	113.401
2964.24	113.811
2968.58	113.749
2972.92	113.34
2977.26	112.194
2981.59	109.844
2985.92	108.728
2990.25	108.075
2994.58	108.002
2998.9	108.738
3003.22	109.329
3007.54	109.777
3011.85	110.294
3016.16	110.413
3020.47	109.807
3024.77	110.049
3029.07	110.295
3033.37	110.553
3037.67	110.107
3041.96	109.473
3046.25	108.896
3050.54	108.72
3054.82	109.228
3059.11	108.972
3063.38	109.041
3067.66	109.006
3071.93	108.45
3076.2	108.081
3080.47	106.907
3084.73	106.954
3088.99	106.596
3093.25	107.049
3097.51	108.088
3101.76	107.761
3106.01	106.071
3110.26	104.395
3114.5	104.166
3118.74	104.778
3122.98	105.389
3127.22	105.92
3131.45	106.561
3135.68	108.098
3139.91	107.574
3144.13	107.792
3148.35	107.687
3152.57	108.315
3156.78	109.768
3161	110.909
3165.21	112.528
3169.41	113.091
3173.62	112.279
3177.82	111.719
3182.02	109.992
3186.21	108.655
3190.4	108.465
3194.59	109.018
3198.78	110.251
3202.96	111.488
3207.15	112.847
3211.33	113.193
3215.5	112.814
3219.67	112.622
3223.84	111.834
3228.01	110.331
3232.18	109.775
3236.34	109.393
3240.5	109.234
3244.65	109.333
3248.81	109.527
3252.96	108.784
3257.11	108.598
3261.25	108.143
3265.39	106.142
3269.53	103.971
3273.67	102.75
3277.8	101.607
3281.94	100.388
3286.06	99.5433
3290.19	99.6049
3294.31	100.433
3298.43	101.432
3302.55	101.251
3306.67	99.9265
3310.78	98.4944
3314.89	97.8441
3319	96.9504
3323.1	96.089
3327.2	96.2515
3331.3	95.4465
3335.39	96.5329
3339.49	97.9775
3343.58	99.7684
3347.67	102.647
3351.75	105.768
3355.83	107.31
3359.91	106.868
3363.99	105.404
3368.06	105.281
3372.14	105.235
3376.2	105.276
3380.27	105.294
3384.33	106.002
3388.39	106.248
3392.45	107.162
3396.51	107.183
3400.56	107.191
3404.61	108.859
3408.66	110.635
3412.7	113.206
3416.74	116.855
3420.78	119.606
3424.82	123.174
3428.85	125.989
3432.88	125.789
3436.91	122.512
3440.94	120.048
3444.96	119.581
3448.98	119.354
3453	118.741
3457.02	129.452
3461.03	140.496
3465.04	150.975
3469.05	155.743
3473.05	154.718
3477.05	149.374
3481.05	140.486
3485.05	132.501
3489.04	126.055
3493.04	121.27
3497.03	120.116
3501.01	119.662
3505	120.469
3508.98	118.542
3512.96	115.328
3516.93	113.658
3520.9	113.299
3524.88	114.226
3528.84	117.147
3532.81	120.446
3536.77	120.82
3540.73	127.224
3544.69	129.983
3548.65	130.499
3552.6	129.507
3556.55	127.372
3560.5	123.007
3564.44	117.459
3568.38	112.753
3572.32	108.686
3576.26	105.119
3580.2	103.526
3584.13	102.808
3588.06	103.026
3591.98	103.617
3595.91	104.025
3599.83	101.984
3603.75	98.4119
3607.67	93.7748
3611.58	90.941
3615.49	88.1004
3619.4	86.6885
3623.31	86.2242
3627.21	85.7032
3631.11	86.1503
3635.01	86.5795
3638.91	85.7934
3642.8	85.2776
3646.69	85.3458
3650.58	84.6986
3654.47	83.9703
3658.35	83.427
3662.24	82.7335
3666.11	82.08
3669.99	82.0341
3673.86	82.1075
3677.74	81.2805
3681.6	80.029
3685.47	78.9987
3689.34	78.4701
3693.2	79.0332
3697.06	80.0834
3700.91	80.6222
3704.77	82.9333
3708.62	80.0918
3712.47	76.9613
3716.31	77.0634
3720.16	75.4263
3724	72.8126
3727.84	74.331
3731.67	76.8008
3735.51	80.2691
3739.34	81.8833
3743.17	81.9693
3747	80.6678
3750.82	80.7404
3754.64	79.1859
3758.46	77.4981
3762.28	78.5109
3766.09	79.957
3769.9	80.3633
3773.71	78.1554
3777.52	76.0438
3781.33	76.3545
3785.13	76.6226
3788.93	77.355
3792.72	77.0194
3796.52	76.4397
3800.31	77.11
3804.1	77.5614
3807.89	76.8169
3811.68	77.4473
3815.46	77.9339
3819.24	78.4971
3823.02	79.2327
3826.79	79.8847
3830.56	80.3807
3834.34	80.6998
3838.1	79.9002
3841.87	78.5588
3845.63	77.0431
3849.39	75.6721
3853.15	75.671
3856.91	75.9575
3860.66	75.5807
3864.42	74.7904
3868.16	74.7567
3871.91	74.525
3875.66	73.836
3879.4	73.5133
3883.14	72.766
3886.88	72.6835
3890.61	72.9597
3894.34	73.3425
3898.07	73.5699
3901.8	74.6603
3905.53	75.7446
3909.25	76.5842
3912.97	77.5095
3916.69	77.387
3920.4	76.336
3924.12	74.2625
3927.83	73.0647
3931.54	72.6735
3935.24	73.0252
3938.95	73.8114
3942.65	74.5885
3946.35	74.233
3950.05	73.4239
3953.74	73.2465
3957.44	73.116
3961.13	72.0992
3964.81	71.5561
3968.5	71.2191
3972.18	71.5327
3975.86	72.288
3979.54	73.0812
3983.22	74.1507
3986.89	74.3491
3990.56	74.4829
3994.23	74.3778
3997.9	75.2934
3999.73	77.1177