File: Data/Raman/raw/bu19w-ore4-apatite-up_150 (500nm)_633nm_edge_100%_x50_vis_lwd_h30um_30sx2_01_0.txt
#Acq. time (s)=	30
#Accumulations=	2
#Range (cm-¹)=	100...4000
#Windows=	1
#Auto scanning=	Off
#Autofocus=	Off
#Macrospot=	Off
#AutoExposure=	Off
#Spike filter=	Multiple accum.
#Delay time (s)=	2
#Binning=	1
#Readout mode=	Signal
#DeNoise=	Standard
#ICS correction=	On
#Dark correction=	Off
#Inst. Process=	Off
#Detector Gain=	Best Dynamic
#Detector ADC=	50 kHz HS
#Detector temperature (°C)=	-60.09
#Instrument=	LabRAM HR Evol
#Detector=	SIN-EM FIVIS
#Objective=	x50_VIS_LWD
#Grating=	150 (500nm)
#ND Filter=	100%
#Laser=	633nm_Edge
#Hole=	30.0125
#Temperature=	0
#Range=	Visible
#StageXY=	75x50mm Scan+
#StageZ=	Z motor
#X (µm)=	0
#Y (µm)=	0
#Z (µm)=	70.2
#Full time(mm:ss)=	1:04
#Project=	21_02_17
#Sample=	BU19w
#Site=
#Title=	BU19w-Ore4-apatite-up_150 (500nm)_633nm_Edge_100%_x50_VIS_LWD_H30um_30sX2
#Remark=
#Date=	17.02.2021 11:45
#Acquired=	17.02.2021 11:45:51
100.724	651.294
107.24	646.907
113.751	645.788
120.256	675.279
126.756	742.644
133.251	856.466
139.74	853.753
146.224	810.313
152.702	707.821
159.175	656.57
165.643	632.628
172.105	623.341
178.561	626.232
185.013	634.008
191.459	644.833
197.9	652.361
204.336	653.954
210.765	645.316
217.19	631.898
223.61	632.174
230.024	659.469
236.432	670.394
242.836	659.155
249.233	641.128
255.627	631.991
262.015	642.633
268.397	657.412
274.774	667.886
281.145	664.418
287.513	652.486
293.873	637.197
300.23	623.702
306.58	612.779
312.927	605.137
319.266	600.844
325.602	599.854
331.932	599.762
338.256	600.997
344.577	597.929
350.89	593.595
357.199	588.781
363.504	583.779
369.803	579.711
376.096	579.153
382.384	576.537
388.669	575.937
394.947	579.311
401.219	582.706
407.487	591.161
413.75	618.876
420.007	705.892
426.261	926.824
432.508	1018.53
438.751	1023.58
444.988	1073.76
451.22	963.255
457.447	860.224
463.669	776.422
469.886	708.754
476.098	655.31
482.303	616.452
488.505	594.527
494.702	578.069
500.894	574.939
507.081	579.498
513.263	580.535
519.44	576.682
525.61	570.272
531.777	567.742
537.939	564.682
544.096	564.019
550.246	572.94
556.393	573.729
562.535	596.254
568.671	664.756
574.803	963.499
580.929	983.094
587.051	814.148
593.167	783.788
599.28	637.931
605.387	671.422
611.489	793.536
617.585	769.779
623.678	711.593
629.764	624.467
635.847	592.633
641.924	584.211
647.998	585.925
654.065	591.003
660.127	596.555
666.184	602.145
672.238	603.336
678.286	602.167
684.329	598.184
690.367	593.445
696.401	586.013
702.43	575.915
708.453	565.434
714.472	557.048
720.486	550.947
726.495	547.033
732.5	545.119
738.501	545.142
744.495	546.353
750.485	546.765
756.471	546.422
762.451	544.904
768.426	544.98
774.397	545.716
780.363	546.302
786.325	546.551
792.281	546.388
798.234	545.936
804.181	545.268
810.124	544.539
816.06	544.27
821.993	545.885
827.922	547.95
833.846	549.85
839.764	551.467
845.678	553.737
851.588	554.961
857.492	553.666
863.392	550.451
869.287	547.104
875.178	545.558
881.063	545.285
886.945	549.094
892.822	552.984
898.694	555.82
904.56	558.95
910.424	564.943
916.281	563.65
922.135	567.585
927.984	577.708
933.827	637.578
939.668	727.046
945.502	1010.09
951.332	2130.05
957.159	4120.58
962.979	4547.03
968.796	2621.23
974.607	1249.87
980.414	738.596
986.218	624.208
992.016	592.569
997.809	600.847
1003.6	619.453
1009.38	671.328
1015.16	718.742
1020.94	746.147
1026.71	730.253
1032.48	709.021
1038.24	687.911
1043.99	673.026
1049.75	673.033
1055.5	700.177
1061.24	750.249
1066.98	721.094
1072.71	669.153
1078.44	645.677
1084.17	619.668
1089.89	592.302
1095.61	571.582
1101.32	558.406
1107.03	551.221
1112.73	547.839
1118.43	547.703
1124.12	548.46
1129.81	545.531
1135.5	543.391
1141.18	539.049
1146.86	536.581
1152.53	535.833
1158.2	536.865
1163.86	536.49
1169.52	534.286
1175.17	533.124
1180.83	531.744
1186.47	529.474
1192.11	527.783
1197.75	527.356
1203.38	527.746
1209.01	529.27
1214.63	531.276
1220.25	533.359
1225.87	534.21
1231.48	533.891
1237.09	530.398
1242.69	523.916
1248.29	517.737
1253.88	512.98
1259.47	509.453
1265.05	507.17
1270.63	506.24
1276.21	506.894
1281.78	507.767
1287.35	507.606
1292.91	506.009
1298.47	508.087
1304.03	509.991
1309.58	510.736
1315.13	510.077
1320.67	508.477
1326.2	507.114
1331.74	506.144
1337.27	503.548
1342.79	501.039
1348.31	498.93
1353.83	497.69
1359.34	497.206
1364.85	497.21
1370.35	498.149
1375.85	499.32
1381.35	500.456
1386.84	500.087
1392.32	498.901
1397.81	497.308
1403.29	496.374
1408.76	495.978
1414.23	496.172
1419.7	496.565
1425.16	495.403
1430.61	492.886
1436.07	490.634
1441.52	488.411
1446.96	486.519
1452.4	485.044
1457.84	484.402
1463.27	484.703
1468.7	485.326
1474.12	484.824
1479.55	483.513
1484.96	481.821
1490.37	479.522
1495.78	477.083
1501.18	474.965
1506.58	473.263
1511.98	473.04
1517.37	474.342
1522.76	476.557
1528.14	477.188
1533.52	476.87
1538.9	476.081
1544.27	475.478
1549.63	475.896
1555	475.729
1560.35	472.951
1565.71	469.927
1571.06	467.482
1576.41	465.651
1581.75	464.262
1587.09	463.312
1592.42	462.784
1597.75	462.965
1603.08	463.912
1608.4	464.981
1613.72	464.986
1619.03	464.293
1624.34	462.941
1629.65	461.135
1634.95	458.528
1640.25	454.071
1645.54	449.292
1650.83	446.175
1656.12	445.765
1661.4	446.238
1666.68	446.631
1671.96	446.554
1677.23	446.148
1682.49	445.172
1687.75	441.8
1693.01	439.225
1698.27	437.106
1703.52	434.957
1708.77	432.937
1714.01	430.305
1719.25	427.731
1724.48	425.609
1729.71	424.84
1734.94	425.137
1740.16	426.446
1745.38	427.416
1750.6	427.623
1755.81	426.96
1761.02	425.177
1766.22	422.662
1771.42	421.799
1776.62	423.457
1781.81	426.635
1787	428.991
1792.18	427.004
1797.36	422.596
1802.54	417.065
1807.71	411.55
1812.88	406.72
1818.05	403.052
1823.21	402.452
1828.36	403.033
1833.52	403.758
1838.67	404.496
1843.81	404.975
1848.95	404.861
1854.09	404.341
1859.23	405.812
1864.36	407.847
1869.48	409.365
1874.61	408.78
1879.73	405.557
1884.84	405.159
1889.95	404.663
1895.06	403.212
1900.17	401.158
1905.27	398.743
1910.36	395.727
1915.45	392.592
1920.54	389.611
1925.63	387.266
1930.71	385.784
1935.79	384.472
1940.86	383.22
1945.93	381.654
1951	379.992
1956.06	378.204
1961.12	376.377
1966.18	374.845
1971.23	373.91
1976.28	373.449
1981.32	372.198
1986.36	370.607
1991.4	368.814
1996.43	366.99
2001.46	365.186
2006.48	363.439
2011.51	362.082
2016.52	361.326
2021.54	361.278
2026.55	361.198
2031.56	360.754
2036.56	359.828
2041.56	358.52
2046.56	356.47
2051.55	354.295
2056.54	352.304
2061.52	351.764
2066.51	351.115
2071.48	350.33
2076.46	348.694
2081.43	347.107
2086.4	345.606
2091.36	343.557
2096.32	341.57
2101.28	340.962
2106.23	342.133
2111.18	342.732
2116.12	341.701
2121.06	339.214
2126	336.448
2130.94	334.797
2135.87	334.255
2140.79	335.074
2145.72	336.012
2150.64	335.302
2155.56	333.07
2160.47	329.531
2165.38	325.348
2170.28	320.75
2175.19	318.29
2180.09	319.624
2184.98	322.383
2189.87	323.556
2194.76	323.694
2199.65	322.78
2204.53	320.935
2209.4	318.433
2214.28	314.866
2219.15	311.293
2224.02	309.03
2228.88	307.672
2233.74	307.018
2238.6	306.724
2243.45	307.562
2248.3	308.373
2253.14	308.66
2257.99	307.317
2262.83	305.39
2267.66	302.808
2272.49	299.576
2277.32	295.663
2282.15	292.389
2286.97	292.142
2291.79	294.381
2296.6	296.943
2301.41	297.609
2306.22	296.575
2311.02	294.498
2315.83	291.505
2320.62	287.75
2325.42	284.972
2330.21	284.119
2335	284.845
2339.78	285.982
2344.56	285.172
2349.34	283.902
2354.11	282.956
2358.88	282.821
2363.65	282.797
2368.41	282.765
2373.17	282.744
2377.93	282.562
2382.68	281.968
2387.43	281.225
2392.17	280.415
2396.92	279.679
2401.66	279.09
2406.39	278.356
2411.13	276.329
2415.85	274.583
2420.58	273.28
2425.3	272.093
2430.02	271.006
2434.74	270.037
2439.45	269.1
2444.16	268.207
2448.86	266.852
2453.57	264.971
2458.27	263.215
2462.96	262.38
2467.65	261.434
2472.34	260.9
2477.03	260.806
2481.71	260.79
2486.39	260.734
2491.07	261.498
2495.74	261.981
2500.41	261.91
2505.07	261.028
2509.74	258.906
2514.4	255.92
2519.05	252.991
2523.7	250.824
2528.35	249.381
2533	248.779
2537.64	247.474
2542.28	251.778
2546.92	252.637
2551.55	253.11
2556.18	250.952
2560.81	247.343
2565.43	244.037
2570.05	241.238
2574.67	240.478
2579.28	240.314
2583.89	240.03
2588.5	239.695
2593.1	239.285
2597.7	238.796
2602.3	238.259
2606.89	237.777
2611.48	237.12
2616.07	236.119
2620.66	235.553
2625.24	234.077
2629.82	233.396
2634.39	233.647
2638.96	231.927
2643.53	230.527
2648.09	229.42
2652.66	227.964
2657.21	225.867
2661.77	223.221
2666.32	221.499
2670.87	220.502
2675.42	221.822
2679.96	222.524
2684.5	223.211
2689.04	224.921
2693.57	225.438
2698.1	224.619
2702.63	223.797
2707.15	223.374
2711.67	223.086
2716.19	222.832
2720.7	222.571
2725.21	222.196
2729.72	221.572
2734.23	220.47
2738.73	217.34
2743.23	215.091
2747.72	213.946
2752.22	213.2
2756.7	212.714
2761.19	213.045
2765.67	213.435
2770.15	212.514
2774.63	210.981
2779.1	209.873
2783.57	209.303
2788.04	208.667
2792.51	207.389
2796.97	205.422
2801.43	205.177
2805.88	205.851
2810.33	206.324
2814.78	206.522
2819.23	206.316
2823.67	205.46
2828.11	205.595
2832.55	205.307
2836.98	203.669
2841.41	200.992
2845.84	200.739
2850.26	201.364
2854.69	201.723
2859.1	201.673
2863.52	201.011
2867.93	200.653
2872.34	200.499
2876.75	200.291
2881.15	200.344
2885.55	200.904
2889.95	198.158
2894.34	196.478
2898.73	195.772
2903.12	198.627
2907.5	199.741
2911.89	197.383
2916.27	195.922
2920.64	193.815
2925.01	191.531
2929.38	190.388
2933.75	189.964
2938.12	189.578
2942.48	189.465
2946.84	189.846
2951.19	190.988
2955.54	192.29
2959.89	192.412
2964.24	190.365
2968.58	186.365
2972.92	184.258
2977.26	182.779
2981.59	182.261
2985.92	183.272
2990.25	184.329
2994.58	185.124
2998.9	185.645
3003.22	185.927
3007.54	185.965
3011.85	185.734
3016.16	185.268
3020.47	184.506
3024.77	183.377
3029.07	182.432
3033.37	181.281
3037.67	179.82
3041.96	178.421
3046.25	177.315
3050.54	175.639
3054.82	174.087
3059.11	173.288
3063.38	173.168
3067.66	174.444
3071.93	175.17
3076.2	172.919
3080.47	171.61
3084.73	170.796
3088.99	170.271
3093.25	170.092
3097.51	170.299
3101.76	170.664
3106.01	171.2
3110.26	171.745
3114.5	172.074
3118.74	171.737
3122.98	170.687
3127.22	169.23
3131.45	168.699
3135.68	169.483
3139.91	170.277
3144.13	171.003
3148.35	171.955
3152.57	171.644
3156.78	170.36
3161	167.576
3165.21	165.52
3169.41	164.758
3173.62	164.177
3177.82	163.448
3182.02	162.78
3186.21	162.075
3190.4	161.374
3194.59	160.721
3198.78	160.383
3202.96	160.065
3207.15	159.674
3211.33	159.148
3215.5	158.307
3219.67	156.357
3223.84	154.759
3228.01	153.131
3232.18	153.768
3236.34	153.979
3240.5	153.99
3244.65	153.952
3248.81	153.734
3252.96	153.834
3257.11	154.498
3261.25	156.722
3265.39	158.416
3269.53	158.992
3273.67	158.36
3277.8	156.558
3281.94	153.988
3286.06	151.221
3290.19	150.044
3294.31	149.189
3298.43	148.488
3302.55	147.635
3306.67	146.853
3310.78	145.717
3314.89	145.13
3319	146.353
3323.1	148.327
3327.2	150.87
3331.3	151.936
3335.39	151.999
3339.49	152.433
3343.58	151.168
3347.67	149.702
3351.75	148.588
3355.83	147.986
3359.91	147.356
3363.99	146.732
3368.06	146.174
3372.14	145.181
3376.2	143.42
3380.27	141.778
3384.33	140.325
3388.39	139.603
3392.45	139.297
3396.51	139.382
3400.56	139.781
3404.61	140.505
3408.66	141.78
3412.7	143.109
3416.74	142.676
3420.78	140.817
3424.82	140.317
3428.85	138.736
3432.88	137.232
3436.91	136.068
3440.94	135.317
3444.96	134.768
3448.98	134.52
3453	134.595
3457.02	134.777
3461.03	135.309
3465.04	135.929
3469.05	136.524
3473.05	136.814
3477.05	136.634
3481.05	136.019
3485.05	135.133
3489.04	134.288
3493.04	134.161
3497.03	134.496
3501.01	134.85
3505	135.452
3508.98	136.243
3512.96	137.156
3516.93	137.977
3520.9	138.566
3524.88	138.343
3528.84	140.764
3532.81	139.745
3536.77	137.928
3540.73	136.757
3544.69	135.938
3548.65	135.442
3552.6	134.495
3556.55	131.289
3560.5	134.754
3564.44	135.54
3568.38	135.921
3572.32	136.178
3576.26	134.879
3580.2	132.565
3584.13	130.533
3588.06	129.955
3591.98	128.692
3595.91	127.656
3599.83	127.986
3603.75	127.149
3607.67	125.362
3611.58	123.203
3615.49	120.858
3619.4	118.726
3623.31	117.614
3627.21	116.935
3631.11	116.769
3635.01	116.825
3638.91	116.005
3642.8	115.505
3646.69	116.541
3650.58	118.295
3654.47	119.844
3658.35	121.132
3662.24	122.112
3666.11	122.747
3669.99	123.071
3673.86	122.828
3677.74	122.383
3681.6	123.07
3685.47	121.585
3689.34	119.621
3693.2	119.349
3697.06	119.633
3700.91	119.093
3704.77	116.914
3708.62	115.994
3712.47	116.011
3716.31	116.557
3720.16	117.142
3724	117.472
3727.84	117.462
3731.67	117.032
3735.51	116.241
3739.34	115.222
3743.17	114.119
3747	112.952
3750.82	111.75
3754.64	111.085
3758.46	110.706
3762.28	110.897
3766.09	112.123
3769.9	114.752
3773.71	117.205
3777.52	117.852
3781.33	117.189
3785.13	116.004
3788.93	115.094
3792.72	114.403
3796.52	113.23
3800.31	111.78
3804.1	110.537
3807.89	109.903
3811.68	109.714
3815.46	109.835
3819.24	110.282
3823.02	110.978
3826.79	111.875
3830.56	112.624
3834.34	112.333
3838.1	112.025
3841.87	112.308
3845.63	113.141
3849.39	109.983
3853.15	108.023
3856.91	107.792
3860.66	108.574
3864.42	107.143
3868.16	107.004
3871.91	107.001
3875.66	107.219
3879.4	107.802
3883.14	108.056
3886.88	107.683
3890.61	106.958
3894.34	106.135
3898.07	105.323
3901.8	104.726
3905.53	104.454
3909.25	104.604
3912.97	104.527
3916.69	103.352
3920.4	102.742
3924.12	103.241
3927.83	103.624
3931.54	103.777
3935.24	102.206
3938.95	100.673
3942.65	99.7898
3946.35	98.6664
3950.05	97.4253
3953.74	97.4784
3957.44	98.3545
3961.13	99.2942
3964.81	100.654
3968.5	102.145
3972.18	103.463
3975.86	104.55
3979.54	105.117
3983.22	105.08
3986.89	104.241
3990.56	102.786
3994.23	100.36
3997.9	96.611
3999.73	94.162