File: Data/Raman/raw/bu24-ore1_150 (500nm)_633nm_edge_25%_x100_vis_h30um_30sx2_01.txt
#Acq. time (s)=	30
#Accumulations=	2
#Range (cm-¹)=	100...4000
#Windows=	1
#Auto scanning=	Off
#Autofocus=	Off
#Macrospot=	Off
#AutoExposure=	Off
#Spike filter=	Multiple accum.
#Delay time (s)=	2
#Binning=	1
#Readout mode=	Signal
#DeNoise=	Standard
#ICS correction=	On
#Dark correction=	Off
#Inst. Process=	Off
#Detector Gain=	Best Dynamic
#Detector ADC=	50 kHz HS
#Detector temperature (°C)=	-60.09
#Instrument=	LabRAM HR Evol
#Detector=	SIN-EM FIVIS
#Objective=	x100_VIS
#Grating=	150 (500nm)
#ND Filter=	25%
#Laser=	633nm_Edge
#Hole=	30.0125
#Temperature=	0
#Range=	Visible
#StageXY=	75x50mm Scan+
#StageZ=	Z motor
#X (µm)=	0
#Y (µm)=	0
#Z (µm)=	59.1
#Full time(mm:ss)=	1:04
#Project=	20_10_27
#Sample=	BU24
#Site=
#Title=	BU24-Ore1_150 (500nm)_633nm_Edge_25%_x100_VIS_H30um_30sX2
#Remark=
#Date=	27.10.2020 18:53
#Acquired=	27.10.2020 18:53:26
100.764	473.466
107.281	481.105
113.791	501.172
120.297	545.613
126.797	687.736
133.291	792.378
139.78	787.881
146.264	612.533
152.741	514.199
159.214	498.994
165.682	525.887
172.144	529.739
178.601	530.775
185.053	522.938
191.499	509.928
197.939	513.787
204.374	549.94
210.805	568.45
217.23	538.962
223.648	503.85
230.063	511.087
236.472	550.563
242.874	618.908
249.273	690.196
255.667	719.32
262.053	780
268.436	989.734
274.813	1205.97
281.185	999.264
287.552	771.831
293.913	701.945
300.27	679.472
306.62	623.589
312.965	595.08
319.306	578.311
325.64	548.35
331.971	512.375
338.295	483.514
344.614	472.232
350.93	467.269
357.238	463.62
363.542	472.252
369.842	478.27
376.135	497.958
382.423	521.162
388.706	537.928
394.984	531.159
401.258	516.733
407.526	500.899
413.789	486.933
420.046	478.082
426.299	482.605
432.546	494.568
438.788	508.196
445.025	524
451.257	542.386
457.484	560.578
463.706	578.557
469.923	603.225
476.135	632.31
482.342	659.391
488.544	668.713
494.741	658.276
500.933	626.323
507.12	599.456
513.3	594.338
519.477	628.743
525.649	685.554
531.815	708.637
537.976	652.154
544.133	590.107
550.285	550.846
556.43	525.862
562.572	512.212
568.709	503.981
574.84	501.241
580.967	503.012
587.09	508.839
593.205	521.617
599.318	539.77
605.424	560.22
611.527	595.176
617.623	635.639
623.716	691.922
629.802	747.338
635.884	776.549
641.962	749.037
648.034	692.757
654.101	637.941
660.165	594.594
666.222	568.553
672.274	554.011
678.324	546.047
684.366	543.888
690.404	546.44
696.438	552.792
702.466	559.592
708.491	567.504
714.51	574.125
720.523	581.985
726.533	591.659
732.537	603.261
738.537	617.963
744.531	633.86
750.521	652.769
756.507	674.76
762.487	692.122
768.463	709.088
774.434	724.074
780.4	735.243
786.362	738.964
792.319	743.583
798.269	746.451
804.217	753.392
810.159	774.78
816.097	811.032
822.03	872.457
827.958	917.594
833.881	954.289
839.801	1013.71
845.714	1146
851.624	1377.68
857.529	1805.41
863.428	2640.93
869.324	4118.73
875.215	5911.86
881.1	4638.75
886.982	2320.43
892.858	1230.1
898.73	810.178
904.597	605.96
910.459	508.086
916.318	445.823
922.171	405.544
928.02	374.261
933.864	352.338
939.703	336.753
945.539	324.713
951.368	315.238
957.194	307.187
963.014	301.377
968.832	296.156
974.643	290.969
980.45	285.942
986.253	279.742
992.051	273.156
997.844	266.979
1003.63	259.189
1009.42	254.842
1015.2	253.65
1020.97	255.903
1026.74	258.233
1032.51	260.092
1038.27	262.541
1044.03	263.283
1049.78	263.198
1055.53	259.022
1061.27	254.803
1067.01	250.057
1072.75	248.539
1078.48	247.715
1084.2	246.392
1089.92	244.898
1095.64	244.949
1101.35	244.15
1107.06	241.084
1112.77	239.263
1118.46	239.816
1124.16	239.899
1129.85	236.719
1135.53	232.945
1141.22	229.344
1146.89	226.285
1152.56	224.679
1158.23	222.98
1163.9	222.005
1169.56	220.994
1175.21	220.235
1180.86	218.636
1186.51	215.717
1192.15	213.365
1197.78	211.254
1203.42	209.345
1209.04	207.749
1214.67	206.726
1220.29	205.788
1225.9	205.745
1231.51	205.388
1237.12	204.317
1242.72	202.825
1248.32	198.719
1253.92	194.755
1259.5	191.132
1265.09	188.082
1270.67	186.579
1276.25	187.013
1281.82	186.488
1287.39	185.133
1292.95	183.752
1298.51	182.829
1304.06	181.829
1309.61	179.735
1315.16	178.927
1320.7	178.067
1326.24	177.623
1331.77	177.545
1337.3	177.03
1342.83	176.4
1348.35	176.21
1353.86	175.478
1359.37	172.611
1364.88	168.985
1370.39	166.878
1375.89	166.636
1381.38	169.484
1386.87	171.034
1392.36	171.805
1397.84	172.849
1403.32	173.333
1408.79	172.356
1414.26	171.247
1419.73	170.353
1425.19	170.05
1430.65	169.698
1436.1	169.666
1441.55	169.367
1447	168.735
1452.44	167.229
1457.87	164.773
1463.31	163.048
1468.73	161.658
1474.16	160.853
1479.58	160.498
1484.99	160.804
1490.41	160.832
1495.81	161.188
1501.22	161.92
1506.62	162.497
1512.01	162.113
1517.4	160.001
1522.79	157.596
1528.17	155.894
1533.55	155.098
1538.93	155.722
1544.3	155.276
1549.67	154.386
1555.03	152.691
1560.39	151.75
1565.74	150.371
1571.09	149.159
1576.44	148.106
1581.78	147.517
1587.12	147.553
1592.45	146.964
1597.78	146.656
1603.11	145.791
1608.43	145.575
1613.75	144.792
1619.07	143.699
1624.38	142.181
1629.68	141.534
1634.98	140.58
1640.28	139.124
1645.58	137.837
1650.87	137.065
1656.15	136.932
1661.44	136.493
1666.71	135.933
1671.99	134.904
1677.26	135.079
1682.53	133.646
1687.79	131.859
1693.05	131.869
1698.3	132.701
1703.55	135.243
1708.8	138.471
1714.04	140.223
1719.28	140.304
1724.51	138.77
1729.75	136.85
1734.97	132.718
1740.2	128.846
1745.42	126.069
1750.63	123.025
1755.84	120.485
1761.05	117.887
1766.25	115.413
1771.45	113.595
1776.65	110.403
1781.84	107.267
1787.03	105.24
1792.21	104.194
1797.39	103.904
1802.57	103.097
1807.74	101.827
1812.91	101.733
1818.08	101.469
1823.24	100.165
1828.39	98.1143
1833.55	96.3383
1838.7	94.7791
1843.84	92.7002
1848.99	91.5703
1854.12	91.0283
1859.26	91.5576
1864.39	92.5982
1869.52	92.9604
1874.64	92.873
1879.76	92.9393
1884.87	93.2608
1889.98	90.896
1895.09	88.3891
1900.2	87.4009
1905.3	87.0617
1910.39	86.9831
1915.49	87.8496
1920.57	88.3787
1925.66	88.7185
1930.74	88.5815
1935.82	88.2863
1940.89	88.1467
1945.96	88.3174
1951.03	88.2602
1956.09	88.0237
1961.15	87.3133
1966.21	86.335
1971.26	85.9319
1976.31	85.8818
1981.35	85.439
1986.39	85.1382
1991.43	84.2166
1996.46	83.1029
2001.49	82.1927
2006.52	81.1633
2011.54	80.6187
2016.56	81.1935
2021.57	81.1504
2026.58	80.5863
2031.59	80.2163
2036.59	80.0885
2041.59	79.1826
2046.59	78.8553
2051.58	78.5929
2056.57	77.5734
2061.55	76.5631
2066.54	76.6076
2071.51	76.4594
2076.49	76.5004
2081.46	76.9598
2086.43	77.1444
2091.39	77.064
2096.35	76.4726
2101.3	76.0681
2106.26	75.7764
2111.21	75.9143
2116.15	76.4032
2121.09	75.7613
2126.03	74.7106
2130.97	74.2467
2135.9	73.5146
2140.83	72.915
2145.75	72.7247
2150.67	73.1066
2155.59	72.3585
2160.5	70.8117
2165.41	70.2138
2170.31	70.5304
2175.22	72.0899
2180.12	73.0266
2185.01	72.9579
2189.9	73.8589
2194.79	73.5279
2199.68	72.8906
2204.56	72.1519
2209.43	70.6256
2214.31	69.1485
2219.18	67.9342
2224.05	66.8759
2228.91	66.7817
2233.77	66.7215
2238.63	66.7376
2243.48	66.505
2248.33	66.65
2253.17	67.2579
2258.02	67.3662
2262.86	67.4605
2267.69	67.5636
2272.52	67.6111
2277.35	67.6528
2282.18	67.6755
2287	67.7103
2291.82	67.744
2296.63	67.7809
2301.44	67.7601
2306.25	67.4088
2311.05	66.5339
2315.86	65.8994
2320.65	65.1749
2325.45	64.1175
2330.24	64.1595
2335.03	64.1139
2339.81	64.0209
2344.59	63.9609
2349.37	63.2703
2354.14	63.0203
2358.91	62.7366
2363.67	62.7307
2368.44	62.2921
2373.2	61.5717
2377.95	60.8596
2382.71	60.1687
2387.46	59.786
2392.2	59.4416
2396.95	59.2833
2401.68	59.6685
2406.42	59.6855
2411.15	60.2847
2415.88	60.9423
2420.61	61.0457
2425.33	59.8077
2430.05	58.937
2434.77	58.6089
2439.48	58.2725
2444.19	58.7849
2448.89	59.3897
2453.6	59.0894
2458.29	58.6971
2462.99	57.3305
2467.68	56.4111
2472.37	56.2518
2477.06	56.9734
2481.74	55.9901
2486.42	57.03
2491.1	57.5575
2495.77	58.0311
2500.44	57.5869
2505.1	56.7321
2509.76	55.5808
2514.42	54.7433
2519.08	54.598
2523.73	54.5149
2528.38	54.4104
2533.03	54.5608
2537.67	54.7305
2542.31	55.5204
2546.95	56.1115
2551.58	56.2383
2556.21	55.6803
2560.84	54.8046
2565.46	53.7018
2570.08	52.6684
2574.7	53.1523
2579.31	53.0116
2583.92	51.7138
2588.53	50.6789
2593.13	52.54
2597.73	52.1256
2602.33	52.1495
2606.92	52.1901
2611.51	51.9588
2616.1	51.6538
2620.68	51.5072
2625.26	51.789
2629.84	51.7799
2634.42	50.887
2638.99	50.254
2643.56	49.9538
2648.12	49.8727
2652.68	49.902
2657.24	50.1281
2661.8	50.2946
2666.35	50.1224
2670.9	49.7775
2675.45	49.2472
2679.99	48.7212
2684.53	47.8915
2689.06	47.5444
2693.6	47.347
2698.13	47.3526
2702.66	47.3747
2707.18	47.4364
2711.7	47.5468
2716.22	47.6232
2720.73	47.6829
2725.24	47.7368
2729.75	47.6585
2734.26	47.5754
2738.76	47.4703
2743.25	47.3604
2747.75	47.1418
2752.24	46.1437
2756.73	45.362
2761.22	45.3094
2765.7	45.3665
2770.18	45.5456
2774.66	45.9023
2779.13	45.8247
2783.6	46.0922
2788.07	47.0066
2792.53	47.715
2797	48.3578
2801.45	48.771
2805.91	49.0542
2810.36	49.1559
2814.81	49.2202
2819.26	45.0033
2823.7	37.8756
2828.14	48.945
2832.57	48.1589
2837.01	47.2102
2841.44	45.6032
2845.87	45.2704
2850.29	45.4076
2854.71	45.7481
2859.13	46.209
2863.55	46.6298
2867.96	46.9407
2872.37	46.959
2876.77	46.7021
2881.18	46.4915
2885.58	46.7223
2889.97	47.128
2894.37	47.0641
2898.76	46.0918
2903.15	45.6676
2907.53	44.9442
2911.91	44.4584
2916.29	43.6912
2920.67	43.1817
2925.04	43.0986
2929.41	42.9029
2933.78	43.7595
2938.14	44.0035
2942.5	44.3198
2946.86	44.869
2951.22	45.3253
2955.57	44.9409
2959.92	44.5423
2964.26	44.1968
2968.61	44.0825
2972.95	44.1043
2977.28	44.1891
2981.62	44.3443
2985.95	44.5646
2990.28	44.7582
2994.6	44.0939
2998.93	43.9183
3003.25	43.7208
3007.56	43.7821
3011.88	44.431
3016.19	45.0436
3020.49	45.7198
3024.8	46.4417
3029.1	46.8528
3033.4	45.9395
3037.7	44.7518
3041.99	43.6172
3046.28	42.6328
3050.57	42.8573
3054.85	43.6724
3059.13	43.7819
3063.41	43.7038
3067.69	43.5119
3071.96	43.262
3076.23	43.49
3080.5	43.9404
3084.76	44.493
3089.02	44.4227
3093.28	44.3465
3097.53	44.2715
3101.79	44.1996
3106.04	43.6102
3110.28	43.0009
3114.53	42.5497
3118.77	43.0148
3123.01	43.6617
3127.24	44.3886
3131.47	44.8123
3135.7	44.3978
3139.93	43.8523
3144.15	43.6603
3148.38	43.1752
3152.59	41.788
3156.81	41.2272
3161.02	41.3432
3165.23	42.2167
3169.44	43.0476
3173.64	42.5624
3177.84	42.1342
3182.04	41.9823
3186.24	43.0475
3190.43	42.4123
3194.62	41.4864
3198.81	41.3665
3202.99	42.1531
3207.17	43.0791
3211.35	43.6922
3215.53	44.4318
3219.7	43.5545
3223.87	42.9731
3228.04	42.8983
3232.2	43.1045
3236.36	43.4597
3240.52	43.8415
3244.68	44.2467
3248.83	44.6433
3252.98	45.0179
3257.13	45.0411
3261.28	45.0483
3265.42	44.8764
3269.56	44.5693
3273.7	43.8905
3277.83	43.5904
3281.96	43.1268
3286.09	42.7649
3290.22	42.9804
3294.34	43.698
3298.46	43.7989
3302.58	43.6049
3306.69	43.0885
3310.8	42.4632
3314.91	42.6458
3319.02	42.8088
3323.12	43.0971
3327.23	43.4347
3331.32	43.4959
3335.42	44.1411
3339.51	43.0943
3343.6	41.4213
3347.69	41.27
3351.78	42.9898
3355.86	44.2283
3359.94	44.4905
3364.02	44.7249
3368.09	44.7783
3372.16	44.5042
3376.23	44.0842
3380.29	43.8631
3384.36	43.6822
3388.42	43.3433
3392.48	42.3336
3396.53	42.619
3400.58	43.2145
3404.63	43.7565
3408.68	43.7789
3412.73	43.6987
3416.77	41.5577
3420.81	43.181
3424.84	45.8162
3428.88	45.9113
3432.91	44.6223
3436.94	43.5094
3440.96	42.0461
3444.99	41.6922
3449.01	42.2165
3453.03	42.3737
3457.04	43.0842
3461.05	43.9765
3465.06	43.6136
3469.07	43.4966
3473.08	43.9308
3477.08	44.2514
3481.08	44.3387
3485.07	44.906
3489.07	44.5528
3493.06	43.7011
3497.05	43.1324
3501.04	42.9667
3505.02	43.1855
3509	43.9416
3512.98	43.6817
3516.96	43.4262
3520.93	43.7862
3524.9	44.5714
3528.87	43.8258
3532.83	43.2647
3536.8	43.1317
3540.76	43.5217
3544.71	43.5035
3548.67	42.8802
3552.62	42.9309
3556.57	43.4124
3560.52	44.0338
3564.47	44.0942
3568.41	44.0252
3572.35	44.5334
3576.29	44.8338
3580.22	44.6108
3584.15	43.6135
3588.08	42.8675
3592.01	42.3085
3595.93	41.2163
3599.85	41.7823
3603.77	42.7274
3607.69	43.201
3611.61	43.5627
3615.52	43.9382
3619.43	42.5738
3623.33	42.7604
3627.24	42.7211
3631.14	42.8625
3635.04	43.133
3638.93	43.3118
3642.83	43.1057
3646.72	42.7684
3650.61	42.4275
3654.49	42.1443
3658.38	41.913
3662.26	41.7534
3666.14	41.6744
3670.01	41.8433
3673.89	42.0214
3677.76	42.1895
3681.63	41.259
3685.5	40.9552
3689.36	40.8814
3693.22	41.5071
3697.08	41.9401
3700.94	42.8204
3704.79	43.7797
3708.64	44.0911
3712.49	44.5011
3716.34	44.7698
3720.18	44.0023
3724.02	42.7711
3727.86	42.4008
3731.7	42.2557
3735.53	41.4803
3739.36	40.8723
3743.19	40.8752
3747.02	41.0151
3750.84	41.8857
3754.66	42.29
3758.48	42.1619
3762.3	42.9218
3766.12	44.0785
3769.93	44.0226
3773.74	43.9668
3777.54	43.9237
3781.35	43.9045
3785.15	43.9567
3788.95	44.0338
3792.75	44.1385
3796.54	44.2943
3800.34	44.2389
3804.13	44.1557
3807.91	44.0501
3811.7	42.4671
3815.48	43.1569
3819.26	43.0923
3823.04	42.9444
3826.82	43.2942
3830.59	43.366
3834.36	43.0658
3838.13	43.4258
3841.89	43.9906
3845.66	44.2099
3849.42	44.3108
3853.18	44.3421
3856.93	43.6503
3860.69	43.0013
3864.44	41.9723
3868.19	41.7627
3871.93	42.3043
3875.68	42.7502
3879.42	42.4109
3883.16	42.1401
3886.9	42.0321
3890.63	42.4308
3894.37	43.3534
3898.1	43.913
3901.82	43.2526
3905.55	42.1652
3909.27	42.2938
3912.99	42.8285
3916.71	42.2512
3920.43	42.5497
3924.14	43.6235
3927.85	42.9086
3931.56	41.9645
3935.27	42.0744
3938.97	42.1071
3942.67	42.5937
3946.37	43.0258
3950.07	43.5097
3953.77	44.1326
3957.46	44.756
3961.15	45.1218
3964.84	44.765
3968.52	43.2179
3972.2	42.7172
3975.89	42.6569
3979.56	42.0254
3983.24	41.5468
3986.92	41.7938
3990.59	42.3593
3994.26	43.8993
3997.92	45.7476
3999.76	45.0074