File: Data/Raman/raw/bu24-ore3-top_grain_150 (500nm)_633nm_edge_100%_x100_vis_h30um_10sx2_01.txt
#Acq. time (s)=	10
#Accumulations=	2
#Range (cm-¹)=	100...4000
#Windows=	1
#Auto scanning=	Off
#Autofocus=	Off
#Macrospot=	Off
#AutoExposure=	Off
#Spike filter=	Multiple accum.
#Delay time (s)=	2
#Binning=	1
#Readout mode=	Signal
#DeNoise=	Standard
#ICS correction=	On
#Dark correction=	Off
#Inst. Process=	Off
#Detector Gain=	Best Dynamic
#Detector ADC=	50 kHz HS
#Detector temperature (°C)=	-60.09
#Instrument=	LabRAM HR Evol
#Detector=	SIN-EM FIVIS
#Objective=	x20_VIS
#Grating=	150 (500nm)
#ND Filter=	100%
#Laser=	633nm_Edge
#Hole=	30.0125
#Temperature=	0
#Range=	Visible
#StageXY=	75x50mm Scan+
#StageZ=	Z motor
#X (µm)=	0
#Y (µm)=	0
#Z (µm)=	52.5
#Full time(s)=	24
#Project=	20_10_27
#Sample=	BU24
#Site=
#Title=	BU24-Ore3-top_grain_150 (500nm)_633nm_Edge_100%_x20_VIS_H30um_10sX2
#Remark=
#Date=	27.10.2020 19:07
#Acquired=	27.10.2020 19:07:31
100.764	740.186
107.281	778.79
113.791	838.586
120.297	946.761
126.797	1223.68
133.291	1556.4
139.78	1773.89
146.264	1049.88
152.741	834.832
159.214	849.076
165.682	994.114
172.144	919.488
178.601	899.69
185.053	864.103
191.499	799.296
197.939	823.307
204.374	932.615
210.805	1027.53
217.23	830.149
223.648	761.272
230.063	791.317
236.472	871.455
242.874	994.164
249.273	1078.05
255.667	1100.04
262.053	1258.82
268.436	1501.55
274.813	1525.04
281.185	1269.1
287.552	1109.25
293.913	1035.77
300.27	1026.75
306.62	1002.86
312.965	918.143
319.306	892.241
325.64	839.105
331.971	778.252
338.295	745.274
344.614	740.707
350.93	750.795
357.238	761.115
363.542	765.929
369.842	788.825
376.135	845.303
382.423	945.314
388.706	1054.84
394.984	1099.95
401.258	1085.33
407.526	963.872
413.789	861.521
420.046	817.368
426.299	802.257
432.546	803.395
438.788	811.889
445.025	826.092
451.257	838.119
457.484	863.984
463.706	896.055
469.923	938.43
476.135	971.079
482.342	994.087
488.544	1011.39
494.741	996.555
500.933	983.495
507.12	994.926
513.3	1033.51
519.477	1115.07
525.649	1226.85
531.815	1241.32
537.976	1116
544.133	986.684
550.285	910.524
556.43	860.585
562.572	830.486
568.709	812.633
574.84	797.277
580.967	792.925
587.09	797.362
593.205	814.09
599.318	834.852
605.424	862.713
611.527	901.072
617.623	955.855
623.716	1017.94
629.802	1075.91
635.884	1055.53
641.962	994.869
648.034	924.512
654.101	867.98
660.165	823.518
666.222	792.349
672.274	769.2
678.324	755.443
684.366	746.915
690.404	745.116
696.438	745.664
702.466	746.59
708.491	748.401
714.51	750.927
720.523	754.232
726.533	758.31
732.537	763.246
738.537	769.386
744.531	779.218
750.521	790.288
756.507	802.227
762.487	809.183
768.463	821.95
774.434	839.31
780.4	850.233
786.362	865.788
792.319	889.655
798.269	927.354
804.217	984.359
810.159	1073.24
816.097	1190.71
822.03	1311.95
827.958	1425.1
833.881	1475.43
839.801	1612.3
845.714	1989.36
851.624	2598.52
857.529	3720.9
863.428	5624.4
869.324	8483.25
875.215	8629.54
881.1	5439.05
886.982	2964.46
892.858	1835.87
898.73	1289.22
904.597	1016.53
910.459	838.448
916.318	750.431
922.171	693.256
928.02	649.796
933.864	616.632
939.703	583.822
945.539	562.992
951.368	548.045
957.194	535.918
963.014	524.142
968.832	513.926
974.643	502.891
980.45	491.034
986.253	478.946
992.051	469.827
997.844	463.77
1003.63	460.347
1009.42	457.558
1015.2	455.302
1020.97	453.38
1026.74	452.097
1032.51	451.18
1038.27	449.857
1044.03	447.867
1049.78	445.101
1055.53	443.283
1061.27	441.004
1067.01	437.801
1072.75	436.671
1078.48	436.315
1084.2	434.766
1089.92	430.808
1095.64	426.265
1101.35	421.753
1107.06	418.396
1112.77	415.039
1118.46	412.423
1124.16	410.913
1129.85	409.363
1135.53	406.127
1141.22	401.69
1146.89	396.81
1152.56	392.125
1158.23	386.761
1163.9	381.758
1169.56	378.297
1175.21	375.796
1180.86	374.495
1186.51	371.74
1192.15	370.41
1197.78	369.271
1203.42	369.484
1209.04	366.313
1214.67	362.162
1220.29	360.426
1225.9	356.533
1231.51	351.784
1237.12	347.17
1242.72	342.722
1248.32	339.612
1253.92	338.36
1259.5	336.363
1265.09	333.55
1270.67	330.625
1276.25	327.913
1281.82	325.499
1287.39	323.769
1292.95	322.427
1298.51	320.7
1304.06	319.051
1309.61	318.294
1315.16	318.221
1320.7	318.114
1326.24	317.482
1331.77	316.487
1337.3	314.567
1342.83	313.714
1348.35	312.874
1353.86	310.889
1359.37	308.338
1364.88	305.409
1370.39	302.04
1375.89	298.177
1381.38	295.377
1386.87	294.108
1392.36	294.229
1397.84	295.241
1403.32	294.895
1408.79	294.534
1414.26	294
1419.73	293.138
1425.19	286.421
1430.65	283.178
1436.1	290.72
1441.55	289.652
1447	287.362
1452.44	285.493
1457.87	281.189
1463.31	276.983
1468.73	275.692
1474.16	275.576
1479.58	276.28
1484.99	276.948
1490.41	277.363
1495.81	277.972
1501.22	277.889
1506.62	275.47
1512.01	271.549
1517.4	267.773
1522.79	264.997
1528.17	263.082
1533.55	261.307
1538.93	257.872
1544.3	256.823
1549.67	256.084
1555.03	255.023
1560.39	253.62
1565.74	251.733
1571.09	249.252
1576.44	248.373
1581.78	248.299
1587.12	247.443
1592.45	245.943
1597.78	244.013
1603.11	241.749
1608.43	239.514
1613.75	237.917
1619.07	237.184
1624.38	237.252
1629.68	237.132
1634.98	238.479
1640.28	240.408
1645.58	241.398
1650.87	238.779
1656.15	236.22
1661.44	235.272
1666.71	234.524
1671.99	233.648
1677.26	233.394
1682.53	233.528
1687.79	233.971
1693.05	236.55
1698.3	239.426
1703.55	242.386
1708.8	244.782
1714.04	246.268
1719.28	246.82
1724.51	245.745
1729.75	243.202
1734.97	239.382
1740.2	234.841
1745.42	229.605
1750.63	222.513
1755.84	215.434
1761.05	208.533
1766.25	201.044
1771.45	194.699
1776.65	189.339
1781.84	184.992
1787.03	182.518
1792.21	181.111
1797.39	180.027
1802.57	178.795
1807.74	177.224
1812.91	175.418
1818.08	173.225
1823.24	170.017
1828.39	167.622
1833.55	166.927
1838.7	166.576
1843.84	166.05
1848.99	164.263
1854.12	163.384
1859.26	163.328
1864.39	163.177
1869.52	162.72
1874.64	161.818
1879.76	160.834
1884.87	159.17
1889.98	157.379
1895.09	155.53
1900.2	153.74
1905.3	152.29
1910.39	151.11
1915.49	150.386
1920.57	149.784
1925.66	149.317
1930.74	148.944
1935.82	148.581
1940.89	148.165
1945.96	147.343
1951.03	146.621
1956.09	145.324
1961.15	143.917
1966.21	142.599
1971.26	141.831
1976.31	141.624
1981.35	141.949
1986.39	142.391
1991.43	142.796
1996.46	142.868
2001.49	141.849
2006.52	140.766
2011.54	139.701
2016.56	138.842
2021.57	137.743
2026.58	135.066
2031.59	133.779
2036.59	133.194
2041.59	132.795
2046.59	132.308
2051.58	130.794
2056.57	129.084
2061.55	127.399
2066.54	126.863
2071.51	127.199
2076.49	127.765
2081.46	128.405
2086.43	128.252
2091.39	125.56
2096.35	123.992
2101.3	123.483
2106.26	123.162
2111.21	122.573
2116.15	121.805
2121.09	120.812
2126.03	119.648
2130.97	118.545
2135.9	117.454
2140.83	116.608
2145.75	117.685
2150.67	117.242
2155.59	116.066
2160.5	113.706
2165.41	112.524
2170.31	114.918
2175.22	116.423
2180.12	115.943
2185.01	115.468
2189.9	114.682
2194.79	112.797
2199.68	111.125
2204.56	108.661
2209.43	106.924
2214.31	106.424
2219.18	107.202
2224.05	109.025
2228.91	108.423
2233.77	107.141
2238.63	106.164
2243.48	105.604
2248.33	105.273
2253.17	104.901
2258.02	104.543
2262.86	103.392
2267.69	101.902
2272.52	100.301
2277.35	98.7957
2282.18	98.0596
2287	98.0955
2291.82	98.208
2296.63	98.3805
2301.44	98.5948
2306.25	98.4718
2311.05	98.1846
2315.86	97.7622
2320.65	97.157
2325.45	96.352
2330.24	95.5702
2335.03	94.7717
2339.81	94.0789
2344.59	93.2586
2349.37	92.1778
2354.14	91.1612
2358.91	90.3682
2363.67	91.3373
2368.44	92.5738
2373.2	93.8086
2377.95	93.3191
2382.71	92.5269
2387.46	91.7721
2392.2	91.0724
2396.95	90.4532
2401.68	89.8521
2406.42	89.3056
2411.15	88.7698
2415.88	88.1257
2420.61	88.1736
2425.33	88.0253
2430.05	88.1337
2434.77	88.6131
2439.48	89.2542
2444.19	88.3281
2448.89	86.8901
2453.6	85.4926
2458.29	84.3368
2462.99	84.054
2467.68	84.2402
2472.37	84.9365
2477.06	85.7514
2481.74	86.3979
2486.42	86.2455
2491.1	86.0956
2495.77	85.8782
2500.44	84.4965
2505.1	82.9429
2509.76	81.3181
2514.42	80.2252
2519.08	79.9831
2523.73	79.9354
2528.38	79.386
2533.03	78.7227
2537.67	78.4298
2542.31	78.2849
2546.95	78.2518
2551.58	78.8362
2556.21	79.2424
2560.84	78.6301
2565.46	77.9946
2570.08	77.2985
2574.7	76.564
2579.31	75.8194
2583.92	75.0039
2588.53	76.4226
2593.13	77.5988
2597.73	76.7561
2602.33	73.8918
2606.92	72.2662
2611.51	72.1568
2616.1	74.0458
2620.68	73.3922
2625.26	72.6996
2629.84	71.7817
2634.42	70.367
2638.99	69.4923
2643.56	69.0305
2648.12	69.1353
2652.68	69.8122
2657.24	70.6354
2661.8	71.4509
2666.35	72.0756
2670.9	71.8383
2675.45	71.3803
2679.99	70.5665
2684.53	69.702
2689.06	68.8396
2693.6	68.0004
2698.13	67.342
2702.66	66.8385
2707.18	66.4762
2711.7	65.7637
2716.22	65.2031
2720.73	64.8259
2725.24	64.6616
2729.75	64.88
2734.26	65.2135
2738.76	65.5896
2743.25	65.8931
2747.75	65.4259
2752.24	64.7452
2756.73	63.7928
2761.22	62.6721
2765.7	61.6045
2770.18	61.806
2774.66	62.2646
2779.13	62.6863
2783.6	62.7964
2788.07	62.8775
2792.53	63.0976
2797	62.8916
2801.45	62.6252
2805.91	62.3288
2810.36	61.2869
2814.81	59.3553
2819.26	58.1901
2823.7	57.6807
2828.14	58.7102
2832.57	60.3281
2837.01	60.1413
2841.44	60.163
2845.87	60.2436
2850.29	60.454
2854.71	60.6141
2859.13	60.7845
2863.55	60.9338
2867.96	61.0567
2872.37	61.1524
2876.77	61.2004
2881.18	61.1761
2885.58	60.628
2889.97	60.3016
2894.37	59.6276
2898.76	58.8606
2903.15	58.0461
2907.53	57.1779
2911.91	56.4426
2916.29	56.6354
2920.67	56.9633
2925.04	57.2932
2929.41	57.8032
2933.78	57.7356
2938.14	57.248
2942.5	56.7476
2946.86	56.0996
2951.22	55.6544
2955.57	55.3022
2959.92	55.6069
2964.26	55.9347
2968.61	56.1137
2972.95	56.2652
2977.28	56.3719
2981.62	56.4536
2985.95	56.3629
2990.28	56.3326
2994.6	56.1259
2998.93	55.8782
3003.25	55.5656
3007.56	55.2341
3011.88	54.9521
3016.19	54.7937
3020.49	54.8253
3024.8	55.3318
3029.1	55.7485
3033.4	56.2895
3037.7	56.3117
3041.99	55.8395
3046.28	55.3906
3050.57	54.9653
3054.85	54.5075
3059.13	54.0945
3063.41	53.7215
3067.69	53.4597
3071.96	53.6454
3076.23	53.6815
3080.5	53.9105
3084.76	54.2174
3089.02	54.5932
3093.28	54.9462
3097.53	55.0392
3101.79	54.9871
3106.04	54.8673
3110.28	54.7332
3114.53	54.5822
3118.77	54.0806
3123.01	53.6085
3127.24	53.3749
3131.47	53.8828
3135.7	53.7456
3139.93	53.4867
3144.15	53.0485
3148.38	52.5937
3152.59	52.0656
3156.81	51.6593
3161.02	51.3114
3165.23	51.0852
3169.44	50.4461
3173.64	50.8434
3177.84	51.4712
3182.04	52.0933
3186.24	52.7115
3190.43	52.9727
3194.62	53.2679
3198.81	53.5653
3202.99	53.8317
3207.17	52.9941
3211.35	51.9784
3215.53	51.2903
3219.7	50.6931
3223.87	50.1748
3228.04	49.8099
3232.2	49.6456
3236.36	49.6455
3240.52	49.7751
3244.68	50.1011
3248.83	50.6972
3252.98	51.3591
3257.13	50.2505
3261.28	49.0354
3265.42	49.1373
3269.56	49.8345
3273.7	50.7627
3277.83	50.9796
3281.96	50.2013
3286.09	50.381
3290.22	49.9289
3294.34	48.9183
3298.46	48.825
3302.58	49.0049
3306.69	50.1715
3310.8	51.8096
3314.91	51.934
3319.02	51.8934
3323.12	51.8659
3327.23	51.3076
3331.32	50.1774
3335.42	49.2777
3339.51	48.8512
3343.6	48.7966
3347.69	48.5377
3351.78	48.2205
3355.86	48.0757
3359.94	48.1281
3364.02	48.2854
3368.09	48.6024
3372.16	49.0053
3376.23	49.6713
3380.29	50.4075
3384.36	50.4448
3388.42	49.151
3392.48	48.7681
3396.53	48.7284
3400.58	48.9893
3404.63	49.0687
3408.68	49.7045
3412.73	49.5696
3416.77	49.6785
3420.81	49.8388
3424.84	49.9757
3428.88	50.0286
3432.91	47.7664
3436.94	47.6875
3440.96	48.808
3444.99	48.8419
3449.01	48.0256
3453.03	47.2113
3457.04	46.8111
3461.05	46.7535
3465.06	47.01
3469.07	47.9435
3473.08	48.0795
3477.08	47.9717
3481.08	48.8366
3485.07	49.9087
3489.07	50.9971
3493.06	51.9764
3497.05	52.1733
3501.04	51.9978
3505.02	51.6581
3509	51.2813
3512.98	50.7049
3516.96	50.1301
3520.93	48.8264
3524.9	47.0281
3528.87	45.3727
3532.83	44.8781
3536.8	45.8227
3540.76	47.632
3544.71	49.5119
3548.67	50.1345
3552.62	50.6896
3556.57	50.1948
3560.52	49.4132
3564.47	48.6206
3568.41	47.8207
3572.35	47.6004
3576.29	47.616
3580.22	47.7698
3584.15	48.0373
3588.08	48.3667
3592.01	48.6862
3595.93	47.7164
3599.85	45.2241
3603.77	45.5556
3607.69	46.941
3611.61	47.7742
3615.52	46.7415
3619.43	45.7391
3623.33	45.8512
3627.24	46.6952
3631.14	47.1601
3635.04	46.1998
3638.93	45.3335
3642.83	45.1285
3646.72	44.9396
3650.61	44.8551
3654.49	44.8263
3658.38	44.8505
3662.26	44.9135
3666.14	44.8374
3670.01	43.9678
3673.89	43.5863
3677.76	44.1377
3681.63	44.9738
3685.5	45.8974
3689.36	47.246
3693.22	47.145
3697.08	47.0495
3700.94	47.1816
3704.79	47.3535
3708.64	47.5131
3712.49	47.6909
3716.34	47.1013
3720.18	44.3136
3724.02	44.8678
3727.86	45.5874
3731.7	46.0816
3735.53	46.4578
3739.36	46.6871
3743.19	47.41
3747.02	48.2209
3750.84	49.0794
3754.66	48.9067
3758.48	47.7502
3762.3	47.0637
3766.12	47.0101
3769.93	47.0223
3773.74	47.1843
3777.54	47.2727
3781.35	47.371
3785.15	47.3132
3788.95	47.1705
3792.75	47.1266
3796.54	47.1171
3800.34	47.1282
3804.13	47.177
3807.91	46.6416
3811.7	46.171
3815.48	45.7585
3819.26	45.3937
3823.04	45.1326
3826.82	44.9606
3830.59	44.9896
3834.36	45.1692
3838.13	45.3398
3841.89	45.7747
3845.66	46.255
3849.42	46.768
3853.18	46.9043
3856.93	47.0368
3860.69	47.6512
3864.44	47.9159
3868.19	48.0188
3871.93	47.7215
3875.68	47.2338
3879.42	46.83
3883.16	46.321
3886.9	45.8733
3890.63	45.6498
3894.37	46.045
3898.1	46.2953
3901.82	46.208
3905.55	46.1101
3909.27	46.0135
3912.99	45.8949
3916.71	45.855
3920.43	45.8485
3924.14	46.1379
3927.85	46.4978
3931.56	45.4234
3935.27	44.6372
3938.97	44.2126
3942.67	44.1226
3946.37	44.3424
3950.07	44.7045
3953.77	45.4597
3957.46	46.2601
3961.15	46.7094
3964.84	46.7072
3968.52	45.988
3972.2	47.1081
3975.89	48.6488
3979.56	48.3905
3983.24	47.8364
3986.92	45.8605
3990.59	41.6564
3994.26	44.6652
3997.92	43.09
3999.76	42.1235