File: Data/Raman/raw/bu24-ore2-rim_150 (500nm)_633nm_edge_100%_x100_vis_h30um_10sx2_01.txt
#Acq. time (s)=	10
#Accumulations=	2
#Range (cm-¹)=	100...4000
#Windows=	1
#Auto scanning=	Off
#Autofocus=	Off
#Macrospot=	Off
#AutoExposure=	Off
#Spike filter=	Multiple accum.
#Delay time (s)=	2
#Binning=	1
#Readout mode=	Signal
#DeNoise=	Standard
#ICS correction=	On
#Dark correction=	Off
#Inst. Process=	Off
#Detector Gain=	Best Dynamic
#Detector ADC=	50 kHz HS
#Detector temperature (°C)=	-60.09
#Instrument=	LabRAM HR Evol
#Detector=	SIN-EM FIVIS
#Objective=	x20_VIS
#Grating=	150 (500nm)
#ND Filter=	100%
#Laser=	633nm_Edge
#Hole=	30.0125
#Temperature=	0
#Range=	Visible
#StageXY=	75x50mm Scan+
#StageZ=	Z motor
#X (µm)=	0
#Y (µm)=	0
#Z (µm)=	56.8
#Full time(s)=	24
#Project=	20_10_27
#Sample=	BU24
#Site=
#Title=	BU24-Ore2-rim_150 (500nm)_633nm_Edge_100%_x20_VIS_H30um_10sX2
#Remark=
#Date=	27.10.2020 19:03
#Acquired=	27.10.2020 19:03:47
100.764	1035.65
107.281	1060.82
113.791	1129.22
120.297	1243.39
126.797	1513.71
133.291	1885.58
139.78	1885.13
146.264	1210.58
152.741	972.826
159.214	940.196
165.682	982.887
172.144	1028.87
178.601	1032.84
185.053	987.07
191.499	929.134
197.939	933.087
204.374	978.995
210.805	939.578
217.23	919.443
223.648	909.669
230.063	937.124
236.472	1013.98
242.874	1077.24
249.273	1109.19
255.667	1098.39
262.053	1174.35
268.436	1198.13
274.813	1171.55
281.185	1113.34
287.552	1048.99
293.913	981.083
300.27	937.157
306.62	901.621
312.965	872.496
319.306	849.724
325.64	833.775
331.971	823.66
338.295	819.915
344.614	821.528
350.93	830.875
357.238	841.253
363.542	850.865
369.842	864.009
376.135	879.666
382.423	913.711
388.706	954.002
394.984	984.406
401.258	953.268
407.526	897.417
413.789	849.717
420.046	816.199
426.299	803.133
432.546	799.548
438.788	804.284
445.025	815.658
451.257	822.012
457.484	831.252
463.706	844.664
469.923	861.855
476.135	879.691
482.342	894.662
488.544	906.031
494.741	914.917
500.933	925.089
507.12	941.2
513.3	979.758
519.477	1048.89
525.649	1120.7
531.815	1113.05
537.976	1041.7
544.133	960.882
550.285	893.973
556.43	839.808
562.572	809.186
568.709	792.621
574.84	783.577
580.967	780.945
587.09	785.35
593.205	793.367
599.318	801.583
605.424	809.279
611.527	816.184
617.623	822.425
623.716	826.092
629.802	824.521
635.884	816.974
641.962	805.472
648.034	791.721
654.101	778.799
660.165	768.138
666.222	760.073
672.274	754.46
678.324	752.154
684.366	753.762
690.404	758.625
696.438	765.11
702.466	771.981
708.491	778.538
714.51	784.46
720.523	790.41
726.533	797.232
732.537	805.897
738.537	817.363
744.531	832.335
750.521	854.288
756.507	874.774
762.487	886.248
768.463	893.044
774.434	901.409
780.4	918.462
786.362	930.929
792.319	945.201
798.269	953.919
804.217	966.61
810.159	998.012
816.097	1049.74
822.03	1100.92
827.958	1148.87
833.881	1213.99
839.801	1326.6
845.714	1515.06
851.624	1858.32
857.529	2456.89
863.428	3283.59
869.324	4294.33
875.215	4105.16
881.1	2737.09
886.982	1670.04
892.858	1101.8
898.73	871.701
904.597	735.306
910.459	658.932
916.318	604.895
922.171	568.14
928.02	543.255
933.864	524.216
939.703	508.001
945.539	495.116
951.368	484.093
957.194	473.645
963.014	464.9
968.832	457.307
974.643	450.613
980.45	444.321
986.253	437.722
992.051	431.762
997.844	427.051
1003.63	423.553
1009.42	421.021
1015.2	419.929
1020.97	420.375
1026.74	420.148
1032.51	417.381
1038.27	413.764
1044.03	410.731
1049.78	408.216
1055.53	404.819
1061.27	400.506
1067.01	396.307
1072.75	392.984
1078.48	389.402
1084.2	385.876
1089.92	382.805
1095.64	380.782
1101.35	379.77
1107.06	378.781
1112.77	377.44
1118.46	375.51
1124.16	373.281
1129.85	370.973
1135.53	368.88
1141.22	367.317
1146.89	365.755
1152.56	364.239
1158.23	362.335
1163.9	359.577
1169.56	356.598
1175.21	354.574
1180.86	353.33
1186.51	352.472
1192.15	351.464
1197.78	350.23
1203.42	348.723
1209.04	348.418
1214.67	348.823
1220.29	347.941
1225.9	345.649
1231.51	342.104
1237.12	338.19
1242.72	334.444
1248.32	330.817
1253.92	327.567
1259.5	324.759
1265.09	322.543
1270.67	321.072
1276.25	320.495
1281.82	320.547
1287.39	321.039
1292.95	321.375
1298.51	320.809
1304.06	318.144
1309.61	314.023
1315.16	307.926
1320.7	303.377
1326.24	303.382
1331.77	304.376
1337.3	306.745
1342.83	309.868
1348.35	312.346
1353.86	311.427
1359.37	307.51
1364.88	305.127
1370.39	303.396
1375.89	301.603
1381.38	299.733
1386.87	297.591
1392.36	295.517
1397.84	293.453
1403.32	291.617
1408.79	289.978
1414.26	288.918
1419.73	289.154
1425.19	289.262
1430.65	288.818
1436.1	287.816
1441.55	286.239
1447	284.142
1452.44	281.717
1457.87	279.334
1463.31	277.58
1468.73	276.55
1474.16	276.739
1479.58	277.244
1484.99	277.419
1490.41	275.876
1495.81	273.975
1501.22	272.271
1506.62	270.996
1512.01	270.135
1517.4	269.33
1522.79	268.515
1528.17	267.376
1533.55	265.363
1538.93	262.209
1544.3	260.341
1549.67	259.052
1555.03	257.877
1560.39	256.573
1565.74	255.136
1571.09	253.627
1576.44	252.24
1581.78	250.93
1587.12	249.67
1592.45	248.406
1597.78	247.107
1603.11	245.9
1608.43	244.65
1613.75	243.327
1619.07	242.067
1624.38	239.82
1629.68	236.921
1634.98	234.079
1640.28	231.359
1645.58	229.517
1650.87	227.932
1656.15	226.505
1661.44	225.262
1666.71	223.916
1671.99	222.463
1677.26	221.174
1682.53	220.131
1687.79	219.276
1693.05	218.757
1698.3	219.174
1703.55	220.173
1708.8	220.527
1714.04	219.986
1719.28	218.724
1724.51	217.207
1729.75	215.378
1734.97	213.348
1740.2	210.804
1745.42	207.771
1750.63	204.241
1755.84	200.334
1761.05	195.507
1766.25	190.736
1771.45	187.76
1776.65	186.849
1781.84	187.345
1787.03	187.836
1792.21	187.586
1797.39	186.162
1802.57	183.502
1807.74	179.864
1812.91	176.16
1818.08	173.479
1823.24	172.651
1828.39	172.34
1833.55	171.818
1838.7	169.982
1843.84	168.233
1848.99	166.67
1854.12	165.514
1859.26	165.351
1864.39	165.785
1869.52	166.18
1874.64	165.907
1879.76	164.87
1884.87	162.577
1889.98	159.969
1895.09	157.67
1900.2	157.296
1905.3	157.909
1910.39	159.755
1915.49	161.509
1920.57	162.26
1925.66	161.91
1930.74	160.827
1935.82	158.057
1940.89	154.916
1945.96	151.734
1951.03	149.692
1956.09	147.946
1961.15	146.594
1966.21	145.582
1971.26	144.928
1976.31	144.642
1981.35	144.551
1986.39	144.533
1991.43	144.335
1996.46	144.084
2001.49	142.583
2006.52	140.893
2011.54	139.393
2016.56	138.734
2021.57	138.963
2026.58	139.559
2031.59	140.188
2036.59	140.595
2041.59	140.438
2046.59	138.83
2051.58	136.906
2056.57	134.866
2061.55	133.143
2066.54	132.034
2071.51	131.129
2076.49	130.483
2081.46	130.283
2086.43	130.207
2091.39	130.07
2096.35	129.332
2101.3	128.059
2106.26	126.198
2111.21	124.608
2116.15	124.108
2121.09	124.843
2126.03	126.009
2130.97	126.517
2135.9	126.344
2140.83	125.627
2145.75	125.137
2150.67	124.575
2155.59	123.464
2160.5	121.806
2165.41	121.053
2170.31	121.007
2175.22	119.573
2180.12	117.815
2185.01	116.129
2189.9	114.606
2194.79	113.274
2199.68	112.669
2204.56	112.352
2209.43	112.248
2214.31	112.282
2219.18	112.425
2224.05	112.582
2228.91	112.326
2233.77	111.497
2238.63	110.137
2243.48	108.315
2248.33	106.613
2253.17	105.479
2258.02	105.088
2262.86	105.549
2267.69	106.695
2272.52	107.238
2277.35	106.728
2282.18	104.856
2287	102.977
2291.82	101.818
2296.63	101.708
2301.44	102.727
2306.25	103.854
2311.05	104.388
2315.86	104.08
2320.65	102.841
2325.45	100.658
2330.24	98.415
2335.03	96.848
2339.81	96.8265
2344.59	97.4353
2349.37	98.2336
2354.14	98.9346
2358.91	98.7324
2363.67	98.3914
2368.44	97.8011
2373.2	97.0267
2377.95	96.1613
2382.71	95.2646
2387.46	94.5065
2392.2	93.6284
2396.95	92.6655
2401.68	91.7974
2406.42	91.1789
2411.15	90.7987
2415.88	89.4712
2420.61	86.4792
2425.33	86.0007
2430.05	87.2787
2434.77	89.839
2439.48	90.6771
2444.19	90.5753
2448.89	90.3653
2453.6	90.2741
2458.29	90.1584
2462.99	89.9077
2467.68	89.4298
2472.37	88.6335
2477.06	87.3991
2481.74	85.5871
2486.42	83.516
2491.1	82.3466
2495.77	82.7861
2500.44	83.5155
2505.1	84.1278
2509.76	84.4738
2514.42	84.4951
2519.08	84.1171
2523.73	83.524
2528.38	82.6204
2533.03	81.5215
2537.67	80.3172
2542.31	79.6855
2546.95	81.3543
2551.58	83.94
2556.21	82.4532
2560.84	79.8601
2565.46	78.1161
2570.08	77.9098
2574.7	78.8349
2579.31	78.7391
2583.92	77.8781
2588.53	78.1368
2593.13	78.7908
2597.73	78.7711
2602.33	78.6856
2606.92	77.7349
2611.51	75.8981
2616.1	73.838
2620.68	73.6396
2625.26	73.7835
2629.84	74.1114
2634.42	74.1867
2638.99	74.2796
2643.56	73.7318
2648.12	73.0195
2652.68	71.9989
2657.24	71.4123
2661.8	70.8948
2666.35	70.7145
2670.9	70.4731
2675.45	70.2576
2679.99	70.071
2684.53	69.9127
2689.06	69.6703
2693.6	69.4885
2698.13	69.3816
2702.66	69.2975
2707.18	69.2429
2711.7	69.1968
2716.22	69.1407
2720.73	69.0682
2725.24	68.971
2729.75	68.8497
2734.26	68.7087
2738.76	68.5409
2743.25	68.3337
2747.75	68.0514
2752.24	67.772
2756.73	67.3763
2761.22	67.0628
2765.7	65.7156
2770.18	64.3003
2774.66	64.3705
2779.13	65.3719
2783.6	64.8
2788.07	64.2055
2792.53	63.6161
2797	63.0424
2801.45	62.5164
2805.91	62.0872
2810.36	62.0808
2814.81	62.0223
2819.26	62.7675
2823.7	63.8861
2828.14	64.5124
2832.57	64.7782
2837.01	64.8174
2841.44	64.2665
2845.87	63.4534
2850.29	62.4462
2854.71	61.2205
2859.13	60.841
2863.55	61.4932
2867.96	61.6143
2872.37	61.1215
2876.77	60.1348
2881.18	58.8092
2885.58	57.746
2889.97	57.2913
2894.37	58.5614
2898.76	59.4841
2903.15	59.1344
2907.53	59.0836
2911.91	59.0138
2916.29	59.2254
2920.67	59.6694
2925.04	59.9375
2929.41	59.9035
2933.78	59.3467
2938.14	58.6461
2942.5	57.8448
2946.86	57.078
2951.22	56.3567
2955.57	55.77
2959.92	55.5617
2964.26	55.5076
2968.61	55.5984
2972.95	55.7387
2977.28	55.9114
2981.62	56.0229
2985.95	55.8841
2990.28	54.612
2994.6	52.9579
2998.93	54.56
3003.25	56.9533
3007.56	55.955
3011.88	55.6311
3016.19	53.9751
3020.49	53.7289
3024.8	54.5163
3029.1	55.1415
3033.4	54.393
3037.7	53.817
3041.99	53.4908
3046.28	53.7876
3050.57	53.9496
3054.85	54.3296
3059.13	54.7711
3063.41	55.3133
3067.69	55.7483
3071.96	55.3181
3076.23	54.7481
3080.5	54.1336
3084.76	53.5307
3089.02	52.8306
3093.28	53.0835
3097.53	53.4814
3101.79	53.1722
3106.04	53.1399
3110.28	53.3418
3114.53	53.5151
3118.77	53.7394
3123.01	54.0021
3127.24	54.2686
3131.47	54.4225
3135.7	53.934
3139.93	53.4655
3144.15	53.073
3148.38	53.3031
3152.59	52.7751
3156.81	52.8979
3161.02	52.958
3165.23	53.0589
3169.44	52.6193
3173.64	51.8653
3177.84	51.2214
3182.04	50.6243
3186.24	50.1529
3190.43	49.6784
3194.62	49.3502
3198.81	49.0592
3202.99	49.1611
3207.17	49.4202
3211.35	49.7817
3215.53	50.1026
3219.7	50.3414
3223.87	50.2222
3228.04	50.0464
3232.2	49.6257
3236.36	49.2343
3240.52	48.8868
3244.68	48.5556
3248.83	48.4557
3252.98	48.9023
3257.13	49.3775
3261.28	49.9967
3265.42	50.6919
3269.56	51.1133
3273.7	50.9735
3277.83	50.9023
3281.96	50.2643
3286.09	49.4802
3290.22	48.7637
3294.34	48.2
3298.46	48.5472
3302.58	49.3288
3306.69	48.8477
3310.8	48.0288
3314.91	47.2233
3319.02	46.9501
3323.12	46.8128
3327.23	48.0429
3331.32	49.5981
3335.42	50.5905
3339.51	50.1133
3343.6	49.5548
3347.69	48.978
3351.78	48.4829
3355.86	48.1124
3359.94	47.9641
3364.02	48.5284
3368.09	49.0551
3372.16	49.532
3376.23	49.6863
3380.29	49.0806
3384.36	48.374
3388.42	47.6667
3392.48	46.9548
3396.53	46.254
3400.58	45.6483
3404.63	44.9174
3408.68	45.0878
3412.73	45.4213
3416.77	45.9511
3420.81	46.548
3424.84	47.146
3428.88	47.4884
3432.91	47.5877
3436.94	47.5402
3440.96	47.4662
3444.99	47.3802
3449.01	47.2913
3453.03	47.2079
3457.04	47.1099
3461.05	46.9987
3465.06	46.9705
3469.07	47.0614
3473.08	47.4231
3477.08	47.7393
3481.08	47.8299
3485.07	47.6836
3489.07	47.3998
3493.06	47.1447
3497.05	47.2309
3501.04	47.583
3505.02	47.2647
3509	46.8041
3512.98	46.3562
3516.96	46.0987
3520.93	45.9176
3524.9	45.8695
3528.87	45.9965
3532.83	46.4323
3536.8	47.0739
3540.76	47.8866
3544.71	48.1697
3548.67	47.9012
3552.62	48.1645
3556.57	48.2323
3560.52	47.846
3564.47	47.6098
3568.41	47.2049
3572.35	46.6158
3576.29	46.4224
3580.22	45.3122
3584.15	45.0536
3588.08	45.4856
3592.01	44.2749
3595.93	44.1171
3599.85	44.3965
3603.77	44.7464
3607.69	45.0245
3611.61	45.2865
3615.52	45.5218
3619.43	45.5131
3623.33	45.4106
3627.24	45.583
3631.14	45.8007
3635.04	46.028
3638.93	46.2349
3642.83	46.3716
3646.72	46.599
3650.61	46.7265
3654.49	46.8325
3658.38	46.9808
3662.26	46.9313
3666.14	46.7177
3670.01	46.3003
3673.89	45.903
3677.76	45.5154
3681.63	45.17
3685.5	44.8667
3689.36	44.6216
3693.22	44.5098
3697.08	45.2971
3700.94	44.5707
3704.79	42.799
3708.64	42.9057
3712.49	44.45
3716.34	45.8119
3720.18	46.3345
3724.02	46.2973
3727.86	46.1192
3731.7	46.4245
3735.53	46.706
3739.36	46.8698
3743.19	46.8733
3747.02	46.5981
3750.84	46.0952
3754.66	45.4343
3758.48	44.9213
3762.3	44.5426
3766.12	44.5259
3769.93	45.2228
3773.74	46.1081
3777.54	47.0365
3781.35	47.6666
3785.15	47.2886
3788.95	46.7401
3792.75	46.1197
3796.54	45.5926
3800.34	45.4981
3804.13	45.3949
3807.91	45.5053
3811.7	45.6288
3815.48	45.7573
3819.26	45.8842
3823.04	45.8901
3826.82	45.8011
3830.59	45.9301
3834.36	46.1076
3838.13	46.2909
3841.89	46.3811
3845.66	45.3792
3849.42	43.9808
3853.18	44.7534
3856.93	44.6476
3860.69	44.1728
3864.44	43.1148
3868.19	44.4962
3871.93	45.9864
3875.68	46.6352
3879.42	46.628
3883.16	47.1914
3886.9	45.2474
3890.63	44.4137
3894.37	44.6228
3898.1	43.9067
3901.82	43.754
3905.55	44.2554
3909.27	43.6417
3912.99	42.4354
3916.71	42.0023
3920.43	43.0453
3924.14	43.9577
3927.85	44.4896
3931.56	44.7235
3935.27	45.252
3938.97	45.0162
3942.67	44.6711
3946.37	44.2929
3950.07	43.5061
3953.77	42.845
3957.46	42.7346
3961.15	43.4332
3964.84	44.7691
3968.52	46.1728
3972.2	47.0832
3975.89	46.8821
3979.56	46.6215
3983.24	46.2691
3986.92	45.8952
3990.59	45.3238
3994.26	44.615
3997.92	44.0329
3999.76	43.9475