File: Data/Raman/raw/bu24-ore4-prism_top_150 (500nm)_633nm_edge_100%_x100_vis_h30um_10sx2_01.txt
#Acq. time (s)=	10
#Accumulations=	2
#Range (cm-¹)=	100...4000
#Windows=	1
#Auto scanning=	Off
#Autofocus=	Off
#Macrospot=	Off
#AutoExposure=	Off
#Spike filter=	Multiple accum.
#Delay time (s)=	2
#Binning=	1
#Readout mode=	Signal
#DeNoise=	Standard
#ICS correction=	On
#Dark correction=	Off
#Inst. Process=	Off
#Detector Gain=	Best Dynamic
#Detector ADC=	50 kHz HS
#Detector temperature (°C)=	-60.09
#Instrument=	LabRAM HR Evol
#Detector=	SIN-EM FIVIS
#Objective=	x100_VIS
#Grating=	150 (500nm)
#ND Filter=	100%
#Laser=	633nm_Edge
#Hole=	30.0125
#Temperature=	0
#Range=	Visible
#StageXY=	75x50mm Scan+
#StageZ=	Z motor
#X (µm)=	0
#Y (µm)=	0
#Z (µm)=	52.9
#Full time(s)=	25
#Project=	20_10_27
#Sample=	BU24
#Site=
#Title=	BU24-Ore4-prism_top_150 (500nm)_633nm_Edge_100%_x100_VIS_H30um_10sX2
#Remark=
#Date=	27.10.2020 19:16
#Acquired=	27.10.2020 19:16:34
100.764	761.535
107.281	801.583
113.791	857.25
120.297	905.397
126.797	908.086
133.291	862.74
139.78	749.41
146.264	650.161
152.741	595.784
159.214	565.254
165.682	547.696
172.144	540.105
178.601	539.368
185.053	540.2
191.499	533.823
197.939	529.823
204.374	522.184
210.805	516.502
217.23	510.549
223.648	504.986
230.063	500.545
236.472	497.63
242.874	496.452
249.273	496.106
255.667	493.491
262.053	492.487
268.436	492.97
274.813	496.58
281.185	499.393
287.552	498.433
293.913	494.759
300.27	487.85
306.62	482.314
312.965	470.909
319.306	459.55
325.64	447.147
331.971	439.705
338.295	436.775
344.614	438.34
350.93	441.09
357.238	441.254
363.542	441.69
369.842	442.109
376.135	439.85
382.423	437.857
388.706	437.497
394.984	437.171
401.258	435.908
407.526	433.217
413.789	425.882
420.046	417.365
426.299	408.989
432.546	401.234
438.788	394.396
445.025	388.329
451.257	383.513
457.484	380.033
463.706	374.862
469.923	369.862
476.135	365.446
482.342	360.178
488.544	354.561
494.741	349.503
500.933	345.179
507.12	340.998
513.3	337.231
519.477	335.654
525.649	335.903
531.815	336.654
537.976	337.19
544.133	336.948
550.285	336.968
556.43	336.355
562.572	335.228
568.709	333.169
574.84	332.385
580.967	333.03
587.09	335.004
593.205	337.866
599.318	340.888
605.424	341.979
611.527	341.957
617.623	342.38
623.716	342.249
629.802	342.081
635.884	341.212
641.962	340.915
648.034	340.484
654.101	340.158
660.165	339.429
666.222	338.897
672.274	338.651
678.324	339.426
684.366	340.772
690.404	343.638
696.438	347.063
702.466	352.047
708.491	356.457
714.51	362.543
720.523	368.816
726.533	375.378
732.537	383.596
738.537	393.708
744.531	401.517
750.521	408.737
756.507	416.375
762.487	422.284
768.463	427.195
774.434	429.471
780.4	430.358
786.362	426.895
792.319	421.73
798.269	416.368
804.217	410.193
810.159	408.209
816.097	412.405
822.03	411.991
827.958	416.38
833.881	421.57
839.801	424.619
845.714	425.093
851.624	419.945
857.529	410.695
863.428	378.697
869.324	337.638
875.215	295.201
881.1	254.457
886.982	224.915
892.858	203.527
898.73	191.248
904.597	184.312
910.459	180.704
916.318	176.759
922.171	170.529
928.02	165.076
933.864	160.379
939.703	155.837
945.539	152.368
951.368	149.673
957.194	148.787
963.014	148.331
968.832	146.938
974.643	145.292
980.45	143.654
986.253	141.246
992.051	138.295
997.844	135.689
1003.63	133.192
1009.42	131.684
1015.2	130.633
1020.97	129.125
1026.74	128.039
1032.51	127.216
1038.27	126.171
1044.03	124.811
1049.78	123.455
1055.53	122.463
1061.27	121.698
1067.01	120.78
1072.75	119.626
1078.48	118.279
1084.2	117.152
1089.92	116.005
1095.64	114.821
1101.35	113.776
1107.06	112.987
1112.77	111.355
1118.46	110.509
1124.16	109.587
1129.85	108.903
1135.53	107.763
1141.22	106.958
1146.89	105.955
1152.56	105.715
1158.23	104.979
1163.9	103.315
1169.56	102.257
1175.21	100.703
1180.86	99.3419
1186.51	98.3703
1192.15	97.0386
1197.78	96.4988
1203.42	96.1162
1209.04	96.2029
1214.67	96.3025
1220.29	96.5732
1225.9	96.7541
1231.51	95.7988
1237.12	94.5852
1242.72	93.1601
1248.32	91.0115
1253.92	90.0426
1259.5	89.8715
1265.09	89.4128
1270.67	88.0648
1276.25	87.2866
1281.82	87.336
1287.39	87.802
1292.95	87.338
1298.51	86.6606
1304.06	86.6885
1309.61	85.7408
1315.16	84.7592
1320.7	83.6973
1326.24	82.3231
1331.77	81.2281
1337.3	79.7161
1342.83	78.6976
1348.35	78.3846
1353.86	78.6016
1359.37	78.5361
1364.88	77.8019
1370.39	77.4148
1375.89	77.3541
1381.38	77.06
1386.87	75.803
1392.36	74.9034
1397.84	73.9435
1403.32	73.4279
1408.79	73.5965
1414.26	73.6579
1419.73	72.9939
1425.19	72.3544
1430.65	71.574
1436.1	71.1128
1441.55	70.0885
1447	69.8819
1452.44	70.2414
1457.87	70.7385
1463.31	71.2042
1468.73	71.0052
1474.16	70.1794
1479.58	69.6616
1484.99	69.4141
1490.41	69.2002
1495.81	67.8338
1501.22	67.1425
1506.62	66.4368
1512.01	65.699
1517.4	63.67
1522.79	61.7567
1528.17	60.8065
1533.55	60.4713
1538.93	60.7357
1544.3	61.104
1549.67	62.206
1555.03	63.0518
1560.39	63.3385
1565.74	63.907
1571.09	63.5823
1576.44	63.1572
1581.78	62.599
1587.12	61.7707
1592.45	61.0373
1597.78	60.6954
1603.11	60.5437
1608.43	60.2273
1613.75	60.0127
1619.07	59.719
1624.38	58.8571
1629.68	59.2233
1634.98	59.1492
1640.28	59.4462
1645.58	59.1469
1650.87	58.46
1656.15	57.4911
1661.44	56.777
1666.71	56.0327
1671.99	55.3385
1677.26	53.9369
1682.53	52.9466
1687.79	52.9981
1693.05	53.5421
1698.3	53.4027
1703.55	52.7869
1708.8	52.0282
1714.04	51.2748
1719.28	50.3688
1724.51	50.024
1729.75	49.5374
1734.97	49.5353
1740.2	48.5582
1745.42	47.1778
1750.63	46.1348
1755.84	45.5456
1761.05	45.3226
1766.25	45.7528
1771.45	46.1449
1776.65	46.6503
1781.84	46.6028
1787.03	46.3885
1792.21	46.2806
1797.39	46.9571
1802.57	46.6032
1807.74	45.2566
1812.91	44.0048
1818.08	43.4682
1823.24	43.7037
1828.39	43.977
1833.55	44.653
1838.7	45.1629
1843.84	45.142
1848.99	44.4718
1854.12	43.4606
1859.26	43.0302
1864.39	43.1846
1869.52	42.8118
1874.64	42.4178
1879.76	42.6047
1884.87	42.6434
1889.98	42.2672
1895.09	41.831
1900.2	41.2966
1905.3	41.1393
1910.39	40.8494
1915.49	41.16
1920.57	41.3076
1925.66	41.4489
1930.74	41.4125
1935.82	41.3304
1940.89	41.0928
1945.96	40.8458
1951.03	40.7015
1956.09	40.8679
1961.15	41.0182
1966.21	40.9103
1971.26	40.5509
1976.31	39.8944
1981.35	39.5332
1986.39	39.4339
1991.43	37.921
1996.46	36.8083
2001.49	36.1685
2006.52	35.857
2011.54	36.5171
2016.56	36.7827
2021.57	36.6335
2026.58	36.922
2031.59	37.6047
2036.59	38.2482
2041.59	38.5605
2046.59	37.5356
2051.58	37.5212
2056.57	38.0138
2061.55	38.4109
2066.54	38.2224
2071.51	37.6115
2076.49	36.8199
2081.46	35.9463
2086.43	35.3869
2091.39	35.4479
2096.35	35.7124
2101.3	36.2707
2106.26	35.8466
2111.21	34.9386
2116.15	34.7961
2121.09	34.5538
2126.03	34.5724
2130.97	34.7905
2135.9	35.1904
2140.83	35.4143
2145.75	34.5672
2150.67	33.8216
2155.59	33.6127
2160.5	33.6354
2165.41	33.3884
2170.31	33.1133
2175.22	33.1156
2180.12	33.5756
2185.01	34.0877
2189.9	34.557
2194.79	34.6382
2199.68	34.3112
2204.56	34.1579
2209.43	33.9113
2214.31	33.7145
2219.18	32.913
2224.05	32.4
2228.91	32.1463
2233.77	32.4496
2238.63	32.6919
2243.48	31.1864
2248.33	30.505
2253.17	30.6825
2258.02	31.2082
2262.86	32.4018
2267.69	33.6698
2272.52	32.7009
2277.35	31.1588
2282.18	30.6572
2287	30.6998
2291.82	31.1448
2296.63	31.7075
2301.44	32.248
2306.25	31.8836
2311.05	31.6536
2315.86	31.124
2320.65	31.0224
2325.45	31.2307
2330.24	31.6835
2335.03	32.068
2339.81	32.1069
2344.59	31.5166
2349.37	31.1383
2354.14	31.2501
2358.91	31.4145
2363.67	31.3374
2368.44	30.7091
2373.2	30.6284
2377.95	30.8721
2382.71	31.2097
2387.46	31.2453
2392.2	30.6685
2396.95	29.8406
2401.68	29.4619
2406.42	28.8971
2411.15	28.7316
2415.88	29.0771
2420.61	29.7444
2425.33	30.3522
2430.05	30.6392
2434.77	29.4447
2439.48	28.8919
2444.19	29.545
2448.89	30.2266
2453.6	31.0193
2458.29	31.0804
2462.99	31.3267
2467.68	31.5666
2472.37	31.4816
2477.06	31.1436
2481.74	30.3142
2486.42	30.134
2491.1	30.7965
2495.77	31.4644
2500.44	31.5767
2505.1	30.5526
2509.76	31.0382
2514.42	31.462
2519.08	31.4829
2523.73	30.9648
2528.38	30.4245
2533.03	29.7448
2537.67	30.3957
2542.31	30.6564
2546.95	30.2618
2551.58	29.551
2556.21	29.6239
2560.84	30.0024
2565.46	29.1111
2570.08	28.3484
2574.7	28.3928
2579.31	28.5281
2583.92	28.4727
2588.53	28.1599
2593.13	28.0249
2597.73	27.8732
2602.33	26.9227
2606.92	27.272
2611.51	28.545
2616.1	29.4679
2620.68	29.1593
2625.26	28.7427
2629.84	27.995
2634.42	27.2551
2638.99	27.4093
2643.56	28.2553
2648.12	29.1282
2652.68	28.0972
2657.24	26.6094
2661.8	28.7317
2666.35	29.8473
2670.9	29.0745
2675.45	29.02
2679.99	29.1825
2684.53	29.335
2689.06	28.9972
2693.6	28.9452
2698.13	28.7821
2702.66	28.7195
2707.18	28.6518
2711.7	29.1815
2716.22	29.4946
2720.73	29.592
2725.24	29.7323
2729.75	29.9606
2734.26	29.8629
2738.76	29.9182
2743.25	29.7497
2747.75	29.3918
2752.24	29.36
2756.73	29.7087
2761.22	29.9873
2765.7	29.5896
2770.18	29.2068
2774.66	29.1606
2779.13	29.765
2783.6	30.3313
2788.07	30.7475
2792.53	29.972
2797	29.4298
2801.45	29.1603
2805.91	29.2104
2810.36	29.4844
2814.81	29.8961
2819.26	29.84
2823.7	30.0783
2828.14	30.239
2832.57	30.0943
2837.01	29.421
2841.44	28.4686
2845.87	27.9627
2850.29	27.9043
2854.71	28.2338
2859.13	28.4807
2863.55	29.0612
2867.96	29.5776
2872.37	30.6053
2876.77	31.6552
2881.18	31.8179
2885.58	31.6218
2889.97	31.5203
2894.37	31.2925
2898.76	31.12
2903.15	30.9371
2907.53	30.6372
2911.91	30.3569
2916.29	30.3361
2920.67	30.2336
2925.04	30.037
2929.41	29.9652
2933.78	29.8196
2938.14	29.5576
2942.5	29.5334
2946.86	30.0805
2951.22	30.29
2955.57	30.2642
2959.92	30.2086
2964.26	29.726
2968.61	29.2102
2972.95	29.0546
2977.28	29.0632
2981.62	29.4188
2985.95	29.7798
2990.28	29.6527
2994.6	29.8016
2998.93	29.9007
3003.25	29.9435
3007.56	29.8829
3011.88	29.7475
3016.19	29.9327
3020.49	30.7149
3024.8	29.9485
3029.1	29.2318
3033.4	29.2992
3037.7	30.0229
3041.99	30.6254
3046.28	30.3843
3050.57	29.9661
3054.85	30.4498
3059.13	31.461
3063.41	31.962
3067.69	31.7312
3071.96	31.8524
3076.23	31.3544
3080.5	30.952
3084.76	29.7011
3089.02	29.1568
3093.28	29.4857
3097.53	30.3158
3101.79	30.9426
3106.04	31.4456
3110.28	31.5077
3114.53	31.9951
3118.77	32.4594
3123.01	31.8407
3127.24	31.7889
3131.47	32.5363
3135.7	32.9984
3139.93	32.7636
3144.15	32.5562
3148.38	32.2805
3152.59	32.0451
3156.81	32.2356
3161.02	32.3084
3165.23	32.1945
3169.44	32.606
3173.64	32.6496
3177.84	32.4884
3182.04	32.3367
3186.24	32.8401
3190.43	32.8146
3194.62	32.3893
3198.81	32.0967
3202.99	32.3362
3207.17	33.2908
3211.35	32.4361
3215.53	31.9019
3219.7	32.0779
3223.87	32.6957
3228.04	33.1461
3232.2	32.5803
3236.36	32.6905
3240.52	33.074
3244.68	33.4923
3248.83	33.4486
3252.98	32.9826
3257.13	32.7636
3261.28	33.2119
3265.42	32.9229
3269.56	32.4511
3273.7	32.4062
3277.83	32.7899
3281.96	33.4415
3286.09	33.6475
3290.22	34.0479
3294.34	34.5164
3298.46	35.0823
3302.58	34.709
3306.69	34.0976
3310.8	33.542
3314.91	33.5541
3319.02	33.6054
3323.12	33.2197
3327.23	33.6956
3331.32	33.9902
3335.42	34.2965
3339.51	34.2747
3343.6	33.5844
3347.69	33.1746
3351.78	32.8049
3355.86	32.5429
3359.94	32.7917
3364.02	33.7955
3368.09	34.6203
3372.16	35.3261
3376.23	35.7804
3380.29	35.8998
3384.36	36.0446
3388.42	35.9804
3392.48	35.6889
3396.53	35.2281
3400.58	34.6781
3404.63	34.2394
3408.68	34.1887
3412.73	34.6017
3416.77	34.8937
3420.81	34.4378
3424.84	34.3901
3428.88	34.5694
3432.91	34.9938
3436.94	35.5239
3440.96	36.6765
3444.99	36.5229
3449.01	35.8577
3453.03	35.4046
3457.04	35.0904
3461.05	34.8142
3465.06	34.382
3469.07	34.5482
3473.08	35.6676
3477.08	36.5325
3481.08	36.9445
3485.07	36.8324
3489.07	36.282
3493.06	35.4359
3497.05	34.5605
3501.04	34.3097
3505.02	34.223
3509	34.3143
3512.98	34.5937
3516.96	35.0968
3520.93	35.2471
3524.9	34.9335
3528.87	35.082
3532.83	35.5896
3536.8	36.4034
3540.76	36.4283
3544.71	36.8752
3548.67	37.3985
3552.62	37.0426
3556.57	35.9254
3560.52	34.993
3564.47	34.4972
3568.41	34.2893
3572.35	34.9332
3576.29	35.5011
3580.22	35.4019
3584.15	36.1849
3588.08	36.8495
3592.01	36.4683
3595.93	36.3802
3599.85	35.8949
3603.77	35.8748
3607.69	35.5213
3611.61	35.6554
3615.52	34.8036
3619.43	34.4438
3623.33	34.5448
3627.24	35.2066
3631.14	36.4902
3635.04	36.0644
3638.93	35.2586
3642.83	35.0878
3646.72	34.5764
3650.61	34.2971
3654.49	34.4739
3658.38	34.555
3662.26	34.3301
3666.14	34.7504
3670.01	36.3169
3673.89	34.564
3677.76	36.4477
3681.63	36.213
3685.5	36.5371
3689.36	37.088
3693.22	37.7776
3697.08	38.1013
3700.94	37.4626
3704.79	36.4657
3708.64	35.8343
3712.49	35.848
3716.34	36.7355
3720.18	37.2247
3724.02	35.9162
3727.86	34.6487
3731.7	34.1317
3735.53	34.8845
3739.36	36.2953
3743.19	36.5627
3747.02	37.5604
3750.84	38.3815
3754.66	38.657
3758.48	38.7285
3762.3	38.525
3766.12	38.4005
3769.93	38.692
3773.74	39.0408
3777.54	39.7448
3781.35	40.4004
3785.15	40.5466
3788.95	39.8348
3792.75	38.5646
3796.54	37.6181
3800.34	36.5099
3804.13	35.5554
3807.91	35.5496
3811.7	35.6818
3815.48	35.4908
3819.26	35.021
3823.04	35.0501
3826.82	35.9736
3830.59	37.695
3834.36	38.7605
3838.13	39.1234
3841.89	39.1627
3845.66	38.8318
3849.42	38.1149
3853.18	37.966
3856.93	38.0926
3860.69	38.2254
3864.44	38.3127
3868.19	38.2002
3871.93	38.1169
3875.68	38.135
3879.42	37.6461
3883.16	37.2546
3886.9	36.5643
3890.63	36.1078
3894.37	35.9494
3898.1	35.7782
3901.82	35.9055
3905.55	36.516
3909.27	37.8505
3912.99	38.5133
3916.71	39.5135
3920.43	38.7711
3924.14	37.4291
3927.85	36.4651
3931.56	36.0141
3935.27	35.1856
3938.97	35.7682
3942.67	34.7147
3946.37	35.1935
3950.07	37.7902
3953.77	40.0112
3957.46	40.5389
3961.15	40.3198
3964.84	38.8899
3968.52	37.7419
3972.2	37.3199
3975.89	37.28
3979.56	37.6816
3983.24	37.7417
3986.92	37.4034
3990.59	37.5003
3994.26	38.5964
3997.92	38.1687
3999.76	35.6721