File: Data/Raman/raw/bu24-ore4-anhedral_top_150 (500nm)_633nm_edge_100%_x100_vis_h30um_20sx2_01.txt
#Acq. time (s)=	20
#Accumulations=	2
#Range (cm-¹)=	100...4000
#Windows=	1
#Auto scanning=	Off
#Autofocus=	Off
#Macrospot=	Off
#AutoExposure=	Off
#Spike filter=	Multiple accum.
#Delay time (s)=	2
#Binning=	1
#Readout mode=	Signal
#DeNoise=	Standard
#ICS correction=	On
#Dark correction=	Off
#Inst. Process=	Off
#Detector Gain=	Best Dynamic
#Detector ADC=	50 kHz HS
#Detector temperature (°C)=	-60.09
#Instrument=	LabRAM HR Evol
#Detector=	SIN-EM FIVIS
#Objective=	x100_VIS
#Grating=	150 (500nm)
#ND Filter=	100%
#Laser=	633nm_Edge
#Hole=	30.0125
#Temperature=	0
#Range=	Visible
#StageXY=	75x50mm Scan+
#StageZ=	Z motor
#X (µm)=	0
#Y (µm)=	0
#Z (µm)=	0.8
#Full time(s)=	44
#Project=	20_10_27
#Sample=	BU24
#Site=
#Title=	BU24-Ore4-anhedral_top_150 (500nm)_633nm_Edge_100%_x100_VIS_H30um_20sX2
#Remark=
#Date=	27.10.2020 19:32
#Acquired=	27.10.2020 19:32:29
100.764	1619.59
107.281	1647.74
113.791	1738.73
120.297	1929.39
126.797	2265.46
133.291	2708.54
139.78	2620.38
146.264	1767.66
152.741	1471.3
159.214	1385.92
165.682	1447.63
172.144	1479.5
178.601	1476.51
185.053	1442.3
191.499	1386.4
197.939	1424.66
204.374	1497.32
210.805	1459.06
217.23	1393.2
223.648	1355.65
230.063	1387.77
236.472	1470.59
242.874	1571.82
249.273	1617.13
255.667	1659
262.053	1734.87
268.436	1776.37
274.813	1749.65
281.185	1650.64
287.552	1537.96
293.913	1447.53
300.27	1367.66
306.62	1313.32
312.965	1273.27
319.306	1244.35
325.64	1223.51
331.971	1213.52
338.295	1208.7
344.614	1208.61
350.93	1210.81
357.238	1215.13
363.542	1217.04
369.842	1242.94
376.135	1255.3
382.423	1294.95
388.706	1339.16
394.984	1355.92
401.258	1325.08
407.526	1268.26
413.789	1215.11
420.046	1180.1
426.299	1168.44
432.546	1161.12
438.788	1160.22
445.025	1166.48
451.257	1177.78
457.484	1189.63
463.706	1197.61
469.923	1209.95
476.135	1220.34
482.342	1231.01
488.544	1241.13
494.741	1250.45
500.933	1257.06
507.12	1253.72
513.3	1274.16
519.477	1333.21
525.649	1376.45
531.815	1357.89
537.976	1300.16
544.133	1232.44
550.285	1170.74
556.43	1124.78
562.572	1095.33
568.709	1075.92
574.84	1062.69
580.967	1056.83
587.09	1056.02
593.205	1058.62
599.318	1064.62
605.424	1073.05
611.527	1083.36
617.623	1093.25
623.716	1099.12
629.802	1098.28
635.884	1090.7
641.962	1076.95
648.034	1059.43
654.101	1040.65
660.165	1024.94
666.222	1014.47
672.274	1009.67
678.324	1009.96
684.366	1013.35
690.404	1020.81
696.438	1026.34
702.466	1030.58
708.491	1034.84
714.51	1039.61
720.523	1046.13
726.533	1053.79
732.537	1060.48
738.537	1077.17
744.531	1099.21
750.521	1117.31
756.507	1129.82
762.487	1142.76
768.463	1161.24
774.434	1173.36
780.4	1184.7
786.362	1195.18
792.319	1206.35
798.269	1222.79
804.217	1248.19
810.159	1288.71
816.097	1341.81
822.03	1404.01
827.958	1482.79
833.881	1582.13
839.801	1752.35
845.714	2037.32
851.624	2497.07
857.529	3222.31
863.428	4110.15
869.324	4793.6
875.215	4206.8
881.1	2876.74
886.982	1882.56
892.858	1342.92
898.73	1081.66
904.597	912.672
910.459	803.031
916.318	740.071
922.171	695.711
928.02	659.836
933.864	636.304
939.703	618.701
945.539	601.171
951.368	587.037
957.194	573.746
963.014	561.101
968.832	549.18
974.643	538.94
980.45	529.827
986.253	521.507
992.051	513.886
997.844	507.945
1003.63	503.657
1009.42	500.477
1015.2	497.736
1020.97	495.484
1026.74	493.125
1032.51	488.939
1038.27	485.061
1044.03	478.415
1049.78	472.686
1055.53	469.017
1061.27	465.367
1067.01	461.43
1072.75	458.268
1078.48	456.525
1084.2	451.654
1089.92	447.398
1095.64	444.719
1101.35	441.483
1107.06	439.133
1112.77	435.545
1118.46	431.955
1124.16	428.339
1129.85	424.654
1135.53	420.919
1141.22	417.221
1146.89	413.588
1152.56	410.039
1158.23	406.551
1163.9	403.134
1169.56	399.469
1175.21	396.541
1180.86	393.547
1186.51	390.964
1192.15	388.819
1197.78	387.325
1203.42	385.763
1209.04	384.39
1214.67	383.12
1220.29	382.114
1225.9	381.117
1231.51	378.92
1237.12	372.768
1242.72	367.412
1248.32	363.171
1253.92	359.459
1259.5	355.67
1265.09	352.348
1270.67	349.426
1276.25	347.187
1281.82	344.704
1287.39	345.514
1292.95	343.814
1298.51	340.655
1304.06	333.624
1309.61	330.013
1315.16	326.191
1320.7	326.122
1326.24	325.999
1331.77	323.158
1337.3	324.254
1342.83	321.392
1348.35	320.248
1353.86	317.585
1359.37	314.753
1364.88	312.158
1370.39	310.264
1375.89	307.32
1381.38	304.68
1386.87	302.659
1392.36	301.341
1397.84	300.623
1403.32	300.431
1408.79	300.876
1414.26	300.319
1419.73	298.117
1425.19	294.592
1430.65	291.71
1436.1	289.908
1441.55	289.125
1447	289.355
1452.44	287.796
1457.87	285.806
1463.31	284.546
1468.73	284.286
1474.16	284.294
1479.58	282.931
1484.99	280.448
1490.41	276.601
1495.81	273.523
1501.22	271.594
1506.62	270.259
1512.01	269.376
1517.4	268.779
1522.79	268.261
1528.17	267.099
1533.55	265.807
1538.93	264.007
1544.3	260.798
1549.67	263.844
1555.03	261.352
1560.39	253.665
1565.74	248.801
1571.09	246.736
1576.44	247.156
1581.78	247.175
1587.12	247.03
1592.45	246.401
1597.78	245.815
1603.11	245.483
1608.43	244.739
1613.75	243.734
1619.07	242.413
1624.38	239.311
1629.68	236.469
1634.98	233.97
1640.28	232.08
1645.58	230.787
1650.87	230.472
1656.15	230.96
1661.44	232.082
1666.71	232.335
1671.99	232.407
1677.26	230.636
1682.53	228.516
1687.79	226.204
1693.05	223.64
1698.3	221.265
1703.55	220.794
1708.8	220.654
1714.04	219.984
1719.28	218.878
1724.51	216.984
1729.75	213.991
1734.97	208.72
1740.2	204.126
1745.42	200.817
1750.63	198.167
1755.84	195.681
1761.05	193.337
1766.25	191.38
1771.45	189.443
1776.65	186.97
1781.84	183.725
1787.03	181.828
1792.21	180.593
1797.39	179.468
1802.57	178.441
1807.74	177.425
1812.91	176.079
1818.08	174.95
1823.24	173.959
1828.39	173.118
1833.55	172.506
1838.7	172.207
1843.84	171.69
1848.99	169.36
1854.12	166.199
1859.26	163.104
1864.39	160.675
1869.52	159.202
1874.64	158.341
1879.76	157.834
1884.87	158.085
1889.98	158.432
1895.09	158.402
1900.2	158.342
1905.3	157.667
1910.39	155.954
1915.49	154.109
1920.57	152.254
1925.66	150.628
1930.74	149.787
1935.82	149.37
1940.89	149.271
1945.96	149.441
1951.03	149.696
1956.09	149.759
1961.15	149.081
1966.21	147.708
1971.26	145.253
1976.31	142.645
1981.35	140.865
1986.39	139.554
1991.43	138.471
1996.46	137.565
2001.49	136.798
2006.52	136.119
2011.54	135.428
2016.56	134.566
2021.57	133.875
2026.58	133.249
2031.59	132.683
2036.59	132.135
2041.59	131.604
2046.59	131.08
2051.58	130.597
2056.57	130.112
2061.55	129.587
2066.54	129.126
2071.51	128.628
2076.49	128.152
2081.46	127.677
2086.43	127.185
2091.39	126.616
2096.35	125.71
2101.3	124.107
2106.26	122.586
2111.21	121.22
2116.15	120.337
2121.09	120.32
2126.03	120.469
2130.97	120.72
2135.9	120.67
2140.83	120.517
2145.75	119.5
2150.67	118.251
2155.59	116.763
2160.5	115.256
2165.41	114.008
2170.31	113.886
2175.22	114.58
2180.12	115.485
2185.01	116.345
2189.9	116.689
2194.79	115.848
2199.68	114.042
2204.56	112.417
2209.43	110.69
2214.31	109.046
2219.18	107.995
2224.05	106.071
2228.91	104.645
2233.77	103.606
2238.63	103.874
2243.48	104.671
2248.33	105.404
2253.17	105.678
2258.02	104.634
2262.86	103.953
2267.69	102.173
2272.52	100.487
2277.35	98.9895
2282.18	98.5839
2287	98.5677
2291.82	98.5771
2296.63	97.8556
2301.44	97.0778
2306.25	96.3407
2311.05	95.7454
2315.86	95.2901
2320.65	95.0249
2325.45	95.5645
2330.24	96.1009
2335.03	96.5972
2339.81	96.1072
2344.59	94.9894
2349.37	95.0608
2354.14	94.6083
2358.91	92.9875
2363.67	91.202
2368.44	89.4094
2373.2	88.0086
2377.95	87.4796
2382.71	87.8124
2387.46	88.7261
2392.2	89.7053
2396.95	90.095
2401.68	89.264
2406.42	88.233
2411.15	87.6178
2415.88	86.9136
2420.61	85.6359
2425.33	84.4825
2430.05	85.0034
2434.77	85.7366
2439.48	86.1433
2444.19	85.6895
2448.89	83.9657
2453.6	84.0203
2458.29	84.465
2462.99	83.966
2467.68	83.5762
2472.37	83.4133
2477.06	83.9646
2481.74	85.8146
2486.42	86.0829
2491.1	85.9547
2495.77	85.7824
2500.44	84.7289
2505.1	83.868
2509.76	82.7626
2514.42	81.7841
2519.08	81.39
2523.73	81.1786
2528.38	81.292
2533.03	79.9221
2537.67	78.4925
2542.31	77.2179
2546.95	76.5817
2551.58	76.3348
2556.21	76.258
2560.84	76.2928
2565.46	76.4081
2570.08	76.5285
2574.7	76.1523
2579.31	75.7693
2583.92	75.3924
2588.53	74.9447
2593.13	74.4666
2597.73	73.9144
2602.33	73.3474
2606.92	72.7471
2611.51	72.1454
2616.1	71.5753
2620.68	71.0713
2625.26	70.6454
2629.84	70.388
2634.42	70.3746
2638.99	70.335
2643.56	70.5466
2648.12	70.8244
2652.68	71.1012
2657.24	70.7338
2661.8	67.8882
2666.35	66.3149
2670.9	73.5119
2675.45	72.7292
2679.99	70.8909
2684.53	69.5089
2689.06	68.5363
2693.6	67.4047
2698.13	64.9335
2702.66	63.2153
2707.18	62.1457
2711.7	61.7737
2716.22	62.0419
2720.73	63.1506
2725.24	64.4872
2729.75	65.9976
2734.26	67.1256
2738.76	66.0169
2743.25	63.9853
2747.75	65.6171
2752.24	66.1238
2756.73	65.8852
2761.22	64.858
2765.7	63.5424
2770.18	63.246
2774.66	63.907
2779.13	65.4553
2783.6	65.9335
2788.07	65.9896
2792.53	66.0875
2797	66.1934
2801.45	66.2473
2805.91	66.1555
2810.36	65.207
2814.81	61.1511
2819.26	58.3878
2823.7	58.0427
2828.14	57.5838
2832.57	60.5599
2837.01	62.9755
2841.44	63.5572
2845.87	63.4246
2850.29	63.4961
2854.71	63.6328
2859.13	62.4175
2863.55	61.2152
2867.96	61.1599
2872.37	61.1875
2876.77	61.211
2881.18	61.2359
2885.58	61.2808
2889.97	61.1826
2894.37	61.3596
2898.76	61.3454
2903.15	61.2977
2907.53	61.2445
2911.91	61.2277
2916.29	60.8989
2920.67	60.5225
2925.04	59.934
2929.41	60.1281
2933.78	61.231
2938.14	59.7261
2942.5	58.5057
2946.86	57.7257
2951.22	57.2657
2955.57	56.9475
2959.92	56.6501
2964.26	56.4412
2968.61	56.3375
2972.95	56.2654
2977.28	56.3518
2981.62	56.6143
2985.95	57.4915
2990.28	58.6625
2994.6	58.7792
2998.93	56.7905
3003.25	57.0518
3007.56	57.6332
3011.88	58.1422
3016.19	57.5542
3020.49	56.2552
3024.8	54.6672
3029.1	53.8452
3033.4	53.9094
3037.7	55.1899
3041.99	56.5367
3046.28	57.7735
3050.57	57.8012
3054.85	57.5202
3059.13	57.1482
3063.41	56.7624
3067.69	56.4003
3071.96	56.1124
3076.23	56.2522
3080.5	56.4876
3084.76	56.5684
3089.02	56.6318
3093.28	56.6515
3097.53	56.6151
3101.79	56.4931
3106.04	56.6376
3110.28	57.0267
3114.53	56.2965
3118.77	54.9189
3123.01	53.5195
3127.24	52.1426
3131.47	51.0585
3135.7	51.2553
3139.93	52.5405
3144.15	54.084
3148.38	55.2457
3152.59	55.4682
3156.81	55.7149
3161.02	56.0015
3165.23	56.2434
3169.44	56.3646
3173.64	55.7081
3177.84	54.7566
3182.04	53.9617
3186.24	53.5278
3190.43	53.1588
3194.62	52.3918
3198.81	52.03
3202.99	52.5007
3207.17	53.4964
3211.35	55.0367
3215.53	55.0994
3219.7	54.1571
3223.87	53.2584
3228.04	52.7231
3232.2	53.1073
3236.36	53.2779
3240.52	52.3378
3244.68	51.77
3248.83	51.3495
3252.98	52.2222
3257.13	53.3271
3261.28	54.4892
3265.42	55.6287
3269.56	56.1692
3273.7	56.191
3277.83	55.821
3281.96	55.1738
3286.09	54.6906
3290.22	54.2941
3294.34	54.0033
3298.46	53.8939
3302.58	54.722
3306.69	54.9009
3310.8	54.5154
3314.91	54.6261
3319.02	54.821
3323.12	54.9614
3327.23	53.7513
3331.32	52.5149
3335.42	52.1386
3339.51	52.4587
3343.6	53.4486
3347.69	53.0035
3351.78	53.232
3355.86	53.5775
3359.94	53.8721
3364.02	54.1076
3368.09	54.0792
3372.16	54.0649
3376.23	53.8034
3380.29	53.3596
3384.36	52.9132
3388.42	52.3975
3392.48	52.1408
3396.53	51.9742
3400.58	52.2559
3404.63	53.5706
3408.68	54.3603
3412.73	54.2062
3416.77	54.4078
3420.81	53.7974
3424.84	53.7388
3428.88	53.5792
3432.91	53.9688
3436.94	53.4654
3440.96	53.0775
3444.99	52.5346
3449.01	52.624
3453.03	53.1342
3457.04	52.8513
3461.05	52.7749
3465.06	53.6931
3469.07	53.3423
3473.08	52.0604
3477.08	50.8948
3481.08	49.7263
3485.07	48.5593
3489.07	47.2435
3493.06	48.4108
3497.05	50.466
3501.04	52.1715
3505.02	53.3515
3509	53.5714
3512.98	53.7528
3516.96	53.6019
3520.93	53.2319
3524.9	52.8511
3528.87	52.5301
3532.83	52.2701
3536.8	52.173
3540.76	52.5934
3544.71	53.4006
3548.67	54.2932
3552.62	54.8334
3556.57	53.6602
3560.52	52.2705
3564.47	51.8629
3568.41	51.6706
3572.35	50.5806
3576.29	50.0091
3580.22	50.0996
3584.15	50.5641
3588.08	51.1653
3592.01	51.7572
3595.93	52.2068
3599.85	52.6308
3603.77	52.9072
3607.69	53.1071
3611.61	53.2566
3615.52	53.2981
3619.43	53.1677
3623.33	52.7112
3627.24	52.1826
3631.14	51.6578
3635.04	52.1964
3638.93	51.9829
3642.83	52.4009
3646.72	51.8667
3650.61	51.8341
3654.49	51.9109
3658.38	52.0503
3662.26	52.0855
3666.14	51.7627
3670.01	51.6009
3673.89	52.2128
3677.76	52.3993
3681.63	51.8963
3685.5	51.2185
3689.36	50.6542
3693.22	50.1364
3697.08	50.5727
3700.94	51.2181
3704.79	52.1186
3708.64	51.9657
3712.49	51.7855
3716.34	51.4084
3720.18	50.8094
3724.02	50.4625
3727.86	48.2749
3731.7	47.7639
3735.53	48.0673
3739.36	51.1604
3743.19	53.5553
3747.02	48.0332
3750.84	45.5183
3754.66	50.6225
3758.48	50.5262
3762.3	51.5813
3766.12	51.85
3769.93	51.2502
3773.74	50.5729
3777.54	50.0139
3781.35	49.6328
3785.15	49.6565
3788.95	50.4753
3792.75	51.3617
3796.54	52.2848
3800.34	53.0962
3804.13	53.3289
3807.91	52.5037
3811.7	52.6258
3815.48	52.6502
3819.26	53.4079
3823.04	53.0153
3826.82	52.59
3830.59	52.3066
3834.36	52.4539
3838.13	53.7061
3841.89	53.8504
3845.66	54.1499
3849.42	54.6445
3853.18	54.2857
3856.93	53.0636
3860.69	51.8955
3864.44	51.0332
3868.19	50.7663
3871.93	50.9607
3875.68	51.3756
3879.42	50.24
3883.16	49.2967
3886.9	48.703
3890.63	48.5338
3894.37	48.9967
3898.1	49.8601
3901.82	50.2463
3905.55	50.5285
3909.27	51.0279
3912.99	51.7418
3916.71	52.203
3920.43	50.7208
3924.14	50.061
3927.85	49.6186
3931.56	50.1433
3935.27	51.189
3938.97	51.2963
3942.67	51.1931
3946.37	50.5737
3950.07	49.9913
3953.77	49.5463
3957.46	49.2747
3961.15	49.1681
3964.84	49.1758
3968.52	49.3797
3972.2	49.7369
3975.89	50.2368
3979.56	50.3474
3983.24	51.042
3986.92	51.348
3990.59	51.7067
3994.26	52.6337
3997.92	49.1634
3999.76	46.3325