File: Data/Raman/raw/bu24-ore4-prism_top2_150 (500nm)_633nm_edge_100%_x100_vis_h50um_20sx2_01.txt
#Acq. time (s)=	20
#Accumulations=	2
#Range (cm-¹)=	100...4000
#Windows=	1
#Auto scanning=	Off
#Autofocus=	Off
#Macrospot=	Off
#AutoExposure=	Off
#Spike filter=	Multiple accum.
#Delay time (s)=	2
#Binning=	1
#Readout mode=	Signal
#DeNoise=	Standard
#ICS correction=	On
#Dark correction=	Off
#Inst. Process=	Off
#Detector Gain=	Best Dynamic
#Detector ADC=	50 kHz HS
#Detector temperature (°C)=	-60.09
#Instrument=	LabRAM HR Evol
#Detector=	SIN-EM FIVIS
#Objective=	x100_VIS
#Grating=	150 (500nm)
#ND Filter=	100%
#Laser=	633nm_Edge
#Hole=	49.98
#Temperature=	0
#Range=	Visible
#StageXY=	75x50mm Scan+
#StageZ=	Z motor
#X (µm)=	0
#Y (µm)=	0
#Z (µm)=	-0.1
#Full time(s)=	44
#Project=	20_10_27
#Sample=	BU24
#Site=
#Title=	BU24-Ore4-prism_top2_150 (500nm)_633nm_Edge_100%_x100_VIS_H50um_20sX2
#Remark=
#Date=	27.10.2020 19:36
#Acquired=	27.10.2020 19:36:04
100.764	3817.95
107.281	4040.2
113.791	4263.9
120.297	4579.18
126.797	4769.2
133.291	4464.48
139.78	3759.17
146.264	3241.1
152.741	2939.06
159.214	2814.1
165.682	2768.11
172.144	2722.05
178.601	2714.25
185.053	2717.23
191.499	2722.82
197.939	2708.49
204.374	2660.19
210.805	2622.93
217.23	2594.05
223.648	2577.87
230.063	2554.88
236.472	2540.73
242.874	2545.62
249.273	2557.89
255.667	2567.75
262.053	2551.35
268.436	2592.97
274.813	2660.14
281.185	2694.97
287.552	2704.91
293.913	2675.22
300.27	2617.03
306.62	2553.36
312.965	2491.48
319.306	2445.21
325.64	2414.99
331.971	2397.48
338.295	2395.35
344.614	2404.52
350.93	2419.48
357.238	2438.2
363.542	2451.41
369.842	2475.69
376.135	2501.12
382.423	2518.34
388.706	2515.89
394.984	2510.58
401.258	2484.08
407.526	2442.66
413.789	2389.78
420.046	2341.65
426.299	2297.15
432.546	2258.1
438.788	2226.27
445.025	2198.73
451.257	2180.26
457.484	2162.5
463.706	2141.84
469.923	2120.77
476.135	2103.9
482.342	2087.74
488.544	2074.56
494.741	2056.47
500.933	2039.87
507.12	2027.64
513.3	2018.29
519.477	2008.07
525.649	2001.47
531.815	2002.13
537.976	1998.89
544.133	1997.44
550.285	1998.92
556.43	1996.93
562.572	1993.36
568.709	1989.4
574.84	1986.39
580.967	1988.82
587.09	1997.99
593.205	2013.07
599.318	2028.68
605.424	2044.63
611.527	2060.89
617.623	2069.07
623.716	2068.96
629.802	2061.84
635.884	2056.05
641.962	2054.64
648.034	2056.99
654.101	2062.74
660.165	2076.66
666.222	2092.86
672.274	2109.83
678.324	2126.96
684.366	2144.38
690.404	2165.29
696.438	2189.51
702.466	2216.12
708.491	2244.89
714.51	2277.99
720.523	2318.16
726.533	2362.92
732.537	2412.24
738.537	2459.8
744.531	2529.47
750.521	2599.89
756.507	2666.17
762.487	2720.27
768.463	2764.81
774.434	2788.32
780.4	2804.98
786.362	2800.59
792.319	2789.08
798.269	2774.24
804.217	2762.67
810.159	2758.12
816.097	2783.24
822.03	2815.32
827.958	2854.51
833.881	2898.34
839.801	2993.99
845.714	3085.15
851.624	3130.6
857.529	3094.39
863.428	2969.41
869.324	2637.81
875.215	2258.21
881.1	1920.2
886.982	1635.44
892.858	1493.51
898.73	1388.73
904.597	1316.81
910.459	1257.22
916.318	1217.69
922.171	1182.07
928.02	1157.33
933.864	1138.09
939.703	1115.92
945.539	1096.43
951.368	1078.5
957.194	1060.68
963.014	1042.85
968.832	1027.47
974.643	1013.84
980.45	1001.83
986.253	990.357
992.051	979.882
997.844	970.275
1003.63	961.623
1009.42	952.645
1015.2	945.796
1020.97	940.788
1026.74	936.341
1032.51	932.308
1038.27	928.136
1044.03	921.926
1049.78	914.712
1055.53	905.988
1061.27	894.699
1067.01	883.358
1072.75	873.173
1078.48	865.971
1084.2	859.664
1089.92	852.334
1095.64	847.082
1101.35	844.603
1107.06	842.08
1112.77	837.008
1118.46	832.377
1124.16	827.639
1129.85	823.232
1135.53	820.378
1141.22	817.724
1146.89	811.591
1152.56	805.288
1158.23	799.482
1163.9	793.44
1169.56	787.843
1175.21	783.449
1180.86	779.81
1186.51	776.875
1192.15	774.554
1197.78	772.343
1203.42	768.727
1209.04	764.734
1214.67	760.98
1220.29	757.539
1225.9	754.125
1231.51	750.716
1237.12	747.129
1242.72	743.112
1248.32	739.038
1253.92	734.99
1259.5	729.847
1265.09	717.099
1270.67	712.125
1276.25	710.451
1281.82	712.188
1287.39	711.383
1292.95	707.222
1298.51	702.059
1304.06	696.597
1309.61	694.306
1315.16	692.507
1320.7	690.102
1326.24	684.031
1331.77	680.122
1337.3	677.579
1342.83	674.776
1348.35	672.806
1353.86	670.324
1359.37	666.62
1364.88	661.604
1370.39	655.586
1375.89	653.414
1381.38	655.312
1386.87	652.341
1392.36	649.038
1397.84	647.467
1403.32	644.614
1408.79	642.189
1414.26	639.498
1419.73	636.362
1425.19	633.073
1430.65	629.491
1436.1	625.598
1441.55	621.639
1447	617.05
1452.44	612.457
1457.87	606.712
1463.31	601.5
1468.73	599.199
1474.16	598.079
1479.58	597.73
1484.99	597.748
1490.41	593.563
1495.81	591.285
1501.22	589.005
1506.62	587.766
1512.01	587.272
1517.4	587.211
1522.79	586.969
1528.17	581.945
1533.55	576.754
1538.93	575.056
1544.3	574.861
1549.67	575.82
1555.03	577.037
1560.39	576.756
1565.74	576.375
1571.09	574.525
1576.44	569.978
1581.78	565.769
1587.12	562.246
1592.45	558.877
1597.78	555.698
1603.11	553.146
1608.43	548.771
1613.75	544.927
1619.07	543.072
1624.38	541.444
1629.68	538.169
1634.98	534.281
1640.28	530.275
1645.58	525.511
1650.87	520.627
1656.15	517.872
1661.44	514.792
1666.71	511.36
1671.99	507.246
1677.26	503.596
1682.53	500.426
1687.79	496.425
1693.05	493.51
1698.3	492.836
1703.55	489.252
1708.8	485.403
1714.04	482.725
1719.28	474.774
1724.51	471.738
1729.75	472.464
1734.97	468.525
1740.2	462.145
1745.42	456.804
1750.63	452.421
1755.84	449.914
1761.05	443.705
1766.25	438.338
1771.45	434.76
1776.65	433.782
1781.84	433.151
1787.03	432.718
1792.21	432.248
1797.39	431.149
1802.57	429.037
1807.74	428.803
1812.91	424.569
1818.08	419.182
1823.24	414.358
1828.39	410.422
1833.55	407.122
1838.7	405.526
1843.84	404.716
1848.99	404.476
1854.12	404.554
1859.26	403.834
1864.39	403.369
1869.52	403.229
1874.64	402.001
1879.76	398.429
1884.87	395.042
1889.98	392.87
1895.09	391.944
1900.2	391.997
1905.3	389.901
1910.39	387.846
1915.49	388.148
1920.57	386.942
1925.66	383.769
1930.74	380.862
1935.82	377.192
1940.89	371.66
1945.96	367.605
1951.03	365.342
1956.09	364.782
1961.15	360.489
1966.21	361.802
1971.26	363.651
1976.31	364.544
1981.35	364.949
1986.39	362.034
1991.43	358.333
1996.46	355.317
2001.49	353.675
2006.52	352.994
2011.54	354.61
2016.56	355.338
2021.57	354.247
2026.58	352.254
2031.59	349.334
2036.59	346.245
2041.59	343.759
2046.59	343.201
2051.58	344.128
2056.57	344.738
2061.55	344.152
2066.54	342.156
2071.51	339.819
2076.49	337.691
2081.46	335.381
2086.43	330.063
2091.39	324.859
2096.35	321.259
2101.3	319.226
2106.26	319.403
2111.21	320.204
2116.15	320.683
2121.09	320.762
2126.03	319.898
2130.97	319.332
2135.9	317.444
2140.83	314.647
2145.75	309.922
2150.67	307.892
2155.59	307.01
2160.5	306.655
2165.41	306.76
2170.31	304.554
2175.22	301.878
2180.12	300.036
2185.01	298.521
2189.9	297.251
2194.79	296.26
2199.68	295.434
2204.56	294.934
2209.43	294.797
2214.31	294.858
2219.18	294.811
2224.05	292.391
2228.91	290.119
2233.77	288.16
2238.63	286.97
2243.48	286.075
2248.33	285.06
2253.17	283.498
2258.02	281.422
2262.86	281.799
2267.69	281.147
2272.52	278.864
2277.35	276.818
2282.18	275.254
2287	275.411
2291.82	273.496
2296.63	271.765
2301.44	270.955
2306.25	270.548
2311.05	270.226
2315.86	269.783
2320.65	269.268
2325.45	269.193
2330.24	269.331
2335.03	265.806
2339.81	263.959
2344.59	262.967
2349.37	262.637
2354.14	262.662
2358.91	261.455
2363.67	261.108
2368.44	260.952
2373.2	260.767
2377.95	260.5
2382.71	259.768
2387.46	257.565
2392.2	254.035
2396.95	251.76
2401.68	250.06
2406.42	247.943
2411.15	248.563
2415.88	249.938
2420.61	250.4
2425.33	248.761
2430.05	246.958
2434.77	244.942
2439.48	242.53
2444.19	239.954
2448.89	237.762
2453.6	237.724
2458.29	238.548
2462.99	239.561
2467.68	240.372
2472.37	240.603
2477.06	240.217
2481.74	239.368
2486.42	238.37
2491.1	237.267
2495.77	236.126
2500.44	235.627
2505.1	235.252
2509.76	234.141
2514.42	230.806
2519.08	228.083
2523.73	226.016
2528.38	223.97
2533.03	222.936
2537.67	222.953
2542.31	225.188
2546.95	227.526
2551.58	228.361
2556.21	228.258
2560.84	227.222
2565.46	224.985
2570.08	222.675
2574.7	221.326
2579.31	220.535
2583.92	220.306
2588.53	220.615
2593.13	220.273
2597.73	218.49
2602.33	217.411
2606.92	218.217
2611.51	216.8
2616.1	213.745
2620.68	210.896
2625.26	208.527
2629.84	206.913
2634.42	206.474
2638.99	206.223
2643.56	205.234
2648.12	206.46
2652.68	207.062
2657.24	207.309
2661.8	206.948
2666.35	205.569
2670.9	202.728
2675.45	200.465
2679.99	197.146
2684.53	198.438
2689.06	200.033
2693.6	200.763
2698.13	196.413
2702.66	195.413
2707.18	195.275
2711.7	194.719
2716.22	193.377
2720.73	192.894
2725.24	193.487
2729.75	194.074
2734.26	193.522
2738.76	193.1
2743.25	193.693
2747.75	193.423
2752.24	190.155
2756.73	187.283
2761.22	185.314
2765.7	184.182
2770.18	183.845
2774.66	184.302
2779.13	185.404
2783.6	186.746
2788.07	186.967
2792.53	185.184
2797	184.874
2801.45	186.625
2805.91	187.594
2810.36	185.586
2814.81	184.201
2819.26	183.56
2823.7	182.126
2828.14	179.445
2832.57	177.914
2837.01	176.861
2841.44	175.915
2845.87	172.589
2850.29	171.091
2854.71	171.843
2859.13	175.049
2863.55	176.87
2867.96	177.7
2872.37	178.15
2876.77	178.549
2881.18	178.573
2885.58	177.11
2889.97	174.527
2894.37	172.5
2898.76	170.852
2903.15	170.263
2907.53	170.716
2911.91	170.645
2916.29	171.524
2920.67	171.47
2925.04	169.838
2929.41	167.936
2933.78	166.064
2938.14	164.61
2942.5	163.366
2946.86	162.932
2951.22	162.753
2955.57	162.751
2959.92	162.724
2964.26	162.365
2968.61	160.953
2972.95	159.539
2977.28	158.235
2981.62	157.904
2985.95	158.041
2990.28	158.343
2994.6	158.715
2998.93	159.082
3003.25	158.157
3007.56	157.421
3011.88	156.996
3016.19	155.987
3020.49	155.799
3024.8	155.996
3029.1	154.861
3033.4	154.493
3037.7	153.729
3041.99	153.205
3046.28	151.739
3050.57	150.022
3054.85	148.266
3059.13	147.016
3063.41	147.954
3067.69	150.205
3071.96	152.519
3076.23	154.246
3080.5	155.378
3084.76	154.505
3089.02	151.944
3093.28	149.982
3097.53	148.626
3101.79	147.614
3106.04	146.966
3110.28	146.796
3114.53	147.102
3118.77	147.782
3123.01	148.005
3127.24	148.033
3131.47	148.947
3135.7	149.707
3139.93	147.664
3144.15	145.09
3148.38	142.843
3152.59	140.908
3156.81	139.309
3161.02	137.979
3165.23	136.851
3169.44	136.093
3173.64	135.594
3177.84	135.679
3182.04	137.414
3186.24	139.868
3190.43	140.626
3194.62	140.036
3198.81	138.699
3202.99	137.245
3207.17	136.585
3211.35	137.23
3215.53	138.16
3219.7	140.016
3223.87	140.966
3228.04	141.066
3232.2	139.483
3236.36	137.423
3240.52	136.716
3244.68	136.97
3248.83	135.514
3252.98	133.72
3257.13	132.184
3261.28	131.185
3265.42	130.54
3269.56	130.211
3273.7	130.224
3277.83	131.362
3281.96	132.439
3286.09	132.575
3290.22	132.091
3294.34	129.783
3298.46	129.374
3302.58	129.191
3306.69	129.245
3310.8	129.362
3314.91	129.572
3319.02	128.542
3323.12	127.053
3327.23	125.87
3331.32	125.336
3335.42	124.942
3339.51	125.503
3343.6	126.229
3347.69	126.991
3351.78	127.766
3355.86	128.358
3359.94	128.426
3364.02	128.111
3368.09	127.691
3372.16	127.067
3376.23	126.285
3380.29	125.411
3384.36	124.543
3388.42	124.213
3392.48	123.012
3396.53	121.876
3400.58	121.543
3404.63	121.082
3408.68	121.516
3412.73	120.897
3416.77	120.24
3420.81	121.162
3424.84	122.333
3428.88	123.445
3432.91	124.234
3436.94	124.651
3440.96	123.4
3444.99	122.563
3449.01	122.745
3453.03	123.573
3457.04	124.616
3461.05	125.791
3465.06	126.622
3469.07	126.038
3473.08	125.235
3477.08	124.652
3481.08	123.9
3485.07	122.358
3489.07	121.065
3493.06	119.898
3497.05	118.77
3501.04	119.133
3505.02	120.388
3509	121.199
3512.98	121.321
3516.96	120.947
3520.93	121.037
3524.9	121.144
3528.87	119.655
3532.83	118.446
3536.8	117.352
3540.76	116.385
3544.71	115.419
3548.67	114.441
3552.62	113.777
3556.57	113.999
3560.52	114.527
3564.47	114.761
3568.41	114.261
3572.35	114.003
3576.29	114.161
3580.22	114.197
3584.15	113.805
3588.08	113.767
3592.01	115.02
3595.93	116.096
3599.85	117.554
3603.77	119.025
3607.69	119.486
3611.61	118.559
3615.52	116.356
3619.43	113.271
3623.33	110.873
3627.24	109.905
3631.14	108.926
3635.04	108.186
3638.93	110.552
3642.83	112.525
3646.72	112.465
3650.61	111.65
3654.49	110.21
3658.38	109.071
3662.26	108.266
3666.14	106.589
3670.01	106.044
3673.89	107.187
3677.76	108.948
3681.63	110.391
3685.5	111.856
3689.36	112.663
3693.22	111.827
3697.08	112.525
3700.94	113.009
3704.79	112.951
3708.64	114.028
3712.49	114.128
3716.34	111.16
3720.18	108.428
3724.02	106.624
3727.86	105.899
3731.7	106.153
3735.53	105.927
3739.36	104.426
3743.19	103.112
3747.02	102.094
3750.84	101.573
3754.66	101.149
3758.48	101.885
3762.3	102.933
3766.12	103.733
3769.93	102.977
3773.74	102.885
3777.54	103.535
3781.35	104.937
3785.15	105.913
3788.95	106.618
3792.75	106.627
3796.54	106.534
3800.34	106.441
3804.13	105.917
3807.91	105.224
3811.7	104.592
3815.48	104.094
3819.26	103.866
3823.04	103.751
3826.82	103.727
3830.59	103.917
3834.36	104.214
3838.13	104.694
3841.89	105.271
3845.66	105.064
3849.42	104.492
3853.18	104.017
3856.93	104.239
3860.69	104.995
3864.44	105.114
3868.19	104.948
3871.93	104.196
3875.68	100.892
3879.42	98.2426
3883.16	102.382
3886.9	101.572
3890.63	97.5508
3894.37	96.1495
3898.1	97.243
3901.82	100.001
3905.55	102.772
3909.27	104.77
3912.99	105.936
3916.71	103.745
3920.43	103.469
3924.14	103.041
3927.85	101.155
3931.56	99.144
3935.27	98.8274
3938.97	97.7799
3942.67	97.0749
3946.37	96.6262
3950.07	96.7991
3953.77	97.5559
3957.46	98.3018
3961.15	98.9864
3964.84	99.2574
3968.52	98.9397
3972.2	98.213
3975.89	97.2542
3979.56	96.31
3983.24	95.4061
3986.92	95.3931
3990.59	95.2963
3994.26	94.3175
3997.92	92.1825
3999.76	90.9552