File: Data/Raman/raw/bu24-ore2_150 (500nm)_633nm_edge_100%_x100_vis_h30um_10sx2_01.txt
#Acq. time (s)=	10
#Accumulations=	2
#Range (cm-¹)=	100...4000
#Windows=	1
#Auto scanning=	Off
#Autofocus=	Off
#Macrospot=	Off
#AutoExposure=	Off
#Spike filter=	Multiple accum.
#Delay time (s)=	2
#Binning=	1
#Readout mode=	Signal
#DeNoise=	Standard
#ICS correction=	On
#Dark correction=	Off
#Inst. Process=	Off
#Detector Gain=	Best Dynamic
#Detector ADC=	50 kHz HS
#Detector temperature (°C)=	-60.09
#Instrument=	LabRAM HR Evol
#Detector=	SIN-EM FIVIS
#Objective=	x20_VIS
#Grating=	150 (500nm)
#ND Filter=	100%
#Laser=	633nm_Edge
#Hole=	30.0125
#Temperature=	0
#Range=	Visible
#StageXY=	75x50mm Scan+
#StageZ=	Z motor
#X (µm)=	0
#Y (µm)=	0
#Z (µm)=	56.3
#Full time(s)=	25
#Project=	20_10_27
#Sample=	BU24
#Site=
#Title=	BU24-Ore2_150 (500nm)_633nm_Edge_100%_x20_VIS_H30um_10sX2
#Remark=
#Date=	27.10.2020 19:02
#Acquired=	27.10.2020 19:02:28
100.764	1034.88
107.281	1052.83
113.791	1111.78
120.297	1236.18
126.797	1422.39
133.291	1666.76
139.78	1546.2
146.264	1146.21
152.741	939.535
159.214	907.601
165.682	919.945
172.144	935.926
178.601	933.173
185.053	904.706
191.499	879.158
197.939	881.305
204.374	902.984
210.805	890.481
217.23	856.393
223.648	851.321
230.063	882.005
236.472	927.256
242.874	968.231
249.273	989.486
255.667	1002.29
262.053	1016.94
268.436	1021.51
274.813	1000.74
281.185	966.961
287.552	927.377
293.913	884.983
300.27	846.189
306.62	813.958
312.965	789.851
319.306	769.891
325.64	754.144
331.971	747.073
338.295	744.987
344.614	743.729
350.93	747.718
357.238	749.94
363.542	762.845
369.842	780.281
376.135	794.979
382.423	809.895
388.706	820.076
394.984	823.253
401.258	803.778
407.526	771.491
413.789	739.599
420.046	716.522
426.299	709.675
432.546	706.843
438.788	708.562
445.025	711.47
451.257	716.361
457.484	719.854
463.706	723.607
469.923	726.155
476.135	741.903
482.342	759.288
488.544	765.822
494.741	766.628
500.933	761.077
507.12	780.445
513.3	809.465
519.477	835.274
525.649	855.419
531.815	868.903
537.976	844.419
544.133	806.788
550.285	762.366
556.43	721.127
562.572	687.946
568.709	678.668
574.84	675.079
580.967	676.607
587.09	677.413
593.205	680.875
599.318	685.841
605.424	690.789
611.527	692.72
617.623	693.051
623.716	692.554
629.802	691.64
635.884	688.968
641.962	684.386
648.034	679.188
654.101	671.821
660.165	665.932
666.222	663.48
672.274	661.843
678.324	663.11
684.366	665.418
690.404	670.512
696.438	675.789
702.466	679.491
708.491	682.505
714.51	686.891
720.523	689.919
726.533	697.21
732.537	707.976
738.537	719.82
744.531	734.858
750.521	752.44
756.507	771.832
762.487	789.317
768.463	800.889
774.434	809.317
780.4	814.345
786.362	816.706
792.319	819.89
798.269	826.672
804.217	836.703
810.159	847.607
816.097	877.588
822.03	915.547
827.958	944.307
833.881	992.62
839.801	1064.47
845.714	1198.12
851.624	1409.9
857.529	1723.48
863.428	2247.35
869.324	2786.92
875.215	2826.66
881.1	2091.53
886.982	1293.12
892.858	883.838
898.73	682.485
904.597	574.833
910.459	512.942
916.318	476.658
922.171	447.431
928.02	427.476
933.864	410.214
939.703	394.611
945.539	384.836
951.368	376.51
957.194	369.594
963.014	361.753
968.832	355.141
974.643	351.087
980.45	345.49
986.253	339.827
992.051	335.664
997.844	331.562
1003.63	327.955
1009.42	326.336
1015.2	325.526
1020.97	324.585
1026.74	322.93
1032.51	320.783
1038.27	318.833
1044.03	317.049
1049.78	314.867
1055.53	311.433
1061.27	307.866
1067.01	304.594
1072.75	301.879
1078.48	298.942
1084.2	296.551
1089.92	294.727
1095.64	292.872
1101.35	292.271
1107.06	291.045
1112.77	290.593
1118.46	289.582
1124.16	288.016
1129.85	286.07
1135.53	283.734
1141.22	281.242
1146.89	279.178
1152.56	273.813
1158.23	269.257
1163.9	266.017
1169.56	264.867
1175.21	263.759
1180.86	262.28
1186.51	261.553
1192.15	261.654
1197.78	261.481
1203.42	261.14
1209.04	260.451
1214.67	256.335
1220.29	253.66
1225.9	251.667
1231.51	250.3
1237.12	248.759
1242.72	248.268
1248.32	245.912
1253.92	241.792
1259.5	238.906
1265.09	235.124
1270.67	235.351
1276.25	235.559
1281.82	235.32
1287.39	232.165
1292.95	227.477
1298.51	223.043
1304.06	221.599
1309.61	224.399
1315.16	226.418
1320.7	227.874
1326.24	226.685
1331.77	226.714
1337.3	227.332
1342.83	224.363
1348.35	220.914
1353.86	218.689
1359.37	217.101
1364.88	215.573
1370.39	214.7
1375.89	213.689
1381.38	212.134
1386.87	210.647
1392.36	209.823
1397.84	208.153
1403.32	207.183
1408.79	206.465
1414.26	205.841
1419.73	206.954
1425.19	208.028
1430.65	208.128
1436.1	208.517
1441.55	206.219
1447	203.869
1452.44	200.812
1457.87	199.465
1463.31	198.271
1468.73	196.758
1474.16	195.432
1479.58	194.29
1484.99	193.344
1490.41	192.58
1495.81	192.002
1501.22	191.606
1506.62	191.442
1512.01	191.103
1517.4	189.754
1522.79	187.785
1528.17	186.807
1533.55	185.952
1538.93	185.185
1544.3	185.222
1549.67	185.211
1555.03	181.979
1560.39	179.483
1565.74	178.289
1571.09	178.063
1576.44	180.019
1581.78	179.613
1587.12	176.75
1592.45	174.516
1597.78	172.914
1603.11	171.837
1608.43	171.089
1613.75	170.656
1619.07	170.457
1624.38	170.328
1629.68	169.719
1634.98	168.851
1640.28	167.312
1645.58	166.995
1650.87	165.955
1656.15	164.66
1661.44	163.543
1666.71	163.177
1671.99	161.899
1677.26	159.513
1682.53	156.643
1687.79	153.847
1693.05	152.742
1698.3	154.257
1703.55	156.974
1708.8	153.815
1714.04	153.947
1719.28	156.173
1724.51	155.667
1729.75	153.754
1734.97	151.218
1740.2	147.963
1745.42	144.238
1750.63	140.818
1755.84	138.05
1761.05	136.761
1766.25	136.25
1771.45	136.461
1776.65	135.719
1781.84	133.562
1787.03	131.585
1792.21	130.004
1797.39	128.61
1802.57	127.347
1807.74	126.159
1812.91	125.062
1818.08	124.034
1823.24	123.079
1828.39	122.122
1833.55	121.726
1838.7	121.434
1843.84	121.213
1848.99	121.069
1854.12	120.885
1859.26	120.682
1864.39	119.979
1869.52	119.224
1874.64	118.459
1879.76	117.654
1884.87	116.825
1889.98	115.983
1895.09	115.14
1900.2	114.308
1905.3	113.497
1910.39	112.722
1915.49	112.069
1920.57	111.473
1925.66	110.97
1930.74	110.472
1935.82	109.984
1940.89	109.514
1945.96	109.048
1951.03	108.571
1956.09	107.584
1961.15	106.593
1966.21	105.457
1971.26	104.239
1976.31	102.847
1981.35	101.91
1986.39	103.44
1991.43	102.129
1996.46	100.915
2001.49	99.7554
2006.52	99.925
2011.54	100.017
2016.56	101.359
2021.57	100.544
2026.58	98.2332
2031.59	96.5623
2036.59	96.4487
2041.59	96.6672
2046.59	96.8925
2051.58	97.0825
2056.57	95.5404
2061.55	94.3859
2066.54	94.2037
2071.51	93.1474
2076.49	92.5939
2081.46	93.0928
2086.43	92.5403
2091.39	88.3184
2096.35	90.4046
2101.3	91.8921
2106.26	91.1553
2111.21	87.0517
2116.15	87.0516
2121.09	87.3628
2126.03	87.5331
2130.97	87.5432
2135.9	87.4867
2140.83	87.4698
2145.75	87.2276
2150.67	86.9156
2155.59	86.4129
2160.5	85.403
2165.41	85.1938
2170.31	85.3479
2175.22	84.9354
2180.12	84.5271
2185.01	84.1237
2189.9	83.7272
2194.79	83.3398
2199.68	82.964
2204.56	82.6124
2209.43	82.287
2214.31	81.9536
2219.18	81.6299
2224.05	81.3165
2228.91	81.0155
2233.77	79.7449
2238.63	79.3892
2243.48	80.1842
2248.33	79.9209
2253.17	79.6546
2258.02	79.3767
2262.86	79.0791
2267.69	78.5091
2272.52	77.6145
2277.35	76.6759
2282.18	76.5741
2287	75.7394
2291.82	75.0629
2296.63	74.3043
2301.44	74.8464
2306.25	75.6351
2311.05	75.9818
2315.86	74.9327
2320.65	74.0355
2325.45	73.9449
2330.24	72.567
2335.03	71.266
2339.81	70.3248
2344.59	69.9098
2349.37	70.1564
2354.14	70.2493
2358.91	69.6367
2363.67	68.9063
2368.44	68.8077
2373.2	69.4836
2377.95	69.0722
2382.71	69.41
2387.46	68.7305
2392.2	68.0663
2396.95	67.5477
2401.68	67.1655
2406.42	66.7801
2411.15	66.4383
2415.88	66.1336
2420.61	65.8606
2425.33	65.6101
2430.05	65.369
2434.77	65.1363
2439.48	64.9119
2444.19	64.6953
2448.89	64.4845
2453.6	64.2819
2458.29	64.092
2462.99	63.934
2467.68	64.0418
2472.37	64.1143
2477.06	64.1886
2481.74	64.154
2486.42	64.5847
2491.1	65.0224
2495.77	65.4439
2500.44	65.7689
2505.1	65.0191
2509.76	64.2497
2514.42	62.6503
2519.08	61.0262
2523.73	59.6331
2528.38	59.4108
2533.03	59.7296
2537.67	60.5989
2542.31	61.4251
2546.95	60.9657
2551.58	60.4551
2556.21	60.3724
2560.84	59.9865
2565.46	60.0773
2570.08	59.8486
2574.7	59.4163
2579.31	59.173
2583.92	58.5873
2588.53	57.7319
2593.13	56.5316
2597.73	55.7585
2602.33	55.4316
2606.92	55.3364
2611.51	55.4725
2616.1	55.6395
2620.68	55.6273
2625.26	55.9582
2629.84	56.3387
2634.42	56.7809
2638.99	56.9813
2643.56	56.1111
2648.12	55.1849
2652.68	53.9664
2657.24	53.0059
2661.8	51.7058
2666.35	52.2631
2670.9	53.4585
2675.45	53.2062
2679.99	53.4368
2684.53	53.3721
2689.06	53.1902
2693.6	53.0102
2698.13	52.8633
2702.66	52.8105
2707.18	53.2584
2711.7	54.259
2716.22	54.9865
2720.73	53.2661
2725.24	51.8514
2729.75	50.5741
2734.26	50.0993
2738.76	51.1685
2743.25	52.6257
2747.75	52.0533
2752.24	51.5281
2756.73	51.0906
2761.22	50.9566
2765.7	50.1096
2770.18	49.1745
2774.66	49.2012
2779.13	49.5587
2783.6	50.0287
2788.07	50.1354
2792.53	50.5196
2797	50.5014
2801.45	50.3181
2805.91	49.605
2810.36	48.6727
2814.81	48.1363
2819.26	48.3284
2823.7	49.4519
2828.14	49.5322
2832.57	49.4543
2837.01	49.3588
2841.44	49.2254
2845.87	49.0771
2850.29	48.8837
2854.71	48.6894
2859.13	48.4835
2863.55	48.236
2867.96	48.0477
2872.37	47.8911
2876.77	47.7252
2881.18	47.6655
2885.58	47.5901
2889.97	47.6702
2894.37	47.5258
2898.76	47.1909
2903.15	45.7946
2907.53	45.8236
2911.91	45.9036
2916.29	45.9815
2920.67	46.805
2925.04	47.1626
2929.41	47.1059
2933.78	46.4182
2938.14	45.8943
2942.5	45.8588
2946.86	46.6962
2951.22	48.1972
2955.57	48.0988
2959.92	47.9005
2964.26	47.576
2968.61	46.7949
2972.95	45.5807
2977.28	45.5173
2981.62	45.8806
2985.95	45.8268
2990.28	45.5781
2994.6	44.9871
2998.93	44.6761
3003.25	44.5708
3007.56	44.9113
3011.88	44.826
3016.19	44.7458
3020.49	45.5085
3024.8	45.2851
3029.1	44.9238
3033.4	44.9215
3037.7	45.3264
3041.99	45.864
3046.28	45.8167
3050.57	45.7996
3054.85	45.6388
3059.13	45.4956
3063.41	45.3699
3067.69	45.2608
3071.96	45.1661
3076.23	45.0843
3080.5	45.0122
3084.76	44.9837
3089.02	44.8952
3093.28	44.7945
3097.53	44.6914
3101.79	44.5697
3106.04	44.4125
3110.28	43.5437
3114.53	43.2101
3118.77	43.2933
3123.01	43.0807
3127.24	43.3644
3131.47	43.5318
3135.7	43.1616
3139.93	43.2716
3144.15	43.0917
3148.38	42.9096
3152.59	42.7476
3156.81	42.6353
3161.02	42.5849
3165.23	42.5745
3169.44	42.7023
3173.64	42.6855
3177.84	42.6493
3182.04	42.6176
3186.24	42.5988
3190.43	42.602
3194.62	42.6379
3198.81	42.7184
3202.99	39.8716
3207.17	43.0304
3211.35	43.3653
3215.53	43.8206
3219.7	44.8338
3223.87	45.7485
3228.04	45.7697
3232.2	46.1867
3236.36	45.9513
3240.52	44.5825
3244.68	42.9202
3248.83	41.2937
3252.98	40.3722
3257.13	40.2277
3261.28	41.15
3265.42	42.2704
3269.56	43.4719
3273.7	44.2723
3277.83	44.633
3281.96	43.7185
3286.09	43.2939
3290.22	44.3021
3294.34	44.2504
3298.46	44.3886
3302.58	45.2009
3306.69	45.607
3310.8	44.915
3314.91	44.0991
3319.02	42.7479
3323.12	42.047
3327.23	41.958
3331.32	42.0016
3335.42	42.4936
3339.51	43.0763
3343.6	42.8933
3347.69	42.4733
3351.78	41.9931
3355.86	41.9934
3359.94	42.3033
3364.02	42.8926
3368.09	43.4563
3372.16	44.0582
3376.23	45.2461
3380.29	45.4535
3384.36	44.1828
3388.42	43.7901
3392.48	43.9727
3396.53	44.5986
3400.58	44.412
3404.63	44.1206
3408.68	43.9082
3412.73	44.0048
3416.77	44.2675
3420.81	44.8095
3424.84	44.0972
3428.88	43.2939
3432.91	42.2874
3436.94	41.8588
3440.96	41.8323
3444.99	42.6136
3449.01	43.1878
3453.03	42.5838
3457.04	42.4934
3461.05	42.7402
3465.06	43.1143
3469.07	43.6099
3473.08	44.0633
3477.08	43.8019
3481.08	43.6997
3485.07	43.6891
3489.07	43.9272
3493.06	43.6498
3497.05	43.4089
3501.04	43.243
3505.02	43.2362
3509	43.6376
3512.98	44.1336
3516.96	44.6058
3520.93	44.5061
3524.9	44.6878
3528.87	44.3218
3532.83	44.0298
3536.8	43.1446
3540.76	42.4327
3544.71	42.3622
3548.67	42.1208
3552.62	42.2953
3556.57	42.9167
3560.52	44.0295
3564.47	45.4876
3568.41	45.7868
3572.35	45.276
3576.29	43.9229
3580.22	41.773
3584.15	39.5819
3588.08	38.9847
3592.01	40.4581
3595.93	41.7247
3599.85	42.9396
3603.77	43.9974
3607.69	44.0554
3611.61	43.8887
3615.52	43.3606
3619.43	43.2947
3623.33	43.556
3627.24	43.3231
3631.14	42.6916
3635.04	41.7816
3638.93	40.8795
3642.83	40.4086
3646.72	40.7226
3650.61	41.1677
3654.49	42.2153
3658.38	43.172
3662.26	43.4729
3666.14	43.735
3670.01	43.1402
3673.89	42.5627
3677.76	42.0117
3681.63	41.3433
3685.5	41.1745
3689.36	41.6538
3693.22	42.116
3697.08	42.6157
3700.94	43.3069
3704.79	43.3899
3708.64	43.121
3712.49	42.4872
3716.34	41.7657
3720.18	41.3971
3724.02	42.4778
3727.86	42.782
3731.7	43.0614
3735.53	43.3676
3739.36	43.741
3743.19	44.3136
3747.02	44.7502
3750.84	37.7008
3754.66	46.3068
3758.48	46.8289
3762.3	46.0751
3766.12	44.9142
3769.93	43.0603
3773.74	42.0748
3777.54	41.5564
3781.35	41.9592
3785.15	42.1373
3788.95	42.476
3792.75	43.1714
3796.54	43.4537
3800.34	43.3244
3804.13	43.0337
3807.91	42.9928
3811.7	43.2824
3815.48	43.5128
3819.26	42.9321
3823.04	42.5068
3826.82	43.0451
3830.59	43.9222
3834.36	43.6523
3838.13	43.4771
3841.89	43.9682
3845.66	45.1342
3849.42	45.8049
3853.18	45.1675
3856.93	44.3284
3860.69	42.9401
3864.44	41.8366
3868.19	41.2009
3871.93	41.1251
3875.68	41.7706
3879.42	42.4846
3883.16	42.8298
3886.9	43.3739
3890.63	43.5467
3894.37	43.6418
3898.1	42.6848
3901.82	42.0177
3905.55	41.6901
3909.27	42.2215
3912.99	42.7106
3916.71	42.5567
3920.43	42.4204
3924.14	42.3173
3927.85	42.241
3931.56	41.86
3935.27	41.9898
3938.97	42.207
3942.67	42.277
3946.37	42.3841
3950.07	42.5038
3953.77	42.636
3957.46	42.6662
3961.15	41.5684
3964.84	41.3157
3968.52	41.1924
3972.2	41.4476
3975.89	41.7819
3979.56	42.5598
3983.24	42.7568
3986.92	43.1891
3990.59	42.8284
3994.26	42.3925
3997.92	41.8391
3999.76	41.4185