File: Data/Raman/raw/bu24-ore4-prism_leftp_150 (500nm)_633nm_edge_100%_x100_vis_h50um_20sx2_01.txt
#Acq. time (s)=	20
#Accumulations=	2
#Range (cm-¹)=	100...4000
#Windows=	1
#Auto scanning=	Off
#Autofocus=	Off
#Macrospot=	Off
#AutoExposure=	Off
#Spike filter=	Multiple accum.
#Delay time (s)=	2
#Binning=	1
#Readout mode=	Signal
#DeNoise=	Standard
#ICS correction=	On
#Dark correction=	Off
#Inst. Process=	Off
#Detector Gain=	Best Dynamic
#Detector ADC=	50 kHz HS
#Detector temperature (°C)=	-60.09
#Instrument=	LabRAM HR Evol
#Detector=	SIN-EM FIVIS
#Objective=	x100_VIS
#Grating=	150 (500nm)
#ND Filter=	100%
#Laser=	633nm_Edge
#Hole=	49.98
#Temperature=	0
#Range=	Visible
#StageXY=	75x50mm Scan+
#StageZ=	Z motor
#X (µm)=	0
#Y (µm)=	0
#Z (µm)=	0
#Full time(s)=	48
#Project=	20_10_27
#Sample=	BU24
#Site=
#Title=	BU24-Ore4-prism_leftp_150 (500nm)_633nm_Edge_100%_x100_VIS_H50um_20sX2
#Remark=
#Date=	27.10.2020 19:21
#Acquired=	27.10.2020 19:21:52
100.764	2990.33
107.281	3078.44
113.791	3220.14
120.297	3467.72
126.797	4075.85
133.291	4736.19
139.78	4244.82
146.264	3113.28
152.741	2680.26
159.214	2626.26
165.682	2590.24
172.144	2555.82
178.601	2516.95
185.053	2493.83
191.499	2474.46
197.939	2560.41
204.374	2657.51
210.805	2557.99
217.23	2447.49
223.648	2458.2
230.063	2507.45
236.472	2589.27
242.874	2692.73
249.273	2792.98
255.667	2894.12
262.053	3037.15
268.436	3162.7
274.813	3160.29
281.185	3024.22
287.552	2824.2
293.913	2722.38
300.27	2632.36
306.62	2524.3
312.965	2426.91
319.306	2345.1
325.64	2284
331.971	2242.58
338.295	2223.11
344.614	2223.79
350.93	2244.38
357.238	2282.87
363.542	2339.47
369.842	2426.17
376.135	2528.31
382.423	2650.9
388.706	2753.04
394.984	2752
401.258	2666.6
407.526	2537.85
413.789	2413.35
420.046	2344.04
426.299	2300.97
432.546	2287.9
438.788	2279.03
445.025	2277.41
451.257	2285.63
457.484	2297.51
463.706	2311.87
469.923	2327.09
476.135	2338.86
482.342	2344.47
488.544	2345.92
494.741	2343.45
500.933	2336.58
507.12	2334.04
513.3	2344.84
519.477	2372.77
525.649	2405.45
531.815	2396.83
537.976	2347.81
544.133	2286.22
550.285	2223.06
556.43	2160.89
562.572	2113.66
568.709	2101.41
574.84	2090.46
580.967	2094.12
587.09	2110.39
593.205	2132.61
599.318	2156.06
605.424	2187.21
611.527	2217.7
617.623	2247.69
623.716	2268.57
629.802	2275.44
635.884	2270.39
641.962	2251.24
648.034	2228.55
654.101	2204.45
660.165	2182.75
666.222	2171.31
672.274	2170.47
678.324	2174.26
684.366	2184.02
690.404	2198.31
696.438	2216.09
702.466	2233.7
708.491	2250.54
714.51	2271.5
720.523	2298.39
726.533	2331.11
732.537	2365.04
738.537	2411.74
744.531	2472.66
750.521	2532.38
756.507	2594.23
762.487	2650.13
768.463	2704.25
774.434	2759.76
780.4	2793.95
786.362	2822.18
792.319	2838.37
798.269	2862.47
804.217	2926.28
810.159	3024.54
816.097	3145.11
822.03	3316.21
827.958	3492.06
833.881	3704.45
839.801	4054.98
845.714	4703.34
851.624	5629.36
857.529	6936.36
863.428	8605.68
869.324	9719.49
875.215	8820.01
881.1	6173.11
886.982	4030.11
892.858	2870.34
898.73	2276.67
904.597	1928.48
910.459	1729.36
916.318	1600.86
922.171	1499.4
928.02	1426.76
933.864	1375.11
939.703	1337.13
945.539	1303.85
951.368	1269.03
957.194	1236.23
963.014	1209.47
968.832	1188.08
974.643	1170.67
980.45	1156.19
986.253	1143.97
992.051	1130.2
997.844	1119.95
1003.63	1114.02
1009.42	1106.37
1015.2	1097.59
1020.97	1088.11
1026.74	1079.93
1032.51	1074
1038.27	1069.49
1044.03	1061.21
1049.78	1053.86
1055.53	1047.19
1061.27	1041.36
1067.01	1035.9
1072.75	1029.55
1078.48	1021.19
1084.2	1010.82
1089.92	1004.71
1095.64	1005.22
1101.35	998.299
1107.06	989.062
1112.77	984.672
1118.46	977.941
1124.16	971.842
1129.85	966.879
1135.53	960.826
1141.22	953.601
1146.89	946.306
1152.56	939.24
1158.23	927.982
1163.9	917.125
1169.56	908.976
1175.21	904.291
1180.86	901.324
1186.51	896.418
1192.15	891.866
1197.78	888.108
1203.42	885.719
1209.04	884.765
1214.67	884.765
1220.29	883.686
1225.9	879.401
1231.51	873.333
1237.12	865.735
1242.72	857.113
1248.32	849.132
1253.92	839.228
1259.5	830.928
1265.09	821.649
1270.67	812.989
1276.25	806.152
1281.82	802.223
1287.39	801.391
1292.95	802.199
1298.51	803.033
1304.06	802.72
1309.61	795.839
1315.16	787.679
1320.7	780.382
1326.24	775.422
1331.77	773.167
1337.3	768.817
1342.83	767.059
1348.35	770.403
1353.86	767.932
1359.37	760.631
1364.88	753.553
1370.39	747.912
1375.89	744.214
1381.38	741.027
1386.87	740.21
1392.36	738.727
1397.84	733.41
1403.32	735.765
1408.79	741.31
1414.26	738.608
1419.73	729.691
1425.19	724.604
1430.65	723.444
1436.1	717.034
1441.55	711.486
1447	708.016
1452.44	706.138
1457.87	705.986
1463.31	705.777
1468.73	697.858
1474.16	691.726
1479.58	692.027
1484.99	692.902
1490.41	693.926
1495.81	695.85
1501.22	697.098
1506.62	693.387
1512.01	689.798
1517.4	686.851
1522.79	687.006
1528.17	684.732
1533.55	682.63
1538.93	679.445
1544.3	677.354
1549.67	669.211
1555.03	661.7
1560.39	656.364
1565.74	653.071
1571.09	652.089
1576.44	652.816
1581.78	651.818
1587.12	650.726
1592.45	648.587
1597.78	644.384
1603.11	639.1
1608.43	635.865
1613.75	633.619
1619.07	630.367
1624.38	627.142
1629.68	624.786
1634.98	623.085
1640.28	621.862
1645.58	621.174
1650.87	620.852
1656.15	619.349
1661.44	618.965
1666.71	616.074
1671.99	611.237
1677.26	608.256
1682.53	605.976
1687.79	603.903
1693.05	601.232
1698.3	599.425
1703.55	599.007
1708.8	598.486
1714.04	597.292
1719.28	595.148
1724.51	592.108
1729.75	588.078
1734.97	580.62
1740.2	571.809
1745.42	561.787
1750.63	551.517
1755.84	542.154
1761.05	532.905
1766.25	524.846
1771.45	519.606
1776.65	515.813
1781.84	511.505
1787.03	508.66
1792.21	507.127
1797.39	504.43
1802.57	502.667
1807.74	502.496
1812.91	497.75
1818.08	492.075
1823.24	487.349
1828.39	481.942
1833.55	475.942
1838.7	471.085
1843.84	468.261
1848.99	465.403
1854.12	463.337
1859.26	462.369
1864.39	462.33
1869.52	462.794
1874.64	463.956
1879.76	462.993
1884.87	460.578
1889.98	457.241
1895.09	454.289
1900.2	451.214
1905.3	450.402
1910.39	452.351
1915.49	450.074
1920.57	447.708
1925.66	445.013
1930.74	437.134
1935.82	429.229
1940.89	423.875
1945.96	424.207
1951.03	422.781
1956.09	424.154
1961.15	426.604
1966.21	424.14
1971.26	422.058
1976.31	419.228
1981.35	417.102
1986.39	417.136
1991.43	414.389
1996.46	411.333
2001.49	408.811
2006.52	407.588
2011.54	405.99
2016.56	405.25
2021.57	405.377
2026.58	404.357
2031.59	399.956
2036.59	396.773
2041.59	396.538
2046.59	397.707
2051.58	398.204
2056.57	394.186
2061.55	389.788
2066.54	385.938
2071.51	382.206
2076.49	380.457
2081.46	379.033
2086.43	379.447
2091.39	377.198
2096.35	373.656
2101.3	371.488
2106.26	370.295
2111.21	371.941
2116.15	372.759
2121.09	368.979
2126.03	364.41
2130.97	362.142
2135.9	359.159
2140.83	356.583
2145.75	353.996
2150.67	352.772
2155.59	354.146
2160.5	353.712
2165.41	353.36
2170.31	353.958
2175.22	352.947
2180.12	354.034
2185.01	353.588
2189.9	353.085
2194.79	352.453
2199.68	351.774
2204.56	350.92
2209.43	349.704
2214.31	347.307
2219.18	344.131
2224.05	339.85
2228.91	335.703
2233.77	332.66
2238.63	330.615
2243.48	329.069
2248.33	326.315
2253.17	324.4
2258.02	322.514
2262.86	321.221
2267.69	318.462
2272.52	316.312
2277.35	315.025
2282.18	313.988
2287	313.575
2291.82	314.554
2296.63	315.853
2301.44	316.916
2306.25	315.105
2311.05	313.065
2315.86	311.186
2320.65	309.443
2325.45	308.294
2330.24	307.226
2335.03	306.136
2339.81	305.284
2344.59	304.557
2349.37	303.812
2354.14	301.801
2358.91	296.265
2363.67	292.332
2368.44	292.001
2373.2	292.883
2377.95	293.641
2382.71	291.801
2387.46	290.878
2392.2	289.996
2396.95	288.803
2401.68	287.442
2406.42	285.867
2411.15	284.127
2415.88	282.287
2420.61	279.541
2425.33	277.742
2430.05	276.908
2434.77	276.696
2439.48	273.391
2444.19	274.069
2448.89	275.232
2453.6	275.89
2458.29	277.403
2462.99	276.799
2467.68	275.015
2472.37	271.033
2477.06	268.96
2481.74	269.484
2486.42	269.762
2491.1	269.078
2495.77	268.358
2500.44	266.858
2505.1	265.831
2509.76	264.971
2514.42	263.151
2519.08	262.065
2523.73	260.835
2528.38	258.147
2533.03	255.051
2537.67	252.508
2542.31	250.921
2546.95	250.595
2551.58	250.833
2556.21	250.993
2560.84	250.061
2565.46	249.203
2570.08	248.38
2574.7	247.575
2579.31	246.794
2583.92	246.15
2588.53	244.972
2593.13	242.271
2597.73	239.533
2602.33	236.935
2606.92	236.916
2611.51	238.191
2616.1	240.26
2620.68	240.647
2625.26	238.664
2629.84	236.171
2634.42	233.619
2638.99	230.403
2643.56	227.587
2648.12	225.741
2652.68	225.465
2657.24	225.61
2661.8	223.171
2666.35	220.985
2670.9	219.898
2675.45	218.966
2679.99	217.974
2684.53	217.074
2689.06	217.42
2693.6	215.17
2698.13	213.618
2702.66	213.38
2707.18	215.177
2711.7	218.166
2716.22	218.738
2720.73	217.97
2725.24	216.741
2729.75	214.637
2734.26	212.816
2738.76	211.408
2743.25	210.38
2747.75	210.052
2752.24	210.292
2756.73	209.868
2761.22	209.089
2765.7	211.437
2770.18	207.228
2774.66	200.511
2779.13	198.264
2783.6	198.409
2788.07	201.144
2792.53	205.222
2797	203.583
2801.45	201.752
2805.91	199.81
2810.36	199.582
2814.81	200.947
2819.26	199.152
2823.7	196.967
2828.14	195.527
2832.57	194.64
2837.01	195.054
2841.44	194.508
2845.87	193.136
2850.29	192.986
2854.71	193.272
2859.13	191.175
2863.55	189.142
2867.96	187.436
2872.37	186.388
2876.77	186.127
2881.18	186.792
2885.58	188.03
2889.97	189.527
2894.37	190.888
2898.76	190.904
2903.15	190.177
2907.53	188.292
2911.91	186.556
2916.29	186.176
2920.67	185.741
2925.04	185.389
2929.41	184.885
2933.78	184.02
2938.14	182.985
2942.5	181.615
2946.86	179.826
2951.22	179.34
2955.57	178.287
2959.92	177.131
2964.26	176.566
2968.61	176.36
2972.95	176.567
2977.28	175.679
2981.62	174.505
2985.95	172.745
2990.28	171.863
2994.6	171.354
2998.93	169.872
3003.25	168.808
3007.56	170.146
3011.88	151.494
3016.19	177.413
3020.49	178.126
3024.8	177.498
3029.1	173.614
3033.4	168.386
3037.7	164.761
3041.99	164.266
3046.28	164.36
3050.57	164.524
3054.85	164.919
3059.13	165.427
3063.41	163.502
3067.69	161.687
3071.96	160.162
3076.23	159.756
3080.5	162.041
3084.76	163.673
3089.02	164.721
3093.28	165.66
3097.53	165.935
3101.79	164.068
3106.04	162.605
3110.28	161.381
3114.53	160.443
3118.77	159.809
3123.01	159.381
3127.24	159.366
3131.47	159.457
3135.7	159.723
3139.93	159.2
3144.15	161.164
3148.38	160.677
3152.59	159.101
3156.81	157.341
3161.02	155.721
3165.23	152.701
3169.44	152.998
3173.64	152.963
3177.84	153.284
3182.04	154.238
3186.24	155.612
3190.43	156.179
3194.62	155.457
3198.81	153.045
3202.99	151.102
3207.17	149.76
3211.35	149.179
3215.53	145.365
3219.7	145.224
3223.87	145.758
3228.04	146.626
3232.2	148.431
3236.36	150.629
3240.52	149.96
3244.68	148.716
3248.83	147.782
3252.98	147.254
3257.13	147.155
3261.28	147.561
3265.42	146.547
3269.56	145.112
3273.7	145.507
3277.83	147.539
3281.96	149.766
3286.09	149.827
3290.22	148.143
3294.34	145.58
3298.46	143.008
3302.58	141.145
3306.69	140.45
3310.8	140.503
3314.91	142.018
3319.02	143.099
3323.12	143.781
3327.23	143.727
3331.32	143.681
3335.42	144.358
3339.51	144.275
3343.6	142.657
3347.69	140.388
3351.78	138.769
3355.86	137.753
3359.94	137.246
3364.02	136.976
3368.09	137.085
3372.16	136.787
3376.23	136.261
3380.29	137.031
3384.36	136.917
3388.42	136.061
3392.48	135.523
3396.53	135.314
3400.58	133.434
3404.63	131.444
3408.68	130.713
3412.73	130.689
3416.77	131.071
3420.81	131.103
3424.84	131.729
3428.88	128.741
3432.91	126.098
3436.94	125.788
3440.96	126.882
3444.99	129.236
3449.01	131.285
3453.03	132.472
3457.04	132.656
3461.05	131.435
3465.06	129.28
3469.07	123.507
3473.08	123.665
3477.08	125.845
3481.08	129.448
3485.07	132.64
3489.07	133.367
3493.06	131.619
3497.05	129.878
3501.04	127.956
3505.02	126.227
3509	125.038
3512.98	124.819
3516.96	125.339
3520.93	126.263
3524.9	125.857
3528.87	122.34
3532.83	121.074
3536.8	120.16
3540.76	119.357
3544.71	118.917
3548.67	118.411
3552.62	118.081
3556.57	118.106
3560.52	118.321
3564.47	119.428
3568.41	121.237
3572.35	121.517
3576.29	121.272
3580.22	121.591
3584.15	120.538
3588.08	119.169
3592.01	119.611
3595.93	120.36
3599.85	120.079
3603.77	118.734
3607.69	118.974
3611.61	119.978
3615.52	120.041
3619.43	119.574
3623.33	118.949
3627.24	118.625
3631.14	118.54
3635.04	118.529
3638.93	118.244
3642.83	117.787
3646.72	118.418
3650.61	118.513
3654.49	118.584
3658.38	117.549
3662.26	117.395
3666.14	118.471
3670.01	119.414
3673.89	118.905
3677.76	117.985
3681.63	117.082
3685.5	116.473
3689.36	114.854
3693.22	113.582
3697.08	114.479
3700.94	115.763
3704.79	113.932
3708.64	112.18
3712.49	111.057
3716.34	110.84
3720.18	111.086
3724.02	112.357
3727.86	113.789
3731.7	113.328
3735.53	112.601
3739.36	111.424
3743.19	111.544
3747.02	110.841
3750.84	109.13
3754.66	108.216
3758.48	107.964
3762.3	109.254
3766.12	110.758
3769.93	110.039
3773.74	106.617
3777.54	107.104
3781.35	107.76
3785.15	108.648
3788.95	110.166
3792.75	109.12
3796.54	108.703
3800.34	108.765
3804.13	109.103
3807.91	109.7
3811.7	108.624
3815.48	107.038
3819.26	106.076
3823.04	106.193
3826.82	107.324
3830.59	109.671
3834.36	111.633
3838.13	111.435
3841.89	111.296
3845.66	111.12
3849.42	108.088
3853.18	105.259
3856.93	103.64
3860.69	102.829
3864.44	102.665
3868.19	103.293
3871.93	104.105
3875.68	104.286
3879.42	104.943
3883.16	106.254
3886.9	108.001
3890.63	108.793
3894.37	109.221
3898.1	109.264
3901.82	108.822
3905.55	107.759
3909.27	106.161
3912.99	104.057
3916.71	102.119
3920.43	101.208
3924.14	100.718
3927.85	100.786
3931.56	101.266
3935.27	101.874
3938.97	102.555
3942.67	102.609
3946.37	101.444
3950.07	100.896
3953.77	100.628
3957.46	100.719
3961.15	100.842
3964.84	100.8
3968.52	99.9135
3972.2	98.5469
3975.89	97.1998
3979.56	96.0393
3983.24	95.2405
3986.92	95.4956
3990.59	96.1086
3994.26	95.2213
3997.92	95.9952
3999.76	97.7021