File: Data/Raman/raw/bu24-ore3-bottom_grain_150 (500nm)_633nm_edge_100%_x100_vis_h30um_10sx2_01.txt
#Acq. time (s)=	10
#Accumulations=	2
#Range (cm-¹)=	100...4000
#Windows=	1
#Auto scanning=	Off
#Autofocus=	Off
#Macrospot=	Off
#AutoExposure=	Off
#Spike filter=	Multiple accum.
#Delay time (s)=	2
#Binning=	1
#Readout mode=	Signal
#DeNoise=	Standard
#ICS correction=	On
#Dark correction=	Off
#Inst. Process=	Off
#Detector Gain=	Best Dynamic
#Detector ADC=	50 kHz HS
#Detector temperature (°C)=	-60.09
#Instrument=	LabRAM HR Evol
#Detector=	SIN-EM FIVIS
#Objective=	x100_VIS
#Grating=	150 (500nm)
#ND Filter=	100%
#Laser=	633nm_Edge
#Hole=	30.0125
#Temperature=	0
#Range=	Visible
#StageXY=	75x50mm Scan+
#StageZ=	Z motor
#X (µm)=	0
#Y (µm)=	0
#Z (µm)=	52.1
#Full time(s)=	24
#Project=	20_10_27
#Sample=	BU24
#Site=
#Title=	BU24-Ore3-bottom_grain_150 (500nm)_633nm_Edge_100%_x100_VIS_H30um_10sX2
#Remark=
#Date=	27.10.2020 19:09
#Acquired=	27.10.2020 19:09:05
100.764	888.131
107.281	919.049
113.791	959.375
120.297	1082.13
126.797	1304.97
133.291	1673.71
139.78	1865.63
146.264	1126.04
152.741	868.004
159.214	814.549
165.682	840.83
172.144	872.734
178.601	886.627
185.053	843.9
191.499	800.756
197.939	852.993
204.374	953.506
210.805	959.149
217.23	847.334
223.648	791.16
230.063	811.385
236.472	872.357
242.874	958.503
249.273	1030.11
255.667	1006.55
262.053	1097.6
268.436	1198.67
274.813	1164.8
281.185	1067.15
287.552	976.07
293.913	896.835
300.27	831.409
306.62	785.504
312.965	760.998
319.306	755.691
325.64	743.838
331.971	738.455
338.295	725.606
344.614	729.967
350.93	750.143
357.238	761.032
363.542	770.11
369.842	783.767
376.135	814.068
382.423	884.691
388.706	962.645
394.984	1081.17
401.258	1048.3
407.526	954.158
413.789	830.608
420.046	769.682
426.299	756.789
432.546	748.536
438.788	748.356
445.025	753.274
451.257	764.584
457.484	770.183
463.706	789.087
469.923	813.089
476.135	838.699
482.342	858.735
488.544	864.881
494.741	856.63
500.933	850.779
507.12	853.728
513.3	899.518
519.477	972.974
525.649	1065.39
531.815	1038.58
537.976	965.029
544.133	880.5
550.285	814.841
556.43	760.886
562.572	724.818
568.709	699.743
574.84	684.152
580.967	676.371
587.09	672.034
593.205	672.581
599.318	676.643
605.424	687.825
611.527	699.086
617.623	709.866
623.716	720.138
629.802	732.994
635.884	727.887
641.962	714.485
648.034	696.562
654.101	678.037
660.165	663.713
666.222	654.436
672.274	650.918
678.324	649.541
684.366	649.168
690.404	650.947
696.438	653.681
702.466	656.513
708.491	659.141
714.51	661.704
720.523	664.571
726.533	669.477
732.537	676.075
738.537	684.25
744.531	693.899
750.521	706.396
756.507	721.294
762.487	732.273
768.463	747.137
774.434	761.03
780.4	774.616
786.362	780.488
792.319	782.999
798.269	792.672
804.217	814.619
810.159	847.684
816.097	893.217
822.03	946.519
827.958	1010.85
833.881	1079.31
839.801	1180.94
845.714	1355.95
851.624	1688.09
857.529	2270.7
863.428	3281.26
869.324	4570.96
875.215	4723.7
881.1	3171
886.982	1792.81
892.858	1166.49
898.73	846.38
904.597	692.311
910.459	592.337
916.318	532.475
922.171	495.379
928.02	469.915
933.864	448.189
939.703	432.38
945.539	419.61
951.368	407.643
957.194	400.267
963.014	393.629
968.832	386.21
974.643	377.965
980.45	368.759
986.253	360.472
992.051	353.548
997.844	348.408
1003.63	347.82
1009.42	346.47
1015.2	345.414
1020.97	343.439
1026.74	340.495
1032.51	339.312
1038.27	337.974
1044.03	335.066
1049.78	332.988
1055.53	332.145
1061.27	331.122
1067.01	330.199
1072.75	328.953
1078.48	326.809
1084.2	321.833
1089.92	317.359
1095.64	313.908
1101.35	311.384
1107.06	309.75
1112.77	308.782
1118.46	308.321
1124.16	308.027
1129.85	307.089
1135.53	303.451
1141.22	299.613
1146.89	296.201
1152.56	293.375
1158.23	291.131
1163.9	289.153
1169.56	287.161
1175.21	286.206
1180.86	285.817
1186.51	283.741
1192.15	283.687
1197.78	282.321
1203.42	280.532
1209.04	278.673
1214.67	277.16
1220.29	275.911
1225.9	274.553
1231.51	273.577
1237.12	271.263
1242.72	267.25
1248.32	263.473
1253.92	260.512
1259.5	258.14
1265.09	256.381
1270.67	255.215
1276.25	254.554
1281.82	254.581
1287.39	253.452
1292.95	249.643
1298.51	246.232
1304.06	244.166
1309.61	244.45
1315.16	245.238
1320.7	245.284
1326.24	245.001
1331.77	243.639
1337.3	240.688
1342.83	238.34
1348.35	236.584
1353.86	235.285
1359.37	234.542
1364.88	234.349
1370.39	233.818
1375.89	232.381
1381.38	229.724
1386.87	227.181
1392.36	225.192
1397.84	223.769
1403.32	222.93
1408.79	222.72
1414.26	223.024
1419.73	223.76
1425.19	223.667
1430.65	222.423
1436.1	221.152
1441.55	220.142
1447	219.613
1452.44	219.264
1457.87	219.08
1463.31	219.049
1468.73	219.028
1474.16	217.258
1479.58	214.875
1484.99	212.532
1490.41	210.398
1495.81	210.413
1501.22	208.307
1506.62	206.163
1512.01	205.787
1517.4	202.106
1522.79	200.19
1528.17	199.06
1533.55	201.235
1538.93	201.64
1544.3	200.116
1549.67	196.547
1555.03	193.977
1560.39	191.842
1565.74	189.807
1571.09	187.416
1576.44	187.49
1581.78	188.173
1587.12	186.194
1592.45	184.078
1597.78	182.542
1603.11	181.429
1608.43	180.757
1613.75	180.749
1619.07	181.131
1624.38	181.518
1629.68	181.814
1634.98	181.738
1640.28	181.08
1645.58	179.709
1650.87	177.971
1656.15	175.939
1661.44	173.83
1666.71	172.2
1671.99	170.697
1677.26	169.313
1682.53	169.939
1687.79	170.834
1693.05	171.549
1698.3	172.033
1703.55	172.238
1708.8	172.235
1714.04	171.996
1719.28	170.752
1724.51	170.151
1729.75	169.997
1734.97	168.876
1740.2	166.004
1745.42	161.297
1750.63	157.27
1755.84	154.255
1761.05	152.783
1766.25	149.3
1771.45	146.332
1776.65	144.62
1781.84	143.347
1787.03	142.026
1792.21	140.364
1797.39	137.807
1802.57	135.169
1807.74	132.572
1812.91	130.089
1818.08	127.949
1823.24	126.723
1828.39	125.973
1833.55	125.591
1838.7	125.496
1843.84	125.649
1848.99	125.616
1854.12	125.814
1859.26	126.483
1864.39	126.839
1869.52	127.083
1874.64	126.542
1879.76	125.71
1884.87	124.854
1889.98	122.888
1895.09	120.376
1900.2	118.527
1905.3	118.277
1910.39	119.362
1915.49	120.201
1920.57	120.06
1925.66	119.015
1930.74	117.229
1935.82	115.173
1940.89	113.341
1945.96	111.916
1951.03	112.273
1956.09	112.661
1961.15	112.291
1966.21	110.579
1971.26	109.37
1976.31	108.771
1981.35	108.876
1986.39	109.301
1991.43	108.823
1996.46	109.034
2001.49	110.323
2006.52	110.207
2011.54	107.731
2016.56	104.598
2021.57	101.532
2026.58	100.008
2031.59	99.7342
2036.59	100.018
2041.59	100.475
2046.59	101.041
2051.58	101.646
2056.57	102.17
2061.55	101.234
2066.54	100.773
2071.51	101.008
2076.49	101.285
2081.46	101.729
2086.43	100.819
2091.39	99.719
2096.35	98.0775
2101.3	96.628
2106.26	96.254
2111.21	95.6657
2116.15	95.2408
2121.09	94.8798
2126.03	94.6189
2130.97	94.4315
2135.9	94.3943
2140.83	94.4205
2145.75	94.0057
2150.67	93.5235
2155.59	92.3264
2160.5	91.5118
2165.41	91.3212
2170.31	90.7753
2175.22	90.3513
2180.12	89.5618
2185.01	88.9066
2189.9	89.1354
2194.79	89.0446
2199.68	88.8857
2204.56	87.2102
2209.43	83.1246
2214.31	82.2381
2219.18	83.2057
2224.05	84.6034
2228.91	84.1823
2233.77	83.7514
2238.63	83.662
2243.48	84.2615
2248.33	84.5375
2253.17	83.6499
2258.02	82.4223
2262.86	81.1313
2267.69	79.9605
2272.52	78.9456
2277.35	78.2298
2282.18	77.8773
2287	78.1234
2291.82	78.5206
2296.63	78.9528
2301.44	79.3956
2306.25	79.8245
2311.05	79.9817
2315.86	79.7868
2320.65	79.0669
2325.45	78.2304
2330.24	77.2797
2335.03	76.2614
2339.81	75.2533
2344.59	75.1079
2349.37	75.2196
2354.14	75.6128
2358.91	75.7781
2363.67	75.263
2368.44	74.2655
2373.2	73.2588
2377.95	73.0567
2382.71	72.3939
2387.46	71.7833
2392.2	71.4329
2396.95	71.1084
2401.68	71.049
2406.42	70.5694
2411.15	70.0453
2415.88	69.5151
2420.61	68.4516
2425.33	68.4565
2430.05	68.3379
2434.77	68.8606
2439.48	69.1464
2444.19	69.3924
2448.89	69.578
2453.6	69.2297
2458.29	69.2663
2462.99	69.3101
2467.68	69.3355
2472.37	69.3335
2477.06	68.9646
2481.74	67.9497
2486.42	66.9676
2491.1	66.0836
2495.77	65.7019
2500.44	65.6241
2505.1	65.0067
2509.76	64.0636
2514.42	63.6276
2519.08	63.3365
2523.73	63.6994
2528.38	64.3791
2533.03	65.196
2537.67	65.9558
2542.31	66.6512
2546.95	65.6202
2551.58	64.4981
2556.21	63.9265
2560.84	63.4635
2565.46	63.2143
2570.08	63.1815
2574.7	63.0398
2579.31	62.4799
2583.92	62.3837
2588.53	62.4028
2593.13	62.4907
2597.73	62.5805
2602.33	62.721
2606.92	62.6025
2611.51	62.1767
2616.1	60.8404
2620.68	59.8397
2625.26	59.2257
2629.84	59.7646
2634.42	59.5133
2638.99	59.2368
2643.56	59.4421
2648.12	59.6599
2652.68	59.9683
2657.24	60.3677
2661.8	60.4437
2666.35	59.6172
2670.9	58.7494
2675.45	57.8803
2679.99	57.1598
2684.53	56.5938
2689.06	55.8727
2693.6	54.8053
2698.13	53.3527
2702.66	53.451
2707.18	54.1643
2711.7	55.4215
2716.22	56.8715
2720.73	57.8809
2725.24	58.0141
2729.75	56.2745
2734.26	55.4081
2738.76	54.7483
2743.25	54.1164
2747.75	53.5202
2752.24	53.8129
2756.73	54.3905
2761.22	54.9652
2765.7	55.1712
2770.18	55.1861
2774.66	55.3209
2779.13	54.4002
2783.6	53.4716
2788.07	52.7532
2792.53	52.8686
2797	53.6218
2801.45	53.6412
2805.91	53.3955
2810.36	52.794
2814.81	52.2045
2819.26	51.6476
2823.7	51.7763
2828.14	52.2236
2832.57	52.7344
2837.01	53.1876
2841.44	52.866
2845.87	52.5066
2850.29	52.7417
2854.71	52.6386
2859.13	52.527
2863.55	52.3687
2867.96	52.1326
2872.37	51.5491
2876.77	51.2898
2881.18	51.0807
2885.58	51.1589
2889.97	51.487
2894.37	51.8251
2898.76	52.1064
2903.15	52.3019
2907.53	52.1574
2911.91	51.6561
2916.29	51.0186
2920.67	50.3939
2925.04	49.8746
2929.41	49.9629
2933.78	50.7192
2938.14	50.4349
2942.5	50.1814
2946.86	50.1276
2951.22	49.8406
2955.57	49.5151
2959.92	49.1571
2964.26	48.7891
2968.61	48.5668
2972.95	48.4166
2977.28	48.81
2981.62	48.9993
2985.95	49.0574
2990.28	48.9716
2994.6	48.4136
2998.93	47.5266
3003.25	44.9645
3007.56	45.5795
3011.88	46.8207
3016.19	48.0367
3020.49	48.969
3024.8	49.533
3029.1	49.3753
3033.4	48.8861
3037.7	48.5545
3041.99	48.2556
3046.28	48.2684
3050.57	48.4684
3054.85	48.4365
3059.13	48.3843
3063.41	48.3259
3067.69	47.5802
3071.96	45.9032
3076.23	45.1179
3080.5	45.9698
3084.76	47.585
3089.02	48.8756
3093.28	49.851
3097.53	50.3615
3101.79	50.7139
3106.04	51.0324
3110.28	50.2381
3114.53	48.9623
3118.77	48.192
3123.01	48.3067
3127.24	48.038
3131.47	47.1976
3135.7	46.9304
3139.93	46.9721
3144.15	46.7761
3148.38	46.6446
3152.59	46.4203
3156.81	46.1979
3161.02	45.9824
3165.23	45.7578
3169.44	45.6224
3173.64	45.5083
3177.84	45.5809
3182.04	45.7289
3186.24	45.994
3190.43	46.6368
3194.62	46.9318
3198.81	47.1892
3202.99	47.251
3207.17	47.3201
3211.35	47.0521
3215.53	46.2304
3219.7	45.8733
3223.87	45.7475
3228.04	45.9953
3232.2	46.8275
3236.36	47.8142
3240.52	48.726
3244.68	48.5883
3248.83	47.4947
3252.98	46.4636
3257.13	45.4432
3261.28	44.4661
3265.42	43.7642
3269.56	43.9691
3273.7	44.4162
3277.83	44.9962
3281.96	45.7516
3286.09	46.0611
3290.22	45.8957
3294.34	45.7711
3298.46	45.679
3302.58	45.6524
3306.69	45.7265
3310.8	45.9582
3314.91	46.7505
3319.02	46.4155
3323.12	46.4237
3327.23	46.7547
3331.32	47.4604
3335.42	47.9932
3339.51	48.5147
3343.6	47.2684
3347.69	45.8691
3351.78	44.9177
3355.86	44.4508
3359.94	44.2529
3364.02	44.633
3368.09	45.0904
3372.16	45.0384
3376.23	45.611
3380.29	46.5991
3384.36	46.804
3388.42	46.431
3392.48	45.9461
3396.53	45.8807
3400.58	45.6311
3404.63	45.1378
3408.68	44.6989
3412.73	43.4786
3416.77	47.2808
3420.81	47.5683
3424.84	45.7545
3428.88	43.5884
3432.91	41.9988
3436.94	42.0564
3440.96	42.2586
3444.99	42.8247
3449.01	44.0835
3453.03	45.7018
3457.04	46.7996
3461.05	46.3278
3465.06	45.8737
3469.07	45.7355
3473.08	45.3459
3477.08	44.8216
3481.08	43.9049
3485.07	43.4763
3489.07	43.4219
3493.06	43.3937
3497.05	42.8754
3501.04	44.0674
3505.02	45.483
3509	45.3558
3512.98	45.3179
3516.96	45.4191
3520.93	45.5416
3524.9	45.3691
3528.87	45.0286
3532.83	44.6179
3536.8	43.513
3540.76	42.4007
3544.71	41.9448
3548.67	42.2827
3552.62	42.778
3556.57	43.3965
3560.52	44.05
3564.47	44.5315
3568.41	45.0111
3572.35	45.3396
3576.29	45.521
3580.22	45.6543
3584.15	45.6974
3588.08	45.4681
3592.01	45.1949
3595.93	44.9487
3599.85	44.7254
3603.77	44.5761
3607.69	44.6498
3611.61	44.4621
3615.52	44.2514
3619.43	44.0035
3623.33	43.6487
3627.24	43.632
3631.14	42.8591
3635.04	42.1924
3638.93	41.6421
3642.83	41.2491
3646.72	41.2733
3650.61	41.4077
3654.49	41.7091
3658.38	42.2055
3662.26	42.8768
3666.14	43.5596
3670.01	44.6635
3673.89	45.8034
3677.76	46.8805
3681.63	47.7237
3685.5	48.0394
3689.36	47.002
3693.22	46.7512
3697.08	45.5472
3700.94	44.2797
3704.79	43.0751
3708.64	42.6729
3712.49	42.3336
3716.34	42.3147
3720.18	42.6046
3724.02	43.234
3727.86	44.1967
3731.7	45.1953
3735.53	45.5245
3739.36	45.4872
3743.19	44.5959
3747.02	44.0616
3750.84	43.8416
3754.66	43.8066
3758.48	43.3028
3762.3	42.2973
3766.12	42.3122
3769.93	42.005
3773.74	42.7927
3777.54	43.9447
3781.35	45.1544
3785.15	45.6715
3788.95	45.9675
3792.75	46.1446
3796.54	46.2668
3800.34	46.2981
3804.13	46.202
3807.91	46.0465
3811.7	45.7549
3815.48	45.3919
3819.26	45.0034
3823.04	44.6306
3826.82	44.2462
3830.59	44.0979
3834.36	43.6144
3838.13	43.0698
3841.89	42.529
3845.66	42.0837
3849.42	41.7789
3853.18	41.6346
3856.93	41.9523
3860.69	42.4424
3864.44	43.3675
3868.19	44.4111
3871.93	44.6007
3875.68	43.8151
3879.42	43.1827
3883.16	43.1281
3886.9	43.7171
3890.63	44.5296
3894.37	44.9254
3898.1	45.2821
3901.82	45.318
3905.55	44.2634
3909.27	43.0843
3912.99	42.2887
3916.71	42.5466
3920.43	43.4355
3924.14	43.6895
3927.85	43.7894
3931.56	43.7625
3935.27	43.6924
3938.97	43.5918
3942.67	43.5064
3946.37	43.4521
3950.07	43.382
3953.77	43.5195
3957.46	43.6261
3961.15	43.6958
3964.84	43.7158
3968.52	43.5745
3972.2	43.5173
3975.89	43.2958
3979.56	42.952
3983.24	42.5064
3986.92	41.5694
3990.59	40.8013
3994.26	40.1363
3997.92	41.6192
3999.76	43.094