File: Data/Raman/raw/bu25ts-ore1_2_1800 (450-850nm)_532nm_edge_5%_x50_vis_lwd_h30um_60sx2_01.txt
#Acq. time (s)=	60
#Accumulations=	2
#Range=	Off
#Autofocus=	Off
#Macrospot=	Off
#AutoExposure=	Off
#Spike filter=	Multiple accum.
#Delay time (s)=	2
#Binning=	1
#Readout mode=	Signal
#DeNoise=	Standard
#ICS correction=	On
#Dark correction=	Off
#Inst. Process=	Off
#Detector Gain=	Best Dynamic
#Detector ADC=	50 kHz HS
#Detector temperature (°C)=	-60.09
#Instrument=	LabRAM HR Evol
#Detector=	SIN-EM FIVIS
#Objective=	x50_VIS_LWD
#Grating=	1800 (450-850nm)
#ND Filter=	5%
#Laser=	532nm_Edge
#Spectro (cm-¹)=	849.971
#Hole=	30.0125
#Temperature=	0
#Range=	Visible
#StageXY=	75x50mm Scan+
#StageZ=	Z motor
#X (µm)=	0
#Y (µm)=	0
#Z (µm)=	-859.9
#Full time(mm:ss)=	2:05
#Project=	20_12_18
#Sample=	BU25TS
#Site=
#Title=	BU25TS-Ore1_2_1800 (450-850nm)_532nm_Edge_5%_x50_VIS_LWD_H30um_60sX2
#Remark=
#Date=	18.12.2020 15:49
#Acquired=	18.12.2020 15:49:46
1076.92	15.2185
1076.36	15.8325
1075.81	16.0291
1075.25	16.1626
1074.69	16.2432
1074.13	16.2805
1073.57	16.2813
1073.01	16.2511
1072.45	16.1896
1071.89	16.1228
1071.34	16.0474
1070.78	15.9654
1070.22	15.8804
1069.66	15.797
1069.1	15.7189
1068.54	15.6486
1067.98	15.5881
1067.42	15.5859
1066.86	15.5822
1066.31	15.5945
1065.75	15.618
1065.19	15.6954
1064.63	15.7337
1064.07	15.7627
1063.51	15.7793
1062.95	15.7811
1062.39	15.7678
1061.83	15.7407
1061.27	15.647
1060.71	15.6022
1060.15	15.5658
1059.59	15.545
1059.03	15.5473
1058.47	15.5781
1057.91	15.6369
1057.35	15.722
1056.79	15.8296
1056.23	15.9546
1055.67	16.0905
1055.11	16.1457
1054.55	16.118
1053.99	16.0876
1053.43	16.0639
1052.87	16.0476
1052.31	16.042
1051.75	16.0492
1051.19	16.0706
1050.63	16.1063
1050.07	16.1551
1049.51	16.1723
1048.95	16.259
1048.39	16.3522
1047.82	16.3241
1047.26	16.2568
1046.7	16.2056
1046.14	16.1738
1045.58	16.1626
1045.02	16.1699
1044.46	16.1913
1043.9	16.2225
1043.33	16.2585
1042.77	16.2926
1042.21	16.0998
1041.65	15.7349
1041.09	15.1653
1040.53	15.1829
1039.97	15.2578
1039.4	15.858
1038.84	16.2474
1038.28	16.2393
1037.72	16.2426
1037.16	16.2572
1036.6	16.2784
1036.03	16.3078
1035.47	16.3487
1034.91	16.4077
1034.35	16.4698
1033.78	16.4064
1033.22	16.236
1032.66	16.083
1032.1	15.9547
1031.53	15.8557
1030.97	15.7896
1030.41	15.8383
1029.85	15.8825
1029.28	15.9385
1028.72	15.987
1028.16	16.0135
1027.6	16.0285
1027.03	16.0336
1026.47	16.032
1025.91	16.0204
1025.35	16.0141
1024.78	16.0195
1024.22	16.0403
1023.65	16.0783
1023.09	16.1337
1022.53	16.2052
1021.97	16.2899
1021.4	16.3823
1020.84	16.2658
1020.28	16.1106
1019.71	15.9767
1019.15	15.8788
1018.58	15.8295
1018.02	15.8125
1017.46	15.8386
1016.89	15.965
1016.33	16.0357
1015.77	16.2548
1015.2	16.4001
1014.64	16.3643
1014.07	16.279
1013.51	16.198
1012.95	16.1231
1012.38	16.0614
1011.82	16.0148
1011.25	15.9849
1010.69	15.9674
1010.12	15.9337
1009.56	15.9271
1008.99	15.7979
1008.43	15.7211
1007.86	15.7116
1007.3	15.7608
1006.74	15.8061
1006.17	15.8667
1005.61	15.9345
1005.04	16.0032
1004.48	16.0681
1003.91	16.1342
1003.35	16.1958
1002.78	16.2475
1002.21	16.3619
1001.65	16.2994
1001.09	16.2127
1000.52	16.0968
999.954	15.9549
999.388	15.7792
998.824	15.6206
998.258	15.5221
997.692	15.467
997.126	15.4726
996.56	15.8345
995.996	16.0189
995.43	16.2068
994.864	16.3662
994.297	16.591
993.731	16.845
993.165	17.0998
992.599	17.0934
992.032	17.0549
991.466	16.9071
990.899	16.753
990.335	16.5681
989.768	16.3972
989.202	16.2362
988.635	16.0818
988.069	15.9423
987.502	15.8407
986.936	15.7939
986.369	15.8177
985.802	15.9301
985.235	15.9356
984.669	15.9399
984.102	15.9536
983.535	15.9768
982.968	16.0097
982.399	16.0617
981.832	16.1243
981.265	16.1916
980.698	16.0238
980.131	16.3096
979.564	16.3601
978.997	16.3986
978.43	16.423
977.862	16.4325
977.295	16.3893
976.726	15.9197
976.158	15.6302
975.591	15.6043
975.024	15.7997
974.456	15.9677
973.887	16.0984
973.319	16.1926
972.752	16.263
972.184	16.276
971.617	16.244
971.047	16.1997
970.479	16.1416
969.911	16.0697
969.344	15.9839
968.774	15.8869
968.206	15.7838
967.638	15.6809
967.068	15.5858
966.5	15.5069
965.932	15.4526
965.364	15.4299
964.794	15.4443
964.226	15.495
963.656	15.5785
963.088	15.6892
962.52	15.8195
961.95	15.9604
961.381	16.0924
960.813	16.2073
960.243	16.2779
959.674	16.2917
959.104	16.2777
958.536	16.2398
957.965	16.1898
957.397	16.1422
956.828	16.1087
956.258	16.0978
955.689	16.116
955.118	16.1677
954.549	16.2596
953.979	16.3763
953.41	16.5154
952.839	16.6018
952.27	16.6076
951.7	16.621
951.129	16.6464
950.56	16.692
949.989	16.7874
949.42	16.9611
948.849	17.2611
948.28	17.4572
947.708	17.4103
947.137	16.7616
946.568	14.4377
945.997	16.4094
945.426	16.8201
944.856	16.6111
944.285	16.4431
943.714	16.3908
943.144	17.3401
942.573	17.4879
942.001	17.3212
941.432	16.8973
940.86	16.565
940.289	16.5402
939.719	16.2171
939.147	16.0165
938.576	15.9509
938.004	15.9664
937.434	16.0514
936.862	16.1855
936.291	16.2604
935.719	16.3498
935.147	16.4712
934.577	16.6121
934.005	16.7603
933.433	16.9029
932.861	17.0496
932.289	17.1917
931.717	17.1829
931.146	17.075
930.574	16.9381
930.002	16.7977
929.43	16.6707
928.857	16.6324
928.285	16.7817
927.713	17.2356
927.14	17.0375
926.568	16.873
925.997	16.7527
925.425	16.8667
924.852	16.9526
924.28	17.1008
923.707	17.3245
923.134	17.6821
922.562	17.7968
921.989	17.6992
921.416	17.7174
920.843	17.8053
920.27	17.9285
919.698	17.2639
919.125	16.2947
918.552	16.2806
917.977	16.568
917.404	16.6295
916.831	16.7369
916.257	17.4563
915.684	18.1654
915.111	18.7979
914.538	19.1243
913.965	19.0638
913.391	19.0222
912.818	18.9698
912.243	18.9309
911.669	18.9016
911.096	18.8869
910.522	18.6736
909.949	18.5535
909.375	18.5108
908.8	18.7683
908.226	19.0557
907.652	19.4856
907.079	19.6652
906.503	19.8009
905.929	19.9165
905.356	19.8211
904.782	19.8908
904.206	20.0038
903.632	20.1752
903.058	20.423
902.484	20.6065
901.908	20.7879
901.334	20.9717
900.76	21.1622
900.184	21.3724
899.61	21.5401
899.035	21.6625
898.459	21.8423
897.885	22.0816
897.31	22.3937
896.734	22.7969
896.16	23.2761
895.583	23.8341
895.009	24.4644
894.434	24.9705
893.858	25.5167
893.283	26.1431
892.707	26.7859
892.132	27.3527
891.555	27.9683
890.981	28.6382
890.404	29.3749
889.829	30.1772
889.252	31.1248
888.677	32.2127
888.101	33.4649
887.526	35.4341
886.949	37.1396
886.374	38.39
885.797	39.9816
885.222	42.9729
884.644	45.3612
884.069	47.593
883.492	49.8485
882.915	52.8207
882.34	56.5501
881.762	60.1405
881.187	63.6762
880.61	66.8408
880.032	69.6987
879.457	72.5389
878.879	75.2895
878.302	77.7706
877.726	79.3307
877.149	80.2757
876.571	80.8931
875.995	81.2567
875.418	81.4325
874.84	81.4284
874.262	81.43
873.686	81.2588
873.108	80.9236
872.531	80.3724
871.955	79.6161
871.377	78.6488
870.799	77.47
870.221	75.6281
869.643	73.2512
869.066	70.4095
868.488	67.2199
867.91	64.1094
867.332	63.1109
866.754	60.8527
866.175	59.0142
865.599	56.7756
865.021	54.4489
864.442	52.5777
863.864	51.1728
863.285	50.0978
862.707	48.9414
862.128	47.6674
861.55	46.355
860.973	45.0695
860.394	43.5381
859.816	42.1005
859.237	41.0913
858.658	40.6015
858.079	40.4173
857.501	39.9473
856.922	39.1874
856.343	38.2181
855.764	36.9932
855.185	35.5937
854.606	34.2408
854.027	33.0003
853.448	31.9617
852.868	31.1177
852.289	30.5444
851.71	31.075
851.131	31.6432
850.551	31.6505
849.97	31.5364
849.391	31.419
848.811	31.291
848.232	30.3614
847.652	29.3906
847.073	28.7918
846.493	28.6116
845.914	28.4986
845.332	28.3279
844.753	28.1687
844.173	27.9782
843.593	27.4514
843.013	27.2146
842.433	27.1264
841.852	27.1016
841.272	27.1347
840.692	27.3633
840.112	27.3918
839.532	27.4003
838.95	27.3427
838.37	27.1361
837.79	26.9524
837.208	26.7738
836.627	26.6016
836.047	26.4371
835.467	26.2816
834.885	26.1385
834.304	26.0101
833.724	25.8999
833.141	25.8119
832.561	25.7498
831.98	25.7207
831.398	25.7256
830.817	25.7608
830.237	25.8216
829.654	25.9023
829.073	25.9979
828.491	26.1052
827.91	26.22
827.329	26.3373
826.746	26.4474
826.166	26.5405
825.583	26.6109
825.002	26.5491
824.419	26.4281
823.838	26.3289
823.255	26.239
822.674	26.1582
822.091	26.0853
821.509	26.0137
820.926	25.8844
820.345	25.5545
819.762	25.1846
819.18	24.7861
818.597	24.3885
818.016	23.9556
817.432	23.585
816.851	23.2648
816.267	23.0058
815.684	22.8157
815.102	22.8785
814.519	22.8524
813.937	22.8619
813.353	22.8996
812.769	22.7558
812.188	22.4429
811.604	22.15
811.02	21.8885
810.438	21.7827
809.854	21.7313
809.27	21.8533
808.688	21.983
808.104	22.0717
807.52	22.1876
806.938	22.2905
806.354	22.3123
805.77	22.3078
805.186	22.2619
804.603	21.9205
804.019	21.7241
803.435	21.5068
802.85	21.3327
802.268	21.2325
801.684	21.2299
801.099	21.2824
800.515	21.5162
799.93	21.5037
799.347	21.492
798.763	21.4712
798.178	21.4279
797.594	21.3607
797.009	21.2326
796.424	20.4138
795.841	21.0444
795.256	21.0535
794.671	21.0096
794.087	20.9809
793.502	20.9696
792.917	20.9949
792.332	21.0432
791.746	21.0991
791.161	21.158
790.576	21.2145
789.991	21.2473
789.406	21.0775
788.82	20.9255
788.235	20.7973
787.65	20.696
787.064	20.6261
786.479	20.5855
785.894	20.5694
785.308	20.5729
784.723	20.5917
784.137	20.622
783.551	20.6616
782.966	20.7087
782.38	20.76
781.794	20.809
781.209	20.826
780.623	20.7766
780.037	20.7157
779.451	20.6435
778.863	20.5585
778.277	20.465
777.691	20.3711
777.105	20.2828
776.519	20.2198
775.933	20.1899
775.347	20.2026
774.759	20.2595
774.172	20.3584
773.586	20.486
773	20.6303
772.414	20.7819
771.825	20.9319
771.239	20.9668
770.652	20.9587
770.066	20.9476
769.477	20.9617
768.891	20.9921
768.304	21.0394
767.718	21.1048
767.129	21.1908
766.542	21.2767
765.955	21.2121
765.367	21.1406
764.78	21.0664
764.193	20.9937
763.604	20.9203
763.017	20.8415
762.43	20.7598
761.841	20.6799
761.254	20.609
760.667	20.5639
760.078	20.5313
759.491	20.515
758.901	20.5183
758.314	20.542
757.727	20.2951
757.138	20.0266
756.55	19.8216
755.961	19.6972
755.373	19.8923
754.784	20.1651
754.196	20.6654
753.607	20.8619
753.019	20.7926
752.43	20.7035
751.842	20.6021
751.252	20.5019
750.665	20.3772
750.075	20.3475
749.487	19.9053
748.897	20.1839
748.309	20.45
747.719	20.6995
747.131	20.9624
746.541	20.8413
745.951	20.1516
745.363	19.6008
744.773	19.2026
744.185	19.5943
743.595	20.0316
743.004	20.4645
742.416	20.7759
741.826	20.5573
741.235	20.3316
740.647	20.1102
740.057	19.9037
739.466	19.7226
738.878	19.578
738.287	19.4757
737.697	19.4183
737.108	19.4777
736.517	19.5554
735.927	19.6493
735.336	19.7598
734.747	19.9285
734.156	20.0941
733.565	20.228
732.974	20.3464
732.385	20.4331
731.794	20.4796
731.203	20.4954
730.612	20.4816
730.021	20.4406
729.432	20.3755
728.841	20.2418
728.25	20.1601
727.659	20.081
727.067	20.0113
726.476	19.9588
725.887	19.7396
725.295	19.3993
724.704	19.0573
724.112	18.7118
723.521	18.4359
722.929	18.1849
722.338	18.2855
721.746	19.0731
721.154	19.5728
720.563	19.9777
719.971	19.8485
719.379	19.9173
718.787	20.0107
718.197	20.1244
717.606	20.3002
717.014	20.0871
716.422	19.8179
715.83	19.599
715.236	19.4861
714.643	19.8905
714.051	20.4263
713.459	20.8715
712.867	20.3242
712.275	18.8532
711.682	18.3955
711.09	19.2813
710.498	19.8794
709.905	20.2699
709.313	20.2304
708.72	20.2032
708.128	20.2607
707.535	20.1168
706.941	19.7874
706.348	19.5076
705.755	19.2098
705.163	19.1153
704.57	19.1017
703.977	19.1381
703.382	19.1797
702.789	19.3505
702.197	19.5163
701.604	19.667
701.011	19.7032
700.416	19.6688
699.823	19.641
699.229	19.6118
698.636	19.5737
698.041	19.5183
697.448	19.4206
696.855	19.2856
696.261	19.1162
695.666	18.9174
695.073	18.7027
694.479	18.5193
693.884	18.3521
693.29	18.2072
692.697	18.0888
692.101	17.9999
691.508	17.9548
690.914	17.9532
690.318	17.9891
689.724	18.0564
689.131	18.1506
688.535	18.2669
687.941	18.4005
687.345	18.5536
686.751	18.7118
686.157	18.8699
685.561	19.0251
684.967	19.1747
684.371	19.3149
683.777	19.4416
683.181	19.5614
682.587	19.6784
681.99	19.7626
681.396	19.7279
680.8	19.6524
680.206	19.5376
679.609	19.3896
679.015	19.2214
678.418	19.0443
677.824	18.8366
677.227	18.5956
676.633	18.6463
676.036	18.7376
675.441	19.0885
674.845	19.3996
674.248	19.4653
673.653	19.3557
673.056	19.2752
672.461	19.2258
671.864	19.2276
671.268	19.277
670.672	19.3657
670.076	19.4841
669.478	19.5149
668.883	19.4794
668.286	19.4488
667.689	19.4261
667.094	19.4063
666.497	19.4285
665.899	19.3529
665.304	19.5988
664.707	19.982
664.109	20.2977
663.512	20.4063
662.916	20.4614
662.319	20.5188
661.721	20.5812
661.123	20.6515
660.528	20.5273
659.93	20.2846
659.332	20.0547
658.735	19.8459
658.139	19.662
657.541	19.499
656.943	19.3561
656.345	19.2586
655.747	19.222
655.149	19.1673
654.553	19.137
653.955	19.1318
653.357	19.0849
652.759	19.1445
652.161	19.2414
651.562	19.3746
650.964	19.5423
650.366	19.743
649.767	19.8031
649.169	19.8195
648.573	19.7318
647.974	19.9067
647.376	20.1137
646.777	20.3452
646.178	20.5916
645.58	20.8647
644.981	21.0569
644.382	21.201
643.784	21.2904
643.185	21.2944
642.586	21.2028
641.987	21.108
641.388	20.9972
640.789	20.8674
640.19	20.7272
639.591	20.5865
638.992	20.4547
638.391	20.3406
637.792	20.2512
637.193	20.1884
636.593	20.1523
635.994	20.1662
635.395	20.2534
634.796	20.3226
634.196	20.3953
633.597	20.483
632.995	20.5906
632.396	20.7078
631.796	20.834
631.197	20.9663
630.597	21.1023
629.997	21.2289
629.396	21.3436
628.796	21.4464
628.196	21.5497
627.596	21.6522
626.996	21.7253
626.394	21.7852
625.794	21.8217
625.195	21.7869
624.594	21.6463
623.992	21.4612
623.392	21.2398
622.792	20.9976
622.19	20.7481
621.59	20.5059
620.99	20.287
620.389	20.1068
619.787	19.9787
619.186	19.9086
618.586	20.0276
617.984	20.1724
617.383	20.4059
616.783	20.4993
616.18	20.2398
615.579	19.9758
614.977	19.7128
614.376	19.463
613.775	19.2689
613.473	19.2012