File: Data/Raman/raw/burangaite_150 (500nm)_532nm_Edge_100%_x100_VIS_H100um_20sX2.txt
#Acq. time (s)=	20
#Accumulations=	2
#Range (cm-¹)=	100...5300
#Windows=	1
#Auto scanning=	Off
#Autofocus=	Off
#Macrospot=	Off
#AutoExposure=	Off
#Spike filter=	Multiple accum.
#Delay time (s)=	1
#Binning=	1
#Readout mode=	Signal
#DeNoise=	Standard
#ICS correction=	On
#Dark correction=	Off
#Inst. Process=	On
#Detector Gain=	Best Dynamic
#Detector ADC=	50 kHz HS
#Detector temperature (°C)=	-60.09
#Instrument=	LabRAM HR Evol
#Detector=	SIN-EM FIVIS
#Objective=	x100_VIS
#Grating=	150 (500nm)
#ND Filter=	100%
#Laser=	532nm_Edge
#Hole=	100.021
#Temperature=	0
#Range=	Visible
#StageXY=	75x50mm Scan+
#StageZ=	Z motor
#X (µm)=	0
#Y (µm)=	0
#Z (µm)=	37.1
#Project=	20_05_08
#Sample=	BU20
#Site=
#Title=	burangaite_BU20C_150 (500nm)_532nm_Edge_100%_x100_VIS_H100um_20sX2
#Remark=
#Date=	08.05.2020 17:34
#Acquired=	08.05.2020 17:34:35
104.231	17145.7
113.473	15606.8
122.707	14096.7
131.93	12435.6
141.145	11241.5
150.349	10844.6
159.547	10273.7
168.733	9829.98
177.912	9799.06
187.08	10057
196.241	10911.6
205.391	11265.5
214.532	11476.8
223.666	11973.9
232.789	13530.8
241.905	12346.2
251.01	10273.6
260.106	11131.5
269.195	14491.3
278.274	15465.6
287.343	13203.1
296.404	11261.6
305.458	12295.6
314.5	13813.1
323.534	13558.1
332.559	12891.3
341.576	12732.4
350.583	12963.4
359.584	12387.9
368.574	10892.5
377.555	10795.4
386.528	12277.4
395.491	13032.1
404.446	10197.2
413.393	8424.26
422.33	8386.89
431.259	8636.73
440.179	8671.88
449.091	8718.52
457.994	9434.87
466.888	10805.2
475.772	11597.6
484.649	11247
493.517	10835.4
502.377	10389.1
511.228	9970.86
520.071	9505.82
528.903	8986.76
537.728	8641.58
546.546	8446.28
555.354	8421.48
564.152	9204.68
572.944	11141.5
581.727	13641.7
590.499	13225.6
599.266	11063.3
608.023	9230.25
616.771	9399.29
625.512	11211.9
634.242	12258.8
642.966	10337
651.68	8251.47
660.387	7354.2
669.084	6984.14
677.775	6722.54
686.455	6324.17
695.129	5939.49
703.793	5637.06
712.448	5493.58
721.098	5493.84
729.736	5550.84
738.367	5622
746.991	5676.99
755.606	5713.6
764.212	5745.48
772.809	5765.27
781.401	5781.42
789.982	5797.44
798.555	5816.64
807.12	5850.56
815.677	5887.36
824.228	5918.46
832.768	5949.87
841.301	6019.81
849.825	6181.1
858.342	6328.84
866.85	6376.74
875.35	6289.22
883.842	6194.14
892.326	6136.5
900.802	6167.71
909.27	6263.53
917.73	6429.41
926.182	6682.82
934.626	6986.77
943.06	7241.57
951.488	7757.25
959.908	8730.36
968.32	10434.5
976.724	12389.9
985.119	13551.4
993.507	15456.1
1001.89	22352.1
1010.26	28004.9
1018.62	26165.6
1026.98	25476.1
1035.33	20712.8
1043.67	15528.3
1052	12867.7
1060.32	11912.3
1068.64	11315.4
1076.95	10911
1085.25	10895.4
1093.55	10786.4
1101.83	9675.93
1110.11	8881.57
1118.38	9062.91
1126.64	9327.35
1134.9	9117.32
1143.14	8558.27
1151.38	7761.8
1159.61	7146.73
1167.84	6884
1176.05	6936.74
1184.26	7321.91
1192.46	7578.77
1200.65	7118.2
1208.84	6715.65
1217.02	6534.9
1225.19	6390.75
1233.35	6255.51
1241.5	6122.37
1249.65	6011.04
1257.79	5944.29
1265.92	5910.41
1274.05	5905.44
1282.16	5915.54
1290.27	5932.58
1298.37	5955.05
1306.47	5977.86
1314.55	5999.13
1322.63	6020.15
1330.7	6034.37
1338.77	6042.86
1346.83	6048.4
1354.87	6049.52
1362.91	6051.55
1370.95	6058.93
1378.98	6067.83
1387	6077.35
1395.01	6088.13
1403.01	6099.95
1411.01	6112.67
1419	6120.73
1426.98	6116.67
1434.95	6104.28
1442.92	6086.44
1450.88	6082.01
1458.84	6080.68
1466.78	6079.5
1474.72	6088.91
1482.65	6097.24
1490.57	6103.59
1498.49	6107.67
1506.4	6110.39
1514.3	6114.61
1522.2	6125.03
1530.08	6142.75
1537.96	6156.65
1545.83	6176.21
1553.7	6196.57
1561.56	6209.73
1569.41	6220.44
1577.25	6224.87
1585.09	6221.1
1592.92	6208.42
1600.74	6188.05
1608.56	6162.93
1616.37	6132.62
1624.17	6101.47
1631.96	6079.09
1639.75	6062.3
1647.53	6053.39
1655.3	6053.01
1663.07	6061.01
1670.82	6076.45
1678.58	6093
1686.32	6105.66
1694.06	6110.81
1701.79	6106.86
1709.51	6090.51
1717.23	6073.28
1724.94	6046.46
1732.64	6015.94
1740.33	5988.03
1748.02	5965.11
1755.7	5945.1
1763.38	5927.59
1771.04	5911.6
1778.7	5897.3
1786.36	5885.55
1794.01	5875.82
1801.64	5867.05
1809.28	5859.55
1816.9	5863.12
1824.52	5869.46
1832.13	5880.49
1839.74	5892.85
1847.34	5904.7
1854.93	5911.23
1862.51	5910.63
1870.09	5902.82
1877.66	5889.37
1885.23	5872.37
1892.79	5852.89
1900.34	5831.72
1907.88	5811.95
1915.42	5789.5
1922.95	5783.91
1930.47	5790.71
1937.99	5805.05
1945.5	5822.68
1953	5839.05
1960.5	5849.63
1967.99	5862.12
1975.47	5866.2
1982.95	5861.83
1990.42	5851.99
1997.88	5838.63
2005.34	5821.63
2012.79	5800.42
2020.23	5783.71
2027.67	5770.15
2035.1	5762.38
2042.52	5757.18
2049.94	5748.12
2057.35	5739.89
2064.75	5732.88
2072.15	5734.96
2079.54	5744.79
2086.92	5758.48
2094.3	5773.19
2101.67	5778.71
2109.03	5787.46
2116.39	5791.66
2123.74	5783.88
2131.09	5787.19
2138.42	5788.76
2145.76	5769.66
2153.08	5732.68
2160.4	5691.02
2167.71	5653.7
2175.02	5622.96
2182.32	5601.12
2189.61	5583.31
2196.9	5567.04
2204.17	5551.81
2211.45	5537.19
2218.72	5521.15
2225.98	5486.07
2233.23	5485.02
2240.48	5452.16
2247.72	5430.35
2254.96	5414.44
2262.18	5405.91
2269.41	5400.11
2276.62	5384.01
2283.83	5362.79
2291.04	5350.5
2298.23	5338.06
2305.42	5324.78
2312.61	5328.86
2319.79	5336.51
2326.96	5338.05
2334.12	5337.91
2341.28	5330.78
2348.44	5308.65
2355.58	5284.24
2362.72	5269.9
2369.86	5257.5
2376.99	5241.99
2384.11	5223.79
2391.22	5202.85
2398.33	5180.25
2405.44	5157.51
2412.53	5136.66
2419.62	5116.88
2426.71	5098.79
2433.79	5086.46
2440.86	5086.08
2447.92	5087.32
2454.98	5085.71
2462.04	5080.7
2469.09	5075.83
2476.13	5070.2
2483.16	5060.27
2490.19	5046.55
2497.22	5029.8
2504.23	5010.82
2511.24	4990.62
2518.25	4970.52
2525.25	4950.57
2532.24	4930.69
2539.23	4911.1
2546.21	4891.6
2553.19	4875.07
2560.15	4864.05
2567.12	4857.44
2574.07	4855.8
2581.02	4859.07
2587.97	4863.77
2594.91	4864.19
2601.84	4869.59
2608.77	4869.94
2615.69	4871.97
2622.6	4879.03
2629.51	4887.77
2636.42	4898.55
2643.31	4909.34
2650.2	4915.89
2657.09	4914.11
2663.97	4902.6
2670.84	4880.39
2677.71	4856
2684.57	4832.14
2691.43	4809.47
2698.28	4788.72
2705.12	4769.89
2711.96	4751.57
2718.79	4736.5
2725.62	4727.09
2732.44	4713.86
2739.25	4698.67
2746.06	4680.42
2752.87	4660.19
2759.66	4639.16
2766.46	4612.86
2773.24	4603.15
2780.02	4596.4
2786.8	4585.39
2793.56	4571.44
2800.33	4554.51
2807.08	4527.76
2813.83	4497.1
2820.58	4468.63
2827.32	4440.66
2834.05	4415.57
2840.78	4399.64
2847.51	4381.75
2854.22	4364.8
2860.93	4351.68
2867.64	4342.67
2874.34	4336.8
2881.03	4324.95
2887.72	4306.89
2894.41	4285.81
2901.08	4268.14
2907.75	4251.19
2914.42	4229.7
2921.08	4213.58
2927.73	4199.9
2934.38	4184.82
2941.03	4168.75
2947.67	4149.21
2954.3	4127.63
2960.93	4097.7
2967.54	4061.2
2974.16	4024.62
2980.77	4000.15
2987.38	3986.95
2993.97	3975.51
3000.57	3965.83
3007.16	3961.07
3013.74	3954.83
3020.31	3944.6
3026.89	3930.53
3033.45	3918.18
3040.01	3908.73
3046.57	3900.59
3053.12	3889.69
3059.66	3874.74
3066.2	3862.1
3072.73	3854.23
3079.26	3847.14
3085.78	3838.21
3092.29	3829.06
3098.81	3821.24
3105.31	3815.16
3111.81	3809.72
3118.31	3804.89
3124.8	3799.62
3131.28	3795.81
3137.76	3797.67
3144.23	3799.48
3150.7	3802.67
3157.16	3809.26
3163.62	3823.33
3170.07	3835.87
3176.52	3849.24
3182.96	3860.77
3189.39	3889.3
3195.82	3944.61
3202.25	4011.85
3208.67	4126.89
3215.08	4315.46
3221.49	4596.05
3227.89	4954.92
3234.29	5408.96
3240.68	5917.72
3247.07	6341.92
3253.45	6529.52
3259.83	6469.24
3266.2	6384.41
3272.57	6299.66
3278.93	6001.95
3285.29	5428.56
3291.64	4901.28
3297.98	4554.85
3304.32	4238.05
3310.66	4028.78
3316.99	3868.79
3323.31	3746.22
3329.63	3649.63
3335.95	3560.12
3342.26	3494.98
3348.56	3446.26
3354.86	3409.43
3361.15	3379.75
3367.44	3354.39
3373.72	3330.3
3380	3306.16
3386.27	3284.04
3392.54	3263.84
3398.8	3251.34
3405.06	3247.16
3411.31	3243.73
3417.56	3232.42
3423.8	3207.6
3430.04	3166.29
3436.27	3122.43
3442.5	3084.17
3448.72	3042.89
3454.94	3003.98
3461.15	2969.99
3467.36	2940.54
3473.56	2916.32
3479.75	2898.98
3485.94	2891.32
3492.13	2885.54
3498.31	2887.1
3504.49	2874.55
3510.66	2855.18
3516.82	2835.36
3522.99	2866.89
3529.14	2957.15
3535.29	3014.8
3541.44	2951.59
3547.58	2879.13
3553.72	2862.3
3559.85	2885.55
3565.98	3018.78
3572.1	3291.17
3578.21	3870.29
3584.32	5307.02
3590.43	10417.7
3596.53	20898.5
3602.63	18935.5
3608.72	10196.6
3614.81	6468.39
3620.89	4307.86
3626.97	3161.14
3633.04	2784.89
3639.11	2553.71
3645.17	2449.33
3651.22	2386.86
3657.28	2344.37
3663.32	2312.47
3669.37	2286.29
3675.4	2261.2
3681.44	2238.06
3687.47	2216.99
3693.49	2196.2
3699.51	2171.08
3705.52	2160.75
3711.53	2151.95
3717.53	2152.4
3723.53	2147.02
3729.53	2134.85
3735.52	2126.9
3741.5	2122.78
3747.48	2115.03
3753.46	2105.87
3759.43	2096.54
3765.39	2086.35
3771.35	2075.1
3777.31	2062.3
3783.26	2048.43
3789.21	2035.93
3795.15	2024
3801.09	2008.93
3807.02	1993.29
3812.95	1979.27
3818.87	1967.5
3824.79	1958.33
3830.7	1947.66
3836.61	1939.28
3842.51	1933.54
3848.41	1930.42
3854.31	1922.57
3860.2	1910.79
3866.08	1904.12
3871.96	1896.91
3877.84	1890.29
3883.71	1884.59
3889.58	1880.85
3895.44	1878.34
3901.29	1873.19
3907.15	1865.99
3913	1857.47
3918.84	1849.92
3924.68	1843.8
3930.51	1836.74
3936.34	1827.88
3942.17	1816.6
3947.99	1805
3953.8	1795.36
3959.61	1786.47
3965.42	1778.15
3971.22	1767.57
3977.02	1761.42
3982.81	1755.18
3988.6	1745.18
3994.38	1733.99
4000.16	1720.36
4005.94	1708.1
4011.71	1697.5
4017.47	1689.08
4023.23	1682.91
4028.99	1682.17
4034.74	1683.48
4040.49	1684.53
4046.23	1681.19
4051.97	1672.77
4057.7	1660.97
4063.43	1649.25
4069.16	1641.09
4074.88	1635.32
4080.59	1630.85
4086.31	1626.32
4092.01	1621.26
4097.72	1614.67
4103.41	1607.2
4109.11	1600.57
4114.8	1595.97
4120.48	1593.41
4126.16	1593.21
4131.84	1591.88
4137.51	1588.38
4143.17	1585.47
4148.84	1582.85
4154.5	1578.17
4160.15	1576.06
4165.8	1572.75
4171.44	1570.54
4177.08	1571.13
4182.72	1573.06
4188.35	1575.04
4193.98	1575.45
4199.6	1572.59
4205.22	1566.33
4210.83	1557.33
4216.44	1545.38
4222.05	1531.74
4227.65	1518.92
4233.25	1506.53
4238.84	1495.55
4244.43	1485.45
4250.01	1475.8
4255.59	1467.1
4261.17	1459.32
4266.74	1452.55
4272.31	1446.06
4277.87	1437.21
4283.42	1428.89
4288.98	1422.06
4294.53	1418.29
4300.07	1415.22
4305.61	1413.27
4311.15	1411.1
4316.68	1407.25
4322.21	1396.65
4327.73	1389.03
4333.25	1380.36
4338.77	1374.75
4344.28	1372.64
4349.79	1371.84
4355.29	1367.57
4360.79	1360.99
4366.28	1349.99
4371.77	1339.56
4377.26	1330.3
4382.74	1322.61
4388.22	1316.71
4393.69	1312.56
4399.16	1309.78
4404.62	1307.81
4410.08	1305.9
4415.54	1305.35
4420.99	1302.1
4426.44	1298.13
4431.88	1290.83
4437.32	1288.79
4442.76	1289.83
4448.19	1291.69
4453.62	1291.68
4459.04	1287.48
4464.46	1286.22
4469.87	1274.89
4475.28	1264.58
4480.69	1256.61
4486.09	1249.59
4491.49	1243.02
4496.89	1237.02
4502.27	1231.57
4507.66	1224.78
4513.04	1216.55
4518.42	1206.84
4523.79	1195.2
4529.16	1183.4
4534.53	1174.54
4539.89	1166.99
4545.25	1159.61
4550.6	1156.81
4555.95	1165.61
4561.3	1176.22
4566.64	1182.58
4571.97	1185.59
4577.31	1181.56
4582.64	1170.43
4587.96	1159.53
4593.28	1147.99
4598.6	1137.4
4603.91	1129.22
4609.22	1122.58
4614.53	1115.21
4619.83	1107.79
4625.12	1101.69
4630.42	1098.04
4635.71	1092.5
4640.99	1085.85
4646.27	1077.82
4651.55	1070.62
4656.82	1064.79
4662.09	1060.86
4667.36	1059.01
4672.62	1059.9
4677.87	1063.55
4683.13	1062.87
4688.38	1059.45
4693.62	1052.88
4698.86	1043.96
4704.1	1037.37
4709.33	1033.32
4714.56	1032.34
4719.79	1032.51
4725.01	1032.64
4730.23	1031.02
4735.44	1023.99
4740.65	1016.71
4745.86	1006.32
4751.06	995.577
4756.26	988.501
4761.45	985.711
4766.64	985.834
4771.83	987.853
4777.01	989.25
4782.19	989.157
4787.37	985.441
4792.54	979.044
4797.71	971.678
4802.87	964.947
4808.03	958.994
4813.18	955.891
4818.34	950.617
4823.48	945.99
4828.63	941.41
4833.77	936.381
4838.91	926.078
4844.04	921.3
4849.17	919.445
4854.29	919.146
4859.41	928.993
4864.53	929.421
4869.65	922.371
4874.76	912.915
4879.86	906.131
4884.96	900.874
4890.06	898.497
4895.16	902.623
4900.25	902.009
4905.34	898.021
4910.42	893.08
4915.5	884.025
4920.58	875.933
4925.65	868.589
4930.72	862.259
4935.78	859.558
4940.84	857.369
4945.9	855.565
4950.95	854.189
4956	853.039
4961.05	852.566
4966.09	851.968
4971.13	849.96
4976.17	846.155
4981.2	840.956
4986.23	837.646
4991.25	834.788
4996.27	832.206
5001.29	829.867
5006.3	827.649
5011.31	826.672
5016.31	825.761
5021.32	824.533
5026.31	821.384
5031.31	817.83
5036.3	814.248
5041.29	811.249
5046.27	808.658
5051.25	806.628
5056.23	804.481
5061.2	801.037
5066.17	794.984
5071.13	790.014
5076.1	786.886
5081.05	785.722
5086.01	785.993
5090.96	787.037
5095.91	783.765
5100.85	778.495
5105.79	772.144
5110.73	766.659
5115.66	763.203
5120.59	758.812
5125.52	754.512
5130.44	750.847
5135.35	748.389
5140.27	746.315
5145.18	742.939
5150.09	741.64
5154.99	740.49
5159.89	738.731
5164.79	737.414
5169.69	733.521
5174.57	729.711
5179.46	727.841
5184.34	726.886
5189.22	726.087
5194.1	725.819
5198.97	726.149
5203.84	726.685
5208.71	723.902
5213.57	719.499
5218.42	715.683
5223.28	711.141
5228.13	705.93
5232.98	699.648
5237.82	692.972
5242.66	690.242
5247.5	687.263
5252.33	686.526
5257.17	687.469
5261.99	690.035
5266.82	692.951
5271.64	694.093
5276.45	692.104
5281.26	686.325
5286.07	680.531
5290.88	678.081
5295.68	675.28
5298.08	678.038