File: Data/Raman/raw/montebrasite-F_150 (500nm)_532nm_Edge_100%_x50_VIS_LWD_H100um_20sX2.txt
#Acq. time (s)=	20
#Accumulations=	2
#Range (cm-¹)=	100...5300
#Windows=	1
#Auto scanning=	Off
#Autofocus=	Off
#Macrospot=	Off
#AutoExposure=	Off
#Spike filter=	Multiple accum.
#Delay time (s)=	1
#Binning=	1
#Readout mode=	Signal
#DeNoise=	Standard
#ICS correction=	On
#Dark correction=	Off
#Inst. Process=	On
#Detector Gain=	Best Dynamic
#Detector ADC=	50 kHz HS
#Detector temperature (°C)=	-60.09
#Instrument=	LabRAM HR Evol
#Detector=	SIN-EM FIVIS
#Objective=	x50_VIS_LWD
#Grating=	150 (500nm)
#ND Filter=	100%
#Laser=	532nm_Edge
#Hole=	100.021
#Temperature=	0
#Range=	Visible
#StageXY=	75x50mm Scan+
#StageZ=	Z motor
#X (µm)=	0
#Y (µm)=	0
#Z (µm)=	1335.9
#Project=	20_05_08
#Sample=	BU20
#Site=
#Title=	montebrasite_BU20B_150 (500nm)_532nm_Edge_100%_x50_VIS_LWD_H100um_20sX2
#Remark=
#Date=	08.05.2020 16:51
#Acquired=	08.05.2020 16:51:33
104.231	5595.93
113.473	8624.75
122.707	8243.66
131.93	5707
141.145	5879.53
150.349	5941.09
159.547	5063.74
168.733	4455.52
177.912	4218.41
187.08	3600.43
196.241	3539.05
205.391	3714.08
214.532	3656.04
223.666	3491.46
232.789	3402.37
241.905	3659.49
251.01	4611.76
260.106	5901.89
269.195	9804.48
278.274	21209.3
287.343	25564.7
296.404	16218.4
305.458	9548.07
314.5	6780.76
323.534	5396.06
332.559	4784.39
341.576	4807.6
350.583	5032.7
359.584	5196.79
368.574	5077.78
377.555	4855.68
386.528	4736.32
395.491	4982.98
404.446	6503.83
413.393	6796.4
422.33	4783.19
431.259	4135.12
440.179	4108.91
449.091	4689.12
457.994	6116.28
466.888	7265.25
475.772	7136.86
484.649	6066.15
493.517	4645.87
502.377	3941.66
511.228	3647.99
520.071	3620.96
528.903	3677.9
537.728	3738.92
546.546	3783.66
555.354	3905.39
564.152	4194.81
572.944	5695.69
581.727	8871.98
590.499	8510.56
599.266	7180.63
608.023	9776.98
616.771	14342.8
625.512	21550.1
634.242	19116.2
642.966	7802.14
651.68	4418.37
660.387	3717.67
669.084	3424.56
677.775	3258.53
686.455	3171.3
695.129	3117.97
703.793	3098.65
712.448	3099.55
721.098	3123.39
729.736	3157.74
738.367	3212.03
746.991	3240.28
755.606	3328.5
764.212	3496.2
772.809	3793.14
781.401	4126.78
789.982	4249.74
798.555	4038.56
807.12	3719.87
815.677	3551.77
824.228	3525.65
832.768	3571.43
841.301	3679.02
849.825	3853.11
858.342	4074.79
866.85	4309.72
875.35	4486.95
883.842	4572.18
892.326	4305.11
900.802	4117.83
909.27	4085.01
917.73	4156.21
926.182	4312.85
934.626	4447.68
943.06	4720.3
951.488	5162.43
959.908	5989.01
968.32	7692.87
976.724	13028.7
985.119	25869.9
993.507	34374
1001.89	32892.1
1010.26	18456
1018.62	13025.5
1026.98	15364.5
1035.33	24182.5
1043.67	33067.5
1052	22258.2
1060.32	10040
1068.64	6915.72
1076.95	6196.36
1085.25	6951.12
1093.55	8517.4
1101.83	8731.12
1110.11	7387.94
1118.38	5851.34
1126.64	5007.2
1134.9	4661.29
1143.14	4636.66
1151.38	4873.75
1159.61	5124.33
1167.84	5633.27
1176.05	5971.76
1184.26	5679.13
1192.46	4865.25
1200.65	4215.66
1208.84	3937.18
1217.02	3816.36
1225.19	3755.06
1233.35	3718.4
1241.5	3684.39
1249.65	3670.32
1257.79	3664.72
1265.92	3666.39
1274.05	3673.09
1282.16	3677.78
1290.27	3678.33
1298.37	3674.98
1306.47	3667.83
1314.55	3657.71
1322.63	3645.27
1330.7	3631.7
1338.77	3616.94
1346.83	3602.99
1354.87	3587.22
1362.91	3569.6
1370.95	3553.06
1378.98	3540.51
1387	3532.57
1395.01	3534.43
1403.01	3547.71
1411.01	3566.45
1419	3590.84
1426.98	3604.42
1434.95	3607.04
1442.92	3597.32
1450.88	3577.68
1458.84	3560.3
1466.78	3547
1474.72	3537.52
1482.65	3531.03
1490.57	3525.97
1498.49	3521.05
1506.4	3517.99
1514.3	3514.75
1522.2	3510.48
1530.08	3524.74
1537.96	3553.87
1545.83	3595.13
1553.7	3642.29
1561.56	3687.9
1569.41	3726.56
1577.25	3738.99
1585.09	3727.39
1592.92	3707.4
1600.74	3679.57
1608.56	3649.24
1616.37	3617.89
1624.17	3586.9
1631.96	3561.52
1639.75	3545.9
1647.53	3531.2
1655.3	3520.12
1663.07	3513.97
1670.82	3513.92
1678.58	3521.37
1686.32	3531.92
1694.06	3539.89
1701.79	3547.97
1709.51	3553.31
1717.23	3549.98
1724.94	3536.66
1732.64	3521.17
1740.33	3505.98
1748.02	3492.43
1755.7	3480.04
1763.38	3467.83
1771.04	3456.85
1778.7	3446.83
1786.36	3437.53
1794.01	3429.33
1801.64	3424.2
1809.28	3425.4
1816.9	3431.64
1824.52	3438
1832.13	3443.94
1839.74	3449.73
1847.34	3453.15
1854.93	3451.42
1862.51	3446.81
1870.09	3439.24
1877.66	3427.77
1885.23	3409.55
1892.79	3383.19
1900.34	3358.14
1907.88	3337.72
1915.42	3325.43
1922.95	3324.92
1930.47	3329.28
1937.99	3336.57
1945.5	3346.34
1953	3356.71
1960.5	3364.4
1967.99	3372.36
1975.47	3381.92
1982.95	3392.27
1990.42	3400.02
1997.88	3403.78
2005.34	3400.93
2012.79	3387.99
2020.23	3368.69
2027.67	3357.17
2035.1	3343.81
2042.52	3331.76
2049.94	3322.58
2057.35	3317.45
2064.75	3316.09
2072.15	3317.21
2079.54	3319.74
2086.92	3322.78
2094.3	3326.96
2101.67	3331.34
2109.03	3335.01
2116.39	3337.7
2123.74	3340.43
2131.09	3342.56
2138.42	3342.78
2145.76	3339.41
2153.08	3332.99
2160.4	3326.18
2167.71	3318.26
2175.02	3321.72
2182.32	3304.09
2189.61	3281.9
2196.9	3278.08
2204.17	3325.67
2211.45	3306.33
2218.72	3341.54
2225.98	3374.75
2233.23	3381.26
2240.48	3362.35
2247.72	3327.95
2254.96	3301.1
2262.18	3281.32
2269.41	3267.69
2276.62	3259.54
2283.83	3257.17
2291.04	3262.41
2298.23	3274.06
2305.42	3292.6
2312.61	3313.1
2319.79	3324.43
2326.96	3332.7
2334.12	3337.11
2341.28	3338.93
2348.44	3337.23
2355.58	3340.76
2362.72	3331.16
2369.86	3316.27
2376.99	3299.68
2384.11	3281.48
2391.22	3262.69
2398.33	3246.13
2405.44	3236.7
2412.53	3230.17
2419.62	3220.61
2426.71	3210.56
2433.79	3203.63
2440.86	3202.98
2447.92	3208.29
2454.98	3218.14
2462.04	3231.3
2469.09	3244.45
2476.13	3252.16
2483.16	3254.42
2490.19	3251.53
2497.22	3245.99
2504.23	3238.67
2511.24	3229.82
2518.25	3219.72
2525.25	3209.5
2532.24	3199.89
2539.23	3189.22
2546.21	3178.14
2553.19	3168.68
2560.15	3161.78
2567.12	3156.37
2574.07	3151.24
2581.02	3147.68
2587.97	3146.68
2594.91	3147.86
2601.84	3150.37
2608.77	3154.04
2615.69	3159.23
2622.6	3165.52
2629.51	3171.17
2636.42	3175.13
2643.31	3178.1
2650.2	3179.91
2657.09	3179.26
2663.97	3174.53
2670.84	3166.16
2677.71	3155.49
2684.57	3144.74
2691.43	3135.61
2698.28	3128.16
2705.12	3122.27
2711.96	3118.6
2718.79	3118.48
2725.62	3123.19
2732.44	3126.39
2739.25	3128.11
2746.06	3126.21
2752.87	3119.08
2759.66	3112.79
2766.46	3109.77
2773.24	3109.41
2780.02	3110.04
2786.8	3109.24
2793.56	3108.95
2800.33	3111.59
2807.08	3116.94
2813.83	3123.69
2820.58	3131.54
2827.32	3139.07
2834.05	3145.49
2840.78	3146.73
2847.51	3153.69
2854.22	3164.2
2860.93	3175.92
2867.64	3187.79
2874.34	3197.44
2881.03	3202.67
2887.72	3203.87
2894.41	3201.88
2901.08	3196.95
2907.75	3196.71
2914.42	3241.56
2921.08	3288.7
2927.73	3307.62
2934.38	3284.34
2941.03	3256.1
2947.67	3242.46
2954.3	3225.77
2960.93	3205.9
2967.54	3183.95
2974.16	3158.94
2980.77	3133.85
2987.38	3109.92
2993.97	3091
3000.57	3073.56
3007.16	3061.37
3013.74	3055.06
3020.31	3048.96
3026.89	3044.3
3033.45	3042.11
3040.01	3042.67
3046.57	3047.3
3053.12	3053.8
3059.66	3059.76
3066.2	3062.81
3072.73	3061.65
3079.26	3057.07
3085.78	3051.6
3092.29	3047.07
3098.81	3043.8
3105.31	3042.93
3111.81	3046.5
3118.31	3052.26
3124.8	3058.56
3131.28	3063.56
3137.76	3068.13
3144.23	3072.27
3150.7	3076.42
3157.16	3080.93
3163.62	3087.31
3170.07	3091.41
3176.52	3092.83
3182.96	3098.03
3189.39	3105.09
3195.82	3112.77
3202.25	3115.79
3208.67	3116.92
3215.08	3119.82
3221.49	3123.25
3227.89	3127.02
3234.29	3126.61
3240.68	3124.51
3247.07	3119.84
3253.45	3116.59
3259.83	3115.89
3266.2	3115.35
3272.57	3120.59
3278.93	3133.77
3285.29	3146.84
3291.64	3183.17
3297.98	3254.05
3304.32	3402.17
3310.66	3657.86
3316.99	4019.8
3323.31	4578.21
3329.63	5326.57
3335.95	6198.46
3342.26	7258.54
3348.56	8115.16
3354.86	8502.13
3361.15	8217.31
3367.44	7462.25
3373.72	6461.38
3380	5849.02
3386.27	5405.53
3392.54	5153.42
3398.8	4927.1
3405.06	4637.21
3411.31	4300.35
3417.56	3886.64
3423.8	3503.57
3430.04	3258.02
3436.27	3121.41
3442.5	3070.2
3448.72	3054.01
3454.94	3039.82
3461.15	3040.81
3467.36	3042.7
3473.56	3041.69
3479.75	3031.74
3485.94	3026.38
3492.13	3016.03
3498.31	2998.61
3504.49	2975.05
3510.66	2951.01
3516.82	2927.87
3522.99	2905.81
3529.14	2886.83
3535.29	2874.89
3541.44	2867.84
3547.58	2863.51
3553.72	2855.14
3559.85	2862.76
3565.98	2866.3
3572.1	2861.62
3578.21	2845.67
3584.32	2816
3590.43	2782.59
3596.53	2762.17
3602.63	2747.35
3608.72	2735.69
3614.81	2725.81
3620.89	2715.59
3626.97	2707.19
3633.04	2694.05
3639.11	2677.12
3645.17	2663.21
3651.22	2653.16
3657.28	2640.93
3663.32	2628.09
3669.37	2621.72
3675.4	2616.65
3681.44	2610.68
3687.47	2607.18
3693.49	2601.32
3699.51	2595.44
3705.52	2589.82
3711.53	2581.53
3717.53	2576.67
3723.53	2572.86
3729.53	2570.54
3735.52	2569.01
3741.5	2563.66
3747.48	2561.77
3753.46	2558.66
3759.43	2555.65
3765.39	2550.5
3771.35	2542.4
3777.31	2535.97
3783.26	2529.27
3789.21	2524.44
3795.15	2520.4
3801.09	2515.66
3807.02	2523.28
3812.95	2515.82
3818.87	2504.21
3824.79	2491.87
3830.7	2480.55
3836.61	2473.45
3842.51	2479
3848.41	2491.5
3854.31	2497.14
3860.2	2498.71
3866.08	2494.79
3871.96	2483.09
3877.84	2479.29
3883.71	2475.05
3889.58	2472.17
3895.44	2469.3
3901.29	2463.98
3907.15	2462.16
3913	2455.87
3918.84	2445.88
3924.68	2436.33
3930.51	2430.17
3936.34	2422.86
3942.17	2419.39
3947.99	2419.65
3953.8	2425.56
3959.61	2430.86
3965.42	2428.51
3971.22	2416.18
3977.02	2403.91
3982.81	2393.82
3988.6	2394.92
3994.38	2389.24
4000.16	2379.93
4005.94	2360.52
4011.71	2352.31
4017.47	2355.4
4023.23	2363.57
4028.99	2366.78
4034.74	2365.41
4040.49	2353.25
4046.23	2350.14
4051.97	2346.06
4057.7	2341.78
4063.43	2338.6
4069.16	2334.47
4074.88	2330.2
4080.59	2327.16
4086.31	2322.71
4092.01	2315.61
4097.72	2311.56
4103.41	2311.75
4109.11	2313.04
4114.8	2315.65
4120.48	2322.75
4126.16	2327.98
4131.84	2333.67
4137.51	2330
4143.17	2329.88
4148.84	2335.91
4154.5	2334.31
4160.15	2316.64
4165.8	2312.36
4171.44	2305.5
4177.08	2298.78
4182.72	2299.28
4188.35	2305.06
4193.98	2311.3
4199.6	2316.82
4205.22	2320.62
4210.83	2318.31
4216.44	2311.56
4222.05	2301.65
4227.65	2285.81
4233.25	2270.21
4238.84	2259.46
4244.43	2254.83
4250.01	2251.79
4255.59	2248.48
4261.17	2243.86
4266.74	2238.31
4272.31	2232.44
4277.87	2225.54
4283.42	2222.95
4288.98	2217.99
4294.53	2211.92
4300.07	2207.39
4305.61	2204.17
4311.15	2212.72
4316.68	2219.91
4322.21	2220.11
4327.73	2198.33
4333.25	2184.33
4338.77	2172.83
4344.28	2159.9
4349.79	2146.35
4355.29	2139.26
4360.79	2135.72
4366.28	2135.27
4371.77	2138.41
4377.26	2140.48
4382.74	2136.27
4388.22	2131.42
4393.69	2124.54
4399.16	2116.48
4404.62	2110.88
4410.08	2107.21
4415.54	2106.35
4420.99	2108.06
4426.44	2107.52
4431.88	2105.93
4437.32	2101.83
4442.76	2097.37
4448.19	2090.21
4453.62	2084.25
4459.04	2078.19
4464.46	2078.74
4469.87	2082.34
4475.28	2085.06
4480.69	2085.98
4486.09	2081.97
4491.49	2074.27
4496.89	2065.52
4502.27	2057.55
4507.66	2051.73
4513.04	2046.6
4518.42	2042.2
4523.79	2037.37
4529.16	2034.35
4534.53	2031.24
4539.89	2028.3
4545.25	2024.21
4550.6	2022.39
4555.95	2023.05
4561.3	2022.54
4566.64	2020.27
4571.97	2017.7
4577.31	2011.65
4582.64	2007.91
4587.96	2001.17
4593.28	1993.19
4598.6	1985.57
4603.91	1978.55
4609.22	1974.59
4614.53	1972.53
4619.83	1970.66
4625.12	1963.15
4630.42	1957.84
4635.71	1950.26
4640.99	1940.75
4646.27	1935.39
4651.55	1930.55
4656.82	1926.78
4662.09	1921.27
4667.36	1914.49
4672.62	1907.99
4677.87	1904.78
4683.13	1903.21
4688.38	1899.5
4693.62	1894.05
4698.86	1888.15
4704.1	1884.69
4709.33	1880.82
4714.56	1877.16
4719.79	1875.32
4725.01	1877.16
4730.23	1879.16
4735.44	1878.87
4740.65	1875.14
4745.86	1868.6
4751.06	1862.69
4756.26	1858.82
4761.45	1854.17
4766.64	1852.59
4771.83	1846.41
4777.01	1842.66
4782.19	1839.76
4787.37	1834.1
4792.54	1827.68
4797.71	1820.06
4802.87	1814.73
4808.03	1808.83
4813.18	1802.64
4818.34	1797.57
4823.48	1794.94
4828.63	1791.71
4833.77	1787.72
4838.91	1785.88
4844.04	1786.07
4849.17	1784.53
4854.29	1780.25
4859.41	1777.05
4864.53	1777.77
4869.65	1779.67
4874.76	1778.92
4879.86	1775.95
4884.96	1772.92
4890.06	1765.82
4895.16	1757.78
4900.25	1749.51
4905.34	1745.57
4910.42	1744.26
4915.5	1745.3
4920.58	1743.8
4925.65	1739.44
4930.72	1734.05
4935.78	1724.32
4940.84	1715.4
4945.9	1708.45
4950.95	1704.97
4956	1702.28
4961.05	1698.87
4966.09	1692.78
4971.13	1686.95
4976.17	1684.47
4981.2	1681.47
4986.23	1684.41
4991.25	1686.18
4996.27	1686.41
5001.29	1684.83
5006.3	1678.89
5011.31	1669.53
5016.31	1662.21
5021.32	1655.73
5026.31	1650.01
5031.31	1644.98
5036.3	1642.52
5041.29	1641.56
5046.27	1639.56
5051.25	1635.14
5056.23	1629.79
5061.2	1626.18
5066.17	1622.44
5071.13	1618.24
5076.1	1614.1
5081.05	1609.73
5086.01	1609.43
5090.96	1609.71
5095.91	1610.08
5100.85	1612.76
5105.79	1613.1
5110.73	1608.73
5115.66	1600.18
5120.59	1591.79
5125.52	1582.53
5130.44	1571.68
5135.35	1563.49
5140.27	1556.72
5145.18	1551.28
5150.09	1544.9
5154.99	1543
5159.89	1551.62
5164.79	1541.89
5169.69	1528.26
5174.57	1529.02
5179.46	1533.1
5184.34	1536.52
5189.22	1530.98
5194.1	1521.84
5198.97	1518.45
5203.84	1516.98
5208.71	1512.47
5213.57	1508.14
5218.42	1503.64
5223.28	1502.21
5228.13	1502.85
5232.98	1499.9
5237.82	1494.73
5242.66	1493.73
5247.5	1493.56
5252.33	1489.72
5257.17	1484.29
5261.99	1485.19
5266.82	1482.1
5271.64	1478.38
5276.45	1475.56
5281.26	1469.23
5286.07	1461.37
5290.88	1450.14
5295.68	1444.87
5298.08	1441.74