File: Data/Raman/raw/montebrasite-OH_150 (500nm)_633nm_Edge_50%_x50_VIS_LWD_H100um_15sX2.txt
#Acq. time (s)=	15
#Accumulations=	2
#Range (cm-¹)=	100...4000
#Windows=	1
#Auto scanning=	Off
#Autofocus=	Off
#Macrospot=	Off
#AutoExposure=	Off
#Spike filter=	Multiple accum.
#Delay time (s)=	0
#Binning=	1
#Readout mode=	Signal
#DeNoise=	Standard
#ICS correction=	On
#Dark correction=	Off
#Inst. Process=	On
#Detector Gain=	Best Dynamic
#Detector ADC=	50 kHz HS
#Detector temperature (°C)=	-60.09
#Instrument=	LabRAM HR Evol
#Detector=	SIN-EM FIVIS
#Objective=	x50_VIS_LWD
#Grating=	150 (500nm)
#ND Filter=	50%
#Laser=	633nm_Edge
#Hole=	100.021
#Temperature=	0
#Range=	Visible
#StageXY=	75x50mm Scan+
#StageZ=	Z motor
#X (µm)=	0
#Y (µm)=	0
#Z (µm)=	82.3
#Project=	20_05_11
#Sample=	BU20b
#Site=
#Title=	BU20b-area1-cleavaged-clear-rim_150 (500nm)_633nm_Edge_50%_x50_VIS_LWD_H100um_15sX2
#Remark=
#Date=	11.05.2020 17:45
#Acquired=	11.05.2020 17:45:00
100.862	1296.01
107.378	1293.83
113.889	1291.6
120.394	1288.6
126.894	1290.25
133.388	1307.51
139.878	1363.4
146.361	1337.2
152.84	1296.75
159.313	1300.15
165.78	1364.02
172.242	1502.98
178.699	1534.46
185.149	1428.62
191.596	1384.17
198.037	1334.3
204.472	1298.45
210.903	1290.19
217.326	1318.87
223.746	1385.05
230.16	1422.92
236.568	1383.82
242.972	1338.9
249.371	1279.79
255.762	1244.7
262.151	1266.86
268.533	1341.93
274.91	1678.44
281.282	2235.15
287.648	1690.79
294.01	1699.03
300.365	2549.1
306.716	2082.67
313.061	1597.69
319.401	1398.94
325.737	1293.38
332.066	1236.23
338.392	1204.34
344.711	1181.06
351.024	1171.48
357.335	1169.54
363.638	1171.72
369.936	1179.03
376.23	1187.15
382.519	1198.98
388.802	1214.32
395.08	1230.42
401.353	1243.18
407.62	1251.36
413.884	1255.14
420.141	1270.77
426.394	1367.63
432.641	1494.91
438.883	1255.63
445.12	1177.35
451.352	1160.03
457.579	1144.63
463.801	1164.23
470.018	1224.49
476.23	1349.12
482.437	1597.2
488.638	1738.41
494.834	1632.52
501.026	1451.02
507.212	1278.69
513.394	1150.17
519.571	1100.51
525.743	1084.84
531.908	1082.83
538.07	1075.24
544.227	1068.96
550.377	1064.13
556.524	1058.91
562.666	1049.09
568.801	1044.44
574.933	1024.6
581.061	1042.14
587.181	1038.9
593.299	1088.48
599.41	1187.92
605.517	1296.17
611.618	1145.16
617.716	1121.11
623.807	1282.58
629.895	1628.44
635.977	1505.18
642.053	1367.58
648.127	1678.82
654.193	1421.22
660.256	1139.37
666.314	1037.05
672.367	991.168
678.414	977.511
684.457	972.56
690.496	978.639
696.529	982.13
702.558	966.111
708.581	957.913
714.6	953.846
720.614	955.034
726.624	952.952
732.628	948.663
738.628	948.105
744.623	949.099
750.613	951.309
756.598	956.625
762.578	964.855
768.554	978.429
774.525	988.819
780.49	1005.75
786.451	1043.83
792.408	1123.93
798.36	1310.86
804.307	1440.96
810.25	1281.18
816.186	1137.22
822.119	1039.75
828.048	986.319
833.972	970.871
839.889	970.469
845.804	968.287
851.714	964.545
857.617	962.479
863.518	964.09
869.413	964.673
875.303	965.331
881.19	964.477
887.07	961.347
892.947	956.347
898.818	953.591
904.686	951.962
910.548	949.669
916.406	950.927
922.26	952.1
928.108	956.593
933.953	962.442
939.792	969.597
945.626	976.48
951.457	982.767
957.282	986.359
963.103	989.353
968.919	984.482
974.731	997.807
980.539	999.841
986.341	1015.59
992.139	1072.19
997.932	1179.55
1003.72	1380.76
1009.51	1833.46
1015.29	2211.72
1021.06	1798.55
1026.83	1407.46
1032.6	1291.5
1038.36	1413.99
1044.12	1762.6
1049.87	2060.43
1055.62	1740.8
1061.36	1608.59
1067.1	1365.17
1072.84	1189.63
1078.56	1097.89
1084.29	1067.21
1090.01	1072.59
1095.73	1093.07
1101.44	1151.58
1107.15	1448.62
1112.85	1706.46
1118.55	1444.42
1124.24	1238.6
1129.94	1120.62
1135.62	1065.1
1141.3	1036.61
1146.98	1021.61
1152.65	1016.21
1158.32	1014.86
1163.98	1018.6
1169.64	1030.39
1175.3	1050.7
1180.95	1085.64
1186.59	1144.59
1192.23	1217.35
1197.87	1182.94
1203.5	1123.7
1209.13	1080.57
1214.75	1057.11
1220.37	1039.93
1225.99	1027.27
1231.6	1019
1237.21	1010.93
1242.81	1007.24
1248.41	1006.07
1254	1005.25
1259.59	1005.96
1265.17	1005.42
1270.75	1003.11
1276.33	1001.65
1281.9	1000.25
1287.47	998.443
1293.03	998.784
1298.59	1002.4
1304.15	1007.18
1309.7	1011.49
1315.24	1013.93
1320.78	1015.38
1326.32	1015.29
1331.85	1010.69
1337.38	1009.62
1342.91	1014.82
1348.43	1019.14
1353.95	1021.42
1359.46	1015.01
1364.97	1006.78
1370.47	999.65
1375.97	996.232
1381.46	996.582
1386.96	998.801
1392.44	1000.6
1397.92	1002.54
1403.4	1003.73
1408.88	1007.34
1414.35	1008.92
1419.81	1007.47
1425.27	1007.06
1430.73	1007.53
1436.18	1008.56
1441.63	1008.99
1447.08	1007.25
1452.52	1005.63
1457.96	1003.94
1463.39	1000.43
1468.82	996.756
1474.24	994.7
1479.66	993.229
1485.08	994.263
1490.49	998.026
1495.9	1005.13
1501.3	1011.91
1506.7	1015.87
1512.09	1017.5
1517.49	1018.67
1522.87	1021.32
1528.26	1019.48
1533.63	1017.22
1539.01	1015.79
1544.38	1013.73
1549.75	1012.83
1555.11	1013.09
1560.47	1015.38
1565.82	1019.32
1571.17	1023.61
1576.52	1027.69
1581.86	1031.35
1587.2	1033.75
1592.54	1033.39
1597.86	1029.63
1603.19	1024.84
1608.51	1022.71
1613.83	1021.43
1619.15	1020.39
1624.46	1020.66
1629.76	1021.61
1635.06	1021.37
1640.36	1019.54
1645.66	1012.74
1650.95	1009.91
1656.23	1008.21
1661.52	1009.06
1666.79	1011.08
1672.07	1017.79
1677.34	1021.81
1682.6	1022.36
1687.87	1020.46
1693.13	1014.91
1698.38	1009.97
1703.63	1008.44
1708.88	1008.49
1714.12	1007.34
1719.36	1007.92
1724.59	1005.36
1729.82	1003.97
1735.05	1002.2
1740.27	1001.26
1745.49	999.146
1750.71	999.639
1755.92	1002.27
1761.13	1004.09
1766.33	1003.92
1771.53	1001.14
1776.73	996.726
1781.92	992.703
1787.11	991.674
1792.29	992.091
1797.47	995.077
1802.65	997.982
1807.82	998.365
1812.99	997.973
1818.15	996.523
1823.32	995.99
1828.47	994.707
1833.63	993.387
1838.78	994.174
1843.92	993.946
1849.06	993.508
1854.2	992.355
1859.34	988.837
1864.47	987.58
1869.59	987.168
1874.72	986.179
1879.84	982.475
1884.95	977.195
1890.06	974.033
1895.17	974.701
1900.27	976.628
1905.37	977.329
1910.47	978.511
1915.56	980.714
1920.65	983.473
1925.74	986.718
1930.82	986.613
1935.9	986.041
1940.97	985.645
1946.04	985.839
1951.11	981.906
1956.17	981.034
1961.23	982.167
1966.28	982.245
1971.33	981.64
1976.38	979.198
1981.43	976.484
1986.47	972.647
1991.5	970.277
1996.54	969.722
2001.57	970.507
2006.59	971.952
2011.61	974.386
2016.63	976.67
2021.65	978.624
2026.66	978.522
2031.66	980.025
2036.67	981.351
2041.67	982.927
2046.66	981.499
2051.66	980.053
2056.65	978.634
2061.63	975.85
2066.61	974.783
2071.59	975.254
2076.56	975.667
2081.53	976.392
2086.5	974.342
2091.46	974.057
2096.42	974.93
2101.38	977.434
2106.33	982.892
2111.28	987.693
2116.23	985.853
2121.17	983.967
2126.11	978.148
2131.04	973.654
2135.97	971.334
2140.9	968.416
2145.82	964.793
2150.74	964.702
2155.66	966.459
2160.57	970.081
2165.48	972.508
2170.39	972.991
2175.29	970.763
2180.19	967.323
2185.09	963.91
2189.98	960.266
2194.86	960.354
2199.75	965.817
2204.63	972.162
2209.51	980.214
2214.38	984.077
2219.25	984.108
2224.12	983.114
2228.98	980.481
2233.84	978.441
2238.7	977.816
2243.55	982.111
2248.4	986.844
2253.25	984.756
2258.09	979.519
2262.93	974.823
2267.76	971.521
2272.6	968.419
2277.43	963.797
2282.25	959.232
2287.07	957.855
2291.89	961.195
2296.7	961.626
2301.52	960.934
2306.32	963.485
2311.13	966.13
2315.93	967.44
2320.73	964.254
2325.52	963.292
2330.31	964.98
2335.1	967.334
2339.88	967.462
2344.66	971.323
2349.44	974.182
2354.21	976.937
2358.98	977.603
2363.75	974.04
2368.51	968.372
2373.27	960.954
2378.03	954.83
2382.78	950.554
2387.53	948.439
2392.28	947.273
2397.02	946.733
2401.76	945.978
2406.49	945.701
2411.23	948.63
2415.95	950.217
2420.68	952.364
2425.4	951.959
2430.12	952.492
2434.84	947.949
2439.55	944.234
2444.26	946.69
2448.96	949.501
2453.67	948.546
2458.37	941.845
2463.06	936.478
2467.75	934.237
2472.44	932.973
2477.13	929.52
2481.81	929.301
2486.49	930.889
2491.17	936.94
2495.84	941.763
2500.51	946.336
2505.17	947.426
2509.84	946.797
2514.5	941.968
2519.15	934.736
2523.8	929.292
2528.45	923.561
2533.1	921.242
2537.74	923.798
2542.38	927.858
2547.02	926.489
2551.65	924.953
2556.28	923.828
2560.91	921.544
2565.53	918.769
2570.15	916.819
2574.77	914.124
2579.38	914.021
2583.99	922.951
2588.6	923.48
2593.2	918.073
2597.8	913.987
2602.4	907.225
2606.99	905.013
2611.58	902.807
2616.17	900.394
2620.75	898.785
2625.33	898.37
2629.91	898.374
2634.49	897.733
2639.06	897.391
2643.63	898.3
2648.19	898.547
2652.75	897.678
2657.31	896.509
2661.87	896.013
2666.42	896.588
2670.97	896.543
2675.51	897.995
2680.06	896.694
2684.6	896.37
2689.13	896.737
2693.67	896.075
2698.2	896.787
2702.72	890.197
2707.25	881.896
2711.77	876.193
2716.28	872.386
2720.8	868.748
2725.31	866.783
2729.82	866.975
2734.32	869.807
2738.83	873.218
2743.32	876.01
2747.82	875.792
2752.31	873.321
2756.8	871.344
2761.29	870.221
2765.77	870.295
2770.25	872.25
2774.73	874.131
2779.2	873.883
2783.67	872.326
2788.14	871.842
2792.6	872.007
2797.06	870.991
2801.52	870.869
2805.98	871.899
2810.43	871.444
2814.88	869.484
2819.32	869.909
2823.77	870.967
2828.2	872.376
2832.64	871.59
2837.08	868.091
2841.51	864.087
2845.93	864.085
2850.36	863.718
2854.78	863.197
2859.2	864.841
2863.61	865.678
2868.02	862.935
2872.43	857.305
2876.84	855.796
2881.24	856.821
2885.64	858.69
2890.04	858.879
2894.43	861.346
2898.82	863.844
2903.21	865.875
2907.6	864.735
2911.98	861.85
2916.36	862.154
2920.74	863.159
2925.11	862.427
2929.48	865.068
2933.84	862.809
2938.21	858.728
2942.57	853.51
2946.93	850.49
2951.28	847.054
2955.64	845.828
2959.98	846.825
2964.33	855.566
2968.67	857.143
2973.01	849.633
2977.35	848.726
2981.68	866.532
2986.02	868.744
2990.34	867.824
2994.67	866.395
2998.99	852.634
3003.31	848.973
3007.63	853.621
3011.94	855.797
3016.25	855.331
3020.56	849.062
3024.86	851.05
3029.17	854.26
3033.47	854.993
3037.76	851.572
3042.05	852.159
3046.34	854.964
3050.63	855.43
3054.92	853.594
3059.2	849.769
3063.48	847.335
3067.75	848.499
3072.02	849.689
3076.29	849.408
3080.56	848.229
3084.82	844.165
3089.09	843.975
3093.34	842.072
3097.6	839.787
3101.85	840.496
3106.1	843.859
3110.35	847.705
3114.59	851.382
3118.83	852.317
3123.07	850.992
3127.31	848.539
3131.54	845.001
3135.77	838.733
3140	838.02
3144.22	841.153
3148.44	854.618
3152.66	853.005
3156.87	850.964
3161.09	850.21
3165.29	848.357
3169.5	841.93
3173.71	839.548
3177.91	838.94
3182.11	840.871
3186.3	844.451
3190.49	842.7
3194.68	842.347
3198.87	844.081
3203.05	847.276
3207.24	851.295
3211.41	855.283
3215.59	857.748
3219.76	861.117
3223.93	855.699
3228.1	856.814
3232.27	860.253
3236.43	865.17
3240.59	866.139
3244.74	863.755
3248.9	866.245
3253.05	867.567
3257.2	869.342
3261.34	867.395
3265.48	862.971
3269.62	857.353
3273.76	854.892
3277.89	847.721
3282.02	840.73
3286.15	835.026
3290.28	831.721
3294.4	833.357
3298.52	838.087
3302.64	841.941
3306.75	844.305
3310.87	846.467
3314.98	846.715
3319.08	851.641
3323.19	846.323
3327.29	846.132
3331.39	851.965
3335.48	871.411
3339.58	918.381
3343.67	982.821
3347.75	1070.92
3351.84	1174.71
3355.92	1313.54
3360	1514.44
3364.08	1844.05
3368.15	2268.42
3372.22	2727.89
3376.29	3109.62
3380.36	3214.76
3384.42	2766.59
3388.48	2132.19
3392.54	1589.23
3396.59	1412.7
3400.65	1270.46
3404.7	1193.78
3408.74	1154.65
3412.79	1107.82
3416.83	1086.19
3420.87	1075.65
3424.91	1041.69
3428.94	991.964
3432.97	930.536
3437	880.922
3441.02	848.273
3445.05	828.791
3449.07	810.948
3453.09	803.606
3457.1	799.107
3461.11	800.358
3465.13	805.143
3469.13	808.258
3473.14	809.931
3477.14	810.006
3481.14	808.457
3485.14	807.86
3489.13	809.996
3493.12	810.449
3497.11	809.458
3501.1	809.651
3505.08	806.937
3509.06	804.211
3513.04	803.256
3517.02	799.187
3520.99	795.001
3524.96	792.286
3528.93	787.811
3532.89	784.728
3536.86	782.404
3540.82	782.265
3544.78	779.627
3548.73	774.621
3552.68	772.152
3556.63	771.236
3560.58	769.248
3564.53	768.878
3568.47	772.042
3572.41	772.132
3576.34	767.901
3580.28	767.646
3584.21	766.392
3588.14	766.62
3592.07	759.238
3595.99	749.766
3599.91	740.605
3603.83	737.221
3607.75	735.541
3611.66	738.988
3615.58	739.685
3619.49	739.261
3623.39	737.745
3627.3	734.871
3631.2	727.178
3635.1	723.373
3638.99	719.248
3642.89	716.227
3646.78	717.478
3650.67	719.657
3654.55	723.258
3658.44	722.623
3662.32	717.505
3666.2	717.792
3670.07	712.323
3673.95	705.958
3677.82	700.669
3681.69	696.736
3685.55	693.896
3689.42	694.643
3693.28	696.128
3697.14	699.791
3700.99	700.707
3704.85	705.627
3708.7	703.306
3712.55	700.656
3716.39	696.802
3720.24	691.901
3724.08	688.39
3727.92	685.446
3731.76	684.005
3735.59	681.034
3739.42	676.933
3743.25	675.479
3747.08	676.187
3750.9	674.803
3754.72	679.267
3758.54	678.892
3762.36	676.511
3766.17	677.178
3769.99	676.499
3773.79	672.258
3777.6	665.986
3781.41	665.143
3785.21	668.515
3789.01	672.55
3792.81	657.289
3796.6	655.484
3800.39	664.706
3804.18	676.061
3807.97	675.645
3811.76	666.221
3815.54	652.114
3819.32	641.26
3823.1	642.913
3826.87	647.928
3830.65	649.128
3834.42	653.465
3838.18	653.03
3841.95	648.819
3845.71	647.2
3849.48	646.608
3853.23	646.088
3856.99	648.274
3860.74	652.289
3864.5	651.616
3868.24	647.902
3871.99	644.609
3875.74	634.407
3879.48	631.28
3883.22	631.358
3886.95	630.866
3890.69	631.061
3894.42	633.119
3898.15	637.576
3901.88	635.653
3905.61	633.201
3909.33	633.494
3913.05	630.687
3916.77	628.814
3920.48	622.299
3924.2	617.291
3927.91	614.906
3931.62	613.705
3935.32	610.711
3939.03	606.934
3942.73	604.377
3946.43	604.14
3950.13	604.869
3953.82	607.574
3957.51	610.877
3961.2	610.93
3964.89	608.709
3968.58	599.182
3972.26	591.996
3975.94	586.338
3979.62	582.361
3983.3	581.677
3986.97	579.852
3990.64	577.61
3994.31	576.735
3997.98	577.245
3999.81	581.86