File: Data/Raman/raw/muscovite_150 (500nm)_633nm_edge_100%_x50_vis_lwd_h30um_15sx2_01.txt
#Acq. time (s)=	15
#Accumulations=	2
#Range (cm-¹)=	100...4000
#Windows=	1
#Auto scanning=	Off
#Autofocus=	Off
#Macrospot=	Off
#AutoExposure=	Off
#Spike filter=	Multiple accum.
#Delay time (s)=	2
#Binning=	1
#Readout mode=	Signal
#DeNoise=	Standard
#ICS correction=	On
#Dark correction=	Off
#Inst. Process=	Off
#Detector Gain=	Best Dynamic
#Detector ADC=	50 kHz EM
#Detector EM gain=	500
#Detector temperature (°C)=	-60.09
#Instrument=	LabRAM HR Evol
#Detector=	SIN-EM FIVIS
#Objective=	x50_VIS_LWD
#Grating=	150 (500nm)
#ND Filter=	100%
#Laser=	633nm_Edge
#Hole=	30.0125
#Temperature=	0
#Range=	Visible
#StageXY=	75x50mm Scan+
#StageZ=	Z motor
#X (µm)=	0
#Y (µm)=	0
#Z (µm)=	-2.1
#Full time(s)=	34
#Project=	20_11_11
#Sample=	BU18FA04
#Site=
#Title=	BU04-area1-mid_beige_150 (500nm)_633nm_Edge_100%_x50_VIS_LWD_H30um_15sX2
#Remark=
#Date=	11.11.2020 17:42
#Acquired=	11.11.2020 17:42:54
100.804	11786.6
107.32	10922.3
113.83	9177.92
120.336	8849.91
126.836	8749.14
133.33	8672.48
139.819	8598.48
146.303	8580.29
152.781	8626.5
159.254	8718.18
165.722	8835.87
172.184	9039.83
178.64	9298.11
185.091	9593.09
191.538	10240.2
197.979	10648.3
204.414	10343.2
210.843	9821.6
217.268	9455
223.688	9149.91
230.103	9030.51
236.51	9067.77
242.914	9266.07
249.313	9891.95
255.705	11426.4
262.093	14443.8
268.475	13724.6
274.852	11042.4
281.225	10061.3
287.59	9717.13
293.952	9546.45
300.308	9495.2
306.658	9465.85
313.004	9452.19
319.344	9450.21
325.68	9433.25
332.009	9414.6
338.335	9404.5
344.654	9414.12
350.968	9452.12
357.278	9523.25
363.581	9626.41
369.88	9758.9
376.173	9921.42
382.462	10092.8
388.745	10295.5
395.023	10521.1
401.296	10798
407.564	10866.2
413.826	10709.4
420.085	10395.5
426.337	10105
432.585	9846.49
438.827	9693.83
445.064	9586.23
451.296	9529.69
457.523	9518.22
463.745	9549.41
469.962	9600.5
476.174	9644.62
482.381	9679.84
488.581	9709.14
494.778	9724.16
500.97	9709.18
507.157	9683.02
513.338	9666.09
519.515	9662.19
525.686	9669.94
531.852	9690.18
538.014	9718.64
544.171	9748.71
550.322	9770.82
556.469	9784.06
562.611	9787.45
568.746	9783.1
574.878	9792.53
581.004	9858.04
587.126	9810.9
593.244	9796.34
599.355	10007.9
605.462	10176.5
611.563	10074
617.661	10107.3
623.752	10344.6
629.839	10476
635.922	10475.6
641.999	10398.1
648.072	10275.3
654.139	10168.2
660.201	10108.2
666.26	10093.4
672.312	10166.5
678.36	10319.4
684.403	10600.7
690.442	11083.9
696.475	11792.1
702.503	11885
708.527	11410
714.546	10923.6
720.56	10527.5
726.569	10412.5
732.574	10359.2
738.574	10409.5
744.569	10516.9
750.559	10619.3
756.544	10701.9
762.524	10702.3
768.5	10604.5
774.47	10517.9
780.436	10411.3
786.398	10317.2
792.354	10257
798.306	10228.8
804.254	10236.6
810.196	10253.7
816.133	10243.1
822.066	10232.1
827.995	10223.4
833.918	10208.7
839.836	10180
845.751	10151.1
851.66	10158.5
857.564	10176.6
863.465	10200.4
869.359	10229.9
875.25	10267.9
881.137	10304.9
887.017	10354
892.894	10417.1
898.766	10480.4
904.634	10536
910.496	10570.3
916.353	10553.1
922.207	10541.8
928.055	10536
933.9	10515.6
939.739	10518.3
945.573	10542.1
951.403	10567.1
957.23	10587.1
963.051	10602.7
968.867	10610
974.678	10608.7
980.487	10599.5
986.289	10558.3
992.087	10542.4
997.88	10560
1003.67	10604.8
1009.45	10675.8
1015.23	10768.3
1021.01	10846.3
1026.78	10893.4
1032.55	10906.2
1038.31	10899.2
1044.06	10907.1
1049.82	10937.5
1055.57	10985.1
1061.31	11020.2
1067.05	11026.8
1072.78	10987.7
1078.51	10916.6
1084.24	10851.1
1089.96	10810.5
1095.68	10791.2
1101.39	10792.7
1107.1	10813.7
1112.8	10854.1
1118.5	10907.9
1124.19	10933.4
1129.88	10920.3
1135.57	10912.6
1141.25	10901.3
1146.93	10877.3
1152.6	10838.3
1158.27	10789.4
1163.93	10766.9
1169.59	10768.5
1175.24	10779.2
1180.89	10765.9
1186.54	10781.4
1192.18	10832.4
1197.82	10888.1
1203.45	10941.2
1209.08	10988.2
1214.7	11027.2
1220.32	11056.4
1225.94	11076.9
1231.55	11095.1
1237.16	11113.5
1242.76	11121.5
1248.36	11086
1253.95	11039.1
1259.54	10995.5
1265.12	10962.3
1270.7	10935.1
1276.28	10902.6
1281.85	10925.4
1287.42	10992.1
1292.98	11085.1
1298.54	11139.5
1304.1	11172.1
1309.65	11193
1315.19	11199.6
1320.73	11179.6
1326.27	11157.6
1331.81	11137.2
1337.33	11100.7
1342.86	11043.4
1348.38	10974.1
1353.9	10917.3
1359.41	10893.7
1364.92	10890.5
1370.42	10896.1
1375.92	10896.3
1381.41	10897.9
1386.91	10888.4
1392.39	10874.2
1397.88	10870.7
1403.35	10860.4
1408.83	10875.8
1414.3	10904.4
1419.76	10926.6
1425.22	10933.1
1430.68	10928.7
1436.14	10934.6
1441.58	10944.5
1447.03	10969.6
1452.47	10983.2
1457.91	10984.4
1463.34	10971.9
1468.77	10940.6
1474.19	10910.7
1479.61	10902.1
1485.03	10900.7
1490.44	10907.1
1495.85	10911.2
1501.25	10905.9
1506.65	10891.6
1512.05	10870.8
1517.44	10851.8
1522.82	10856.9
1528.21	10867.9
1533.59	10877.3
1538.96	10893.2
1544.33	10906.3
1549.7	10905.6
1555.06	10896.6
1560.42	10888.4
1565.77	10890.3
1571.13	10892
1576.47	10897.9
1581.81	10863.8
1587.15	10816.4
1592.49	10779.2
1597.82	10742.5
1603.14	10708.7
1608.47	10676.9
1613.78	10720.1
1619.1	10460.5
1624.41	10842.1
1629.71	10868.7
1635.02	10851.3
1640.31	10827.2
1645.61	10793.5
1650.9	10817.2
1656.19	10796.9
1661.47	10756.7
1666.75	10709.7
1672.02	10660.5
1677.29	10609.1
1682.56	10556.5
1687.82	10505
1693.08	10468
1698.33	10477.5
1703.58	10504
1708.83	10536.9
1714.07	10573.8
1719.31	10606.7
1724.55	10628.9
1729.78	10623.7
1735	10578.6
1740.23	10499.7
1745.45	10393.2
1750.66	10287.3
1755.87	10216.6
1761.08	10177.7
1766.29	10169.5
1771.48	10173.5
1776.68	10192.8
1781.87	10202.2
1787.06	10175.7
1792.24	10147.8
1797.42	10135
1802.6	10135.2
1807.77	10145.4
1812.94	10162.3
1818.11	10174.1
1823.27	10183
1828.43	10169.9
1833.58	10124.8
1838.73	10052.2
1843.87	9985.49
1849.02	9937.29
1854.16	9912.39
1859.29	9910.25
1864.42	9921.95
1869.55	9977.22
1874.67	9994.71
1879.79	9985.81
1884.9	9965.35
1890.02	9881.3
1895.12	9845.76
1900.23	9858.23
1905.33	9931.52
1910.42	9923.28
1915.52	9868.25
1920.61	9782.34
1925.69	9670
1930.77	9671.56
1935.85	9673.55
1940.92	9667.33
1945.99	9668.02
1951.06	9671.38
1956.12	9673.23
1961.18	9670.84
1966.24	9664.11
1971.29	9650.45
1976.34	9630.86
1981.38	9627.99
1986.42	9580.67
1991.46	9532.02
1996.49	9505.2
2001.52	9493.75
2006.55	9494.13
2011.57	9502.75
2016.59	9513
2021.6	9523.11
2026.61	9514.72
2031.62	9465.96
2036.62	9391.5
2041.62	9319.14
2046.62	9261.79
2051.61	9220.52
2056.6	9197.16
2061.58	9198.62
2066.57	9184.58
2071.54	9147.32
2076.52	9124.17
2081.49	9098.84
2086.46	9088.12
2091.42	9093.11
2096.38	9106.68
2101.34	9128.28
2106.29	9143.06
2111.24	9132.79
2116.18	9106.41
2121.12	9087.35
2126.06	9042.03
2131	8985.69
2135.93	8937.5
2140.85	8893.62
2145.78	8858.74
2150.7	8824.97
2155.62	8797.83
2160.53	8778.24
2165.44	8758.24
2170.34	8747.17
2175.25	8751.83
2180.15	8764.93
2185.04	8781.63
2189.93	8798.66
2194.82	8825.91
2199.71	8782.28
2204.59	8757.4
2209.46	8746.59
2214.34	8728.09
2219.21	8697.21
2224.08	8672.69
2228.94	8664.44
2233.8	8641.16
2238.66	8632.59
2243.51	8622.1
2248.36	8592.05
2253.2	8550.21
2258.05	8510.12
2262.89	8470.08
2267.72	8440.28
2272.55	8423.43
2277.38	8415.97
2282.21	8426.86
2287.03	8440.77
2291.85	8437.98
2296.66	8414.45
2301.47	8383.48
2306.28	8358.34
2311.08	8328.48
2315.88	8319.61
2320.68	8307.24
2325.48	8293.73
2330.27	8277.21
2335.05	8246.53
2339.84	8214.21
2344.62	8178.88
2349.4	8160.66
2354.17	8158.98
2358.94	8171.72
2363.7	8157.99
2368.47	8131.7
2373.23	8100.71
2377.98	8073.57
2382.74	8048.32
2387.49	8001.57
2392.23	7947.62
2396.97	7922.12
2401.71	7928.39
2406.45	7954.26
2411.18	7988.73
2415.91	8036.62
2420.64	8084.11
2425.36	8114.42
2430.08	8124.8
2434.79	8112.6
2439.51	8082.93
2444.22	8039.42
2448.92	7982.07
2453.62	7917.27
2458.32	7887.54
2463.02	7870.07
2467.71	7863.34
2472.4	7861.26
2477.09	7863.61
2481.77	7869.5
2486.45	7893.86
2491.12	7920.88
2495.8	7936.32
2500.47	7943.74
2505.13	7930.85
2509.79	7868.34
2514.45	7773.31
2519.11	7681.54
2523.76	7606.18
2528.41	7537.53
2533.06	7471.12
2537.7	7457.76
2542.34	7493.57
2546.98	7529.45
2551.61	7568.28
2556.24	7599.41
2560.86	7617.98
2565.49	7616.68
2570.11	7603.05
2574.72	7579.99
2579.34	7553.73
2583.95	7522.32
2588.55	7482.03
2593.16	7440.92
2597.76	7405.1
2602.36	7376.99
2606.95	7365.69
2611.54	7391.69
2616.13	7410.3
2620.71	7415.22
2625.29	7399.11
2629.87	7368.27
2634.45	7327.57
2639.02	7283.4
2643.59	7223.61
2648.15	7225.94
2652.71	7342.76
2657.27	7345.19
2661.83	7283.77
2666.38	7169.66
2670.93	7100.68
2675.47	7069.52
2680.02	7043.68
2684.56	7036.48
2689.09	7062.67
2693.63	7111.14
2698.16	7169.76
2702.68	7195.51
2707.21	7145.82
2711.73	7116.25
2716.24	7087.25
2720.76	7065.2
2725.27	7045.53
2729.78	7035.99
2734.28	7043.52
2738.78	7068.89
2743.28	7094.67
2747.78	7082.49
2752.27	7065.3
2756.76	7045.48
2761.25	7019.47
2765.73	6987.3
2770.21	6948.17
2774.69	6907.29
2779.16	6891.22
2783.63	6904.94
2788.1	6934.11
2792.56	6930.72
2797.02	6917.69
2801.48	6835.75
2805.94	6746.09
2810.39	6676.36
2814.84	6610.01
2819.28	6533.64
2823.73	6518.41
2828.16	6525.93
2832.6	6538.01
2837.04	6556.36
2841.47	6578.93
2845.89	6604.56
2850.32	6633.36
2854.74	6666.57
2859.16	6709.9
2863.57	6736.46
2867.99	6750.27
2872.39	6684.68
2876.8	6639.96
2881.2	6603.81
2885.6	6576.68
2890	6567.01
2894.39	6579.52
2898.79	6622.56
2903.17	6664.98
2907.56	6647.85
2911.94	6599.37
2916.32	6529.6
2920.7	6447.65
2925.07	6387.46
2929.44	6349.08
2933.81	6333.69
2938.17	6346.03
2942.53	6382.84
2946.89	6413.87
2951.24	6417.86
2955.6	6408.99
2959.94	6397.12
2964.29	6381.48
2968.63	6329.99
2972.97	6287.8
2977.31	6279.06
2981.65	6268.67
2985.98	6256.05
2990.31	6226.2
2994.63	6197.78
2998.95	6205.56
3003.27	6193.96
3007.59	6164.36
3011.9	6140.27
3016.21	6113.83
3020.52	6081.53
3024.83	6037.44
3029.13	5994.72
3033.43	6007.29
3037.72	6025.35
3042.02	6038.8
3046.31	6035.94
3050.59	6058.73
3054.88	6080.39
3059.16	6092.14
3063.44	6107.67
3067.71	6069.53
3071.99	6137.92
3076.26	6051.17
3080.52	5997.39
3084.79	5983.56
3089.05	5999.13
3093.31	5926.19
3097.56	6095.74
3101.81	6070.28
3106.06	5997.75
3110.31	5896.48
3114.55	5795.02
3118.79	5806.36
3123.03	5824.18
3127.27	5808.04
3131.5	5830.33
3135.73	5871.12
3139.96	5893.45
3144.18	5865.48
3148.4	5806.85
3152.62	5776.11
3156.83	5754.87
3161.05	5744.43
3165.26	5738.07
3169.46	5726.15
3173.67	5700.34
3177.87	5658.09
3182.07	5626.68
3186.26	5609.99
3190.46	5599.85
3194.65	5592.9
3198.83	5584.67
3203.02	5578
3207.2	5565.88
3211.38	5545.24
3215.55	5510.76
3219.73	5476.67
3223.9	5477.96
3228.06	5439.66
3232.23	5453.74
3236.39	5474.85
3240.55	5501.88
3244.71	5556.49
3248.86	5554.18
3253.01	5509.16
3257.16	5491.58
3261.3	5476.81
3265.44	5470.45
3269.58	5474.26
3273.72	5483.38
3277.86	5503.32
3281.99	5539.32
3286.12	5570.2
3290.24	5573.33
3294.36	5542.07
3298.48	5483.15
3302.6	5399.07
3306.72	5322.3
3310.83	5336.4
3314.94	5299.13
3319.05	5253.47
3323.15	5252.56
3327.25	5257.45
3331.35	5277.88
3335.45	5322.65
3339.54	5381
3343.63	5428.78
3347.72	5445.65
3351.8	5402.17
3355.88	5328.72
3359.96	5259.95
3364.04	5189.18
3368.11	5119.07
3372.19	5078.11
3376.25	5040.78
3380.32	5011.8
3384.38	4993.61
3388.44	4986.9
3392.5	4996.29
3396.56	5018.96
3400.61	5046.91
3404.66	5080.77
3408.71	5105.77
3412.75	5091.68
3416.79	5041.85
3420.83	5013.44
3424.87	4956.62
3428.9	4891.36
3432.93	4876.43
3436.96	4877.08
3440.99	4867.94
3445.01	4847.27
3449.03	4813.4
3453.05	4797.19
3457.07	4808.91
3461.08	4851.18
3465.09	4892.94
3469.1	4946.64
3473.1	4955.19
3477.1	4931.92
3481.1	4882.68
3485.1	4817.4
3489.09	4785.5
3493.08	4812.56
3497.07	4819.07
3501.06	4821.86
3505.04	4803.8
3509.03	4788.81
3513	4775.06
3516.98	4761.15
3520.95	4782.55
3524.92	4776.35
3528.89	4740.99
3532.86	4706.97
3536.82	4692.69
3540.78	4676.49
3544.74	4640.26
3548.69	4628.96
3552.65	4638.42
3556.6	4645.93
3560.55	4621.69
3564.49	4585.54
3568.43	4542
3572.37	4506.06
3576.31	4487.66
3580.24	4487.64
3584.18	4520.77
3588.11	4555.25
3592.03	4590.22
3595.96	4627.14
3599.88	4670.16
3603.8	4725.73
3607.71	4797.8
3611.63	4888.46
3615.54	4990.21
3619.45	5093.31
3623.36	5187.75
3627.26	5188.09
3631.16	5141.01
3635.06	5069.6
3638.96	4989.14
3642.85	4936.41
3646.74	4892.61
3650.63	4852.84
3654.52	4821.81
3658.4	4764.47
3662.28	4666.62
3666.16	4559.68
3670.04	4487.64
3673.91	4414.83
3677.78	4359.63
3681.65	4337.41
3685.52	4308.09
3689.38	4276.25
3693.24	4216.35
3697.1	4176.55
3700.96	4174.69
3704.81	4189.95
3708.66	4195.38
3712.51	4178.02
3716.36	4196.46
3720.2	4204.86
3724.05	4210.89
3727.88	4208.34
3731.72	4226.92
3735.56	4256.07
3739.39	4278.03
3743.22	4325.8
3747.04	4291.93
3750.87	4154.71
3754.69	4069.82
3758.51	4051.71
3762.32	4128.1
3766.14	4199.78
3769.95	4218.31
3773.76	4150.13
3777.57	4088.92
3781.37	4045.05
3785.17	4048.02
3788.97	4084.56
3792.77	4112.2
3796.57	4146.15
3800.36	4168.62
3804.15	4155.37
3807.94	4098.09
3811.72	4000.78
3815.5	3922.26
3819.28	3883.22
3823.06	3862.24
3826.84	3906.94
3830.61	3979.56
3834.38	4022.21
3838.15	4024.16
3841.92	4005.62
3845.68	3971.72
3849.44	3924.32
3853.2	3882.13
3856.96	3854.92
3860.71	3841.89
3864.46	3846.21
3868.21	3875.92
3871.96	3844.26
3875.7	3809.96
3879.44	3879.13
3883.18	3929.56
3886.92	3955.43
3890.66	3948.31
3894.39	3850.85
3898.12	3839.71
3901.85	3870.32
3905.57	3892.25
3909.29	3904.96
3913.02	3906.23
3916.73	3866.07
3920.45	3817.9
3924.16	3711.44
3927.88	3631.03
3931.58	3613.85
3935.29	3660.07
3938.99	3715.17
3942.7	3776.8
3946.4	3786.14
3950.09	3767.81
3953.79	3699.33
3957.48	3678.44
3961.17	3668.47
3964.86	3661.08
3968.54	3647.87
3972.23	3620.7
3975.91	3563.58
3979.59	3516.43
3983.26	3462.62
3986.94	3409.16
3990.61	3414.6
3994.28	3471.94
3997.95	3567.68
3999.78	3598.06