File: Data/Raman/raw/quartz_150 (500nm)_532nm_Edge_50%_x50_VIS_LWD_H50um_20sX2.txt
#Acq. time (s)=	20
#Accumulations=	2
#Range (cm-¹)=	100...5300
#Windows=	1
#Auto scanning=	Off
#Autofocus=	Off
#Macrospot=	Off
#AutoExposure=	Off
#Spike filter=	Single accum. (Size=4)
#Delay time (s)=	0
#Binning=	1
#Readout mode=	Signal
#DeNoise=	Standard
#ICS correction=	On
#Dark correction=	Off
#Inst. Process=	On
#Detector Gain=	Best Dynamic
#Detector ADC=	50 kHz HS
#Detector temperature (°C)=	-60.09
#Instrument=	LabRAM HR Evol
#Detector=	SIN-EM FIVIS
#Objective=	x50_VIS_LWD
#Grating=	150 (500nm)
#ND Filter=	50%
#Laser=	532nm_Edge
#Hole=	49.98
#Temperature=	0
#Range=	Visible
#StageXY=	75x50mm Scan+
#StageZ=	Z motor
#X (µm)=	0
#Y (µm)=	0
#Z (µm)=	83.7
#Project=	20_05_11
#Sample=	BU19w
#Site=
#Title=	BU19w-area5_quartz_mid_150 (500nm)_532nm_Edge_50%_x50_VIS_LWD_H50um_20sX2
#Remark=
#Date=	11.05.2020 11:57
#Acquired=	11.05.2020 11:57:49
100.18	611.223
109.425	619.416
118.662	679.424
127.888	989.453
137.107	3181.7
146.315	1042.33
155.516	913.976
164.706	850.557
173.888	879.57
183.06	1019.6
192.225	1318.36
201.378	2103.54
210.525	3621.19
219.661	3776.15
228.789	2309.41
237.907	1496.15
247.015	1138.18
256.117	987.727
265.208	1011.62
274.29	1382.6
283.363	837.034
292.429	771.919
301.484	767.096
310.531	751.563
319.568	745.954
328.597	752.312
337.619	760.117
346.63	783.462
355.632	906.353
364.626	1497.94
373.61	830.192
382.586	776.358
391.553	809.242
400.512	1170.28
409.462	960.422
418.403	839.877
427.335	844.2
436.259	879.67
445.174	966.253
454.08	1287.14
462.978	2785.43
471.867	12589.2
480.747	5200.32
489.619	2099.76
498.482	1422.78
507.335	1180.58
516.181	1102.42
525.019	1085.6
533.848	1047.02
542.666	1007.08
551.478	976.958
560.282	954.703
569.077	939.831
577.861	930.323
586.639	930.215
595.407	934.211
604.168	938.405
612.92	942.031
621.663	943.551
630.398	942.726
639.124	940.974
647.843	938.644
656.552	936.161
665.254	933.642
673.946	937.266
682.632	941.928
691.307	950.761
699.976	1041.09
708.635	1050.15
717.285	991.684
725.93	980.697
734.563	978.282
743.189	978.241
751.809	980.967
760.418	982.867
769.019	988.048
777.612	996.055
786.198	1012.26
794.775	1035.76
803.343	1069.87
811.903	1304.69
820.455	1222.49
829.001	1077.64
837.536	1055.91
846.064	1047.7
854.584	1046.23
863.095	1046.72
871.598	1053.28
880.094	1051.55
888.581	1052.27
897.06	1063.45
905.531	1068.97
913.994	1068.96
922.45	1068.31
930.895	1068.59
939.334	1069.83
947.765	1071.08
956.188	1072.35
964.604	1073.2
973.011	1073.96
981.409	1074.47
989.8	1075.9
998.184	1079.72
1006.56	1083.15
1014.93	1086.12
1023.29	1088.88
1031.64	1092.02
1039.98	1092.92
1048.32	1098.22
1056.64	1107.98
1064.96	1122.42
1073.28	1137.03
1081.58	1145.86
1089.88	1147.33
1098.17	1142.03
1106.45	1135.41
1114.72	1125.12
1122.99	1128.17
1131.24	1136.42
1139.49	1142.51
1147.73	1147.22
1155.97	1189.05
1164.2	1351.78
1172.41	1315.86
1180.63	1179.07
1188.83	1152.74
1197.03	1147.42
1205.21	1151.98
1213.39	1159.57
1221.57	1174.6
1229.73	1191.1
1237.89	1202.11
1246.04	1205.68
1254.18	1199.34
1262.32	1191.79
1270.44	1184.5
1278.56	1178.39
1286.68	1174.18
1294.78	1174.39
1302.88	1174.73
1310.97	1175.81
1319.05	1177.43
1327.12	1177.92
1335.19	1175.66
1343.25	1179.35
1351.3	1183.75
1359.35	1189.25
1367.38	1191.67
1375.41	1192.26
1383.44	1194.64
1391.45	1196.95
1399.46	1199.27
1407.46	1201.96
1415.45	1205.4
1423.44	1209.19
1431.41	1212.27
1439.38	1216.18
1447.35	1220.47
1455.3	1223.72
1463.25	1224.48
1471.19	1223.31
1479.13	1222.42
1487.05	1222.73
1494.97	1224.57
1502.88	1225.76
1510.79	1228.05
1518.68	1229.12
1526.58	1231.55
1534.46	1236.42
1542.33	1242.22
1550.2	1248.47
1558.06	1255.92
1565.92	1251.69
1573.76	1247.8
1581.6	1249.85
1589.44	1253.33
1597.26	1256.27
1605.08	1258.64
1612.89	1260.73
1620.69	1263.29
1628.49	1265.36
1636.28	1266.32
1644.06	1265.9
1651.84	1266.23
1659.61	1266.25
1667.37	1265.07
1675.12	1262.61
1682.87	1259.03
1690.61	1255.63
1698.34	1254.35
1706.07	1254.43
1713.79	1255.78
1721.5	1258.31
1729.2	1262.3
1736.9	1267.56
1744.59	1272.87
1752.28	1277.64
1759.96	1280.4
1767.63	1281.74
1775.29	1282.66
1782.95	1282.93
1790.6	1284.25
1798.24	1285.75
1805.87	1286.43
1813.5	1286.51
1821.12	1285.88
1828.74	1284.73
1836.35	1283.29
1843.95	1281.61
1851.54	1279.99
1859.13	1279.27
1866.71	1279.58
1874.28	1281.48
1881.85	1283.89
1889.41	1286.38
1896.96	1288.08
1904.51	1289.18
1912.05	1289.46
1919.58	1289.89
1927.11	1291.02
1934.63	1291.84
1942.14	1293.07
1949.65	1293.28
1957.15	1290.15
1964.64	1286.22
1972.13	1283.12
1979.61	1281.75
1987.08	1282.16
1994.54	1283.27
2002	1285.76
2009.45	1287.07
2016.9	1286.41
2024.34	1284.54
2031.77	1282.81
2039.2	1281.6
2046.62	1281.69
2054.03	1282.28
2061.44	1283.42
2068.84	1284.62
2076.23	1285.56
2083.62	1286.07
2091	1288.5
2098.37	1288.65
2105.74	1286.88
2113.1	1283.05
2120.45	1280.61
2127.8	1280.41
2135.14	1282.06
2142.47	1282.87
2149.8	1282.52
2157.12	1281.57
2164.43	1280.43
2171.74	1279.98
2179.04	1280.77
2186.34	1283.48
2193.63	1286.09
2200.91	1287.41
2208.19	1286.55
2215.46	1284.13
2222.72	1280.96
2229.98	1279.32
2237.23	1280.75
2244.47	1283.31
2251.71	1284.74
2258.94	1283.94
2266.17	1282.47
2273.38	1281
2280.6	1279.76
2287.8	1278.76
2295	1278.33
2302.2	1278.9
2309.38	1278.61
2316.56	1274.82
2323.74	1268.68
2330.9	1262.07
2338.07	1255.63
2345.22	1250.88
2352.37	1250.94
2359.51	1254.68
2366.65	1256.69
2373.78	1258.29
2380.91	1259.8
2388.02	1260.87
2395.14	1260.97
2402.24	1259.82
2409.34	1256.99
2416.43	1254
2423.52	1252.03
2430.6	1251.55
2437.68	1252.24
2444.75	1252.73
2451.81	1252.98
2458.87	1252.15
2465.92	1249.67
2472.96	1246.53
2480	1242.94
2487.03	1236.38
2494.05	1229.96
2501.08	1226.26
2508.09	1223.89
2515.1	1222.26
2522.1	1222.18
2529.09	1225.85
2536.08	1229.29
2543.07	1230.9
2550.04	1231.51
2557.01	1231.2
2563.98	1230.93
2570.94	1230.47
2577.89	1230.03
2584.84	1229.15
2591.78	1227.61
2598.72	1225.72
2605.64	1223.21
2612.57	1219.81
2619.49	1216.43
2626.4	1212.01
2633.3	1208.77
2640.2	1205.53
2647.1	1202.19
2653.98	1198.31
2660.87	1196.39
2667.74	1195.03
2674.61	1193.71
2681.47	1192.24
2688.33	1190.84
2695.19	1189.47
2702.03	1189.54
2708.87	1189.62
2715.71	1189.99
2722.54	1189.9
2729.36	1189.18
2736.18	1187.47
2742.99	1184.82
2749.79	1182.72
2756.59	1180.88
2763.39	1179.35
2770.18	1178.17
2776.96	1177.14
2783.73	1175.68
2790.5	1173.89
2797.27	1170.54
2804.03	1167.19
2810.78	1165.19
2817.53	1164.2
2824.27	1163.73
2831.01	1163.67
2837.74	1163.4
2844.46	1162.8
2851.18	1161.7
2857.9	1160.31
2864.61	1158.07
2871.31	1154.3
2878	1149.98
2884.69	1146.18
2891.38	1142.68
2898.06	1139.78
2904.73	1137.35
2911.4	1136.17
2918.06	1135.99
2924.72	1135.98
2931.37	1136.2
2938.02	1134.66
2944.66	1131.64
2951.29	1127.61
2957.92	1122.85
2964.55	1117.65
2971.16	1115
2977.78	1114.03
2984.38	1116.53
2990.98	1116.66
2997.58	1114.38
3004.17	1110.23
3010.75	1105.25
3017.33	1099.28
3023.9	1092.81
3030.47	1087.76
3037.04	1084.48
3043.59	1082.96
3050.14	1082.52
3056.69	1082.29
3063.23	1081.1
3069.77	1079.77
3076.29	1077.73
3082.82	1074.62
3089.34	1070.78
3095.85	1066.78
3102.36	1062.97
3108.86	1058.66
3115.36	1053.9
3121.85	1052.52
3128.33	1049.97
3134.82	1046.45
3141.29	1044.26
3147.76	1043.34
3154.22	1042.09
3160.68	1041.54
3167.14	1039.98
3173.59	1038.39
3180.03	1034.29
3186.47	1029.89
3192.9	1025.19
3199.32	1021.68
3205.75	1019.37
3212.16	1017.01
3218.57	1015.17
3224.98	1013.3
3231.38	1010.85
3237.77	1008.26
3244.16	1005.78
3250.55	1003.49
3256.93	1001.92
3263.3	1001.8
3269.67	1001.18
3276.03	999.549
3282.39	997.489
3288.75	995.14
3295.09	992.258
3301.44	988.876
3307.77	985.856
3314.1	983.024
3320.43	979.727
3326.75	974.945
3333.07	970.195
3339.38	965.488
3345.69	961.568
3351.99	959.156
3358.28	960.551
3364.57	964.703
3370.86	967.415
3377.14	967.522
3383.41	964.803
3389.68	957.09
3395.95	952.064
3402.21	949.167
3408.46	944.391
3414.71	939.924
3420.95	936.502
3427.19	933.029
3433.43	929.534
3439.66	926.228
3445.88	922.355
3452.1	918.164
3458.31	914.72
3464.52	912.03
3470.72	908.956
3476.92	906.293
3483.12	904.836
3489.3	904.247
3495.49	904.046
3501.67	902.999
3507.84	901.449
3514.01	899.518
3520.17	897.222
3526.33	894.57
3532.48	890.453
3538.63	887.748
3544.77	885.586
3550.91	883.158
3557.05	881.056
3563.17	878.912
3569.3	876.276
3575.42	873.466
3581.53	870.131
3587.64	866.26
3593.74	862.745
3599.84	860.464
3605.93	858.886
3612.02	858.288
3618.1	857.149
3624.18	854.748
3630.26	851.171
3636.33	846.665
3642.39	841.839
3648.45	837.47
3654.5	834.816
3660.55	832.818
3666.6	830.337
3672.64	828.858
3678.67	827.676
3684.7	826.093
3690.73	824.574
3696.75	823.967
3702.76	824.38
3708.77	823.954
3714.78	821.72
3720.78	817.572
3726.78	811.542
3732.77	805.515
3738.76	800.102
3744.74	796.094
3750.71	793.366
3756.69	792.003
3762.65	791.404
3768.62	790.294
3774.57	788.87
3780.53	786.474
3786.48	784.002
3792.42	782.87
3798.36	781.041
3804.29	777.594
3810.22	773.268
3816.15	769.43
3822.07	768.283
3827.98	766.931
3833.89	765.529
3839.8	765
3845.7	765.359
3851.6	765.786
3857.49	765.317
3863.38	764.577
3869.26	757.716
3875.14	751.442
3881.01	746.872
3886.88	743.774
3892.74	746.899
3898.6	745.983
3904.46	743.372
3910.3	738.545
3916.15	734.112
3921.99	730.333
3927.83	727.7
3933.66	725.922
3939.48	724.241
3945.31	722.21
3951.12	720.099
3956.94	717.771
3962.75	715.499
3968.55	714.279
3974.35	713.381
3980.14	712.712
3985.93	711.947
3991.72	709.738
3997.5	706.62
4003.28	703.45
4009.05	700.39
4014.82	696.854
4020.58	695.395
4026.34	695.225
4032.09	696.121
4037.84	697.879
4043.58	700.189
4049.32	698.015
4055.06	693.373
4060.79	687.58
4066.52	682.693
4072.24	678.565
4077.96	674.14
4083.67	670.953
4089.38	669.113
4095.08	667.021
4100.78	665.528
4106.48	663.641
4112.17	663.972
4117.86	666.248
4123.54	665.535
4129.21	660.519
4134.89	654.421
4140.56	650.077
4146.22	647.878
4151.88	646.587
4157.54	645.933
4163.19	645.151
4168.83	644.821
4174.48	643.521
4180.11	639.29
4185.75	635.248
4191.38	631.685
4197	629.054
4202.62	627.283
4208.24	627.989
4213.85	626.923
4219.46	624.371
4225.06	624.263
4230.66	620.611
4236.25	616.244
4241.84	612.126
4247.43	608.974
4253.01	608.426
4258.59	606.911
4264.16	606.16
4269.73	606.251
4275.29	605.377
4280.85	602.168
4286.41	598.473
4291.96	596.51
4297.5	595.64
4303.05	594.523
4308.58	592.889
4314.12	590.795
4319.65	588.066
4325.17	584.124
4330.69	579.134
4336.21	575.244
4341.72	572.327
4347.23	570.475
4352.74	569.397
4358.24	568.809
4363.73	568.573
4369.22	568.061
4374.71	564.965
4380.19	560.285
4385.67	556.757
4391.15	553.476
4396.62	550.316
4402.08	547.371
4407.55	544.836
4413	542.657
4418.46	541.269
4423.91	540.138
4429.35	539.512
4434.8	538.935
4440.23	537.697
4445.67	535.754
4451.09	533.448
4456.52	531.468
4461.94	529.135
4467.36	526.4
4472.77	524.209
4478.18	522.745
4483.58	521.149
4488.98	519.034
4494.38	515.908
4499.77	513.672
4505.16	511.598
4510.54	509.84
4515.92	507.75
4521.29	505.532
4526.66	503.39
4532.03	501.393
4537.39	499.264
4542.75	497.116
4548.11	494.834
4553.46	493.093
4558.81	490.873
4564.15	488.339
4569.49	486.266
4574.82	484.649
4580.15	483.779
4585.48	483.772
4590.8	481.51
4596.12	477.95
4601.44	474.294
4606.75	469.975
4612.05	465.297
4617.35	462.113
4622.65	460.233
4627.95	458.963
4633.24	458.548
4638.52	459.262
4643.81	459.961
4649.08	459.046
4654.36	457.265
4659.63	454.852
4664.9	452.717
4670.16	451.41
4675.42	450.954
4680.67	451.011
4685.92	451.202
4691.17	450.962
4696.41	448.201
4701.65	444.795
4706.89	441.951
4712.12	439.446
4717.35	437.339
4722.57	436.488
4727.79	435.754
4733	434.466
4738.22	432.762
4743.42	430.742
4748.63	428.74
4753.83	426.833
4759.02	425.235
4764.22	423.812
4769.4	422.896
4774.59	422.192
4779.77	421.434
4784.94	419.176
4790.12	415.735
4795.29	412.832
4800.45	410.695
4805.61	408.541
4810.77	406.316
4815.92	404.337
4821.07	403.005
4826.22	402.366
4831.36	401.953
4836.5	401.197
4841.63	400.065
4846.76	399.307
4851.89	398.112
4857.01	394.846
4862.13	391.405
4867.25	388.185
4872.36	385.553
4877.47	383.549
4882.57	381.962
4887.67	381.053
4892.77	380.754
4897.86	380.093
4902.95	379.021
4908.03	377.393
4913.12	375.028
4918.19	372.458
4923.27	370.304
4928.34	368.948
4933.4	367.657
4938.47	366.699
4943.53	365.475
4948.58	363.976
4953.63	362.637
4958.68	361.859
4963.72	361.151
4968.76	359.035
4973.8	356.811
4978.83	354.281
4983.86	351.7
4988.89	349.64
4993.91	347.304
4998.93	345.354
5003.94	345.34
5008.95	345.58
5013.96	345.418
5018.96	344.7
5023.96	343.275
5028.96	340.889
5033.95	338.097
5038.94	336.171
5043.93	334.82
5048.91	334.007
5053.88	333.678
5058.86	333.49
5063.83	332.833
5068.8	330.321
5073.76	327.7
5078.72	324.323
5083.67	320.694
5088.63	318.02
5093.58	316.878
5098.52	316.046
5103.46	315.444
5108.4	315.537
5113.33	316.172
5118.27	316.859
5123.19	316.936
5128.12	315.783
5133.04	314.277
5137.95	312.704
5142.87	311.057
5147.77	309.204
5152.68	307.511
5157.58	305.743
5162.48	303.758
5167.38	302.008
5172.27	301.152
5177.16	300.621
5182.04	300.256
5186.92	299.643
5191.8	298.319
5196.67	296.629
5201.54	294.888
5206.41	292.65
5211.27	290.917
5216.13	290.008
5220.99	288.659
5225.84	286.451
5230.69	284.367
5235.53	282.501
5240.38	281.111
5245.21	280.052
5250.05	279.63
5254.88	279.845
5259.71	280.218
5264.53	280.463
5269.36	279.838
5274.17	278.636
5278.99	277.286
5283.8	275.999
5288.61	273.745
5293.41	272.603
5298.21	257.151