File: Data/Raman/raw/samuelsonite_150 (500nm)_633nm_Edge_100%_x50_VIS_LWD_H100um_15sX2.txt
#Acq. time (s)=	15
#Accumulations=	2
#Range (cm-¹)=	100...4000
#Windows=	1
#Auto scanning=	Off
#Autofocus=	Off
#Macrospot=	Off
#AutoExposure=	Off
#Spike filter=	Single accum. (Size=4)
#Delay time (s)=	0
#Binning=	1
#Readout mode=	Signal
#DeNoise=	Standard
#ICS correction=	On
#Dark correction=	Off
#Inst. Process=	On
#Detector Gain=	Best Dynamic
#Detector ADC=	50 kHz HS
#Detector temperature (°C)=	-60.09
#Instrument=	LabRAM HR Evol
#Detector=	SIN-EM FIVIS
#Objective=	x50_VIS_LWD
#Grating=	150 (500nm)
#ND Filter=	100%
#Laser=	633nm_Edge
#Hole=	100.021
#Temperature=	0
#Range=	Visible
#StageXY=	75x50mm Scan+
#StageZ=	Z motor
#X (µm)=	0
#Y (µm)=	0
#Z (µm)=	-23.9
#Project=	20_05_11
#Sample=	BU19TS
#Site=
#Title=	BU19TS-area5-samuelsonite_150 (500nm)_633nm_Edge_100%_x50_VIS_LWD_H100um_15sX2
#Remark=
#Date=	11.05.2020 19:35
#Acquired=	11.05.2020 19:35:43
100.862	10346.7
107.378	10327.5
113.889	10216.8
120.394	10105.2
126.894	10027.9
133.388	9977.13
139.878	9950.16
146.361	9939.73
152.84	9937.16
159.313	9949.98
165.78	9955.77
172.242	9950.43
178.699	9937.1
185.149	9916.78
191.596	9899.57
198.037	9904.24
204.472	9938.93
210.903	9990.3
217.326	10045.8
223.746	10100.4
230.16	10126
236.568	10084.9
242.972	10022
249.371	9967.35
255.762	9903.3
262.151	9895.23
268.533	9899.16
274.91	9909.69
281.282	9916.62
287.648	9910.93
294.01	9884.87
300.365	9844.15
306.716	9794.41
313.061	9751.06
319.401	9718.09
325.737	9693.26
332.066	9674.31
338.392	9667.77
344.711	9643.79
351.024	9604.29
357.335	9561.9
363.638	9508.5
369.936	9465.08
376.23	9437.42
382.519	9426.34
388.802	9439.77
395.08	9501.74
401.353	9632.4
407.62	9831.88
413.884	10067.2
420.141	10126
426.394	9995.55
432.641	9910.79
438.883	9856.41
445.12	9821.39
451.352	9789
457.579	9752.73
463.801	9713.64
470.018	9672.13
476.23	9621.64
482.437	9589.68
488.638	9589.9
494.834	9565.06
501.026	9486.27
507.212	9395.67
513.394	9319.57
519.571	9268.03
525.743	9243.24
531.908	9231.88
538.07	9239.49
544.227	9256.63
550.377	9310.3
556.524	9376.77
562.666	9465.48
568.801	9502.95
574.933	9480.8
581.061	9468.72
587.181	9453.56
593.299	9434.97
599.41	9420.83
605.517	9412.83
611.618	9405
617.716	9391.59
623.807	9396.13
629.895	9402.4
635.977	9420.2
642.053	9414.09
648.127	9346.21
654.193	9228.67
660.256	9130.17
666.314	9077.67
672.367	9059.87
678.414	9074.89
684.457	9087.46
690.496	9099.8
696.529	9108.35
702.558	9109.91
708.581	9098.79
714.6	9084.19
720.614	9069.97
726.624	9061.23
732.628	9061.75
738.628	9069.93
744.623	9083.11
750.613	9098.38
756.598	9130.93
762.578	9165.03
768.554	9193.02
774.525	9225.52
780.49	9255.34
786.451	9259.9
792.408	9266.07
798.36	9281.41
804.307	9318.5
810.25	9362.19
816.186	9414.74
822.119	9480.01
828.048	9553.6
833.972	9627.73
839.889	9693.55
845.804	9740.34
851.714	9768.04
857.617	9779.61
863.518	9770.86
869.413	9753.59
875.303	9732.39
881.19	9696.2
887.07	9718.7
892.947	9714.79
898.818	9837.93
904.686	10036.9
910.548	10515.3
916.406	11214.7
922.26	11541.8
928.108	10841.8
933.953	10285.7
939.792	10245
945.626	10490.5
951.457	11405.6
957.282	13803.5
963.103	14493
968.919	12118.9
974.731	11181
980.539	11191.2
986.341	11456.4
992.139	11672.9
997.932	11643
1003.72	11247.9
1009.51	11058.6
1015.29	10973.5
1021.06	10942.1
1026.83	10925.1
1032.6	10914.4
1038.36	10924.4
1044.12	10940.3
1049.87	10954.4
1055.62	10947.4
1061.36	10942.5
1067.1	10939.8
1072.84	10944.6
1078.56	10934.3
1084.29	10917.2
1090.01	10897.9
1095.73	10897.9
1101.44	10918.8
1107.15	10959.7
1112.85	11009.2
1118.55	11049.5
1124.24	11072
1129.94	11089.8
1135.62	11104.1
1141.3	11126.3
1146.98	11158.4
1152.65	11189.2
1158.32	11214.9
1163.98	11237.2
1169.64	11255
1175.3	11275.7
1180.95	11314.8
1186.59	11354.4
1192.23	11399.4
1197.87	11449.6
1203.5	11503.7
1209.13	11557.4
1214.75	11610.2
1220.37	11665.6
1225.99	11717.2
1231.6	11762
1237.21	11796.7
1242.81	11808.2
1248.41	11819.1
1254	11814.7
1259.59	11809.2
1265.17	11812.4
1270.75	11838
1276.33	11881.2
1281.9	11931
1287.47	11990.9
1293.03	12054.5
1298.59	12121.2
1304.15	12188.4
1309.7	12253.2
1315.24	12309
1320.78	12361.5
1326.32	12411.3
1331.85	12457.5
1337.38	12495.5
1342.91	12520.2
1348.43	12545.6
1353.95	12574.9
1359.46	12609.5
1364.97	12648.7
1370.47	12696.9
1375.97	12750.5
1381.46	12801.1
1386.96	12846.1
1392.44	12888.3
1397.92	12930.4
1403.4	12975.5
1408.88	13022.5
1414.35	13072.4
1419.81	13121.9
1425.27	13169.7
1430.73	13219.1
1436.18	13268.2
1441.63	13319.4
1447.08	13374.8
1452.52	13430.5
1457.96	13482.6
1463.39	13529.8
1468.82	13574.1
1474.24	13619.5
1479.66	13671.8
1485.08	13727.2
1490.49	13786.9
1495.9	13856.6
1501.3	13927.2
1506.7	13992.9
1512.09	14053.8
1517.49	14117.6
1522.87	14186.2
1528.26	14255.6
1533.63	14321
1539.01	14371.8
1544.38	14409.8
1549.75	14442.5
1555.11	14481.9
1560.47	14528.8
1565.82	14582.2
1571.17	14643.1
1576.52	14712.8
1581.86	14792.8
1587.2	14882.9
1592.54	14968.7
1597.86	15065.3
1603.19	15164
1608.51	15264.8
1613.83	15358.3
1619.15	15426.3
1624.46	15470.1
1629.76	15515.5
1635.06	15561.8
1640.36	15606.9
1645.66	15652.1
1650.95	15699.3
1656.23	15749.3
1661.52	15800.6
1666.79	15850.3
1672.07	15899.6
1677.34	15949.2
1682.6	15999.8
1687.87	16056.5
1693.13	16125.9
1698.38	16206.2
1703.63	16294.3
1708.88	16383.6
1714.12	16463.8
1719.36	16543.2
1724.59	16629.4
1729.82	16693.1
1735.05	16746.6
1740.27	16801.6
1745.49	16856.2
1750.71	16905.4
1755.92	16946.6
1761.13	16983.5
1766.33	17026.2
1771.53	17082.4
1776.73	17152.3
1781.92	17232.7
1787.11	17321
1792.29	17415.5
1797.47	17513.1
1802.65	17606.7
1807.82	17688.8
1812.99	17756.1
1818.15	17812.6
1823.32	17864.4
1828.47	17918.2
1833.63	17965.8
1838.78	18015.2
1843.92	18062.7
1849.06	18109.2
1854.2	18158.6
1859.34	18215.1
1864.47	18276.4
1869.59	18343.2
1874.72	18415.6
1879.84	18489.8
1884.95	18559.1
1890.06	18629.6
1895.17	18701
1900.27	18769.4
1905.37	18838.3
1910.47	18909.3
1915.56	18982.6
1920.65	19054
1925.74	19112.5
1930.82	19164.2
1935.9	19209.8
1940.97	19254.8
1946.04	19292.7
1951.11	19318.5
1956.17	19344.5
1961.23	19381.7
1966.28	19429.1
1971.33	19484.7
1976.38	19545.1
1981.43	19613.1
1986.47	19686
1991.5	19744.7
1996.54	19818.2
2001.57	19869.4
2006.59	19932.1
2011.61	20001.7
2016.63	20070.3
2021.65	20144.2
2026.66	20219.2
2031.66	20281.5
2036.67	20313.9
2041.67	20358.6
2046.66	20423.2
2051.66	20474.3
2056.65	20525.7
2061.63	20580.2
2066.61	20636.9
2071.59	20694.4
2076.56	20746.3
2081.53	20791.8
2086.5	20831.8
2091.46	20847.7
2096.42	20877.2
2101.38	20944.1
2106.33	20998.2
2111.28	21043.6
2116.23	21084.4
2121.17	21109.3
2126.11	21133.6
2131.04	21157.8
2135.97	21180.3
2140.9	21202.7
2145.82	21227.3
2150.74	21258.1
2155.66	21290.7
2160.57	21323.9
2165.48	21354.7
2170.39	21388.4
2175.29	21426.3
2180.19	21484.2
2185.09	21519.5
2189.98	21547.9
2194.86	21575.4
2199.75	21605.8
2204.63	21637.9
2209.51	21680
2214.38	21727.6
2219.25	21766.5
2224.12	21790.8
2228.98	21803.3
2233.84	21815.2
2238.7	21821.1
2243.55	21832
2248.4	21848.8
2253.25	21863.5
2258.09	21874.9
2262.93	21886.6
2267.76	21892.6
2272.6	21896
2277.43	21898.2
2282.25	21901.7
2287.07	21904.2
2291.89	21938.6
2296.7	21955.2
2301.52	21974.4
2306.32	22010.2
2311.13	22053.1
2315.93	22116
2320.73	22132.6
2325.52	22119.7
2330.31	22142
2335.1	22168.4
2339.88	22195.5
2344.66	22226.1
2349.44	22253.1
2354.21	22259.1
2358.98	22244.2
2363.75	22219.8
2368.51	22205
2373.27	22192.7
2378.03	22179.6
2382.78	22164.5
2387.53	22147.3
2392.28	22128.4
2397.02	22109.7
2401.76	22099.8
2406.49	22101.8
2411.23	22110.4
2415.95	22128.2
2420.68	22151.5
2425.4	22174.1
2430.12	22193.1
2434.84	22209.7
2439.55	22228.2
2444.26	22246.3
2448.96	22251.1
2453.67	22242.4
2458.37	22229.2
2463.06	22213
2467.75	22192.2
2472.44	22164.2
2477.13	22126.8
2481.81	22092.8
2486.49	22068.1
2491.17	22051.5
2495.84	22040.9
2500.51	22033.7
2505.17	22030.8
2509.84	22028.7
2514.5	22021.9
2519.15	22007.2
2523.8	21983.7
2528.45	21955.3
2533.1	21928.4
2537.74	21903.1
2542.38	21873.3
2547.02	21848.8
2551.65	21831.8
2556.28	21818.7
2560.91	21804.9
2565.53	21790.8
2570.15	21765.8
2574.77	21731.2
2579.38	21701.2
2583.99	21667.3
2588.6	21626.9
2593.2	21589.2
2597.8	21560.3
2602.4	21521.2
2606.99	21485
2611.58	21456.8
2616.17	21438.7
2620.75	21409.3
2625.33	21400.6
2629.91	21393.9
2634.49	21385
2639.06	21357.3
2643.63	21300.9
2648.19	21246.7
2652.75	21189
2657.31	21133.5
2661.87	21086.6
2666.42	21037.8
2670.97	21036.7
2675.51	21050.8
2680.06	21047.6
2684.6	21037.4
2689.13	21018.5
2693.67	20974.4
2698.2	20913.3
2702.72	20848.2
2707.25	20790.3
2711.77	20742.4
2716.28	20699.4
2720.8	20657.4
2725.31	20611.4
2729.82	20528.8
2734.32	20461.7
2738.83	20441.3
2743.32	20423.2
2747.82	20409.8
2752.31	20401.5
2756.8	20397.9
2761.29	20387.7
2765.77	20362.7
2770.25	20328.5
2774.73	20292.8
2779.2	20253
2783.67	20214.1
2788.14	20181.4
2792.6	20156.2
2797.06	20138.3
2801.52	20116.4
2805.98	20088
2810.43	20047.4
2814.88	20008.7
2819.32	19974
2823.77	19936.3
2828.2	19904.6
2832.64	19881.2
2837.08	19867.6
2841.51	19858.7
2845.93	19846
2850.36	19832.8
2854.78	19824.3
2859.2	19816.6
2863.61	19803.9
2868.02	19788.3
2872.43	19773.1
2876.84	19761.8
2881.24	19756.7
2885.64	19751.7
2890.04	19735.2
2894.43	19708.6
2898.82	19670.9
2903.21	19628.4
2907.6	19580.6
2911.98	19531.6
2916.36	19488.5
2920.74	19458.3
2925.11	19438.7
2929.48	19425.9
2933.84	19411.7
2938.21	19388
2942.57	19352.6
2946.93	19308.1
2951.28	19260.3
2955.64	19197
2959.98	19179.8
2964.33	19164.4
2968.67	19144.9
2973.01	19102.7
2977.35	19037
2981.68	18981.2
2986.02	18939.7
2990.34	18891.4
2994.67	18817
2998.99	18785.7
3003.31	18783.9
3007.63	18775.4
3011.94	18748.9
3016.25	18710.4
3020.56	18669.5
3024.86	18621.8
3029.17	18567.2
3033.47	18512.4
3037.76	18459.8
3042.05	18412.6
3046.34	18375.9
3050.63	18340.2
3054.92	18326.7
3059.2	18332.2
3063.48	18354.8
3067.75	18377.8
3072.02	18385.6
3076.29	18358.6
3080.56	18319.3
3084.82	18269.5
3089.09	18216.5
3093.34	18169.1
3097.6	18128.3
3101.85	18096.8
3106.1	18074.2
3110.35	18052.8
3114.59	18023.7
3118.83	17987.3
3123.07	17953.4
3127.31	17920.4
3131.54	17899.3
3135.77	17877.6
3140	17844.8
3144.22	17802.3
3148.44	17757.1
3152.66	17714.3
3156.87	17680.8
3161.09	17654.1
3165.29	17631.8
3169.5	17609.8
3173.71	17581.6
3177.91	17539.9
3182.11	17492
3186.3	17440.6
3190.49	17390.5
3194.68	17353.4
3198.87	17329.8
3203.05	17319.6
3207.24	17322.6
3211.41	17336.3
3215.59	17356.8
3219.76	17355.5
3223.93	17333.4
3228.1	17314.6
3232.27	17290.5
3236.43	17265.3
3240.59	17240.5
3244.74	17212.4
3248.9	17181.9
3253.05	17148.5
3257.2	17096.1
3261.34	17048.8
3265.48	17020.8
3269.62	16995.8
3273.76	16968.9
3277.89	16937.2
3282.02	16897.2
3286.15	16850.8
3290.28	16800.1
3294.4	16756.9
3298.52	16729.1
3302.64	16711.9
3306.75	16699.6
3310.87	16690
3314.98	16681.3
3319.08	16659.8
3323.19	16620.6
3327.29	16584.1
3331.39	16555.5
3335.48	16519.5
3339.58	16476.5
3343.67	16425.4
3347.75	16376.9
3351.84	16337.4
3355.92	16307.4
3360	16280.7
3364.08	16257.1
3368.15	16234.9
3372.22	16209.8
3376.29	16196.3
3380.36	16181.1
3384.42	16155
3388.48	16129.7
3392.54	16112.8
3396.59	16078.3
3400.65	16057.7
3404.7	16048.3
3408.74	16032.9
3412.79	16017.3
3416.83	15993.1
3420.87	15965.3
3424.91	15941.8
3428.94	15923.8
3432.97	15906.1
3437	15881.7
3441.02	15862.3
3445.05	15848
3449.07	15836.2
3453.09	15821.1
3457.1	15799.5
3461.11	15772.7
3465.13	15741.8
3469.13	15719.4
3473.14	15699.1
3477.14	15670.9
3481.14	15649.7
3485.14	15634.3
3489.13	15618.4
3493.12	15600.9
3497.11	15584.5
3501.1	15566.6
3505.08	15536.4
3509.06	15485.7
3513.04	15431.4
3517.02	15373.8
3520.99	15321.1
3524.96	15280.9
3528.93	15264.2
3532.89	15240.1
3536.86	15225.7
3540.82	15213
3544.78	15190.8
3548.73	15157.4
3552.68	15117.4
3556.63	15091.3
3560.58	15071.3
3564.53	15048.2
3568.47	15020.3
3572.41	14977.7
3576.34	14926.5
3580.28	14905.9
3584.21	14895.4
3588.14	14877
3592.07	14868.6
3595.99	14845.8
3599.91	14823.7
3603.83	14788.7
3607.75	14741.2
3611.66	14693.7
3615.58	14643.8
3619.49	14594
3623.39	14556.6
3627.3	14529.1
3631.2	14513.7
3635.1	14499.8
3638.99	14485.1
3642.89	14471.2
3646.78	14452.4
3650.67	14423
3654.55	14390.4
3658.44	14357.9
3662.32	14325.3
3666.2	14288.7
3670.07	14253.5
3673.95	14222.1
3677.82	14191.1
3681.69	14160.2
3685.55	14135.5
3689.42	14117
3693.28	14103.5
3697.14	14092
3700.99	14084.7
3704.85	14056.8
3708.7	14026.3
3712.55	14002.5
3716.39	13983.6
3720.24	13966.1
3724.08	13941.9
3727.92	13905.7
3731.76	13871.9
3735.59	13834.9
3739.42	13787.4
3743.25	13766.1
3747.08	13772.5
3750.9	13758.6
3754.72	13725.4
3758.54	13645.1
3762.36	13625.3
3766.17	13638.5
3769.99	13640.5
3773.79	13623.8
3777.6	13577
3781.41	13528.6
3785.21	13482.6
3789.01	13439.8
3792.81	13407.2
3796.6	13386.6
3800.39	13374.6
3804.18	13366.5
3807.97	13342.1
3811.76	13312.8
3815.54	13283.5
3819.32	13254.1
3823.1	13245.7
3826.87	13220.2
3830.65	13180
3834.42	13141.7
3838.18	13120.7
3841.95	13088.3
3845.71	13051.1
3849.48	13008.4
3853.23	12961.3
3856.99	12909
3860.74	12868.2
3864.5	12846.8
3868.24	12835.2
3871.99	12821.6
3875.74	12800.2
3879.48	12775.2
3883.22	12748.9
3886.95	12721.4
3890.69	12688.3
3894.42	12653
3898.15	12621.5
3901.88	12594.8
3905.61	12571.8
3909.33	12546.9
3913.05	12525
3916.77	12503.4
3920.48	12473.6
3924.2	12425.7
3927.91	12366.1
3931.62	12303.6
3935.32	12249.2
3939.03	12203.3
3942.73	12165.8
3946.43	12138.2
3950.13	12115.3
3953.82	12091.4
3957.51	12056.4
3961.2	12003
3964.89	11969
3968.58	11933.5
3972.26	11899.4
3975.94	11863.9
3979.62	11829.2
3983.3	11798.3
3986.97	11754.9
3990.64	11712.9
3994.31	11672.4
3997.98	11629.3
3999.81	11607.8