File: Data/Raman/raw/tourmaline-core_150 (500nm)_633nm_edge_100%_x50_vis_lwd_h30um_30sx2_01.txt
#Acq. time (s)=	30
#Accumulations=	2
#Range (cm-¹)=	100...4000
#Windows=	1
#Auto scanning=	Off
#Autofocus=	Off
#Macrospot=	Off
#AutoExposure=	Off
#Spike filter=	Multiple accum.
#Delay time (s)=	2
#Binning=	1
#Readout mode=	Signal
#DeNoise=	Standard
#ICS correction=	On
#Dark correction=	Off
#Inst. Process=	Off
#Detector Gain=	Best Dynamic
#Detector ADC=	50 kHz HS
#Detector temperature (°C)=	-60.09
#Instrument=	LabRAM HR Evol
#Detector=	SIN-EM FIVIS
#Objective=	x50_VIS_LWD
#Grating=	150 (500nm)
#ND Filter=	100%
#Laser=	633nm_Edge
#Hole=	30.0125
#Temperature=	0
#Range=	Visible
#StageXY=	75x50mm Scan+
#StageZ=	Z motor
#X (µm)=	0
#Y (µm)=	0
#Z (µm)=	59.3
#Full time(mm:ss)=	1:06
#Project=	20_10_27
#Sample=	BU24
#Site=
#Title=	BU24-Turm1-core_150 (500nm)_633nm_Edge_100%_x50_VIS_LWD_H30um_30sX2
#Remark=
#Date=	27.10.2020 18:23
#Acquired=	27.10.2020 18:23:04
100.764	3032.83
107.281	3054.51
113.791	3041.91
120.297	3040.79
126.797	3075.41
133.291	3127.12
139.78	3155.79
146.264	3146.77
152.741	3124.92
159.214	3085.34
165.682	3110.78
172.144	3073.25
178.601	3000.73
185.053	2863.56
191.499	2680.23
197.939	2588.37
204.374	2530.31
210.805	2485.45
217.23	2440.18
223.648	2391.57
230.063	2323.97
236.472	2250.71
242.874	2179.77
249.273	2112.89
255.667	2057.33
262.053	2028.55
268.436	2008.66
274.813	1995.22
281.185	1988.64
287.552	1989.26
293.913	1995.48
300.27	2003.11
306.62	2011.57
312.965	2021.82
319.306	2032.95
325.64	2043.38
331.971	2052.78
338.295	2059.53
344.614	2065.93
350.93	2075.2
357.238	2089.7
363.542	2193.25
369.842	2212.4
376.135	2160.51
382.423	2069.6
388.706	2020.48
394.984	1984.7
401.258	1961.58
407.526	1954.73
413.789	1933.27
420.046	1908.34
426.299	1877.69
432.546	1845.46
438.788	1820.88
445.025	1803.72
451.257	1801.29
457.484	1805.47
463.706	1815
469.923	1827.04
476.135	1839.79
482.342	1853.98
488.544	1871.28
494.741	1892.42
500.933	1916.7
507.12	1942.31
513.3	1966.94
519.477	1987.9
525.649	2005.62
531.815	2017.01
537.976	2022.55
544.133	2013.59
550.285	1992.67
556.43	1962.2
562.572	1925.71
568.709	1891.78
574.84	1858.61
580.967	1828.82
587.09	1806.66
593.205	1791.09
599.318	1780.01
605.424	1761.19
611.527	1729.82
617.623	1708.81
623.716	1730.09
629.802	1720.4
635.884	1708.35
641.962	1699.88
648.034	1683.18
654.101	1669.07
660.165	1644.76
666.222	1621.9
672.274	1609.82
678.324	1598.24
684.366	1588.33
690.404	1589.97
696.438	1609.97
702.466	1643.97
708.491	1642.04
714.51	1613.55
720.523	1561.79
726.533	1516.98
732.537	1489.85
738.537	1471.59
744.531	1461.86
750.521	1456.54
756.507	1452.4
762.487	1449.33
768.463	1443.1
774.434	1431.07
780.4	1418.51
786.362	1406.52
792.319	1395.33
798.269	1385.11
804.217	1375.6
810.159	1367.79
816.097	1360.07
822.03	1354.14
827.958	1348.55
833.881	1346.06
839.801	1344.81
845.714	1340.71
851.624	1334.78
857.529	1327.52
863.428	1319.41
869.324	1310.61
875.215	1301.56
881.1	1294.36
886.982	1289.31
892.858	1286.71
898.73	1283.68
904.597	1281.65
910.459	1280.26
916.318	1278.75
922.171	1278.43
928.02	1280.16
933.864	1284.51
939.703	1288.79
945.539	1292.08
951.368	1294.64
957.194	1296.32
963.014	1297.11
968.832	1297.47
974.643	1298.23
980.45	1299.13
986.253	1300.09
992.051	1301.28
997.844	1302.93
1003.63	1305.21
1009.42	1308.23
1015.2	1309.22
1020.97	1306.3
1026.74	1304.17
1032.51	1304.37
1038.27	1304.8
1044.03	1303.52
1049.78	1303.62
1055.53	1295.44
1061.27	1281.85
1067.01	1264.71
1072.75	1243.73
1078.48	1227.81
1084.2	1217.63
1089.92	1213.47
1095.64	1214.28
1101.35	1211.27
1107.06	1209.38
1112.77	1203.13
1118.46	1193.88
1124.16	1181.66
1129.85	1167.17
1135.53	1152.16
1141.22	1139.62
1146.89	1129.93
1152.56	1123.18
1158.23	1117.57
1163.9	1111.57
1169.56	1104.64
1175.21	1099.31
1180.86	1095.62
1186.51	1092.92
1192.15	1090.86
1197.78	1085.83
1203.42	1083.7
1209.04	1084.63
1214.67	1085.63
1220.29	1087.94
1225.9	1086.51
1231.51	1081.75
1237.12	1073.5
1242.72	1062.63
1248.32	1057.15
1253.92	1055.03
1259.5	1055.51
1265.09	1058.42
1270.67	1061.95
1276.25	1064.84
1281.82	1064.94
1287.39	1060.06
1292.95	1056.42
1298.51	1053.7
1304.06	1052.72
1309.61	1051.45
1315.16	1047.8
1320.7	1042.25
1326.24	1031.64
1331.77	1025.09
1337.3	1022.76
1342.83	1019.44
1348.35	1015.93
1353.86	1012.02
1359.37	1006.66
1364.88	999.272
1370.39	990.275
1375.89	982.462
1381.38	976.854
1386.87	972.401
1392.36	967.417
1397.84	961.488
1403.32	954.043
1408.79	947.59
1414.26	941.096
1419.73	934.411
1425.19	926.917
1430.65	919.176
1436.1	912.013
1441.55	906.34
1447	901.902
1452.44	899.91
1457.87	902.036
1463.31	900.599
1468.73	896.965
1474.16	892.597
1479.58	888.727
1484.99	885.921
1490.41	884.145
1495.81	883.641
1501.22	882.224
1506.62	878.985
1512.01	872.949
1517.4	867.957
1522.79	865.222
1528.17	865.423
1533.55	863.012
1538.93	860.763
1544.3	856.62
1549.67	850.608
1555.03	842.45
1560.39	835.165
1565.74	829.979
1571.09	827.216
1576.44	827.708
1581.78	830.605
1587.12	831.167
1592.45	829.325
1597.78	825.44
1603.11	820.233
1608.43	814.423
1613.75	809.058
1619.07	804.495
1624.38	801.221
1629.68	800.354
1634.98	798.975
1640.28	796.652
1645.58	793.55
1650.87	789.915
1656.15	785.894
1661.44	781.631
1666.71	777.218
1671.99	772.499
1677.26	767.745
1682.53	763.21
1687.79	759.686
1693.05	756.766
1698.3	754.317
1703.55	751.103
1708.8	747.853
1714.04	745.779
1719.28	744.591
1724.51	743.677
1729.75	741.682
1734.97	739.326
1740.2	739.169
1745.42	736.307
1750.63	731.966
1755.84	729.115
1761.05	726.629
1766.25	723.7
1771.45	719.485
1776.65	714.587
1781.84	708.863
1787.03	706.684
1792.21	705.546
1797.39	704.541
1802.57	703.508
1807.74	702.309
1812.91	700.199
1818.08	696.708
1823.24	693.406
1828.39	689.452
1833.55	686.886
1838.7	686.089
1843.84	683.648
1848.99	682.161
1854.12	680.971
1859.26	678.522
1864.39	674.324
1869.52	669.503
1874.64	665.531
1879.76	662.505
1884.87	659.626
1889.98	656.134
1895.09	653.717
1900.2	653.733
1905.3	653.954
1910.39	653.366
1915.49	652.84
1920.57	652.022
1925.66	650.251
1930.74	646.242
1935.82	639.513
1940.89	631.764
1945.96	625.829
1951.03	622.164
1956.09	620.42
1961.15	612.806
1966.21	617.179
1971.26	615.962
1976.31	614.849
1981.35	613.869
1986.39	608.78
1991.43	606.265
1996.46	604.149
2001.49	602.227
2006.52	599.541
2011.54	596.477
2016.56	593.322
2021.57	590.688
2026.58	589.314
2031.59	588.159
2036.59	586.97
2041.59	585.189
2046.59	582.805
2051.58	580.095
2056.57	576.763
2061.55	573.718
2066.54	570.977
2071.51	569.896
2076.49	568.644
2081.46	566.873
2086.43	564.537
2091.39	561.848
2096.35	558.838
2101.3	555.568
2106.26	551.8
2111.21	547.683
2116.15	546.473
2121.09	546.311
2126.03	545.72
2130.97	543.551
2135.9	539.725
2140.83	535.238
2145.75	530.884
2150.67	526.347
2155.59	521.867
2160.5	520.553
2165.41	521.205
2170.31	523.051
2175.22	525.993
2180.12	530.022
2185.01	532.032
2189.9	530.093
2194.79	527.011
2199.68	522.915
2204.56	514.613
2209.43	508.828
2214.31	501.598
2219.18	496.26
2224.05	499.353
2228.91	501.084
2233.77	500.763
2238.63	498.639
2243.48	494.867
2248.33	491.06
2253.17	492.258
2258.02	493.275
2262.86	493.321
2267.69	492.469
2272.52	491.004
2277.35	488.937
2282.18	486.552
2287	484.376
2291.82	482.925
2296.63	483.009
2301.44	482.173
2306.25	478.692
2311.05	475.281
2315.86	473.743
2320.65	472.393
2325.45	470.882
2330.24	468.733
2335.03	466.52
2339.81	465.092
2344.59	463.79
2349.37	460.806
2354.14	456.529
2358.91	454.224
2363.67	452.497
2368.44	451.158
2373.2	450.046
2377.95	450.059
2382.71	449.905
2387.46	446.577
2392.2	441.864
2396.95	437.101
2401.68	432.134
2406.42	428.305
2411.15	426.577
2415.88	429.959
2420.61	430.096
2425.33	429.801
2430.05	428.948
2434.77	427.74
2439.48	425.983
2444.19	423.921
2448.89	421.766
2453.6	420.212
2458.29	419.172
2462.99	418.066
2467.68	415.509
2472.37	413.803
2477.06	413.321
2481.74	413.207
2486.42	411.86
2491.1	410.275
2495.77	408.506
2500.44	406.835
2505.1	405.016
2509.76	402.744
2514.42	399.784
2519.08	396.98
2523.73	394.308
2528.38	391.658
2533.03	388.957
2537.67	387.201
2542.31	388.3
2546.95	390.481
2551.58	390.158
2556.21	388.398
2560.84	385.77
2565.46	382.732
2570.08	377.885
2574.7	375.748
2579.31	376.534
2583.92	378.196
2588.53	378.028
2593.13	376.233
2597.73	372.763
2602.33	368.202
2606.92	365.127
2611.51	363.727
2616.1	363.269
2620.68	363.798
2625.26	367.46
2629.84	366.455
2634.42	363.795
2638.99	359.837
2643.56	361.177
2648.12	360.266
2652.68	353.078
2657.24	345.901
2661.8	346.126
2666.35	352.878
2670.9	350.652
2675.45	351.151
2679.99	350.771
2684.53	349.855
2689.06	348.124
2693.6	345.584
2698.13	341.637
2702.66	337.426
2707.18	336.658
2711.7	336.889
2716.22	336.772
2720.73	333.921
2725.24	327.907
2729.75	330.179
2734.26	331.962
2738.76	327.47
2743.25	323.285
2747.75	320.643
2752.24	320.621
2756.73	321.8
2761.22	322.558
2765.7	323.075
2770.18	322.491
2774.66	319.15
2779.13	315.419
2783.6	313.205
2788.07	311.97
2792.53	312.104
2797	313.898
2801.45	316.734
2805.91	318.169
2810.36	317.143
2814.81	313.724
2819.26	308.837
2823.7	306.109
2828.14	304.859
2832.57	303.681
2837.01	302.896
2841.44	302.006
2845.87	301.056
2850.29	299.921
2854.71	298.697
2859.13	296.402
2863.55	293.775
2867.96	291.498
2872.37	290.192
2876.77	289.52
2881.18	289.687
2885.58	290.536
2889.97	291.907
2894.37	291.67
2898.76	290.33
2903.15	289.025
2907.53	287.717
2911.91	286.237
2916.29	284.974
2920.67	280.054
2925.04	281.785
2929.41	283.636
2933.78	283.166
2938.14	283.488
2942.5	285.023
2946.86	286.437
2951.22	283.349
2955.57	279.992
2959.92	277.518
2964.26	276.191
2968.61	275.529
2972.95	274.843
2977.28	273.824
2981.62	272.686
2985.95	271.257
2990.28	269.832
2994.6	267.403
2998.93	265.124
3003.25	263.996
3007.56	264.167
3011.88	265.268
3016.19	267.365
3020.49	269.638
3024.8	269.027
3029.1	267.181
3033.4	264.618
3037.7	262.468
3041.99	261.894
3046.28	261.705
3050.57	261.495
3054.85	261.094
3059.13	259.972
3063.41	258.325
3067.69	255.568
3071.96	251.296
3076.23	245.94
3080.5	243.29
3084.76	242.916
3089.02	244.315
3093.28	248.47
3097.53	251.136
3101.79	252.88
3106.04	255.305
3110.28	255.406
3114.53	253.831
3118.77	251.501
3123.01	246.558
3127.24	242.435
3131.47	240.512
3135.7	240.038
3139.93	242.068
3144.15	246.14
3148.38	244.68
3152.59	242.986
3156.81	241.288
3161.02	239.739
3165.23	238.662
3169.44	238.295
3173.64	238.169
3177.84	238.59
3182.04	239.515
3186.24	240.136
3190.43	239.273
3194.62	238.094
3198.81	236.328
3202.99	235.155
3207.17	234.975
3211.35	233.886
3215.53	232.042
3219.7	229.796
3223.87	226.503
3228.04	222.924
3232.2	220.099
3236.36	219.327
3240.52	219.733
3244.68	221.481
3248.83	224.064
3252.98	224.65
3257.13	223.043
3261.28	219.565
3265.42	214.872
3269.56	211.726
3273.7	211.545
3277.83	212.311
3281.96	213.365
3286.09	215.022
3290.22	216.874
3294.34	217.175
3298.46	216.898
3302.58	215.263
3306.69	217.379
3310.8	215.414
3314.91	213.773
3319.02	212.211
3323.12	210.471
3327.23	209.142
3331.32	209.1
3335.42	209.545
3339.51	210.944
3343.6	212.729
3347.69	212.672
3351.78	212.707
3355.86	212.43
3359.94	211.69
3364.02	209.559
3368.09	206.06
3372.16	202.193
3376.23	199.51
3380.29	198.649
3384.36	198.244
3388.42	198.769
3392.48	199.478
3396.53	200.08
3400.58	200.249
3404.63	199.18
3408.68	197.491
3412.73	196.106
3416.77	195.663
3420.81	195.209
3424.84	194.188
3428.88	193.411
3432.91	193.081
3436.94	194.093
3440.96	193.867
3444.99	192.551
3449.01	191.903
3453.03	192.419
3457.04	193.878
3461.05	195.517
3465.06	193.279
3469.07	194.611
3473.08	195.261
3477.08	196.148
3481.08	197.747
3485.07	200.316
3489.07	202.249
3493.06	202.484
3497.05	201.284
3501.04	199.251
3505.02	197.587
3509	196.835
3512.98	196.155
3516.96	196.332
3520.93	198.174
3524.9	200.381
3528.87	200.696
3532.83	199.342
3536.8	198.109
3540.76	198.855
3544.71	200.1
3548.67	199.705
3552.62	201.444
3556.57	205.127
3560.52	208.964
3564.47	211.247
3568.41	211.808
3572.35	208.857
3576.29	204.251
3580.22	200.038
3584.15	195.41
3588.08	191.324
3592.01	187.851
3595.93	185.018
3599.85	182.955
3603.77	181.711
3607.69	181.204
3611.61	181.276
3615.52	180.686
3619.43	178.458
3623.33	177.387
3627.24	176.6
3631.14	175.042
3635.04	172.765
3638.93	170.238
3642.83	169.33
3646.72	169.629
3650.61	170.691
3654.49	171.752
3658.38	169.277
3662.26	167.759
3666.14	168.248
3670.01	168.502
3673.89	168.97
3677.76	169.287
3681.63	169.585
3685.5	169.802
3689.36	169.473
3693.22	168.44
3697.08	167.166
3700.94	167.187
3704.79	167.168
3708.64	166.92
3712.49	166.497
3716.34	166.144
3720.18	164.795
3724.02	163.375
3727.86	162.276
3731.7	161.405
3735.53	160.905
3739.36	161.087
3743.19	162.274
3747.02	164.643
3750.84	165.223
3754.66	164.269
3758.48	163.454
3762.3	164.068
3766.12	164.766
3769.93	165.052
3773.74	164.929
3777.54	164.474
3781.35	163.562
3785.15	162.228
3788.95	160.448
3792.75	158.165
3796.54	158.269
3800.34	158.819
3804.13	158.77
3807.91	158.11
3811.7	156.845
3815.48	155.136
3819.26	152.052
3823.04	147.407
3826.82	146.757
3830.59	149.863
3834.36	154.233
3838.13	155.303
3841.89	155.966
3845.66	157.163
3849.42	156.502
3853.18	154.756
3856.93	151.326
3860.69	148.467
3864.44	146.608
3868.19	145.721
3871.93	145.502
3875.68	145.957
3879.42	146.435
3883.16	144.901
3886.9	146.1
3890.63	149.892
3894.37	148.686
3898.1	147.674
3901.82	147.385
3905.55	146.27
3909.27	145.075
3912.99	144.538
3916.71	145.357
3920.43	144.734
3924.14	145.148
3927.85	146.533
3931.56	146.014
3935.27	144.996
3938.97	143.297
3942.67	141.344
3946.37	139.443
3950.07	138.239
3953.77	137.336
3957.46	136.866
3961.15	136.754
3964.84	136.891
3968.52	137.376
3972.2	138.075
3975.89	138.862
3979.56	139.406
3983.24	139.454
3986.92	137.676
3990.59	136.498
3994.26	139.304
3997.92	144.064
3999.76	148.693