File: Data/Raman/raw/tourmaline-rim_150 (500nm)_633nm_edge_100%_x50_vis_lwd_h30um_10sx2_01.txt
#Acq. time (s)=	10
#Accumulations=	2
#Range (cm-¹)=	100...4000
#Windows=	1
#Auto scanning=	Off
#Autofocus=	Off
#Macrospot=	Off
#AutoExposure=	Off
#Spike filter=	Multiple accum.
#Delay time (s)=	2
#Binning=	1
#Readout mode=	Signal
#DeNoise=	Standard
#ICS correction=	On
#Dark correction=	Off
#Inst. Process=	Off
#Detector Gain=	Best Dynamic
#Detector ADC=	50 kHz HS
#Detector temperature (°C)=	-60.09
#Instrument=	LabRAM HR Evol
#Detector=	SIN-EM FIVIS
#Objective=	x50_VIS_LWD
#Grating=	150 (500nm)
#ND Filter=	100%
#Laser=	633nm_Edge
#Hole=	30.0125
#Temperature=	0
#Range=	Visible
#StageXY=	75x50mm Scan+
#StageZ=	Z motor
#X (µm)=	0
#Y (µm)=	0
#Z (µm)=	60
#Full time(s)=	26
#Project=	20_10_27
#Sample=	BU24
#Site=
#Title=	BU24-Turm2-rim_150 (500nm)_633nm_Edge_100%_x50_VIS_LWD_H30um_10sX2
#Remark=
#Date=	27.10.2020 18:33
#Acquired=	27.10.2020 18:33:45
100.764	471.591
107.281	477.232
113.791	482.771
120.297	486.55
126.797	488.306
133.291	488.115
139.78	484.676
146.264	477.878
152.741	469.527
159.214	461.508
165.682	454.494
172.144	448.225
178.601	440.411
185.053	428.665
191.499	415.798
197.939	403.149
204.374	391.415
210.805	381.388
217.23	376.192
223.648	385.513
230.063	399.077
236.472	406.144
242.874	395.008
249.273	369.819
255.667	348.481
262.053	335.141
268.436	322.935
274.813	311.862
281.185	303.81
287.552	299.376
293.913	299.307
300.27	301.127
306.62	302.665
312.965	304.121
319.306	303.305
325.64	303.116
331.971	302.988
338.295	306.081
344.614	311.078
350.93	317.547
357.238	329.181
363.542	382.105
369.842	383.862
376.135	356.914
382.423	332.836
388.706	318.611
394.984	308.865
401.258	300.266
407.526	293.689
413.789	287.587
420.046	281.521
426.299	276.329
432.546	272.191
438.788	268.857
445.025	264.436
451.257	262.05
457.484	261.318
463.706	261.882
469.923	263.987
476.135	267.564
482.342	270.387
488.544	271.694
494.741	272.236
500.933	272.606
507.12	273.013
513.3	273.678
519.477	273.736
525.649	274.106
531.815	275.658
537.976	274.919
544.133	272.915
550.285	269.562
556.43	265.601
562.572	262.163
568.709	259.489
574.84	256.57
580.967	252.986
587.09	249.509
593.205	246.651
599.318	244.984
605.424	244.222
611.527	245.669
617.623	248.41
623.716	250.366
629.802	251.593
635.884	252.649
641.962	251.896
648.034	247.725
654.101	243.356
660.165	239.169
666.222	237.098
672.274	236.241
678.324	233.99
684.366	231.814
690.404	231.499
696.438	233.674
702.466	236.614
708.491	232.704
714.51	224.702
720.523	215.606
726.533	206.948
732.537	200.275
738.537	195.68
744.531	192.766
750.521	192.377
756.507	191.157
762.487	189.338
768.463	187.777
774.434	186.089
780.4	184.46
786.362	181.358
792.319	178.811
798.269	176.914
804.217	175.505
810.159	174.545
816.097	173.88
822.03	173.394
827.958	173.07
833.881	172.698
839.801	172.301
845.714	171.731
851.624	171.117
857.529	170.671
863.428	170.34
869.324	170.043
875.215	169.85
881.1	169.306
886.982	168.627
892.858	167.595
898.73	166.653
904.597	165.769
910.459	165.042
916.318	164.331
922.171	163.758
928.02	163.413
933.864	163.459
939.703	164.271
945.539	166.023
951.368	167.92
957.194	168.514
963.014	167.969
968.832	166.537
974.643	164.609
980.45	162.806
986.253	162.656
992.051	163.237
997.844	164.323
1003.63	165.781
1009.42	167.498
1015.2	167.504
1020.97	168.16
1026.74	169.503
1032.51	171.303
1038.27	173.414
1044.03	175.674
1049.78	177.02
1055.53	174.964
1061.27	171.377
1067.01	166.154
1072.75	161.092
1078.48	157.006
1084.2	154.304
1089.92	152.348
1095.64	151.316
1101.35	150.93
1107.06	150.62
1112.77	149.605
1118.46	147.718
1124.16	144.816
1129.85	142.07
1135.53	140.091
1141.22	138.903
1146.89	138.22
1152.56	138.427
1158.23	138.828
1163.9	137.906
1169.56	136.696
1175.21	134.697
1180.86	133.303
1186.51	132.554
1192.15	132.858
1197.78	133.448
1203.42	132.031
1209.04	130.786
1214.67	129.995
1220.29	128.982
1225.9	128.505
1231.51	128.435
1237.12	128.05
1242.72	127.65
1248.32	127.378
1253.92	127.164
1259.5	127.029
1265.09	127.022
1270.67	125.601
1276.25	124.418
1281.82	125.024
1287.39	126.346
1292.95	128.349
1298.51	128.858
1304.06	127.85
1309.61	126.669
1315.16	125.402
1320.7	124.437
1326.24	123.929
1331.77	123.325
1337.3	121.573
1342.83	120.211
1348.35	120.157
1353.86	119.874
1359.37	119.213
1364.88	118.149
1370.39	117.583
1375.89	117.407
1381.38	116.617
1386.87	115.58
1392.36	114.91
1397.84	114.632
1403.32	114.475
1408.79	113.856
1414.26	112.773
1419.73	111.161
1425.19	109.613
1430.65	107.898
1436.1	107.498
1441.55	108.247
1447	108.852
1452.44	107.973
1457.87	106.982
1463.31	106.389
1468.73	106.443
1474.16	106.741
1479.58	105.618
1484.99	105.47
1490.41	104.196
1495.81	103.008
1501.22	102.164
1506.62	101.501
1512.01	101.121
1517.4	101.236
1522.79	101.28
1528.17	101.398
1533.55	101.519
1538.93	101.385
1544.3	100.452
1549.67	99.0716
1555.03	96.8086
1560.39	96.1371
1565.74	96.3085
1571.09	96.7306
1576.44	97.0813
1581.78	96.1133
1587.12	95.1596
1592.45	94.2982
1597.78	93.74
1603.11	93.7258
1608.43	94.5266
1613.75	96.627
1619.07	96.6639
1624.38	95.8105
1629.68	94.8721
1634.98	93.6865
1640.28	92.5653
1645.58	91.629
1650.87	91.0267
1656.15	90.9184
1661.44	90.9997
1666.71	91.1896
1671.99	91.4168
1677.26	91.5854
1682.53	88.8438
1687.79	89.6189
1693.05	89.5333
1698.3	85.5542
1703.55	83.6171
1708.8	88.2054
1714.04	89.7337
1719.28	89.3273
1724.51	86.0208
1729.75	81.2724
1734.97	81.6492
1740.2	83.0734
1745.42	84.9452
1750.63	84.6067
1755.84	83.9089
1761.05	83.683
1766.25	83.6594
1771.45	83.8664
1776.65	83.7332
1781.84	83.2719
1787.03	83.1565
1792.21	83.1667
1797.39	83.3052
1802.57	83.5012
1807.74	83.7319
1812.91	83.8905
1818.08	82.9972
1823.24	82.2919
1828.39	81.6296
1833.55	80.8733
1838.7	80.4825
1843.84	81.0897
1848.99	81.2831
1854.12	80.0874
1859.26	79.2585
1864.39	78.6937
1869.52	78.3151
1874.64	76.4418
1879.76	75.7427
1884.87	74.314
1889.98	73.7424
1895.09	75.1099
1900.2	77.2815
1905.3	77.407
1910.39	75.558
1915.49	75.7628
1920.57	75.9727
1925.66	76.1015
1930.74	76.168
1935.82	76.1601
1940.89	76.0694
1945.96	75.8954
1951.03	75.6731
1956.09	74.9488
1961.15	73.0487
1966.21	71.3445
1971.26	70.5973
1976.31	71.9499
1981.35	72.2814
1986.39	71.4175
1991.43	70.9883
1996.46	72.1827
2001.49	73.4928
2006.52	73.7589
2011.54	72.8368
2016.56	71.8262
2021.57	71.029
2026.58	70.0454
2031.59	69.1671
2036.59	67.462
2041.59	66.7487
2046.59	67.0186
2051.58	67.6066
2056.57	68.3357
2061.55	68.8635
2066.54	68.5177
2071.51	67.9743
2076.49	67.472
2081.46	66.9961
2086.43	66.6397
2091.39	66.5237
2096.35	66.7414
2101.3	67.1454
2106.26	67.5216
2111.21	67.8415
2116.15	67.817
2121.09	66.0357
2126.03	64.1031
2130.97	60.9122
2135.9	60.2326
2140.83	60.7778
2145.75	64.1409
2150.67	65.6959
2155.59	65.9154
2160.5	65.4322
2165.41	64.1567
2170.31	63.284
2175.22	62.6381
2180.12	62.1644
2185.01	61.8004
2189.9	61.4968
2194.79	61.4118
2199.68	61.6327
2204.56	61.9119
2209.43	61.7363
2214.31	61.4454
2219.18	61.1606
2224.05	60.8775
2228.91	60.5856
2233.77	60.3004
2238.63	59.9042
2243.48	59.208
2248.33	59.4303
2253.17	59.8516
2258.02	60.036
2262.86	60.3437
2267.69	60.4821
2272.52	60.4725
2277.35	59.8801
2282.18	59.2843
2287	58.8962
2291.82	59.3741
2296.63	59.8899
2301.44	60.1192
2306.25	60.6812
2311.05	61.1124
2315.86	60.7516
2320.65	60.1785
2325.45	59.5667
2330.24	59.1023
2335.03	59.0267
2339.81	58.3964
2344.59	56.9546
2349.37	55.8777
2354.14	55.2254
2358.91	55.0077
2363.67	55.325
2368.44	55.9106
2373.2	56.5893
2377.95	56.908
2382.71	56.19
2387.46	55.4624
2392.2	55.0728
2396.95	55.0101
2401.68	53.7326
2406.42	53.1946
2411.15	52.9012
2415.88	52.7749
2420.61	52.7962
2425.33	52.9118
2430.05	53.1007
2434.77	53.3333
2439.48	53.611
2444.19	53.8407
2448.89	54.4324
2453.6	55.0632
2458.29	55.7122
2462.99	55.4227
2467.68	55.0328
2472.37	54.3775
2477.06	53.6774
2481.74	52.9914
2486.42	52.3237
2491.1	51.8679
2495.77	51.716
2500.44	52.3116
2505.1	53.1009
2509.76	53.8547
2514.42	54.5134
2519.08	54.6306
2523.73	54.5958
2528.38	54.2266
2533.03	53.6249
2537.67	52.9037
2542.31	52.4215
2546.95	51.8253
2551.58	50.9833
2556.21	50.6352
2560.84	50.5733
2565.46	50.019
2570.08	50.7291
2574.7	51.0406
2579.31	50.6009
2583.92	50.4377
2588.53	50.7496
2593.13	51.0474
2597.73	51.0983
2602.33	50.969
2606.92	49.7042
2611.51	48.7175
2616.1	48.5029
2620.68	49.0187
2625.26	49.9086
2629.84	49.9252
2634.42	51.5215
2638.99	51.1555
2643.56	50.351
2648.12	49.4992
2652.68	49.3709
2657.24	49.77
2661.8	49.3895
2666.35	49.0826
2670.9	48.9316
2675.45	48.8807
2679.99	48.9112
2684.53	48.9984
2689.06	49.2597
2693.6	48.4334
2698.13	47.766
2702.66	47.2625
2707.18	47.2565
2711.7	47.4295
2716.22	47.3168
2720.73	47.2962
2725.24	47.4197
2729.75	47.5835
2734.26	47.7706
2738.76	47.9609
2743.25	48.0599
2747.75	48.3127
2752.24	48.0074
2756.73	45.0914
2761.22	48.6468
2765.7	48.6208
2770.18	46.7196
2774.66	46.101
2779.13	46.7409
2783.6	47.1724
2788.07	46.5296
2792.53	45.8429
2797	45.3122
2801.45	45.6537
2805.91	45.8263
2810.36	45.942
2814.81	45.9522
2819.26	45.5349
2823.7	44.9117
2828.14	45.312
2832.57	45.5214
2837.01	45.0065
2841.44	46.1796
2845.87	45.8966
2850.29	45.5729
2854.71	45.2223
2859.13	44.9854
2863.55	44.7033
2867.96	44.4384
2872.37	44.2183
2876.77	44.1535
2881.18	44.1743
2885.58	44.0343
2889.97	44.3583
2894.37	45.4786
2898.76	45.968
2903.15	45.8759
2907.53	45.4709
2911.91	44.8668
2916.29	43.9394
2920.67	43.4679
2925.04	44.0564
2929.41	44.0628
2933.78	44.2474
2938.14	44.5086
2942.5	44.7859
2946.86	44.8127
2951.22	44.7393
2955.57	44.2859
2959.92	43.9449
2964.26	43.7221
2968.61	43.8476
2972.95	44.0028
2977.28	44.1741
2981.62	44.34
2985.95	44.4824
2990.28	44.5364
2994.6	44.4152
2998.93	43.8708
3003.25	44.4177
3007.56	45.7927
3011.88	46.3998
3016.19	45.6152
3020.49	43.198
3024.8	41.8642
3029.1	41.9165
3033.4	43.4913
3037.7	44.6885
3041.99	44.9706
3046.28	43.7799
3050.57	43.0212
3054.85	42.8076
3059.13	42.8866
3063.41	43.1709
3067.69	43.5054
3071.96	43.6372
3076.23	43.1738
3080.5	42.8308
3084.76	42.2791
3089.02	41.9444
3093.28	42.1069
3097.53	41.9111
3101.79	41.7817
3106.04	41.5587
3110.28	41.2425
3114.53	41.0383
3118.77	41.1956
3123.01	41.7783
3127.24	42.2927
3131.47	41.8397
3135.7	41.4894
3139.93	41.2919
3144.15	41.2787
3148.38	41.8591
3152.59	42.5423
3156.81	43.2722
3161.02	42.1654
3165.23	41.4658
3169.44	41.3871
3173.64	41.9232
3177.84	42.5697
3182.04	43.2621
3186.24	43.8848
3190.43	44.1984
3194.62	44.2167
3198.81	43.7011
3202.99	43.1682
3207.17	42.6978
3211.35	42.5801
3215.53	43.2171
3219.7	43.1263
3223.87	43.5616
3228.04	44.2351
3232.2	44.4173
3236.36	44.225
3240.52	43.9251
3244.68	43.6599
3248.83	43.3949
3252.98	43.1615
3257.13	43.1449
3261.28	42.5016
3265.42	42.4362
3269.56	42.8268
3273.7	44.0874
3277.83	43.5596
3281.96	44.1926
3286.09	44.0549
3290.22	44.0288
3294.34	44.0173
3298.46	42.9902
3302.58	42.7154
3306.69	43.271
3310.8	43.1854
3314.91	44.0546
3319.02	43.8815
3323.12	43.7143
3327.23	43.5299
3331.32	43.4741
3335.42	43.6421
3339.51	43.9693
3343.6	43.086
3347.69	42.6528
3351.78	42.8081
3355.86	43.4891
3359.94	44.5467
3364.02	44.6567
3368.09	44.0068
3372.16	43.4425
3376.23	43.2876
3380.29	43.2626
3384.36	43.3534
3388.42	42.8473
3392.48	41.243
3396.53	39.3301
3400.58	39.458
3404.63	42.9611
3408.68	42.2732
3412.73	42.33
3416.77	42.7914
3420.81	43.5336
3424.84	43.9377
3428.88	43.9148
3432.91	42.9494
3436.94	42.233
3440.96	41.9835
3444.99	41.9767
3449.01	42.6128
3453.03	43.3516
3457.04	44.1257
3461.05	44.1387
3465.06	44.1199
3469.07	44.0802
3473.08	44.0857
3477.08	44.1546
3481.08	44.3178
3485.07	44.558
3489.07	45.3014
3493.06	46.1842
3497.05	46.6931
3501.04	46.3361
3505.02	45.9915
3509	45.6864
3512.98	45.4389
3516.96	45.871
3520.93	46.0328
3524.9	46.3102
3528.87	47.914
3532.83	49.6467
3536.8	51.6017
3540.76	53.7163
3544.71	55.8241
3548.67	55.4992
3552.62	56.6815
3556.57	57.8147
3560.52	59.5085
3564.47	59.3073
3568.41	58.9304
3572.35	58.0444
3576.29	55.0193
3580.22	51.1674
3584.15	47.0962
3588.08	45.9984
3592.01	43.5328
3595.93	43.4995
3599.85	43.9399
3603.77	43.4418
3607.69	41.7647
3611.61	39.6919
3615.52	40.1571
3619.43	41.8812
3623.33	43.2291
3627.24	43.1389
3631.14	43.0497
3635.04	42.9535
3638.93	42.8688
3642.83	42.0715
3646.72	41.16
3650.61	40.7411
3654.49	40.7373
3658.38	41.1654
3662.26	42.0002
3666.14	42.6471
3670.01	42.6037
3673.89	42.5443
3677.76	42.4765
3681.63	40.8386
3685.5	42.0865
3689.36	41.9549
3693.22	41.4374
3697.08	41.0481
3700.94	40.8357
3704.79	42.0423
3708.64	43.2588
3712.49	43.5439
3716.34	43.4931
3720.18	43.4915
3724.02	43.4712
3727.86	42.7846
3731.7	41.8872
3735.53	41.4332
3739.36	40.9188
3743.19	42.1346
3747.02	43.2943
3750.84	43.3746
3754.66	42.6256
3758.48	41.7894
3762.3	40.9899
3766.12	40.4366
3769.93	41.0506
3773.74	41.6682
3777.54	41.7169
3781.35	41.9121
3785.15	42.1888
3788.95	42.5103
3792.75	42.8518
3796.54	43.1788
3800.34	41.4297
3804.13	41.074
3807.91	42.0161
3811.7	43.2268
3815.48	43.0127
3819.26	42.2087
3823.04	41.8754
3826.82	41.8245
3830.59	41.9288
3834.36	42.0984
3838.13	42.3684
3841.89	42.6817
3845.66	42.9547
3849.42	43.2047
3853.18	43.3739
3856.93	43.5576
3860.69	43.659
3864.44	41.4459
3868.19	42.6388
3871.93	43.3462
3875.68	44.0584
3879.42	44.5727
3883.16	44.4218
3886.9	44.2319
3890.63	44.048
3894.37	43.8863
3898.1	43.7343
3901.82	43.5933
3905.55	43.4544
3909.27	43.3133
3912.99	43.2548
3916.71	43.0256
3920.43	42.7611
3924.14	42.4585
3927.85	42.0843
3931.56	41.893
3935.27	41.7916
3938.97	41.7666
3942.67	41.0764
3946.37	40.1085
3950.07	39.4036
3953.77	39.6287
3957.46	40.2893
3961.15	41.3731
3964.84	42.7468
3968.52	44.2126
3972.2	45.7364
3975.89	46.3632
3979.56	46.2194
3983.24	45.4808
3986.92	44.3565
3990.59	42.9582
3994.26	41.5815
3997.92	41.9437
3999.76	44.2777