File: Data/Raman/raw/wardite_150 (500nm)_532nm_edge_100%_x50_vis_lwd_h50um_10sx2_01.txt
#Acq. time (s)=	10
#Accumulations=	2
#Range (cm-¹)=	100...5200
#Windows=	1
#Auto scanning=	Off
#Autofocus=	Off
#Macrospot=	Off
#AutoExposure=	Off
#Spike filter=	Multiple accum.
#Delay time (s)=	2
#Binning=	1
#Readout mode=	Signal
#DeNoise=	Off
#ICS correction=	On
#Dark correction=	Off
#Inst. Process=	Off
#Detector Gain=	Best Dynamic
#Detector ADC=	50 kHz HS
#Detector temperature (°C)=	-60.09
#Instrument=	LabRAM HR Evol
#Detector=	SIN-EM FIVIS
#Objective=	x50_VIS_LWD
#Grating=	150 (500nm)
#ND Filter=	100%
#Laser=	532nm_Edge
#Hole=	49.98
#Temperature=	0
#Range=	Visible
#StageXY=	75x50mm Scan+
#StageZ=	Z motor
#X (µm)=	0
#Y (µm)=	0
#Z (µm)=	-73.4
#Full time(s)=	25
#Project=	21_06_18
#Sample=	BU02a
#Site=
#Title=	BU02a-Area8-wardite-right-colorless_150 (500nm)_532nm_Edge_100%_x50_VIS_LWD_H50um_10sX2
#Remark=
#Date=	18.06.2021 15:44
#Acquired=	18.06.2021 15:44:12
101.963	2732
111.206	2276.83
120.443	2368.11
129.668	2465.05
138.887	2982.89
148.096	4202.08
157.294	3311.04
166.485	2839.03
175.665	7973.29
184.838	9997.17
194	3895.43
203.153	2113.17
212.299	2778.22
221.434	4959.65
230.562	4422.9
239.679	3442.65
248.787	3157.93
257.888	4994.18
266.978	4375.33
276.059	2239.99
285.133	1816.77
294.197	1667.2
303.251	1697.38
312.297	1889.05
321.334	2750.53
330.364	3350.77
339.383	3392.28
348.393	2938.5
357.395	2792.97
366.388	2393.97
375.372	1992.3
384.347	2194.56
393.314	2890.26
402.271	3432.36
411.22	2716.55
420.161	2059.43
429.092	2086.01
438.015	2063.76
446.93	2232.39
455.835	2560.55
464.732	2460.79
473.621	2660.77
482.501	3332.12
491.372	3299.35
500.234	2627.39
509.086	2351.53
517.932	2019.58
526.769	1777.42
535.597	1846.68
544.415	2147.28
553.226	2384.67
562.029	2254.54
570.823	2376.82
579.607	2888.68
588.384	3309.39
597.153	3812.53
605.912	5197.2
614.664	6603.63
623.405	7049.49
632.141	4887.68
640.865	3069.98
649.584	2300.58
658.292	2215.09
666.993	2291.97
675.685	2081.53
684.37	1772.63
693.045	1646.03
701.713	1516.85
710.371	1460.99
719.021	1456.02
727.664	1445.31
736.298	1507.75
744.923	1483.75
753.542	1460.52
762.15	1602.87
770.75	1689.5
779.345	1823.24
787.929	1832.07
796.504	1777.44
805.072	1633.58
813.631	1579.7
822.183	1600.29
830.728	1495.28
839.263	1503.71
847.79	1467.07
856.309	1440.19
864.82	1439.5
873.322	1471.31
881.817	1574.88
890.304	1597.69
898.782	1622.5
907.253	1601.41
915.715	1649.47
924.17	1666.91
932.616	1693.1
941.053	1732.34
949.484	1787.32
957.906	1935.66
966.321	2189.33
974.728	2730.54
983.125	4326.91
991.515	8868.48
999.898	10669.1
1008.27	6022.3
1016.64	3908.65
1025	3845.28
1033.35	5005.3
1041.69	7162.23
1050.03	10825.2
1058.36	8588.16
1066.67	4652.71
1074.99	3825.14
1083.29	4392.45
1091.59	3808.59
1099.87	3294
1108.15	3243.15
1116.43	3050.09
1124.69	2763.47
1132.95	2792.61
1141.2	2897.06
1149.44	2567.48
1157.67	2204.65
1165.9	1938.7
1174.12	1872.75
1182.33	2039.13
1190.53	2000.14
1198.73	1732.65
1206.91	1697.71
1215.09	1669.26
1223.26	1721.12
1231.43	1747.08
1239.59	1716.29
1247.74	1742.4
1255.88	1737.53
1264.01	1696.89
1272.14	1712.44
1280.26	1684.09
1288.37	1706.04
1296.47	1797.56
1304.57	1733.07
1312.66	1707.05
1320.74	1700.42
1328.81	1743.18
1336.88	1711.41
1344.94	1741.35
1352.99	1746.93
1361.04	1764.44
1369.07	1741.02
1377.1	1758.54
1385.12	1769.77
1393.14	1782.02
1401.14	1753.82
1409.14	1773.78
1417.13	1791.38
1425.12	1831.48
1433.1	1838.07
1441.07	1883.26
1449.03	1903.1
1456.98	1915.05
1464.93	1957
1472.87	1912.65
1480.81	1886.68
1488.73	1933.46
1496.65	1937.28
1504.56	1929.2
1512.47	1931.46
1520.36	1991.54
1528.25	1983.32
1536.13	2027.19
1544.01	2028.59
1551.88	1994.18
1559.74	2050.05
1567.59	2051.64
1575.44	2076.8
1583.28	2092.95
1591.11	2074.93
1598.93	2132.75
1606.75	2233.25
1614.56	2251.72
1622.36	2202.83
1630.16	2197.89
1637.95	2192.67
1645.73	2173.57
1653.51	2200.57
1661.28	2193.69
1669.04	2211.6
1676.79	2222.94
1684.54	2222.58
1692.28	2263.85
1700.01	2256.6
1707.73	2248.54
1715.45	2304.5
1723.16	2243.19
1730.87	2331.17
1738.56	2363.8
1746.26	2365.6
1753.94	2343.28
1761.62	2401.6
1769.28	2378.23
1776.95	2425
1784.6	2367.69
1792.25	2411.32
1799.89	2425.31
1807.53	2426.61
1815.16	2437.02
1822.78	2426.35
1830.39	2398.35
1838	2488.59
1845.6	2467.74
1853.19	2476.78
1860.78	2468.55
1868.36	2516.78
1875.94	2554.79
1883.5	2568.66
1891.06	2585.71
1898.61	2583.97
1906.16	2604.23
1913.7	2617.33
1921.23	2603.89
1928.76	2653.41
1936.28	2626.89
1943.79	2708.33
1951.29	2624.96
1958.79	2703.78
1966.28	2747.21
1973.77	2724.91
1981.25	2796.41
1988.72	2783.63
1996.19	2808.2
2003.65	2843.97
2011.1	2845.13
2018.54	2879.07
2025.98	2819.12
2033.41	2881.74
2040.84	2930.23
2048.26	2961.54
2055.67	2940.21
2063.08	2981.54
2070.47	2962.38
2077.87	2968.59
2085.25	3055.9
2092.63	3053.89
2100	3020.12
2107.37	3091.08
2114.73	3110.16
2122.08	3128.1
2129.43	3162.26
2136.77	3192.14
2144.1	3143.59
2151.43	3184.32
2158.75	3193.95
2166.07	3262.39
2173.38	3223.23
2180.68	3255.75
2187.97	3306.51
2195.26	3288.31
2202.54	3287.06
2209.82	3357.23
2217.09	3362.58
2224.35	3408.04
2231.6	3369.62
2238.85	3431.49
2246.1	3339.21
2253.33	3442.44
2260.57	3396.83
2267.79	3476.95
2275.01	3444.77
2282.22	3490.41
2289.43	3538.17
2296.62	3558.69
2303.82	3524.1
2311	3598.71
2318.18	3543.15
2325.36	3640.52
2332.52	3701.81
2339.69	3633.75
2346.84	3585.01
2353.99	3693.41
2361.13	3662.26
2368.27	3735.99
2375.4	3755.49
2382.52	3745.7
2389.64	3723.1
2396.75	3780.83
2403.86	3823.96
2410.96	3873.71
2418.05	3841.7
2425.14	3872.49
2432.22	3921
2439.29	3922.66
2446.36	3930.14
2453.42	4001.01
2460.48	3988.59
2467.53	3976.79
2474.57	3933.17
2481.61	4000.82
2488.64	3958.45
2495.66	4050.76
2502.68	4011.72
2509.7	4093.41
2516.7	4028.25
2523.7	4064.95
2530.7	4132.73
2537.69	4132.72
2544.67	4165.44
2551.65	4223.61
2558.62	4190.15
2565.58	4189.28
2572.54	4200.58
2579.5	4262.55
2586.44	4285.96
2593.38	4304.33
2600.32	4264.69
2607.25	4331.42
2614.17	4338.4
2621.09	4351.54
2628	4338.76
2634.9	4381.8
2641.8	4432.61
2648.69	4470.7
2655.58	4468.88
2662.46	4474.84
2669.34	4487.71
2676.21	4497.66
2683.07	4563.82
2689.93	4616.98
2696.78	4588.98
2703.63	4646.07
2710.47	4746.57
2717.3	4744.69
2724.13	4710.81
2730.95	4798.18
2737.77	4785.39
2744.58	4860.44
2751.39	4865.64
2758.18	4864.81
2764.98	4932.13
2771.76	5118.28
2778.55	5070.03
2785.32	5060.5
2792.09	5185.4
2798.86	5269.11
2805.62	5289.94
2812.37	5305.56
2819.12	5450.81
2825.86	5471.94
2832.6	5533.53
2839.33	5750.63
2846.05	5738.42
2852.77	5944.11
2859.48	5982.93
2866.19	6241.93
2872.89	6307.62
2879.59	6323.59
2886.28	6342.28
2892.96	6376.87
2899.64	6401.49
2906.31	6442.25
2912.98	6462.6
2919.64	6505.23
2926.3	6495.41
2932.95	6481.43
2939.6	6497.68
2946.24	6476.42
2952.87	6282.68
2959.5	6408.8
2966.12	6368.45
2972.74	6341.02
2979.35	6310.64
2985.96	6305.55
2992.56	6248.29
2999.15	6225.06
3005.74	6178.47
3012.33	6118.05
3018.91	6057.96
3025.48	6139.9
3032.05	6118.18
3038.61	6092.67
3045.17	6169.36
3051.72	6165.87
3058.26	6224.12
3064.8	6374.07
3071.34	6340.19
3077.86	6331.05
3084.39	6161.7
3090.91	6130.55
3097.42	6127.62
3103.93	6178.38
3110.43	6096.1
3116.92	6076.87
3123.42	6080.44
3129.9	6055.02
3136.38	6070.42
3142.86	6051.51
3149.33	6058.69
3155.79	6137.83
3162.25	6038.45
3168.7	6102.48
3175.15	6132.34
3181.59	6216.11
3188.03	6208.73
3194.46	6197.37
3200.89	6192.35
3207.31	6288.81
3213.72	6357.85
3220.14	6402.54
3226.54	6553.89
3232.94	6754.33
3239.33	6848.33
3245.72	7128.07
3252.11	7408.42
3258.49	7595.92
3264.86	7787.06
3271.23	8053.5
3277.59	7990.43
3283.95	7854.73
3290.3	7712.67
3296.65	7498.82
3302.99	7255.54
3309.33	7111.73
3315.66	6956.38
3321.99	6790.06
3328.31	6677.21
3334.62	6648.66
3340.93	6641.18
3347.24	6414.52
3353.54	6492.62
3359.83	6400.87
3366.12	6426.18
3372.41	6440.35
3378.69	6399.03
3384.96	6367.71
3391.23	6340.02
3397.5	6252.32
3403.76	6277.57
3410.01	6216.6
3416.26	6158.76
3422.5	6197.05
3428.74	6170.05
3434.98	6133.25
3441.2	6061.45
3447.43	6072.03
3453.64	6028.68
3459.86	5988.14
3466.07	5943.44
3472.27	5893.81
3478.47	5906.87
3484.66	5937.92
3490.85	5892.33
3497.03	5932.02
3503.21	5942.51
3509.38	6058.58
3515.55	6143.14
3521.71	6242.39
3527.87	6470.2
3534.02	7176.96
3540.17	11183.6
3546.31	30664.1
3552.45	23981.7
3558.58	9401.74
3564.71	6550.65
3570.83	6000.68
3576.95	5948.14
3583.07	5810.01
3589.17	5968.05
3595.28	6271.16
3601.37	7381.44
3607.47	13661.3
3613.56	21026.5
3619.64	12726.9
3625.72	7573.53
3631.79	6124.97
3637.86	5684.59
3643.92	5373.47
3649.98	5382.45
3656.04	5280.03
3662.09	5173.28
3668.13	5183.89
3674.17	5206.03
3680.21	5114.18
3686.23	5153.32
3692.26	5166.58
3698.28	5027.44
3704.29	5074.24
3710.31	5105.27
3716.31	5228.47
3722.31	5079.07
3728.31	5094.17
3734.3	5039.98
3740.28	5088.44
3746.27	5040.55
3752.24	5039.37
3758.21	4927.71
3764.18	5028.97
3770.14	5012.78
3776.1	4971.87
3782.05	5005.06
3788	5034.23
3793.95	4970.7
3799.88	4996.89
3805.82	5002.37
3811.75	4963.36
3817.67	4974.18
3823.59	4980.94
3829.51	4964.95
3835.42	4995.87
3841.32	4984.19
3847.22	4975.34
3853.12	4923.43
3859.01	4951.18
3864.9	4938.71
3870.78	4996.41
3876.66	4948.75
3882.53	4952.9
3888.4	4903.98
3894.26	4893.42
3900.12	4896.16
3905.97	4888.77
3911.82	4934.38
3917.67	4928.16
3923.51	4913.87
3929.34	4915.23
3935.17	4957.88
3941	4851.48
3946.82	4859.29
3952.64	4893.61
3958.45	4824.75
3964.26	4876.78
3970.06	4900.19
3975.86	4894.33
3981.66	4820.09
3987.45	4875.78
3993.23	4922.66
3999.01	4852.35
4004.79	4832.51
4010.56	4833.52
4016.33	4807.48
4022.09	4841.27
4027.85	4848.18
4033.6	4844.74
4039.35	4821.41
4045.09	4802.05
4050.83	4812.57
4056.57	4864.16
4062.3	4834.2
4068.02	4852.61
4073.75	4873.77
4079.46	4804.06
4085.18	4803.41
4090.88	4764.24
4096.59	4739.95
4102.29	4809.49
4107.98	4808.69
4113.67	4735.41
4119.36	4792.03
4125.04	4728.2
4130.72	4706.57
4136.39	4734.11
4142.06	4781.82
4147.72	4706.26
4153.38	4736.48
4159.04	4653.59
4164.69	4633.17
4170.34	4724.08
4175.98	4650.58
4181.62	4706.69
4187.25	4642.5
4192.88	4662.68
4198.5	4650.02
4204.12	4654.59
4209.74	4672.85
4215.35	4636.78
4220.96	4651.03
4226.56	4645.94
4232.16	4561.74
4237.75	4587.88
4243.34	4580.98
4248.92	4579.45
4254.5	4559.62
4260.08	4511.58
4265.65	4497.95
4271.22	4577.61
4276.78	4533.32
4282.34	4540.84
4287.9	4500.97
4293.45	4460.22
4299	4449.13
4304.54	4565.41
4310.08	4504.24
4315.61	4475.86
4321.14	4515.76
4326.66	4438.29
4332.19	4465.29
4337.7	4446.01
4343.21	4439.18
4348.72	4405.15
4354.23	4398.24
4359.73	4435.57
4365.22	4361.23
4370.71	4414.99
4376.2	4368.06
4381.68	4345.73
4387.16	4384.39
4392.64	4331.47
4398.11	4366.43
4403.57	4432.59
4409.03	4366.27
4414.49	4303.42
4419.95	4325.11
4425.39	4275.86
4430.84	4224.75
4436.28	4247.44
4441.72	4312.1
4447.15	4335.47
4452.58	4290.99
4458	4257.09
4463.42	4253.37
4468.84	4305.01
4474.25	4239.76
4479.66	4203.29
4485.06	4204.53
4490.46	4150.99
4495.86	4183.3
4501.25	4199.38
4506.64	4175.69
4512.02	4122.97
4517.4	4169.26
4522.77	4128.31
4528.14	4114.23
4533.51	4139.83
4538.87	4073.16
4544.23	4095.67
4549.59	4042.49
4554.94	4065.76
4560.28	4061.04
4565.63	4029.98
4570.96	4060.75
4576.3	4059.7
4581.63	4048.3
4586.96	4015.16
4592.28	3997.1
4597.6	4010.16
4602.91	3947.06
4608.22	3949.83
4613.53	3980.1
4618.83	3910.3
4624.13	3892.57
4629.42	3888.17
4634.71	3896.01
4640	3897.13
4645.28	3880.31
4650.56	3921.8
4655.83	3951.57
4661.1	3863.14
4666.37	3873.37
4671.63	3824.4
4676.89	3933.56
4682.14	3847.31
4687.39	3791.07
4692.64	3760.77
4697.88	3812.05
4703.12	3751.65
4708.36	3784.02
4713.59	3758.27
4718.81	3781.77
4724.04	3798.99
4729.26	3790.09
4734.47	3732.68
4739.68	3766.72
4744.89	3809.11
4750.09	3702.21
4755.29	3697.3
4760.49	3734.71
4765.68	3698.11
4770.87	3665.98
4776.05	3606.37
4781.23	3625.56
4786.41	3608.25
4791.58	3639.18
4796.75	3643.26
4801.92	3654.23
4807.08	3615.95
4812.23	3611.95
4817.39	3651.26
4822.54	3520.29
4827.68	3591.78
4832.82	3522.08
4837.96	3555.74
4843.1	3561.34
4848.23	3547.55
4853.35	3500.67
4858.48	3558.02
4863.59	3510.5
4868.71	3457.07
4873.82	3447.14
4878.93	3490.07
4884.03	3449.29
4889.13	3393.93
4894.23	3402.73
4899.32	3422.99
4904.41	3392.88
4909.49	3432.71
4914.57	3457.53
4919.65	3401.73
4924.73	3324.79
4929.79	3400.9
4934.86	3354.66
4939.92	3278.31
4944.98	3288.71
4950.04	3321.68
4955.09	3303.17
4960.14	3354.12
4965.18	3302.4
4970.22	3285.51
4975.25	3223.68
4980.29	3257.14
4985.32	3235.31
4990.34	3176.06
4995.36	3227.06
5000.38	3291.64
5005.4	3213.78
5010.4	3185.38
5015.41	3167.02
5020.42	3210.01
5025.41	3228.24
5030.41	3195.45
5035.4	3194.57
5040.39	3074.99
5045.38	3092.91
5050.36	3191.04
5055.33	3122.85
5060.31	3179.67
5065.28	3054
5070.24	3096.27
5075.21	3120.69
5080.17	3039.15
5085.12	3097.43
5090.07	3055.01
5095.02	3054.27
5099.97	3059.73
5104.91	3040.21
5109.85	2983.96
5114.78	2991.8
5119.71	2968.97
5124.64	2984.16
5129.56	3009.52
5134.48	2969.39
5139.4	2990.23
5144.31	2964.01
5149.22	2894.69
5154.12	2934.97
5159.03	2878.38
5163.92	2845.48
5168.82	2893.53
5173.71	2926.62
5178.6	2915.02
5183.48	2838.54
5188.36	2809.52
5193.24	2826.68
5198.11	2809.16